{
 "version": 8,
 "blockIdVersion": 11,
 "anchorX": 0,
 "anchorY": 16,
 "anchorZ": 0,
 "entities": [
  {
   "Components": {
    "Transform": {
     "Position": {
      "X": 0.5,
      "Y": 9.0,
      "Z": 0.5
     },
     "Rotation": {
      "Pitch": 0.0,
      "Yaw": 0.0,
      "Roll": 0.0
     }
    },
    "HiddenFromAdventurePlayer": {},
    "Model": {
     "Model": {
      "Id": "NPC_Path_Marker",
      "Scale": 1.0,
      "Static": false
     }
    },
    "PersistentDisplayName": {
     "DisplayName": {
      "RawText": "kn_shrine_marker"
     }
    },
    "Nameplate": {
     "Text": "kn_shrine_marker"
    }
   }
  },
  {
   "Components": {
    "Nameplate": {
     "Text": "KweebecNightmare_Husk_Patrol"
    },
    "HiddenFromAdventurePlayer": {},
    "SpawnMarkerComponent": {
     "SpawnMarker": "KweebecNightmare_Husk_Patrol",
     "RespawnTime": 0.0,
     "SpawnCount": 0,
     "NPCReferences": [],
     "PersistedFlock": {},
     "SpawnPosition": {
      "X": 0.0,
      "Y": 0.0,
      "Z": 0.0
     }
    },
    "Transform": {
     "Position": {
      "X": 0.5,
      "Y": 17.0,
      "Z": -0.5
     },
     "Rotation": {
      "Pitch": 0.0,
      "Yaw": 107.4063949584961,
      "Roll": 0.0
     }
    },
    "Intangible": {},
    "PrefabCopyable": {},
    "Model": {
     "Model": {
      "Id": "NPC_Spawn_Marker",
      "Scale": 1.0,
      "Static": false
     }
    },
    "UUID": {
     "$binary": "PrXRkyM3RASbKLTHyRnUWA==",
     "$type": "04"
    },
    "HeadRotation": {
     "Rotation": {
      "Pitch": 0.0,
      "Yaw": 104.26480102539062,
      "Roll": 0.0
     }
    }
   }
  },
  {
   "Components": {
    "Nameplate": {
     "Text": "KN_CryptPatrol #1"
    },
    "PatrolPathMarker": {
     "Version": 5,
     "DisplayName": "0.fa351b86-5ad0-4563-aac2-b944b3bcf6f1 (Z3Kweebec_P2) #6 [Wait 10.0s] <Rotate 90.00deg>",
     "UUID": {
      "$binary": "mZxFmnkrSx6m2MwZOaPiRQ==",
      "$type": "04"
     },
     "PathId": {
      "$binary": "KUtdD9kmSSmosx58bW9mpA==",
      "$type": "04"
     },
     "PathName": "KN_CryptPatrol",
     "PathLength": 4,
     "Order": 1,
     "PauseTime": 10.0,
     "ObsvAngle": 1.5707963705062866
    },
    "HiddenFromAdventurePlayer": {},
    "Transform": {
     "Position": {
      "X": 3.5,
      "Y": 17.0,
      "Z": 8.5
     },
     "Rotation": {
      "Pitch": 0.0,
      "Yaw": 98.83663940429688,
      "Roll": 0.0
     }
    },
    "Velocity": {
     "Velocity": {
      "X": 0.0,
      "Y": 0.0,
      "Z": 0.0
     }
    },
    "PrefabCopyable": {},
    "Model": {
     "Model": {
      "Id": "NPC_Path_Marker",
      "Scale": 1.0,
      "Static": false
     }
    },
    "UUID": {
     "$binary": "reHr9zlPSKyPyIdHjOPUMA==",
     "$type": "04"
    },
    "PersistentDisplayName": {
     "DisplayName": {
      "RawText": "KN_CryptPatrol #1"
     }
    },
    "HeadRotation": {
     "Rotation": {
      "Pitch": 0.0,
      "Yaw": 98.83663940429688,
      "Roll": 0.0
     }
    }
   }
  },
  {
   "Components": {
    "Nameplate": {
     "Text": "KN_CryptPatrol #2"
    },
    "PatrolPathMarker": {
     "Version": 5,
     "DisplayName": "0.fa351b86-5ad0-4563-aac2-b944b3bcf6f1 (Z3Kweebec_P2) #6 [Wait 10.0s] <Rotate 90.00deg>",
     "UUID": {
      "$binary": "1+ceAygZQPCCUO04xkhHcw==",
      "$type": "04"
     },
     "PathId": {
      "$binary": "KUtdD9kmSSmosx58bW9mpA==",
      "$type": "04"
     },
     "PathName": "KN_CryptPatrol",
     "PathLength": 4,
     "Order": 2,
     "PauseTime": 10.0,
     "ObsvAngle": 1.5707963705062866
    },
    "HiddenFromAdventurePlayer": {},
    "Transform": {
     "Position": {
      "X": -1.5,
      "Y": 18.0,
      "Z": 8.5
     },
     "Rotation": {
      "Pitch": 0.0,
      "Yaw": 98.83663940429688,
      "Roll": 0.0
     }
    },
    "Velocity": {
     "Velocity": {
      "X": 0.0,
      "Y": 0.0,
      "Z": 0.0
     }
    },
    "PrefabCopyable": {},
    "Model": {
     "Model": {
      "Id": "NPC_Path_Marker",
      "Scale": 1.0,
      "Static": false
     }
    },
    "UUID": {
     "$binary": "fKAkM/uSSQivAQ+JyjKotQ==",
     "$type": "04"
    },
    "PersistentDisplayName": {
     "DisplayName": {
      "RawText": "KN_CryptPatrol #2"
     }
    },
    "HeadRotation": {
     "Rotation": {
      "Pitch": 0.0,
      "Yaw": 98.83663940429688,
      "Roll": 0.0
     }
    }
   }
  },
  {
   "Components": {
    "Nameplate": {
     "Text": "KN_CryptPatrol #3"
    },
    "PatrolPathMarker": {
     "Version": 5,
     "DisplayName": "0.fa351b86-5ad0-4563-aac2-b944b3bcf6f1 (Z3Kweebec_P2) #6 [Wait 10.0s] <Rotate 90.00deg>",
     "UUID": {
      "$binary": "mLSLx+z7TrWpm+EHsw5pgQ==",
      "$type": "04"
     },
     "PathId": {
      "$binary": "KUtdD9kmSSmosx58bW9mpA==",
      "$type": "04"
     },
     "PathName": "KN_CryptPatrol",
     "PathLength": 4,
     "Order": 3,
     "PauseTime": 10.0,
     "ObsvAngle": 1.5707963705062866
    },
    "HiddenFromAdventurePlayer": {},
    "Transform": {
     "Position": {
      "X": -0.5,
      "Y": 18.0,
      "Z": -9.5
     },
     "Rotation": {
      "Pitch": 0.0,
      "Yaw": 98.83663940429688,
      "Roll": 0.0
     }
    },
    "Velocity": {
     "Velocity": {
      "X": 0.0,
      "Y": 0.0,
      "Z": 0.0
     }
    },
    "PrefabCopyable": {},
    "Model": {
     "Model": {
      "Id": "NPC_Path_Marker",
      "Scale": 1.0,
      "Static": false
     }
    },
    "UUID": {
     "$binary": "+BVpxIfNTIu2FQWRYooYbA==",
     "$type": "04"
    },
    "PersistentDisplayName": {
     "DisplayName": {
      "RawText": "KN_CryptPatrol #3"
     }
    },
    "HeadRotation": {
     "Rotation": {
      "Pitch": 0.0,
      "Yaw": 98.83663940429688,
      "Roll": 0.0
     }
    }
   }
  },
  {
   "Components": {
    "Nameplate": {
     "Text": "KN_CryptPatrol #4"
    },
    "PatrolPathMarker": {
     "Version": 5,
     "DisplayName": "0.fa351b86-5ad0-4563-aac2-b944b3bcf6f1 (Z3Kweebec_P2) #6 [Wait 10.0s] <Rotate 90.00deg>",
     "UUID": {
      "$binary": "KzTVZZxJT12deWJH6obkUA==",
      "$type": "04"
     },
     "PathId": {
      "$binary": "KUtdD9kmSSmosx58bW9mpA==",
      "$type": "04"
     },
     "PathName": "KN_CryptPatrol",
     "PathLength": 4,
     "Order": 4,
     "PauseTime": 10.0,
     "ObsvAngle": 1.5707963705062866
    },
    "HiddenFromAdventurePlayer": {},
    "Transform": {
     "Position": {
      "X": 1.5,
      "Y": 18.0,
      "Z": -9.5
     },
     "Rotation": {
      "Pitch": 0.0,
      "Yaw": 98.83663940429688,
      "Roll": 0.0
     }
    },
    "Velocity": {
     "Velocity": {
      "X": 0.0,
      "Y": 0.0,
      "Z": 0.0
     }
    },
    "PrefabCopyable": {},
    "Model": {
     "Model": {
      "Id": "NPC_Path_Marker",
      "Scale": 1.0,
      "Static": false
     }
    },
    "UUID": {
     "$binary": "2r4DhEk6Q0CdD2thZR1T4A==",
     "$type": "04"
    },
    "PersistentDisplayName": {
     "DisplayName": {
      "RawText": "KN_CryptPatrol #4"
     }
    },
    "HeadRotation": {
     "Rotation": {
      "Pitch": 0.0,
      "Yaw": 98.83663940429688,
      "Roll": 0.0
     }
    }
   }
  }
 ],
 "blocks": [
  {
   "x": -14,
   "y": 28,
   "z": -3,
   "name": "Plant_Vine_Wall",
   "rotation": 3
  },
  {
   "x": -14,
   "y": 22,
   "z": 0,
   "name": "Plant_Leaves_Ash"
  },
  {
   "x": -14,
   "y": 23,
   "z": 0,
   "name": "Plant_Leaves_Ash"
  },
  {
   "x": -14,
   "y": 21,
   "z": 1,
   "name": "Plant_Leaves_Ash"
  },
  {
   "x": -14,
   "y": 22,
   "z": 1,
   "name": "Plant_Leaves_Ash"
  },
  {
   "x": -14,
   "y": 23,
   "z": 1,
   "name": "Plant_Leaves_Ash"
  },
  {
   "x": -14,
   "y": 24,
   "z": 1,
   "name": "Plant_Leaves_Ash"
  },
  {
   "x": -14,
   "y": 23,
   "z": 2,
   "name": "Plant_Leaves_Ash"
  },
  {
   "x": -14,
   "y": 24,
   "z": 2,
   "name": "Plant_Leaves_Ash"
  },
  {
   "x": -13,
   "y": 27,
   "z": -4,
   "name": "Plant_Leaves_Ash"
  },
  {
   "x": -13,
   "y": 28,
   "z": -4,
   "name": "Plant_Leaves_Ash"
  },
  {
   "x": -13,
   "y": 27,
   "z": -3,
   "name": "Plant_Vine_Hanging"
  },
  {
   "x": -13,
   "y": 28,
   "z": -3,
   "name": "Plant_Leaves_Ash"
  },
  {
   "x": -13,
   "y": 28,
   "z": -2,
   "name": "Plant_Vine_Wall"
  },
  {
   "x": -13,
   "y": 22,
   "z": -1,
   "name": "Plant_Leaves_Ash"
  },
  {
   "x": -13,
   "y": 23,
   "z": -1,
   "name": "Plant_Leaves_Ash"
  },
  {
   "x": -13,
   "y": 22,
   "z": 0,
   "name": "Plant_Leaves_Ash"
  },
  {
   "x": -13,
   "y": 23,
   "z": 0,
   "name": "Plant_Leaves_Ash"
  },
  {
   "x": -13,
   "y": 24,
   "z": 0,
   "name": "Plant_Leaves_Ash"
  },
  {
   "x": -13,
   "y": 21,
   "z": 1,
   "name": "Plant_Vine_Hanging"
  },
  {
   "x": -13,
   "y": 22,
   "z": 1,
   "name": "Plant_Leaves_Ash"
  },
  {
   "x": -13,
   "y": 23,
   "z": 1,
   "name": "Wood_Ash_Branch_Long",
   "rotation": 5
  },
  {
   "x": -13,
   "y": 24,
   "z": 1,
   "name": "Plant_Leaves_Ash"
  },
  {
   "x": -13,
   "y": 22,
   "z": 2,
   "name": "Plant_Leaves_Ash"
  },
  {
   "x": -13,
   "y": 23,
   "z": 2,
   "name": "Plant_Leaves_Ash"
  },
  {
   "x": -13,
   "y": 24,
   "z": 2,
   "name": "Plant_Leaves_Ash"
  },
  {
   "x": -13,
   "y": 25,
   "z": 2,
   "name": "Plant_Leaves_Ash"
  },
  {
   "x": -13,
   "y": 26,
   "z": 2,
   "name": "Plant_Leaves_Ash"
  },
  {
   "x": -13,
   "y": 27,
   "z": 2,
   "name": "Plant_Leaves_Ash"
  },
  {
   "x": -13,
   "y": 23,
   "z": 3,
   "name": "Plant_Leaves_Ash"
  },
  {
   "x": -13,
   "y": 27,
   "z": 3,
   "name": "Plant_Leaves_Ash"
  },
  {
   "x": -13,
   "y": 28,
   "z": 3,
   "name": "Plant_Leaves_Ash"
  },
  {
   "x": -13,
   "y": 23,
   "z": 4,
   "name": "Plant_Leaves_Ash"
  },
  {
   "x": -12,
   "y": 27,
   "z": -5,
   "name": "Plant_Leaves_Ash"
  },
  {
   "x": -12,
   "y": 28,
   "z": -5,
   "name": "Plant_Leaves_Ash"
  },
  {
   "x": -12,
   "y": 26,
   "z": -4,
   "name": "Plant_Leaves_Ash"
  },
  {
   "x": -12,
   "y": 27,
   "z": -4,
   "name": "Plant_Leaves_Ash"
  },
  {
   "x": -12,
   "y": 28,
   "z": -4,
   "name": "Plant_Leaves_Ash"
  },
  {
   "x": -12,
   "y": 29,
   "z": -4,
   "name": "Plant_Leaves_Ash"
  },
  {
   "x": -12,
   "y": 12,
   "z": -3,
   "name": "Wood_Ash_Branch_Corner",
   "rotation": 3
  },
  {
   "x": -12,
   "y": 13,
   "z": -3,
   "name": "Wood_Ash_Branch_Corner",
   "rotation": 9
  },
  {
   "x": -12,
   "y": 25,
   "z": -3,
   "name": "Plant_Leaves_Ash"
  },
  {
   "x": -12,
   "y": 26,
   "z": -3,
   "name": "Plant_Leaves_Ash"
  },
  {
   "x": -12,
   "y": 27,
   "z": -3,
   "name": "Plant_Leaves_Ash"
  },
  {
   "x": -12,
   "y": 28,
   "z": -3,
   "name": "Plant_Leaves_Ash"
  },
  {
   "x": -12,
   "y": 29,
   "z": -3,
   "name": "Plant_Leaves_Ash"
  },
  {
   "x": -12,
   "y": 29,
   "z": -2,
   "name": "Plant_Leaves_Ash"
  },
  {
   "x": -12,
   "y": 22,
   "z": -1,
   "name": "Plant_Leaves_Ash"
  },
  {
   "x": -12,
   "y": 29,
   "z": -1,
   "name": "Plant_Vine_Wall",
   "rotation": 3
  },
  {
   "x": -12,
   "y": 3,
   "z": 0,
   "name": "Rock_Stone"
  },
  {
   "x": -12,
   "y": 4,
   "z": 0,
   "name": "Rock_Stone"
  },
  {
   "x": -12,
   "y": 5,
   "z": 0,
   "name": "Rock_Stone"
  },
  {
   "x": -12,
   "y": 6,
   "z": 0,
   "name": "Rock_Stone"
  },
  {
   "x": -12,
   "y": 22,
   "z": 0,
   "name": "Plant_Leaves_Ash"
  },
  {
   "x": -12,
   "y": 23,
   "z": 0,
   "name": "Plant_Leaves_Ash"
  },
  {
   "x": -12,
   "y": 3,
   "z": 1,
   "name": "Rock_Stone"
  },
  {
   "x": -12,
   "y": 4,
   "z": 1,
   "name": "Rock_Stone"
  },
  {
   "x": -12,
   "y": 5,
   "z": 1,
   "name": "Rock_Stone"
  },
  {
   "x": -12,
   "y": 6,
   "z": 1,
   "name": "Rock_Stone"
  },
  {
   "x": -12,
   "y": 23,
   "z": 1,
   "name": "Wood_Ash_Branch_Long",
   "rotation": 5
  },
  {
   "x": -12,
   "y": 24,
   "z": 1,
   "name": "Plant_Leaves_Ash"
  },
  {
   "x": -12,
   "y": 3,
   "z": 2,
   "name": "Rock_Stone"
  },
  {
   "x": -12,
   "y": 4,
   "z": 2,
   "name": "Rock_Stone"
  },
  {
   "x": -12,
   "y": 5,
   "z": 2,
   "name": "Rock_Stone"
  },
  {
   "x": -12,
   "y": 6,
   "z": 2,
   "name": "Rock_Stone"
  },
  {
   "x": -12,
   "y": 22,
   "z": 2,
   "name": "Plant_Leaves_Ash"
  },
  {
   "x": -12,
   "y": 23,
   "z": 2,
   "name": "Plant_Leaves_Ash"
  },
  {
   "x": -12,
   "y": 24,
   "z": 2,
   "name": "Plant_Leaves_Ash"
  },
  {
   "x": -12,
   "y": 27,
   "z": 2,
   "name": "Plant_Leaves_Ash"
  },
  {
   "x": -12,
   "y": 28,
   "z": 2,
   "name": "Plant_Leaves_Ash"
  },
  {
   "x": -12,
   "y": 3,
   "z": 3,
   "name": "Rock_Stone"
  },
  {
   "x": -12,
   "y": 4,
   "z": 3,
   "name": "Rock_Stone"
  },
  {
   "x": -12,
   "y": 5,
   "z": 3,
   "name": "Rock_Stone"
  },
  {
   "x": -12,
   "y": 22,
   "z": 3,
   "name": "Plant_Vine_Hanging"
  },
  {
   "x": -12,
   "y": 23,
   "z": 3,
   "name": "Plant_Leaves_Ash"
  },
  {
   "x": -12,
   "y": 24,
   "z": 3,
   "name": "Plant_Leaves_Ash"
  },
  {
   "x": -12,
   "y": 27,
   "z": 3,
   "name": "Plant_Leaves_Ash"
  },
  {
   "x": -12,
   "y": 28,
   "z": 3,
   "name": "Plant_Leaves_Ash"
  },
  {
   "x": -12,
   "y": 29,
   "z": 3,
   "name": "Plant_Leaves_Ash"
  },
  {
   "x": -12,
   "y": 23,
   "z": 4,
   "name": "Plant_Leaves_Ash"
  },
  {
   "x": -12,
   "y": 25,
   "z": 4,
   "name": "Plant_Leaves_Ash"
  },
  {
   "x": -12,
   "y": 26,
   "z": 4,
   "name": "Plant_Leaves_Ash"
  },
  {
   "x": -12,
   "y": 27,
   "z": 4,
   "name": "Plant_Leaves_Ash"
  },
  {
   "x": -12,
   "y": 28,
   "z": 4,
   "name": "Plant_Leaves_Ash"
  },
  {
   "x": -12,
   "y": 29,
   "z": 4,
   "name": "Plant_Leaves_Ash"
  },
  {
   "x": -12,
   "y": 26,
   "z": 5,
   "name": "Plant_Leaves_Ash"
  },
  {
   "x": -12,
   "y": 27,
   "z": 5,
   "name": "Plant_Leaves_Ash"
  },
  {
   "x": -11,
   "y": 27,
   "z": -5,
   "name": "Plant_Vine_Wall",
   "rotation": 2
  },
  {
   "x": -11,
   "y": 28,
   "z": -5,
   "name": "Plant_Leaves_Ash"
  },
  {
   "x": -11,
   "y": 29,
   "z": -5,
   "name": "Plant_Leaves_Ash"
  },
  {
   "x": -11,
   "y": 3,
   "z": -4,
   "name": "Rock_Stone"
  },
  {
   "x": -11,
   "y": 4,
   "z": -4,
   "name": "Rock_Stone"
  },
  {
   "x": -11,
   "y": 5,
   "z": -4,
   "name": "Rock_Stone"
  },
  {
   "x": -11,
   "y": 26,
   "z": -4,
   "name": "Plant_Vine_Hanging"
  },
  {
   "x": -11,
   "y": 27,
   "z": -4,
   "name": "Plant_Leaves_Ash"
  },
  {
   "x": -11,
   "y": 28,
   "z": -4,
   "name": "Wood_Ash_Trunk_Full"
  },
  {
   "x": -11,
   "y": 29,
   "z": -4,
   "name": "Plant_Leaves_Ash"
  },
  {
   "x": -11,
   "y": 30,
   "z": -4,
   "name": "Plant_Leaves_Ash"
  },
  {
   "x": -11,
   "y": 3,
   "z": -3,
   "name": "Rock_Stone"
  },
  {
   "x": -11,
   "y": 4,
   "z": -3,
   "name": "Rock_Stone"
  },
  {
   "x": -11,
   "y": 5,
   "z": -3,
   "name": "Rock_Stone"
  },
  {
   "x": -11,
   "y": 6,
   "z": -3,
   "name": "Rock_Stone"
  },
  {
   "x": -11,
   "y": 7,
   "z": -3,
   "name": "Rock_Stone"
  },
  {
   "x": -11,
   "y": 12,
   "z": -3,
   "name": "Wood_Ash_Branch_Long",
   "rotation": 5
  },
  {
   "x": -11,
   "y": 13,
   "z": -3,
   "name": "Wood_Ash_Branch_Corner",
   "rotation": 11
  },
  {
   "x": -11,
   "y": 27,
   "z": -3,
   "name": "Wood_Ash_Trunk_Full"
  },
  {
   "x": -11,
   "y": 28,
   "z": -3,
   "name": "Wood_Ash_Trunk_Full"
  },
  {
   "x": -11,
   "y": 29,
   "z": -3,
   "name": "Plant_Leaves_Ash"
  },
  {
   "x": -11,
   "y": 30,
   "z": -3,
   "name": "Plant_Leaves_Ash"
  },
  {
   "x": -11,
   "y": 2,
   "z": -2,
   "name": "Rock_Stone"
  },
  {
   "x": -11,
   "y": 3,
   "z": -2,
   "name": "Rock_Stone"
  },
  {
   "x": -11,
   "y": 4,
   "z": -2,
   "name": "Rock_Stone"
  },
  {
   "x": -11,
   "y": 5,
   "z": -2,
   "name": "Rock_Stone"
  },
  {
   "x": -11,
   "y": 6,
   "z": -2,
   "name": "Rock_Stone"
  },
  {
   "x": -11,
   "y": 7,
   "z": -2,
   "name": "Rock_Stone"
  },
  {
   "x": -11,
   "y": 8,
   "z": -2,
   "name": "Rock_Stone"
  },
  {
   "x": -11,
   "y": 26,
   "z": -2,
   "name": "Wood_Ash_Trunk_Full"
  },
  {
   "x": -11,
   "y": 27,
   "z": -2,
   "name": "Wood_Ash_Trunk_Full"
  },
  {
   "x": -11,
   "y": 28,
   "z": -2,
   "name": "Plant_Leaves_Ash"
  },
  {
   "x": -11,
   "y": 2,
   "z": -1,
   "name": "Rock_Stone"
  },
  {
   "x": -11,
   "y": 3,
   "z": -1,
   "name": "Rock_Stone"
  },
  {
   "x": -11,
   "y": 4,
   "z": -1,
   "name": "Rock_Stone"
  },
  {
   "x": -11,
   "y": 5,
   "z": -1,
   "name": "Rock_Stone"
  },
  {
   "x": -11,
   "y": 6,
   "z": -1,
   "name": "Rock_Stone"
  },
  {
   "x": -11,
   "y": 7,
   "z": -1,
   "name": "Rock_Stone"
  },
  {
   "x": -11,
   "y": 8,
   "z": -1,
   "name": "Rock_Stone"
  },
  {
   "x": -11,
   "y": 26,
   "z": -1,
   "name": "Wood_Ash_Trunk_Full"
  },
  {
   "x": -11,
   "y": 28,
   "z": -1,
   "name": "Plant_Vine_Hanging"
  },
  {
   "x": -11,
   "y": 29,
   "z": -1,
   "name": "Plant_Leaves_Ash"
  },
  {
   "x": -11,
   "y": 30,
   "z": -1,
   "name": "Plant_Leaves_Ash"
  },
  {
   "x": -11,
   "y": 2,
   "z": 0,
   "name": "Rock_Stone"
  },
  {
   "x": -11,
   "y": 3,
   "z": 0,
   "name": "Rock_Stone"
  },
  {
   "x": -11,
   "y": 4,
   "z": 0,
   "name": "Rock_Stone"
  },
  {
   "x": -11,
   "y": 5,
   "z": 0,
   "name": "Rock_Stone"
  },
  {
   "x": -11,
   "y": 6,
   "z": 0,
   "name": "Rock_Stone"
  },
  {
   "x": -11,
   "y": 7,
   "z": 0,
   "name": "Rock_Stone"
  },
  {
   "x": -11,
   "y": 8,
   "z": 0,
   "name": "Rock_Stone"
  },
  {
   "x": -11,
   "y": 28,
   "z": 0,
   "name": "Plant_Leaves_Ash"
  },
  {
   "x": -11,
   "y": 29,
   "z": 0,
   "name": "Plant_Leaves_Ash"
  },
  {
   "x": -11,
   "y": 30,
   "z": 0,
   "name": "Plant_Leaves_Ash"
  },
  {
   "x": -11,
   "y": 1,
   "z": 1,
   "name": "Rock_Stone"
  },
  {
   "x": -11,
   "y": 2,
   "z": 1,
   "name": "Rock_Stone"
  },
  {
   "x": -11,
   "y": 3,
   "z": 1,
   "name": "Rock_Stone"
  },
  {
   "x": -11,
   "y": 4,
   "z": 1,
   "name": "Rock_Stone"
  },
  {
   "x": -11,
   "y": 5,
   "z": 1,
   "name": "Rock_Stone"
  },
  {
   "x": -11,
   "y": 6,
   "z": 1,
   "name": "Rock_Stone"
  },
  {
   "x": -11,
   "y": 7,
   "z": 1,
   "name": "Rock_Stone"
  },
  {
   "x": -11,
   "y": 8,
   "z": 1,
   "name": "Rock_Stone"
  },
  {
   "x": -11,
   "y": 23,
   "z": 1,
   "name": "Wood_Ash_Trunk_Full"
  },
  {
   "x": -11,
   "y": 30,
   "z": 1,
   "name": "Plant_Leaves_Ash"
  },
  {
   "x": -11,
   "y": 2,
   "z": 2,
   "name": "Rock_Stone"
  },
  {
   "x": -11,
   "y": 3,
   "z": 2,
   "name": "Rock_Stone"
  },
  {
   "x": -11,
   "y": 4,
   "z": 2,
   "name": "Rock_Stone"
  },
  {
   "x": -11,
   "y": 5,
   "z": 2,
   "name": "Rock_Stone"
  },
  {
   "x": -11,
   "y": 6,
   "z": 2,
   "name": "Rock_Stone"
  },
  {
   "x": -11,
   "y": 7,
   "z": 2,
   "name": "Rock_Stone"
  },
  {
   "x": -11,
   "y": 8,
   "z": 2,
   "name": "Rock_Stone"
  },
  {
   "x": -11,
   "y": 27,
   "z": 2,
   "name": "Wood_Ash_Trunk_Full"
  },
  {
   "x": -11,
   "y": 1,
   "z": 3,
   "name": "Rock_Stone"
  },
  {
   "x": -11,
   "y": 2,
   "z": 3,
   "name": "Rock_Stone"
  },
  {
   "x": -11,
   "y": 3,
   "z": 3,
   "name": "Rock_Stone"
  },
  {
   "x": -11,
   "y": 4,
   "z": 3,
   "name": "Rock_Stone"
  },
  {
   "x": -11,
   "y": 5,
   "z": 3,
   "name": "Rock_Stone"
  },
  {
   "x": -11,
   "y": 6,
   "z": 3,
   "name": "Rock_Stone"
  },
  {
   "x": -11,
   "y": 7,
   "z": 3,
   "name": "Rock_Stone"
  },
  {
   "x": -11,
   "y": 8,
   "z": 3,
   "name": "Rock_Stone"
  },
  {
   "x": -11,
   "y": 23,
   "z": 3,
   "name": "Plant_Leaves_Ash"
  },
  {
   "x": -11,
   "y": 27,
   "z": 3,
   "name": "Wood_Ash_Trunk_Full"
  },
  {
   "x": -11,
   "y": 28,
   "z": 3,
   "name": "Wood_Ash_Trunk_Full"
  },
  {
   "x": -11,
   "y": 29,
   "z": 3,
   "name": "Plant_Leaves_Ash"
  },
  {
   "x": -11,
   "y": 2,
   "z": 4,
   "name": "Rock_Stone"
  },
  {
   "x": -11,
   "y": 3,
   "z": 4,
   "name": "Rock_Stone"
  },
  {
   "x": -11,
   "y": 4,
   "z": 4,
   "name": "Rock_Stone"
  },
  {
   "x": -11,
   "y": 5,
   "z": 4,
   "name": "Rock_Stone"
  },
  {
   "x": -11,
   "y": 6,
   "z": 4,
   "name": "Rock_Stone"
  },
  {
   "x": -11,
   "y": 7,
   "z": 4,
   "name": "Rock_Stone"
  },
  {
   "x": -11,
   "y": 8,
   "z": 4,
   "name": "Rock_Stone"
  },
  {
   "x": -11,
   "y": 21,
   "z": 4,
   "name": "Plant_Leaves_Ash"
  },
  {
   "x": -11,
   "y": 22,
   "z": 4,
   "name": "Plant_Leaves_Ash"
  },
  {
   "x": -11,
   "y": 23,
   "z": 4,
   "name": "Plant_Leaves_Ash"
  },
  {
   "x": -11,
   "y": 24,
   "z": 4,
   "name": "Plant_Leaves_Ash"
  },
  {
   "x": -11,
   "y": 27,
   "z": 4,
   "name": "Plant_Leaves_Ash"
  },
  {
   "x": -11,
   "y": 28,
   "z": 4,
   "name": "Wood_Ash_Trunk_Full"
  },
  {
   "x": -11,
   "y": 29,
   "z": 4,
   "name": "Plant_Leaves_Ash"
  },
  {
   "x": -11,
   "y": 2,
   "z": 5,
   "name": "Rock_Stone"
  },
  {
   "x": -11,
   "y": 3,
   "z": 5,
   "name": "Rock_Stone"
  },
  {
   "x": -11,
   "y": 4,
   "z": 5,
   "name": "Rock_Stone"
  },
  {
   "x": -11,
   "y": 5,
   "z": 5,
   "name": "Rock_Stone"
  },
  {
   "x": -11,
   "y": 6,
   "z": 5,
   "name": "Rock_Stone"
  },
  {
   "x": -11,
   "y": 7,
   "z": 5,
   "name": "Rock_Stone"
  },
  {
   "x": -11,
   "y": 23,
   "z": 5,
   "name": "Plant_Leaves_Ash"
  },
  {
   "x": -11,
   "y": 27,
   "z": 5,
   "name": "Plant_Leaves_Ash"
  },
  {
   "x": -11,
   "y": 28,
   "z": 5,
   "name": "Plant_Leaves_Ash"
  },
  {
   "x": -10,
   "y": 4,
   "z": -6,
   "name": "Rock_Stone"
  },
  {
   "x": -10,
   "y": 5,
   "z": -6,
   "name": "Rock_Stone"
  },
  {
   "x": -10,
   "y": 28,
   "z": -6,
   "name": "Plant_Vine_Wall",
   "rotation": 3
  },
  {
   "x": -10,
   "y": 2,
   "z": -5,
   "name": "Rock_Stone"
  },
  {
   "x": -10,
   "y": 3,
   "z": -5,
   "name": "Rock_Stone"
  },
  {
   "x": -10,
   "y": 4,
   "z": -5,
   "name": "Rock_Stone"
  },
  {
   "x": -10,
   "y": 5,
   "z": -5,
   "name": "Rock_Stone"
  },
  {
   "x": -10,
   "y": 6,
   "z": -5,
   "name": "Rock_Stone"
  },
  {
   "x": -10,
   "y": 7,
   "z": -5,
   "name": "Rock_Stone"
  },
  {
   "x": -10,
   "y": 8,
   "z": -5,
   "name": "Rock_Stone"
  },
  {
   "x": -10,
   "y": 25,
   "z": -5,
   "name": "Plant_Leaves_Ash"
  },
  {
   "x": -10,
   "y": 26,
   "z": -5,
   "name": "Plant_Leaves_Ash"
  },
  {
   "x": -10,
   "y": 27,
   "z": -5,
   "name": "Plant_Leaves_Ash"
  },
  {
   "x": -10,
   "y": 28,
   "z": -5,
   "name": "Plant_Leaves_Ash"
  },
  {
   "x": -10,
   "y": 29,
   "z": -5,
   "name": "Plant_Leaves_Ash"
  },
  {
   "x": -10,
   "y": 2,
   "z": -4,
   "name": "Rock_Stone"
  },
  {
   "x": -10,
   "y": 3,
   "z": -4,
   "name": "Rock_Stone"
  },
  {
   "x": -10,
   "y": 4,
   "z": -4,
   "name": "Rock_Stone"
  },
  {
   "x": -10,
   "y": 5,
   "z": -4,
   "name": "Rock_Stone"
  },
  {
   "x": -10,
   "y": 6,
   "z": -4,
   "name": "Rock_Stone"
  },
  {
   "x": -10,
   "y": 7,
   "z": -4,
   "name": "Rock_Stone"
  },
  {
   "x": -10,
   "y": 8,
   "z": -4,
   "name": "Rock_Stone"
  },
  {
   "x": -10,
   "y": 26,
   "z": -4,
   "name": "Plant_Leaves_Ash"
  },
  {
   "x": -10,
   "y": 27,
   "z": -4,
   "name": "Plant_Leaves_Ash"
  },
  {
   "x": -10,
   "y": 28,
   "z": -4,
   "name": "Plant_Leaves_Ash"
  },
  {
   "x": -10,
   "y": 29,
   "z": -4,
   "name": "Plant_Leaves_Ash"
  },
  {
   "x": -10,
   "y": 30,
   "z": -4,
   "name": "Plant_Leaves_Ash"
  },
  {
   "x": -10,
   "y": 1,
   "z": -3,
   "name": "Rock_Stone"
  },
  {
   "x": -10,
   "y": 2,
   "z": -3,
   "name": "Rock_Stone"
  },
  {
   "x": -10,
   "y": 3,
   "z": -3,
   "name": "Rock_Stone"
  },
  {
   "x": -10,
   "y": 4,
   "z": -3,
   "name": "Rock_Stone"
  },
  {
   "x": -10,
   "y": 5,
   "z": -3,
   "name": "Rock_Stone"
  },
  {
   "x": -10,
   "y": 6,
   "z": -3,
   "name": "Rock_Stone"
  },
  {
   "x": -10,
   "y": 7,
   "z": -3,
   "name": "Rock_Stone"
  },
  {
   "x": -10,
   "y": 8,
   "z": -3,
   "name": "Rock_Stone"
  },
  {
   "x": -10,
   "y": 9,
   "z": -3,
   "name": "Rock_Stone"
  },
  {
   "x": -10,
   "y": 12,
   "z": -3,
   "name": "Wood_Ash_Branch_Corner",
   "rotation": 1
  },
  {
   "x": -10,
   "y": 13,
   "z": -3,
   "name": "Wood_Ash_Trunk_Full"
  },
  {
   "x": -10,
   "y": 14,
   "z": -3,
   "name": "Wood_Ash_Trunk"
  },
  {
   "x": -10,
   "y": 15,
   "z": -3,
   "name": "Wood_Ash_Trunk"
  },
  {
   "x": -10,
   "y": 16,
   "z": -3,
   "name": "Wood_Ash_Trunk_Full"
  },
  {
   "x": -10,
   "y": 27,
   "z": -3,
   "name": "Plant_Leaves_Ash"
  },
  {
   "x": -10,
   "y": 28,
   "z": -3,
   "name": "Plant_Leaves_Ash"
  },
  {
   "x": -10,
   "y": 29,
   "z": -3,
   "name": "Plant_Leaves_Ash"
  },
  {
   "x": -10,
   "y": 30,
   "z": -3,
   "name": "Plant_Leaves_Ash"
  },
  {
   "x": -10,
   "y": 1,
   "z": -2,
   "name": "Rock_Stone"
  },
  {
   "x": -10,
   "y": 2,
   "z": -2,
   "name": "Rock_Stone"
  },
  {
   "x": -10,
   "y": 3,
   "z": -2,
   "name": "Rock_Stone"
  },
  {
   "x": -10,
   "y": 4,
   "z": -2,
   "name": "Rock_Stone"
  },
  {
   "x": -10,
   "y": 5,
   "z": -2,
   "name": "Rock_Stone"
  },
  {
   "x": -10,
   "y": 6,
   "z": -2,
   "name": "Rock_Stone"
  },
  {
   "x": -10,
   "y": 7,
   "z": -2,
   "name": "Rock_Stone"
  },
  {
   "x": -10,
   "y": 8,
   "z": -2,
   "name": "Rock_Stone"
  },
  {
   "x": -10,
   "y": 9,
   "z": -2,
   "name": "Rock_Stone"
  },
  {
   "x": -10,
   "y": 29,
   "z": -2,
   "name": "Plant_Leaves_Ash"
  },
  {
   "x": -10,
   "y": 1,
   "z": -1,
   "name": "Rock_Stone"
  },
  {
   "x": -10,
   "y": 2,
   "z": -1,
   "name": "Rock_Stone"
  },
  {
   "x": -10,
   "y": 3,
   "z": -1,
   "name": "Rock_Stone"
  },
  {
   "x": -10,
   "y": 4,
   "z": -1,
   "name": "Rock_Stone"
  },
  {
   "x": -10,
   "y": 5,
   "z": -1,
   "name": "Rock_Stone"
  },
  {
   "x": -10,
   "y": 6,
   "z": -1,
   "name": "Rock_Stone"
  },
  {
   "x": -10,
   "y": 7,
   "z": -1,
   "name": "Rock_Stone"
  },
  {
   "x": -10,
   "y": 8,
   "z": -1,
   "name": "Rock_Stone"
  },
  {
   "x": -10,
   "y": 9,
   "z": -1,
   "name": "Rock_Stone"
  },
  {
   "x": -10,
   "y": 26,
   "z": -1,
   "name": "Wood_Ash_Trunk_Full"
  },
  {
   "x": -10,
   "y": 29,
   "z": -1,
   "name": "Plant_Leaves_Ash"
  },
  {
   "x": -10,
   "y": 30,
   "z": -1,
   "name": "Plant_Leaves_Ash"
  },
  {
   "x": -10,
   "y": 1,
   "z": 0,
   "name": "Rock_Stone"
  },
  {
   "x": -10,
   "y": 2,
   "z": 0,
   "name": "Rock_Stone"
  },
  {
   "x": -10,
   "y": 3,
   "z": 0,
   "name": "Rock_Stone"
  },
  {
   "x": -10,
   "y": 4,
   "z": 0,
   "name": "Rock_Stone"
  },
  {
   "x": -10,
   "y": 5,
   "z": 0,
   "name": "Rock_Stone"
  },
  {
   "x": -10,
   "y": 6,
   "z": 0,
   "name": "Rock_Stone"
  },
  {
   "x": -10,
   "y": 7,
   "z": 0,
   "name": "Rock_Stone"
  },
  {
   "x": -10,
   "y": 8,
   "z": 0,
   "name": "Rock_Stone"
  },
  {
   "x": -10,
   "y": 9,
   "z": 0,
   "name": "Rock_Stone"
  },
  {
   "x": -10,
   "y": 23,
   "z": 0,
   "name": "Wood_Ash_Trunk_Full"
  },
  {
   "x": -10,
   "y": 25,
   "z": 0,
   "name": "Wood_Ash_Trunk_Full"
  },
  {
   "x": -10,
   "y": 26,
   "z": 0,
   "name": "Wood_Ash_Trunk"
  },
  {
   "x": -10,
   "y": 27,
   "z": 0,
   "name": "Wood_Ash_Trunk"
  },
  {
   "x": -10,
   "y": 28,
   "z": 0,
   "name": "Wood_Ash_Trunk_Full"
  },
  {
   "x": -10,
   "y": 29,
   "z": 0,
   "name": "Wood_Ash_Trunk_Full"
  },
  {
   "x": -10,
   "y": 30,
   "z": 0,
   "name": "Plant_Leaves_Ash"
  },
  {
   "x": -10,
   "y": 31,
   "z": 0,
   "name": "Plant_Leaves_Ash"
  },
  {
   "x": -10,
   "y": 1,
   "z": 1,
   "name": "Rock_Stone"
  },
  {
   "x": -10,
   "y": 2,
   "z": 1,
   "name": "Rock_Stone"
  },
  {
   "x": -10,
   "y": 3,
   "z": 1,
   "name": "Rock_Stone"
  },
  {
   "x": -10,
   "y": 4,
   "z": 1,
   "name": "Rock_Stone"
  },
  {
   "x": -10,
   "y": 5,
   "z": 1,
   "name": "Rock_Stone"
  },
  {
   "x": -10,
   "y": 6,
   "z": 1,
   "name": "Rock_Stone"
  },
  {
   "x": -10,
   "y": 7,
   "z": 1,
   "name": "Rock_Stone"
  },
  {
   "x": -10,
   "y": 8,
   "z": 1,
   "name": "Rock_Stone"
  },
  {
   "x": -10,
   "y": 9,
   "z": 1,
   "name": "Soil_Gravel"
  },
  {
   "x": -10,
   "y": 23,
   "z": 1,
   "name": "Wood_Ash_Trunk_Full"
  },
  {
   "x": -10,
   "y": 27,
   "z": 1,
   "name": "Wood_Ash_Trunk_Full"
  },
  {
   "x": -10,
   "y": 28,
   "z": 1,
   "name": "Plant_Leaves_Ash"
  },
  {
   "x": -10,
   "y": 29,
   "z": 1,
   "name": "Plant_Leaves_Ash"
  },
  {
   "x": -10,
   "y": 30,
   "z": 1,
   "name": "Plant_Leaves_Ash"
  },
  {
   "x": -10,
   "y": 31,
   "z": 1,
   "name": "Plant_Leaves_Ash"
  },
  {
   "x": -10,
   "y": 0,
   "z": 2,
   "name": "Rock_Stone"
  },
  {
   "x": -10,
   "y": 1,
   "z": 2,
   "name": "Rock_Stone"
  },
  {
   "x": -10,
   "y": 2,
   "z": 2,
   "name": "Rock_Stone"
  },
  {
   "x": -10,
   "y": 3,
   "z": 2,
   "name": "Rock_Stone"
  },
  {
   "x": -10,
   "y": 4,
   "z": 2,
   "name": "Rock_Stone"
  },
  {
   "x": -10,
   "y": 5,
   "z": 2,
   "name": "Rock_Stone"
  },
  {
   "x": -10,
   "y": 6,
   "z": 2,
   "name": "Rock_Stone"
  },
  {
   "x": -10,
   "y": 7,
   "z": 2,
   "name": "Rock_Stone"
  },
  {
   "x": -10,
   "y": 8,
   "z": 2,
   "name": "Soil_Gravel"
  },
  {
   "x": -10,
   "y": 9,
   "z": 2,
   "name": "Soil_Gravel"
  },
  {
   "x": -10,
   "y": 23,
   "z": 2,
   "name": "Wood_Ash_Trunk_Full"
  },
  {
   "x": -10,
   "y": 27,
   "z": 2,
   "name": "Wood_Ash_Trunk_Full"
  },
  {
   "x": -10,
   "y": 29,
   "z": 2,
   "name": "Plant_Leaves_Ash"
  },
  {
   "x": -10,
   "y": 30,
   "z": 2,
   "name": "Plant_Leaves_Ash"
  },
  {
   "x": -10,
   "y": 0,
   "z": 3,
   "name": "Rock_Stone"
  },
  {
   "x": -10,
   "y": 1,
   "z": 3,
   "name": "Rock_Stone"
  },
  {
   "x": -10,
   "y": 2,
   "z": 3,
   "name": "Rock_Stone"
  },
  {
   "x": -10,
   "y": 3,
   "z": 3,
   "name": "Rock_Stone"
  },
  {
   "x": -10,
   "y": 4,
   "z": 3,
   "name": "Rock_Stone"
  },
  {
   "x": -10,
   "y": 5,
   "z": 3,
   "name": "Rock_Stone"
  },
  {
   "x": -10,
   "y": 6,
   "z": 3,
   "name": "Rock_Stone"
  },
  {
   "x": -10,
   "y": 7,
   "z": 3,
   "name": "Rock_Stone"
  },
  {
   "x": -10,
   "y": 8,
   "z": 3,
   "name": "Rock_Stone"
  },
  {
   "x": -10,
   "y": 9,
   "z": 3,
   "name": "Soil_Gravel"
  },
  {
   "x": -10,
   "y": 23,
   "z": 3,
   "name": "Wood_Ash_Branch_Long",
   "rotation": 4
  },
  {
   "x": -10,
   "y": 24,
   "z": 3,
   "name": "Plant_Leaves_Ash"
  },
  {
   "x": -10,
   "y": 1,
   "z": 4,
   "name": "Rock_Stone"
  },
  {
   "x": -10,
   "y": 2,
   "z": 4,
   "name": "Rock_Stone"
  },
  {
   "x": -10,
   "y": 3,
   "z": 4,
   "name": "Rock_Stone"
  },
  {
   "x": -10,
   "y": 4,
   "z": 4,
   "name": "Rock_Stone"
  },
  {
   "x": -10,
   "y": 5,
   "z": 4,
   "name": "Rock_Stone"
  },
  {
   "x": -10,
   "y": 6,
   "z": 4,
   "name": "Rock_Stone"
  },
  {
   "x": -10,
   "y": 7,
   "z": 4,
   "name": "Rock_Stone"
  },
  {
   "x": -10,
   "y": 8,
   "z": 4,
   "name": "Rock_Stone"
  },
  {
   "x": -10,
   "y": 9,
   "z": 4,
   "name": "Rock_Stone"
  },
  {
   "x": -10,
   "y": 21,
   "z": 4,
   "name": "Plant_Vine_Hanging"
  },
  {
   "x": -10,
   "y": 22,
   "z": 4,
   "name": "Plant_Leaves_Ash"
  },
  {
   "x": -10,
   "y": 23,
   "z": 4,
   "name": "Wood_Ash_Branch_Long",
   "rotation": 4
  },
  {
   "x": -10,
   "y": 24,
   "z": 4,
   "name": "Plant_Leaves_Ash"
  },
  {
   "x": -10,
   "y": 28,
   "z": 4,
   "name": "Plant_Leaves_Ash"
  },
  {
   "x": -10,
   "y": 1,
   "z": 5,
   "name": "Rock_Stone"
  },
  {
   "x": -10,
   "y": 2,
   "z": 5,
   "name": "Rock_Stone"
  },
  {
   "x": -10,
   "y": 3,
   "z": 5,
   "name": "Rock_Stone"
  },
  {
   "x": -10,
   "y": 4,
   "z": 5,
   "name": "Rock_Stone"
  },
  {
   "x": -10,
   "y": 5,
   "z": 5,
   "name": "Rock_Stone"
  },
  {
   "x": -10,
   "y": 6,
   "z": 5,
   "name": "Rock_Stone"
  },
  {
   "x": -10,
   "y": 7,
   "z": 5,
   "name": "Rock_Stone"
  },
  {
   "x": -10,
   "y": 8,
   "z": 5,
   "name": "Rock_Stone"
  },
  {
   "x": -10,
   "y": 22,
   "z": 5,
   "name": "Plant_Leaves_Ash"
  },
  {
   "x": -10,
   "y": 23,
   "z": 5,
   "name": "Plant_Leaves_Ash"
  },
  {
   "x": -10,
   "y": 24,
   "z": 5,
   "name": "Plant_Leaves_Ash"
  },
  {
   "x": -10,
   "y": 27,
   "z": 5,
   "name": "Plant_Leaves_Ash"
  },
  {
   "x": -10,
   "y": 28,
   "z": 5,
   "name": "Plant_Leaves_Ash"
  },
  {
   "x": -10,
   "y": 29,
   "z": 5,
   "name": "Plant_Leaves_Ash"
  },
  {
   "x": -10,
   "y": 2,
   "z": 6,
   "name": "Rock_Stone"
  },
  {
   "x": -10,
   "y": 3,
   "z": 6,
   "name": "Rock_Stone"
  },
  {
   "x": -10,
   "y": 4,
   "z": 6,
   "name": "Rock_Stone"
  },
  {
   "x": -10,
   "y": 5,
   "z": 6,
   "name": "Rock_Stone"
  },
  {
   "x": -10,
   "y": 6,
   "z": 6,
   "name": "Rock_Stone"
  },
  {
   "x": -10,
   "y": 7,
   "z": 6,
   "name": "Rock_Stone"
  },
  {
   "x": -10,
   "y": 8,
   "z": 6,
   "name": "Rock_Stone"
  },
  {
   "x": -10,
   "y": 3,
   "z": 7,
   "name": "Rock_Stone"
  },
  {
   "x": -10,
   "y": 4,
   "z": 7,
   "name": "Rock_Stone"
  },
  {
   "x": -10,
   "y": 5,
   "z": 7,
   "name": "Rock_Stone"
  },
  {
   "x": -10,
   "y": 6,
   "z": 7,
   "name": "Rock_Stone"
  },
  {
   "x": -9,
   "y": 24,
   "z": -9,
   "name": "Plant_Vine_Wall",
   "rotation": 3
  },
  {
   "x": -9,
   "y": 25,
   "z": -8,
   "name": "Plant_Vine_Wall",
   "rotation": 3
  },
  {
   "x": -9,
   "y": 4,
   "z": -7,
   "name": "Rock_Stone"
  },
  {
   "x": -9,
   "y": 5,
   "z": -7,
   "name": "Rock_Stone"
  },
  {
   "x": -9,
   "y": 6,
   "z": -7,
   "name": "Rock_Stone"
  },
  {
   "x": -9,
   "y": 7,
   "z": -7,
   "name": "Rock_Stone"
  },
  {
   "x": -9,
   "y": 28,
   "z": -7,
   "name": "Plant_Vine_Wall",
   "rotation": 2
  },
  {
   "x": -9,
   "y": 2,
   "z": -6,
   "name": "Rock_Stone"
  },
  {
   "x": -9,
   "y": 3,
   "z": -6,
   "name": "Rock_Stone"
  },
  {
   "x": -9,
   "y": 4,
   "z": -6,
   "name": "Rock_Stone"
  },
  {
   "x": -9,
   "y": 5,
   "z": -6,
   "name": "Rock_Stone"
  },
  {
   "x": -9,
   "y": 6,
   "z": -6,
   "name": "Rock_Stone"
  },
  {
   "x": -9,
   "y": 7,
   "z": -6,
   "name": "Rock_Stone"
  },
  {
   "x": -9,
   "y": 8,
   "z": -6,
   "name": "Rock_Stone"
  },
  {
   "x": -9,
   "y": 27,
   "z": -6,
   "name": "Plant_Vine_Hanging"
  },
  {
   "x": -9,
   "y": 28,
   "z": -6,
   "name": "Plant_Leaves_Ash"
  },
  {
   "x": -9,
   "y": 1,
   "z": -5,
   "name": "Rock_Stone"
  },
  {
   "x": -9,
   "y": 2,
   "z": -5,
   "name": "Rock_Stone"
  },
  {
   "x": -9,
   "y": 3,
   "z": -5,
   "name": "Rock_Stone"
  },
  {
   "x": -9,
   "y": 4,
   "z": -5,
   "name": "Rock_Stone"
  },
  {
   "x": -9,
   "y": 5,
   "z": -5,
   "name": "Rock_Stone"
  },
  {
   "x": -9,
   "y": 6,
   "z": -5,
   "name": "Rock_Stone"
  },
  {
   "x": -9,
   "y": 7,
   "z": -5,
   "name": "Rock_Stone"
  },
  {
   "x": -9,
   "y": 8,
   "z": -5,
   "name": "Rock_Stone"
  },
  {
   "x": -9,
   "y": 9,
   "z": -5,
   "name": "Rock_Stone"
  },
  {
   "x": -9,
   "y": 28,
   "z": -5,
   "name": "Plant_Leaves_Ash"
  },
  {
   "x": -9,
   "y": 29,
   "z": -5,
   "name": "Plant_Leaves_Ash"
  },
  {
   "x": -9,
   "y": 1,
   "z": -4,
   "name": "Rock_Stone"
  },
  {
   "x": -9,
   "y": 2,
   "z": -4,
   "name": "Rock_Stone"
  },
  {
   "x": -9,
   "y": 3,
   "z": -4,
   "name": "Rock_Stone"
  },
  {
   "x": -9,
   "y": 4,
   "z": -4,
   "name": "Rock_Stone"
  },
  {
   "x": -9,
   "y": 5,
   "z": -4,
   "name": "Rock_Stone"
  },
  {
   "x": -9,
   "y": 6,
   "z": -4,
   "name": "Rock_Stone"
  },
  {
   "x": -9,
   "y": 7,
   "z": -4,
   "name": "Rock_Stone"
  },
  {
   "x": -9,
   "y": 8,
   "z": -4,
   "name": "Rock_Stone"
  },
  {
   "x": -9,
   "y": 9,
   "z": -4,
   "name": "Rock_Stone"
  },
  {
   "x": -9,
   "y": 10,
   "z": -4,
   "name": "Rock_Stone"
  },
  {
   "x": -9,
   "y": 28,
   "z": -4,
   "name": "Plant_Leaves_Ash"
  },
  {
   "x": -9,
   "y": 29,
   "z": -4,
   "name": "Plant_Leaves_Ash"
  },
  {
   "x": -9,
   "y": 30,
   "z": -4,
   "name": "Plant_Leaves_Ash"
  },
  {
   "x": -9,
   "y": 1,
   "z": -3,
   "name": "Rock_Stone"
  },
  {
   "x": -9,
   "y": 2,
   "z": -3,
   "name": "Rock_Stone"
  },
  {
   "x": -9,
   "y": 3,
   "z": -3,
   "name": "Rock_Stone"
  },
  {
   "x": -9,
   "y": 4,
   "z": -3,
   "name": "Rock_Stone"
  },
  {
   "x": -9,
   "y": 5,
   "z": -3,
   "name": "Rock_Stone"
  },
  {
   "x": -9,
   "y": 6,
   "z": -3,
   "name": "Rock_Stone"
  },
  {
   "x": -9,
   "y": 7,
   "z": -3,
   "name": "Rock_Stone"
  },
  {
   "x": -9,
   "y": 8,
   "z": -3,
   "name": "Rock_Stone"
  },
  {
   "x": -9,
   "y": 9,
   "z": -3,
   "name": "Rock_Stone"
  },
  {
   "x": -9,
   "y": 10,
   "z": -3,
   "name": "Soil_Gravel"
  },
  {
   "x": -9,
   "y": 11,
   "z": -3,
   "name": "Wood_Ash_Roots"
  },
  {
   "x": -9,
   "y": 12,
   "z": -3,
   "name": "Wood_Ash_Trunk_Full"
  },
  {
   "x": -9,
   "y": 13,
   "z": -3,
   "name": "Wood_Ash_Trunk_Full"
  },
  {
   "x": -9,
   "y": 16,
   "z": -3,
   "name": "Wood_Ash_Trunk_Full"
  },
  {
   "x": -9,
   "y": 17,
   "z": -3,
   "name": "Wood_Ash_Trunk_Full"
  },
  {
   "x": -9,
   "y": 19,
   "z": -3,
   "name": "Plant_Vine_Liana",
   "rotation": 3
  },
  {
   "x": -9,
   "y": 21,
   "z": -3,
   "name": "Plant_Crop_Mushroom_Shelve_Green"
  },
  {
   "x": -9,
   "y": 28,
   "z": -3,
   "name": "Plant_Leaves_Ash"
  },
  {
   "x": -9,
   "y": 29,
   "z": -3,
   "name": "Plant_Leaves_Ash"
  },
  {
   "x": -9,
   "y": 30,
   "z": -3,
   "name": "Plant_Leaves_Ash"
  },
  {
   "x": -9,
   "y": 0,
   "z": -2,
   "name": "Rock_Stone"
  },
  {
   "x": -9,
   "y": 1,
   "z": -2,
   "name": "Rock_Stone"
  },
  {
   "x": -9,
   "y": 2,
   "z": -2,
   "name": "Rock_Stone"
  },
  {
   "x": -9,
   "y": 3,
   "z": -2,
   "name": "Rock_Stone"
  },
  {
   "x": -9,
   "y": 4,
   "z": -2,
   "name": "Rock_Stone"
  },
  {
   "x": -9,
   "y": 5,
   "z": -2,
   "name": "Rock_Stone"
  },
  {
   "x": -9,
   "y": 6,
   "z": -2,
   "name": "Rock_Stone"
  },
  {
   "x": -9,
   "y": 7,
   "z": -2,
   "name": "Rock_Stone"
  },
  {
   "x": -9,
   "y": 8,
   "z": -2,
   "name": "Rock_Stone"
  },
  {
   "x": -9,
   "y": 9,
   "z": -2,
   "name": "Soil_Gravel"
  },
  {
   "x": -9,
   "y": 10,
   "z": -2,
   "name": "Soil_Gravel"
  },
  {
   "x": -9,
   "y": 11,
   "z": -2,
   "name": "Rock_Stone"
  },
  {
   "x": -9,
   "y": 19,
   "z": -2,
   "name": "Plant_Vine_Wall",
   "rotation": 3
  },
  {
   "x": -9,
   "y": 20,
   "z": -2,
   "name": "Wood_Ash_Trunk_Full"
  },
  {
   "x": -9,
   "y": 21,
   "z": -2,
   "name": "Wood_Ash_Trunk_Full"
  },
  {
   "x": -9,
   "y": 22,
   "z": -2,
   "name": "Plant_Crop_Mushroom_Shelve_Green"
  },
  {
   "x": -9,
   "y": 29,
   "z": -2,
   "name": "Plant_Leaves_Ash"
  },
  {
   "x": -9,
   "y": 30,
   "z": -2,
   "name": "Plant_Leaves_Ash"
  },
  {
   "x": -9,
   "y": 0,
   "z": -1,
   "name": "Rock_Stone"
  },
  {
   "x": -9,
   "y": 1,
   "z": -1,
   "name": "Rock_Stone"
  },
  {
   "x": -9,
   "y": 2,
   "z": -1,
   "name": "Rock_Stone"
  },
  {
   "x": -9,
   "y": 3,
   "z": -1,
   "name": "Rock_Stone"
  },
  {
   "x": -9,
   "y": 4,
   "z": -1,
   "name": "Rock_Stone"
  },
  {
   "x": -9,
   "y": 5,
   "z": -1,
   "name": "Rock_Stone"
  },
  {
   "x": -9,
   "y": 6,
   "z": -1,
   "name": "Rock_Stone"
  },
  {
   "x": -9,
   "y": 7,
   "z": -1,
   "name": "Rock_Stone"
  },
  {
   "x": -9,
   "y": 8,
   "z": -1,
   "name": "Rock_Stone"
  },
  {
   "x": -9,
   "y": 9,
   "z": -1,
   "name": "Soil_Gravel"
  },
  {
   "x": -9,
   "y": 10,
   "z": -1,
   "name": "Soil_Gravel"
  },
  {
   "x": -9,
   "y": 11,
   "z": -1,
   "name": "Rock_Stone"
  },
  {
   "x": -9,
   "y": 21,
   "z": -1,
   "name": "Wood_Ash_Trunk_Full"
  },
  {
   "x": -9,
   "y": 22,
   "z": -1,
   "name": "Wood_Ash_Trunk"
  },
  {
   "x": -9,
   "y": 23,
   "z": -1,
   "name": "Wood_Ash_Trunk_Full"
  },
  {
   "x": -9,
   "y": 30,
   "z": -1,
   "name": "Plant_Leaves_Ash"
  },
  {
   "x": -9,
   "y": 31,
   "z": -1,
   "name": "Plant_Leaves_Ash"
  },
  {
   "x": -9,
   "y": 32,
   "z": -1,
   "name": "Plant_Leaves_Ash"
  },
  {
   "x": -9,
   "y": 0,
   "z": 0,
   "name": "Rock_Stone"
  },
  {
   "x": -9,
   "y": 1,
   "z": 0,
   "name": "Rock_Stone"
  },
  {
   "x": -9,
   "y": 2,
   "z": 0,
   "name": "Rock_Stone"
  },
  {
   "x": -9,
   "y": 3,
   "z": 0,
   "name": "Rock_Stone"
  },
  {
   "x": -9,
   "y": 4,
   "z": 0,
   "name": "Rock_Stone"
  },
  {
   "x": -9,
   "y": 5,
   "z": 0,
   "name": "Rock_Stone"
  },
  {
   "x": -9,
   "y": 6,
   "z": 0,
   "name": "Rock_Stone"
  },
  {
   "x": -9,
   "y": 7,
   "z": 0,
   "name": "Rock_Stone"
  },
  {
   "x": -9,
   "y": 8,
   "z": 0,
   "name": "Rock_Stone"
  },
  {
   "x": -9,
   "y": 9,
   "z": 0,
   "name": "Rock_Stone"
  },
  {
   "x": -9,
   "y": 10,
   "z": 0,
   "name": "Soil_Gravel"
  },
  {
   "x": -9,
   "y": 11,
   "z": 0,
   "name": "Rock_Stone"
  },
  {
   "x": -9,
   "y": 23,
   "z": 0,
   "name": "Wood_Ash_Trunk_Full"
  },
  {
   "x": -9,
   "y": 24,
   "z": 0,
   "name": "Wood_Ash_Trunk"
  },
  {
   "x": -9,
   "y": 25,
   "z": 0,
   "name": "Wood_Ash_Trunk_Full"
  },
  {
   "x": -9,
   "y": 29,
   "z": 0,
   "name": "Wood_Ash_Trunk_Full"
  },
  {
   "x": -9,
   "y": 30,
   "z": 0,
   "name": "Wood_Ash_Branch_Long"
  },
  {
   "x": -9,
   "y": 31,
   "z": 0,
   "name": "Wood_Ash_Branch_Long"
  },
  {
   "x": -9,
   "y": 32,
   "z": 0,
   "name": "Plant_Leaves_Ash"
  },
  {
   "x": -9,
   "y": 0,
   "z": 1,
   "name": "Rock_Stone"
  },
  {
   "x": -9,
   "y": 1,
   "z": 1,
   "name": "Rock_Stone"
  },
  {
   "x": -9,
   "y": 2,
   "z": 1,
   "name": "Rock_Stone"
  },
  {
   "x": -9,
   "y": 3,
   "z": 1,
   "name": "Rock_Stone"
  },
  {
   "x": -9,
   "y": 4,
   "z": 1,
   "name": "Rock_Stone"
  },
  {
   "x": -9,
   "y": 5,
   "z": 1,
   "name": "Rock_Stone"
  },
  {
   "x": -9,
   "y": 6,
   "z": 1,
   "name": "Rock_Stone"
  },
  {
   "x": -9,
   "y": 7,
   "z": 1,
   "name": "Rock_Stone"
  },
  {
   "x": -9,
   "y": 8,
   "z": 1,
   "name": "Rock_Stone"
  },
  {
   "x": -9,
   "y": 9,
   "z": 1,
   "name": "Rock_Stone"
  },
  {
   "x": -9,
   "y": 10,
   "z": 1,
   "name": "Rock_Stone"
  },
  {
   "x": -9,
   "y": 30,
   "z": 1,
   "name": "Plant_Leaves_Ash"
  },
  {
   "x": -9,
   "y": 31,
   "z": 1,
   "name": "Plant_Leaves_Ash"
  },
  {
   "x": -9,
   "y": 32,
   "z": 1,
   "name": "Plant_Leaves_Ash"
  },
  {
   "x": -9,
   "y": 0,
   "z": 2,
   "name": "Rock_Stone"
  },
  {
   "x": -9,
   "y": 1,
   "z": 2,
   "name": "Rock_Stone"
  },
  {
   "x": -9,
   "y": 2,
   "z": 2,
   "name": "Rock_Stone"
  },
  {
   "x": -9,
   "y": 3,
   "z": 2,
   "name": "Rock_Stone"
  },
  {
   "x": -9,
   "y": 4,
   "z": 2,
   "name": "Rock_Stone"
  },
  {
   "x": -9,
   "y": 5,
   "z": 2,
   "name": "Rock_Stone"
  },
  {
   "x": -9,
   "y": 6,
   "z": 2,
   "name": "Rock_Stone"
  },
  {
   "x": -9,
   "y": 7,
   "z": 2,
   "name": "Rock_Stone"
  },
  {
   "x": -9,
   "y": 8,
   "z": 2,
   "name": "Rock_Stone"
  },
  {
   "x": -9,
   "y": 9,
   "z": 2,
   "name": "Soil_Gravel"
  },
  {
   "x": -9,
   "y": 10,
   "z": 2,
   "name": "Soil_Gravel"
  },
  {
   "x": -9,
   "y": 29,
   "z": 2,
   "name": "Plant_Vine_Hanging"
  },
  {
   "x": -9,
   "y": 30,
   "z": 2,
   "name": "Plant_Leaves_Ash"
  },
  {
   "x": -9,
   "y": 31,
   "z": 2,
   "name": "Plant_Leaves_Ash"
  },
  {
   "x": -9,
   "y": 0,
   "z": 3,
   "name": "Rock_Stone"
  },
  {
   "x": -9,
   "y": 1,
   "z": 3,
   "name": "Rock_Stone"
  },
  {
   "x": -9,
   "y": 2,
   "z": 3,
   "name": "Rock_Stone"
  },
  {
   "x": -9,
   "y": 3,
   "z": 3,
   "name": "Rock_Stone"
  },
  {
   "x": -9,
   "y": 4,
   "z": 3,
   "name": "Rock_Stone"
  },
  {
   "x": -9,
   "y": 5,
   "z": 3,
   "name": "Rock_Stone"
  },
  {
   "x": -9,
   "y": 6,
   "z": 3,
   "name": "Rock_Stone"
  },
  {
   "x": -9,
   "y": 7,
   "z": 3,
   "name": "Rock_Stone"
  },
  {
   "x": -9,
   "y": 8,
   "z": 3,
   "name": "Rock_Stone"
  },
  {
   "x": -9,
   "y": 9,
   "z": 3,
   "name": "Soil_Gravel"
  },
  {
   "x": -9,
   "y": 10,
   "z": 3,
   "name": "Soil_Gravel"
  },
  {
   "x": -9,
   "y": 30,
   "z": 3,
   "name": "Plant_Leaves_Ash"
  },
  {
   "x": -9,
   "y": 31,
   "z": 3,
   "name": "Plant_Leaves_Ash"
  },
  {
   "x": -9,
   "y": 0,
   "z": 4,
   "name": "Rock_Stone"
  },
  {
   "x": -9,
   "y": 1,
   "z": 4,
   "name": "Rock_Stone"
  },
  {
   "x": -9,
   "y": 2,
   "z": 4,
   "name": "Rock_Stone"
  },
  {
   "x": -9,
   "y": 3,
   "z": 4,
   "name": "Rock_Stone"
  },
  {
   "x": -9,
   "y": 4,
   "z": 4,
   "name": "Rock_Stone"
  },
  {
   "x": -9,
   "y": 5,
   "z": 4,
   "name": "Rock_Stone"
  },
  {
   "x": -9,
   "y": 6,
   "z": 4,
   "name": "Rock_Stone"
  },
  {
   "x": -9,
   "y": 7,
   "z": 4,
   "name": "Rock_Stone"
  },
  {
   "x": -9,
   "y": 8,
   "z": 4,
   "name": "Rock_Stone"
  },
  {
   "x": -9,
   "y": 9,
   "z": 4,
   "name": "Soil_Gravel"
  },
  {
   "x": -9,
   "y": 10,
   "z": 4,
   "name": "Soil_Gravel"
  },
  {
   "x": -9,
   "y": 22,
   "z": 4,
   "name": "Plant_Leaves_Ash"
  },
  {
   "x": -9,
   "y": 23,
   "z": 4,
   "name": "Plant_Leaves_Ash"
  },
  {
   "x": -9,
   "y": 24,
   "z": 4,
   "name": "Plant_Leaves_Ash"
  },
  {
   "x": -9,
   "y": 30,
   "z": 4,
   "name": "Plant_Leaves_Ash"
  },
  {
   "x": -9,
   "y": 1,
   "z": 5,
   "name": "Rock_Stone"
  },
  {
   "x": -9,
   "y": 2,
   "z": 5,
   "name": "Rock_Stone"
  },
  {
   "x": -9,
   "y": 3,
   "z": 5,
   "name": "Rock_Stone"
  },
  {
   "x": -9,
   "y": 4,
   "z": 5,
   "name": "Rock_Stone"
  },
  {
   "x": -9,
   "y": 5,
   "z": 5,
   "name": "Rock_Stone"
  },
  {
   "x": -9,
   "y": 6,
   "z": 5,
   "name": "Rock_Stone"
  },
  {
   "x": -9,
   "y": 7,
   "z": 5,
   "name": "Rock_Stone"
  },
  {
   "x": -9,
   "y": 8,
   "z": 5,
   "name": "Rock_Stone"
  },
  {
   "x": -9,
   "y": 9,
   "z": 5,
   "name": "Rock_Stone"
  },
  {
   "x": -9,
   "y": 10,
   "z": 5,
   "name": "Soil_Gravel"
  },
  {
   "x": -9,
   "y": 23,
   "z": 5,
   "name": "Plant_Leaves_Ash"
  },
  {
   "x": -9,
   "y": 1,
   "z": 6,
   "name": "Rock_Stone"
  },
  {
   "x": -9,
   "y": 2,
   "z": 6,
   "name": "Rock_Stone"
  },
  {
   "x": -9,
   "y": 3,
   "z": 6,
   "name": "Rock_Stone"
  },
  {
   "x": -9,
   "y": 4,
   "z": 6,
   "name": "Rock_Stone"
  },
  {
   "x": -9,
   "y": 5,
   "z": 6,
   "name": "Rock_Stone"
  },
  {
   "x": -9,
   "y": 6,
   "z": 6,
   "name": "Rock_Stone"
  },
  {
   "x": -9,
   "y": 7,
   "z": 6,
   "name": "Rock_Stone"
  },
  {
   "x": -9,
   "y": 8,
   "z": 6,
   "name": "Rock_Stone"
  },
  {
   "x": -9,
   "y": 9,
   "z": 6,
   "name": "Rock_Stone"
  },
  {
   "x": -9,
   "y": 1,
   "z": 7,
   "name": "Rock_Stone"
  },
  {
   "x": -9,
   "y": 2,
   "z": 7,
   "name": "Rock_Stone"
  },
  {
   "x": -9,
   "y": 3,
   "z": 7,
   "name": "Rock_Stone"
  },
  {
   "x": -9,
   "y": 4,
   "z": 7,
   "name": "Rock_Stone"
  },
  {
   "x": -9,
   "y": 5,
   "z": 7,
   "name": "Rock_Stone"
  },
  {
   "x": -9,
   "y": 6,
   "z": 7,
   "name": "Rock_Stone"
  },
  {
   "x": -9,
   "y": 7,
   "z": 7,
   "name": "Rock_Stone"
  },
  {
   "x": -9,
   "y": 8,
   "z": 7,
   "name": "Rock_Stone"
  },
  {
   "x": -9,
   "y": 9,
   "z": 7,
   "name": "Rock_Stone"
  },
  {
   "x": -9,
   "y": 2,
   "z": 8,
   "name": "Rock_Stone"
  },
  {
   "x": -9,
   "y": 3,
   "z": 8,
   "name": "Rock_Stone"
  },
  {
   "x": -9,
   "y": 4,
   "z": 8,
   "name": "Rock_Stone"
  },
  {
   "x": -9,
   "y": 5,
   "z": 8,
   "name": "Rock_Stone"
  },
  {
   "x": -9,
   "y": 6,
   "z": 8,
   "name": "Rock_Stone"
  },
  {
   "x": -9,
   "y": 7,
   "z": 8,
   "name": "Rock_Stone"
  },
  {
   "x": -9,
   "y": 8,
   "z": 8,
   "name": "Rock_Stone"
  },
  {
   "x": -9,
   "y": 3,
   "z": 9,
   "name": "Rock_Stone"
  },
  {
   "x": -9,
   "y": 4,
   "z": 9,
   "name": "Rock_Stone"
  },
  {
   "x": -8,
   "y": 24,
   "z": -10,
   "name": "Plant_Vine_Wall",
   "rotation": 2
  },
  {
   "x": -8,
   "y": 23,
   "z": -9,
   "name": "Plant_Vine_Hanging"
  },
  {
   "x": -8,
   "y": 24,
   "z": -9,
   "name": "Plant_Leaves_Ash"
  },
  {
   "x": -8,
   "y": 4,
   "z": -8,
   "name": "Rock_Stone"
  },
  {
   "x": -8,
   "y": 5,
   "z": -8,
   "name": "Rock_Stone"
  },
  {
   "x": -8,
   "y": 6,
   "z": -8,
   "name": "Rock_Stone"
  },
  {
   "x": -8,
   "y": 7,
   "z": -8,
   "name": "Rock_Stone"
  },
  {
   "x": -8,
   "y": 8,
   "z": -8,
   "name": "Rock_Stone"
  },
  {
   "x": -8,
   "y": 24,
   "z": -8,
   "name": "Plant_Vine_Hanging"
  },
  {
   "x": -8,
   "y": 25,
   "z": -8,
   "name": "Plant_Leaves_Ash"
  },
  {
   "x": -8,
   "y": 2,
   "z": -7,
   "name": "Rock_Stone"
  },
  {
   "x": -8,
   "y": 3,
   "z": -7,
   "name": "Rock_Stone"
  },
  {
   "x": -8,
   "y": 4,
   "z": -7,
   "name": "Rock_Stone"
  },
  {
   "x": -8,
   "y": 5,
   "z": -7,
   "name": "Rock_Stone"
  },
  {
   "x": -8,
   "y": 6,
   "z": -7,
   "name": "Rock_Stone"
  },
  {
   "x": -8,
   "y": 7,
   "z": -7,
   "name": "Rock_Stone"
  },
  {
   "x": -8,
   "y": 8,
   "z": -7,
   "name": "Rock_Stone"
  },
  {
   "x": -8,
   "y": 9,
   "z": -7,
   "name": "Rock_Stone"
  },
  {
   "x": -8,
   "y": 25,
   "z": -7,
   "name": "Plant_Leaves_Ash"
  },
  {
   "x": -8,
   "y": 28,
   "z": -7,
   "name": "Plant_Leaves_Ash"
  },
  {
   "x": -8,
   "y": 1,
   "z": -6,
   "name": "Rock_Stone"
  },
  {
   "x": -8,
   "y": 2,
   "z": -6,
   "name": "Rock_Stone"
  },
  {
   "x": -8,
   "y": 3,
   "z": -6,
   "name": "Rock_Stone"
  },
  {
   "x": -8,
   "y": 4,
   "z": -6,
   "name": "Rock_Stone"
  },
  {
   "x": -8,
   "y": 5,
   "z": -6,
   "name": "Rock_Stone"
  },
  {
   "x": -8,
   "y": 6,
   "z": -6,
   "name": "Rock_Stone"
  },
  {
   "x": -8,
   "y": 7,
   "z": -6,
   "name": "Rock_Stone"
  },
  {
   "x": -8,
   "y": 8,
   "z": -6,
   "name": "Rock_Stone"
  },
  {
   "x": -8,
   "y": 9,
   "z": -6,
   "name": "Rock_Stone"
  },
  {
   "x": -8,
   "y": 27,
   "z": -6,
   "name": "Plant_Leaves_Ash"
  },
  {
   "x": -8,
   "y": 28,
   "z": -6,
   "name": "Plant_Leaves_Ash"
  },
  {
   "x": -8,
   "y": 29,
   "z": -6,
   "name": "Plant_Leaves_Ash"
  },
  {
   "x": -8,
   "y": 30,
   "z": -6,
   "name": "Plant_Leaves_Ash"
  },
  {
   "x": -8,
   "y": 0,
   "z": -5,
   "name": "Rock_Stone"
  },
  {
   "x": -8,
   "y": 1,
   "z": -5,
   "name": "Rock_Stone"
  },
  {
   "x": -8,
   "y": 2,
   "z": -5,
   "name": "Rock_Stone"
  },
  {
   "x": -8,
   "y": 3,
   "z": -5,
   "name": "Rock_Stone"
  },
  {
   "x": -8,
   "y": 4,
   "z": -5,
   "name": "Rock_Stone"
  },
  {
   "x": -8,
   "y": 5,
   "z": -5,
   "name": "Rock_Stone"
  },
  {
   "x": -8,
   "y": 6,
   "z": -5,
   "name": "Rock_Stone"
  },
  {
   "x": -8,
   "y": 7,
   "z": -5,
   "name": "Rock_Stone"
  },
  {
   "x": -8,
   "y": 8,
   "z": -5,
   "name": "Rock_Stone"
  },
  {
   "x": -8,
   "y": 9,
   "z": -5,
   "name": "Rock_Stone"
  },
  {
   "x": -8,
   "y": 10,
   "z": -5,
   "name": "Rock_Stone"
  },
  {
   "x": -8,
   "y": 11,
   "z": -5,
   "name": "Rock_Stone"
  },
  {
   "x": -8,
   "y": 28,
   "z": -5,
   "name": "Plant_Leaves_Ash"
  },
  {
   "x": -8,
   "y": 29,
   "z": -5,
   "name": "Plant_Leaves_Ash"
  },
  {
   "x": -8,
   "y": 30,
   "z": -5,
   "name": "Plant_Leaves_Ash"
  },
  {
   "x": -8,
   "y": 31,
   "z": -5,
   "name": "Plant_Leaves_Ash"
  },
  {
   "x": -8,
   "y": 0,
   "z": -4,
   "name": "Rock_Stone"
  },
  {
   "x": -8,
   "y": 1,
   "z": -4,
   "name": "Rock_Stone"
  },
  {
   "x": -8,
   "y": 2,
   "z": -4,
   "name": "Rock_Stone"
  },
  {
   "x": -8,
   "y": 3,
   "z": -4,
   "name": "Rock_Stone"
  },
  {
   "x": -8,
   "y": 4,
   "z": -4,
   "name": "Rock_Stone"
  },
  {
   "x": -8,
   "y": 5,
   "z": -4,
   "name": "Rock_Stone"
  },
  {
   "x": -8,
   "y": 6,
   "z": -4,
   "name": "Rock_Stone"
  },
  {
   "x": -8,
   "y": 7,
   "z": -4,
   "name": "Rock_Stone"
  },
  {
   "x": -8,
   "y": 8,
   "z": -4,
   "name": "Rock_Stone"
  },
  {
   "x": -8,
   "y": 9,
   "z": -4,
   "name": "Rock_Stone"
  },
  {
   "x": -8,
   "y": 10,
   "z": -4,
   "name": "Rock_Stone"
  },
  {
   "x": -8,
   "y": 11,
   "z": -4,
   "name": "Rock_Stone"
  },
  {
   "x": -8,
   "y": 12,
   "z": -4,
   "name": "Rock_Stone"
  },
  {
   "x": -8,
   "y": 13,
   "z": -4,
   "name": "Wood_Ash_Trunk_Full"
  },
  {
   "x": -8,
   "y": 14,
   "z": -4,
   "name": "Wood_Ash_Trunk_Full"
  },
  {
   "x": -8,
   "y": 15,
   "z": -4,
   "name": "Wood_Ash_Trunk_Full"
  },
  {
   "x": -8,
   "y": 30,
   "z": -4,
   "name": "Plant_Leaves_Ash"
  },
  {
   "x": -8,
   "y": 31,
   "z": -4,
   "name": "Plant_Leaves_Ash"
  },
  {
   "x": -8,
   "y": 0,
   "z": -3,
   "name": "Rock_Stone"
  },
  {
   "x": -8,
   "y": 1,
   "z": -3,
   "name": "Rock_Stone"
  },
  {
   "x": -8,
   "y": 2,
   "z": -3,
   "name": "Rock_Stone"
  },
  {
   "x": -8,
   "y": 3,
   "z": -3,
   "name": "Rock_Stone"
  },
  {
   "x": -8,
   "y": 4,
   "z": -3,
   "name": "Rock_Stone"
  },
  {
   "x": -8,
   "y": 5,
   "z": -3,
   "name": "Rock_Stone"
  },
  {
   "x": -8,
   "y": 6,
   "z": -3,
   "name": "Rock_Stone"
  },
  {
   "x": -8,
   "y": 7,
   "z": -3,
   "name": "Rock_Stone"
  },
  {
   "x": -8,
   "y": 8,
   "z": -3,
   "name": "Rock_Stone"
  },
  {
   "x": -8,
   "y": 9,
   "z": -3,
   "name": "Rock_Stone"
  },
  {
   "x": -8,
   "y": 10,
   "z": -3,
   "name": "Rock_Stone"
  },
  {
   "x": -8,
   "y": 11,
   "z": -3,
   "name": "Rock_Stone"
  },
  {
   "x": -8,
   "y": 12,
   "z": -3,
   "name": "Rock_Stone"
  },
  {
   "x": -8,
   "y": 13,
   "z": -3,
   "name": "Rock_Stone"
  },
  {
   "x": -8,
   "y": 14,
   "z": -3,
   "name": "Wood_Ash_Trunk_Full"
  },
  {
   "x": -8,
   "y": 15,
   "z": -3,
   "name": "Wood_Ash_Trunk_Full"
  },
  {
   "x": -8,
   "y": 16,
   "z": -3,
   "name": "Wood_Ash_Trunk_Full"
  },
  {
   "x": -8,
   "y": 17,
   "z": -3,
   "name": "Wood_Ash_Trunk_Full"
  },
  {
   "x": -8,
   "y": 18,
   "z": -3,
   "name": "Wood_Ash_Trunk"
  },
  {
   "x": -8,
   "y": 19,
   "z": -3,
   "name": "Wood_Ash_Trunk"
  },
  {
   "x": -8,
   "y": 20,
   "z": -3,
   "name": "Wood_Ash_Trunk"
  },
  {
   "x": -8,
   "y": 21,
   "z": -3,
   "name": "Wood_Ash_Trunk"
  },
  {
   "x": -8,
   "y": 22,
   "z": -3,
   "name": "Wood_Ash_Trunk_Full"
  },
  {
   "x": -8,
   "y": 30,
   "z": -3,
   "name": "Plant_Leaves_Ash"
  },
  {
   "x": -8,
   "y": 31,
   "z": -3,
   "name": "Plant_Leaves_Ash"
  },
  {
   "x": -8,
   "y": 0,
   "z": -2,
   "name": "Rock_Stone"
  },
  {
   "x": -8,
   "y": 1,
   "z": -2,
   "name": "Rock_Stone"
  },
  {
   "x": -8,
   "y": 2,
   "z": -2,
   "name": "Rock_Stone"
  },
  {
   "x": -8,
   "y": 3,
   "z": -2,
   "name": "Rock_Stone"
  },
  {
   "x": -8,
   "y": 4,
   "z": -2,
   "name": "Rock_Stone"
  },
  {
   "x": -8,
   "y": 5,
   "z": -2,
   "name": "Rock_Stone"
  },
  {
   "x": -8,
   "y": 6,
   "z": -2,
   "name": "Rock_Stone"
  },
  {
   "x": -8,
   "y": 7,
   "z": -2,
   "name": "Rock_Stone"
  },
  {
   "x": -8,
   "y": 8,
   "z": -2,
   "name": "Rock_Stone"
  },
  {
   "x": -8,
   "y": 9,
   "z": -2,
   "name": "Rock_Stone"
  },
  {
   "x": -8,
   "y": 10,
   "z": -2,
   "name": "Soil_Gravel"
  },
  {
   "x": -8,
   "y": 11,
   "z": -2,
   "name": "Rock_Stone"
  },
  {
   "x": -8,
   "y": 12,
   "z": -2,
   "name": "Rock_Stone"
  },
  {
   "x": -8,
   "y": 13,
   "z": -2,
   "name": "Rock_Stone"
  },
  {
   "x": -8,
   "y": 14,
   "z": -2,
   "name": "Rock_Stone"
  },
  {
   "x": -8,
   "y": 15,
   "z": -2,
   "name": "Rock_Stone"
  },
  {
   "x": -8,
   "y": 16,
   "z": -2,
   "name": "Wood_Ash_Trunk_Full"
  },
  {
   "x": -8,
   "y": 17,
   "z": -2,
   "name": "Wood_Ash_Trunk_Full"
  },
  {
   "x": -8,
   "y": 18,
   "z": -2,
   "name": "Wood_Ash_Trunk"
  },
  {
   "x": -8,
   "y": 19,
   "z": -2,
   "name": "Wood_Ash_Trunk"
  },
  {
   "x": -8,
   "y": 20,
   "z": -2,
   "name": "Wood_Ash_Trunk"
  },
  {
   "x": -8,
   "y": 21,
   "z": -2,
   "name": "Wood_Ash_Trunk"
  },
  {
   "x": -8,
   "y": 22,
   "z": -2,
   "name": "Wood_Ash_Trunk_Full"
  },
  {
   "x": -8,
   "y": 23,
   "z": -2,
   "name": "Plant_Crop_Mushroom_Shelve_Green"
  },
  {
   "x": -8,
   "y": 29,
   "z": -2,
   "name": "Plant_Leaves_Ash"
  },
  {
   "x": -8,
   "y": 30,
   "z": -2,
   "name": "Plant_Leaves_Ash"
  },
  {
   "x": -8,
   "y": 31,
   "z": -2,
   "name": "Plant_Leaves_Ash"
  },
  {
   "x": -8,
   "y": 0,
   "z": -1,
   "name": "Rock_Stone"
  },
  {
   "x": -8,
   "y": 1,
   "z": -1,
   "name": "Rock_Stone"
  },
  {
   "x": -8,
   "y": 2,
   "z": -1,
   "name": "Rock_Stone"
  },
  {
   "x": -8,
   "y": 3,
   "z": -1,
   "name": "Rock_Stone"
  },
  {
   "x": -8,
   "y": 4,
   "z": -1,
   "name": "Rock_Stone"
  },
  {
   "x": -8,
   "y": 5,
   "z": -1,
   "name": "Rock_Stone"
  },
  {
   "x": -8,
   "y": 6,
   "z": -1,
   "name": "Rock_Stone"
  },
  {
   "x": -8,
   "y": 7,
   "z": -1,
   "name": "Rock_Stone"
  },
  {
   "x": -8,
   "y": 8,
   "z": -1,
   "name": "Rock_Stone"
  },
  {
   "x": -8,
   "y": 9,
   "z": -1,
   "name": "Rock_Stone"
  },
  {
   "x": -8,
   "y": 10,
   "z": -1,
   "name": "Soil_Gravel"
  },
  {
   "x": -8,
   "y": 11,
   "z": -1,
   "name": "Rock_Stone"
  },
  {
   "x": -8,
   "y": 12,
   "z": -1,
   "name": "Rock_Stone"
  },
  {
   "x": -8,
   "y": 13,
   "z": -1,
   "name": "Rock_Stone"
  },
  {
   "x": -8,
   "y": 14,
   "z": -1,
   "name": "Rock_Stone"
  },
  {
   "x": -8,
   "y": 15,
   "z": -1,
   "name": "Wood_Ash_Branch_Corner",
   "rotation": 2
  },
  {
   "x": -8,
   "y": 16,
   "z": -1,
   "name": "Wood_Ash_Branch_Corner",
   "rotation": 8
  },
  {
   "x": -8,
   "y": 17,
   "z": -1,
   "name": "Wood_Ash_Branch_Long",
   "rotation": 4
  },
  {
   "x": -8,
   "y": 21,
   "z": -1,
   "name": "Plant_Crop_Mushroom_Shelve_Green"
  },
  {
   "x": -8,
   "y": 22,
   "z": -1,
   "name": "Plant_Crop_Mushroom_Shelve_Green"
  },
  {
   "x": -8,
   "y": 31,
   "z": -1,
   "name": "Plant_Leaves_Ash"
  },
  {
   "x": -8,
   "y": 32,
   "z": -1,
   "name": "Plant_Leaves_Ash"
  },
  {
   "x": -8,
   "y": 0,
   "z": 0,
   "name": "Rock_Stone"
  },
  {
   "x": -8,
   "y": 1,
   "z": 0,
   "name": "Rock_Stone"
  },
  {
   "x": -8,
   "y": 2,
   "z": 0,
   "name": "Rock_Stone"
  },
  {
   "x": -8,
   "y": 3,
   "z": 0,
   "name": "Rock_Stone"
  },
  {
   "x": -8,
   "y": 4,
   "z": 0,
   "name": "Rock_Stone"
  },
  {
   "x": -8,
   "y": 5,
   "z": 0,
   "name": "Rock_Stone"
  },
  {
   "x": -8,
   "y": 6,
   "z": 0,
   "name": "Rock_Stone"
  },
  {
   "x": -8,
   "y": 7,
   "z": 0,
   "name": "Rock_Stone"
  },
  {
   "x": -8,
   "y": 8,
   "z": 0,
   "name": "Rock_Stone"
  },
  {
   "x": -8,
   "y": 9,
   "z": 0,
   "name": "Rock_Stone"
  },
  {
   "x": -8,
   "y": 10,
   "z": 0,
   "name": "Rock_Stone"
  },
  {
   "x": -8,
   "y": 11,
   "z": 0,
   "name": "Soil_Gravel"
  },
  {
   "x": -8,
   "y": 12,
   "z": 0,
   "name": "Rock_Stone"
  },
  {
   "x": -8,
   "y": 13,
   "z": 0,
   "name": "Plant_Moss_Wall_Green_Dark",
   "rotation": 3
  },
  {
   "x": -8,
   "y": 14,
   "z": 0,
   "name": "Plant_Moss_Wall_Green_Dark",
   "rotation": 3
  },
  {
   "x": -8,
   "y": 15,
   "z": 0,
   "name": "Wood_Ash_Branch_Corner"
  },
  {
   "x": -8,
   "y": 16,
   "z": 0,
   "name": "Wood_Ash_Branch_Long"
  },
  {
   "x": -8,
   "y": 17,
   "z": 0,
   "name": "Wood_Ash_Branch_Corner",
   "rotation": 10
  },
  {
   "x": -8,
   "y": 27,
   "z": 0,
   "name": "Plant_Vine_Hanging"
  },
  {
   "x": -8,
   "y": 31,
   "z": 0,
   "name": "Plant_Leaves_Ash"
  },
  {
   "x": -8,
   "y": 32,
   "z": 0,
   "name": "Plant_Leaves_Ash"
  },
  {
   "x": -8,
   "y": 0,
   "z": 1,
   "name": "Rock_Stone"
  },
  {
   "x": -8,
   "y": 1,
   "z": 1,
   "name": "Rock_Stone"
  },
  {
   "x": -8,
   "y": 2,
   "z": 1,
   "name": "Rock_Stone"
  },
  {
   "x": -8,
   "y": 3,
   "z": 1,
   "name": "Rock_Stone"
  },
  {
   "x": -8,
   "y": 4,
   "z": 1,
   "name": "Rock_Stone"
  },
  {
   "x": -8,
   "y": 5,
   "z": 1,
   "name": "Rock_Stone"
  },
  {
   "x": -8,
   "y": 6,
   "z": 1,
   "name": "Rock_Stone"
  },
  {
   "x": -8,
   "y": 7,
   "z": 1,
   "name": "Rock_Stone"
  },
  {
   "x": -8,
   "y": 8,
   "z": 1,
   "name": "Rock_Stone"
  },
  {
   "x": -8,
   "y": 9,
   "z": 1,
   "name": "Rock_Stone"
  },
  {
   "x": -8,
   "y": 10,
   "z": 1,
   "name": "Soil_Gravel"
  },
  {
   "x": -8,
   "y": 11,
   "z": 1,
   "name": "Soil_Gravel"
  },
  {
   "x": -8,
   "y": 12,
   "z": 1,
   "name": "Soil_Gravel"
  },
  {
   "x": -8,
   "y": 14,
   "z": 1,
   "name": "Plant_Moss_Wall_Green_Dark",
   "rotation": 3
  },
  {
   "x": -8,
   "y": 15,
   "z": 1,
   "name": "Plant_Moss_Wall_Green_Dark",
   "rotation": 3
  },
  {
   "x": -8,
   "y": 16,
   "z": 1,
   "name": "Plant_Moss_Wall_Green_Dark",
   "rotation": 3
  },
  {
   "x": -8,
   "y": 28,
   "z": 1,
   "name": "Plant_Leaves_Ash"
  },
  {
   "x": -8,
   "y": 29,
   "z": 1,
   "name": "Plant_Leaves_Ash"
  },
  {
   "x": -8,
   "y": 30,
   "z": 1,
   "name": "Plant_Leaves_Ash"
  },
  {
   "x": -8,
   "y": 31,
   "z": 1,
   "name": "Plant_Leaves_Ash"
  },
  {
   "x": -8,
   "y": 32,
   "z": 1,
   "name": "Plant_Leaves_Ash"
  },
  {
   "x": -8,
   "y": 0,
   "z": 2,
   "name": "Rock_Stone"
  },
  {
   "x": -8,
   "y": 1,
   "z": 2,
   "name": "Rock_Stone"
  },
  {
   "x": -8,
   "y": 2,
   "z": 2,
   "name": "Rock_Stone"
  },
  {
   "x": -8,
   "y": 3,
   "z": 2,
   "name": "Rock_Stone"
  },
  {
   "x": -8,
   "y": 4,
   "z": 2,
   "name": "Rock_Stone"
  },
  {
   "x": -8,
   "y": 5,
   "z": 2,
   "name": "Rock_Stone"
  },
  {
   "x": -8,
   "y": 6,
   "z": 2,
   "name": "Rock_Stone"
  },
  {
   "x": -8,
   "y": 7,
   "z": 2,
   "name": "Rock_Stone"
  },
  {
   "x": -8,
   "y": 8,
   "z": 2,
   "name": "Rock_Stone"
  },
  {
   "x": -8,
   "y": 9,
   "z": 2,
   "name": "Rock_Stone"
  },
  {
   "x": -8,
   "y": 10,
   "z": 2,
   "name": "Rock_Stone"
  },
  {
   "x": -8,
   "y": 11,
   "z": 2,
   "name": "Soil_Gravel"
  },
  {
   "x": -8,
   "y": 12,
   "z": 2,
   "name": "Soil_Gravel"
  },
  {
   "x": -8,
   "y": 13,
   "z": 2,
   "name": "Soil_Gravel"
  },
  {
   "x": -8,
   "y": 15,
   "z": 2,
   "name": "Plant_Moss_Wall_Green_Dark",
   "rotation": 3
  },
  {
   "x": -8,
   "y": 31,
   "z": 2,
   "name": "Plant_Leaves_Ash"
  },
  {
   "x": -8,
   "y": 0,
   "z": 3,
   "name": "Rock_Stone"
  },
  {
   "x": -8,
   "y": 1,
   "z": 3,
   "name": "Rock_Stone"
  },
  {
   "x": -8,
   "y": 2,
   "z": 3,
   "name": "Rock_Stone"
  },
  {
   "x": -8,
   "y": 3,
   "z": 3,
   "name": "Rock_Stone"
  },
  {
   "x": -8,
   "y": 4,
   "z": 3,
   "name": "Rock_Stone"
  },
  {
   "x": -8,
   "y": 5,
   "z": 3,
   "name": "Rock_Stone"
  },
  {
   "x": -8,
   "y": 6,
   "z": 3,
   "name": "Rock_Stone"
  },
  {
   "x": -8,
   "y": 7,
   "z": 3,
   "name": "Rock_Stone"
  },
  {
   "x": -8,
   "y": 8,
   "z": 3,
   "name": "Rock_Stone"
  },
  {
   "x": -8,
   "y": 9,
   "z": 3,
   "name": "Rock_Stone"
  },
  {
   "x": -8,
   "y": 10,
   "z": 3,
   "name": "Soil_Gravel"
  },
  {
   "x": -8,
   "y": 11,
   "z": 3,
   "name": "Rock_Stone"
  },
  {
   "x": -8,
   "y": 12,
   "z": 3,
   "name": "Soil_Gravel"
  },
  {
   "x": -8,
   "y": 13,
   "z": 3,
   "name": "Soil_Gravel"
  },
  {
   "x": -8,
   "y": 14,
   "z": 3,
   "name": "Furniture_Village_Tombstone",
   "rotation": 3
  },
  {
   "x": -8,
   "y": 15,
   "z": 3,
   "name": "Furniture_Village_Tombstone",
   "filler": 1024,
   "rotation": 3
  },
  {
   "x": -8,
   "y": 29,
   "z": 3,
   "name": "Plant_Vine_Hanging"
  },
  {
   "x": -8,
   "y": 30,
   "z": 3,
   "name": "Plant_Leaves_Ash"
  },
  {
   "x": -8,
   "y": 0,
   "z": 4,
   "name": "Rock_Stone"
  },
  {
   "x": -8,
   "y": 1,
   "z": 4,
   "name": "Rock_Stone"
  },
  {
   "x": -8,
   "y": 2,
   "z": 4,
   "name": "Rock_Stone"
  },
  {
   "x": -8,
   "y": 3,
   "z": 4,
   "name": "Rock_Stone"
  },
  {
   "x": -8,
   "y": 4,
   "z": 4,
   "name": "Rock_Stone"
  },
  {
   "x": -8,
   "y": 5,
   "z": 4,
   "name": "Rock_Stone"
  },
  {
   "x": -8,
   "y": 6,
   "z": 4,
   "name": "Rock_Stone"
  },
  {
   "x": -8,
   "y": 7,
   "z": 4,
   "name": "Rock_Stone"
  },
  {
   "x": -8,
   "y": 8,
   "z": 4,
   "name": "Rock_Stone"
  },
  {
   "x": -8,
   "y": 9,
   "z": 4,
   "name": "Rock_Stone"
  },
  {
   "x": -8,
   "y": 10,
   "z": 4,
   "name": "Soil_Gravel"
  },
  {
   "x": -8,
   "y": 11,
   "z": 4,
   "name": "Rock_Stone"
  },
  {
   "x": -8,
   "y": 12,
   "z": 4,
   "name": "Soil_Gravel"
  },
  {
   "x": -8,
   "y": 13,
   "z": 4,
   "name": "Soil_Gravel"
  },
  {
   "x": -8,
   "y": 30,
   "z": 4,
   "name": "Plant_Leaves_Ash"
  },
  {
   "x": -8,
   "y": 0,
   "z": 5,
   "name": "Rock_Stone"
  },
  {
   "x": -8,
   "y": 1,
   "z": 5,
   "name": "Rock_Stone"
  },
  {
   "x": -8,
   "y": 2,
   "z": 5,
   "name": "Rock_Stone"
  },
  {
   "x": -8,
   "y": 3,
   "z": 5,
   "name": "Rock_Stone"
  },
  {
   "x": -8,
   "y": 4,
   "z": 5,
   "name": "Rock_Stone"
  },
  {
   "x": -8,
   "y": 5,
   "z": 5,
   "name": "Rock_Stone"
  },
  {
   "x": -8,
   "y": 6,
   "z": 5,
   "name": "Rock_Stone"
  },
  {
   "x": -8,
   "y": 7,
   "z": 5,
   "name": "Rock_Stone"
  },
  {
   "x": -8,
   "y": 8,
   "z": 5,
   "name": "Rock_Stone"
  },
  {
   "x": -8,
   "y": 9,
   "z": 5,
   "name": "Rock_Stone"
  },
  {
   "x": -8,
   "y": 10,
   "z": 5,
   "name": "Rock_Stone"
  },
  {
   "x": -8,
   "y": 11,
   "z": 5,
   "name": "Rock_Stone"
  },
  {
   "x": -8,
   "y": 12,
   "z": 5,
   "name": "Rock_Stone"
  },
  {
   "x": -8,
   "y": 13,
   "z": 5,
   "name": "Soil_Gravel"
  },
  {
   "x": -8,
   "y": 14,
   "z": 5,
   "name": "Rock_Stone"
  },
  {
   "x": -8,
   "y": 0,
   "z": 6,
   "name": "Rock_Stone"
  },
  {
   "x": -8,
   "y": 1,
   "z": 6,
   "name": "Rock_Stone"
  },
  {
   "x": -8,
   "y": 2,
   "z": 6,
   "name": "Rock_Stone"
  },
  {
   "x": -8,
   "y": 3,
   "z": 6,
   "name": "Rock_Stone"
  },
  {
   "x": -8,
   "y": 4,
   "z": 6,
   "name": "Rock_Stone"
  },
  {
   "x": -8,
   "y": 5,
   "z": 6,
   "name": "Rock_Stone"
  },
  {
   "x": -8,
   "y": 6,
   "z": 6,
   "name": "Rock_Stone"
  },
  {
   "x": -8,
   "y": 7,
   "z": 6,
   "name": "Rock_Stone"
  },
  {
   "x": -8,
   "y": 8,
   "z": 6,
   "name": "Rock_Stone"
  },
  {
   "x": -8,
   "y": 9,
   "z": 6,
   "name": "Rock_Stone"
  },
  {
   "x": -8,
   "y": 10,
   "z": 6,
   "name": "Rock_Stone"
  },
  {
   "x": -8,
   "y": 11,
   "z": 6,
   "name": "Rock_Stone"
  },
  {
   "x": -8,
   "y": 12,
   "z": 6,
   "name": "Rock_Stone"
  },
  {
   "x": -8,
   "y": 13,
   "z": 6,
   "name": "Rock_Stone"
  },
  {
   "x": -8,
   "y": 14,
   "z": 6,
   "name": "Soil_Gravel"
  },
  {
   "x": -8,
   "y": 0,
   "z": 7,
   "name": "Rock_Stone"
  },
  {
   "x": -8,
   "y": 1,
   "z": 7,
   "name": "Rock_Stone"
  },
  {
   "x": -8,
   "y": 2,
   "z": 7,
   "name": "Rock_Stone"
  },
  {
   "x": -8,
   "y": 3,
   "z": 7,
   "name": "Rock_Stone"
  },
  {
   "x": -8,
   "y": 4,
   "z": 7,
   "name": "Rock_Stone"
  },
  {
   "x": -8,
   "y": 5,
   "z": 7,
   "name": "Rock_Stone"
  },
  {
   "x": -8,
   "y": 6,
   "z": 7,
   "name": "Rock_Stone"
  },
  {
   "x": -8,
   "y": 7,
   "z": 7,
   "name": "Rock_Stone"
  },
  {
   "x": -8,
   "y": 8,
   "z": 7,
   "name": "Rock_Stone"
  },
  {
   "x": -8,
   "y": 9,
   "z": 7,
   "name": "Rock_Stone"
  },
  {
   "x": -8,
   "y": 10,
   "z": 7,
   "name": "Rock_Stone"
  },
  {
   "x": -8,
   "y": 11,
   "z": 7,
   "name": "Rock_Stone"
  },
  {
   "x": -8,
   "y": 12,
   "z": 7,
   "name": "Rock_Stone"
  },
  {
   "x": -8,
   "y": 13,
   "z": 7,
   "name": "Soil_Gravel"
  },
  {
   "x": -8,
   "y": 14,
   "z": 7,
   "name": "Soil_Gravel"
  },
  {
   "x": -8,
   "y": 1,
   "z": 8,
   "name": "Rock_Stone"
  },
  {
   "x": -8,
   "y": 2,
   "z": 8,
   "name": "Rock_Stone"
  },
  {
   "x": -8,
   "y": 3,
   "z": 8,
   "name": "Rock_Stone"
  },
  {
   "x": -8,
   "y": 4,
   "z": 8,
   "name": "Rock_Stone"
  },
  {
   "x": -8,
   "y": 5,
   "z": 8,
   "name": "Rock_Stone"
  },
  {
   "x": -8,
   "y": 6,
   "z": 8,
   "name": "Rock_Stone"
  },
  {
   "x": -8,
   "y": 7,
   "z": 8,
   "name": "Rock_Stone"
  },
  {
   "x": -8,
   "y": 8,
   "z": 8,
   "name": "Rock_Stone"
  },
  {
   "x": -8,
   "y": 9,
   "z": 8,
   "name": "Rock_Stone"
  },
  {
   "x": -8,
   "y": 10,
   "z": 8,
   "name": "Rock_Stone"
  },
  {
   "x": -8,
   "y": 11,
   "z": 8,
   "name": "Rock_Stone"
  },
  {
   "x": -8,
   "y": 12,
   "z": 8,
   "name": "Rock_Stone"
  },
  {
   "x": -8,
   "y": 2,
   "z": 9,
   "name": "Rock_Stone"
  },
  {
   "x": -8,
   "y": 3,
   "z": 9,
   "name": "Rock_Stone"
  },
  {
   "x": -8,
   "y": 4,
   "z": 9,
   "name": "Rock_Stone"
  },
  {
   "x": -8,
   "y": 5,
   "z": 9,
   "name": "Rock_Stone"
  },
  {
   "x": -8,
   "y": 6,
   "z": 9,
   "name": "Rock_Stone"
  },
  {
   "x": -8,
   "y": 7,
   "z": 9,
   "name": "Rock_Stone"
  },
  {
   "x": -8,
   "y": 8,
   "z": 9,
   "name": "Rock_Stone"
  },
  {
   "x": -8,
   "y": 3,
   "z": 10,
   "name": "Rock_Stone"
  },
  {
   "x": -8,
   "y": 4,
   "z": 10,
   "name": "Rock_Stone"
  },
  {
   "x": -7,
   "y": 4,
   "z": -9,
   "name": "Rock_Stone"
  },
  {
   "x": -7,
   "y": 5,
   "z": -9,
   "name": "Rock_Stone"
  },
  {
   "x": -7,
   "y": 6,
   "z": -9,
   "name": "Rock_Stone"
  },
  {
   "x": -7,
   "y": 7,
   "z": -9,
   "name": "Rock_Stone"
  },
  {
   "x": -7,
   "y": 8,
   "z": -9,
   "name": "Rock_Stone"
  },
  {
   "x": -7,
   "y": 22,
   "z": -9,
   "name": "Plant_Leaves_Ash"
  },
  {
   "x": -7,
   "y": 23,
   "z": -9,
   "name": "Plant_Leaves_Ash"
  },
  {
   "x": -7,
   "y": 24,
   "z": -9,
   "name": "Plant_Leaves_Ash"
  },
  {
   "x": -7,
   "y": 2,
   "z": -8,
   "name": "Rock_Stone"
  },
  {
   "x": -7,
   "y": 3,
   "z": -8,
   "name": "Rock_Stone"
  },
  {
   "x": -7,
   "y": 4,
   "z": -8,
   "name": "Rock_Stone"
  },
  {
   "x": -7,
   "y": 5,
   "z": -8,
   "name": "Rock_Stone"
  },
  {
   "x": -7,
   "y": 6,
   "z": -8,
   "name": "Rock_Stone"
  },
  {
   "x": -7,
   "y": 7,
   "z": -8,
   "name": "Rock_Stone"
  },
  {
   "x": -7,
   "y": 8,
   "z": -8,
   "name": "Rock_Stone"
  },
  {
   "x": -7,
   "y": 9,
   "z": -8,
   "name": "Rock_Stone"
  },
  {
   "x": -7,
   "y": 10,
   "z": -8,
   "name": "Rock_Stone"
  },
  {
   "x": -7,
   "y": 24,
   "z": -8,
   "name": "Plant_Leaves_Ash"
  },
  {
   "x": -7,
   "y": 25,
   "z": -8,
   "name": "Plant_Leaves_Ash"
  },
  {
   "x": -7,
   "y": 1,
   "z": -7,
   "name": "Rock_Stone"
  },
  {
   "x": -7,
   "y": 2,
   "z": -7,
   "name": "Rock_Stone"
  },
  {
   "x": -7,
   "y": 3,
   "z": -7,
   "name": "Rock_Stone"
  },
  {
   "x": -7,
   "y": 4,
   "z": -7,
   "name": "Rock_Stone"
  },
  {
   "x": -7,
   "y": 5,
   "z": -7,
   "name": "Rock_Stone"
  },
  {
   "x": -7,
   "y": 6,
   "z": -7,
   "name": "Rock_Stone"
  },
  {
   "x": -7,
   "y": 7,
   "z": -7,
   "name": "Rock_Stone"
  },
  {
   "x": -7,
   "y": 8,
   "z": -7,
   "name": "Rock_Stone"
  },
  {
   "x": -7,
   "y": 9,
   "z": -7,
   "name": "Rock_Stone"
  },
  {
   "x": -7,
   "y": 10,
   "z": -7,
   "name": "Rock_Stone"
  },
  {
   "x": -7,
   "y": 11,
   "z": -7,
   "name": "Rock_Stone"
  },
  {
   "x": -7,
   "y": 12,
   "z": -7,
   "name": "Rock_Stone"
  },
  {
   "x": -7,
   "y": 13,
   "z": -7,
   "name": "Rock_Stone"
  },
  {
   "x": -7,
   "y": 14,
   "z": -7,
   "name": "Wood_Ash_Branch_Corner",
   "rotation": 2
  },
  {
   "x": -7,
   "y": 15,
   "z": -7,
   "name": "Wood_Ash_Branch_Long"
  },
  {
   "x": -7,
   "y": 16,
   "z": -7,
   "name": "Wood_Ash_Branch_Corner",
   "rotation": 8
  },
  {
   "x": -7,
   "y": 25,
   "z": -7,
   "name": "Plant_Leaves_Ash"
  },
  {
   "x": -7,
   "y": 28,
   "z": -7,
   "name": "Plant_Leaves_Ash"
  },
  {
   "x": -7,
   "y": 29,
   "z": -7,
   "name": "Plant_Leaves_Ash"
  },
  {
   "x": -7,
   "y": 1,
   "z": -6,
   "name": "Rock_Stone"
  },
  {
   "x": -7,
   "y": 2,
   "z": -6,
   "name": "Rock_Stone"
  },
  {
   "x": -7,
   "y": 3,
   "z": -6,
   "name": "Rock_Stone"
  },
  {
   "x": -7,
   "y": 4,
   "z": -6,
   "name": "Rock_Stone"
  },
  {
   "x": -7,
   "y": 5,
   "z": -6,
   "name": "Rock_Stone"
  },
  {
   "x": -7,
   "y": 6,
   "z": -6,
   "name": "Rock_Stone"
  },
  {
   "x": -7,
   "y": 7,
   "z": -6,
   "name": "Rock_Stone"
  },
  {
   "x": -7,
   "y": 8,
   "z": -6,
   "name": "Rock_Stone"
  },
  {
   "x": -7,
   "y": 9,
   "z": -6,
   "name": "Rock_Stone"
  },
  {
   "x": -7,
   "y": 10,
   "z": -6,
   "name": "Rock_Stone"
  },
  {
   "x": -7,
   "y": 11,
   "z": -6,
   "name": "Rock_Stone"
  },
  {
   "x": -7,
   "y": 12,
   "z": -6,
   "name": "Rock_Stone"
  },
  {
   "x": -7,
   "y": 13,
   "z": -6,
   "name": "Rock_Stone"
  },
  {
   "x": -7,
   "y": 14,
   "z": -6,
   "name": "Wood_Ash_Branch_Long",
   "rotation": 4
  },
  {
   "x": -7,
   "y": 15,
   "z": -6,
   "name": "Wood_Ash_Branch_Corner"
  },
  {
   "x": -7,
   "y": 16,
   "z": -6,
   "name": "Wood_Ash_Branch_Corner",
   "rotation": 10
  },
  {
   "x": -7,
   "y": 24,
   "z": -6,
   "name": "Wood_Ash_Trunk_Full"
  },
  {
   "x": -7,
   "y": 27,
   "z": -6,
   "name": "Plant_Leaves_Ash"
  },
  {
   "x": -7,
   "y": 28,
   "z": -6,
   "name": "Plant_Leaves_Ash"
  },
  {
   "x": -7,
   "y": 29,
   "z": -6,
   "name": "Plant_Leaves_Ash"
  },
  {
   "x": -7,
   "y": 30,
   "z": -6,
   "name": "Plant_Leaves_Ash"
  },
  {
   "x": -7,
   "y": 0,
   "z": -5,
   "name": "Rock_Stone"
  },
  {
   "x": -7,
   "y": 1,
   "z": -5,
   "name": "Rock_Stone"
  },
  {
   "x": -7,
   "y": 2,
   "z": -5,
   "name": "Rock_Stone"
  },
  {
   "x": -7,
   "y": 3,
   "z": -5,
   "name": "Rock_Stone"
  },
  {
   "x": -7,
   "y": 4,
   "z": -5,
   "name": "Rock_Stone"
  },
  {
   "x": -7,
   "y": 5,
   "z": -5,
   "name": "Rock_Stone"
  },
  {
   "x": -7,
   "y": 6,
   "z": -5,
   "name": "Rock_Stone"
  },
  {
   "x": -7,
   "y": 7,
   "z": -5,
   "name": "Rock_Stone"
  },
  {
   "x": -7,
   "y": 8,
   "z": -5,
   "name": "Rock_Stone"
  },
  {
   "x": -7,
   "y": 9,
   "z": -5,
   "name": "Rock_Stone"
  },
  {
   "x": -7,
   "y": 10,
   "z": -5,
   "name": "Rock_Stone"
  },
  {
   "x": -7,
   "y": 11,
   "z": -5,
   "name": "Rock_Stone"
  },
  {
   "x": -7,
   "y": 12,
   "z": -5,
   "name": "Rock_Stone"
  },
  {
   "x": -7,
   "y": 13,
   "z": -5,
   "name": "Rock_Stone"
  },
  {
   "x": -7,
   "y": 14,
   "z": -5,
   "name": "Wood_Ash_Branch_Corner"
  },
  {
   "x": -7,
   "y": 15,
   "z": -5,
   "name": "Wood_Ash_Trunk_Full"
  },
  {
   "x": -7,
   "y": 16,
   "z": -5,
   "name": "Wood_Ash_Trunk"
  },
  {
   "x": -7,
   "y": 17,
   "z": -5,
   "name": "Wood_Ash_Trunk_Full"
  },
  {
   "x": -7,
   "y": 24,
   "z": -5,
   "name": "Wood_Ash_Trunk_Full"
  },
  {
   "x": -7,
   "y": 29,
   "z": -5,
   "name": "Wood_Ash_Trunk_Full"
  },
  {
   "x": -7,
   "y": 30,
   "z": -5,
   "name": "Wood_Ash_Branch_Long"
  },
  {
   "x": -7,
   "y": 31,
   "z": -5,
   "name": "Plant_Leaves_Ash"
  },
  {
   "x": -7,
   "y": 0,
   "z": -4,
   "name": "Rock_Stone"
  },
  {
   "x": -7,
   "y": 1,
   "z": -4,
   "name": "Rock_Stone"
  },
  {
   "x": -7,
   "y": 2,
   "z": -4,
   "name": "Rock_Stone"
  },
  {
   "x": -7,
   "y": 3,
   "z": -4,
   "name": "Rock_Stone"
  },
  {
   "x": -7,
   "y": 4,
   "z": -4,
   "name": "Rock_Stone"
  },
  {
   "x": -7,
   "y": 5,
   "z": -4,
   "name": "Rock_Stone"
  },
  {
   "x": -7,
   "y": 6,
   "z": -4,
   "name": "Rock_Stone"
  },
  {
   "x": -7,
   "y": 7,
   "z": -4,
   "name": "Rock_Stone"
  },
  {
   "x": -7,
   "y": 8,
   "z": -4,
   "name": "Rock_Stone"
  },
  {
   "x": -7,
   "y": 9,
   "z": -4,
   "name": "Rock_Stone"
  },
  {
   "x": -7,
   "y": 10,
   "z": -4,
   "name": "Rock_Stone"
  },
  {
   "x": -7,
   "y": 11,
   "z": -4,
   "name": "Rock_Stone"
  },
  {
   "x": -7,
   "y": 12,
   "z": -4,
   "name": "Rock_Stone"
  },
  {
   "x": -7,
   "y": 13,
   "z": -4,
   "name": "Rock_Stone"
  },
  {
   "x": -7,
   "y": 14,
   "z": -4,
   "name": "Rock_Stone"
  },
  {
   "x": -7,
   "y": 15,
   "z": -4,
   "name": "Rock_Stone"
  },
  {
   "x": -7,
   "y": 16,
   "z": -4,
   "name": "Rock_Stone"
  },
  {
   "x": -7,
   "y": 17,
   "z": -4,
   "name": "Wood_Ash_Trunk_Full"
  },
  {
   "x": -7,
   "y": 18,
   "z": -4,
   "name": "Wood_Ash_Trunk_Full"
  },
  {
   "x": -7,
   "y": 24,
   "z": -4,
   "name": "Wood_Ash_Trunk_Full"
  },
  {
   "x": -7,
   "y": 26,
   "z": -4,
   "name": "Wood_Ash_Trunk_Full"
  },
  {
   "x": -7,
   "y": 27,
   "z": -4,
   "name": "Wood_Ash_Trunk"
  },
  {
   "x": -7,
   "y": 28,
   "z": -4,
   "name": "Wood_Ash_Trunk"
  },
  {
   "x": -7,
   "y": 29,
   "z": -4,
   "name": "Wood_Ash_Trunk_Full"
  },
  {
   "x": -7,
   "y": 30,
   "z": -4,
   "name": "Plant_Leaves_Ash"
  },
  {
   "x": -7,
   "y": 31,
   "z": -4,
   "name": "Plant_Leaves_Ash"
  },
  {
   "x": -7,
   "y": 0,
   "z": -3,
   "name": "Rock_Stone"
  },
  {
   "x": -7,
   "y": 1,
   "z": -3,
   "name": "Rock_Stone"
  },
  {
   "x": -7,
   "y": 2,
   "z": -3,
   "name": "Rock_Stone"
  },
  {
   "x": -7,
   "y": 3,
   "z": -3,
   "name": "Rock_Stone"
  },
  {
   "x": -7,
   "y": 4,
   "z": -3,
   "name": "Rock_Stone"
  },
  {
   "x": -7,
   "y": 5,
   "z": -3,
   "name": "Rock_Stone"
  },
  {
   "x": -7,
   "y": 6,
   "z": -3,
   "name": "Rock_Stone"
  },
  {
   "x": -7,
   "y": 7,
   "z": -3,
   "name": "Rock_Stone"
  },
  {
   "x": -7,
   "y": 8,
   "z": -3,
   "name": "Rock_Stone"
  },
  {
   "x": -7,
   "y": 9,
   "z": -3,
   "name": "Rock_Stone"
  },
  {
   "x": -7,
   "y": 10,
   "z": -3,
   "name": "Rock_Stone"
  },
  {
   "x": -7,
   "y": 11,
   "z": -3,
   "name": "Rock_Stone"
  },
  {
   "x": -7,
   "y": 12,
   "z": -3,
   "name": "Rock_Stone"
  },
  {
   "x": -7,
   "y": 13,
   "z": -3,
   "name": "Rock_Stone"
  },
  {
   "x": -7,
   "y": 14,
   "z": -3,
   "name": "Rock_Stone"
  },
  {
   "x": -7,
   "y": 15,
   "z": -3,
   "name": "Wood_Ash_Trunk_Full"
  },
  {
   "x": -7,
   "y": 16,
   "z": -3,
   "name": "Wood_Ash_Trunk_Full"
  },
  {
   "x": -7,
   "y": 17,
   "z": -3,
   "name": "Wood_Ash_Trunk_Full"
  },
  {
   "x": -7,
   "y": 18,
   "z": -3,
   "name": "Wood_Ash_Trunk"
  },
  {
   "x": -7,
   "y": 19,
   "z": -3,
   "name": "Wood_Ash_Trunk_Full"
  },
  {
   "x": -7,
   "y": 22,
   "z": -3,
   "name": "Wood_Ash_Trunk_Full"
  },
  {
   "x": -7,
   "y": 23,
   "z": -3,
   "name": "Wood_Ash_Trunk"
  },
  {
   "x": -7,
   "y": 24,
   "z": -3,
   "name": "Wood_Ash_Trunk_Full"
  },
  {
   "x": -7,
   "y": 25,
   "z": -3,
   "name": "Wood_Ash_Trunk"
  },
  {
   "x": -7,
   "y": 26,
   "z": -3,
   "name": "Wood_Ash_Trunk_Full"
  },
  {
   "x": -7,
   "y": 27,
   "z": -3,
   "name": "Plant_Crop_Mushroom_Shelve_Green"
  },
  {
   "x": -7,
   "y": 28,
   "z": -3,
   "name": "Plant_Crop_Mushroom_Shelve_Green"
  },
  {
   "x": -7,
   "y": 31,
   "z": -3,
   "name": "Plant_Leaves_Ash"
  },
  {
   "x": -7,
   "y": 0,
   "z": -2,
   "name": "Rock_Stone"
  },
  {
   "x": -7,
   "y": 1,
   "z": -2,
   "name": "Rock_Stone"
  },
  {
   "x": -7,
   "y": 2,
   "z": -2,
   "name": "Rock_Stone"
  },
  {
   "x": -7,
   "y": 3,
   "z": -2,
   "name": "Rock_Stone"
  },
  {
   "x": -7,
   "y": 4,
   "z": -2,
   "name": "Rock_Stone"
  },
  {
   "x": -7,
   "y": 5,
   "z": -2,
   "name": "Rock_Stone"
  },
  {
   "x": -7,
   "y": 6,
   "z": -2,
   "name": "Rock_Stone"
  },
  {
   "x": -7,
   "y": 7,
   "z": -2,
   "name": "Rock_Stone"
  },
  {
   "x": -7,
   "y": 8,
   "z": -2,
   "name": "Rock_Stone"
  },
  {
   "x": -7,
   "y": 9,
   "z": -2,
   "name": "Rock_Stone"
  },
  {
   "x": -7,
   "y": 10,
   "z": -2,
   "name": "Rock_Stone"
  },
  {
   "x": -7,
   "y": 11,
   "z": -2,
   "name": "Wood_Ash_Roots"
  },
  {
   "x": -7,
   "y": 12,
   "z": -2,
   "name": "Wood_Ash_Trunk_Full"
  },
  {
   "x": -7,
   "y": 13,
   "z": -2,
   "name": "Wood_Ash_Trunk_Full"
  },
  {
   "x": -7,
   "y": 14,
   "z": -2,
   "name": "Rock_Stone"
  },
  {
   "x": -7,
   "y": 15,
   "z": -2,
   "name": "Rock_Stone"
  },
  {
   "x": -7,
   "y": 16,
   "z": -2,
   "name": "Wood_Ash_Trunk_Full"
  },
  {
   "x": -7,
   "y": 17,
   "z": -2,
   "name": "Wood_Ash_Trunk_Full"
  },
  {
   "x": -7,
   "y": 18,
   "z": -2,
   "name": "Wood_Ash_Trunk"
  },
  {
   "x": -7,
   "y": 19,
   "z": -2,
   "name": "Wood_Ash_Trunk"
  },
  {
   "x": -7,
   "y": 20,
   "z": -2,
   "name": "Wood_Ash_Trunk"
  },
  {
   "x": -7,
   "y": 21,
   "z": -2,
   "name": "Wood_Ash_Trunk_Full"
  },
  {
   "x": -7,
   "y": 22,
   "z": -2,
   "name": "Plant_Crop_Mushroom_Shelve_Green"
  },
  {
   "x": -7,
   "y": 26,
   "z": -2,
   "name": "Wood_Ash_Trunk_Full"
  },
  {
   "x": -7,
   "y": 27,
   "z": -2,
   "name": "Wood_Ash_Trunk_Full"
  },
  {
   "x": -7,
   "y": 30,
   "z": -2,
   "name": "Plant_Leaves_Ash"
  },
  {
   "x": -7,
   "y": 0,
   "z": -1,
   "name": "Rock_Stone"
  },
  {
   "x": -7,
   "y": 1,
   "z": -1,
   "name": "Rock_Stone"
  },
  {
   "x": -7,
   "y": 2,
   "z": -1,
   "name": "Rock_Stone"
  },
  {
   "x": -7,
   "y": 3,
   "z": -1,
   "name": "Rock_Stone"
  },
  {
   "x": -7,
   "y": 4,
   "z": -1,
   "name": "Rock_Stone"
  },
  {
   "x": -7,
   "y": 5,
   "z": -1,
   "name": "Rock_Stone"
  },
  {
   "x": -7,
   "y": 6,
   "z": -1,
   "name": "Rock_Stone"
  },
  {
   "x": -7,
   "y": 7,
   "z": -1,
   "name": "Rock_Stone"
  },
  {
   "x": -7,
   "y": 8,
   "z": -1,
   "name": "Rock_Stone"
  },
  {
   "x": -7,
   "y": 9,
   "z": -1,
   "name": "Rock_Stone"
  },
  {
   "x": -7,
   "y": 10,
   "z": -1,
   "name": "Rock_Stone"
  },
  {
   "x": -7,
   "y": 11,
   "z": -1,
   "name": "Rock_Stone"
  },
  {
   "x": -7,
   "y": 12,
   "z": -1,
   "name": "Wood_Ash_Roots"
  },
  {
   "x": -7,
   "y": 13,
   "z": -1,
   "name": "Wood_Ash_Trunk_Full"
  },
  {
   "x": -7,
   "y": 14,
   "z": -1,
   "name": "Wood_Ash_Trunk"
  },
  {
   "x": -7,
   "y": 15,
   "z": -1,
   "name": "Wood_Ash_Trunk"
  },
  {
   "x": -7,
   "y": 16,
   "z": -1,
   "name": "Wood_Ash_Trunk_Full"
  },
  {
   "x": -7,
   "y": 17,
   "z": -1,
   "name": "Rubble_Stone"
  },
  {
   "x": -7,
   "y": 20,
   "z": -1,
   "name": "Plant_Crop_Mushroom_Shelve_Green"
  },
  {
   "x": -7,
   "y": 21,
   "z": -1,
   "name": "Plant_Crop_Mushroom_Shelve_Green"
  },
  {
   "x": -7,
   "y": 27,
   "z": -1,
   "name": "Wood_Ash_Trunk_Full"
  },
  {
   "x": -7,
   "y": 30,
   "z": -1,
   "name": "Plant_Leaves_Ash"
  },
  {
   "x": -7,
   "y": 31,
   "z": -1,
   "name": "Plant_Leaves_Ash"
  },
  {
   "x": -7,
   "y": 0,
   "z": 0,
   "name": "Rock_Stone"
  },
  {
   "x": -7,
   "y": 1,
   "z": 0,
   "name": "Rock_Stone"
  },
  {
   "x": -7,
   "y": 2,
   "z": 0,
   "name": "Rock_Stone"
  },
  {
   "x": -7,
   "y": 3,
   "z": 0,
   "name": "Rock_Stone"
  },
  {
   "x": -7,
   "y": 4,
   "z": 0,
   "name": "Rock_Stone"
  },
  {
   "x": -7,
   "y": 5,
   "z": 0,
   "name": "Rock_Stone"
  },
  {
   "x": -7,
   "y": 6,
   "z": 0,
   "name": "Rock_Stone"
  },
  {
   "x": -7,
   "y": 7,
   "z": 0,
   "name": "Rock_Stone"
  },
  {
   "x": -7,
   "y": 8,
   "z": 0,
   "name": "Rock_Stone"
  },
  {
   "x": -7,
   "y": 9,
   "z": 0,
   "name": "Rock_Stone"
  },
  {
   "x": -7,
   "y": 10,
   "z": 0,
   "name": "Rock_Stone"
  },
  {
   "x": -7,
   "y": 11,
   "z": 0,
   "name": "Rock_Stone"
  },
  {
   "x": -7,
   "y": 12,
   "z": 0,
   "name": "Rock_Stone"
  },
  {
   "x": -7,
   "y": 13,
   "z": 0,
   "name": "Rock_Stone"
  },
  {
   "x": -7,
   "y": 14,
   "z": 0,
   "name": "Rock_Stone"
  },
  {
   "x": -7,
   "y": 15,
   "z": 0,
   "name": "Rock_Stone"
  },
  {
   "x": -7,
   "y": 16,
   "z": 0,
   "name": "Rock_Stone"
  },
  {
   "x": -7,
   "y": 17,
   "z": 0,
   "name": "Plant_Moss_Wall_Green_Dark",
   "rotation": 3
  },
  {
   "x": -7,
   "y": 27,
   "z": 0,
   "name": "Wood_Ash_Trunk_Full"
  },
  {
   "x": -7,
   "y": 28,
   "z": 0,
   "name": "Wood_Ash_Trunk_Full"
  },
  {
   "x": -7,
   "y": 29,
   "z": 0,
   "name": "Wood_Ash_Branch_Long"
  },
  {
   "x": -7,
   "y": 30,
   "z": 0,
   "name": "Plant_Leaves_Ash"
  },
  {
   "x": -7,
   "y": 31,
   "z": 0,
   "name": "Plant_Leaves_Ash"
  },
  {
   "x": -7,
   "y": 32,
   "z": 0,
   "name": "Plant_Leaves_Ash"
  },
  {
   "x": -7,
   "y": 0,
   "z": 1,
   "name": "Rock_Stone"
  },
  {
   "x": -7,
   "y": 1,
   "z": 1,
   "name": "Rock_Stone"
  },
  {
   "x": -7,
   "y": 2,
   "z": 1,
   "name": "Rock_Stone"
  },
  {
   "x": -7,
   "y": 3,
   "z": 1,
   "name": "Rock_Stone"
  },
  {
   "x": -7,
   "y": 4,
   "z": 1,
   "name": "Rock_Stone"
  },
  {
   "x": -7,
   "y": 5,
   "z": 1,
   "name": "Rock_Stone"
  },
  {
   "x": -7,
   "y": 6,
   "z": 1,
   "name": "Rock_Stone"
  },
  {
   "x": -7,
   "y": 7,
   "z": 1,
   "name": "Rock_Stone"
  },
  {
   "x": -7,
   "y": 8,
   "z": 1,
   "name": "Rock_Stone"
  },
  {
   "x": -7,
   "y": 9,
   "z": 1,
   "name": "Rock_Stone"
  },
  {
   "x": -7,
   "y": 10,
   "z": 1,
   "name": "Rock_Stone"
  },
  {
   "x": -7,
   "y": 11,
   "z": 1,
   "name": "Soil_Gravel"
  },
  {
   "x": -7,
   "y": 12,
   "z": 1,
   "name": "Rock_Stone"
  },
  {
   "x": -7,
   "y": 13,
   "z": 1,
   "name": "Rock_Stone"
  },
  {
   "x": -7,
   "y": 14,
   "z": 1,
   "name": "Rock_Stone"
  },
  {
   "x": -7,
   "y": 15,
   "z": 1,
   "name": "Rock_Stone"
  },
  {
   "x": -7,
   "y": 16,
   "z": 1,
   "name": "Rock_Stone"
  },
  {
   "x": -7,
   "y": 17,
   "z": 1,
   "name": "Plant_Moss_Rug_Green_Dark"
  },
  {
   "x": -7,
   "y": 27,
   "z": 1,
   "name": "Plant_Vine_Hanging"
  },
  {
   "x": -7,
   "y": 28,
   "z": 1,
   "name": "Plant_Leaves_Ash"
  },
  {
   "x": -7,
   "y": 29,
   "z": 1,
   "name": "Plant_Leaves_Ash"
  },
  {
   "x": -7,
   "y": 30,
   "z": 1,
   "name": "Plant_Leaves_Ash"
  },
  {
   "x": -7,
   "y": 31,
   "z": 1,
   "name": "Plant_Leaves_Ash"
  },
  {
   "x": -7,
   "y": 0,
   "z": 2,
   "name": "Rock_Stone"
  },
  {
   "x": -7,
   "y": 1,
   "z": 2,
   "name": "Rock_Stone"
  },
  {
   "x": -7,
   "y": 2,
   "z": 2,
   "name": "Rock_Stone"
  },
  {
   "x": -7,
   "y": 3,
   "z": 2,
   "name": "Rock_Stone"
  },
  {
   "x": -7,
   "y": 4,
   "z": 2,
   "name": "Rock_Stone"
  },
  {
   "x": -7,
   "y": 5,
   "z": 2,
   "name": "Rock_Stone"
  },
  {
   "x": -7,
   "y": 6,
   "z": 2,
   "name": "Rock_Stone"
  },
  {
   "x": -7,
   "y": 7,
   "z": 2,
   "name": "Rock_Stone"
  },
  {
   "x": -7,
   "y": 8,
   "z": 2,
   "name": "Rock_Stone"
  },
  {
   "x": -7,
   "y": 9,
   "z": 2,
   "name": "Rock_Stone"
  },
  {
   "x": -7,
   "y": 10,
   "z": 2,
   "name": "Rock_Stone"
  },
  {
   "x": -7,
   "y": 11,
   "z": 2,
   "name": "Rock_Stone"
  },
  {
   "x": -7,
   "y": 12,
   "z": 2,
   "name": "Soil_Gravel"
  },
  {
   "x": -7,
   "y": 13,
   "z": 2,
   "name": "Rock_Stone"
  },
  {
   "x": -7,
   "y": 14,
   "z": 2,
   "name": "Rock_Stone"
  },
  {
   "x": -7,
   "y": 15,
   "z": 2,
   "name": "Rock_Stone"
  },
  {
   "x": -7,
   "y": 16,
   "z": 2,
   "name": "Plant_Moss_Rug_Green_Dark"
  },
  {
   "x": -7,
   "y": 28,
   "z": 2,
   "name": "Plant_Vine_Wall"
  },
  {
   "x": -7,
   "y": 29,
   "z": 2,
   "name": "Plant_Leaves_Ash"
  },
  {
   "x": -7,
   "y": 30,
   "z": 2,
   "name": "Plant_Leaves_Ash"
  },
  {
   "x": -7,
   "y": 31,
   "z": 2,
   "name": "Plant_Leaves_Ash"
  },
  {
   "x": -7,
   "y": 0,
   "z": 3,
   "name": "Rock_Stone"
  },
  {
   "x": -7,
   "y": 1,
   "z": 3,
   "name": "Rock_Stone"
  },
  {
   "x": -7,
   "y": 2,
   "z": 3,
   "name": "Rock_Stone"
  },
  {
   "x": -7,
   "y": 3,
   "z": 3,
   "name": "Rock_Stone"
  },
  {
   "x": -7,
   "y": 4,
   "z": 3,
   "name": "Rock_Stone"
  },
  {
   "x": -7,
   "y": 5,
   "z": 3,
   "name": "Rock_Stone"
  },
  {
   "x": -7,
   "y": 6,
   "z": 3,
   "name": "Rock_Stone"
  },
  {
   "x": -7,
   "y": 7,
   "z": 3,
   "name": "Rock_Stone"
  },
  {
   "x": -7,
   "y": 8,
   "z": 3,
   "name": "Rock_Stone"
  },
  {
   "x": -7,
   "y": 9,
   "z": 3,
   "name": "Rock_Stone"
  },
  {
   "x": -7,
   "y": 10,
   "z": 3,
   "name": "Rock_Stone"
  },
  {
   "x": -7,
   "y": 11,
   "z": 3,
   "name": "Rock_Stone"
  },
  {
   "x": -7,
   "y": 12,
   "z": 3,
   "name": "Rock_Stone"
  },
  {
   "x": -7,
   "y": 13,
   "z": 3,
   "name": "Soil_Gravel"
  },
  {
   "x": -7,
   "y": 14,
   "z": 3,
   "name": "Rock_Stone"
  },
  {
   "x": -7,
   "y": 30,
   "z": 3,
   "name": "Plant_Leaves_Ash"
  },
  {
   "x": -7,
   "y": 0,
   "z": 4,
   "name": "Rock_Stone"
  },
  {
   "x": -7,
   "y": 1,
   "z": 4,
   "name": "Rock_Stone"
  },
  {
   "x": -7,
   "y": 2,
   "z": 4,
   "name": "Rock_Stone"
  },
  {
   "x": -7,
   "y": 3,
   "z": 4,
   "name": "Rock_Stone"
  },
  {
   "x": -7,
   "y": 4,
   "z": 4,
   "name": "Rock_Stone"
  },
  {
   "x": -7,
   "y": 5,
   "z": 4,
   "name": "Rock_Stone"
  },
  {
   "x": -7,
   "y": 6,
   "z": 4,
   "name": "Rock_Stone"
  },
  {
   "x": -7,
   "y": 7,
   "z": 4,
   "name": "Rock_Stone"
  },
  {
   "x": -7,
   "y": 8,
   "z": 4,
   "name": "Rock_Stone"
  },
  {
   "x": -7,
   "y": 9,
   "z": 4,
   "name": "Rock_Stone"
  },
  {
   "x": -7,
   "y": 10,
   "z": 4,
   "name": "Rock_Stone"
  },
  {
   "x": -7,
   "y": 11,
   "z": 4,
   "name": "Rock_Stone"
  },
  {
   "x": -7,
   "y": 12,
   "z": 4,
   "name": "Rock_Stone"
  },
  {
   "x": -7,
   "y": 13,
   "z": 4,
   "name": "Soil_Gravel"
  },
  {
   "x": -7,
   "y": 14,
   "z": 4,
   "name": "Rock_Stone"
  },
  {
   "x": -7,
   "y": 15,
   "z": 4,
   "name": "Rock_Stone"
  },
  {
   "x": -7,
   "y": 0,
   "z": 5,
   "name": "Rock_Stone"
  },
  {
   "x": -7,
   "y": 1,
   "z": 5,
   "name": "Rock_Stone"
  },
  {
   "x": -7,
   "y": 2,
   "z": 5,
   "name": "Rock_Stone"
  },
  {
   "x": -7,
   "y": 3,
   "z": 5,
   "name": "Rock_Stone"
  },
  {
   "x": -7,
   "y": 4,
   "z": 5,
   "name": "Rock_Stone"
  },
  {
   "x": -7,
   "y": 5,
   "z": 5,
   "name": "Rock_Stone"
  },
  {
   "x": -7,
   "y": 6,
   "z": 5,
   "name": "Rock_Stone"
  },
  {
   "x": -7,
   "y": 7,
   "z": 5,
   "name": "Rock_Stone"
  },
  {
   "x": -7,
   "y": 8,
   "z": 5,
   "name": "Rock_Stone"
  },
  {
   "x": -7,
   "y": 9,
   "z": 5,
   "name": "Rock_Stone"
  },
  {
   "x": -7,
   "y": 10,
   "z": 5,
   "name": "Rock_Stone"
  },
  {
   "x": -7,
   "y": 11,
   "z": 5,
   "name": "Rock_Stone"
  },
  {
   "x": -7,
   "y": 12,
   "z": 5,
   "name": "Rock_Stone"
  },
  {
   "x": -7,
   "y": 13,
   "z": 5,
   "name": "Rock_Stone"
  },
  {
   "x": -7,
   "y": 14,
   "z": 5,
   "name": "Rock_Stone"
  },
  {
   "x": -7,
   "y": 15,
   "z": 5,
   "name": "Rock_Stone"
  },
  {
   "x": -7,
   "y": 16,
   "z": 5,
   "name": "Rock_Stone"
  },
  {
   "x": -7,
   "y": 0,
   "z": 6,
   "name": "Rock_Stone"
  },
  {
   "x": -7,
   "y": 1,
   "z": 6,
   "name": "Rock_Stone"
  },
  {
   "x": -7,
   "y": 2,
   "z": 6,
   "name": "Rock_Stone"
  },
  {
   "x": -7,
   "y": 3,
   "z": 6,
   "name": "Rock_Stone"
  },
  {
   "x": -7,
   "y": 4,
   "z": 6,
   "name": "Rock_Stone"
  },
  {
   "x": -7,
   "y": 5,
   "z": 6,
   "name": "Rock_Stone"
  },
  {
   "x": -7,
   "y": 6,
   "z": 6,
   "name": "Rock_Stone"
  },
  {
   "x": -7,
   "y": 7,
   "z": 6,
   "name": "Rock_Stone"
  },
  {
   "x": -7,
   "y": 8,
   "z": 6,
   "name": "Rock_Stone"
  },
  {
   "x": -7,
   "y": 9,
   "z": 6,
   "name": "Rock_Stone"
  },
  {
   "x": -7,
   "y": 10,
   "z": 6,
   "name": "Rock_Stone"
  },
  {
   "x": -7,
   "y": 11,
   "z": 6,
   "name": "Rock_Stone"
  },
  {
   "x": -7,
   "y": 12,
   "z": 6,
   "name": "Rock_Stone"
  },
  {
   "x": -7,
   "y": 13,
   "z": 6,
   "name": "Rock_Stone"
  },
  {
   "x": -7,
   "y": 14,
   "z": 6,
   "name": "Rock_Stone"
  },
  {
   "x": -7,
   "y": 15,
   "z": 6,
   "name": "Rock_Stone"
  },
  {
   "x": -7,
   "y": 16,
   "z": 6,
   "name": "Rock_Stone"
  },
  {
   "x": -7,
   "y": 17,
   "z": 6,
   "name": "Rock_Stone"
  },
  {
   "x": -7,
   "y": 18,
   "z": 6,
   "name": "Rock_Stone"
  },
  {
   "x": -7,
   "y": 0,
   "z": 7,
   "name": "Rock_Stone"
  },
  {
   "x": -7,
   "y": 1,
   "z": 7,
   "name": "Rock_Stone"
  },
  {
   "x": -7,
   "y": 2,
   "z": 7,
   "name": "Rock_Stone"
  },
  {
   "x": -7,
   "y": 3,
   "z": 7,
   "name": "Rock_Stone"
  },
  {
   "x": -7,
   "y": 4,
   "z": 7,
   "name": "Rock_Stone"
  },
  {
   "x": -7,
   "y": 5,
   "z": 7,
   "name": "Rock_Stone"
  },
  {
   "x": -7,
   "y": 6,
   "z": 7,
   "name": "Rock_Stone"
  },
  {
   "x": -7,
   "y": 7,
   "z": 7,
   "name": "Rock_Stone"
  },
  {
   "x": -7,
   "y": 8,
   "z": 7,
   "name": "Rock_Stone"
  },
  {
   "x": -7,
   "y": 9,
   "z": 7,
   "name": "Rock_Stone"
  },
  {
   "x": -7,
   "y": 10,
   "z": 7,
   "name": "Rock_Stone"
  },
  {
   "x": -7,
   "y": 11,
   "z": 7,
   "name": "Rock_Stone"
  },
  {
   "x": -7,
   "y": 12,
   "z": 7,
   "name": "Rock_Stone"
  },
  {
   "x": -7,
   "y": 13,
   "z": 7,
   "name": "Rock_Stone"
  },
  {
   "x": -7,
   "y": 14,
   "z": 7,
   "name": "Soil_Gravel"
  },
  {
   "x": -7,
   "y": 15,
   "z": 7,
   "name": "Rock_Stone"
  },
  {
   "x": -7,
   "y": 16,
   "z": 7,
   "name": "Rock_Stone"
  },
  {
   "x": -7,
   "y": 17,
   "z": 7,
   "name": "Rock_Stone"
  },
  {
   "x": -7,
   "y": 18,
   "z": 7,
   "name": "Rock_Stone"
  },
  {
   "x": -7,
   "y": 1,
   "z": 8,
   "name": "Rock_Stone"
  },
  {
   "x": -7,
   "y": 2,
   "z": 8,
   "name": "Rock_Stone"
  },
  {
   "x": -7,
   "y": 3,
   "z": 8,
   "name": "Rock_Stone"
  },
  {
   "x": -7,
   "y": 4,
   "z": 8,
   "name": "Rock_Stone"
  },
  {
   "x": -7,
   "y": 5,
   "z": 8,
   "name": "Rock_Stone"
  },
  {
   "x": -7,
   "y": 6,
   "z": 8,
   "name": "Rock_Stone"
  },
  {
   "x": -7,
   "y": 7,
   "z": 8,
   "name": "Rock_Stone"
  },
  {
   "x": -7,
   "y": 8,
   "z": 8,
   "name": "Rock_Stone"
  },
  {
   "x": -7,
   "y": 9,
   "z": 8,
   "name": "Rock_Stone"
  },
  {
   "x": -7,
   "y": 10,
   "z": 8,
   "name": "Rock_Stone"
  },
  {
   "x": -7,
   "y": 11,
   "z": 8,
   "name": "Rock_Stone"
  },
  {
   "x": -7,
   "y": 12,
   "z": 8,
   "name": "Rock_Stone"
  },
  {
   "x": -7,
   "y": 13,
   "z": 8,
   "name": "Rock_Stone"
  },
  {
   "x": -7,
   "y": 14,
   "z": 8,
   "name": "Rock_Stone"
  },
  {
   "x": -7,
   "y": 15,
   "z": 8,
   "name": "Rock_Stone"
  },
  {
   "x": -7,
   "y": 16,
   "z": 8,
   "name": "Rock_Stone"
  },
  {
   "x": -7,
   "y": 1,
   "z": 9,
   "name": "Rock_Stone"
  },
  {
   "x": -7,
   "y": 2,
   "z": 9,
   "name": "Rock_Stone"
  },
  {
   "x": -7,
   "y": 3,
   "z": 9,
   "name": "Rock_Stone"
  },
  {
   "x": -7,
   "y": 4,
   "z": 9,
   "name": "Rock_Stone"
  },
  {
   "x": -7,
   "y": 5,
   "z": 9,
   "name": "Rock_Stone"
  },
  {
   "x": -7,
   "y": 6,
   "z": 9,
   "name": "Rock_Stone"
  },
  {
   "x": -7,
   "y": 7,
   "z": 9,
   "name": "Rock_Stone"
  },
  {
   "x": -7,
   "y": 8,
   "z": 9,
   "name": "Rock_Stone"
  },
  {
   "x": -7,
   "y": 9,
   "z": 9,
   "name": "Rock_Stone"
  },
  {
   "x": -7,
   "y": 10,
   "z": 9,
   "name": "Rock_Stone"
  },
  {
   "x": -7,
   "y": 11,
   "z": 9,
   "name": "Rock_Stone"
  },
  {
   "x": -7,
   "y": 12,
   "z": 9,
   "name": "Rock_Stone"
  },
  {
   "x": -7,
   "y": 13,
   "z": 9,
   "name": "Rock_Stone"
  },
  {
   "x": -7,
   "y": 2,
   "z": 10,
   "name": "Rock_Stone"
  },
  {
   "x": -7,
   "y": 3,
   "z": 10,
   "name": "Rock_Stone"
  },
  {
   "x": -7,
   "y": 4,
   "z": 10,
   "name": "Rock_Stone"
  },
  {
   "x": -7,
   "y": 5,
   "z": 10,
   "name": "Rock_Stone"
  },
  {
   "x": -7,
   "y": 6,
   "z": 10,
   "name": "Rock_Stone"
  },
  {
   "x": -7,
   "y": 7,
   "z": 10,
   "name": "Rock_Stone"
  },
  {
   "x": -7,
   "y": 8,
   "z": 10,
   "name": "Rock_Stone"
  },
  {
   "x": -7,
   "y": 9,
   "z": 10,
   "name": "Rock_Stone"
  },
  {
   "x": -7,
   "y": 5,
   "z": 11,
   "name": "Rock_Stone"
  },
  {
   "x": -6,
   "y": 5,
   "z": -10,
   "name": "Rock_Stone"
  },
  {
   "x": -6,
   "y": 6,
   "z": -10,
   "name": "Rock_Stone"
  },
  {
   "x": -6,
   "y": 7,
   "z": -10,
   "name": "Rock_Stone"
  },
  {
   "x": -6,
   "y": 8,
   "z": -10,
   "name": "Rock_Stone"
  },
  {
   "x": -6,
   "y": 9,
   "z": -10,
   "name": "Rock_Stone"
  },
  {
   "x": -6,
   "y": 2,
   "z": -9,
   "name": "Rock_Stone"
  },
  {
   "x": -6,
   "y": 3,
   "z": -9,
   "name": "Rock_Stone"
  },
  {
   "x": -6,
   "y": 4,
   "z": -9,
   "name": "Rock_Stone"
  },
  {
   "x": -6,
   "y": 5,
   "z": -9,
   "name": "Rock_Stone"
  },
  {
   "x": -6,
   "y": 6,
   "z": -9,
   "name": "Rock_Stone"
  },
  {
   "x": -6,
   "y": 7,
   "z": -9,
   "name": "Rock_Stone"
  },
  {
   "x": -6,
   "y": 8,
   "z": -9,
   "name": "Rock_Stone"
  },
  {
   "x": -6,
   "y": 9,
   "z": -9,
   "name": "Rock_Stone"
  },
  {
   "x": -6,
   "y": 10,
   "z": -9,
   "name": "Rock_Stone"
  },
  {
   "x": -6,
   "y": 11,
   "z": -9,
   "name": "Rock_Stone"
  },
  {
   "x": -6,
   "y": 12,
   "z": -9,
   "name": "Rock_Stone"
  },
  {
   "x": -6,
   "y": 23,
   "z": -9,
   "name": "Plant_Leaves_Ash"
  },
  {
   "x": -6,
   "y": 24,
   "z": -9,
   "name": "Plant_Leaves_Ash"
  },
  {
   "x": -6,
   "y": 1,
   "z": -8,
   "name": "Rock_Stone"
  },
  {
   "x": -6,
   "y": 2,
   "z": -8,
   "name": "Rock_Stone"
  },
  {
   "x": -6,
   "y": 3,
   "z": -8,
   "name": "Rock_Stone"
  },
  {
   "x": -6,
   "y": 4,
   "z": -8,
   "name": "Rock_Stone"
  },
  {
   "x": -6,
   "y": 5,
   "z": -8,
   "name": "Rock_Stone"
  },
  {
   "x": -6,
   "y": 6,
   "z": -8,
   "name": "Rock_Stone"
  },
  {
   "x": -6,
   "y": 7,
   "z": -8,
   "name": "Rock_Stone"
  },
  {
   "x": -6,
   "y": 8,
   "z": -8,
   "name": "Rock_Stone"
  },
  {
   "x": -6,
   "y": 9,
   "z": -8,
   "name": "Rock_Stone"
  },
  {
   "x": -6,
   "y": 10,
   "z": -8,
   "name": "Rock_Stone"
  },
  {
   "x": -6,
   "y": 11,
   "z": -8,
   "name": "Rock_Stone"
  },
  {
   "x": -6,
   "y": 12,
   "z": -8,
   "name": "Rock_Stone"
  },
  {
   "x": -6,
   "y": 13,
   "z": -8,
   "name": "Rock_Stone"
  },
  {
   "x": -6,
   "y": 14,
   "z": -8,
   "name": "Rock_Stone"
  },
  {
   "x": -6,
   "y": 15,
   "z": -8,
   "name": "Rock_Stone"
  },
  {
   "x": -6,
   "y": 23,
   "z": -8,
   "name": "Plant_Leaves_Ash"
  },
  {
   "x": -6,
   "y": 24,
   "z": -8,
   "name": "Wood_Ash_Branch_Long",
   "rotation": 4
  },
  {
   "x": -6,
   "y": 25,
   "z": -8,
   "name": "Plant_Leaves_Ash"
  },
  {
   "x": -6,
   "y": 1,
   "z": -7,
   "name": "Rock_Stone"
  },
  {
   "x": -6,
   "y": 2,
   "z": -7,
   "name": "Rock_Stone"
  },
  {
   "x": -6,
   "y": 3,
   "z": -7,
   "name": "Rock_Stone"
  },
  {
   "x": -6,
   "y": 4,
   "z": -7,
   "name": "Rock_Stone"
  },
  {
   "x": -6,
   "y": 5,
   "z": -7,
   "name": "Rock_Stone"
  },
  {
   "x": -6,
   "y": 6,
   "z": -7,
   "name": "Rock_Stone"
  },
  {
   "x": -6,
   "y": 7,
   "z": -7,
   "name": "Rock_Stone"
  },
  {
   "x": -6,
   "y": 8,
   "z": -7,
   "name": "Rock_Stone"
  },
  {
   "x": -6,
   "y": 9,
   "z": -7,
   "name": "Rock_Stone"
  },
  {
   "x": -6,
   "y": 10,
   "z": -7,
   "name": "Rock_Stone"
  },
  {
   "x": -6,
   "y": 11,
   "z": -7,
   "name": "Rock_Stone"
  },
  {
   "x": -6,
   "y": 12,
   "z": -7,
   "name": "Rock_Stone"
  },
  {
   "x": -6,
   "y": 13,
   "z": -7,
   "name": "Rock_Stone"
  },
  {
   "x": -6,
   "y": 14,
   "z": -7,
   "name": "Rock_Stone"
  },
  {
   "x": -6,
   "y": 15,
   "z": -7,
   "name": "Rock_Stone"
  },
  {
   "x": -6,
   "y": 16,
   "z": -7,
   "name": "Rock_Stone_Brick_Smooth"
  },
  {
   "x": -6,
   "y": 17,
   "z": -7,
   "name": "Rock_Stone_Brick_Smooth"
  },
  {
   "x": -6,
   "y": 24,
   "z": -7,
   "name": "Rock_Stone_Brick_Roof",
   "rotation": 3
  },
  {
   "x": -6,
   "y": 25,
   "z": -7,
   "name": "Plant_Leaves_Ash"
  },
  {
   "x": -6,
   "y": 28,
   "z": -7,
   "name": "Plant_Leaves_Ash"
  },
  {
   "x": -6,
   "y": 0,
   "z": -6,
   "name": "Rock_Stone"
  },
  {
   "x": -6,
   "y": 1,
   "z": -6,
   "name": "Rock_Stone"
  },
  {
   "x": -6,
   "y": 2,
   "z": -6,
   "name": "Rock_Stone"
  },
  {
   "x": -6,
   "y": 3,
   "z": -6,
   "name": "Rock_Stone"
  },
  {
   "x": -6,
   "y": 4,
   "z": -6,
   "name": "Rock_Stone"
  },
  {
   "x": -6,
   "y": 5,
   "z": -6,
   "name": "Rock_Stone"
  },
  {
   "x": -6,
   "y": 6,
   "z": -6,
   "name": "Rock_Stone"
  },
  {
   "x": -6,
   "y": 7,
   "z": -6,
   "name": "Rock_Stone"
  },
  {
   "x": -6,
   "y": 8,
   "z": -6,
   "name": "Rock_Stone"
  },
  {
   "x": -6,
   "y": 9,
   "z": -6,
   "name": "Rock_Stone"
  },
  {
   "x": -6,
   "y": 10,
   "z": -6,
   "name": "Rock_Stone"
  },
  {
   "x": -6,
   "y": 11,
