{
 "version": 8,
 "blockIdVersion": 11,
 "anchorX": -1,
 "anchorY": 8,
 "anchorZ": 1,
 "blocks": [
  {
   "x": -11,
   "y": 18,
   "z": 12,
   "name": "Plant_Leaves_Redwood"
  },
  {
   "x": -11,
   "y": 29,
   "z": 12,
   "name": "Plant_Leaves_Redwood"
  },
  {
   "x": -10,
   "y": 14,
   "z": -8,
   "name": "Soil_Grass"
  },
  {
   "x": -10,
   "y": 13,
   "z": -7,
   "name": "Soil_Dirt"
  },
  {
   "x": -10,
   "y": 14,
   "z": -7,
   "name": "Soil_Dirt"
  },
  {
   "x": -10,
   "y": 15,
   "z": -7,
   "name": "Soil_Grass"
  },
  {
   "x": -10,
   "y": 13,
   "z": -6,
   "name": "Soil_Dirt"
  },
  {
   "x": -10,
   "y": 14,
   "z": -6,
   "name": "Soil_Dirt"
  },
  {
   "x": -10,
   "y": 15,
   "z": -6,
   "name": "Soil_Grass"
  },
  {
   "x": -10,
   "y": 16,
   "z": -6,
   "name": "Plant_Flower_Common_White"
  },
  {
   "x": -10,
   "y": 13,
   "z": -5,
   "name": "Rock_Basalt"
  },
  {
   "x": -10,
   "y": 14,
   "z": -5,
   "name": "Soil_Dirt"
  },
  {
   "x": -10,
   "y": 15,
   "z": -5,
   "name": "Soil_Grass"
  },
  {
   "x": -10,
   "y": 14,
   "z": -4,
   "name": "Soil_Dirt"
  },
  {
   "x": -10,
   "y": 15,
   "z": -4,
   "name": "Soil_Grass"
  },
  {
   "x": -10,
   "y": 16,
   "z": -4,
   "name": "Plant_Grass_Winter_Short"
  },
  {
   "x": -10,
   "y": 14,
   "z": -3,
   "name": "Soil_Dirt"
  },
  {
   "x": -10,
   "y": 15,
   "z": -3,
   "name": "Soil_Grass"
  },
  {
   "x": -10,
   "y": 18,
   "z": 11,
   "name": "Plant_Leaves_Redwood"
  },
  {
   "x": -10,
   "y": 29,
   "z": 11,
   "name": "Plant_Leaves_Redwood"
  },
  {
   "x": -10,
   "y": 18,
   "z": 12,
   "name": "Plant_Leaves_Redwood"
  },
  {
   "x": -10,
   "y": 29,
   "z": 12,
   "name": "Plant_Leaves_Redwood"
  },
  {
   "x": -10,
   "y": 33,
   "z": 12,
   "name": "Plant_Leaves_Redwood"
  },
  {
   "x": -10,
   "y": 18,
   "z": 13,
   "name": "Plant_Leaves_Redwood"
  },
  {
   "x": -10,
   "y": 29,
   "z": 13,
   "name": "Plant_Leaves_Redwood"
  },
  {
   "x": -9,
   "y": 12,
   "z": -9,
   "name": "Rock_Basalt"
  },
  {
   "x": -9,
   "y": 13,
   "z": -9,
   "name": "Soil_Dirt"
  },
  {
   "x": -9,
   "y": 14,
   "z": -9,
   "name": "Soil_Grass"
  },
  {
   "x": -9,
   "y": 9,
   "z": -8,
   "name": "Rock_Basalt"
  },
  {
   "x": -9,
   "y": 10,
   "z": -8,
   "name": "Rock_Basalt"
  },
  {
   "x": -9,
   "y": 11,
   "z": -8,
   "name": "Rock_Basalt"
  },
  {
   "x": -9,
   "y": 12,
   "z": -8,
   "name": "Rock_Basalt"
  },
  {
   "x": -9,
   "y": 13,
   "z": -8,
   "name": "Soil_Dirt"
  },
  {
   "x": -9,
   "y": 14,
   "z": -8,
   "name": "Soil_Grass"
  },
  {
   "x": -9,
   "y": 15,
   "z": -8,
   "name": "Plant_Grass_Winter_Short"
  },
  {
   "x": -9,
   "y": 8,
   "z": -7,
   "name": "Rock_Basalt"
  },
  {
   "x": -9,
   "y": 9,
   "z": -7,
   "name": "Rock_Basalt"
  },
  {
   "x": -9,
   "y": 10,
   "z": -7,
   "name": "Rock_Basalt"
  },
  {
   "x": -9,
   "y": 11,
   "z": -7,
   "name": "Rock_Basalt"
  },
  {
   "x": -9,
   "y": 12,
   "z": -7,
   "name": "Rock_Basalt"
  },
  {
   "x": -9,
   "y": 13,
   "z": -7,
   "name": "Soil_Dirt"
  },
  {
   "x": -9,
   "y": 14,
   "z": -7,
   "name": "Soil_Dirt"
  },
  {
   "x": -9,
   "y": 15,
   "z": -7,
   "name": "Soil_Grass"
  },
  {
   "x": -9,
   "y": 16,
   "z": -7,
   "name": "Plant_Grass_Winter"
  },
  {
   "x": -9,
   "y": 8,
   "z": -6,
   "name": "Rock_Basalt"
  },
  {
   "x": -9,
   "y": 9,
   "z": -6,
   "name": "Rock_Basalt"
  },
  {
   "x": -9,
   "y": 10,
   "z": -6,
   "name": "Rock_Basalt"
  },
  {
   "x": -9,
   "y": 11,
   "z": -6,
   "name": "Rock_Basalt"
  },
  {
   "x": -9,
   "y": 12,
   "z": -6,
   "name": "Rock_Basalt"
  },
  {
   "x": -9,
   "y": 13,
   "z": -6,
   "name": "Soil_Dirt"
  },
  {
   "x": -9,
   "y": 14,
   "z": -6,
   "name": "Soil_Dirt"
  },
  {
   "x": -9,
   "y": 15,
   "z": -6,
   "name": "Soil_Grass"
  },
  {
   "x": -9,
   "y": 8,
   "z": -5,
   "name": "Rock_Basalt"
  },
  {
   "x": -9,
   "y": 9,
   "z": -5,
   "name": "Rock_Basalt"
  },
  {
   "x": -9,
   "y": 10,
   "z": -5,
   "name": "Rock_Basalt"
  },
  {
   "x": -9,
   "y": 11,
   "z": -5,
   "name": "Rock_Basalt"
  },
  {
   "x": -9,
   "y": 12,
   "z": -5,
   "name": "Rock_Basalt"
  },
  {
   "x": -9,
   "y": 13,
   "z": -5,
   "name": "Rock_Basalt"
  },
  {
   "x": -9,
   "y": 14,
   "z": -5,
   "name": "Soil_Dirt"
  },
  {
   "x": -9,
   "y": 15,
   "z": -5,
   "name": "Soil_Grass"
  },
  {
   "x": -9,
   "y": 16,
   "z": -5,
   "name": "Plant_Grass_Winter"
  },
  {
   "x": -9,
   "y": 9,
   "z": -4,
   "name": "Rock_Basalt"
  },
  {
   "x": -9,
   "y": 10,
   "z": -4,
   "name": "Rock_Basalt"
  },
  {
   "x": -9,
   "y": 11,
   "z": -4,
   "name": "Rock_Basalt"
  },
  {
   "x": -9,
   "y": 12,
   "z": -4,
   "name": "Rock_Basalt"
  },
  {
   "x": -9,
   "y": 13,
   "z": -4,
   "name": "Rock_Basalt"
  },
  {
   "x": -9,
   "y": 14,
   "z": -4,
   "name": "Soil_Dirt"
  },
  {
   "x": -9,
   "y": 15,
   "z": -4,
   "name": "Soil_Grass"
  },
  {
   "x": -9,
   "y": 16,
   "z": -4,
   "name": "Plant_Grass_Winter_Tall"
  },
  {
   "x": -9,
   "y": 17,
   "z": -4,
   "name": "Plant_Grass_Winter_Tall",
   "filler": 1024
  },
  {
   "x": -9,
   "y": 10,
   "z": -3,
   "name": "Rock_Basalt"
  },
  {
   "x": -9,
   "y": 11,
   "z": -3,
   "name": "Rock_Basalt"
  },
  {
   "x": -9,
   "y": 12,
   "z": -3,
   "name": "Rock_Basalt"
  },
  {
   "x": -9,
   "y": 13,
   "z": -3,
   "name": "Rock_Basalt"
  },
  {
   "x": -9,
   "y": 14,
   "z": -3,
   "name": "Soil_Dirt"
  },
  {
   "x": -9,
   "y": 15,
   "z": -3,
   "name": "Soil_Grass"
  },
  {
   "x": -9,
   "y": 12,
   "z": -2,
   "name": "Rock_Basalt"
  },
  {
   "x": -9,
   "y": 13,
   "z": -2,
   "name": "Rock_Basalt"
  },
  {
   "x": -9,
   "y": 14,
   "z": -2,
   "name": "Rock_Basalt"
  },
  {
   "x": -9,
   "y": 15,
   "z": -2,
   "name": "Soil_Dirt"
  },
  {
   "x": -9,
   "y": 16,
   "z": -2,
   "name": "Soil_Grass"
  },
  {
   "x": -9,
   "y": 14,
   "z": -1,
   "name": "Rock_Basalt"
  },
  {
   "x": -9,
   "y": 15,
   "z": -1,
   "name": "Soil_Dirt"
  },
  {
   "x": -9,
   "y": 16,
   "z": -1,
   "name": "Soil_Grass"
  },
  {
   "x": -9,
   "y": 9,
   "z": 2,
   "name": "Rock_Basalt"
  },
  {
   "x": -9,
   "y": 10,
   "z": 2,
   "name": "Rock_Basalt"
  },
  {
   "x": -9,
   "y": 11,
   "z": 2,
   "name": "Soil_Dirt"
  },
  {
   "x": -9,
   "y": 12,
   "z": 2,
   "name": "Soil_Grass"
  },
  {
   "x": -9,
   "y": 8,
   "z": 3,
   "name": "Rock_Basalt"
  },
  {
   "x": -9,
   "y": 9,
   "z": 3,
   "name": "Rock_Basalt"
  },
  {
   "x": -9,
   "y": 10,
   "z": 3,
   "name": "Rock_Basalt"
  },
  {
   "x": -9,
   "y": 11,
   "z": 3,
   "name": "Soil_Dirt"
  },
  {
   "x": -9,
   "y": 12,
   "z": 3,
   "name": "Soil_Grass"
  },
  {
   "x": -9,
   "y": 8,
   "z": 4,
   "name": "Rock_Basalt"
  },
  {
   "x": -9,
   "y": 9,
   "z": 4,
   "name": "Rock_Basalt"
  },
  {
   "x": -9,
   "y": 10,
   "z": 4,
   "name": "Soil_Dirt"
  },
  {
   "x": -9,
   "y": 11,
   "z": 4,
   "name": "Soil_Grass"
  },
  {
   "x": -9,
   "y": 7,
   "z": 5,
   "name": "Rock_Basalt"
  },
  {
   "x": -9,
   "y": 8,
   "z": 5,
   "name": "Rock_Basalt"
  },
  {
   "x": -9,
   "y": 9,
   "z": 5,
   "name": "Rock_Basalt"
  },
  {
   "x": -9,
   "y": 10,
   "z": 5,
   "name": "Soil_Dirt"
  },
  {
   "x": -9,
   "y": 11,
   "z": 5,
   "name": "Soil_Grass"
  },
  {
   "x": -9,
   "y": 7,
   "z": 6,
   "name": "Rock_Basalt"
  },
  {
   "x": -9,
   "y": 8,
   "z": 6,
   "name": "Rock_Basalt"
  },
  {
   "x": -9,
   "y": 9,
   "z": 6,
   "name": "Rock_Basalt"
  },
  {
   "x": -9,
   "y": 10,
   "z": 6,
   "name": "Soil_Dirt"
  },
  {
   "x": -9,
   "y": 11,
   "z": 6,
   "name": "Soil_Grass"
  },
  {
   "x": -9,
   "y": 12,
   "z": 6,
   "name": "Plant_Grass_Winter_Short"
  },
  {
   "x": -9,
   "y": 7,
   "z": 7,
   "name": "Rock_Basalt"
  },
  {
   "x": -9,
   "y": 8,
   "z": 7,
   "name": "Rock_Basalt"
  },
  {
   "x": -9,
   "y": 9,
   "z": 7,
   "name": "Rock_Basalt"
  },
  {
   "x": -9,
   "y": 10,
   "z": 7,
   "name": "Rock_Basalt"
  },
  {
   "x": -9,
   "y": 11,
   "z": 7,
   "name": "Soil_Grass"
  },
  {
   "x": -9,
   "y": 7,
   "z": 8,
   "name": "Rock_Basalt"
  },
  {
   "x": -9,
   "y": 8,
   "z": 8,
   "name": "Rock_Basalt"
  },
  {
   "x": -9,
   "y": 9,
   "z": 8,
   "name": "Rock_Basalt"
  },
  {
   "x": -9,
   "y": 10,
   "z": 8,
   "name": "Soil_Grass"
  },
  {
   "x": -9,
   "y": 8,
   "z": 9,
   "name": "Rock_Basalt"
  },
  {
   "x": -9,
   "y": 9,
   "z": 9,
   "name": "Rock_Basalt"
  },
  {
   "x": -9,
   "y": 10,
   "z": 9,
   "name": "Soil_Grass"
  },
  {
   "x": -9,
   "y": 8,
   "z": 10,
   "name": "Rock_Basalt"
  },
  {
   "x": -9,
   "y": 9,
   "z": 10,
   "name": "Soil_Dirt"
  },
  {
   "x": -9,
   "y": 10,
   "z": 10,
   "name": "Soil_Grass"
  },
  {
   "x": -9,
   "y": 8,
   "z": 11,
   "name": "Rock_Basalt"
  },
  {
   "x": -9,
   "y": 9,
   "z": 11,
   "name": "Soil_Dirt"
  },
  {
   "x": -9,
   "y": 10,
   "z": 11,
   "name": "Soil_Grass"
  },
  {
   "x": -9,
   "y": 18,
   "z": 11,
   "name": "Plant_Leaves_Redwood"
  },
  {
   "x": -9,
   "y": 29,
   "z": 11,
   "name": "Plant_Leaves_Redwood"
  },
  {
   "x": -9,
   "y": 33,
   "z": 11,
   "name": "Plant_Leaves_Redwood"
  },
  {
   "x": -9,
   "y": 9,
   "z": 12,
   "name": "Soil_Grass"
  },
  {
   "x": -9,
   "y": 18,
   "z": 12,
   "name": "Wood_Redwood_Branch_Corner",
   "rotation": 3
  },
  {
   "x": -9,
   "y": 29,
   "z": 12,
   "name": "Wood_Redwood_Branch_Corner",
   "rotation": 3
  },
  {
   "x": -9,
   "y": 30,
   "z": 12,
   "name": "Plant_Leaves_Redwood"
  },
  {
   "x": -9,
   "y": 33,
   "z": 12,
   "name": "Plant_Leaves_Redwood"
  },
  {
   "x": -9,
   "y": 18,
   "z": 13,
   "name": "Plant_Leaves_Redwood"
  },
  {
   "x": -9,
   "y": 29,
   "z": 13,
   "name": "Plant_Leaves_Redwood"
  },
  {
   "x": -9,
   "y": 33,
   "z": 13,
   "name": "Plant_Leaves_Redwood"
  },
  {
   "x": -9,
   "y": 18,
   "z": 14,
   "name": "Plant_Leaves_Redwood"
  },
  {
   "x": -8,
   "y": 13,
   "z": -12,
   "name": "Soil_Dirt"
  },
  {
   "x": -8,
   "y": 14,
   "z": -12,
   "name": "Soil_Grass"
  },
  {
   "x": -8,
   "y": 11,
   "z": -11,
   "name": "Rock_Basalt"
  },
  {
   "x": -8,
   "y": 12,
   "z": -11,
   "name": "Rock_Basalt"
  },
  {
   "x": -8,
   "y": 13,
   "z": -11,
   "name": "Soil_Dirt"
  },
  {
   "x": -8,
   "y": 14,
   "z": -11,
   "name": "Soil_Grass"
  },
  {
   "x": -8,
   "y": 8,
   "z": -10,
   "name": "Rock_Basalt"
  },
  {
   "x": -8,
   "y": 9,
   "z": -10,
   "name": "Rock_Basalt"
  },
  {
   "x": -8,
   "y": 10,
   "z": -10,
   "name": "Rock_Basalt"
  },
  {
   "x": -8,
   "y": 11,
   "z": -10,
   "name": "Rock_Basalt"
  },
  {
   "x": -8,
   "y": 12,
   "z": -10,
   "name": "Rock_Basalt"
  },
  {
   "x": -8,
   "y": 13,
   "z": -10,
   "name": "Soil_Dirt"
  },
  {
   "x": -8,
   "y": 14,
   "z": -10,
   "name": "Soil_Grass"
  },
  {
   "x": -8,
   "y": 6,
   "z": -9,
   "name": "Rock_Basalt"
  },
  {
   "x": -8,
   "y": 7,
   "z": -9,
   "name": "Rock_Basalt"
  },
  {
   "x": -8,
   "y": 8,
   "z": -9,
   "name": "Rock_Basalt"
  },
  {
   "x": -8,
   "y": 9,
   "z": -9,
   "name": "Rock_Basalt"
  },
  {
   "x": -8,
   "y": 10,
   "z": -9,
   "name": "Rock_Basalt"
  },
  {
   "x": -8,
   "y": 11,
   "z": -9,
   "name": "Rock_Basalt"
  },
  {
   "x": -8,
   "y": 12,
   "z": -9,
   "name": "Rock_Basalt"
  },
  {
   "x": -8,
   "y": 13,
   "z": -9,
   "name": "Soil_Dirt"
  },
  {
   "x": -8,
   "y": 14,
   "z": -9,
   "name": "Soil_Grass"
  },
  {
   "x": -8,
   "y": 15,
   "z": -9,
   "name": "Plant_Grass_Winter_Short"
  },
  {
   "x": -8,
   "y": 5,
   "z": -8,
   "name": "Rock_Basalt"
  },
  {
   "x": -8,
   "y": 6,
   "z": -8,
   "name": "Rock_Basalt"
  },
  {
   "x": -8,
   "y": 7,
   "z": -8,
   "name": "Rock_Basalt"
  },
  {
   "x": -8,
   "y": 8,
   "z": -8,
   "name": "Rock_Basalt"
  },
  {
   "x": -8,
   "y": 9,
   "z": -8,
   "name": "Rock_Basalt"
  },
  {
   "x": -8,
   "y": 10,
   "z": -8,
   "name": "Rock_Basalt"
  },
  {
   "x": -8,
   "y": 11,
   "z": -8,
   "name": "Rock_Basalt"
  },
  {
   "x": -8,
   "y": 12,
   "z": -8,
   "name": "Rock_Basalt"
  },
  {
   "x": -8,
   "y": 13,
   "z": -8,
   "name": "Soil_Dirt"
  },
  {
   "x": -8,
   "y": 14,
   "z": -8,
   "name": "Soil_Dirt"
  },
  {
   "x": -8,
   "y": 15,
   "z": -8,
   "name": "Soil_Grass"
  },
  {
   "x": -8,
   "y": 16,
   "z": -8,
   "name": "Plant_Grass_Winter_Short"
  },
  {
   "x": -8,
   "y": 5,
   "z": -7,
   "name": "Rock_Basalt"
  },
  {
   "x": -8,
   "y": 6,
   "z": -7,
   "name": "Rock_Basalt"
  },
  {
   "x": -8,
   "y": 7,
   "z": -7,
   "name": "Rock_Basalt"
  },
  {
   "x": -8,
   "y": 8,
   "z": -7,
   "name": "Rock_Basalt"
  },
  {
   "x": -8,
   "y": 9,
   "z": -7,
   "name": "Rock_Basalt"
  },
  {
   "x": -8,
   "y": 10,
   "z": -7,
   "name": "Rock_Basalt"
  },
  {
   "x": -8,
   "y": 11,
   "z": -7,
   "name": "Rock_Basalt"
  },
  {
   "x": -8,
   "y": 12,
   "z": -7,
   "name": "Rock_Basalt"
  },
  {
   "x": -8,
   "y": 13,
   "z": -7,
   "name": "Rock_Basalt"
  },
  {
   "x": -8,
   "y": 14,
   "z": -7,
   "name": "Soil_Dirt"
  },
  {
   "x": -8,
   "y": 15,
   "z": -7,
   "name": "Soil_Grass"
  },
  {
   "x": -8,
   "y": 16,
   "z": -7,
   "name": "Plant_Grass_Winter"
  },
  {
   "x": -8,
   "y": 5,
   "z": -6,
   "name": "Rock_Basalt"
  },
  {
   "x": -8,
   "y": 6,
   "z": -6,
   "name": "Rock_Basalt"
  },
  {
   "x": -8,
   "y": 7,
   "z": -6,
   "name": "Rock_Basalt"
  },
  {
   "x": -8,
   "y": 8,
   "z": -6,
   "name": "Rock_Basalt"
  },
  {
   "x": -8,
   "y": 9,
   "z": -6,
   "name": "Rock_Basalt"
  },
  {
   "x": -8,
   "y": 10,
   "z": -6,
   "name": "Rock_Basalt"
  },
  {
   "x": -8,
   "y": 11,
   "z": -6,
   "name": "Rock_Basalt"
  },
  {
   "x": -8,
   "y": 12,
   "z": -6,
   "name": "Rock_Basalt"
  },
  {
   "x": -8,
   "y": 13,
   "z": -6,
   "name": "Rock_Basalt"
  },
  {
   "x": -8,
   "y": 14,
   "z": -6,
   "name": "Soil_Dirt"
  },
  {
   "x": -8,
   "y": 15,
   "z": -6,
   "name": "Soil_Grass"
  },
  {
   "x": -8,
   "y": 16,
   "z": -6,
   "name": "Plant_Grass_Winter_Tall"
  },
  {
   "x": -8,
   "y": 17,
   "z": -6,
   "name": "Plant_Grass_Winter_Tall",
   "filler": 1024
  },
  {
   "x": -8,
   "y": 32,
   "z": -6,
   "name": "Plant_Leaves_Redwood"
  },
  {
   "x": -8,
   "y": 5,
   "z": -5,
   "name": "Rock_Basalt"
  },
  {
   "x": -8,
   "y": 6,
   "z": -5,
   "name": "Rock_Basalt"
  },
  {
   "x": -8,
   "y": 7,
   "z": -5,
   "name": "Rock_Basalt"
  },
  {
   "x": -8,
   "y": 8,
   "z": -5,
   "name": "Rock_Basalt"
  },
  {
   "x": -8,
   "y": 9,
   "z": -5,
   "name": "Rock_Basalt"
  },
  {
   "x": -8,
   "y": 10,
   "z": -5,
   "name": "Rock_Basalt"
  },
  {
   "x": -8,
   "y": 11,
   "z": -5,
   "name": "Rock_Basalt"
  },
  {
   "x": -8,
   "y": 12,
   "z": -5,
   "name": "Rock_Basalt"
  },
  {
   "x": -8,
   "y": 13,
   "z": -5,
   "name": "Rock_Basalt"
  },
  {
   "x": -8,
   "y": 14,
   "z": -5,
   "name": "Soil_Dirt"
  },
  {
   "x": -8,
   "y": 15,
   "z": -5,
   "name": "Soil_Grass"
  },
  {
   "x": -8,
   "y": 16,
   "z": -5,
   "name": "Plant_Grass_Winter_Tall"
  },
  {
   "x": -8,
   "y": 17,
   "z": -5,
   "name": "Plant_Grass_Winter_Tall",
   "filler": 1024
  },
  {
   "x": -8,
   "y": 5,
   "z": -4,
   "name": "Rock_Basalt"
  },
  {
   "x": -8,
   "y": 6,
   "z": -4,
   "name": "Rock_Basalt"
  },
  {
   "x": -8,
   "y": 7,
   "z": -4,
   "name": "Rock_Basalt"
  },
  {
   "x": -8,
   "y": 8,
   "z": -4,
   "name": "Rock_Basalt"
  },
  {
   "x": -8,
   "y": 9,
   "z": -4,
   "name": "Rock_Basalt"
  },
  {
   "x": -8,
   "y": 10,
   "z": -4,
   "name": "Rock_Basalt"
  },
  {
   "x": -8,
   "y": 11,
   "z": -4,
   "name": "Rock_Basalt"
  },
  {
   "x": -8,
   "y": 12,
   "z": -4,
   "name": "Rock_Basalt"
  },
  {
   "x": -8,
   "y": 13,
   "z": -4,
   "name": "Rock_Basalt"
  },
  {
   "x": -8,
   "y": 14,
   "z": -4,
   "name": "Soil_Dirt"
  },
  {
   "x": -8,
   "y": 15,
   "z": -4,
   "name": "Soil_Grass"
  },
  {
   "x": -8,
   "y": 16,
   "z": -4,
   "name": "Plant_Grass_Winter"
  },
  {
   "x": -8,
   "y": 6,
   "z": -3,
   "name": "Rock_Basalt"
  },
  {
   "x": -8,
   "y": 7,
   "z": -3,
   "name": "Rock_Basalt"
  },
  {
   "x": -8,
   "y": 8,
   "z": -3,
   "name": "Rock_Basalt"
  },
  {
   "x": -8,
   "y": 9,
   "z": -3,
   "name": "Rock_Basalt"
  },
  {
   "x": -8,
   "y": 10,
   "z": -3,
   "name": "Rock_Basalt"
  },
  {
   "x": -8,
   "y": 11,
   "z": -3,
   "name": "Rock_Basalt"
  },
  {
   "x": -8,
   "y": 12,
   "z": -3,
   "name": "Rock_Basalt"
  },
  {
   "x": -8,
   "y": 13,
   "z": -3,
   "name": "Rock_Basalt"
  },
  {
   "x": -8,
   "y": 14,
   "z": -3,
   "name": "Soil_Dirt"
  },
  {
   "x": -8,
   "y": 15,
   "z": -3,
   "name": "Soil_Dirt"
  },
  {
   "x": -8,
   "y": 16,
   "z": -3,
   "name": "Soil_Grass"
  },
  {
   "x": -8,
   "y": 7,
   "z": -2,
   "name": "Rock_Basalt"
  },
  {
   "x": -8,
   "y": 8,
   "z": -2,
   "name": "Rock_Basalt"
  },
  {
   "x": -8,
   "y": 9,
   "z": -2,
   "name": "Rock_Basalt"
  },
  {
   "x": -8,
   "y": 10,
   "z": -2,
   "name": "Rock_Basalt"
  },
  {
   "x": -8,
   "y": 11,
   "z": -2,
   "name": "Rock_Basalt"
  },
  {
   "x": -8,
   "y": 12,
   "z": -2,
   "name": "Rock_Basalt"
  },
  {
   "x": -8,
   "y": 13,
   "z": -2,
   "name": "Rock_Basalt"
  },
  {
   "x": -8,
   "y": 14,
   "z": -2,
   "name": "Rock_Basalt"
  },
  {
   "x": -8,
   "y": 15,
   "z": -2,
   "name": "Soil_Dirt"
  },
  {
   "x": -8,
   "y": 16,
   "z": -2,
   "name": "Soil_Grass"
  },
  {
   "x": -8,
   "y": 17,
   "z": -2,
   "name": "Plant_Grass_Winter_Short"
  },
  {
   "x": -8,
   "y": 8,
   "z": -1,
   "name": "Rock_Basalt"
  },
  {
   "x": -8,
   "y": 9,
   "z": -1,
   "name": "Rock_Basalt"
  },
  {
   "x": -8,
   "y": 10,
   "z": -1,
   "name": "Rock_Basalt"
  },
  {
   "x": -8,
   "y": 11,
   "z": -1,
   "name": "Rock_Basalt"
  },
  {
   "x": -8,
   "y": 12,
   "z": -1,
   "name": "Rock_Basalt"
  },
  {
   "x": -8,
   "y": 13,
   "z": -1,
   "name": "Rock_Basalt"
  },
  {
   "x": -8,
   "y": 14,
   "z": -1,
   "name": "Rock_Basalt"
  },
  {
   "x": -8,
   "y": 15,
   "z": -1,
   "name": "Soil_Dirt"
  },
  {
   "x": -8,
   "y": 16,
   "z": -1,
   "name": "Soil_Grass"
  },
  {
   "x": -8,
   "y": 17,
   "z": -1,
   "name": "Plant_Flower_Common_White"
  },
  {
   "x": -8,
   "y": 10,
   "z": 0,
   "name": "Rock_Basalt"
  },
  {
   "x": -8,
   "y": 11,
   "z": 0,
   "name": "Rock_Basalt"
  },
  {
   "x": -8,
   "y": 12,
   "z": 0,
   "name": "Soil_Grass"
  },
  {
   "x": -8,
   "y": 15,
   "z": 0,
   "name": "Soil_Dirt"
  },
  {
   "x": -8,
   "y": 16,
   "z": 0,
   "name": "Soil_Grass"
  },
  {
   "x": -8,
   "y": 7,
   "z": 1,
   "name": "Rock_Basalt"
  },
  {
   "x": -8,
   "y": 8,
   "z": 1,
   "name": "Rock_Basalt"
  },
  {
   "x": -8,
   "y": 9,
   "z": 1,
   "name": "Rock_Basalt"
  },
  {
   "x": -8,
   "y": 10,
   "z": 1,
   "name": "Rock_Basalt"
  },
  {
   "x": -8,
   "y": 11,
   "z": 1,
   "name": "Soil_Dirt"
  },
  {
   "x": -8,
   "y": 12,
   "z": 1,
   "name": "Soil_Grass"
  },
  {
   "x": -8,
   "y": 5,
   "z": 2,
   "name": "Rock_Basalt"
  },
  {
   "x": -8,
   "y": 6,
   "z": 2,
   "name": "Rock_Basalt"
  },
  {
   "x": -8,
   "y": 7,
   "z": 2,
   "name": "Rock_Basalt"
  },
  {
   "x": -8,
   "y": 8,
   "z": 2,
   "name": "Rock_Basalt"
  },
  {
   "x": -8,
   "y": 9,
   "z": 2,
   "name": "Rock_Basalt"
  },
  {
   "x": -8,
   "y": 10,
   "z": 2,
   "name": "Rock_Basalt"
  },
  {
   "x": -8,
   "y": 11,
   "z": 2,
   "name": "Soil_Dirt"
  },
  {
   "x": -8,
   "y": 12,
   "z": 2,
   "name": "Soil_Grass"
  },
  {
   "x": -8,
   "y": 4,
   "z": 3,
   "name": "Rock_Basalt"
  },
  {
   "x": -8,
   "y": 5,
   "z": 3,
   "name": "Rock_Basalt"
  },
  {
   "x": -8,
   "y": 6,
   "z": 3,
   "name": "Rock_Basalt"
  },
  {
   "x": -8,
   "y": 7,
   "z": 3,
   "name": "Rock_Basalt"
  },
  {
   "x": -8,
   "y": 8,
   "z": 3,
   "name": "Rock_Basalt"
  },
  {
   "x": -8,
   "y": 9,
   "z": 3,
   "name": "Rock_Basalt"
  },
  {
   "x": -8,
   "y": 10,
   "z": 3,
   "name": "Rock_Basalt"
  },
  {
   "x": -8,
   "y": 11,
   "z": 3,
   "name": "Soil_Dirt"
  },
  {
   "x": -8,
   "y": 12,
   "z": 3,
   "name": "Soil_Grass"
  },
  {
   "x": -8,
   "y": 4,
   "z": 4,
   "name": "Rock_Basalt"
  },
  {
   "x": -8,
   "y": 5,
   "z": 4,
   "name": "Rock_Basalt"
  },
  {
   "x": -8,
   "y": 6,
   "z": 4,
   "name": "Rock_Basalt"
  },
  {
   "x": -8,
   "y": 7,
   "z": 4,
   "name": "Rock_Basalt"
  },
  {
   "x": -8,
   "y": 8,
   "z": 4,
   "name": "Rock_Basalt"
  },
  {
   "x": -8,
   "y": 9,
   "z": 4,
   "name": "Rock_Basalt"
  },
  {
   "x": -8,
   "y": 10,
   "z": 4,
   "name": "Soil_Dirt"
  },
  {
   "x": -8,
   "y": 11,
   "z": 4,
   "name": "Soil_Grass"
  },
  {
   "x": -8,
   "y": 12,
   "z": 4,
   "name": "Plant_Grass_Winter_Tall"
  },
  {
   "x": -8,
   "y": 13,
   "z": 4,
   "name": "Plant_Grass_Winter_Tall",
   "filler": 1024
  },
  {
   "x": -8,
   "y": 4,
   "z": 5,
   "name": "Rock_Basalt"
  },
  {
   "x": -8,
   "y": 5,
   "z": 5,
   "name": "Rock_Basalt"
  },
  {
   "x": -8,
   "y": 6,
   "z": 5,
   "name": "Rock_Basalt"
  },
  {
   "x": -8,
   "y": 7,
   "z": 5,
   "name": "Rock_Basalt"
  },
  {
   "x": -8,
   "y": 8,
   "z": 5,
   "name": "Rock_Basalt"
  },
  {
   "x": -8,
   "y": 9,
   "z": 5,
   "name": "Rock_Basalt"
  },
  {
   "x": -8,
   "y": 10,
   "z": 5,
   "name": "Soil_Dirt"
  },
  {
   "x": -8,
   "y": 11,
   "z": 5,
   "name": "Soil_Grass"
  },
  {
   "x": -8,
   "y": 12,
   "z": 5,
   "name": "Plant_Grass_Winter_Tall"
  },
  {
   "x": -8,
   "y": 13,
   "z": 5,
   "name": "Plant_Grass_Winter_Tall",
   "filler": 1024
  },
  {
   "x": -8,
   "y": 4,
   "z": 6,
   "name": "Rock_Basalt"
  },
  {
   "x": -8,
   "y": 5,
   "z": 6,
   "name": "Rock_Basalt"
  },
  {
   "x": -8,
   "y": 6,
   "z": 6,
   "name": "Rock_Basalt"
  },
  {
   "x": -8,
   "y": 7,
   "z": 6,
   "name": "Rock_Basalt"
  },
  {
   "x": -8,
   "y": 8,
   "z": 6,
   "name": "Rock_Basalt"
  },
  {
   "x": -8,
   "y": 9,
   "z": 6,
   "name": "Rock_Basalt"
  },
  {
   "x": -8,
   "y": 10,
   "z": 6,
   "name": "Soil_Dirt"
  },
  {
   "x": -8,
   "y": 11,
   "z": 6,
   "name": "Soil_Grass"
  },
  {
   "x": -8,
   "y": 3,
   "z": 7,
   "name": "Rock_Basalt"
  },
  {
   "x": -8,
   "y": 4,
   "z": 7,
   "name": "Rock_Basalt"
  },
  {
   "x": -8,
   "y": 5,
   "z": 7,
   "name": "Rock_Basalt"
  },
  {
   "x": -8,
   "y": 6,
   "z": 7,
   "name": "Rock_Basalt"
  },
  {
   "x": -8,
   "y": 7,
   "z": 7,
   "name": "Rock_Basalt"
  },
  {
   "x": -8,
   "y": 8,
   "z": 7,
   "name": "Rock_Basalt"
  },
  {
   "x": -8,
   "y": 9,
   "z": 7,
   "name": "Rock_Basalt"
  },
  {
   "x": -8,
   "y": 10,
   "z": 7,
   "name": "Soil_Dirt"
  },
  {
   "x": -8,
   "y": 11,
   "z": 7,
   "name": "Soil_Grass"
  },
  {
   "x": -8,
   "y": 12,
   "z": 7,
   "name": "Plant_Grass_Winter_Short"
  },
  {
   "x": -8,
   "y": 3,
   "z": 8,
   "name": "Rock_Basalt"
  },
  {
   "x": -8,
   "y": 4,
   "z": 8,
   "name": "Rock_Basalt"
  },
  {
   "x": -8,
   "y": 5,
   "z": 8,
   "name": "Rock_Basalt"
  },
  {
   "x": -8,
   "y": 6,
   "z": 8,
   "name": "Rock_Basalt"
  },
  {
   "x": -8,
   "y": 7,
   "z": 8,
   "name": "Rock_Basalt"
  },
  {
   "x": -8,
   "y": 8,
   "z": 8,
   "name": "Rock_Basalt"
  },
  {
   "x": -8,
   "y": 9,
   "z": 8,
   "name": "Soil_Dirt"
  },
  {
   "x": -8,
   "y": 10,
   "z": 8,
   "name": "Soil_Grass"
  },
  {
   "x": -8,
   "y": 18,
   "z": 8,
   "name": "Plant_Leaves_Redwood"
  },
  {
   "x": -8,
   "y": 3,
   "z": 9,
   "name": "Rock_Basalt"
  },
  {
   "x": -8,
   "y": 4,
   "z": 9,
   "name": "Rock_Basalt"
  },
  {
   "x": -8,
   "y": 5,
   "z": 9,
   "name": "Rock_Basalt"
  },
  {
   "x": -8,
   "y": 6,
   "z": 9,
   "name": "Rock_Basalt"
  },
  {
   "x": -8,
   "y": 7,
   "z": 9,
   "name": "Rock_Basalt"
  },
  {
   "x": -8,
   "y": 8,
   "z": 9,
   "name": "Rock_Basalt"
  },
  {
   "x": -8,
   "y": 9,
   "z": 9,
   "name": "Soil_Dirt"
  },
  {
   "x": -8,
   "y": 10,
   "z": 9,
   "name": "Soil_Grass"
  },
  {
   "x": -8,
   "y": 18,
   "z": 9,
   "name": "Plant_Leaves_Redwood"
  },
  {
   "x": -8,
   "y": 22,
   "z": 9,
   "name": "Plant_Leaves_Redwood"
  },
  {
   "x": -8,
   "y": 3,
   "z": 10,
   "name": "Rock_Basalt"
  },
  {
   "x": -8,
   "y": 4,
   "z": 10,
   "name": "Rock_Basalt"
  },
  {
   "x": -8,
   "y": 5,
   "z": 10,
   "name": "Rock_Basalt"
  },
  {
   "x": -8,
   "y": 6,
   "z": 10,
   "name": "Rock_Basalt"
  },
  {
   "x": -8,
   "y": 7,
   "z": 10,
   "name": "Rock_Basalt"
  },
  {
   "x": -8,
   "y": 8,
   "z": 10,
   "name": "Rock_Basalt"
  },
  {
   "x": -8,
   "y": 9,
   "z": 10,
   "name": "Soil_Dirt"
  },
  {
   "x": -8,
   "y": 10,
   "z": 10,
   "name": "Soil_Needles"
  },
  {
   "x": -8,
   "y": 18,
   "z": 10,
   "name": "Plant_Leaves_Redwood"
  },
  {
   "x": -8,
   "y": 22,
   "z": 10,
   "name": "Plant_Leaves_Redwood"
  },
  {
   "x": -8,
   "y": 26,
   "z": 10,
   "name": "Plant_Leaves_Redwood"
  },
  {
   "x": -8,
   "y": 30,
   "z": 10,
   "name": "Plant_Leaves_Redwood"
  },
  {
   "x": -8,
   "y": 4,
   "z": 11,
   "name": "Rock_Basalt"
  },
  {
   "x": -8,
   "y": 5,
   "z": 11,
   "name": "Rock_Basalt"
  },
  {
   "x": -8,
   "y": 6,
   "z": 11,
   "name": "Rock_Basalt"
  },
  {
   "x": -8,
   "y": 7,
   "z": 11,
   "name": "Rock_Basalt"
  },
  {
   "x": -8,
   "y": 8,
   "z": 11,
   "name": "Rock_Basalt"
  },
  {
   "x": -8,
   "y": 9,
   "z": 11,
   "name": "Soil_Dirt"
  },
  {
   "x": -8,
   "y": 10,
   "z": 11,
   "name": "Soil_Needles"
  },
  {
   "x": -8,
   "y": 18,
   "z": 11,
   "name": "Plant_Leaves_Redwood"
  },
  {
   "x": -8,
   "y": 22,
   "z": 11,
   "name": "Plant_Leaves_Redwood"
  },
  {
   "x": -8,
   "y": 26,
   "z": 11,
   "name": "Plant_Leaves_Redwood"
  },
  {
   "x": -8,
   "y": 29,
   "z": 11,
   "name": "Plant_Leaves_Redwood"
  },
  {
   "x": -8,
   "y": 30,
   "z": 11,
   "name": "Plant_Leaves_Redwood"
  },
  {
   "x": -8,
   "y": 33,
   "z": 11,
   "name": "Plant_Leaves_Redwood"
  },
  {
   "x": -8,
   "y": 5,
   "z": 12,
   "name": "Rock_Basalt"
  },
  {
   "x": -8,
   "y": 6,
   "z": 12,
   "name": "Rock_Basalt"
  },
  {
   "x": -8,
   "y": 7,
   "z": 12,
   "name": "Rock_Basalt"
  },
  {
   "x": -8,
   "y": 8,
   "z": 12,
   "name": "Rock_Basalt"
  },
  {
   "x": -8,
   "y": 9,
   "z": 12,
   "name": "Wood_Redwood_Trunk"
  },
  {
   "x": -8,
   "y": 10,
   "z": 12,
   "name": "Wood_Redwood_Trunk_Full"
  },
  {
   "x": -8,
   "y": 11,
   "z": 12,
   "name": "Plant_Crop_Mushroom_Shelve_Brown"
  },
  {
   "x": -8,
   "y": 18,
   "z": 12,
   "name": "Wood_Redwood_Branch_Long",
   "rotation": 5
  },
  {
   "x": -8,
   "y": 19,
   "z": 12,
   "name": "Plant_Leaves_Redwood"
  },
  {
   "x": -8,
   "y": 29,
   "z": 12,
   "name": "Wood_Redwood_Branch_Long",
   "rotation": 5
  },
  {
   "x": -8,
   "y": 30,
   "z": 12,
   "name": "Plant_Leaves_Redwood"
  },
  {
   "x": -8,
   "y": 33,
   "z": 12,
   "name": "Wood_Redwood_Branch_Long",
   "rotation": 5
  },
  {
   "x": -8,
   "y": 35,
   "z": 12,
   "name": "Plant_Leaves_Redwood"
  },
  {
   "x": -8,
   "y": 36,
   "z": 12,
   "name": "Plant_Leaves_Redwood"
  },
  {
   "x": -8,
   "y": 37,
   "z": 12,
   "name": "Plant_Leaves_Redwood"
  },
  {
   "x": -8,
   "y": 6,
   "z": 13,
   "name": "Rock_Basalt"
  },
  {
   "x": -8,
   "y": 7,
   "z": 13,
   "name": "Rock_Basalt"
  },
  {
   "x": -8,
   "y": 8,
   "z": 13,
   "name": "Rock_Basalt"
  },
  {
   "x": -8,
   "y": 9,
   "z": 13,
   "name": "Soil_Grass"
  },
  {
   "x": -8,
   "y": 18,
   "z": 13,
   "name": "Plant_Leaves_Redwood"
  },
  {
   "x": -8,
   "y": 21,
   "z": 13,
   "name": "Plant_Leaves_Redwood"
  },
  {
   "x": -8,
   "y": 26,
   "z": 13,
   "name": "Plant_Leaves_Redwood"
  },
  {
   "x": -8,
   "y": 29,
   "z": 13,
   "name": "Plant_Leaves_Redwood"
  },
  {
   "x": -8,
   "y": 31,
   "z": 13,
   "name": "Plant_Leaves_Redwood"
  },
  {
   "x": -8,
   "y": 33,
   "z": 13,
   "name": "Plant_Leaves_Redwood"
  },
  {
   "x": -8,
   "y": 34,
   "z": 13,
   "name": "Plant_Leaves_Redwood"
  },
  {
   "x": -8,
   "y": 35,
   "z": 13,
   "name": "Plant_Leaves_Redwood"
  },
  {
   "x": -8,
   "y": 8,
   "z": 14,
   "name": "Rock_Basalt"
  },
  {
   "x": -8,
   "y": 9,
   "z": 14,
   "name": "Soil_Grass"
  },
  {
   "x": -8,
   "y": 18,
   "z": 14,
   "name": "Plant_Leaves_Redwood"
  },
  {
   "x": -8,
   "y": 26,
   "z": 14,
   "name": "Plant_Leaves_Redwood"
  },
  {
   "x": -8,
   "y": 29,
   "z": 14,
   "name": "Plant_Leaves_Redwood"
  },
  {
   "x": -8,
   "y": 34,
   "z": 14,
   "name": "Plant_Leaves_Redwood"
  },
  {
   "x": -8,
   "y": 18,
   "z": 15,
   "name": "Plant_Leaves_Redwood"
  },
  {
   "x": -8,
   "y": 21,
   "z": 15,
   "name": "Plant_Leaves_Redwood"
  },
  {
   "x": -8,
   "y": 26,
   "z": 15,
   "name": "Plant_Leaves_Redwood"
  },
  {
   "x": -7,
   "y": 12,
   "z": -13,
   "name": "Rock_Basalt"
  },
  {
   "x": -7,
   "y": 13,
   "z": -13,
   "name": "Soil_Dirt"
  },
  {
   "x": -7,
   "y": 14,
   "z": -13,
   "name": "Soil_Grass"
  },
  {
   "x": -7,
   "y": 9,
   "z": -12,
   "name": "Rock_Basalt"
  },
  {
   "x": -7,
   "y": 10,
   "z": -12,
   "name": "Rock_Basalt"
  },
  {
   "x": -7,
   "y": 11,
   "z": -12,
   "name": "Rock_Basalt"
  },
  {
   "x": -7,
   "y": 12,
   "z": -12,
   "name": "Rock_Basalt"
  },
  {
   "x": -7,
   "y": 13,
   "z": -12,
   "name": "Soil_Dirt"
  },
  {
   "x": -7,
   "y": 14,
   "z": -12,
   "name": "Soil_Grass"
  },
  {
   "x": -7,
   "y": 4,
   "z": -11,
   "name": "Rock_Basalt"
  },
  {
   "x": -7,
   "y": 5,
   "z": -11,
   "name": "Rock_Basalt"
  },
  {
   "x": -7,
   "y": 6,
   "z": -11,
   "name": "Rock_Basalt"
  },
  {
   "x": -7,
   "y": 7,
   "z": -11,
   "name": "Rock_Basalt"
  },
  {
   "x": -7,
   "y": 8,
   "z": -11,
   "name": "Rock_Basalt"
  },
  {
   "x": -7,
   "y": 9,
   "z": -11,
   "name": "Rock_Basalt"
  },
  {
   "x": -7,
   "y": 10,
   "z": -11,
   "name": "Rock_Basalt"
  },
  {
   "x": -7,
   "y": 11,
   "z": -11,
   "name": "Rock_Basalt"
  },
  {
   "x": -7,
   "y": 12,
   "z": -11,
   "name": "Rock_Basalt"
  },
  {
   "x": -7,
   "y": 13,
   "z": -11,
   "name": "Soil_Dirt"
  },
  {
   "x": -7,
   "y": 14,
   "z": -11,
   "name": "Soil_Grass"
  },
  {
   "x": -7,
   "y": 3,
   "z": -10,
   "name": "Rock_Basalt"
  },
  {
   "x": -7,
   "y": 4,
   "z": -10,
   "name": "Rock_Basalt"
  },
  {
   "x": -7,
   "y": 5,
   "z": -10,
   "name": "Rock_Basalt"
  },
  {
   "x": -7,
   "y": 6,
   "z": -10,
   "name": "Rock_Basalt"
  },
  {
   "x": -7,
   "y": 7,
   "z": -10,
   "name": "Rock_Basalt"
  },
  {
   "x": -7,
   "y": 8,
   "z": -10,
   "name": "Rock_Basalt"
  },
  {
   "x": -7,
   "y": 9,
   "z": -10,
   "name": "Rock_Basalt"
  },
  {
   "x": -7,
   "y": 10,
   "z": -10,
   "name": "Rock_Basalt"
  },
  {
   "x": -7,
   "y": 11,
   "z": -10,
   "name": "Rock_Basalt"
  },
  {
   "x": -7,
   "y": 12,
   "z": -10,
   "name": "Rock_Basalt"
  },
  {
   "x": -7,
   "y": 13,
   "z": -10,
   "name": "Soil_Dirt"
  },
  {
   "x": -7,
   "y": 14,
   "z": -10,
   "name": "Soil_Grass"
  },
  {
   "x": -7,
   "y": 3,
   "z": -9,
   "name": "Rock_Basalt"
  },
  {
   "x": -7,
   "y": 4,
   "z": -9,
   "name": "Rock_Basalt"
  },
  {
   "x": -7,
   "y": 5,
   "z": -9,
   "name": "Rock_Basalt"
  },
  {
   "x": -7,
   "y": 6,
   "z": -9,
   "name": "Rock_Basalt"
  },
  {
   "x": -7,
   "y": 7,
   "z": -9,
   "name": "Rock_Basalt"
  },
  {
   "x": -7,
   "y": 8,
   "z": -9,
   "name": "Rock_Basalt"
  },
  {
   "x": -7,
   "y": 9,
   "z": -9,
   "name": "Rock_Basalt"
  },
  {
   "x": -7,
   "y": 10,
   "z": -9,
   "name": "Rock_Basalt"
  },
  {
   "x": -7,
   "y": 11,
   "z": -9,
   "name": "Rock_Basalt"
  },
  {
   "x": -7,
   "y": 12,
   "z": -9,
   "name": "Rock_Basalt"
  },
  {
   "x": -7,
   "y": 13,
   "z": -9,
   "name": "Rock_Basalt"
  },
  {
   "x": -7,
   "y": 14,
   "z": -9,
   "name": "Soil_Grass"
  },
  {
   "x": -7,
   "y": 3,
   "z": -8,
   "name": "Rock_Basalt"
  },
  {
   "x": -7,
   "y": 4,
   "z": -8,
   "name": "Rock_Basalt"
  },
  {
   "x": -7,
   "y": 5,
   "z": -8,
   "name": "Rock_Basalt"
  },
  {
   "x": -7,
   "y": 6,
   "z": -8,
   "name": "Rock_Basalt"
  },
  {
   "x": -7,
   "y": 7,
   "z": -8,
   "name": "Rock_Basalt"
  },
  {
   "x": -7,
   "y": 8,
   "z": -8,
   "name": "Rock_Basalt"
  },
  {
   "x": -7,
   "y": 9,
   "z": -8,
   "name": "Rock_Basalt"
  },
  {
   "x": -7,
   "y": 10,
   "z": -8,
   "name": "Rock_Basalt"
  },
  {
   "x": -7,
   "y": 11,
   "z": -8,
   "name": "Rock_Basalt"
  },
  {
   "x": -7,
   "y": 12,
   "z": -8,
   "name": "Rock_Basalt"
  },
  {
   "x": -7,
   "y": 13,
   "z": -8,
   "name": "Rock_Basalt"
  },
  {
   "x": -7,
   "y": 14,
   "z": -8,
   "name": "Soil_Dirt"
  },
  {
   "x": -7,
   "y": 15,
   "z": -8,
   "name": "Soil_Grass"
  },
  {
   "x": -7,
   "y": 3,
   "z": -7,
   "name": "Rock_Basalt"
  },
  {
   "x": -7,
   "y": 4,
   "z": -7,
   "name": "Rock_Basalt"
  },
  {
   "x": -7,
   "y": 5,
   "z": -7,
   "name": "Rock_Basalt"
  },
  {
   "x": -7,
   "y": 6,
   "z": -7,
   "name": "Rock_Basalt"
  },
  {
   "x": -7,
   "y": 7,
   "z": -7,
   "name": "Rock_Basalt"
  },
  {
   "x": -7,
   "y": 8,
   "z": -7,
   "name": "Rock_Basalt"
  },
  {
   "x": -7,
   "y": 9,
   "z": -7,
   "name": "Rock_Basalt"
  },
  {
   "x": -7,
   "y": 10,
   "z": -7,
   "name": "Rock_Basalt"
  },
  {
   "x": -7,
   "y": 11,
   "z": -7,
   "name": "Rock_Basalt"
  },
  {
   "x": -7,
   "y": 12,
   "z": -7,
   "name": "Rock_Basalt"
  },
  {
   "x": -7,
   "y": 13,
   "z": -7,
   "name": "Rock_Basalt"
  },
  {
   "x": -7,
   "y": 14,
   "z": -7,
   "name": "Soil_Dirt"
  },
  {
   "x": -7,
   "y": 15,
   "z": -7,
   "name": "Soil_Grass"
  },
  {
   "x": -7,
   "y": 3,
   "z": -6,
   "name": "Rock_Basalt"
  },
  {
   "x": -7,
   "y": 4,
   "z": -6,
   "name": "Rock_Basalt"
  },
  {
   "x": -7,
   "y": 5,
   "z": -6,
   "name": "Rock_Basalt"
  },
  {
   "x": -7,
   "y": 6,
   "z": -6,
   "name": "Rock_Basalt"
  },
  {
   "x": -7,
   "y": 7,
   "z": -6,
   "name": "Rock_Basalt"
  },
  {
   "x": -7,
   "y": 8,
   "z": -6,
   "name": "Rock_Basalt"
  },
  {
   "x": -7,
   "y": 9,
   "z": -6,
   "name": "Rock_Basalt"
  },
  {
   "x": -7,
   "y": 10,
   "z": -6,
   "name": "Rock_Basalt"
  },
  {
   "x": -7,
   "y": 11,
   "z": -6,
   "name": "Rock_Basalt"
  },
  {
   "x": -7,
   "y": 12,
   "z": -6,
   "name": "Rock_Basalt"
  },
  {
   "x": -7,
   "y": 13,
   "z": -6,
   "name": "Rock_Basalt"
  },
  {
   "x": -7,
   "y": 14,
   "z": -6,
   "name": "Soil_Dirt"
  },
  {
   "x": -7,
   "y": 15,
   "z": -6,
   "name": "Soil_Grass"
  },
  {
   "x": -7,
   "y": 16,
   "z": -6,
   "name": "Plant_Grass_Winter"
  },
  {
   "x": -7,
   "y": 32,
   "z": -6,
   "name": "Plant_Leaves_Redwood"
  },
  {
   "x": -7,
   "y": 3,
   "z": -5,
   "name": "Rock_Basalt"
  },
  {
   "x": -7,
   "y": 4,
   "z": -5,
   "name": "Rock_Basalt"
  },
  {
   "x": -7,
   "y": 5,
   "z": -5,
   "name": "Rock_Basalt"
  },
  {
   "x": -7,
   "y": 6,
   "z": -5,
   "name": "Rock_Basalt"
  },
  {
   "x": -7,
   "y": 7,
   "z": -5,
   "name": "Rock_Basalt"
  },
  {
   "x": -7,
   "y": 8,
   "z": -5,
   "name": "Rock_Basalt"
  },
  {
   "x": -7,
   "y": 9,
   "z": -5,
   "name": "Rock_Basalt"
  },
  {
   "x": -7,
   "y": 10,
   "z": -5,
   "name": "Rock_Basalt"
  },
  {
   "x": -7,
   "y": 11,
   "z": -5,
   "name": "Rock_Basalt"
  },
  {
   "x": -7,
   "y": 12,
   "z": -5,
   "name": "Rock_Basalt"
  },
  {
   "x": -7,
   "y": 13,
   "z": -5,
   "name": "Rock_Basalt"
  },
  {
   "x": -7,
   "y": 14,
   "z": -5,
   "name": "Soil_Dirt"
  },
  {
   "x": -7,
   "y": 15,
   "z": -5,
   "name": "Soil_Grass"
  },
  {
   "x": -7,
   "y": 16,
   "z": -5,
   "name": "Plant_Grass_Winter_Tall"
  },
  {
   "x": -7,
   "y": 17,
   "z": -5,
   "name": "Plant_Grass_Winter_Tall",
   "filler": 1024
  },
  {
   "x": -7,
   "y": 3,
   "z": -4,
   "name": "Rock_Basalt"
  },
  {
   "x": -7,
   "y": 4,
   "z": -4,
   "name": "Rock_Basalt"
  },
  {
   "x": -7,
   "y": 5,
   "z": -4,
   "name": "Rock_Basalt"
  },
  {
   "x": -7,
   "y": 6,
   "z": -4,
   "name": "Rock_Basalt"
  },
  {
   "x": -7,
   "y": 7,
   "z": -4,
   "name": "Rock_Basalt"
  },
  {
   "x": -7,
   "y": 8,
   "z": -4,
   "name": "Rock_Basalt"
  },
  {
   "x": -7,
   "y": 9,
   "z": -4,
   "name": "Rock_Basalt"
  },
  {
   "x": -7,
   "y": 10,
   "z": -4,
   "name": "Rock_Basalt"
  },
  {
   "x": -7,
   "y": 11,
   "z": -4,
   "name": "Rock_Basalt"
  },
  {
   "x": -7,
   "y": 12,
   "z": -4,
   "name": "Rock_Basalt"
  },
  {
   "x": -7,
   "y": 13,
   "z": -4,
   "name": "Rock_Basalt"
  },
  {
   "x": -7,
   "y": 14,
   "z": -4,
   "name": "Soil_Dirt"
  },
  {
   "x": -7,
   "y": 15,
   "z": -4,
   "name": "Soil_Grass"
  },
  {
   "x": -7,
   "y": 16,
   "z": -4,
   "name": "Plant_Grass_Winter_Tall"
  },
  {
   "x": -7,
   "y": 17,
   "z": -4,
   "name": "Plant_Grass_Winter_Tall",
   "filler": 1024
  },
  {
   "x": -7,
   "y": 3,
   "z": -3,
   "name": "Rock_Basalt"
  },
  {
   "x": -7,
   "y": 4,
   "z": -3,
   "name": "Rock_Basalt"
  },
  {
   "x": -7,
   "y": 5,
   "z": -3,
   "name": "Rock_Basalt"
  },
  {
   "x": -7,
   "y": 6,
   "z": -3,
   "name": "Rock_Basalt"
  },
  {
   "x": -7,
   "y": 7,
   "z": -3,
   "name": "Rock_Basalt"
  },
  {
   "x": -7,
   "y": 8,
   "z": -3,
   "name": "Rock_Basalt"
  },
  {
   "x": -7,
   "y": 9,
   "z": -3,
   "name": "Rock_Basalt"
  },
  {
   "x": -7,
   "y": 10,
   "z": -3,
   "name": "Rock_Basalt"
  },
  {
   "x": -7,
   "y": 11,
   "z": -3,
   "name": "Rock_Basalt"
  },
  {
   "x": -7,
   "y": 12,
   "z": -3,
   "name": "Rock_Basalt"
  },
  {
   "x": -7,
   "y": 13,
   "z": -3,
   "name": "Rock_Basalt"
  },
  {
   "x": -7,
   "y": 14,
   "z": -3,
   "name": "Soil_Dirt"
  },
  {
   "x": -7,
   "y": 15,
   "z": -3,
   "name": "Soil_Dirt"
  },
  {
   "x": -7,
   "y": 16,
   "z": -3,
   "name": "Soil_Grass"
  },
  {
   "x": -7,
   "y": 17,
   "z": -3,
   "name": "Plant_Grass_Winter"
  },
  {
   "x": -7,
   "y": 4,
   "z": -2,
   "name": "Rock_Basalt"
  },
  {
   "x": -7,
   "y": 5,
   "z": -2,
   "name": "Rock_Basalt"
  },
  {
   "x": -7,
   "y": 6,
   "z": -2,
   "name": "Rock_Basalt"
  },
  {
   "x": -7,
   "y": 7,
   "z": -2,
   "name": "Rock_Basalt"
  },
  {
   "x": -7,
   "y": 8,
   "z": -2,
   "name": "Rock_Basalt"
  },
  {
   "x": -7,
   "y": 9,
   "z": -2,
   "name": "Rock_Basalt"
  },
  {
   "x": -7,
   "y": 10,
   "z": -2,
   "name": "Rock_Basalt"
  },
  {
   "x": -7,
   "y": 11,
   "z": -2,
   "name": "Rock_Basalt"
  },
  {
   "x": -7,
   "y": 12,
   "z": -2,
   "name": "Rock_Basalt"
  },
  {
   "x": -7,
   "y": 13,
   "z": -2,
   "name": "Rock_Basalt"
  },
  {
   "x": -7,
   "y": 14,
   "z": -2,
   "name": "Rock_Basalt"
  },
  {
   "x": -7,
   "y": 15,
   "z": -2,
   "name": "Soil_Dirt"
  },
  {
   "x": -7,
   "y": 16,
   "z": -2,
   "name": "Soil_Grass"
  },
  {
   "x": -7,
   "y": 17,
   "z": -2,
   "name": "Plant_Grass_Winter_Short"
  },
  {
   "x": -7,
   "y": 5,
   "z": -1,
   "name": "Rock_Basalt"
  },
  {
   "x": -7,
   "y": 6,
   "z": -1,
   "name": "Rock_Basalt"
  },
  {
   "x": -7,
   "y": 7,
   "z": -1,
   "name": "Rock_Basalt"
  },
  {
   "x": -7,
   "y": 8,
   "z": -1,
   "name": "Rock_Basalt"
  },
  {
   "x": -7,
   "y": 9,
   "z": -1,
   "name": "Rock_Basalt"
  },
  {
   "x": -7,
   "y": 10,
   "z": -1,
   "name": "Rock_Basalt"
  },
  {
   "x": -7,
   "y": 11,
   "z": -1,
   "name": "Rock_Basalt"
  },
  {
   "x": -7,
   "y": 12,
   "z": -1,
   "name": "Rock_Basalt"
  },
  {
   "x": -7,
   "y": 13,
   "z": -1,
   "name": "Rock_Basalt"
  },
  {
   "x": -7,
   "y": 14,
   "z": -1,
   "name": "Rock_Basalt"
  },
  {
   "x": -7,
   "y": 15,
   "z": -1,
   "name": "Soil_Dirt"
  },
  {
   "x": -7,
   "y": 16,
   "z": -1,
   "name": "Soil_Grass"
  },
  {
   "x": -7,
   "y": 6,
   "z": 0,
   "name": "Rock_Basalt"
  },
  {
   "x": -7,
   "y": 7,
   "z": 0,
   "name": "Rock_Basalt"
  },
  {
   "x": -7,
   "y": 8,
   "z": 0,
   "name": "Rock_Basalt"
  },
  {
   "x": -7,
   "y": 9,
   "z": 0,
   "name": "Rock_Basalt"
  },
  {
   "x": -7,
   "y": 10,
   "z": 0,
   "name": "Rock_Basalt"
  },
  {
   "x": -7,
   "y": 11,
   "z": 0,
   "name": "Rock_Basalt"
  },
  {
   "x": -7,
   "y": 12,
   "z": 0,
   "name": "Soil_Grass"
  },
  {
   "x": -7,
   "y": 14,
   "z": 0,
   "name": "Rock_Basalt"
  },
  {
   "x": -7,
   "y": 15,
   "z": 0,
   "name": "Soil_Dirt"
  },
  {
   "x": -7,
   "y": 16,
   "z": 0,
   "name": "Soil_Grass"
  },
  {
   "x": -7,
   "y": 4,
   "z": 1,
   "name": "Rock_Basalt"
  },
  {
   "x": -7,
   "y": 5,
   "z": 1,
   "name": "Rock_Basalt"
  },
  {
   "x": -7,
   "y": 6,
   "z": 1,
   "name": "Rock_Basalt"
  },
  {
   "x": -7,
   "y": 7,
   "z": 1,
   "name": "Rock_Basalt"
  },
  {
   "x": -7,
   "y": 8,
   "z": 1,
   "name": "Rock_Basalt"
  },
  {
   "x": -7,
   "y": 9,
   "z": 1,
   "name": "Rock_Basalt"
  },
  {
   "x": -7,
   "y": 10,
   "z": 1,
   "name": "Rock_Basalt"
  },
  {
   "x": -7,
   "y": 11,
   "z": 1,
   "name": "Soil_Dirt"
  },
  {
   "x": -7,
   "y": 12,
   "z": 1,
   "name": "Soil_Grass"
  },
  {
   "x": -7,
   "y": 3,
   "z": 2,
   "name": "Rock_Basalt"
  },
  {
   "x": -7,
   "y": 4,
   "z": 2,
   "name": "Rock_Basalt"
  },
  {
   "x": -7,
   "y": 5,
   "z": 2,
   "name": "Rock_Basalt"
  },
  {
   "x": -7,
   "y": 6,
   "z": 2,
   "name": "Rock_Basalt"
  },
  {
   "x": -7,
   "y": 7,
   "z": 2,
   "name": "Rock_Basalt"
  },
  {
   "x": -7,
   "y": 8,
   "z": 2,
   "name": "Rock_Basalt"
  },
  {
   "x": -7,
   "y": 9,
   "z": 2,
   "name": "Rock_Basalt"
  },
  {
   "x": -7,
   "y": 10,
   "z": 2,
   "name": "Rock_Basalt"
  },
  {
   "x": -7,
   "y": 11,
   "z": 2,
   "name": "Soil_Dirt"
  },
  {
   "x": -7,
   "y": 12,
   "z": 2,
   "name": "Soil_Grass"
  },
  {
   "x": -7,
   "y": 3,
   "z": 3,
   "name": "Rock_Basalt"
  },
  {
   "x": -7,
   "y": 4,
   "z": 3,
   "name": "Rock_Basalt"
  },
  {
   "x": -7,
   "y": 5,
   "z": 3,
   "name": "Rock_Basalt"
  },
  {
   "x": -7,
   "y": 6,
   "z": 3,
   "name": "Rock_Basalt"
  },
  {
   "x": -7,
   "y": 7,
   "z": 3,
   "name": "Rock_Basalt"
  },
  {
   "x": -7,
   "y": 8,
   "z": 3,
   "name": "Rock_Basalt"
  },
  {
   "x": -7,
   "y": 9,
   "z": 3,
   "name": "Rock_Basalt"
  },
  {
   "x": -7,
   "y": 10,
   "z": 3,
   "name": "Rock_Basalt"
  },
  {
   "x": -7,
   "y": 11,
   "z": 3,
   "name": "Soil_Dirt"
  },
  {
   "x": -7,
   "y": 12,
   "z": 3,
   "name": "Soil_Grass"
  },
  {
   "x": -7,
   "y": 13,
   "z": 3,
   "name": "Plant_Grass_Winter_Tall"
  },
  {
   "x": -7,
   "y": 14,
   "z": 3,
   "name": "Plant_Grass_Winter_Tall",
   "filler": 1024
  },
  {
   "x": -7,
   "y": 2,
   "z": 4,
   "name": "Rock_Basalt"
  },
  {
   "x": -7,
   "y": 3,
   "z": 4,
   "name": "Rock_Basalt"
  },
  {
   "x": -7,
   "y": 4,
   "z": 4,
   "name": "Rock_Basalt"
  },
  {
   "x": -7,
   "y": 5,
   "z": 4,
   "name": "Rock_Basalt"
  },
  {
   "x": -7,
   "y": 6,
   "z": 4,
   "name": "Rock_Basalt"
  },
  {
   "x": -7,
   "y": 7,
   "z": 4,
   "name": "Rock_Basalt"
  },
  {
   "x": -7,
   "y": 8,
   "z": 4,
   "name": "Rock_Basalt"
  },
  {
   "x": -7,
   "y": 9,
   "z": 4,
   "name": "Rock_Basalt"
  },
  {
   "x": -7,
   "y": 10,
   "z": 4,
   "name": "Soil_Dirt"
  },
  {
   "x": -7,
   "y": 11,
   "z": 4,
   "name": "Soil_Grass"
  },
  {
   "x": -7,
   "y": 12,
   "z": 4,
   "name": "Plant_Grass_Winter_Tall"
  },
  {
   "x": -7,
   "y": 13,
   "z": 4,
   "name": "Plant_Grass_Winter_Tall",
   "filler": 1024
  },
  {
   "x": -7,
   "y": 2,
   "z": 5,
   "name": "Rock_Basalt"
  },
  {
   "x": -7,
   "y": 3,
   "z": 5,
   "name": "Rock_Basalt"
  },
  {
   "x": -7,
   "y": 4,
   "z": 5,
   "name": "Rock_Basalt"
  },
  {
   "x": -7,
   "y": 5,
   "z": 5,
   "name": "Rock_Basalt"
  },
  {
   "x": -7,
   "y": 6,
   "z": 5,
   "name": "Rock_Basalt"
  },
  {
   "x": -7,
   "y": 7,
   "z": 5,
   "name": "Rock_Basalt"
  },
  {
   "x": -7,
   "y": 8,
   "z": 5,
   "name": "Rock_Basalt"
  },
  {
   "x": -7,
   "y": 9,
   "z": 5,
   "name": "Rock_Basalt"
  },
  {
   "x": -7,
   "y": 10,
   "z": 5,
   "name": "Soil_Dirt"
  },
  {
   "x": -7,
   "y": 11,
   "z": 5,
   "name": "Soil_Grass"
  },
  {
   "x": -7,
   "y": 12,
   "z": 5,
   "name": "Plant_Grass_Winter_Tall"
  },
  {
   "x": -7,
   "y": 13,
   "z": 5,
   "name": "Plant_Grass_Winter_Tall",
   "filler": 1024
  },
  {
   "x": -7,
   "y": 2,
   "z": 6,
   "name": "Rock_Basalt"
  },
  {
   "x": -7,
   "y": 3,
   "z": 6,
   "name": "Rock_Basalt"
  },
  {
   "x": -7,
   "y": 4,
   "z": 6,
   "name": "Rock_Basalt"
  },
  {
   "x": -7,
   "y": 5,
   "z": 6,
   "name": "Rock_Basalt"
  },
  {
   "x": -7,
   "y": 6,
   "z": 6,
   "name": "Rock_Basalt"
  },
  {
   "x": -7,
   "y": 7,
   "z": 6,
   "name": "Rock_Basalt"
  },
  {
   "x": -7,
   "y": 8,
   "z": 6,
   "name": "Rock_Basalt"
  },
  {
   "x": -7,
   "y": 9,
   "z": 6,
   "name": "Rock_Basalt"
  },
  {
   "x": -7,
   "y": 10,
   "z": 6,
   "name": "Soil_Dirt"
  },
  {
   "x": -7,
   "y": 11,
   "z": 6,
   "name": "Soil_Grass"
  },
  {
   "x": -7,
   "y": 12,
   "z": 6,
   "name": "Plant_Grass_Winter"
  },
  {
   "x": -7,
   "y": 1,
   "z": 7,
   "name": "Rock_Basalt"
  },
  {
   "x": -7,
   "y": 2,
   "z": 7,
   "name": "Rock_Basalt"
  },
  {
   "x": -7,
   "y": 3,
   "z": 7,
   "name": "Rock_Basalt"
  },
  {
   "x": -7,
   "y": 4,
   "z": 7,
   "name": "Rock_Basalt"
  },
  {
   "x": -7,
   "y": 5,
   "z": 7,
   "name": "Rock_Basalt"
  },
  {
   "x": -7,
   "y": 6,
   "z": 7,
   "name": "Rock_Basalt"
  },
  {
   "x": -7,
   "y": 7,
   "z": 7,
   "name": "Rock_Basalt"
  },
  {
   "x": -7,
   "y": 8,
   "z": 7,
   "name": "Rock_Basalt"
  },
  {
   "x": -7,
   "y": 9,
   "z": 7,
   "name": "Rock_Basalt"
  },
  {
   "x": -7,
   "y": 10,
   "z": 7,
   "name": "Soil_Dirt"
  },
  {
   "x": -7,
   "y": 11,
   "z": 7,
   "name": "Soil_Grass"
  },
  {
   "x": -7,
   "y": 18,
   "z": 7,
   "name": "Plant_Leaves_Redwood"
  },
  {
   "x": -7,
   "y": 1,
   "z": 8,
   "name": "Rock_Basalt"
  },
  {
   "x": -7,
   "y": 2,
   "z": 8,
   "name": "Rock_Basalt"
  },
  {
   "x": -7,
   "y": 3,
   "z": 8,
   "name": "Rock_Basalt"
  },
  {
   "x": -7,
   "y": 4,
   "z": 8,
   "name": "Rock_Basalt"
  },
  {
   "x": -7,
   "y": 5,
   "z": 8,
   "name": "Rock_Basalt"
  },
  {
   "x": -7,
   "y": 6,
   "z": 8,
   "name": "Rock_Basalt"
  },
  {
   "x": -7,
   "y": 7,
   "z": 8,
   "name": "Rock_Basalt"
  },
  {
   "x": -7,
   "y": 8,
   "z": 8,
   "name": "Rock_Basalt"
  },
  {
   "x": -7,
   "y": 9,
   "z": 8,
   "name": "Soil_Dirt"
  },
  {
   "x": -7,
   "y": 10,
   "z": 8,
   "name": "Soil_Grass"
  },
  {
   "x": -7,
   "y": 18,
   "z": 8,
   "name": "Plant_Leaves_Redwood"
  },
  {
   "x": -7,
   "y": 22,
   "z": 8,
   "name": "Plant_Leaves_Redwood"
  },
  {
   "x": -7,
   "y": 1,
   "z": 9,
   "name": "Rock_Basalt"
  },
  {
   "x": -7,
   "y": 2,
   "z": 9,
   "name": "Rock_Basalt"
  },
  {
   "x": -7,
   "y": 3,
   "z": 9,
   "name": "Rock_Basalt"
  },
  {
   "x": -7,
   "y": 4,
   "z": 9,
   "name": "Rock_Basalt"
  },
  {
   "x": -7,
   "y": 5,
   "z": 9,
   "name": "Rock_Basalt"
  },
  {
   "x": -7,
   "y": 6,
   "z": 9,
   "name": "Rock_Basalt"
  },
  {
   "x": -7,
   "y": 7,
   "z": 9,
   "name": "Rock_Basalt"
  },
  {
   "x": -7,
   "y": 8,
   "z": 9,
   "name": "Rock_Basalt"
  },
  {
   "x": -7,
   "y": 9,
   "z": 9,
   "name": "Soil_Dirt"
  },
  {
   "x": -7,
   "y": 10,
   "z": 9,
   "name": "Soil_Needles"
  },
  {
   "x": -7,
   "y": 18,
   "z": 9,
   "name": "Plant_Leaves_Redwood"
  },
  {
   "x": -7,
   "y": 22,
   "z": 9,
   "name": "Plant_Leaves_Redwood"
  },
  {
   "x": -7,
   "y": 26,
   "z": 9,
   "name": "Plant_Leaves_Redwood"
  },
  {
   "x": -7,
   "y": 30,
   "z": 9,
   "name": "Plant_Leaves_Redwood"
  },
  {
   "x": -7,
   "y": 1,
   "z": 10,
   "name": "Rock_Basalt"
  },
  {
   "x": -7,
   "y": 2,
   "z": 10,
   "name": "Rock_Basalt"
  },
  {
   "x": -7,
   "y": 3,
   "z": 10,
   "name": "Rock_Basalt"
  },
  {
   "x": -7,
   "y": 4,
   "z": 10,
   "name": "Rock_Basalt"
  },
  {
   "x": -7,
   "y": 5,
   "z": 10,
   "name": "Rock_Basalt"
  },
  {
   "x": -7,
   "y": 6,
   "z": 10,
   "name": "Rock_Basalt"
  },
  {
   "x": -7,
   "y": 7,
   "z": 10,
   "name": "Rock_Basalt"
  },
  {
   "x": -7,
   "y": 8,
   "z": 10,
   "name": "Rock_Basalt"
  },
  {
   "x": -7,
   "y": 9,
   "z": 10,
   "name": "Soil_Dirt"
  },
  {
   "x": -7,
   "y": 10,
   "z": 10,
   "name": "Soil_Needles"
  },
  {
   "x": -7,
   "y": 18,
   "z": 10,
   "name": "Wood_Redwood_Branch_Long",
   "rotation": 4
  },
  {
   "x": -7,
   "y": 22,
   "z": 10,
   "name": "Wood_Redwood_Branch_Corner",
   "rotation": 2
  },
  {
   "x": -7,
   "y": 23,
   "z": 10,
   "name": "Plant_Leaves_Redwood"
  },
  {
   "x": -7,
   "y": 26,
   "z": 10,
   "name": "Plant_Leaves_Redwood"
  },
  {
   "x": -7,
   "y": 30,
   "z": 10,
   "name": "Plant_Leaves_Redwood"
  },
  {
   "x": -7,
   "y": 2,
   "z": 11,
   "name": "Rock_Basalt"
  },
  {
   "x": -7,
   "y": 3,
   "z": 11,
   "name": "Rock_Basalt"
  },
  {
   "x": -7,
   "y": 4,
   "z": 11,
   "name": "Rock_Basalt"
  },
  {
   "x": -7,
   "y": 5,
   "z": 11,
   "name": "Rock_Basalt"
  },
  {
   "x": -7,
   "y": 6,
   "z": 11,
   "name": "Rock_Basalt"
  },
  {
   "x": -7,
   "y": 7,
   "z": 11,
   "name": "Wood_Redwood_Trunk"
  },
  {
   "x": -7,
   "y": 8,
   "z": 11,
   "name": "Wood_Redwood_Trunk"
  },
  {
   "x": -7,
   "y": 9,
   "z": 11,
   "name": "Wood_Redwood_Trunk"
  },
  {
   "x": -7,
   "y": 10,
   "z": 11,
   "name": "Wood_Redwood_Trunk"
  },
  {
   "x": -7,
   "y": 11,
   "z": 11,
   "name": "Wood_Redwood_Trunk"
  },
  {
   "x": -7,
   "y": 12,
   "z": 11,
   "name": "Wood_Redwood_Trunk_Full"
  },
  {
   "x": -7,
   "y": 18,
   "z": 11,
   "name": "Wood_Redwood_Branch_Long",
   "rotation": 4
  },
  {
   "x": -7,
   "y": 19,
   "z": 11,
   "name": "Plant_Leaves_Redwood"
  },
  {
   "x": -7,
   "y": 22,
   "z": 11,
   "name": "Wood_Redwood_Branch_Long",
   "rotation": 4
  },
  {
   "x": -7,
   "y": 23,
   "z": 11,
   "name": "Plant_Leaves_Redwood"
  },
  {
   "x": -7,
   "y": 26,
   "z": 11,
   "name": "Wood_Redwood_Branch_Long",
   "rotation": 4
  },
  {
   "x": -7,
   "y": 29,
   "z": 11,
   "name": "Plant_Leaves_Redwood"
  },
  {
   "x": -7,
   "y": 30,
   "z": 11,
   "name": "Wood_Redwood_Branch_Corner",
   "rotation": 2
  },
  {
   "x": -7,
   "y": 31,
   "z": 11,
   "name": "Plant_Leaves_Redwood"
  },
  {
   "x": -7,
   "y": 35,
   "z": 11,
   "name": "Plant_Leaves_Redwood"
  },
  {
   "x": -7,
   "y": 36,
   "z": 11,
   "name": "Plant_Leaves_Redwood"
  },
  {
   "x": -7,
   "y": 2,
   "z": 12,
   "name": "Rock_Basalt"
  },
  {
   "x": -7,
   "y": 3,
   "z": 12,
   "name": "Rock_Basalt"
  },
  {
   "x": -7,
   "y": 4,
   "z": 12,
   "name": "Rock_Basalt"
  },
  {
   "x": -7,
   "y": 5,
   "z": 12,
   "name": "Rock_Basalt"
  },
  {
   "x": -7,
   "y": 6,
   "z": 12,
   "name": "Rock_Basalt"
  },
  {
   "x": -7,
   "y": 7,
   "z": 12,
   "name": "Rock_Basalt"
  },
  {
   "x": -7,
   "y": 8,
   "z": 12,
   "name": "Rock_Basalt"
  },
  {
   "x": -7,
   "y": 9,
   "z": 12,
   "name": "Soil_Dirt"
  },
  {
   "x": -7,
   "y": 10,
   "z": 12,
   "name": "Wood_Redwood_Trunk_Full"
  },
  {
   "x": -7,
   "y": 11,
   "z": 12,
   "name": "Wood_Redwood_Trunk"
  },
  {
   "x": -7,
   "y": 12,
   "z": 12,
   "name": "Wood_Redwood_Trunk"
  },
  {
   "x": -7,
   "y": 13,
   "z": 12,
   "name": "Wood_Redwood_Trunk"
  },
  {
   "x": -7,
   "y": 14,
   "z": 12,
   "name": "Wood_Redwood_Trunk"
  },
  {
   "x": -7,
   "y": 15,
   "z": 12,
   "name": "Wood_Redwood_Trunk"
  },
  {
   "x": -7,
   "y": 16,
   "z": 12,
   "name": "Wood_Redwood_Trunk"
  },
  {
   "x": -7,
   "y": 17,
   "z": 12,
   "name": "Wood_Redwood_Trunk"
  },
  {
   "x": -7,
   "y": 18,
   "z": 12,
   "name": "Wood_Redwood_Trunk"
  },
  {
   "x": -7,
   "y": 19,
   "z": 12,
   "name": "Wood_Redwood_Trunk"
  },
  {
   "x": -7,
   "y": 20,
   "z": 12,
   "name": "Wood_Redwood_Trunk"
  },
  {
   "x": -7,
   "y": 21,
   "z": 12,
   "name": "Wood_Redwood_Trunk"
  },
  {
   "x": -7,
   "y": 22,
   "z": 12,
   "name": "Wood_Redwood_Trunk"
  },
  {
   "x": -7,
   "y": 23,
   "z": 12,
   "name": "Wood_Redwood_Trunk"
  },
  {
   "x": -7,
   "y": 24,
   "z": 12,
   "name": "Wood_Redwood_Trunk"
  },
  {
   "x": -7,
   "y": 25,
   "z": 12,
   "name": "Wood_Redwood_Trunk"
  },
  {
   "x": -7,
   "y": 26,
   "z": 12,
   "name": "Wood_Redwood_Trunk"
  },
  {
   "x": -7,
   "y": 27,
   "z": 12,
   "name": "Wood_Redwood_Trunk"
  },
  {
   "x": -7,
   "y": 28,
   "z": 12,
   "name": "Wood_Redwood_Trunk"
  },
  {
   "x": -7,
   "y": 29,
   "z": 12,
   "name": "Wood_Redwood_Trunk"
  },
  {
   "x": -7,
   "y": 30,
   "z": 12,
   "name": "Wood_Redwood_Trunk"
  },
  {
   "x": -7,
   "y": 31,
   "z": 12,
   "name": "Wood_Redwood_Trunk"
  },
  {
   "x": -7,
   "y": 32,
   "z": 12,
   "name": "Wood_Redwood_Trunk"
  },
  {
   "x": -7,
   "y": 33,
   "z": 12,
   "name": "Wood_Redwood_Trunk"
  },
  {
   "x": -7,
   "y": 34,
   "z": 12,
   "name": "Wood_Redwood_Trunk"
  },
  {
   "x": -7,
   "y": 35,
   "z": 12,
   "name": "Wood_Redwood_Trunk"
  },
  {
   "x": -7,
   "y": 36,
   "z": 12,
   "name": "Plant_Leaves_Redwood"
  },
  {
   "x": -7,
   "y": 37,
   "z": 12,
   "name": "Plant_Leaves_Redwood"
  },
  {
   "x": -7,
   "y": 38,
   "z": 12,
   "name": "Plant_Leaves_Redwood"
  },
  {
   "x": -7,
   "y": 39,
   "z": 12,
   "name": "Plant_Leaves_Redwood"
  },
  {
   "x": -7,
   "y": 40,
   "z": 12,
   "name": "Plant_Leaves_Redwood"
  },
  {
   "x": -7,
   "y": 2,
   "z": 13,
   "name": "Rock_Basalt"
  },
  {
   "x": -7,
   "y": 3,
   "z": 13,
   "name": "Rock_Basalt"
  },
  {
   "x": -7,
   "y": 4,
   "z": 13,
   "name": "Rock_Basalt"
  },
  {
   "x": -7,
   "y": 5,
   "z": 13,
   "name": "Rock_Basalt"
  },
  {
   "x": -7,
   "y": 6,
   "z": 13,
   "name": "Rock_Basalt"
  },
  {
   "x": -7,
   "y": 7,
   "z": 13,
   "name": "Rock_Basalt"
  },
  {
   "x": -7,
   "y": 8,
   "z": 13,
   "name": "Soil_Dirt"
  },
  {
   "x": -7,
   "y": 9,
   "z": 13,
   "name": "Soil_Needles"
  },
  {
   "x": -7,
   "y": 10,
   "z": 13,
   "name": "Wood_Redwood_Trunk_Full"
  },
  {
   "x": -7,
   "y": 18,
   "z": 13,
   "name": "Wood_Redwood_Branch_Long",
   "rotation": 4
  },
  {
   "x": -7,
   "y": 21,
   "z": 13,
   "name": "Wood_Redwood_Branch_Long",
   "rotation": 4
  },
  {
   "x": -7,
   "y": 22,
   "z": 13,
   "name": "Plant_Leaves_Redwood"
  },
  {
   "x": -7,
   "y": 26,
   "z": 13,
   "name": "Wood_Redwood_Branch_Corner"
  },
  {
   "x": -7,
   "y": 27,
   "z": 13,
   "name": "Plant_Leaves_Redwood"
  },
  {
   "x": -7,
   "y": 29,
   "z": 13,
   "name": "Plant_Leaves_Redwood"
  },
  {
   "x": -7,
   "y": 31,
   "z": 13,
   "name": "Wood_Redwood_Branch_Corner"
  },
  {
   "x": -7,
   "y": 32,
   "z": 13,
   "name": "Plant_Leaves_Redwood"
  },
  {
   "x": -7,
   "y": 34,
   "z": 13,
   "name": "Wood_Redwood_Branch_Long",
   "rotation": 4
  },
  {
   "x": -7,
   "y": 35,
   "z": 13,
   "name": "Plant_Leaves_Redwood"
  },
  {
   "x": -7,
   "y": 36,
   "z": 13,
   "name": "Plant_Leaves_Redwood"
  },
  {
   "x": -7,
   "y": 3,
   "z": 14,
   "name": "Rock_Basalt"
  },
  {
   "x": -7,
   "y": 4,
   "z": 14,
   "name": "Rock_Basalt"
  },
  {
   "x": -7,
   "y": 5,
   "z": 14,
   "name": "Rock_Basalt"
  },
  {
   "x": -7,
   "y": 6,
   "z": 14,
   "name": "Rock_Basalt"
  },
  {
   "x": -7,
   "y": 7,
   "z": 14,
   "name": "Rock_Basalt"
  },
  {
   "x": -7,
   "y": 8,
   "z": 14,
   "name": "Soil_Dirt"
  },
  {
   "x": -7,
   "y": 9,
   "z": 14,
   "name": "Soil_Needles"
  },
  {
   "x": -7,
   "y": 18,
   "z": 14,
   "name": "Wood_Redwood_Branch_Corner"
  },
  {
   "x": -7,
   "y": 19,
   "z": 14,
   "name": "Plant_Leaves_Redwood"
  },
  {
   "x": -7,
   "y": 21,
   "z": 14,
   "name": "Plant_Leaves_Redwood"
  },
  {
   "x": -7,
   "y": 26,
   "z": 14,
   "name": "Plant_Leaves_Redwood"
  },
  {
   "x": -7,
   "y": 31,
   "z": 14,
   "name": "Plant_Leaves_Redwood"
  },
  {
   "x": -7,
   "y": 34,
   "z": 14,
   "name": "Plant_Leaves_Redwood"
  },
  {
   "x": -7,
   "y": 6,
   "z": 15,
   "name": "Rock_Basalt"
  },
  {
   "x": -7,
   "y": 7,
   "z": 15,
   "name": "Rock_Basalt"
  },
  {
   "x": -7,
   "y": 8,
   "z": 15,
   "name": "Soil_Grass"
  },
  {
   "x": -7,
   "y": 18,
   "z": 15,
   "name": "Plant_Leaves_Redwood"
  },
  {
   "x": -7,
   "y": 21,
   "z": 15,
   "name": "Plant_Leaves_Redwood"
  },
  {
   "x": -7,
   "y": 26,
   "z": 15,
   "name": "Plant_Leaves_Redwood"
  },
  {
   "x": -7,
   "y": 18,
   "z": 16,
   "name": "Plant_Leaves_Redwood"
  },
  {
   "x": -7,
   "y": 21,
   "z": 16,
   "name": "Plant_Leaves_Redwood"
  },
  {
   "x": -7,
   "y": 26,
   "z": 16,
   "name": "Plant_Leaves_Redwood"
  },
  {
   "x": -6,
   "y": 13,
   "z": -14,
   "name": "Soil_Dirt"
  },
  {
   "x": -6,
   "y": 14,
   "z": -14,
   "name": "Soil_Grass"
  },
  {
   "x": -6,
   "y": 8,
   "z": -13,
   "name": "Rock_Basalt"
  },
  {
   "x": -6,
   "y": 9,
   "z": -13,
   "name": "Rock_Basalt"
  },
  {
   "x": -6,
   "y": 10,
   "z": -13,
   "name": "Rock_Basalt"
  },
  {
   "x": -6,
   "y": 11,
   "z": -13,
   "name": "Rock_Basalt"
  },
  {
   "x": -6,
   "y": 12,
   "z": -13,
   "name": "Rock_Basalt"
  },
  {
   "x": -6,
   "y": 13,
   "z": -13,
   "name": "Soil_Dirt"
  },
  {
   "x": -6,
   "y": 14,
   "z": -13,
   "name": "Soil_Grass"
  },
  {
   "x": -6,
   "y": 5,
   "z": -12,
   "name": "Rock_Basalt"
  },
  {
   "x": -6,
   "y": 6,
   "z": -12,
   "name": "Rock_Basalt"
  },
  {
   "x": -6,
   "y": 7,
   "z": -12,
   "name": "Rock_Basalt"
  },
  {
   "x": -6,
   "y": 8,
   "z": -12,
   "name": "Rock_Basalt"
  },
  {
   "x": -6,
   "y": 9,
   "z": -12,
   "name": "Rock_Basalt"
  },
  {
   "x": -6,
   "y": 10,
   "z": -12,
   "name": "Rock_Basalt"
  },
  {
   "x": -6,
   "y": 11,
   "z": -12,
   "name": "Rock_Basalt"
  },
  {
   "x": -6,
   "y": 12,
   "z": -12,
   "name": "Rock_Basalt"
  },
  {
   "x": -6,
   "y": 13,
   "z": -12,
   "name": "Soil_Dirt"
  },
  {
   "x": -6,
   "y": 14,
   "z": -12,
   "name": "Soil_Grass"
  },
  {
   "x": -6,
   "y": 15,
   "z": -12,
   "name": "KweebecNightmare_Moonbloom_Plant"
  },
  {
   "x": -6,
   "y": 3,
   "z": -11,
   "name": "Rock_Basalt"
  },
  {
   "x": -6,
   "y": 4,
   "z": -11,
   "name": "Rock_Basalt"
  },
  {
   "x": -6,
   "y": 5,
   "z": -11,
   "name": "Rock_Basalt"
  },
  {
   "x": -6,
   "y": 6,
   "z": -11,
   "name": "Rock_Basalt"
  },
  {
   "x": -6,
   "y": 7,
   "z": -11,
   "name": "Rock_Basalt"
  },
  {
   "x": -6,
   "y": 8,
   "z": -11,
   "name": "Rock_Basalt"
  },
  {
   "x": -6,
   "y": 9,
   "z": -11,
   "name": "Rock_Basalt"
  },
  {
   "x": -6,
   "y": 10,
   "z": -11,
   "name": "Rock_Basalt"
  },
  {
   "x": -6,
   "y": 11,
   "z": -11,
   "name": "Rock_Basalt"
  },
  {
   "x": -6,
   "y": 12,
   "z": -11,
   "name": "Rock_Basalt"
  },
  {
   "x": -6,
   "y": 13,
   "z": -11,
   "name": "Soil_Dirt"
  },
  {
   "x": -6,
   "y": 14,
   "z": -11,
   "name": "Soil_Grass"
  },
  {
   "x": -6,
   "y": 15,
   "z": -11,
   "name": "Plant_Flower_Flax_Blue"
  },
  {
   "x": -6,
   "y": 3,
   "z": -10,
   "name": "Rock_Basalt"
  },
  {
   "x": -6,
   "y": 4,
   "z": -10,
   "name": "Rock_Basalt"
  },
  {
   "x": -6,
   "y": 5,
   "z": -10,
   "name": "Rock_Basalt"
  },
  {
   "x": -6,
   "y": 6,
   "z": -10,
   "name": "Rock_Basalt"
  },
  {
   "x": -6,
   "y": 7,
   "z": -10,
   "name": "Rock_Basalt"
  },
  {
   "x": -6,
   "y": 8,
   "z": -10,
   "name": "Rock_Basalt"
  },
  {
   "x": -6,
   "y": 9,
   "z": -10,
   "name": "Rock_Basalt"
  },
  {
   "x": -6,
   "y": 10,
   "z": -10,
   "name": "Rock_Basalt"
  },
  {
   "x": -6,
   "y": 11,
   "z": -10,
   "name": "Rock_Basalt"
  },
  {
   "x": -6,
   "y": 12,
   "z": -10,
   "name": "Rock_Basalt"
  },
  {
   "x": -6,
   "y": 13,
   "z": -10,
   "name": "Soil_Dirt"
  },
  {
   "x": -6,
   "y": 14,
   "z": -10,
   "name": "Soil_Grass"
  },
  {
   "x": -6,
   "y": 3,
   "z": -9,
   "name": "Rock_Basalt"
  },
  {
   "x": -6,
   "y": 4,
   "z": -9,
   "name": "Rock_Basalt"
  },
  {
   "x": -6,
   "y": 5,
   "z": -9,
   "name": "Rock_Basalt"
  },
  {
   "x": -6,
   "y": 6,
   "z": -9,
   "name": "Rock_Basalt"
  },
  {
   "x": -6,
   "y": 7,
   "z": -9,
   "name": "Rock_Basalt"
  },
  {
   "x": -6,
   "y": 8,
   "z": -9,
   "name": "Rock_Basalt"
  },
  {
   "x": -6,
   "y": 9,
   "z": -9,
   "name": "Rock_Basalt"
  },
  {
   "x": -6,
   "y": 10,
   "z": -9,
   "name": "Rock_Basalt"
  },
  {
   "x": -6,
   "y": 11,
   "z": -9,
   "name": "Rock_Basalt"
  },
  {
   "x": -6,
   "y": 12,
   "z": -9,
   "name": "Rock_Basalt"
  },
  {
   "x": -6,
   "y": 13,
   "z": -9,
   "name": "Rock_Basalt"
  },
  {
   "x": -6,
   "y": 14,
   "z": -9,
   "name": "Soil_Grass"
  },
  {
   "x": -6,
   "y": 2,
   "z": -8,
   "name": "Rock_Basalt"
  },
  {
   "x": -6,
   "y": 3,
   "z": -8,
   "name": "Rock_Basalt"
  },
  {
   "x": -6,
   "y": 4,
   "z": -8,
   "name": "Rock_Basalt"
  },
  {
   "x": -6,
   "y": 5,
   "z": -8,
   "name": "Rock_Basalt"
  },
  {
   "x": -6,
   "y": 6,
   "z": -8,
   "name": "Rock_Basalt"
  },
  {
   "x": -6,
   "y": 7,
   "z": -8,
   "name": "Rock_Basalt"
  },
  {
   "x": -6,
   "y": 8,
   "z": -8,
   "name": "Rock_Basalt"
  },
  {
   "x": -6,
   "y": 9,
   "z": -8,
   "name": "Rock_Basalt"
  },
  {
   "x": -6,
   "y": 10,
   "z": -8,
   "name": "Rock_Basalt"
  },
  {
   "x": -6,
   "y": 11,
   "z": -8,
   "name": "Rock_Basalt"
  },
  {
   "x": -6,
   "y": 12,
   "z": -8,
   "name": "Rock_Basalt"
  },
  {
   "x": -6,
   "y": 13,
   "z": -8,
   "name": "Rock_Basalt"
  },
  {
   "x": -6,
   "y": 14,
   "z": -8,
   "name": "Soil_Dirt"
  },
  {
   "x": -6,
   "y": 15,
   "z": -8,
   "name": "Soil_Needles"
  },
  {
   "x": -6,
   "y": 2,
   "z": -7,
   "name": "Rock_Basalt"
  },
  {
   "x": -6,
   "y": 3,
   "z": -7,
   "name": "Rock_Basalt"
  },
  {
   "x": -6,
   "y": 4,
   "z": -7,
   "name": "Rock_Basalt"
  },
  {
   "x": -6,
   "y": 5,
   "z": -7,
   "name": "Rock_Basalt"
  },
  {
   "x": -6,
   "y": 6,
   "z": -7,
   "name": "Rock_Basalt"
  },
  {
   "x": -6,
   "y": 7,
   "z": -7,
   "name": "Rock_Basalt"
  },
  {
   "x": -6,
   "y": 8,
   "z": -7,
   "name": "Rock_Basalt"
  },
  {
   "x": -6,
   "y": 9,
   "z": -7,
   "name": "Rock_Basalt"
  },
  {
   "x": -6,
   "y": 10,
   "z": -7,
   "name": "Rock_Basalt"
  },
  {
   "x": -6,
   "y": 11,
   "z": -7,
   "name": "Rock_Basalt"
  },
  {
   "x": -6,
   "y": 12,
   "z": -7,
   "name": "Rock_Basalt"
  },
  {
   "x": -6,
   "y": 13,
   "z": -7,
   "name": "Rock_Basalt"
  },
  {
   "x": -6,
   "y": 14,
   "z": -7,
   "name": "Rock_Basalt"
  },
  {
   "x": -6,
   "y": 15,
   "z": -7,
   "name": "Soil_Grass"
  },
  {
   "x": -6,
   "y": 32,
   "z": -7,
   "name": "Plant_Leaves_Redwood"
  },
  {
   "x": -6,
   "y": 2,
   "z": -6,
   "name": "Rock_Basalt"
  },
  {
   "x": -6,
   "y": 3,
   "z": -6,
   "name": "Rock_Basalt"
  },
  {
   "x": -6,
   "y": 4,
   "z": -6,
   "name": "Rock_Basalt"
  },
  {
   "x": -6,
   "y": 5,
   "z": -6,
   "name": "Rock_Basalt"
  },
  {
   "x": -6,
   "y": 6,
   "z": -6,
   "name": "Rock_Basalt"
  },
  {
   "x": -6,
   "y": 7,
   "z": -6,
   "name": "Rock_Basalt"
  },
  {
   "x": -6,
   "y": 8,
   "z": -6,
   "name": "Rock_Basalt"
  },
  {
   "x": -6,
   "y": 9,
   "z": -6,
   "name": "Rock_Basalt"
  },
  {
   "x": -6,
   "y": 10,
   "z": -6,
   "name": "Rock_Basalt"
  },
  {
   "x": -6,
   "y": 11,
   "z": -6,
   "name": "Rock_Basalt"
  },
  {
   "x": -6,
   "y": 12,
   "z": -6,
   "name": "Rock_Basalt"
  },
  {
   "x": -6,
   "y": 13,
   "z": -6,
   "name": "Rock_Basalt"
  },
  {
   "x": -6,
   "y": 14,
   "z": -6,
   "name": "Rock_Basalt"
  },
  {
   "x": -6,
   "y": 15,
   "z": -6,
   "name": "Soil_Grass"
  },
  {
   "x": -6,
   "y": 32,
   "z": -6,
   "name": "Plant_Leaves_Redwood"
  },
  {
   "x": -6,
   "y": 46,
   "z": -6,
   "name": "Plant_Leaves_Redwood"
  },
  {
   "x": -6,
   "y": 2,
   "z": -5,
   "name": "Rock_Basalt"
  },
  {
   "x": -6,
   "y": 3,
   "z": -5,
   "name": "Rock_Basalt"
  },
  {
   "x": -6,
   "y": 4,
   "z": -5,
   "name": "Rock_Basalt"
  },
  {
   "x": -6,
   "y": 5,
   "z": -5,
   "name": "Rock_Basalt"
  },
  {
   "x": -6,
   "y": 6,
   "z": -5,
   "name": "Rock_Basalt"
  },
  {
   "x": -6,
   "y": 7,
   "z": -5,
   "name": "Rock_Basalt"
  },
  {
   "x": -6,
   "y": 8,
   "z": -5,
   "name": "Rock_Basalt"
  },
  {
   "x": -6,
   "y": 9,
   "z": -5,
   "name": "Rock_Basalt"
  },
  {
   "x": -6,
   "y": 10,
   "z": -5,
   "name": "Rock_Basalt"
  },
  {
   "x": -6,
   "y": 11,
   "z": -5,
   "name": "Rock_Basalt"
  },
  {
   "x": -6,
   "y": 12,
   "z": -5,
   "name": "Rock_Basalt"
  },
  {
   "x": -6,
   "y": 13,
   "z": -5,
   "name": "Rock_Basalt"
  },
  {
   "x": -6,
   "y": 14,
   "z": -5,
   "name": "Rock_Basalt"
  },
  {
   "x": -6,
   "y": 15,
   "z": -5,
   "name": "Soil_Grass"
  },
  {
   "x": -6,
   "y": 32,
   "z": -5,
   "name": "Plant_Leaves_Redwood"
  },
  {
   "x": -6,
   "y": 41,
   "z": -5,
   "name": "Plant_Leaves_Redwood"
  },
  {
   "x": -6,
   "y": 2,
   "z": -4,
   "name": "Rock_Basalt"
  },
  {
   "x": -6,
   "y": 3,
   "z": -4,
   "name": "Rock_Basalt"
  },
  {
   "x": -6,
   "y": 4,
   "z": -4,
   "name": "Rock_Basalt"
  },
  {
   "x": -6,
   "y": 5,
   "z": -4,
   "name": "Rock_Basalt"
  },
  {
   "x": -6,
   "y": 6,
   "z": -4,
   "name": "Rock_Basalt"
  },
  {
   "x": -6,
   "y": 7,
   "z": -4,
   "name": "Rock_Basalt"
  },
  {
   "x": -6,
   "y": 8,
   "z": -4,
   "name": "Rock_Basalt"
  },
  {
   "x": -6,
   "y": 9,
   "z": -4,
   "name": "Rock_Basalt"
  },
  {
   "x": -6,
   "y": 10,
   "z": -4,
   "name": "Rock_Basalt"
  },
  {
   "x": -6,
   "y": 11,
   "z": -4,
   "name": "Rock_Basalt"
  },
  {
   "x": -6,
   "y": 12,
   "z": -4,
   "name": "Rock_Basalt"
  },
  {
   "x": -6,
   "y": 13,
   "z": -4,
   "name": "Rock_Basalt"
  },
  {
   "x": -6,
   "y": 14,
   "z": -4,
   "name": "Rock_Basalt"
  },
  {
   "x": -6,
   "y": 15,
   "z": -4,
   "name": "Soil_Grass"
  },
  {
   "x": -6,
   "y": 2,
   "z": -3,
   "name": "Rock_Basalt"
  },
  {
   "x": -6,
   "y": 3,
   "z": -3,
   "name": "Rock_Basalt"
  },
  {
   "x": -6,
   "y": 4,
   "z": -3,
   "name": "Rock_Basalt"
  },
  {
   "x": -6,
   "y": 5,
   "z": -3,
   "name": "Rock_Basalt"
  },
  {
   "x": -6,
   "y": 6,
   "z": -3,
   "name": "Rock_Basalt"
  },
  {
   "x": -6,
   "y": 7,
   "z": -3,
   "name": "Rock_Basalt"
  },
  {
   "x": -6,
   "y": 8,
   "z": -3,
   "name": "Rock_Basalt"
  },
  {
   "x": -6,
   "y": 9,
   "z": -3,
   "name": "Rock_Basalt"
  },
  {
   "x": -6,
   "y": 10,
   "z": -3,
   "name": "Rock_Basalt"
  },
  {
   "x": -6,
   "y": 11,
   "z": -3,
   "name": "Rock_Basalt"
  },
  {
   "x": -6,
   "y": 12,
   "z": -3,
   "name": "Rock_Basalt"
  },
  {
   "x": -6,
   "y": 13,
   "z": -3,
   "name": "Rock_Basalt"
  },
  {
   "x": -6,
   "y": 14,
   "z": -3,
   "name": "Rock_Basalt"
  },
  {
   "x": -6,
   "y": 15,
   "z": -3,
   "name": "Soil_Dirt"
  },
  {
   "x": -6,
   "y": 16,
   "z": -3,
   "name": "Soil_Grass"
  },
  {
   "x": -6,
   "y": 3,
   "z": -2,
   "name": "Rock_Basalt"
  },
  {
   "x": -6,
   "y": 4,
   "z": -2,
   "name": "Rock_Basalt"
  },
  {
   "x": -6,
   "y": 5,
   "z": -2,
   "name": "Rock_Basalt"
  },
  {
   "x": -6,
   "y": 6,
   "z": -2,
   "name": "Rock_Basalt"
  },
  {
   "x": -6,
   "y": 7,
   "z": -2,
   "name": "Rock_Basalt"
  },
  {
   "x": -6,
   "y": 8,
   "z": -2,
   "name": "Rock_Basalt"
  },
  {
   "x": -6,
   "y": 9,
   "z": -2,
   "name": "Rock_Basalt"
  },
  {
   "x": -6,
   "y": 10,
   "z": -2,
   "name": "Rock_Basalt"
  },
  {
   "x": -6,
   "y": 11,
   "z": -2,
   "name": "Rock_Basalt"
  },
  {
   "x": -6,
   "y": 12,
   "z": -2,
   "name": "Rock_Basalt"
  },
  {
   "x": -6,
   "y": 13,
   "z": -2,
   "name": "Rock_Basalt"
  },
  {
   "x": -6,
   "y": 14,
   "z": -2,
   "name": "Rock_Basalt"
  },
  {
   "x": -6,
   "y": 15,
   "z": -2,
   "name": "Soil_Dirt"
  },
  {
   "x": -6,
   "y": 16,
   "z": -2,
   "name": "Soil_Grass"
  },
  {
   "x": -6,
   "y": 17,
   "z": -2,
   "name": "Plant_Flower_Flax_Blue"
  },
  {
   "x": -6,
   "y": 3,
   "z": -1,
   "name": "Rock_Basalt"
  },
  {
   "x": -6,
   "y": 4,
   "z": -1,
   "name": "Rock_Basalt"
  },
  {
   "x": -6,
   "y": 5,
   "z": -1,
   "name": "Rock_Basalt"
  },
  {
   "x": -6,
   "y": 6,
   "z": -1,
   "name": "Rock_Basalt"
  },
  {
   "x": -6,
   "y": 7,
   "z": -1,
   "name": "Rock_Basalt"
  },
  {
   "x": -6,
   "y": 8,
   "z": -1,
   "name": "Rock_Basalt"
  },
  {
   "x": -6,
   "y": 9,
   "z": -1,
   "name": "Rock_Basalt"
  },
  {
   "x": -6,
   "y": 10,
   "z": -1,
   "name": "Rock_Basalt"
  },
  {
   "x": -6,
   "y": 11,
   "z": -1,
   "name": "Rock_Basalt"
  },
  {
   "x": -6,
   "y": 12,
   "z": -1,
   "name": "Rock_Basalt"
  },
  {
   "x": -6,
   "y": 13,
   "z": -1,
   "name": "Rock_Basalt"
  },
  {
   "x": -6,
   "y": 14,
   "z": -1,
   "name": "Rock_Basalt"
  },
  {
   "x": -6,
   "y": 15,
   "z": -1,
   "name": "Soil_Dirt"
  },
  {
   "x": -6,
   "y": 16,
   "z": -1,
   "name": "Soil_Grass"
  },
  {
   "x": -6,
   "y": 4,
   "z": 0,
   "name": "Rock_Basalt"
  },
  {
   "x": -6,
   "y": 5,
   "z": 0,
   "name": "Rock_Basalt"
  },
  {
   "x": -6,
   "y": 6,
   "z": 0,
   "name": "Rock_Basalt"
  },
  {
   "x": -6,
   "y": 7,
   "z": 0,
   "name": "Rock_Basalt"
  },
  {
   "x": -6,
   "y": 8,
   "z": 0,
   "name": "Rock_Basalt"
  },
  {
   "x": -6,
   "y": 9,
   "z": 0,
   "name": "Rock_Basalt"
  },
  {
   "x": -6,
   "y": 10,
   "z": 0,
   "name": "Rock_Basalt"
  },
  {
   "x": -6,
   "y": 11,
   "z": 0,
   "name": "Rock_Basalt"
  },
  {
   "x": -6,
   "y": 12,
   "z": 0,
   "name": "Rock_Basalt"
  },
  {
   "x": -6,
   "y": 13,
   "z": 0,
   "name": "Rock_Basalt"
  },
  {
   "x": -6,
   "y": 14,
   "z": 0,
   "name": "Rock_Basalt"
  },
  {
   "x": -6,
   "y": 15,
   "z": 0,
   "name": "Soil_Dirt"
  },
  {
   "x": -6,
   "y": 16,
   "z": 0,
   "name": "Soil_Grass"
  },
  {
   "x": -6,
   "y": 3,
   "z": 1,
   "name": "Rock_Basalt"
  },
  {
   "x": -6,
   "y": 4,
   "z": 1,
   "name": "Rock_Basalt"
  },
  {
   "x": -6,
   "y": 5,
   "z": 1,
   "name": "Rock_Basalt"
  },
  {
   "x": -6,
   "y": 6,
   "z": 1,
   "name": "Rock_Basalt"
  },
  {
   "x": -6,
   "y": 7,
   "z": 1,
   "name": "Rock_Basalt"
  },
  {
   "x": -6,
   "y": 8,
   "z": 1,
   "name": "Rock_Basalt"
  },
  {
   "x": -6,
   "y": 9,
   "z": 1,
   "name": "Rock_Basalt"
  },
  {
   "x": -6,
   "y": 10,
   "z": 1,
   "name": "Rock_Basalt"
  },
  {
   "x": -6,
   "y": 11,
   "z": 1,
   "name": "Rock_Basalt"
  },
  {
   "x": -6,
   "y": 12,
   "z": 1,
   "name": "Soil_Grass"
  },
  {
   "x": -6,
   "y": 3,
   "z": 2,
   "name": "Rock_Basalt"
  },
  {
   "x": -6,
   "y": 4,
   "z": 2,
   "name": "Rock_Basalt"
  },
  {
   "x": -6,
   "y": 5,
   "z": 2,
   "name": "Rock_Basalt"
  },
  {
   "x": -6,
   "y": 6,
   "z": 2,
   "name": "Rock_Basalt"
  },
  {
   "x": -6,
   "y": 7,
   "z": 2,
   "name": "Rock_Basalt"
  },
  {
   "x": -6,
   "y": 8,
   "z": 2,
   "name": "Rock_Basalt"
  },
  {
   "x": -6,
   "y": 9,
   "z": 2,
   "name": "Rock_Basalt"
  },
  {
   "x": -6,
   "y": 10,
   "z": 2,
   "name": "Rock_Basalt"
  },
  {
   "x": -6,
   "y": 11,
   "z": 2,
   "name": "Soil_Dirt"
  },
  {
   "x": -6,
   "y": 12,
   "z": 2,
   "name": "Soil_Grass"
  },
  {
   "x": -6,
   "y": 13,
   "z": 2,
   "name": "Plant_Grass_Winter"
  },
  {
   "x": -6,
   "y": 3,
   "z": 3,
   "name": "Rock_Basalt"
  },
  {
   "x": -6,
   "y": 4,
   "z": 3,
   "name": "Rock_Basalt"
  },
  {
   "x": -6,
   "y": 5,
   "z": 3,
   "name": "Rock_Basalt"
  },
  {
   "x": -6,
   "y": 6,
   "z": 3,
   "name": "Rock_Basalt"
  },
  {
   "x": -6,
   "y": 7,
   "z": 3,
   "name": "Rock_Basalt"
  },
  {
   "x": -6,
   "y": 8,
   "z": 3,
   "name": "Rock_Basalt"
  },
  {
   "x": -6,
   "y": 9,
   "z": 3,
   "name": "Rock_Basalt"
  },
  {
   "x": -6,
   "y": 10,
   "z": 3,
   "name": "Rock_Basalt"
  },
  {
   "x": -6,
   "y": 11,
   "z": 3,
   "name": "Soil_Dirt"
  },
  {
   "x": -6,
   "y": 12,
   "z": 3,
   "name": "Soil_Grass"
  },
  {
   "x": -6,
   "y": 2,
   "z": 4,
   "name": "Rock_Basalt"
  },
  {
   "x": -6,
   "y": 3,
   "z": 4,
   "name": "Rock_Basalt"
  },
  {
   "x": -6,
   "y": 4,
   "z": 4,
   "name": "Rock_Basalt"
  },
  {
   "x": -6,
   "y": 5,
   "z": 4,
   "name": "Rock_Basalt"
  },
  {
   "x": -6,
   "y": 6,
   "z": 4,
   "name": "Rock_Basalt"
  },
  {
   "x": -6,
   "y": 7,
   "z": 4,
   "name": "Rock_Basalt"
  },
  {
   "x": -6,
   "y": 8,
   "z": 4,
   "name": "Rock_Basalt"
  },
  {
   "x": -6,
   "y": 9,
   "z": 4,
   "name": "Rock_Basalt"
  },
  {
   "x": -6,
   "y": 10,
   "z": 4,
   "name": "Soil_Dirt"
  },
  {
   "x": -6,
   "y": 11,
   "z": 4,
   "name": "Soil_Dirt"
  },
  {
   "x": -6,
   "y": 12,
   "z": 4,
   "name": "Soil_Grass"
  },
  {
   "x": -6,
   "y": 13,
   "z": 4,
   "name": "Plant_Grass_Winter_Tall"
  },
  {
   "x": -6,
   "y": 14,
   "z": 4,
   "name": "Plant_Grass_Winter_Tall",
   "filler": 1024
  },
  {
   "x": -6,
   "y": 1,
   "z": 5,
   "name": "Rock_Basalt"
  },
  {
   "x": -6,
   "y": 2,
   "z": 5,
   "name": "Rock_Basalt"
  },
  {
   "x": -6,
   "y": 3,
   "z": 5,
   "name": "Rock_Basalt"
  },
  {
   "x": -6,
   "y": 4,
   "z": 5,
   "name": "Rock_Basalt"
  },
  {
   "x": -6,
   "y": 5,
   "z": 5,
   "name": "Rock_Basalt"
  },
  {
   "x": -6,
   "y": 6,
   "z": 5,
   "name": "Rock_Basalt"
  },
  {
   "x": -6,
   "y": 7,
   "z": 5,
   "name": "Rock_Basalt"
  },
  {
   "x": -6,
   "y": 8,
   "z": 5,
   "name": "Rock_Basalt"
  },
  {
   "x": -6,
   "y": 9,
   "z": 5,
   "name": "Rock_Basalt"
  },
  {
   "x": -6,
   "y": 10,
   "z": 5,
   "name": "Soil_Dirt"
  },
  {
   "x": -6,
   "y": 11,
   "z": 5,
   "name": "Soil_Grass"
  },
  {
   "x": -6,
   "y": 1,
   "z": 6,
   "name": "Rock_Basalt"
  },
  {
   "x": -6,
   "y": 2,
   "z": 6,
   "name": "Rock_Basalt"
  },
  {
   "x": -6,
   "y": 3,
   "z": 6,
   "name": "Rock_Basalt"
  },
  {
   "x": -6,
   "y": 4,
   "z": 6,
   "name": "Rock_Basalt"
  },
  {
   "x": -6,
   "y": 5,
   "z": 6,
   "name": "Rock_Basalt"
  },
  {
   "x": -6,
   "y": 6,
   "z": 6,
   "name": "Rock_Basalt"
  },
  {
   "x": -6,
   "y": 7,
   "z": 6,
   "name": "Rock_Basalt"
  },
  {
   "x": -6,
   "y": 8,
   "z": 6,
   "name": "Rock_Basalt"
  },
  {
   "x": -6,
   "y": 9,
   "z": 6,
   "name": "Rock_Basalt"
  },
  {
   "x": -6,
   "y": 10,
   "z": 6,
   "name": "Soil_Dirt"
  },
  {
   "x": -6,
   "y": 11,
   "z": 6,
   "name": "Soil_Grass"
  },
  {
   "x": -6,
   "y": 1,
   "z": 7,
   "name": "Rock_Basalt"
  },
  {
   "x": -6,
   "y": 2,
   "z": 7,
   "name": "Rock_Basalt"
  },
  {
   "x": -6,
   "y": 3,
   "z": 7,
   "name": "Rock_Basalt"
  },
  {
   "x": -6,
   "y": 4,
   "z": 7,
   "name": "Rock_Basalt"
  },
  {
   "x": -6,
   "y": 5,
   "z": 7,
   "name": "Rock_Basalt"
  },
  {
   "x": -6,
   "y": 6,
   "z": 7,
   "name": "Rock_Basalt"
  },
  {
   "x": -6,
   "y": 7,
   "z": 7,
   "name": "Rock_Basalt"
  },
  {
   "x": -6,
   "y": 8,
   "z": 7,
   "name": "Rock_Basalt"
  },
  {
   "x": -6,
   "y": 9,
   "z": 7,
   "name": "Rock_Basalt"
  },
  {
   "x": -6,
   "y": 10,
   "z": 7,
   "name": "Soil_Dirt"
  },
  {
   "x": -6,
   "y": 11,
   "z": 7,
   "name": "Soil_Needles"
  },
  {
   "x": -6,
   "y": 1,
   "z": 8,
   "name": "Rock_Basalt"
  },
  {
   "x": -6,
   "y": 2,
   "z": 8,
   "name": "Rock_Basalt"
  },
  {
   "x": -6,
   "y": 3,
   "z": 8,
   "name": "Rock_Basalt"
  },
  {
   "x": -6,
   "y": 4,
   "z": 8,
   "name": "Rock_Basalt"
  },
  {
   "x": -6,
   "y": 5,
   "z": 8,
   "name": "Rock_Basalt"
  },
  {
   "x": -6,
   "y": 6,
   "z": 8,
   "name": "Rock_Basalt"
  },
  {
   "x": -6,
   "y": 7,
   "z": 8,
   "name": "Rock_Basalt"
  },
  {
   "x": -6,
   "y": 8,
   "z": 8,
   "name": "Rock_Basalt"
  },
  {
   "x": -6,
   "y": 9,
   "z": 8,
   "name": "Soil_Dirt"
  },
  {
   "x": -6,
   "y": 10,
   "z": 8,
   "name": "Soil_Dirt"
  },
  {
   "x": -6,
   "y": 11,
   "z": 8,
   "name": "Soil_Needles"
  },
  {
   "x": -6,
   "y": 18,
   "z": 8,
   "name": "Plant_Leaves_Redwood"
  },
  {
   "x": -6,
   "y": 1,
   "z": 9,
   "name": "Rock_Basalt"
  },
  {
   "x": -6,
   "y": 2,
   "z": 9,
   "name": "Rock_Basalt"
  },
  {
   "x": -6,
   "y": 3,
   "z": 9,
   "name": "Rock_Basalt"
  },
  {
   "x": -6,
   "y": 4,
   "z": 9,
   "name": "Rock_Basalt"
  },
  {
   "x": -6,
   "y": 5,
   "z": 9,
   "name": "Rock_Basalt"
  },
  {
   "x": -6,
   "y": 6,
   "z": 9,
   "name": "Rock_Basalt"
  },
  {
   "x": -6,
   "y": 7,
   "z": 9,
   "name": "Rock_Basalt"
  },
  {
   "x": -6,
   "y": 8,
   "z": 9,
   "name": "Rock_Basalt"
  },
  {
   "x": -6,
   "y": 9,
   "z": 9,
   "name": "Soil_Dirt"
  },
  {
   "x": -6,
   "y": 10,
   "z": 9,
   "name": "Soil_Needles"
  },
  {
   "x": -6,
   "y": 18,
   "z": 9,
   "name": "Plant_Leaves_Redwood"
  },
  {
   "x": -6,
   "y": 1,
   "z": 10,
   "name": "Rock_Basalt"
  },
  {
   "x": -6,
   "y": 2,
   "z": 10,
   "name": "Rock_Basalt"
  },
  {
   "x": -6,
   "y": 3,
   "z": 10,
   "name": "Rock_Basalt"
  },
  {
   "x": -6,
   "y": 4,
   "z": 10,
   "name": "Rock_Basalt"
  },
  {
   "x": -6,
   "y": 5,
   "z": 10,
   "name": "Rock_Basalt"
  },
  {
   "x": -6,
   "y": 6,
   "z": 10,
   "name": "Rock_Basalt"
  },
  {
   "x": -6,
   "y": 7,
   "z": 10,
   "name": "Rock_Basalt"
  },
  {
   "x": -6,
   "y": 8,
   "z": 10,
   "name": "Rock_Basalt"
  },
  {
   "x": -6,
   "y": 9,
   "z": 10,
   "name": "Soil_Dirt"
  },
  {
   "x": -6,
   "y": 10,
   "z": 10,
   "name": "Soil_Needles"
  },
  {
   "x": -6,
   "y": 18,
   "z": 10,
   "name": "Plant_Leaves_Redwood"
  },
  {
   "x": -6,
   "y": 19,
   "z": 10,
   "name": "Plant_Leaves_Redwood"
  },
  {
   "x": -6,
   "y": 22,
   "z": 10,
   "name": "Plant_Leaves_Redwood"
  },
  {
   "x": -6,
   "y": 30,
   "z": 10,
   "name": "Plant_Leaves_Redwood"
  },
  {
   "x": -6,
   "y": 1,
   "z": 11,
   "name": "Rock_Basalt"
  },
  {
   "x": -6,
   "y": 2,
   "z": 11,
   "name": "Rock_Basalt"
  },
  {
   "x": -6,
   "y": 3,
   "z": 11,
   "name": "Rock_Basalt"
  },
  {
   "x": -6,
   "y": 4,
   "z": 11,
   "name": "Rock_Basalt"
  },
  {
   "x": -6,
   "y": 5,
   "z": 11,
   "name": "Rock_Basalt"
  },
  {
   "x": -6,
   "y": 6,
   "z": 11,
   "name": "Rock_Basalt"
  },
  {
   "x": -6,
   "y": 7,
   "z": 11,
   "name": "Rock_Basalt"
  },
  {
   "x": -6,
   "y": 8,
   "z": 11,
   "name": "Rock_Basalt"
  },
  {
   "x": -6,
   "y": 9,
   "z": 11,
   "name": "Soil_Dirt"
  },
  {
   "x": -6,
   "y": 10,
   "z": 11,
   "name": "Soil_Needles"
  },
  {
   "x": -6,
   "y": 19,
   "z": 11,
   "name": "Plant_Leaves_Redwood"
  },
  {
   "x": -6,
   "y": 22,
   "z": 11,
   "name": "Plant_Leaves_Redwood"
  },
  {
   "x": -6,
   "y": 24,
   "z": 11,
   "name": "Plant_Leaves_Redwood"
  },
  {
   "x": -6,
   "y": 26,
   "z": 11,
   "name": "Plant_Leaves_Redwood"
  },
  {
   "x": -6,
   "y": 29,
   "z": 11,
   "name": "Plant_Leaves_Redwood"
  },
  {
   "x": -6,
   "y": 31,
   "z": 11,
   "name": "Plant_Leaves_Redwood"
  },
  {
   "x": -6,
   "y": 34,
   "z": 11,
   "name": "Plant_Leaves_Redwood"
  },
  {
   "x": -6,
   "y": 35,
   "z": 11,
   "name": "Plant_Leaves_Redwood"
  },
  {
   "x": -6,
   "y": 1,
   "z": 12,
   "name": "Rock_Basalt"
  },
  {
   "x": -6,
   "y": 2,
   "z": 12,
   "name": "Rock_Basalt"
  },
  {
   "x": -6,
   "y": 3,
   "z": 12,
   "name": "Rock_Basalt"
  },
  {
   "x": -6,
   "y": 4,
   "z": 12,
   "name": "Rock_Basalt"
  },
  {
   "x": -6,
   "y": 5,
   "z": 12,
   "name": "Rock_Basalt"
  },
  {
   "x": -6,
   "y": 6,
   "z": 12,
   "name": "Rock_Basalt"
  },
  {
   "x": -6,
   "y": 7,
   "z": 12,
   "name": "Rock_Basalt"
  },
  {
   "x": -6,
   "y": 8,
   "z": 12,
   "name": "Rock_Basalt"
  },
  {
   "x": -6,
   "y": 9,
   "z": 12,
   "name": "Soil_Dirt"
  },
  {
   "x": -6,
   "y": 10,
   "z": 12,
   "name": "Wood_Redwood_Trunk"
  },
  {
   "x": -6,
   "y": 11,
   "z": 12,
   "name": "Wood_Redwood_Trunk_Full"
  },
  {
   "x": -6,
   "y": 18,
   "z": 12,
   "name": "Plant_Leaves_Redwood"
  },
  {
   "x": -6,
   "y": 19,
   "z": 12,
   "name": "Wood_Redwood_Branch_Long",
   "rotation": 5
  },
  {
   "x": -6,
   "y": 23,
   "z": 12,
   "name": "Plant_Leaves_Redwood"
  },
  {
   "x": -6,
   "y": 24,
   "z": 12,
   "name": "Wood_Redwood_Branch_Corner",
   "rotation": 1
  },
  {
   "x": -6,
   "y": 25,
   "z": 12,
   "name": "Plant_Leaves_Redwood"
  },
  {
   "x": -6,
   "y": 26,
   "z": 12,
   "name": "Plant_Leaves_Redwood"
  },
  {
   "x": -6,
   "y": 29,
   "z": 12,
   "name": "Wood_Redwood_Branch_Long",
   "rotation": 5
  },
  {
   "x": -6,
   "y": 34,
   "z": 12,
   "name": "Wood_Redwood_Branch_Long",
   "rotation": 5
  },
  {
   "x": -6,
   "y": 35,
   "z": 12,
   "name": "Plant_Leaves_Redwood"
  },
  {
   "x": -6,
   "y": 36,
   "z": 12,
   "name": "Plant_Leaves_Redwood"
  },
  {
   "x": -6,
   "y": 37,
   "z": 12,
   "name": "Plant_Leaves_Redwood"
  },
  {
   "x": -6,
   "y": 1,
   "z": 13,
   "name": "Rock_Basalt"
  },
  {
   "x": -6,
   "y": 2,
   "z": 13,
   "name": "Rock_Basalt"
  },
  {
   "x": -6,
   "y": 3,
   "z": 13,
   "name": "Rock_Basalt"
  },
  {
   "x": -6,
   "y": 4,
   "z": 13,
   "name": "Rock_Basalt"
  },
  {
   "x": -6,
   "y": 5,
   "z": 13,
   "name": "Rock_Basalt"
  },
  {
   "x": -6,
   "y": 6,
   "z": 13,
   "name": "Rock_Basalt"
  },
  {
   "x": -6,
   "y": 7,
   "z": 13,
   "name": "Rock_Basalt"
  },
  {
   "x": -6,
   "y": 8,
   "z": 13,
   "name": "Wood_Redwood_Trunk"
  },
  {
   "x": -6,
   "y": 9,
   "z": 13,
   "name": "Wood_Redwood_Trunk"
  },
  {
   "x": -6,
   "y": 10,
   "z": 13,
   "name": "Wood_Redwood_Trunk_Full"
  },
  {
   "x": -6,
   "y": 19,
   "z": 13,
   "name": "Plant_Leaves_Redwood"
  },
  {
   "x": -6,
   "y": 21,
   "z": 13,
   "name": "Plant_Leaves_Redwood"
  },
  {
   "x": -6,
   "y": 24,
   "z": 13,
   "name": "Plant_Leaves_Redwood"
  },
  {
   "x": -6,
   "y": 26,
   "z": 13,
   "name": "Plant_Leaves_Redwood"
  },
  {
   "x": -6,
   "y": 29,
   "z": 13,
   "name": "Plant_Leaves_Redwood"
  },
  {
   "x": -6,
   "y": 31,
   "z": 13,
   "name": "Plant_Leaves_Redwood"
  },
  {
   "x": -6,
   "y": 34,
   "z": 13,
   "name": "Plant_Leaves_Redwood"
  },
  {
   "x": -6,
   "y": 35,
   "z": 13,
   "name": "Plant_Leaves_Redwood"
  },
  {
   "x": -6,
   "y": 1,
   "z": 14,
   "name": "Rock_Basalt"
  },
  {
   "x": -6,
   "y": 2,
   "z": 14,
   "name": "Rock_Basalt"
  },
  {
   "x": -6,
   "y": 3,
   "z": 14,
   "name": "Rock_Basalt"
  },
  {
   "x": -6,
   "y": 4,
   "z": 14,
   "name": "Rock_Basalt"
  },
  {
   "x": -6,
   "y": 5,
   "z": 14,
   "name": "Rock_Basalt"
  },
  {
   "x": -6,
   "y": 6,
   "z": 14,
   "name": "Rock_Basalt"
  },
  {
   "x": -6,
   "y": 7,
   "z": 14,
   "name": "Wood_Redwood_Trunk"
  },
  {
   "x": -6,
   "y": 8,
   "z": 14,
   "name": "Wood_Redwood_Trunk_Full"
  },
  {
   "x": -6,
   "y": 9,
   "z": 14,
   "name": "Soil_Needles"
  },
  {
   "x": -6,
   "y": 18,
   "z": 14,
   "name": "Plant_Leaves_Redwood"
  },
  {
   "x": -6,
   "y": 21,
   "z": 14,
   "name": "Plant_Leaves_Redwood"
  },
  {
   "x": -6,
   "y": 26,
   "z": 14,
   "name": "Plant_Leaves_Redwood"
  },
  {
   "x": -6,
   "y": 34,
   "z": 14,
   "name": "Plant_Leaves_Redwood"
  },
  {
   "x": -6,
   "y": 3,
   "z": 15,
   "name": "Rock_Basalt"
  },
  {
   "x": -6,
   "y": 4,
   "z": 15,
   "name": "Rock_Basalt"
  },
  {
   "x": -6,
   "y": 5,
   "z": 15,
   "name": "Rock_Basalt"
  },
  {
   "x": -6,
   "y": 6,
   "z": 15,
   "name": "Rock_Basalt"
  },
  {
   "x": -6,
   "y": 7,
   "z": 15,
   "name": "Rock_Basalt"
  },
  {
   "x": -6,
   "y": 8,
   "z": 15,
   "name": "Soil_Dirt"
  },
  {
   "x": -6,
   "y": 9,
   "z": 15,
   "name": "Soil_Grass"
  },
  {
   "x": -6,
   "y": 18,
   "z": 15,
   "name": "Plant_Leaves_Redwood"
  },
  {
   "x": -6,
   "y": 8,
   "z": 16,
   "name": "Soil_Grass"
  },
  {
   "x": -5,
   "y": 11,
   "z": -14,
   "name": "Rock_Basalt"
  },
  {
   "x": -5,
   "y": 12,
   "z": -14,
   "name": "Rock_Basalt"
  },
  {
   "x": -5,
   "y": 13,
   "z": -14,
   "name": "Soil_Dirt"
  },
  {
   "x": -5,
   "y": 14,
   "z": -14,
   "name": "Soil_Grass"
  },
  {
   "x": -5,
   "y": 6,
   "z": -13,
   "name": "Rock_Basalt"
  },
  {
   "x": -5,
   "y": 7,
   "z": -13,
   "name": "Rock_Basalt"
  },
  {
   "x": -5,
   "y": 8,
   "z": -13,
   "name": "Rock_Basalt"
  },
  {
   "x": -5,
   "y": 9,
   "z": -13,
   "name": "Rock_Basalt"
  },
  {
   "x": -5,
   "y": 10,
   "z": -13,
   "name": "Rock_Basalt"
  },
  {
   "x": -5,
   "y": 11,
   "z": -13,
   "name": "Rock_Basalt"
  },
  {
   "x": -5,
   "y": 12,
   "z": -13,
   "name": "Rock_Basalt"
  },
  {
   "x": -5,
   "y": 13,
   "z": -13,
   "name": "Soil_Dirt"
  },
  {
   "x": -5,
   "y": 14,
   "z": -13,
   "name": "Soil_Grass"
  },
  {
   "x": -5,
   "y": 15,
   "z": -13,
   "name": "Plant_Flower_Flax_Blue"
  },
  {
   "x": -5,
   "y": 3,
   "z": -12,
   "name": "Rock_Basalt"
  },
  {
   "x": -5,
   "y": 4,
   "z": -12,
   "name": "Rock_Basalt"
  },
  {
   "x": -5,
   "y": 5,
   "z": -12,
   "name": "Rock_Basalt"
  },
  {
   "x": -5,
   "y": 6,
   "z": -12,
   "name": "Rock_Basalt"
  },
  {
   "x": -5,
   "y": 7,
   "z": -12,
   "name": "Rock_Basalt"
  },
  {
   "x": -5,
   "y": 8,
   "z": -12,
   "name": "Rock_Basalt"
  },
  {
   "x": -5,
   "y": 9,
   "z": -12,
   "name": "Wood_Redwood_Trunk",
   "support": 15
  },
  {
   "x": -5,
   "y": 10,
   "z": -12,
   "name": "Wood_Redwood_Trunk",
   "support": 15
  },
  {
   "x": -5,
   "y": 11,
   "z": -12,
   "name": "Rock_Basalt"
  },
  {
   "x": -5,
   "y": 12,
   "z": -12,
   "name": "Rock_Basalt"
  },
  {
   "x": -5,
   "y": 13,
   "z": -12,
   "name": "Soil_Dirt"
  },
  {
   "x": -5,
   "y": 14,
   "z": -12,
   "name": "Soil_Grass"
  },
  {
   "x": -5,
   "y": 3,
   "z": -11,
   "name": "Rock_Basalt"
  },
  {
   "x": -5,
   "y": 4,
   "z": -11,
   "name": "Rock_Basalt"
  },
  {
   "x": -5,
   "y": 5,
   "z": -11,
   "name": "Rock_Basalt"
  },
  {
   "x": -5,
   "y": 6,
   "z": -11,
   "name": "Rock_Basalt"
  },
  {
   "x": -5,
   "y": 7,
   "z": -11,
   "name": "Rock_Basalt"
  },
  {
   "x": -5,
   "y": 8,
   "z": -11,
   "name": "Wood_Redwood_Trunk",
   "support": 15
  },
  {
   "x": -5,
   "y": 9,
   "z": -11,
   "name": "Wood_Redwood_Trunk",
   "support": 15
  },
  {
   "x": -5,
   "y": 10,
   "z": -11,
   "name": "Wood_Redwood_Trunk",
   "support": 15
  },
  {
   "x": -5,
   "y": 11,
   "z": -11,
   "name": "Rock_Basalt"
  },
  {
   "x": -5,
   "y": 12,
   "z": -11,
   "name": "Rock_Basalt"
  },
  {
   "x": -5,
   "y": 13,
   "z": -11,
   "name": "Soil_Dirt"
  },
  {
   "x": -5,
   "y": 14,
   "z": -11,
   "name": "Soil_Grass"
  },
  {
   "x": -5,
   "y": 3,
   "z": -10,
   "name": "Rock_Basalt"
  },
  {
   "x": -5,
   "y": 4,
   "z": -10,
   "name": "Rock_Basalt"
  },
  {
   "x": -5,
   "y": 5,
   "z": -10,
   "name": "Rock_Basalt"
  },
  {
   "x": -5,
   "y": 6,
   "z": -10,
   "name": "Rock_Basalt"
  },
  {
   "x": -5,
   "y": 7,
   "z": -10,
   "name": "Rock_Basalt"
  },
  {
   "x": -5,
   "y": 8,
   "z": -10,
   "name": "Rock_Basalt"
  },
  {
   "x": -5,
   "y": 9,
   "z": -10,
   "name": "Rock_Basalt"
  },
  {
   "x": -5,
   "y": 10,
   "z": -10,
   "name": "Rock_Basalt"
  },
  {
   "x": -5,
   "y": 11,
   "z": -10,
   "name": "Rock_Basalt"
  },
  {
   "x": -5,
   "y": 12,
   "z": -10,
   "name": "Rock_Basalt"
  },
  {
   "x": -5,
   "y": 13,
   "z": -10,
   "name": "Soil_Dirt"
  },
  {
   "x": -5,
   "y": 14,
   "z": -10,
   "name": "Soil_Needles"
  },
  {
   "x": -5,
   "y": 2,
   "z": -9,
   "name": "Rock_Basalt"
  },
  {
   "x": -5,
   "y": 3,
   "z": -9,
   "name": "Rock_Basalt"
  },
  {
   "x": -5,
   "y": 4,
   "z": -9,
   "name": "Rock_Basalt"
  },
  {
   "x": -5,
   "y": 5,
   "z": -9,
   "name": "Rock_Basalt"
  },
  {
   "x": -5,
   "y": 6,
   "z": -9,
   "name": "Rock_Basalt"
  },
  {
   "x": -5,
   "y": 7,
   "z": -9,
   "name": "Rock_Basalt"
  },
  {
   "x": -5,
   "y": 8,
   "z": -9,
   "name": "Rock_Basalt"
  },
  {
   "x": -5,
   "y": 9,
   "z": -9,
   "name": "Rock_Basalt"
  },
  {
   "x": -5,
   "y": 10,
   "z": -9,
   "name": "Rock_Basalt"
  },
  {
   "x": -5,
   "y": 11,
   "z": -9,
   "name": "Rock_Basalt"
  },
  {
   "x": -5,
   "y": 12,
   "z": -9,
   "name": "Rock_Basalt"
  },
  {
   "x": -5,
   "y": 13,
   "z": -9,
   "name": "Rock_Basalt"
  },
  {
   "x": -5,
   "y": 14,
   "z": -9,
   "name": "Soil_Dirt"
  },
  {
   "x": -5,
   "y": 15,
   "z": -9,
   "name": "Soil_Needles"
  },
  {
   "x": -5,
   "y": 2,
   "z": -8,
   "name": "Rock_Basalt"
  },
  {
   "x": -5,
   "y": 3,
   "z": -8,
   "name": "Rock_Basalt"
  },
  {
   "x": -5,
   "y": 4,
   "z": -8,
   "name": "Rock_Basalt"
  },
  {
   "x": -5,
   "y": 5,
   "z": -8,
   "name": "Rock_Basalt"
  },
  {
   "x": -5,
   "y": 6,
   "z": -8,
   "name": "Rock_Basalt"
  },
  {
   "x": -5,
   "y": 7,
   "z": -8,
   "name": "Rock_Basalt"
  },
  {
   "x": -5,
   "y": 8,
   "z": -8,
   "name": "Rock_Basalt"
  },
  {
   "x": -5,
   "y": 9,
   "z": -8,
   "name": "Rock_Basalt"
  },
  {
   "x": -5,
   "y": 10,
   "z": -8,
   "name": "Rock_Basalt"
  },
  {
   "x": -5,
   "y": 11,
   "z": -8,
   "name": "Rock_Basalt"
  },
  {
   "x": -5,
   "y": 12,
   "z": -8,
   "name": "Rock_Basalt"
  },
  {
   "x": -5,
   "y": 13,
   "z": -8,
   "name": "Rock_Basalt"
  },
  {
   "x": -5,
   "y": 14,
   "z": -8,
   "name": "Soil_Dirt"
  },
  {
   "x": -5,
   "y": 15,
   "z": -8,
   "name": "Soil_Needles"
  },
  {
   "x": -5,
   "y": 2,
   "z": -7,
   "name": "Rock_Basalt"
  },
  {
   "x": -5,
   "y": 3,
   "z": -7,
   "name": "Rock_Basalt"
  },
  {
   "x": -5,
   "y": 4,
   "z": -7,
   "name": "Rock_Basalt"
  },
  {
   "x": -5,
   "y": 5,
   "z": -7,
   "name": "Rock_Basalt"
  },
  {
   "x": -5,
   "y": 6,
   "z": -7,
   "name": "Rock_Basalt"
  },
  {
   "x": -5,
   "y": 7,
   "z": -7,
   "name": "Rock_Basalt"
  },
  {
   "x": -5,
   "y": 8,
   "z": -7,
   "name": "Rock_Basalt"
  },
  {
   "x": -5,
   "y": 9,
   "z": -7,
   "name": "Rock_Basalt"
  },
  {
   "x": -5,
   "y": 10,
   "z": -7,
   "name": "Rock_Basalt"
  },
  {
   "x": -5,
   "y": 11,
   "z": -7,
   "name": "Rock_Basalt"
  },
  {
   "x": -5,
   "y": 12,
   "z": -7,
   "name": "Rock_Basalt"
  },
  {
   "x": -5,
   "y": 13,
   "z": -7,
   "name": "Rock_Basalt"
  },
  {
   "x": -5,
   "y": 14,
   "z": -7,
   "name": "Rock_Basalt"
  },
  {
   "x": -5,
   "y": 15,
   "z": -7,
   "name": "Soil_Needles"
  },
  {
   "x": -5,
   "y": 32,
   "z": -7,
   "name": "Plant_Leaves_Redwood"
  },
  {
   "x": -5,
   "y": 2,
   "z": -6,
   "name": "Rock_Basalt"
  },
  {
   "x": -5,
   "y": 3,
   "z": -6,
   "name": "Rock_Basalt"
  },
  {
   "x": -5,
   "y": 4,
   "z": -6,
   "name": "Rock_Basalt"
  },
  {
   "x": -5,
   "y": 5,
   "z": -6,
   "name": "Rock_Basalt"
  },
  {
   "x": -5,
   "y": 6,
   "z": -6,
   "name": "Rock_Basalt"
  },
  {
   "x": -5,
   "y": 7,
   "z": -6,
   "name": "Rock_Basalt"
  },
  {
   "x": -5,
   "y": 8,
   "z": -6,
   "name": "Rock_Basalt"
  },
  {
   "x": -5,
   "y": 9,
   "z": -6,
   "name": "Rock_Basalt"
  },
  {
   "x": -5,
   "y": 10,
   "z": -6,
   "name": "Rock_Basalt"
  },
  {
   "x": -5,
   "y": 11,
   "z": -6,
   "name": "Rock_Basalt"
  },
  {
   "x": -5,
   "y": 12,
   "z": -6,
   "name": "Rock_Basalt"
  },
  {
   "x": -5,
   "y": 13,
   "z": -6,
   "name": "Rock_Basalt"
  },
  {
   "x": -5,
   "y": 14,
   "z": -6,
   "name": "Soil_Dirt"
  },
  {
   "x": -5,
   "y": 15,
   "z": -6,
   "name": "Soil_Needles"
  },
  {
   "x": -5,
   "y": 32,
   "z": -6,
   "name": "Plant_Leaves_Redwood"
  },
  {
   "x": -5,
   "y": 41,
   "z": -6,
   "name": "Plant_Leaves_Redwood"
  },
  {
   "x": -5,
   "y": 45,
   "z": -6,
   "name": "Plant_Leaves_Redwood"
  },
  {
   "x": -5,
   "y": 2,
   "z": -5,
   "name": "Rock_Basalt"
  },
  {
   "x": -5,
   "y": 3,
   "z": -5,
   "name": "Rock_Basalt"
  },
  {
   "x": -5,
   "y": 4,
   "z": -5,
   "name": "Rock_Basalt"
  },
  {
   "x": -5,
   "y": 5,
   "z": -5,
   "name": "Rock_Basalt"
  },
  {
   "x": -5,
   "y": 6,
   "z": -5,
   "name": "Rock_Basalt"
  },
  {
   "x": -5,
   "y": 7,
   "z": -5,
   "name": "Rock_Basalt"
  },
  {
   "x": -5,
   "y": 8,
   "z": -5,
   "name": "Rock_Basalt"
  },
  {
   "x": -5,
   "y": 9,
   "z": -5,
   "name": "Rock_Basalt"
  },
  {
   "x": -5,
   "y": 10,
   "z": -5,
   "name": "Rock_Basalt"
  },
  {
   "x": -5,
   "y": 11,
   "z": -5,
   "name": "Rock_Basalt"
  },
  {
   "x": -5,
   "y": 12,
   "z": -5,
   "name": "Rock_Basalt"
  },
  {
   "x": -5,
   "y": 13,
   "z": -5,
   "name": "Rock_Basalt"
  },
  {
   "x": -5,
   "y": 14,
   "z": -5,
   "name": "Soil_Dirt"
  },
  {
   "x": -5,
   "y": 15,
   "z": -5,
   "name": "Soil_Grass"
  },
  {
   "x": -5,
   "y": 32,
   "z": -5,
   "name": "Plant_Leaves_Redwood"
  },
  {
   "x": -5,
   "y": 41,
   "z": -5,
   "name": "Plant_Leaves_Redwood"
  },
  {
   "x": -5,
   "y": 2,
   "z": -4,
   "name": "Rock_Basalt"
  },
  {
   "x": -5,
   "y": 3,
   "z": -4,
   "name": "Rock_Basalt"
  },
  {
   "x": -5,
   "y": 4,
   "z": -4,
   "name": "Rock_Basalt"
  },
  {
   "x": -5,
   "y": 5,
   "z": -4,
   "name": "Rock_Basalt"
  },
  {
   "x": -5,
   "y": 6,
   "z": -4,
   "name": "Rock_Basalt"
  },
  {
   "x": -5,
   "y": 7,
   "z": -4,
   "name": "Rock_Basalt"
  },
  {
   "x": -5,
   "y": 8,
   "z": -4,
   "name": "Rock_Basalt"
  },
  {
   "x": -5,
   "y": 9,
   "z": -4,
   "name": "Rock_Basalt"
  },
  {
   "x": -5,
   "y": 10,
   "z": -4,
   "name": "Rock_Basalt"
  },
  {
   "x": -5,
   "y": 11,
   "z": -4,
   "name": "Rock_Basalt"
  },
  {
   "x": -5,
   "y": 12,
   "z": -4,
   "name": "Rock_Basalt"
  },
  {
   "x": -5,
   "y": 13,
   "z": -4,
   "name": "Rock_Basalt"
  },
  {
   "x": -5,
   "y": 14,
   "z": -4,
   "name": "Soil_Dirt"
  },
  {
   "x": -5,
   "y": 15,
   "z": -4,
   "name": "Soil_Dirt"
  },
  {
   "x": -5,
   "y": 16,
   "z": -4,
   "name": "Soil_Grass"
  },
  {
   "x": -5,
   "y": 2,
   "z": -3,
   "name": "Rock_Basalt"
  },
  {
   "x": -5,
   "y": 3,
   "z": -3,
   "name": "Rock_Basalt"
  },
  {
   "x": -5,
   "y": 4,
   "z": -3,
   "name": "Rock_Basalt"
  },
  {
   "x": -5,
   "y": 5,
   "z": -3,
   "name": "Rock_Basalt"
  },
  {
   "x": -5,
   "y": 6,
   "z": -3,
   "name": "Rock_Basalt"
  },
  {
   "x": -5,
   "y": 7,
   "z": -3,
   "name": "Rock_Basalt"
  },
  {
   "x": -5,
   "y": 8,
   "z": -3,
   "name": "Rock_Basalt"
  },
  {
   "x": -5,
   "y": 9,
   "z": -3,
   "name": "Rock_Basalt"
  },
  {
   "x": -5,
   "y": 10,
   "z": -3,
   "name": "Rock_Basalt"
  },
  {
   "x": -5,
   "y": 11,
   "z": -3,
   "name": "Rock_Basalt"
  },
  {
   "x": -5,
   "y": 12,
   "z": -3,
   "name": "Rock_Basalt"
  },
  {
   "x": -5,
   "y": 13,
   "z": -3,
   "name": "Rock_Basalt"
  },
  {
   "x": -5,
   "y": 14,
   "z": -3,
   "name": "Rock_Basalt"
  },
  {
   "x": -5,
   "y": 15,
   "z": -3,
   "name": "Soil_Dirt"
  },
  {
   "x": -5,
   "y": 16,
   "z": -3,
   "name": "Soil_Grass"
  },
  {
   "x": -5,
   "y": 17,
   "z": -3,
   "name": "Plant_Grass_Winter_Short"
  },
  {
   "x": -5,
   "y": 2,
   "z": -2,
   "name": "Rock_Basalt"
  },
  {
   "x": -5,
   "y": 3,
   "z": -2,
   "name": "Rock_Basalt"
  },
  {
   "x": -5,
   "y": 4,
   "z": -2,
   "name": "Rock_Basalt"
  },
  {
   "x": -5,
   "y": 5,
   "z": -2,
   "name": "Rock_Basalt"
  },
  {
   "x": -5,
   "y": 6,
   "z": -2,
   "name": "Rock_Basalt"
  },
  {
   "x": -5,
   "y": 7,
   "z": -2,
   "name": "Rock_Basalt"
  },
  {
   "x": -5,
   "y": 8,
   "z": -2,
   "name": "Rock_Basalt"
  },
  {
   "x": -5,
   "y": 9,
   "z": -2,
   "name": "Rock_Basalt"
  },
  {
   "x": -5,
   "y": 10,
   "z": -2,
   "name": "Rock_Basalt"
  },
  {
   "x": -5,
   "y": 11,
   "z": -2,
   "name": "Rock_Basalt"
  },
  {
   "x": -5,
   "y": 12,
   "z": -2,
   "name": "Rock_Basalt"
  },
  {
   "x": -5,
   "y": 13,
   "z": -2,
   "name": "Rock_Basalt"
  },
  {
   "x": -5,
   "y": 14,
   "z": -2,
   "name": "Rock_Basalt"
  },
  {
   "x": -5,
   "y": 15,
   "z": -2,
   "name": "Rock_Basalt"
  },
  {
   "x": -5,
   "y": 16,
   "z": -2,
   "name": "Soil_Grass"
  },
  {
   "x": -5,
   "y": 3,
   "z": -1,
   "name": "Rock_Basalt"
  },
  {
   "x": -5,
   "y": 4,
   "z": -1,
   "name": "Rock_Basalt"
  },
  {
   "x": -5,
   "y": 5,
   "z": -1,
   "name": "Rock_Basalt"
  },
  {
   "x": -5,
   "y": 6,
   "z": -1,
   "name": "Rock_Basalt"
  },
  {
   "x": -5,
   "y": 7,
   "z": -1,
   "name": "Rock_Basalt"
  },
  {
   "x": -5,
   "y": 8,
   "z": -1,
   "name": "Rock_Basalt"
  },
  {
   "x": -5,
   "y": 9,
   "z": -1,
   "name": "Rock_Basalt"
  },
  {
   "x": -5,
   "y": 10,
   "z": -1,
   "name": "Rock_Basalt"
  },
  {
   "x": -5,
   "y": 11,
   "z": -1,
   "name": "Rock_Basalt"
  },
  {
   "x": -5,
   "y": 12,
   "z": -1,
   "name": "Rock_Basalt"
  },
  {
   "x": -5,
   "y": 13,
   "z": -1,
   "name": "Rock_Basalt"
  },
  {
   "x": -5,
   "y": 14,
   "z": -1,
   "name": "Rock_Basalt"
  },
  {
   "x": -5,
   "y": 15,
   "z": -1,
   "name": "Soil_Dirt"
  },
  {
   "x": -5,
   "y": 16,
   "z": -1,
   "name": "Soil_Grass"
  },
  {
   "x": -5,
   "y": 36,
   "z": -1,
   "name": "Plant_Leaves_Redwood"
  },
  {
   "x": -5,
   "y": 3,
   "z": 0,
   "name": "Rock_Basalt"
  },
  {
   "x": -5,
   "y": 4,
   "z": 0,
   "name": "Rock_Basalt"
  },
  {
   "x": -5,
   "y": 5,
   "z": 0,
   "name": "Rock_Basalt"
  },
  {
   "x": -5,
   "y": 6,
   "z": 0,
   "name": "Rock_Basalt"
  },
  {
   "x": -5,
   "y": 7,
   "z": 0,
   "name": "Rock_Basalt"
  },
  {
   "x": -5,
   "y": 8,
   "z": 0,
   "name": "Rock_Basalt"
  },
  {
   "x": -5,
   "y": 9,
   "z": 0,
   "name": "Rock_Basalt"
  },
  {
   "x": -5,
   "y": 10,
   "z": 0,
   "name": "Rock_Basalt"
  },
  {
   "x": -5,
   "y": 11,
   "z": 0,
   "name": "Rock_Basalt"
  },
  {
   "x": -5,
   "y": 12,
   "z": 0,
   "name": "Rock_Basalt"
  },
  {
   "x": -5,
   "y": 13,
   "z": 0,
   "name": "Rock_Basalt"
  },
  {
   "x": -5,
   "y": 14,
   "z": 0,
   "name": "Rock_Basalt"
  },
  {
   "x": -5,
   "y": 15,
   "z": 0,
   "name": "Soil_Dirt"
  },
  {
   "x": -5,
   "y": 16,
   "z": 0,
   "name": "Soil_Grass"
  },
  {
   "x": -5,
   "y": 36,
   "z": 0,
   "name": "Plant_Leaves_Redwood"
  },
  {
   "x": -5,
   "y": 3,
   "z": 1,
   "name": "Rock_Basalt"
  },
  {
   "x": -5,
   "y": 4,
   "z": 1,
   "name": "Rock_Basalt"
  },
  {
   "x": -5,
   "y": 5,
   "z": 1,
   "name": "Rock_Basalt"
  },
  {
   "x": -5,
   "y": 6,
   "z": 1,
   "name": "Rock_Basalt"
  },
  {
   "x": -5,
   "y": 7,
   "z": 1,
   "name": "Rock_Basalt"
  },
  {
   "x": -5,
   "y": 8,
   "z": 1,
   "name": "Rock_Basalt"
  },
  {
   "x": -5,
   "y": 9,
   "z": 1,
   "name": "Rock_Basalt"
  },
  {
   "x": -5,
   "y": 10,
   "z": 1,
   "name": "Rock_Basalt"
  },
  {
   "x": -5,
   "y": 11,
   "z": 1,
   "name": "Rock_Basalt"
  },
  {
   "x": -5,
   "y": 12,
   "z": 1,
   "name": "Soil_Grass"
  },
  {
   "x": -5,
   "y": 3,
   "z": 2,
   "name": "Rock_Basalt"
  },
  {
   "x": -5,
   "y": 4,
   "z": 2,
   "name": "Rock_Basalt"
  },
  {
   "x": -5,
   "y": 5,
   "z": 2,
   "name": "Rock_Basalt"
  },
  {
   "x": -5,
   "y": 6,
   "z": 2,
   "name": "Rock_Basalt"
  },
  {
   "x": -5,
   "y": 7,
   "z": 2,
   "name": "Rock_Basalt"
  },
  {
   "x": -5,
   "y": 8,
   "z": 2,
   "name": "Rock_Basalt"
  },
  {
   "x": -5,
   "y": 9,
   "z": 2,
   "name": "Rock_Basalt"
  },
  {
   "x": -5,
   "y": 10,
   "z": 2,
   "name": "Rock_Basalt"
  },
  {
   "x": -5,
   "y": 11,
   "z": 2,
   "name": "Soil_Dirt"
  },
  {
   "x": -5,
   "y": 12,
   "z": 2,
   "name": "Soil_Grass"
  },
  {
   "x": -5,
   "y": 13,
   "z": 2,
   "name": "Plant_Grass_Winter_Short"
  },
  {
   "x": -5,
   "y": 2,
   "z": 3,
   "name": "Rock_Basalt"
  },
  {
   "x": -5,
   "y": 3,
   "z": 3,
   "name": "Rock_Basalt"
  },
  {
   "x": -5,
   "y": 4,
   "z": 3,
   "name": "Rock_Basalt"
  },
  {
   "x": -5,
   "y": 5,
   "z": 3,
   "name": "Rock_Basalt"
  },
  {
   "x": -5,
   "y": 6,
   "z": 3,
   "name": "Rock_Basalt"
  },
  {
   "x": -5,
   "y": 7,
   "z": 3,
   "name": "Rock_Basalt"
