{
 "version": 8,
 "blockIdVersion": 11,
 "anchorX": -5,
 "anchorY": 7,
 "anchorZ": 0,
 "blocks": [
  {
   "x": -12,
   "y": 14,
   "z": 4,
   "name": "Soil_Dirt"
  },
  {
   "x": -12,
   "y": 15,
   "z": 4,
   "name": "Soil_Dirt"
  },
  {
   "x": -12,
   "y": 16,
   "z": 4,
   "name": "Soil_Grass"
  },
  {
   "x": -12,
   "y": 14,
   "z": 5,
   "name": "Rock_Basalt"
  },
  {
   "x": -12,
   "y": 15,
   "z": 5,
   "name": "Soil_Dirt"
  },
  {
   "x": -12,
   "y": 16,
   "z": 5,
   "name": "Soil_Grass"
  },
  {
   "x": -12,
   "y": 15,
   "z": 6,
   "name": "Soil_Dirt"
  },
  {
   "x": -12,
   "y": 16,
   "z": 6,
   "name": "Soil_Grass"
  },
  {
   "x": -12,
   "y": 16,
   "z": 7,
   "name": "Soil_Grass"
  },
  {
   "x": -11,
   "y": 12,
   "z": 2,
   "name": "Rock_Basalt"
  },
  {
   "x": -11,
   "y": 13,
   "z": 2,
   "name": "Rock_Basalt"
  },
  {
   "x": -11,
   "y": 14,
   "z": 2,
   "name": "Soil_Dirt"
  },
  {
   "x": -11,
   "y": 15,
   "z": 2,
   "name": "Soil_Grass"
  },
  {
   "x": -11,
   "y": 8,
   "z": 3,
   "name": "Rock_Basalt"
  },
  {
   "x": -11,
   "y": 9,
   "z": 3,
   "name": "Rock_Basalt"
  },
  {
   "x": -11,
   "y": 10,
   "z": 3,
   "name": "Rock_Basalt"
  },
  {
   "x": -11,
   "y": 11,
   "z": 3,
   "name": "Rock_Basalt"
  },
  {
   "x": -11,
   "y": 12,
   "z": 3,
   "name": "Rock_Basalt"
  },
  {
   "x": -11,
   "y": 13,
   "z": 3,
   "name": "Rock_Basalt"
  },
  {
   "x": -11,
   "y": 14,
   "z": 3,
   "name": "Soil_Dirt"
  },
  {
   "x": -11,
   "y": 15,
   "z": 3,
   "name": "Soil_Dirt"
  },
  {
   "x": -11,
   "y": 16,
   "z": 3,
   "name": "Soil_Grass"
  },
  {
   "x": -11,
   "y": 7,
   "z": 4,
   "name": "Rock_Basalt"
  },
  {
   "x": -11,
   "y": 8,
   "z": 4,
   "name": "Rock_Basalt"
  },
  {
   "x": -11,
   "y": 9,
   "z": 4,
   "name": "Rock_Basalt"
  },
  {
   "x": -11,
   "y": 10,
   "z": 4,
   "name": "Rock_Basalt"
  },
  {
   "x": -11,
   "y": 11,
   "z": 4,
   "name": "Rock_Basalt"
  },
  {
   "x": -11,
   "y": 12,
   "z": 4,
   "name": "Rock_Basalt"
  },
  {
   "x": -11,
   "y": 13,
   "z": 4,
   "name": "Rock_Basalt"
  },
  {
   "x": -11,
   "y": 14,
   "z": 4,
   "name": "Soil_Dirt"
  },
  {
   "x": -11,
   "y": 15,
   "z": 4,
   "name": "Soil_Dirt"
  },
  {
   "x": -11,
   "y": 16,
   "z": 4,
   "name": "Soil_Grass"
  },
  {
   "x": -11,
   "y": 7,
   "z": 5,
   "name": "Rock_Basalt"
  },
  {
   "x": -11,
   "y": 8,
   "z": 5,
   "name": "Rock_Basalt"
  },
  {
   "x": -11,
   "y": 9,
   "z": 5,
   "name": "Rock_Basalt"
  },
  {
   "x": -11,
   "y": 10,
   "z": 5,
   "name": "Rock_Basalt"
  },
  {
   "x": -11,
   "y": 11,
   "z": 5,
   "name": "Rock_Basalt"
  },
  {
   "x": -11,
   "y": 12,
   "z": 5,
   "name": "Rock_Basalt"
  },
  {
   "x": -11,
   "y": 13,
   "z": 5,
   "name": "Rock_Basalt"
  },
  {
   "x": -11,
   "y": 14,
   "z": 5,
   "name": "Soil_Dirt"
  },
  {
   "x": -11,
   "y": 15,
   "z": 5,
   "name": "Soil_Dirt"
  },
  {
   "x": -11,
   "y": 16,
   "z": 5,
   "name": "Soil_Grass"
  },
  {
   "x": -11,
   "y": 7,
   "z": 6,
   "name": "Rock_Basalt"
  },
  {
   "x": -11,
   "y": 8,
   "z": 6,
   "name": "Rock_Basalt"
  },
  {
   "x": -11,
   "y": 9,
   "z": 6,
   "name": "Rock_Basalt"
  },
  {
   "x": -11,
   "y": 10,
   "z": 6,
   "name": "Rock_Basalt"
  },
  {
   "x": -11,
   "y": 11,
   "z": 6,
   "name": "Rock_Basalt"
  },
  {
   "x": -11,
   "y": 12,
   "z": 6,
   "name": "Rock_Basalt"
  },
  {
   "x": -11,
   "y": 13,
   "z": 6,
   "name": "Rock_Basalt"
  },
  {
   "x": -11,
   "y": 14,
   "z": 6,
   "name": "Soil_Dirt"
  },
  {
   "x": -11,
   "y": 15,
   "z": 6,
   "name": "Soil_Dirt"
  },
  {
   "x": -11,
   "y": 16,
   "z": 6,
   "name": "Soil_Grass"
  },
  {
   "x": -11,
   "y": 17,
   "z": 6,
   "name": "Plant_Flower_Flax_Blue"
  },
  {
   "x": -11,
   "y": 9,
   "z": 7,
   "name": "Rock_Basalt"
  },
  {
   "x": -11,
   "y": 10,
   "z": 7,
   "name": "Rock_Basalt"
  },
  {
   "x": -11,
   "y": 11,
   "z": 7,
   "name": "Rock_Basalt"
  },
  {
   "x": -11,
   "y": 12,
   "z": 7,
   "name": "Rock_Basalt"
  },
  {
   "x": -11,
   "y": 13,
   "z": 7,
   "name": "Rock_Basalt"
  },
  {
   "x": -11,
   "y": 14,
   "z": 7,
   "name": "Soil_Dirt"
  },
  {
   "x": -11,
   "y": 15,
   "z": 7,
   "name": "Soil_Dirt"
  },
  {
   "x": -11,
   "y": 16,
   "z": 7,
   "name": "Soil_Grass"
  },
  {
   "x": -11,
   "y": 11,
   "z": 8,
   "name": "Rock_Basalt"
  },
  {
   "x": -11,
   "y": 12,
   "z": 8,
   "name": "Rock_Basalt"
  },
  {
   "x": -11,
   "y": 13,
   "z": 8,
   "name": "Rock_Basalt"
  },
  {
   "x": -11,
   "y": 14,
   "z": 8,
   "name": "Rock_Basalt"
  },
  {
   "x": -11,
   "y": 15,
   "z": 8,
   "name": "Soil_Dirt"
  },
  {
   "x": -11,
   "y": 16,
   "z": 8,
   "name": "Soil_Grass"
  },
  {
   "x": -11,
   "y": 29,
   "z": 8,
   "name": "Plant_Leaves_Cedar"
  },
  {
   "x": -11,
   "y": 15,
   "z": 9,
   "name": "Rock_Basalt"
  },
  {
   "x": -11,
   "y": 16,
   "z": 9,
   "name": "Soil_Grass"
  },
  {
   "x": -11,
   "y": 16,
   "z": 10,
   "name": "Soil_Grass"
  },
  {
   "x": -10,
   "y": 12,
   "z": -7,
   "name": "Soil_Dirt"
  },
  {
   "x": -10,
   "y": 13,
   "z": -7,
   "name": "Soil_Grass"
  },
  {
   "x": -10,
   "y": 11,
   "z": -6,
   "name": "Soil_Dirt"
  },
  {
   "x": -10,
   "y": 12,
   "z": -6,
   "name": "Soil_Dirt"
  },
  {
   "x": -10,
   "y": 13,
   "z": -6,
   "name": "Soil_Grass"
  },
  {
   "x": -10,
   "y": 14,
   "z": -6,
   "name": "Plant_Flower_Flax_Blue"
  },
  {
   "x": -10,
   "y": 10,
   "z": -5,
   "name": "Rock_Basalt"
  },
  {
   "x": -10,
   "y": 11,
   "z": -5,
   "name": "Rock_Basalt"
  },
  {
   "x": -10,
   "y": 12,
   "z": -5,
   "name": "Soil_Dirt"
  },
  {
   "x": -10,
   "y": 13,
   "z": -5,
   "name": "Soil_Grass"
  },
  {
   "x": -10,
   "y": 11,
   "z": -4,
   "name": "Rock_Basalt"
  },
  {
   "x": -10,
   "y": 12,
   "z": -4,
   "name": "Soil_Dirt"
  },
  {
   "x": -10,
   "y": 13,
   "z": -4,
   "name": "Soil_Grass"
  },
  {
   "x": -10,
   "y": 12,
   "z": -3,
   "name": "Soil_Grass"
  },
  {
   "x": -10,
   "y": 12,
   "z": 0,
   "name": "Rock_Basalt"
  },
  {
   "x": -10,
   "y": 13,
   "z": 0,
   "name": "Soil_Dirt"
  },
  {
   "x": -10,
   "y": 14,
   "z": 0,
   "name": "Soil_Grass"
  },
  {
   "x": -10,
   "y": 9,
   "z": 1,
   "name": "Rock_Basalt"
  },
  {
   "x": -10,
   "y": 10,
   "z": 1,
   "name": "Rock_Basalt"
  },
  {
   "x": -10,
   "y": 11,
   "z": 1,
   "name": "Rock_Basalt"
  },
  {
   "x": -10,
   "y": 12,
   "z": 1,
   "name": "Rock_Basalt"
  },
  {
   "x": -10,
   "y": 13,
   "z": 1,
   "name": "Rock_Basalt"
  },
  {
   "x": -10,
   "y": 14,
   "z": 1,
   "name": "Soil_Dirt"
  },
  {
   "x": -10,
   "y": 15,
   "z": 1,
   "name": "Soil_Grass"
  },
  {
   "x": -10,
   "y": 7,
   "z": 2,
   "name": "Rock_Basalt"
  },
  {
   "x": -10,
   "y": 8,
   "z": 2,
   "name": "Rock_Basalt"
  },
  {
   "x": -10,
   "y": 9,
   "z": 2,
   "name": "Rock_Basalt"
  },
  {
   "x": -10,
   "y": 10,
   "z": 2,
   "name": "Rock_Basalt"
  },
  {
   "x": -10,
   "y": 11,
   "z": 2,
   "name": "Rock_Basalt"
  },
  {
   "x": -10,
   "y": 12,
   "z": 2,
   "name": "Rock_Basalt"
  },
  {
   "x": -10,
   "y": 13,
   "z": 2,
   "name": "Soil_Dirt"
  },
  {
   "x": -10,
   "y": 14,
   "z": 2,
   "name": "Soil_Dirt"
  },
  {
   "x": -10,
   "y": 15,
   "z": 2,
   "name": "Rock_Basalt"
  },
  {
   "x": -10,
   "y": 16,
   "z": 2,
   "name": "Rock_Basalt"
  },
  {
   "x": -10,
   "y": 5,
   "z": 3,
   "name": "Rock_Basalt"
  },
  {
   "x": -10,
   "y": 6,
   "z": 3,
   "name": "Rock_Basalt"
  },
  {
   "x": -10,
   "y": 7,
   "z": 3,
   "name": "Rock_Basalt"
  },
  {
   "x": -10,
   "y": 8,
   "z": 3,
   "name": "Rock_Basalt"
  },
  {
   "x": -10,
   "y": 9,
   "z": 3,
   "name": "Rock_Basalt"
  },
  {
   "x": -10,
   "y": 10,
   "z": 3,
   "name": "Rock_Basalt"
  },
  {
   "x": -10,
   "y": 11,
   "z": 3,
   "name": "Rock_Basalt"
  },
  {
   "x": -10,
   "y": 12,
   "z": 3,
   "name": "Rock_Basalt"
  },
  {
   "x": -10,
   "y": 13,
   "z": 3,
   "name": "Rock_Basalt"
  },
  {
   "x": -10,
   "y": 14,
   "z": 3,
   "name": "Soil_Dirt"
  },
  {
   "x": -10,
   "y": 15,
   "z": 3,
   "name": "Soil_Dirt"
  },
  {
   "x": -10,
   "y": 16,
   "z": 3,
   "name": "Rock_Basalt"
  },
  {
   "x": -10,
   "y": 17,
   "z": 3,
   "name": "Rock_Basalt"
  },
  {
   "x": -10,
   "y": 5,
   "z": 4,
   "name": "Rock_Basalt"
  },
  {
   "x": -10,
   "y": 6,
   "z": 4,
   "name": "Rock_Basalt"
  },
  {
   "x": -10,
   "y": 7,
   "z": 4,
   "name": "Rock_Basalt"
  },
  {
   "x": -10,
   "y": 8,
   "z": 4,
   "name": "Rock_Basalt"
  },
  {
   "x": -10,
   "y": 9,
   "z": 4,
   "name": "Rock_Basalt"
  },
  {
   "x": -10,
   "y": 10,
   "z": 4,
   "name": "Rock_Basalt"
  },
  {
   "x": -10,
   "y": 11,
   "z": 4,
   "name": "Rock_Basalt"
  },
  {
   "x": -10,
   "y": 12,
   "z": 4,
   "name": "Rock_Basalt"
  },
  {
   "x": -10,
   "y": 13,
   "z": 4,
   "name": "Rock_Basalt"
  },
  {
   "x": -10,
   "y": 14,
   "z": 4,
   "name": "Soil_Dirt"
  },
  {
   "x": -10,
   "y": 15,
   "z": 4,
   "name": "Soil_Dirt"
  },
  {
   "x": -10,
   "y": 16,
   "z": 4,
   "name": "Soil_Grass"
  },
  {
   "x": -10,
   "y": 5,
   "z": 5,
   "name": "Rock_Basalt"
  },
  {
   "x": -10,
   "y": 6,
   "z": 5,
   "name": "Rock_Basalt"
  },
  {
   "x": -10,
   "y": 7,
   "z": 5,
   "name": "Rock_Basalt"
  },
  {
   "x": -10,
   "y": 8,
   "z": 5,
   "name": "Rock_Basalt"
  },
  {
   "x": -10,
   "y": 9,
   "z": 5,
   "name": "Rock_Basalt"
  },
  {
   "x": -10,
   "y": 10,
   "z": 5,
   "name": "Rock_Basalt"
  },
  {
   "x": -10,
   "y": 11,
   "z": 5,
   "name": "Rock_Basalt"
  },
  {
   "x": -10,
   "y": 12,
   "z": 5,
   "name": "Rock_Basalt"
  },
  {
   "x": -10,
   "y": 13,
   "z": 5,
   "name": "Rock_Basalt"
  },
  {
   "x": -10,
   "y": 14,
   "z": 5,
   "name": "Rock_Basalt"
  },
  {
   "x": -10,
   "y": 15,
   "z": 5,
   "name": "Soil_Dirt"
  },
  {
   "x": -10,
   "y": 16,
   "z": 5,
   "name": "Soil_Grass"
  },
  {
   "x": -10,
   "y": 5,
   "z": 6,
   "name": "Rock_Basalt"
  },
  {
   "x": -10,
   "y": 6,
   "z": 6,
   "name": "Rock_Basalt"
  },
  {
   "x": -10,
   "y": 7,
   "z": 6,
   "name": "Rock_Basalt"
  },
  {
   "x": -10,
   "y": 8,
   "z": 6,
   "name": "Rock_Basalt"
  },
  {
   "x": -10,
   "y": 9,
   "z": 6,
   "name": "Rock_Basalt"
  },
  {
   "x": -10,
   "y": 10,
   "z": 6,
   "name": "Rock_Basalt"
  },
  {
   "x": -10,
   "y": 11,
   "z": 6,
   "name": "Rock_Basalt"
  },
  {
   "x": -10,
   "y": 12,
   "z": 6,
   "name": "Rock_Basalt"
  },
  {
   "x": -10,
   "y": 13,
   "z": 6,
   "name": "Rock_Basalt"
  },
  {
   "x": -10,
   "y": 14,
   "z": 6,
   "name": "Soil_Dirt"
  },
  {
   "x": -10,
   "y": 15,
   "z": 6,
   "name": "Soil_Dirt"
  },
  {
   "x": -10,
   "y": 16,
   "z": 6,
   "name": "Soil_Grass"
  },
  {
   "x": -10,
   "y": 17,
   "z": 6,
   "name": "Plant_Flower_Flax_Blue"
  },
  {
   "x": -10,
   "y": 5,
   "z": 7,
   "name": "Rock_Basalt"
  },
  {
   "x": -10,
   "y": 6,
   "z": 7,
   "name": "Rock_Basalt"
  },
  {
   "x": -10,
   "y": 7,
   "z": 7,
   "name": "Rock_Basalt"
  },
  {
   "x": -10,
   "y": 8,
   "z": 7,
   "name": "Rock_Basalt"
  },
  {
   "x": -10,
   "y": 9,
   "z": 7,
   "name": "Rock_Basalt"
  },
  {
   "x": -10,
   "y": 10,
   "z": 7,
   "name": "Rock_Basalt"
  },
  {
   "x": -10,
   "y": 11,
   "z": 7,
   "name": "Rock_Basalt"
  },
  {
   "x": -10,
   "y": 12,
   "z": 7,
   "name": "Rock_Basalt"
  },
  {
   "x": -10,
   "y": 13,
   "z": 7,
   "name": "Rock_Basalt"
  },
  {
   "x": -10,
   "y": 14,
   "z": 7,
   "name": "Rock_Basalt"
  },
  {
   "x": -10,
   "y": 15,
   "z": 7,
   "name": "Soil_Dirt"
  },
  {
   "x": -10,
   "y": 16,
   "z": 7,
   "name": "Soil_Grass"
  },
  {
   "x": -10,
   "y": 30,
   "z": 7,
   "name": "Plant_Leaves_Cedar"
  },
  {
   "x": -10,
   "y": 6,
   "z": 8,
   "name": "Rock_Basalt"
  },
  {
   "x": -10,
   "y": 7,
   "z": 8,
   "name": "Rock_Basalt"
  },
  {
   "x": -10,
   "y": 8,
   "z": 8,
   "name": "Rock_Basalt"
  },
  {
   "x": -10,
   "y": 9,
   "z": 8,
   "name": "Rock_Basalt"
  },
  {
   "x": -10,
   "y": 10,
   "z": 8,
   "name": "Rock_Basalt"
  },
  {
   "x": -10,
   "y": 11,
   "z": 8,
   "name": "Rock_Basalt"
  },
  {
   "x": -10,
   "y": 12,
   "z": 8,
   "name": "Rock_Basalt"
  },
  {
   "x": -10,
   "y": 13,
   "z": 8,
   "name": "Rock_Basalt"
  },
  {
   "x": -10,
   "y": 14,
   "z": 8,
   "name": "Rock_Basalt"
  },
  {
   "x": -10,
   "y": 15,
   "z": 8,
   "name": "Rock_Basalt"
  },
  {
   "x": -10,
   "y": 16,
   "z": 8,
   "name": "Soil_Grass"
  },
  {
   "x": -10,
   "y": 29,
   "z": 8,
   "name": "Plant_Leaves_Cedar"
  },
  {
   "x": -10,
   "y": 30,
   "z": 8,
   "name": "Plant_Leaves_Cedar"
  },
  {
   "x": -10,
   "y": 35,
   "z": 8,
   "name": "Plant_Leaves_Cedar"
  },
  {
   "x": -10,
   "y": 40,
   "z": 8,
   "name": "Plant_Leaves_Cedar"
  },
  {
   "x": -10,
   "y": 8,
   "z": 9,
   "name": "Rock_Basalt"
  },
  {
   "x": -10,
   "y": 9,
   "z": 9,
   "name": "Rock_Basalt"
  },
  {
   "x": -10,
   "y": 10,
   "z": 9,
   "name": "Rock_Basalt"
  },
  {
   "x": -10,
   "y": 11,
   "z": 9,
   "name": "Rock_Basalt"
  },
  {
   "x": -10,
   "y": 12,
   "z": 9,
   "name": "Rock_Basalt"
  },
  {
   "x": -10,
   "y": 13,
   "z": 9,
   "name": "Rock_Basalt"
  },
  {
   "x": -10,
   "y": 14,
   "z": 9,
   "name": "Rock_Basalt"
  },
  {
   "x": -10,
   "y": 15,
   "z": 9,
   "name": "Soil_Dirt"
  },
  {
   "x": -10,
   "y": 16,
   "z": 9,
   "name": "Soil_Grass"
  },
  {
   "x": -10,
   "y": 30,
   "z": 9,
   "name": "Plant_Leaves_Cedar"
  },
  {
   "x": -10,
   "y": 12,
   "z": 10,
   "name": "Rock_Basalt"
  },
  {
   "x": -10,
   "y": 13,
   "z": 10,
   "name": "Rock_Basalt"
  },
  {
   "x": -10,
   "y": 14,
   "z": 10,
   "name": "Soil_Dirt"
  },
  {
   "x": -10,
   "y": 15,
   "z": 10,
   "name": "Soil_Dirt"
  },
  {
   "x": -10,
   "y": 16,
   "z": 10,
   "name": "Soil_Grass"
  },
  {
   "x": -10,
   "y": 14,
   "z": 11,
   "name": "Rock_Basalt"
  },
  {
   "x": -10,
   "y": 15,
   "z": 11,
   "name": "Soil_Dirt"
  },
  {
   "x": -10,
   "y": 16,
   "z": 11,
   "name": "Soil_Grass"
  },
  {
   "x": -9,
   "y": 11,
   "z": -9,
   "name": "Soil_Dirt"
  },
  {
   "x": -9,
   "y": 12,
   "z": -9,
   "name": "Soil_Grass"
  },
  {
   "x": -9,
   "y": 9,
   "z": -8,
   "name": "Rock_Basalt"
  },
  {
   "x": -9,
   "y": 10,
   "z": -8,
   "name": "Rock_Basalt"
  },
  {
   "x": -9,
   "y": 11,
   "z": -8,
   "name": "Soil_Dirt"
  },
  {
   "x": -9,
   "y": 12,
   "z": -8,
   "name": "Soil_Dirt"
  },
  {
   "x": -9,
   "y": 9,
   "z": -7,
   "name": "Rock_Basalt"
  },
  {
   "x": -9,
   "y": 10,
   "z": -7,
   "name": "Rock_Basalt"
  },
  {
   "x": -9,
   "y": 11,
   "z": -7,
   "name": "Soil_Dirt"
  },
  {
   "x": -9,
   "y": 12,
   "z": -7,
   "name": "Soil_Dirt"
  },
  {
   "x": -9,
   "y": 13,
   "z": -7,
   "name": "Soil_Grass"
  },
  {
   "x": -9,
   "y": 8,
   "z": -6,
   "name": "Rock_Basalt"
  },
  {
   "x": -9,
   "y": 9,
   "z": -6,
   "name": "Rock_Basalt"
  },
  {
   "x": -9,
   "y": 10,
   "z": -6,
   "name": "Rock_Basalt"
  },
  {
   "x": -9,
   "y": 11,
   "z": -6,
   "name": "Rock_Basalt"
  },
  {
   "x": -9,
   "y": 12,
   "z": -6,
   "name": "Soil_Dirt"
  },
  {
   "x": -9,
   "y": 13,
   "z": -6,
   "name": "Soil_Grass"
  },
  {
   "x": -9,
   "y": 24,
   "z": -6,
   "name": "Plant_Leaves_Redwood"
  },
  {
   "x": -9,
   "y": 8,
   "z": -5,
   "name": "Rock_Basalt"
  },
  {
   "x": -9,
   "y": 9,
   "z": -5,
   "name": "Rock_Basalt"
  },
  {
   "x": -9,
   "y": 10,
   "z": -5,
   "name": "Rock_Basalt"
  },
  {
   "x": -9,
   "y": 11,
   "z": -5,
   "name": "Soil_Dirt"
  },
  {
   "x": -9,
   "y": 12,
   "z": -5,
   "name": "Soil_Dirt"
  },
  {
   "x": -9,
   "y": 13,
   "z": -5,
   "name": "Soil_Grass"
  },
  {
   "x": -9,
   "y": 8,
   "z": -4,
   "name": "Rock_Basalt"
  },
  {
   "x": -9,
   "y": 9,
   "z": -4,
   "name": "Rock_Basalt"
  },
  {
   "x": -9,
   "y": 10,
   "z": -4,
   "name": "Rock_Basalt"
  },
  {
   "x": -9,
   "y": 11,
   "z": -4,
   "name": "Soil_Dirt"
  },
  {
   "x": -9,
   "y": 12,
   "z": -4,
   "name": "Soil_Dirt"
  },
  {
   "x": -9,
   "y": 13,
   "z": -4,
   "name": "Soil_Grass"
  },
  {
   "x": -9,
   "y": 14,
   "z": -4,
   "name": "Plant_Flower_Flax_Blue"
  },
  {
   "x": -9,
   "y": 9,
   "z": -3,
   "name": "Rock_Basalt"
  },
  {
   "x": -9,
   "y": 10,
   "z": -3,
   "name": "Rock_Basalt"
  },
  {
   "x": -9,
   "y": 11,
   "z": -3,
   "name": "Soil_Dirt"
  },
  {
   "x": -9,
   "y": 12,
   "z": -3,
   "name": "Soil_Dirt"
  },
  {
   "x": -9,
   "y": 13,
   "z": -3,
   "name": "Soil_Grass"
  },
  {
   "x": -9,
   "y": 11,
   "z": -2,
   "name": "Soil_Dirt"
  },
  {
   "x": -9,
   "y": 12,
   "z": -2,
   "name": "Soil_Dirt"
  },
  {
   "x": -9,
   "y": 13,
   "z": -2,
   "name": "Soil_Dirt"
  },
  {
   "x": -9,
   "y": 14,
   "z": -2,
   "name": "Soil_Grass"
  },
  {
   "x": -9,
   "y": 11,
   "z": -1,
   "name": "Rock_Basalt"
  },
  {
   "x": -9,
   "y": 12,
   "z": -1,
   "name": "Soil_Dirt"
  },
  {
   "x": -9,
   "y": 13,
   "z": -1,
   "name": "Soil_Dirt"
  },
  {
   "x": -9,
   "y": 14,
   "z": -1,
   "name": "Soil_Dirt"
  },
  {
   "x": -9,
   "y": 15,
   "z": -1,
   "name": "Soil_Grass"
  },
  {
   "x": -9,
   "y": 11,
   "z": 0,
   "name": "Rock_Basalt"
  },
  {
   "x": -9,
   "y": 12,
   "z": 0,
   "name": "Rock_Basalt"
  },
  {
   "x": -9,
   "y": 13,
   "z": 0,
   "name": "Soil_Dirt"
  },
  {
   "x": -9,
   "y": 14,
   "z": 0,
   "name": "Soil_Dirt"
  },
  {
   "x": -9,
   "y": 15,
   "z": 0,
   "name": "Soil_Grass"
  },
  {
   "x": -9,
   "y": 7,
   "z": 1,
   "name": "Rock_Basalt"
  },
  {
   "x": -9,
   "y": 8,
   "z": 1,
   "name": "Rock_Basalt"
  },
  {
   "x": -9,
   "y": 9,
   "z": 1,
   "name": "Rock_Basalt"
  },
  {
   "x": -9,
   "y": 10,
   "z": 1,
   "name": "Rock_Basalt"
  },
  {
   "x": -9,
   "y": 11,
   "z": 1,
   "name": "Rock_Basalt"
  },
  {
   "x": -9,
   "y": 12,
   "z": 1,
   "name": "Rock_Basalt"
  },
  {
   "x": -9,
   "y": 13,
   "z": 1,
   "name": "Soil_Dirt"
  },
  {
   "x": -9,
   "y": 14,
   "z": 1,
   "name": "Soil_Dirt"
  },
  {
   "x": -9,
   "y": 15,
   "z": 1,
   "name": "Rock_Basalt"
  },
  {
   "x": -9,
   "y": 5,
   "z": 2,
   "name": "Rock_Basalt"
  },
  {
   "x": -9,
   "y": 6,
   "z": 2,
   "name": "Rock_Basalt"
  },
  {
   "x": -9,
   "y": 7,
   "z": 2,
   "name": "Rock_Basalt"
  },
  {
   "x": -9,
   "y": 8,
   "z": 2,
   "name": "Rock_Basalt"
  },
  {
   "x": -9,
   "y": 9,
   "z": 2,
   "name": "Rock_Basalt"
  },
  {
   "x": -9,
   "y": 10,
   "z": 2,
   "name": "Rock_Basalt"
  },
  {
   "x": -9,
   "y": 11,
   "z": 2,
   "name": "Rock_Basalt"
  },
  {
   "x": -9,
   "y": 12,
   "z": 2,
   "name": "Rock_Basalt"
  },
  {
   "x": -9,
   "y": 13,
   "z": 2,
   "name": "Soil_Dirt"
  },
  {
   "x": -9,
   "y": 14,
   "z": 2,
   "name": "Soil_Dirt"
  },
  {
   "x": -9,
   "y": 15,
   "z": 2,
   "name": "Rock_Basalt"
  },
  {
   "x": -9,
   "y": 16,
   "z": 2,
   "name": "Rock_Basalt"
  },
  {
   "x": -9,
   "y": 17,
   "z": 2,
   "name": "Rock_Basalt"
  },
  {
   "x": -9,
   "y": 18,
   "z": 2,
   "name": "Rock_Basalt"
  },
  {
   "x": -9,
   "y": 4,
   "z": 3,
   "name": "Rock_Basalt"
  },
  {
   "x": -9,
   "y": 5,
   "z": 3,
   "name": "Rock_Basalt"
  },
  {
   "x": -9,
   "y": 6,
   "z": 3,
   "name": "Rock_Basalt"
  },
  {
   "x": -9,
   "y": 7,
   "z": 3,
   "name": "Rock_Basalt"
  },
  {
   "x": -9,
   "y": 8,
   "z": 3,
   "name": "Rock_Basalt"
  },
  {
   "x": -9,
   "y": 9,
   "z": 3,
   "name": "Rock_Basalt"
  },
  {
   "x": -9,
   "y": 10,
   "z": 3,
   "name": "Rock_Basalt"
  },
  {
   "x": -9,
   "y": 11,
   "z": 3,
   "name": "Rock_Basalt"
  },
  {
   "x": -9,
   "y": 12,
   "z": 3,
   "name": "Rock_Basalt"
  },
  {
   "x": -9,
   "y": 13,
   "z": 3,
   "name": "Soil_Dirt"
  },
  {
   "x": -9,
   "y": 14,
   "z": 3,
   "name": "Soil_Dirt"
  },
  {
   "x": -9,
   "y": 15,
   "z": 3,
   "name": "Soil_Dirt"
  },
  {
   "x": -9,
   "y": 16,
   "z": 3,
   "name": "Rock_Basalt"
  },
  {
   "x": -9,
   "y": 17,
   "z": 3,
   "name": "Rock_Basalt"
  },
  {
   "x": -9,
   "y": 18,
   "z": 3,
   "name": "Rock_Basalt"
  },
  {
   "x": -9,
   "y": 4,
   "z": 4,
   "name": "Rock_Basalt"
  },
  {
   "x": -9,
   "y": 5,
   "z": 4,
   "name": "Rock_Basalt"
  },
  {
   "x": -9,
   "y": 6,
   "z": 4,
   "name": "Rock_Basalt"
  },
  {
   "x": -9,
   "y": 7,
   "z": 4,
   "name": "Rock_Basalt"
  },
  {
   "x": -9,
   "y": 8,
   "z": 4,
   "name": "Rock_Basalt"
  },
  {
   "x": -9,
   "y": 9,
   "z": 4,
   "name": "Rock_Basalt"
  },
  {
   "x": -9,
   "y": 10,
   "z": 4,
   "name": "Rock_Basalt"
  },
  {
   "x": -9,
   "y": 11,
   "z": 4,
   "name": "Rock_Basalt"
  },
  {
   "x": -9,
   "y": 12,
   "z": 4,
   "name": "Rock_Basalt"
  },
  {
   "x": -9,
   "y": 13,
   "z": 4,
   "name": "Rock_Basalt"
  },
  {
   "x": -9,
   "y": 14,
   "z": 4,
   "name": "Soil_Dirt"
  },
  {
   "x": -9,
   "y": 15,
   "z": 4,
   "name": "Soil_Dirt"
  },
  {
   "x": -9,
   "y": 16,
   "z": 4,
   "name": "Rock_Basalt"
  },
  {
   "x": -9,
   "y": 17,
   "z": 4,
   "name": "Rock_Basalt"
  },
  {
   "x": -9,
   "y": 3,
   "z": 5,
   "name": "Rock_Basalt"
  },
  {
   "x": -9,
   "y": 4,
   "z": 5,
   "name": "Rock_Basalt"
  },
  {
   "x": -9,
   "y": 5,
   "z": 5,
   "name": "Rock_Basalt"
  },
  {
   "x": -9,
   "y": 6,
   "z": 5,
   "name": "Rock_Basalt"
  },
  {
   "x": -9,
   "y": 7,
   "z": 5,
   "name": "Rock_Basalt"
  },
  {
   "x": -9,
   "y": 8,
   "z": 5,
   "name": "Rock_Basalt"
  },
  {
   "x": -9,
   "y": 9,
   "z": 5,
   "name": "Rock_Basalt"
  },
  {
   "x": -9,
   "y": 10,
   "z": 5,
   "name": "Rock_Basalt"
  },
  {
   "x": -9,
   "y": 11,
   "z": 5,
   "name": "Rock_Basalt"
  },
  {
   "x": -9,
   "y": 12,
   "z": 5,
   "name": "Rock_Basalt"
  },
  {
   "x": -9,
   "y": 13,
   "z": 5,
   "name": "Rock_Basalt"
  },
  {
   "x": -9,
   "y": 14,
   "z": 5,
   "name": "Rock_Basalt"
  },
  {
   "x": -9,
   "y": 15,
   "z": 5,
   "name": "Soil_Dirt"
  },
  {
   "x": -9,
   "y": 16,
   "z": 5,
   "name": "Soil_Grass"
  },
  {
   "x": -9,
   "y": 3,
   "z": 6,
   "name": "Rock_Basalt"
  },
  {
   "x": -9,
   "y": 4,
   "z": 6,
   "name": "Rock_Basalt"
  },
  {
   "x": -9,
   "y": 5,
   "z": 6,
   "name": "Rock_Basalt"
  },
  {
   "x": -9,
   "y": 6,
   "z": 6,
   "name": "Rock_Basalt"
  },
  {
   "x": -9,
   "y": 7,
   "z": 6,
   "name": "Rock_Basalt"
  },
  {
   "x": -9,
   "y": 8,
   "z": 6,
   "name": "Rock_Basalt"
  },
  {
   "x": -9,
   "y": 9,
   "z": 6,
   "name": "Rock_Basalt"
  },
  {
   "x": -9,
   "y": 10,
   "z": 6,
   "name": "Rock_Basalt"
  },
  {
   "x": -9,
   "y": 11,
   "z": 6,
   "name": "Rock_Basalt"
  },
  {
   "x": -9,
   "y": 12,
   "z": 6,
   "name": "Rock_Basalt"
  },
  {
   "x": -9,
   "y": 13,
   "z": 6,
   "name": "Rock_Basalt"
  },
  {
   "x": -9,
   "y": 14,
   "z": 6,
   "name": "Rock_Basalt"
  },
  {
   "x": -9,
   "y": 15,
   "z": 6,
   "name": "Soil_Dirt"
  },
  {
   "x": -9,
   "y": 16,
   "z": 6,
   "name": "Soil_Grass"
  },
  {
   "x": -9,
   "y": 31,
   "z": 6,
   "name": "Plant_Leaves_Cedar"
  },
  {
   "x": -9,
   "y": 3,
   "z": 7,
   "name": "Rock_Basalt"
  },
  {
   "x": -9,
   "y": 4,
   "z": 7,
   "name": "Rock_Basalt"
  },
  {
   "x": -9,
   "y": 5,
   "z": 7,
   "name": "Rock_Basalt"
  },
  {
   "x": -9,
   "y": 6,
   "z": 7,
   "name": "Rock_Basalt"
  },
  {
   "x": -9,
   "y": 7,
   "z": 7,
   "name": "Rock_Basalt"
  },
  {
   "x": -9,
   "y": 8,
   "z": 7,
   "name": "Rock_Basalt"
  },
  {
   "x": -9,
   "y": 9,
   "z": 7,
   "name": "Rock_Basalt"
  },
  {
   "x": -9,
   "y": 10,
   "z": 7,
   "name": "Rock_Basalt"
  },
  {
   "x": -9,
   "y": 11,
   "z": 7,
   "name": "Rock_Basalt"
  },
  {
   "x": -9,
   "y": 12,
   "z": 7,
   "name": "Rock_Basalt"
  },
  {
   "x": -9,
   "y": 13,
   "z": 7,
   "name": "Rock_Basalt"
  },
  {
   "x": -9,
   "y": 14,
   "z": 7,
   "name": "Rock_Basalt"
  },
  {
   "x": -9,
   "y": 15,
   "z": 7,
   "name": "Rock_Basalt"
  },
  {
   "x": -9,
   "y": 16,
   "z": 7,
   "name": "Soil_Grass"
  },
  {
   "x": -9,
   "y": 31,
   "z": 7,
   "name": "Plant_Leaves_Cedar"
  },
  {
   "x": -9,
   "y": 36,
   "z": 7,
   "name": "Plant_Leaves_Cedar"
  },
  {
   "x": -9,
   "y": 41,
   "z": 7,
   "name": "Plant_Leaves_Cedar"
  },
  {
   "x": -9,
   "y": 4,
   "z": 8,
   "name": "Rock_Basalt"
  },
  {
   "x": -9,
   "y": 5,
   "z": 8,
   "name": "Rock_Basalt"
  },
  {
   "x": -9,
   "y": 6,
   "z": 8,
   "name": "Rock_Basalt"
  },
  {
   "x": -9,
   "y": 7,
   "z": 8,
   "name": "Rock_Basalt"
  },
  {
   "x": -9,
   "y": 8,
   "z": 8,
   "name": "Rock_Basalt"
  },
  {
   "x": -9,
   "y": 9,
   "z": 8,
   "name": "Rock_Basalt"
  },
  {
   "x": -9,
   "y": 10,
   "z": 8,
   "name": "Rock_Basalt"
  },
  {
   "x": -9,
   "y": 11,
   "z": 8,
   "name": "Rock_Basalt"
  },
  {
   "x": -9,
   "y": 12,
   "z": 8,
   "name": "Rock_Basalt"
  },
  {
   "x": -9,
   "y": 13,
   "z": 8,
   "name": "Rock_Basalt"
  },
  {
   "x": -9,
   "y": 14,
   "z": 8,
   "name": "Rock_Basalt"
  },
  {
   "x": -9,
   "y": 15,
   "z": 8,
   "name": "Soil_Dirt"
  },
  {
   "x": -9,
   "y": 16,
   "z": 8,
   "name": "Soil_Grass"
  },
  {
   "x": -9,
   "y": 30,
   "z": 8,
   "name": "Plant_Leaves_Cedar"
  },
  {
   "x": -9,
   "y": 31,
   "z": 8,
   "name": "Plant_Leaves_Cedar"
  },
  {
   "x": -9,
   "y": 33,
   "z": 8,
   "name": "Plant_Leaves_Cedar"
  },
  {
   "x": -9,
   "y": 35,
   "z": 8,
   "name": "Plant_Leaves_Cedar"
  },
  {
   "x": -9,
   "y": 36,
   "z": 8,
   "name": "Plant_Leaves_Cedar"
  },
  {
   "x": -9,
   "y": 40,
   "z": 8,
   "name": "Plant_Leaves_Cedar"
  },
  {
   "x": -9,
   "y": 41,
   "z": 8,
   "name": "Plant_Leaves_Cedar"
  },
  {
   "x": -9,
   "y": 5,
   "z": 9,
   "name": "Rock_Basalt"
  },
  {
   "x": -9,
   "y": 6,
   "z": 9,
   "name": "Rock_Basalt"
  },
  {
   "x": -9,
   "y": 7,
   "z": 9,
   "name": "Rock_Basalt"
  },
  {
   "x": -9,
   "y": 8,
   "z": 9,
   "name": "Rock_Basalt"
  },
  {
   "x": -9,
   "y": 9,
   "z": 9,
   "name": "Rock_Basalt"
  },
  {
   "x": -9,
   "y": 10,
   "z": 9,
   "name": "Rock_Basalt"
  },
  {
   "x": -9,
   "y": 11,
   "z": 9,
   "name": "Rock_Basalt"
  },
  {
   "x": -9,
   "y": 12,
   "z": 9,
   "name": "Rock_Basalt"
  },
  {
   "x": -9,
   "y": 13,
   "z": 9,
   "name": "Rock_Basalt"
  },
  {
   "x": -9,
   "y": 14,
   "z": 9,
   "name": "Soil_Dirt"
  },
  {
   "x": -9,
   "y": 15,
   "z": 9,
   "name": "Soil_Dirt"
  },
  {
   "x": -9,
   "y": 16,
   "z": 9,
   "name": "Soil_Grass"
  },
  {
   "x": -9,
   "y": 30,
   "z": 9,
   "name": "Plant_Leaves_Cedar"
  },
  {
   "x": -9,
   "y": 31,
   "z": 9,
   "name": "Plant_Leaves_Cedar"
  },
  {
   "x": -9,
   "y": 33,
   "z": 9,
   "name": "Plant_Leaves_Cedar"
  },
  {
   "x": -9,
   "y": 41,
   "z": 9,
   "name": "Plant_Leaves_Cedar"
  },
  {
   "x": -9,
   "y": 6,
   "z": 10,
   "name": "Rock_Basalt"
  },
  {
   "x": -9,
   "y": 7,
   "z": 10,
   "name": "Rock_Basalt"
  },
  {
   "x": -9,
   "y": 8,
   "z": 10,
   "name": "Rock_Basalt"
  },
  {
   "x": -9,
   "y": 9,
   "z": 10,
   "name": "Rock_Basalt"
  },
  {
   "x": -9,
   "y": 10,
   "z": 10,
   "name": "Rock_Basalt"
  },
  {
   "x": -9,
   "y": 11,
   "z": 10,
   "name": "Rock_Basalt"
  },
  {
   "x": -9,
   "y": 12,
   "z": 10,
   "name": "Rock_Basalt"
  },
  {
   "x": -9,
   "y": 13,
   "z": 10,
   "name": "Rock_Basalt"
  },
  {
   "x": -9,
   "y": 14,
   "z": 10,
   "name": "Soil_Dirt"
  },
  {
   "x": -9,
   "y": 15,
   "z": 10,
   "name": "Soil_Dirt"
  },
  {
   "x": -9,
   "y": 16,
   "z": 10,
   "name": "Soil_Grass"
  },
  {
   "x": -9,
   "y": 30,
   "z": 10,
   "name": "Plant_Leaves_Cedar"
  },
  {
   "x": -9,
   "y": 11,
   "z": 11,
   "name": "Rock_Basalt"
  },
  {
   "x": -9,
   "y": 12,
   "z": 11,
   "name": "Rock_Basalt"
  },
  {
   "x": -9,
   "y": 13,
   "z": 11,
   "name": "Rock_Basalt"
  },
  {
   "x": -9,
   "y": 14,
   "z": 11,
   "name": "Soil_Dirt"
  },
  {
   "x": -9,
   "y": 15,
   "z": 11,
   "name": "Soil_Dirt"
  },
  {
   "x": -9,
   "y": 16,
   "z": 11,
   "name": "Soil_Grass"
  },
  {
   "x": -9,
   "y": 15,
   "z": 12,
   "name": "Soil_Dirt"
  },
  {
   "x": -9,
   "y": 16,
   "z": 12,
   "name": "Soil_Grass"
  },
  {
   "x": -8,
   "y": 10,
   "z": -10,
   "name": "Soil_Dirt"
  },
  {
   "x": -8,
   "y": 11,
   "z": -10,
   "name": "Soil_Dirt"
  },
  {
   "x": -8,
   "y": 12,
   "z": -10,
   "name": "Soil_Grass"
  },
  {
   "x": -8,
   "y": 9,
   "z": -9,
   "name": "Rock_Basalt"
  },
  {
   "x": -8,
   "y": 10,
   "z": -9,
   "name": "Soil_Dirt"
  },
  {
   "x": -8,
   "y": 11,
   "z": -9,
   "name": "Soil_Dirt"
  },
  {
   "x": -8,
   "y": 12,
   "z": -9,
   "name": "Soil_Grass"
  },
  {
   "x": -8,
   "y": 6,
   "z": -8,
   "name": "Rock_Basalt"
  },
  {
   "x": -8,
   "y": 7,
   "z": -8,
   "name": "Rock_Basalt"
  },
  {
   "x": -8,
   "y": 8,
   "z": -8,
   "name": "Rock_Basalt"
  },
  {
   "x": -8,
   "y": 9,
   "z": -8,
   "name": "Rock_Basalt"
  },
  {
   "x": -8,
   "y": 10,
   "z": -8,
   "name": "Soil_Dirt"
  },
  {
   "x": -8,
   "y": 11,
   "z": -8,
   "name": "Soil_Dirt"
  },
  {
   "x": -8,
   "y": 12,
   "z": -8,
   "name": "Soil_Dirt"
  },
  {
   "x": -8,
   "y": 13,
   "z": -8,
   "name": "Soil_Grass"
  },
  {
   "x": -8,
   "y": 5,
   "z": -7,
   "name": "Rock_Basalt"
  },
  {
   "x": -8,
   "y": 6,
   "z": -7,
   "name": "Rock_Basalt"
  },
  {
   "x": -8,
   "y": 7,
   "z": -7,
   "name": "Rock_Basalt"
  },
  {
   "x": -8,
   "y": 8,
   "z": -7,
   "name": "Rock_Basalt"
  },
  {
   "x": -8,
   "y": 9,
   "z": -7,
   "name": "Rock_Basalt"
  },
  {
   "x": -8,
   "y": 10,
   "z": -7,
   "name": "Rock_Basalt"
  },
  {
   "x": -8,
   "y": 11,
   "z": -7,
   "name": "Soil_Dirt"
  },
  {
   "x": -8,
   "y": 12,
   "z": -7,
   "name": "Soil_Dirt"
  },
  {
   "x": -8,
   "y": 13,
   "z": -7,
   "name": "Soil_Grass"
  },
  {
   "x": -8,
   "y": 5,
   "z": -6,
   "name": "Rock_Basalt"
  },
  {
   "x": -8,
   "y": 6,
   "z": -6,
   "name": "Rock_Basalt"
  },
  {
   "x": -8,
   "y": 7,
   "z": -6,
   "name": "Rock_Basalt"
  },
  {
   "x": -8,
   "y": 8,
   "z": -6,
   "name": "Rock_Basalt"
  },
  {
   "x": -8,
   "y": 9,
   "z": -6,
   "name": "Rock_Basalt"
  },
  {
   "x": -8,
   "y": 10,
   "z": -6,
   "name": "Rock_Basalt"
  },
  {
   "x": -8,
   "y": 11,
   "z": -6,
   "name": "Soil_Dirt"
  },
  {
   "x": -8,
   "y": 12,
   "z": -6,
   "name": "Soil_Dirt"
  },
  {
   "x": -8,
   "y": 13,
   "z": -6,
   "name": "Soil_Grass"
  },
  {
   "x": -8,
   "y": 14,
   "z": -6,
   "name": "Plant_Flower_Flax_Blue"
  },
  {
   "x": -8,
   "y": 24,
   "z": -6,
   "name": "Plant_Leaves_Redwood"
  },
  {
   "x": -8,
   "y": 25,
   "z": -6,
   "name": "Plant_Leaves_Redwood"
  },
  {
   "x": -8,
   "y": 29,
   "z": -6,
   "name": "Plant_Leaves_Redwood"
  },
  {
   "x": -8,
   "y": 5,
   "z": -5,
   "name": "Rock_Basalt"
  },
  {
   "x": -8,
   "y": 6,
   "z": -5,
   "name": "Rock_Basalt"
  },
  {
   "x": -8,
   "y": 7,
   "z": -5,
   "name": "Rock_Basalt"
  },
  {
   "x": -8,
   "y": 8,
   "z": -5,
   "name": "Rock_Basalt"
  },
  {
   "x": -8,
   "y": 9,
   "z": -5,
   "name": "Rock_Basalt"
  },
  {
   "x": -8,
   "y": 10,
   "z": -5,
   "name": "Rock_Basalt"
  },
  {
   "x": -8,
   "y": 11,
   "z": -5,
   "name": "Soil_Dirt"
  },
  {
   "x": -8,
   "y": 12,
   "z": -5,
   "name": "Soil_Dirt"
  },
  {
   "x": -8,
   "y": 13,
   "z": -5,
   "name": "Soil_Grass"
  },
  {
   "x": -8,
   "y": 6,
   "z": -4,
   "name": "Rock_Basalt"
  },
  {
   "x": -8,
   "y": 7,
   "z": -4,
   "name": "Rock_Basalt"
  },
  {
   "x": -8,
   "y": 8,
   "z": -4,
   "name": "Rock_Basalt"
  },
  {
   "x": -8,
   "y": 9,
   "z": -4,
   "name": "Rock_Basalt"
  },
  {
   "x": -8,
   "y": 10,
   "z": -4,
   "name": "Rock_Basalt"
  },
  {
   "x": -8,
   "y": 11,
   "z": -4,
   "name": "Soil_Dirt"
  },
  {
   "x": -8,
   "y": 12,
   "z": -4,
   "name": "Soil_Dirt"
  },
  {
   "x": -8,
   "y": 13,
   "z": -4,
   "name": "Soil_Grass"
  },
  {
   "x": -8,
   "y": 6,
   "z": -3,
   "name": "Rock_Basalt"
  },
  {
   "x": -8,
   "y": 7,
   "z": -3,
   "name": "Rock_Basalt"
  },
  {
   "x": -8,
   "y": 8,
   "z": -3,
   "name": "Rock_Basalt"
  },
  {
   "x": -8,
   "y": 9,
   "z": -3,
   "name": "Rock_Basalt"
  },
  {
   "x": -8,
   "y": 10,
   "z": -3,
   "name": "Rock_Basalt"
  },
  {
   "x": -8,
   "y": 11,
   "z": -3,
   "name": "Soil_Dirt"
  },
  {
   "x": -8,
   "y": 12,
   "z": -3,
   "name": "Soil_Dirt"
  },
  {
   "x": -8,
   "y": 13,
   "z": -3,
   "name": "Soil_Dirt"
  },
  {
   "x": -8,
   "y": 14,
   "z": -3,
   "name": "Soil_Grass"
  },
  {
   "x": -8,
   "y": 7,
   "z": -2,
   "name": "Rock_Basalt"
  },
  {
   "x": -8,
   "y": 8,
   "z": -2,
   "name": "Rock_Basalt"
  },
  {
   "x": -8,
   "y": 9,
   "z": -2,
   "name": "Rock_Basalt"
  },
  {
   "x": -8,
   "y": 10,
   "z": -2,
   "name": "Rock_Basalt"
  },
  {
   "x": -8,
   "y": 11,
   "z": -2,
   "name": "Rock_Basalt"
  },
  {
   "x": -8,
   "y": 12,
   "z": -2,
   "name": "Soil_Dirt"
  },
  {
   "x": -8,
   "y": 13,
   "z": -2,
   "name": "Soil_Dirt"
  },
  {
   "x": -8,
   "y": 14,
   "z": -2,
   "name": "Soil_Grass"
  },
  {
   "x": -8,
   "y": 9,
   "z": -1,
   "name": "Rock_Basalt"
  },
  {
   "x": -8,
   "y": 10,
   "z": -1,
   "name": "Rock_Basalt"
  },
  {
   "x": -8,
   "y": 11,
   "z": -1,
   "name": "Rock_Basalt"
  },
  {
   "x": -8,
   "y": 12,
   "z": -1,
   "name": "Rock_Basalt"
  },
  {
   "x": -8,
   "y": 13,
   "z": -1,
   "name": "Soil_Dirt"
  },
  {
   "x": -8,
   "y": 14,
   "z": -1,
   "name": "Soil_Dirt"
  },
  {
   "x": -8,
   "y": 15,
   "z": -1,
   "name": "Soil_Grass"
  },
  {
   "x": -8,
   "y": 8,
   "z": 0,
   "name": "Rock_Basalt"
  },
  {
   "x": -8,
   "y": 9,
   "z": 0,
   "name": "Rock_Basalt"
  },
  {
   "x": -8,
   "y": 10,
   "z": 0,
   "name": "Rock_Basalt"
  },
  {
   "x": -8,
   "y": 11,
   "z": 0,
   "name": "Rock_Basalt"
  },
  {
   "x": -8,
   "y": 12,
   "z": 0,
   "name": "Rock_Basalt"
  },
  {
   "x": -8,
   "y": 13,
   "z": 0,
   "name": "Soil_Dirt"
  },
  {
   "x": -8,
   "y": 14,
   "z": 0,
   "name": "Soil_Dirt"
  },
  {
   "x": -8,
   "y": 15,
   "z": 0,
   "name": "Rock_Basalt"
  },
  {
   "x": -8,
   "y": 7,
   "z": 1,
   "name": "Rock_Basalt"
  },
  {
   "x": -8,
   "y": 8,
   "z": 1,
   "name": "Rock_Basalt"
  },
  {
   "x": -8,
   "y": 9,
   "z": 1,
   "name": "Rock_Basalt"
  },
  {
   "x": -8,
   "y": 10,
   "z": 1,
   "name": "Rock_Basalt"
  },
  {
   "x": -8,
   "y": 11,
   "z": 1,
   "name": "Rock_Basalt"
  },
  {
   "x": -8,
   "y": 12,
   "z": 1,
   "name": "Rock_Basalt"
  },
  {
   "x": -8,
   "y": 13,
   "z": 1,
   "name": "Soil_Dirt"
  },
  {
   "x": -8,
   "y": 14,
   "z": 1,
   "name": "Soil_Dirt"
  },
  {
   "x": -8,
   "y": 15,
   "z": 1,
   "name": "Rock_Basalt"
  },
  {
   "x": -8,
   "y": 16,
   "z": 1,
   "name": "Rock_Basalt"
  },
  {
   "x": -8,
   "y": 17,
   "z": 1,
   "name": "Rock_Basalt"
  },
  {
   "x": -8,
   "y": 6,
   "z": 2,
   "name": "Rock_Basalt"
  },
  {
   "x": -8,
   "y": 7,
   "z": 2,
   "name": "Rock_Basalt"
  },
  {
   "x": -8,
   "y": 8,
   "z": 2,
   "name": "Rock_Basalt"
  },
  {
   "x": -8,
   "y": 9,
   "z": 2,
   "name": "Rock_Basalt"
  },
  {
   "x": -8,
   "y": 10,
   "z": 2,
   "name": "Rock_Basalt"
  },
  {
   "x": -8,
   "y": 11,
   "z": 2,
   "name": "Rock_Basalt"
  },
  {
   "x": -8,
   "y": 12,
   "z": 2,
   "name": "Rock_Basalt"
  },
  {
   "x": -8,
   "y": 13,
   "z": 2,
   "name": "Soil_Dirt"
  },
  {
   "x": -8,
   "y": 14,
   "z": 2,
   "name": "Soil_Dirt"
  },
  {
   "x": -8,
   "y": 15,
   "z": 2,
   "name": "Rock_Basalt"
  },
  {
   "x": -8,
   "y": 16,
   "z": 2,
   "name": "Rock_Basalt"
  },
  {
   "x": -8,
   "y": 17,
   "z": 2,
   "name": "Rock_Basalt"
  },
  {
   "x": -8,
   "y": 18,
   "z": 2,
   "name": "Rock_Basalt"
  },
  {
   "x": -8,
   "y": 4,
   "z": 3,
   "name": "Rock_Basalt"
  },
  {
   "x": -8,
   "y": 5,
   "z": 3,
   "name": "Rock_Basalt"
  },
  {
   "x": -8,
   "y": 6,
   "z": 3,
   "name": "Rock_Basalt"
  },
  {
   "x": -8,
   "y": 7,
   "z": 3,
   "name": "Rock_Basalt"
  },
  {
   "x": -8,
   "y": 8,
   "z": 3,
   "name": "Rock_Basalt"
  },
  {
   "x": -8,
   "y": 9,
   "z": 3,
   "name": "Rock_Basalt"
  },
  {
   "x": -8,
   "y": 10,
   "z": 3,
   "name": "Rock_Basalt"
  },
  {
   "x": -8,
   "y": 11,
   "z": 3,
   "name": "Rock_Basalt"
  },
  {
   "x": -8,
   "y": 12,
   "z": 3,
   "name": "Rock_Basalt"
  },
  {
   "x": -8,
   "y": 13,
   "z": 3,
   "name": "Rock_Basalt"
  },
  {
   "x": -8,
   "y": 14,
   "z": 3,
   "name": "Soil_Dirt"
  },
  {
   "x": -8,
   "y": 15,
   "z": 3,
   "name": "Rock_Basalt"
  },
  {
   "x": -8,
   "y": 16,
   "z": 3,
   "name": "Rock_Basalt"
  },
  {
   "x": -8,
   "y": 17,
   "z": 3,
   "name": "Rock_Basalt"
  },
  {
   "x": -8,
   "y": 18,
   "z": 3,
   "name": "Rock_Basalt"
  },
  {
   "x": -8,
   "y": 3,
   "z": 4,
   "name": "Rock_Basalt"
  },
  {
   "x": -8,
   "y": 4,
   "z": 4,
   "name": "Rock_Basalt"
  },
  {
   "x": -8,
   "y": 5,
   "z": 4,
   "name": "Rock_Basalt"
  },
  {
   "x": -8,
   "y": 6,
   "z": 4,
   "name": "Rock_Basalt"
  },
  {
   "x": -8,
   "y": 7,
   "z": 4,
   "name": "Rock_Basalt"
  },
  {
   "x": -8,
   "y": 8,
   "z": 4,
   "name": "Rock_Basalt"
  },
  {
   "x": -8,
   "y": 9,
   "z": 4,
   "name": "Rock_Basalt"
  },
  {
   "x": -8,
   "y": 10,
   "z": 4,
   "name": "Rock_Basalt"
  },
  {
   "x": -8,
   "y": 11,
   "z": 4,
   "name": "Rock_Basalt"
  },
  {
   "x": -8,
   "y": 12,
   "z": 4,
   "name": "Rock_Basalt"
  },
  {
   "x": -8,
   "y": 13,
   "z": 4,
   "name": "Rock_Basalt"
  },
  {
   "x": -8,
   "y": 14,
   "z": 4,
   "name": "Rock_Basalt"
  },
  {
   "x": -8,
   "y": 15,
   "z": 4,
   "name": "Soil_Dirt"
  },
  {
   "x": -8,
   "y": 16,
   "z": 4,
   "name": "Rock_Basalt"
  },
  {
   "x": -8,
   "y": 17,
   "z": 4,
   "name": "Rock_Basalt"
  },
  {
   "x": -8,
   "y": 31,
   "z": 4,
   "name": "Plant_Leaves_Cedar"
  },
  {
   "x": -8,
   "y": 38,
   "z": 4,
   "name": "Plant_Leaves_Cedar"
  },
  {
   "x": -8,
   "y": 2,
   "z": 5,
   "name": "Rock_Basalt"
  },
  {
   "x": -8,
   "y": 3,
   "z": 5,
   "name": "Rock_Basalt"
  },
  {
   "x": -8,
   "y": 4,
   "z": 5,
   "name": "Rock_Basalt"
  },
  {
   "x": -8,
   "y": 5,
   "z": 5,
   "name": "Rock_Basalt"
  },
  {
   "x": -8,
   "y": 6,
   "z": 5,
   "name": "Rock_Basalt"
  },
  {
   "x": -8,
   "y": 7,
   "z": 5,
   "name": "Rock_Basalt"
  },
  {
   "x": -8,
   "y": 8,
   "z": 5,
   "name": "Rock_Basalt"
  },
  {
   "x": -8,
   "y": 9,
   "z": 5,
   "name": "Rock_Basalt"
  },
  {
   "x": -8,
   "y": 10,
   "z": 5,
   "name": "Rock_Basalt"
  },
  {
   "x": -8,
   "y": 11,
   "z": 5,
   "name": "Rock_Basalt"
  },
  {
   "x": -8,
   "y": 12,
   "z": 5,
   "name": "Rock_Basalt"
  },
  {
   "x": -8,
   "y": 13,
   "z": 5,
   "name": "Rock_Basalt"
  },
  {
   "x": -8,
   "y": 14,
   "z": 5,
   "name": "Soil_Dirt"
  },
  {
   "x": -8,
   "y": 15,
   "z": 5,
   "name": "Soil_Dirt"
  },
  {
   "x": -8,
   "y": 16,
   "z": 5,
   "name": "Soil_Grass"
  },
  {
   "x": -8,
   "y": 31,
   "z": 5,
   "name": "Plant_Leaves_Cedar"
  },
  {
   "x": -8,
   "y": 32,
   "z": 5,
   "name": "Plant_Leaves_Cedar"
  },
  {
   "x": -8,
   "y": 38,
   "z": 5,
   "name": "Plant_Leaves_Cedar"
  },
  {
   "x": -8,
   "y": 2,
   "z": 6,
   "name": "Rock_Basalt"
  },
  {
   "x": -8,
   "y": 3,
   "z": 6,
   "name": "Rock_Basalt"
  },
  {
   "x": -8,
   "y": 4,
   "z": 6,
   "name": "Rock_Basalt"
  },
  {
   "x": -8,
   "y": 5,
   "z": 6,
   "name": "Rock_Basalt"
  },
  {
   "x": -8,
   "y": 6,
   "z": 6,
   "name": "Rock_Basalt"
  },
  {
   "x": -8,
   "y": 7,
   "z": 6,
   "name": "Rock_Basalt"
  },
  {
   "x": -8,
   "y": 8,
   "z": 6,
   "name": "Rock_Basalt"
  },
  {
   "x": -8,
   "y": 9,
   "z": 6,
   "name": "Rock_Basalt"
  },
  {
   "x": -8,
   "y": 10,
   "z": 6,
   "name": "Rock_Basalt"
  },
  {
   "x": -8,
   "y": 11,
   "z": 6,
   "name": "Rock_Basalt"
  },
  {
   "x": -8,
   "y": 12,
   "z": 6,
   "name": "Rock_Basalt"
  },
  {
   "x": -8,
   "y": 13,
   "z": 6,
   "name": "Rock_Basalt"
  },
  {
   "x": -8,
   "y": 14,
   "z": 6,
   "name": "Rock_Basalt"
  },
  {
   "x": -8,
   "y": 15,
   "z": 6,
   "name": "Soil_Dirt"
  },
  {
   "x": -8,
   "y": 16,
   "z": 6,
   "name": "Soil_Grass"
  },
  {
   "x": -8,
   "y": 17,
   "z": 6,
   "name": "Plant_Grass_Winter"
  },
  {
   "x": -8,
   "y": 31,
   "z": 6,
   "name": "Plant_Leaves_Cedar"
  },
  {
   "x": -8,
   "y": 38,
   "z": 6,
   "name": "Plant_Leaves_Cedar"
  },
  {
   "x": -8,
   "y": 39,
   "z": 6,
   "name": "Plant_Leaves_Cedar"
  },
  {
   "x": -8,
   "y": 2,
   "z": 7,
   "name": "Rock_Basalt"
  },
  {
   "x": -8,
   "y": 3,
   "z": 7,
   "name": "Rock_Basalt"
  },
  {
   "x": -8,
   "y": 4,
   "z": 7,
   "name": "Rock_Basalt"
  },
  {
   "x": -8,
   "y": 5,
   "z": 7,
   "name": "Rock_Basalt"
  },
  {
   "x": -8,
   "y": 6,
   "z": 7,
   "name": "Rock_Basalt"
  },
  {
   "x": -8,
   "y": 7,
   "z": 7,
   "name": "Rock_Basalt"
  },
  {
   "x": -8,
   "y": 8,
   "z": 7,
   "name": "Rock_Basalt"
  },
  {
   "x": -8,
   "y": 9,
   "z": 7,
   "name": "Rock_Basalt"
  },
  {
   "x": -8,
   "y": 10,
   "z": 7,
   "name": "Rock_Basalt"
  },
  {
   "x": -8,
   "y": 11,
   "z": 7,
   "name": "Rock_Basalt"
  },
  {
   "x": -8,
   "y": 12,
   "z": 7,
   "name": "Rock_Basalt"
  },
  {
   "x": -8,
   "y": 13,
   "z": 7,
   "name": "Rock_Basalt"
  },
  {
   "x": -8,
   "y": 14,
   "z": 7,
   "name": "Rock_Basalt"
  },
  {
   "x": -8,
   "y": 15,
   "z": 7,
   "name": "Rock_Basalt"
  },
  {
   "x": -8,
   "y": 16,
   "z": 7,
   "name": "Soil_Grass"
  },
  {
   "x": -8,
   "y": 17,
   "z": 7,
   "name": "Plant_Grass_Winter"
  },
  {
   "x": -8,
   "y": 31,
   "z": 7,
   "name": "Plant_Leaves_Cedar"
  },
  {
   "x": -8,
   "y": 34,
   "z": 7,
   "name": "Plant_Leaves_Cedar"
  },
  {
   "x": -8,
   "y": 37,
   "z": 7,
   "name": "Plant_Leaves_Cedar"
  },
  {
   "x": -8,
   "y": 39,
   "z": 7,
   "name": "Plant_Leaves_Cedar"
  },
  {
   "x": -8,
   "y": 42,
   "z": 7,
   "name": "Plant_Leaves_Cedar"
  },
  {
   "x": -8,
   "y": 3,
   "z": 8,
   "name": "Rock_Basalt"
  },
  {
   "x": -8,
   "y": 4,
   "z": 8,
   "name": "Rock_Basalt"
  },
  {
   "x": -8,
   "y": 5,
   "z": 8,
   "name": "Rock_Basalt"
  },
  {
   "x": -8,
   "y": 6,
   "z": 8,
   "name": "Rock_Basalt"
  },
  {
   "x": -8,
   "y": 7,
   "z": 8,
   "name": "Rock_Basalt"
  },
  {
   "x": -8,
   "y": 8,
   "z": 8,
   "name": "Rock_Basalt"
  },
  {
   "x": -8,
   "y": 9,
   "z": 8,
   "name": "Rock_Basalt"
  },
  {
   "x": -8,
   "y": 10,
   "z": 8,
   "name": "Rock_Basalt"
  },
  {
   "x": -8,
   "y": 11,
   "z": 8,
   "name": "Rock_Basalt"
  },
  {
   "x": -8,
   "y": 12,
   "z": 8,
   "name": "Rock_Basalt"
  },
  {
   "x": -8,
   "y": 13,
   "z": 8,
   "name": "Rock_Basalt"
  },
  {
   "x": -8,
   "y": 14,
   "z": 8,
   "name": "Rock_Basalt"
  },
  {
   "x": -8,
   "y": 15,
   "z": 8,
   "name": "Soil_Dirt"
  },
  {
   "x": -8,
   "y": 16,
   "z": 8,
   "name": "Soil_Needles"
  },
  {
   "x": -8,
   "y": 17,
   "z": 8,
   "name": "Plant_Grass_Winter_Short"
  },
  {
   "x": -8,
   "y": 31,
   "z": 8,
   "name": "Wood_Cedar_Branch_Long",
   "rotation": 5
  },
  {
   "x": -8,
   "y": 34,
   "z": 8,
   "name": "Plant_Leaves_Cedar"
  },
  {
   "x": -8,
   "y": 36,
   "z": 8,
   "name": "Plant_Leaves_Cedar"
  },
  {
   "x": -8,
   "y": 37,
   "z": 8,
   "name": "Plant_Leaves_Cedar"
  },
  {
   "x": -8,
   "y": 41,
   "z": 8,
   "name": "Plant_Leaves_Cedar"
  },
  {
   "x": -8,
   "y": 42,
   "z": 8,
   "name": "Plant_Leaves_Cedar"
  },
  {
   "x": -8,
   "y": 44,
   "z": 8,
   "name": "Plant_Leaves_Cedar"
  },
  {
   "x": -8,
   "y": 3,
   "z": 9,
   "name": "Rock_Basalt"
  },
  {
   "x": -8,
   "y": 4,
   "z": 9,
   "name": "Rock_Basalt"
  },
  {
   "x": -8,
   "y": 5,
   "z": 9,
   "name": "Rock_Basalt"
  },
  {
   "x": -8,
   "y": 6,
   "z": 9,
   "name": "Rock_Basalt"
  },
  {
   "x": -8,
   "y": 7,
   "z": 9,
   "name": "Rock_Basalt"
  },
  {
   "x": -8,
   "y": 8,
   "z": 9,
   "name": "Rock_Basalt"
  },
  {
   "x": -8,
   "y": 9,
   "z": 9,
   "name": "Rock_Basalt"
  },
  {
   "x": -8,
   "y": 10,
   "z": 9,
   "name": "Rock_Basalt"
  },
  {
   "x": -8,
   "y": 11,
   "z": 9,
   "name": "Rock_Basalt"
  },
  {
   "x": -8,
   "y": 12,
   "z": 9,
   "name": "Rock_Basalt"
  },
  {
   "x": -8,
   "y": 13,
   "z": 9,
   "name": "Rock_Basalt"
  },
  {
   "x": -8,
   "y": 14,
   "z": 9,
   "name": "Rock_Basalt"
  },
  {
   "x": -8,
   "y": 15,
   "z": 9,
   "name": "Soil_Dirt"
  },
  {
   "x": -8,
   "y": 16,
   "z": 9,
   "name": "Soil_Needles"
  },
  {
   "x": -8,
   "y": 31,
   "z": 9,
   "name": "Plant_Leaves_Cedar"
  },
  {
   "x": -8,
   "y": 33,
   "z": 9,
   "name": "Plant_Leaves_Cedar"
  },
  {
   "x": -8,
   "y": 34,
   "z": 9,
   "name": "Plant_Leaves_Cedar"
  },
  {
   "x": -8,
   "y": 36,
   "z": 9,
   "name": "Plant_Leaves_Cedar"
  },
  {
   "x": -8,
   "y": 41,
   "z": 9,
   "name": "Plant_Leaves_Cedar"
  },
  {
   "x": -8,
   "y": 42,
   "z": 9,
   "name": "Plant_Leaves_Cedar"
  },
  {
   "x": -8,
   "y": 5,
   "z": 10,
   "name": "Rock_Basalt"
  },
  {
   "x": -8,
   "y": 6,
   "z": 10,
   "name": "Rock_Basalt"
  },
  {
   "x": -8,
   "y": 7,
   "z": 10,
   "name": "Rock_Basalt"
  },
  {
   "x": -8,
   "y": 8,
   "z": 10,
   "name": "Rock_Basalt"
  },
  {
   "x": -8,
   "y": 9,
   "z": 10,
   "name": "Rock_Basalt"
  },
  {
   "x": -8,
   "y": 10,
   "z": 10,
   "name": "Rock_Basalt"
  },
  {
   "x": -8,
   "y": 11,
   "z": 10,
   "name": "Rock_Basalt"
  },
  {
   "x": -8,
   "y": 12,
   "z": 10,
   "name": "Rock_Basalt"
  },
  {
   "x": -8,
   "y": 13,
   "z": 10,
   "name": "Rock_Basalt"
  },
  {
   "x": -8,
   "y": 14,
   "z": 10,
   "name": "Soil_Dirt"
  },
  {
   "x": -8,
   "y": 15,
   "z": 10,
   "name": "Soil_Dirt"
  },
  {
   "x": -8,
   "y": 16,
   "z": 10,
   "name": "Soil_Needles"
  },
  {
   "x": -8,
   "y": 30,
   "z": 10,
   "name": "Plant_Leaves_Cedar"
  },
  {
   "x": -8,
   "y": 7,
   "z": 11,
   "name": "Rock_Basalt"
  },
  {
   "x": -8,
   "y": 8,
   "z": 11,
   "name": "Rock_Basalt"
  },
  {
   "x": -8,
   "y": 9,
   "z": 11,
   "name": "Rock_Basalt"
  },
  {
   "x": -8,
   "y": 10,
   "z": 11,
   "name": "Rock_Basalt"
  },
  {
   "x": -8,
   "y": 11,
   "z": 11,
   "name": "Rock_Basalt"
  },
  {
   "x": -8,
   "y": 12,
   "z": 11,
   "name": "Rock_Basalt"
  },
  {
   "x": -8,
   "y": 13,
   "z": 11,
   "name": "Rock_Basalt"
  },
  {
   "x": -8,
   "y": 14,
   "z": 11,
   "name": "Rock_Basalt"
  },
  {
   "x": -8,
   "y": 15,
   "z": 11,
   "name": "Soil_Dirt"
  },
  {
   "x": -8,
   "y": 16,
   "z": 11,
   "name": "Soil_Grass"
  },
  {
   "x": -8,
   "y": 12,
   "z": 12,
   "name": "Rock_Basalt"
  },
  {
   "x": -8,
   "y": 13,
   "z": 12,
   "name": "Rock_Basalt"
  },
  {
   "x": -8,
   "y": 14,
   "z": 12,
   "name": "Soil_Dirt"
  },
  {
   "x": -8,
   "y": 15,
   "z": 12,
   "name": "Soil_Dirt"
  },
  {
   "x": -8,
   "y": 16,
   "z": 12,
   "name": "Soil_Grass"
  },
  {
   "x": -8,
   "y": 31,
   "z": 12,
   "name": "Plant_Leaves_Cedar"
  },
  {
   "x": -8,
   "y": 16,
   "z": 13,
   "name": "Soil_Grass"
  },
  {
   "x": -8,
   "y": 30,
   "z": 13,
   "name": "Plant_Leaves_Cedar"
  },
  {
   "x": -7,
   "y": 11,
   "z": -11,
   "name": "Soil_Dirt"
  },
  {
   "x": -7,
   "y": 12,
   "z": -11,
   "name": "Soil_Grass"
  },
  {
   "x": -7,
   "y": 8,
   "z": -10,
   "name": "Rock_Basalt"
  },
  {
   "x": -7,
   "y": 9,
   "z": -10,
   "name": "Rock_Basalt"
  },
  {
   "x": -7,
   "y": 10,
   "z": -10,
   "name": "Rock_Basalt"
  },
  {
   "x": -7,
   "y": 11,
   "z": -10,
   "name": "Soil_Dirt"
  },
  {
   "x": -7,
   "y": 12,
   "z": -10,
   "name": "Soil_Grass"
  },
  {
   "x": -7,
   "y": 6,
   "z": -9,
   "name": "Rock_Basalt"
  },
  {
   "x": -7,
   "y": 7,
   "z": -9,
   "name": "Rock_Basalt"
  },
  {
   "x": -7,
   "y": 8,
   "z": -9,
   "name": "Rock_Basalt"
  },
  {
   "x": -7,
   "y": 9,
   "z": -9,
   "name": "Rock_Basalt"
  },
  {
   "x": -7,
   "y": 10,
   "z": -9,
   "name": "Soil_Dirt"
  },
  {
   "x": -7,
   "y": 11,
   "z": -9,
   "name": "Soil_Dirt"
  },
  {
   "x": -7,
   "y": 12,
   "z": -9,
   "name": "Soil_Grass"
  },
  {
   "x": -7,
   "y": 4,
   "z": -8,
   "name": "Rock_Basalt"
  },
  {
   "x": -7,
   "y": 5,
   "z": -8,
   "name": "Rock_Basalt"
  },
  {
   "x": -7,
   "y": 6,
   "z": -8,
   "name": "Rock_Basalt"
  },
  {
   "x": -7,
   "y": 7,
   "z": -8,
   "name": "Rock_Basalt"
  },
  {
   "x": -7,
   "y": 8,
   "z": -8,
   "name": "Rock_Basalt"
  },
  {
   "x": -7,
   "y": 9,
   "z": -8,
   "name": "Rock_Basalt"
  },
  {
   "x": -7,
   "y": 10,
   "z": -8,
   "name": "Rock_Basalt"
  },
  {
   "x": -7,
   "y": 11,
   "z": -8,
   "name": "Soil_Dirt"
  },
  {
   "x": -7,
   "y": 12,
   "z": -8,
   "name": "Soil_Dirt"
  },
  {
   "x": -7,
   "y": 13,
   "z": -8,
   "name": "Soil_Grass"
  },
  {
   "x": -7,
   "y": 3,
   "z": -7,
   "name": "Rock_Basalt"
  },
  {
   "x": -7,
   "y": 4,
   "z": -7,
   "name": "Rock_Basalt"
  },
  {
   "x": -7,
   "y": 5,
   "z": -7,
   "name": "Rock_Basalt"
  },
  {
   "x": -7,
   "y": 6,
   "z": -7,
   "name": "Rock_Basalt"
  },
  {
   "x": -7,
   "y": 7,
   "z": -7,
   "name": "Rock_Basalt"
  },
  {
   "x": -7,
   "y": 8,
   "z": -7,
   "name": "Rock_Basalt"
  },
  {
   "x": -7,
   "y": 9,
   "z": -7,
   "name": "Rock_Basalt"
  },
  {
   "x": -7,
   "y": 10,
   "z": -7,
   "name": "Rock_Basalt"
  },
  {
   "x": -7,
   "y": 11,
   "z": -7,
   "name": "Rock_Basalt"
  },
  {
   "x": -7,
   "y": 12,
   "z": -7,
   "name": "Soil_Dirt"
  },
  {
   "x": -7,
   "y": 13,
   "z": -7,
   "name": "Soil_Grass"
  },
  {
   "x": -7,
   "y": 14,
   "z": -7,
   "name": "Plant_Grass_Winter_Short"
  },
  {
   "x": -7,
   "y": 25,
   "z": -7,
   "name": "Plant_Leaves_Redwood"
  },
  {
   "x": -7,
   "y": 3,
   "z": -6,
   "name": "Rock_Basalt"
  },
  {
   "x": -7,
   "y": 4,
   "z": -6,
   "name": "Rock_Basalt"
  },
  {
   "x": -7,
   "y": 5,
   "z": -6,
   "name": "Rock_Basalt"
  },
  {
   "x": -7,
   "y": 6,
   "z": -6,
   "name": "Rock_Basalt"
  },
  {
   "x": -7,
   "y": 7,
   "z": -6,
   "name": "Rock_Basalt"
  },
  {
   "x": -7,
   "y": 8,
   "z": -6,
   "name": "Rock_Basalt"
  },
  {
   "x": -7,
   "y": 9,
   "z": -6,
   "name": "Rock_Basalt"
  },
  {
   "x": -7,
   "y": 10,
   "z": -6,
   "name": "Rock_Basalt"
  },
  {
   "x": -7,
   "y": 11,
   "z": -6,
   "name": "Rock_Basalt"
  },
  {
   "x": -7,
   "y": 12,
   "z": -6,
   "name": "Soil_Dirt"
  },
  {
   "x": -7,
   "y": 13,
   "z": -6,
   "name": "Soil_Grass"
  },
  {
   "x": -7,
   "y": 24,
   "z": -6,
   "name": "Plant_Leaves_Redwood"
  },
  {
   "x": -7,
   "y": 25,
   "z": -6,
   "name": "Plant_Leaves_Redwood"
  },
  {
   "x": -7,
   "y": 29,
   "z": -6,
   "name": "Plant_Leaves_Redwood"
  },
  {
   "x": -7,
   "y": 30,
   "z": -6,
   "name": "Plant_Leaves_Redwood"
  },
  {
   "x": -7,
   "y": 35,
   "z": -6,
   "name": "Plant_Leaves_Redwood"
  },
  {
   "x": -7,
   "y": 3,
   "z": -5,
   "name": "Rock_Basalt"
  },
  {
   "x": -7,
   "y": 4,
   "z": -5,
   "name": "Rock_Basalt"
  },
  {
   "x": -7,
   "y": 5,
   "z": -5,
   "name": "Rock_Basalt"
  },
  {
   "x": -7,
   "y": 6,
   "z": -5,
   "name": "Rock_Basalt"
  },
  {
   "x": -7,
   "y": 7,
   "z": -5,
   "name": "Rock_Basalt"
  },
  {
   "x": -7,
   "y": 8,
   "z": -5,
   "name": "Rock_Basalt"
  },
  {
   "x": -7,
   "y": 9,
   "z": -5,
   "name": "Rock_Basalt"
  },
  {
   "x": -7,
   "y": 10,
   "z": -5,
   "name": "Rock_Basalt"
  },
  {
   "x": -7,
   "y": 11,
   "z": -5,
   "name": "Soil_Dirt"
  },
  {
   "x": -7,
   "y": 12,
   "z": -5,
   "name": "Soil_Dirt"
  },
  {
   "x": -7,
   "y": 13,
   "z": -5,
   "name": "Soil_Grass"
  },
  {
   "x": -7,
   "y": 3,
   "z": -4,
   "name": "Rock_Basalt"
  },
  {
   "x": -7,
   "y": 4,
   "z": -4,
   "name": "Rock_Basalt"
  },
  {
   "x": -7,
   "y": 5,
   "z": -4,
   "name": "Rock_Basalt"
  },
  {
   "x": -7,
   "y": 6,
   "z": -4,
   "name": "Rock_Basalt"
  },
  {
   "x": -7,
   "y": 7,
   "z": -4,
   "name": "Rock_Basalt"
  },
  {
   "x": -7,
   "y": 8,
   "z": -4,
   "name": "Rock_Basalt"
  },
  {
   "x": -7,
   "y": 9,
   "z": -4,
   "name": "Rock_Basalt"
  },
  {
   "x": -7,
   "y": 10,
   "z": -4,
   "name": "Rock_Basalt"
  },
  {
   "x": -7,
   "y": 11,
   "z": -4,
   "name": "Rock_Basalt"
  },
  {
   "x": -7,
   "y": 12,
   "z": -4,
   "name": "Soil_Dirt"
  },
  {
   "x": -7,
   "y": 13,
   "z": -4,
   "name": "Soil_Dirt"
  },
  {
   "x": -7,
   "y": 14,
   "z": -4,
   "name": "Soil_Grass"
  },
  {
   "x": -7,
   "y": 5,
   "z": -3,
   "name": "Rock_Basalt"
  },
  {
   "x": -7,
   "y": 6,
   "z": -3,
   "name": "Rock_Basalt"
  },
  {
   "x": -7,
   "y": 7,
   "z": -3,
   "name": "Rock_Basalt"
  },
  {
   "x": -7,
   "y": 8,
   "z": -3,
   "name": "Rock_Basalt"
  },
  {
   "x": -7,
   "y": 9,
   "z": -3,
   "name": "Rock_Basalt"
  },
  {
   "x": -7,
   "y": 10,
   "z": -3,
   "name": "Rock_Basalt"
  },
  {
   "x": -7,
   "y": 11,
   "z": -3,
   "name": "Rock_Basalt"
  },
  {
   "x": -7,
   "y": 12,
   "z": -3,
   "name": "Soil_Dirt"
  },
  {
   "x": -7,
   "y": 13,
   "z": -3,
   "name": "Soil_Dirt"
  },
  {
   "x": -7,
   "y": 14,
   "z": -3,
   "name": "Soil_Grass"
  },
  {
   "x": -7,
   "y": 6,
   "z": -2,
   "name": "Rock_Basalt"
  },
  {
   "x": -7,
   "y": 7,
   "z": -2,
   "name": "Rock_Basalt"
  },
  {
   "x": -7,
   "y": 8,
   "z": -2,
   "name": "Rock_Basalt"
  },
  {
   "x": -7,
   "y": 9,
   "z": -2,
   "name": "Rock_Basalt"
  },
  {
   "x": -7,
   "y": 10,
   "z": -2,
   "name": "Rock_Basalt"
  },
  {
   "x": -7,
   "y": 11,
   "z": -2,
   "name": "Rock_Basalt"
  },
  {
   "x": -7,
   "y": 12,
   "z": -2,
   "name": "Rock_Basalt"
  },
  {
   "x": -7,
   "y": 13,
   "z": -2,
   "name": "Soil_Dirt"
  },
  {
   "x": -7,
   "y": 14,
   "z": -2,
   "name": "Soil_Grass"
  },
  {
   "x": -7,
   "y": 7,
   "z": -1,
   "name": "Rock_Basalt"
  },
  {
   "x": -7,
   "y": 8,
   "z": -1,
   "name": "Rock_Basalt"
  },
  {
   "x": -7,
   "y": 9,
   "z": -1,
   "name": "Rock_Basalt"
  },
  {
   "x": -7,
   "y": 10,
   "z": -1,
   "name": "Rock_Basalt"
  },
  {
   "x": -7,
   "y": 11,
   "z": -1,
   "name": "Rock_Basalt"
  },
  {
   "x": -7,
   "y": 12,
   "z": -1,
   "name": "Rock_Basalt"
  },
  {
   "x": -7,
   "y": 13,
   "z": -1,
   "name": "Soil_Dirt"
  },
  {
   "x": -7,
   "y": 14,
   "z": -1,
   "name": "Soil_Dirt"
  },
  {
   "x": -7,
   "y": 15,
   "z": -1,
   "name": "Soil_Grass"
  },
  {
   "x": -7,
   "y": 6,
   "z": 0,
   "name": "Rock_Basalt"
  },
  {
   "x": -7,
   "y": 7,
   "z": 0,
   "name": "Rock_Basalt"
  },
  {
   "x": -7,
   "y": 8,
   "z": 0,
   "name": "Rock_Basalt"
  },
  {
   "x": -7,
   "y": 9,
   "z": 0,
   "name": "Rock_Basalt"
  },
  {
   "x": -7,
   "y": 10,
   "z": 0,
   "name": "Rock_Basalt"
  },
  {
   "x": -7,
   "y": 11,
   "z": 0,
   "name": "Rock_Basalt"
  },
  {
   "x": -7,
   "y": 12,
   "z": 0,
   "name": "Rock_Basalt"
  },
  {
   "x": -7,
   "y": 13,
   "z": 0,
   "name": "Soil_Dirt"
  },
  {
   "x": -7,
   "y": 14,
   "z": 0,
   "name": "Soil_Dirt"
  },
  {
   "x": -7,
   "y": 15,
   "z": 0,
   "name": "Rock_Basalt"
  },
  {
   "x": -7,
   "y": 6,
   "z": 1,
   "name": "Rock_Basalt"
  },
  {
   "x": -7,
   "y": 7,
   "z": 1,
   "name": "Rock_Basalt"
  },
  {
   "x": -7,
   "y": 8,
   "z": 1,
   "name": "Rock_Basalt"
  },
  {
   "x": -7,
   "y": 9,
   "z": 1,
   "name": "Rock_Basalt"
  },
  {
   "x": -7,
   "y": 10,
   "z": 1,
   "name": "Rock_Basalt"
  },
  {
   "x": -7,
   "y": 11,
   "z": 1,
   "name": "Rock_Basalt"
  },
  {
   "x": -7,
   "y": 12,
   "z": 1,
   "name": "Rock_Basalt"
  },
  {
   "x": -7,
   "y": 13,
   "z": 1,
   "name": "Soil_Dirt"
  },
  {
   "x": -7,
   "y": 14,
   "z": 1,
   "name": "Soil_Dirt"
  },
  {
   "x": -7,
   "y": 15,
   "z": 1,
   "name": "Rock_Basalt"
  },
  {
   "x": -7,
   "y": 16,
   "z": 1,
   "name": "Rock_Basalt"
  },
  {
   "x": -7,
   "y": 3,
   "z": 2,
   "name": "Rock_Basalt"
  },
  {
   "x": -7,
   "y": 4,
   "z": 2,
   "name": "Rock_Basalt"
  },
  {
   "x": -7,
   "y": 5,
   "z": 2,
   "name": "Rock_Basalt"
  },
  {
   "x": -7,
   "y": 6,
   "z": 2,
   "name": "Rock_Basalt"
  },
  {
   "x": -7,
   "y": 7,
   "z": 2,
   "name": "Rock_Basalt"
  },
  {
   "x": -7,
   "y": 8,
   "z": 2,
   "name": "Rock_Basalt"
  },
  {
   "x": -7,
   "y": 9,
   "z": 2,
   "name": "Rock_Basalt"
  },
  {
   "x": -7,
   "y": 10,
   "z": 2,
   "name": "Rock_Basalt"
  },
  {
   "x": -7,
   "y": 11,
   "z": 2,
   "name": "Rock_Basalt"
  },
  {
   "x": -7,
   "y": 12,
   "z": 2,
   "name": "Rock_Basalt"
  },
  {
   "x": -7,
   "y": 13,
   "z": 2,
   "name": "Soil_Dirt"
  },
  {
   "x": -7,
   "y": 14,
   "z": 2,
   "name": "Soil_Dirt"
  },
  {
   "x": -7,
   "y": 15,
   "z": 2,
   "name": "Rock_Basalt"
  },
  {
   "x": -7,
   "y": 16,
   "z": 2,
   "name": "Rock_Basalt"
  },
  {
   "x": -7,
   "y": 17,
   "z": 2,
   "name": "Rock_Basalt"
  },
  {
   "x": -7,
   "y": 3,
   "z": 3,
   "name": "Rock_Basalt"
  },
  {
   "x": -7,
   "y": 4,
   "z": 3,
   "name": "Rock_Basalt"
  },
  {
   "x": -7,
   "y": 5,
   "z": 3,
   "name": "Rock_Basalt"
  },
  {
   "x": -7,
   "y": 6,
   "z": 3,
   "name": "Rock_Basalt"
  },
  {
   "x": -7,
   "y": 7,
   "z": 3,
   "name": "Rock_Basalt"
  },
  {
   "x": -7,
   "y": 8,
   "z": 3,
   "name": "Rock_Basalt"
  },
  {
   "x": -7,
   "y": 9,
   "z": 3,
   "name": "Rock_Basalt"
  },
  {
   "x": -7,
   "y": 10,
   "z": 3,
   "name": "Rock_Basalt"
  },
  {
   "x": -7,
   "y": 11,
   "z": 3,
   "name": "Rock_Basalt"
  },
  {
   "x": -7,
   "y": 12,
   "z": 3,
   "name": "Rock_Basalt"
  },
  {
   "x": -7,
   "y": 13,
   "z": 3,
   "name": "Rock_Basalt"
  },
  {
   "x": -7,
   "y": 14,
   "z": 3,
   "name": "Soil_Dirt"
  },
  {
   "x": -7,
   "y": 15,
   "z": 3,
   "name": "Rock_Basalt"
  },
  {
   "x": -7,
   "y": 16,
   "z": 3,
   "name": "Rock_Basalt"
  },
  {
   "x": -7,
   "y": 34,
   "z": 3,
   "name": "Plant_Leaves_Cedar"
  },
  {
   "x": -7,
   "y": 1,
   "z": 4,
   "name": "Rock_Basalt"
  },
  {
   "x": -7,
   "y": 2,
   "z": 4,
   "name": "Rock_Basalt"
  },
  {
   "x": -7,
   "y": 3,
   "z": 4,
   "name": "Rock_Basalt"
  },
  {
   "x": -7,
   "y": 4,
   "z": 4,
   "name": "Rock_Basalt"
  },
  {
   "x": -7,
   "y": 5,
   "z": 4,
   "name": "Rock_Basalt"
  },
  {
   "x": -7,
   "y": 6,
   "z": 4,
   "name": "Rock_Basalt"
  },
  {
   "x": -7,
   "y": 7,
   "z": 4,
   "name": "Rock_Basalt"
  },
  {
   "x": -7,
   "y": 8,
   "z": 4,
   "name": "Wood_Cedar_Trunk",
   "support": 15
  },
  {
   "x": -7,
   "y": 9,
   "z": 4,
   "name": "Wood_Cedar_Trunk",
   "support": 15
  },
  {
   "x": -7,
   "y": 10,
   "z": 4,
   "name": "Rock_Basalt"
  },
  {
   "x": -7,
   "y": 11,
   "z": 4,
   "name": "Rock_Basalt"
  },
  {
   "x": -7,
   "y": 12,
   "z": 4,
   "name": "Rock_Basalt"
  },
  {
   "x": -7,
   "y": 13,
   "z": 4,
   "name": "Rock_Basalt"
  },
  {
   "x": -7,
   "y": 14,
   "z": 4,
   "name": "Soil_Dirt"
  },
  {
   "x": -7,
   "y": 15,
   "z": 4,
   "name": "Soil_Dirt"
  },
  {
   "x": -7,
   "y": 16,
   "z": 4,
   "name": "Soil_Grass"
  },
  {
   "x": -7,
   "y": 17,
   "z": 4,
   "name": "Plant_Grass_Winter_Tall"
  },
  {
   "x": -7,
   "y": 18,
   "z": 4,
   "name": "Plant_Grass_Winter_Tall",
   "filler": 1024
  },
  {
   "x": -7,
   "y": 32,
   "z": 4,
   "name": "Plant_Leaves_Cedar"
  },
  {
   "x": -7,
   "y": 35,
   "z": 4,
   "name": "Plant_Leaves_Cedar"
  },
  {
   "x": -7,
   "y": 1,
   "z": 5,
   "name": "Rock_Basalt"
  },
  {
   "x": -7,
   "y": 2,
   "z": 5,
   "name": "Rock_Basalt"
  },
  {
   "x": -7,
   "y": 3,
   "z": 5,
   "name": "Rock_Basalt"
  },
  {
   "x": -7,
   "y": 4,
   "z": 5,
   "name": "Rock_Basalt"
  },
  {
   "x": -7,
   "y": 5,
   "z": 5,
   "name": "Rock_Basalt"
  },
  {
   "x": -7,
   "y": 6,
   "z": 5,
   "name": "Rock_Basalt"
  },
  {
   "x": -7,
   "y": 7,
   "z": 5,
   "name": "Rock_Basalt"
  },
  {
   "x": -7,
   "y": 8,
   "z": 5,
   "name": "Wood_Cedar_Trunk",
   "support": 15
  },
  {
   "x": -7,
   "y": 9,
   "z": 5,
   "name": "Wood_Cedar_Trunk",
   "support": 15
  },
  {
   "x": -7,
   "y": 10,
   "z": 5,
   "name": "Wood_Cedar_Trunk",
   "support": 15
  },
  {
   "x": -7,
   "y": 11,
   "z": 5,
   "name": "Wood_Cedar_Trunk",
   "support": 15
  },
  {
   "x": -7,
   "y": 12,
   "z": 5,
   "name": "Wood_Cedar_Trunk",
   "support": 15
  },
  {
   "x": -7,
   "y": 13,
   "z": 5,
   "name": "Rock_Basalt"
  },
  {
   "x": -7,
   "y": 14,
   "z": 5,
   "name": "Soil_Dirt"
  },
  {
   "x": -7,
   "y": 15,
   "z": 5,
   "name": "Soil_Dirt"
  },
  {
   "x": -7,
   "y": 16,
   "z": 5,
   "name": "Soil_Grass"
  },
  {
   "x": -7,
   "y": 17,
   "z": 5,
   "name": "Plant_Grass_Winter_Short"
  },
  {
   "x": -7,
   "y": 31,
   "z": 5,
   "name": "Plant_Leaves_Cedar"
  },
  {
   "x": -7,
   "y": 32,
   "z": 5,
   "name": "Plant_Leaves_Cedar"
  },
  {
   "x": -7,
   "y": 39,
   "z": 5,
   "name": "Plant_Leaves_Cedar"
  },
  {
   "x": -7,
   "y": 1,
   "z": 6,
   "name": "Rock_Basalt"
  },
  {
   "x": -7,
   "y": 2,
   "z": 6,
   "name": "Rock_Basalt"
  },
  {
   "x": -7,
   "y": 3,
   "z": 6,
   "name": "Rock_Basalt"
  },
  {
   "x": -7,
   "y": 4,
   "z": 6,
   "name": "Rock_Basalt"
  },
  {
   "x": -7,
   "y": 5,
   "z": 6,
   "name": "Rock_Basalt"
  },
  {
   "x": -7,
   "y": 6,
   "z": 6,
   "name": "Rock_Basalt"
  },
  {
   "x": -7,
   "y": 7,
   "z": 6,
   "name": "Rock_Basalt"
  },
  {
   "x": -7,
   "y": 8,
   "z": 6,
   "name": "Empty"
  },
  {
   "x": -7,
   "y": 9,
   "z": 6,
   "name": "Empty"
  },
  {
   "x": -7,
   "y": 10,
   "z": 6,
   "name": "Rock_Basalt"
  },
  {
   "x": -7,
   "y": 11,
   "z": 6,
   "name": "Rock_Basalt"
  },
  {
   "x": -7,
   "y": 12,
   "z": 6,
   "name": "Rock_Basalt"
  },
  {
   "x": -7,
   "y": 13,
   "z": 6,
   "name": "Rock_Basalt"
  },
  {
   "x": -7,
   "y": 14,
   "z": 6,
   "name": "Soil_Dirt"
  },
  {
   "x": -7,
   "y": 15,
   "z": 6,
   "name": "Soil_Dirt"
  },
  {
   "x": -7,
   "y": 16,
   "z": 6,
   "name": "Soil_Grass"
  },
  {
   "x": -7,
   "y": 17,
   "z": 6,
   "name": "Plant_Grass_Winter_Tall"
  },
  {
   "x": -7,
   "y": 18,
   "z": 6,
   "name": "Plant_Grass_Winter_Tall",
   "filler": 1024
  },
  {
   "x": -7,
   "y": 32,
   "z": 6,
   "name": "Plant_Leaves_Cedar"
  },
  {
   "x": -7,
   "y": 39,
   "z": 6,
   "name": "Plant_Leaves_Cedar"
  },
  {
   "x": -7,
   "y": 40,
   "z": 6,
   "name": "Plant_Leaves_Cedar"
  },
  {
   "x": -7,
   "y": 1,
   "z": 7,
   "name": "Rock_Basalt"
  },
  {
   "x": -7,
   "y": 2,
   "z": 7,
   "name": "Rock_Basalt"
  },
  {
   "x": -7,
   "y": 3,
   "z": 7,
   "name": "Rock_Basalt"
  },
  {
   "x": -7,
   "y": 4,
   "z": 7,
   "name": "Rock_Basalt"
  },
  {
   "x": -7,
   "y": 5,
   "z": 7,
   "name": "Rock_Basalt"
  },
  {
   "x": -7,
   "y": 6,
   "z": 7,
   "name": "Rock_Basalt"
  },
  {
   "x": -7,
   "y": 7,
   "z": 7,
   "name": "Rock_Basalt"
  },
  {
   "x": -7,
   "y": 8,
   "z": 7,
   "name": "Furniture_Kweebec_Stool"
  },
  {
   "x": -7,
   "y": 9,
   "z": 7,
   "name": "Empty"
  },
  {
   "x": -7,
   "y": 10,
   "z": 7,
   "name": "Empty"
  },
  {
   "x": -7,
   "y": 11,
   "z": 7,
   "name": "Rock_Basalt"
  },
  {
   "x": -7,
   "y": 12,
   "z": 7,
   "name": "Rock_Basalt"
  },
  {
   "x": -7,
   "y": 13,
   "z": 7,
   "name": "Rock_Basalt"
  },
  {
   "x": -7,
   "y": 14,
   "z": 7,
   "name": "Rock_Basalt"
  },
  {
   "x": -7,
   "y": 15,
   "z": 7,
   "name": "Soil_Dirt"
  },
  {
   "x": -7,
   "y": 16,
   "z": 7,
   "name": "Soil_Needles"
  },
  {
   "x": -7,
   "y": 31,
   "z": 7,
   "name": "Plant_Leaves_Cedar"
  },
  {
   "x": -7,
   "y": 32,
   "z": 7,
   "name": "Plant_Leaves_Cedar"
  },
  {
   "x": -7,
   "y": 34,
   "z": 7,
   "name": "Plant_Leaves_Cedar"
  },
  {
   "x": -7,
   "y": 37,
   "z": 7,
   "name": "Plant_Leaves_Cedar"
  },
  {
   "x": -7,
   "y": 40,
   "z": 7,
   "name": "Plant_Leaves_Cedar"
  },
  {
   "x": -7,
   "y": 42,
   "z": 7,
   "name": "Plant_Leaves_Cedar"
  },
  {
   "x": -7,
   "y": 1,
   "z": 8,
   "name": "Rock_Basalt"
  },
  {
   "x": -7,
   "y": 2,
   "z": 8,
   "name": "Rock_Basalt"
  },
  {
   "x": -7,
   "y": 3,
   "z": 8,
   "name": "Rock_Basalt"
  },
  {
   "x": -7,
   "y": 4,
   "z": 8,
   "name": "Rock_Basalt"
  },
  {
   "x": -7,
   "y": 5,
   "z": 8,
   "name": "Rock_Basalt"
  },
  {
   "x": -7,
   "y": 6,
   "z": 8,
   "name": "Rock_Basalt"
  },
  {
   "x": -7,
   "y": 7,
   "z": 8,
   "name": "Rock_Basalt"
  },
  {
   "x": -7,
   "y": 8,
   "z": 8,
   "name": "Empty"
  },
  {
   "x": -7,
   "y": 9,
   "z": 8,
   "name": "Empty"
  },
  {
   "x": -7,
   "y": 10,
   "z": 8,
   "name": "Empty"
  },
  {
   "x": -7,
   "y": 11,
   "z": 8,
   "name": "Rock_Basalt"
  },
  {
   "x": -7,
   "y": 12,
   "z": 8,
   "name": "Rock_Basalt"
  },
  {
   "x": -7,
   "y": 13,
   "z": 8,
   "name": "Rock_Basalt"
  },
  {
   "x": -7,
   "y": 14,
   "z": 8,
   "name": "Soil_Dirt"
  },
  {
   "x": -7,
   "y": 15,
   "z": 8,
   "name": "Soil_Dirt"
  },
  {
   "x": -7,
   "y": 16,
   "z": 8,
   "name": "Soil_Needles"
  },
  {
   "x": -7,
   "y": 17,
   "z": 8,
   "name": "Plant_Grass_Winter_Short"
  },
  {
   "x": -7,
   "y": 31,
   "z": 8,
   "name": "Wood_Cedar_Branch_Long",
   "rotation": 5
  },
  {
   "x": -7,
   "y": 32,
   "z": 8,
   "name": "Plant_Leaves_Cedar"
  },
  {
   "x": -7,
   "y": 34,
   "z": 8,
   "name": "Wood_Cedar_Branch_Long",
   "rotation": 5
  },
  {
   "x": -7,
   "y": 37,
   "z": 8,
   "name": "Plant_Leaves_Cedar"
  },
  {
   "x": -7,
   "y": 38,
   "z": 8,
   "name": "Plant_Leaves_Cedar"
  },
  {
   "x": -7,
   "y": 40,
   "z": 8,
   "name": "Plant_Leaves_Cedar"
  },
  {
   "x": -7,
   "y": 42,
   "z": 8,
   "name": "Plant_Leaves_Cedar"
  },
  {
   "x": -7,
   "y": 44,
   "z": 8,
   "name": "Plant_Leaves_Cedar"
  },
  {
   "x": -7,
   "y": 45,
   "z": 8,
   "name": "Plant_Leaves_Cedar"
  },
  {
   "x": -7,
   "y": 47,
   "z": 8,
   "name": "Plant_Leaves_Cedar"
  },
  {
   "x": -7,
   "y": 2,
   "z": 9,
   "name": "Rock_Basalt"
  },
  {
   "x": -7,
   "y": 3,
   "z": 9,
   "name": "Rock_Basalt"
  },
  {
   "x": -7,
   "y": 4,
   "z": 9,
   "name": "Rock_Basalt"
  },
  {
   "x": -7,
   "y": 5,
   "z": 9,
   "name": "Rock_Basalt"
  },
  {
   "x": -7,
   "y": 6,
   "z": 9,
   "name": "Rock_Basalt"
  },
  {
   "x": -7,
   "y": 7,
   "z": 9,
   "name": "Rock_Basalt"
  },
  {
   "x": -7,
   "y": 8,
   "z": 9,
   "name": "Empty"
  },
  {
   "x": -7,
   "y": 9,
   "z": 9,
   "name": "Empty"
  },
  {
   "x": -7,
   "y": 10,
   "z": 9,
   "name": "Empty"
  },
  {
   "x": -7,
   "y": 11,
   "z": 9,
   "name": "Wood_Cedar_Trunk_Full"
  },
  {
   "x": -7,
   "y": 12,
   "z": 9,
   "name": "Rock_Basalt"
  },
  {
   "x": -7,
   "y": 13,
   "z": 9,
   "name": "Rock_Basalt"
  },
  {
   "x": -7,
   "y": 14,
   "z": 9,
   "name": "Rock_Basalt"
  },
  {
   "x": -7,
   "y": 15,
   "z": 9,
   "name": "Soil_Dirt"
  },
  {
   "x": -7,
   "y": 16,
   "z": 9,
   "name": "Soil_Needles"
  },
  {
   "x": -7,
   "y": 29,
   "z": 9,
   "name": "Wood_Cedar_Branch_Long",
   "rotation": 5
  },
  {
   "x": -7,
   "y": 31,
   "z": 9,
   "name": "Plant_Leaves_Cedar"
  },
  {
   "x": -7,
   "y": 34,
   "z": 9,
   "name": "Plant_Leaves_Cedar"
  },
  {
   "x": -7,
   "y": 37,
   "z": 9,
   "name": "Plant_Leaves_Cedar"
  },
  {
   "x": -7,
   "y": 40,
   "z": 9,
   "name": "Plant_Leaves_Cedar"
  },
  {
   "x": -7,
   "y": 41,
   "z": 9,
   "name": "Plant_Leaves_Cedar"
  },
  {
   "x": -7,
   "y": 42,
   "z": 9,
   "name": "Plant_Leaves_Cedar"
  },
  {
   "x": -7,
   "y": 45,
   "z": 9,
   "name": "Plant_Leaves_Cedar"
  },
  {
   "x": -7,
   "y": 4,
   "z": 10,
   "name": "Rock_Basalt"
  },
  {
   "x": -7,
   "y": 5,
   "z": 10,
   "name": "Rock_Basalt"
  },
  {
   "x": -7,
   "y": 6,
   "z": 10,
   "name": "Rock_Basalt"
  },
  {
   "x": -7,
   "y": 7,
   "z": 10,
   "name": "Rock_Basalt"
  },
  {
   "x": -7,
   "y": 8,
   "z": 10,
   "name": "Wood_Cedar_Trunk",
   "support": 15
  },
  {
   "x": -7,
   "y": 9,
   "z": 10,
   "name": "Wood_Cedar_Trunk",
   "support": 15
  },
  {
   "x": -7,
   "y": 10,
   "z": 10,
   "name": "Wood_Cedar_Trunk",
   "support": 15
  },
  {
   "x": -7,
   "y": 11,
   "z": 10,
   "name": "Rock_Basalt"
  },
  {
   "x": -7,
   "y": 12,
   "z": 10,
   "name": "Rock_Basalt"
  },
  {
   "x": -7,
   "y": 13,
   "z": 10,
   "name": "Rock_Basalt"
  },
  {
   "x": -7,
   "y": 14,
   "z": 10,
   "name": "Rock_Basalt"
  },
  {
   "x": -7,
   "y": 15,
   "z": 10,
   "name": "Soil_Dirt"
  },
  {
   "x": -7,
   "y": 16,
   "z": 10,
   "name": "Soil_Needles"
  },
  {
   "x": -7,
   "y": 41,
   "z": 10,
   "name": "Plant_Leaves_Cedar"
  },
  {
   "x": -7,
   "y": 6,
   "z": 11,
   "name": "Rock_Basalt"
  },
  {
   "x": -7,
   "y": 7,
   "z": 11,
   "name": "Rock_Basalt"
  },
  {
   "x": -7,
   "y": 8,
   "z": 11,
   "name": "Rock_Basalt"
  },
  {
   "x": -7,
   "y": 9,
   "z": 11,
   "name": "Rock_Basalt"
  },
  {
   "x": -7,
   "y": 10,
   "z": 11,
   "name": "Rock_Basalt"
  },
  {
   "x": -7,
   "y": 11,
   "z": 11,
   "name": "Rock_Basalt"
  },
  {
   "x": -7,
   "y": 12,
   "z": 11,
   "name": "Rock_Basalt"
  },
  {
   "x": -7,
   "y": 13,
   "z": 11,
   "name": "Rock_Basalt"
  },
  {
   "x": -7,
   "y": 14,
   "z": 11,
   "name": "Soil_Dirt"
  },
  {
   "x": -7,
   "y": 15,
   "z": 11,
   "name": "Soil_Dirt"
  },
  {
   "x": -7,
   "y": 16,
   "z": 11,
   "name": "Soil_Needles"
  },
  {
   "x": -7,
   "y": 32,
   "z": 11,
   "name": "Plant_Leaves_Cedar"
  },
  {
   "x": -7,
   "y": 37,
   "z": 11,
   "name": "Plant_Leaves_Cedar"
  },
  {
   "x": -7,
   "y": 9,
   "z": 12,
   "name": "Rock_Basalt"
  },
  {
   "x": -7,
   "y": 10,
   "z": 12,
   "name": "Rock_Basalt"
  },
  {
   "x": -7,
   "y": 11,
   "z": 12,
   "name": "Rock_Basalt"
  },
  {
   "x": -7,
   "y": 12,
   "z": 12,
   "name": "Rock_Basalt"
  },
  {
   "x": -7,
   "y": 13,
   "z": 12,
   "name": "Rock_Basalt"
  },
  {
   "x": -7,
   "y": 14,
   "z": 12,
   "name": "Soil_Dirt"
  },
  {
   "x": -7,
   "y": 15,
   "z": 12,
   "name": "Soil_Dirt"
  },
  {
   "x": -7,
   "y": 16,
   "z": 12,
   "name": "Soil_Grass"
  },
  {
   "x": -7,
   "y": 17,
   "z": 12,
   "name": "Plant_Grass_Winter"
  },
  {
   "x": -7,
   "y": 31,
   "z": 12,
   "name": "Plant_Leaves_Cedar"
  },
  {
   "x": -7,
   "y": 32,
   "z": 12,
   "name": "Plant_Leaves_Cedar"
  },
  {
   "x": -7,
   "y": 37,
   "z": 12,
   "name": "Plant_Leaves_Cedar"
  },
  {
   "x": -7,
   "y": 13,
   "z": 13,
   "name": "Rock_Basalt"
  },
  {
   "x": -7,
   "y": 14,
   "z": 13,
   "name": "Soil_Dirt"
  },
  {
   "x": -7,
   "y": 15,
   "z": 13,
   "name": "Soil_Dirt"
  },
  {
   "x": -7,
   "y": 16,
   "z": 13,
   "name": "Soil_Grass"
  },
  {
   "x": -7,
   "y": 31,
   "z": 13,
   "name": "Plant_Leaves_Cedar"
  },
  {
   "x": -7,
   "y": 16,
   "z": 14,
   "name": "Soil_Grass"
  },
  {
   "x": -6,
   "y": 11,
   "z": -12,
   "name": "Soil_Dirt"
  },
  {
   "x": -6,
   "y": 12,
   "z": -12,
   "name": "Soil_Grass"
  },
  {
   "x": -6,
   "y": 29,
   "z": -12,
   "name": "Plant_Leaves_Redwood"
  },
  {
   "x": -6,
   "y": 7,
   "z": -11,
   "name": "Rock_Basalt"
  },
  {
   "x": -6,
   "y": 8,
   "z": -11,
   "name": "Rock_Basalt"
  },
  {
   "x": -6,
   "y": 9,
   "z": -11,
   "name": "Rock_Basalt"
  },
  {
   "x": -6,
   "y": 10,
   "z": -11,
   "name": "Soil_Dirt"
  },
  {
   "x": -6,
   "y": 11,
   "z": -11,
   "name": "Soil_Dirt"
  },
  {
   "x": -6,
   "y": 12,
   "z": -11,
   "name": "Soil_Grass"
  },
  {
   "x": -6,
   "y": 28,
   "z": -11,
   "name": "Plant_Leaves_Redwood"
  },
  {
   "x": -6,
   "y": 5,
   "z": -10,
   "name": "Rock_Basalt"
  },
  {
   "x": -6,
   "y": 6,
   "z": -10,
   "name": "Rock_Basalt"
  },
  {
   "x": -6,
   "y": 7,
   "z": -10,
   "name": "Rock_Basalt"
  },
  {
   "x": -6,
   "y": 8,
   "z": -10,
   "name": "Rock_Basalt"
  },
  {
   "x": -6,
   "y": 9,
   "z": -10,
   "name": "Rock_Basalt"
  },
  {
   "x": -6,
   "y": 10,
   "z": -10,
   "name": "Soil_Dirt"
  },
  {
   "x": -6,
   "y": 11,
   "z": -10,
   "name": "Soil_Dirt"
  },
  {
   "x": -6,
   "y": 12,
   "z": -10,
   "name": "Soil_Grass"
  },
  {
   "x": -6,
   "y": 4,
   "z": -9,
   "name": "Rock_Basalt"
  },
  {
   "x": -6,
   "y": 5,
   "z": -9,
   "name": "Rock_Basalt"
  },
  {
   "x": -6,
   "y": 6,
   "z": -9,
   "name": "Rock_Basalt"
  },
  {
   "x": -6,
   "y": 7,
   "z": -9,
   "name": "Rock_Basalt"
  },
  {
   "x": -6,
   "y": 8,
   "z": -9,
   "name": "Rock_Basalt"
  },
  {
   "x": -6,
   "y": 9,
   "z": -9,
   "name": "Rock_Basalt"
  },
  {
   "x": -6,
   "y": 10,
   "z": -9,
   "name": "Rock_Basalt"
  },
  {
   "x": -6,
   "y": 11,
   "z": -9,
   "name": "Soil_Dirt"
  },
  {
   "x": -6,
   "y": 12,
   "z": -9,
   "name": "Soil_Dirt"
  },
  {
   "x": -6,
   "y": 13,
   "z": -9,
   "name": "Soil_Grass"
  },
  {
   "x": -6,
   "y": 3,
   "z": -8,
   "name": "Rock_Basalt"
  },
  {
   "x": -6,
   "y": 4,
   "z": -8,
   "name": "Rock_Basalt"
  },
  {
   "x": -6,
   "y": 5,
   "z": -8,
   "name": "Rock_Basalt"
  },
  {
   "x": -6,
   "y": 6,
   "z": -8,
   "name": "Rock_Basalt"
  },
  {
   "x": -6,
   "y": 7,
   "z": -8,
   "name": "Rock_Basalt"
  },
  {
   "x": -6,
   "y": 8,
   "z": -8,
   "name": "Rock_Basalt"
  },
  {
   "x": -6,
   "y": 9,
   "z": -8,
   "name": "Rock_Basalt"
  },
  {
   "x": -6,
   "y": 10,
   "z": -8,
   "name": "Rock_Basalt"
  },
  {
   "x": -6,
   "y": 11,
   "z": -8,
   "name": "Rock_Basalt"
  },
  {
   "x": -6,
   "y": 12,
   "z": -8,
   "name": "Soil_Dirt"
  },
  {
   "x": -6,
   "y": 13,
   "z": -8,
   "name": "Soil_Grass"
  },
  {
   "x": -6,
   "y": 14,
   "z": -8,
   "name": "Plant_Grass_Winter_Tall"
  },
  {
   "x": -6,
   "y": 15,
   "z": -8,
   "name": "Plant_Grass_Winter_Tall",
   "filler": 1024
  },
  {
   "x": -6,
   "y": 2,
   "z": -7,
   "name": "Rock_Basalt"
  },
  {
   "x": -6,
   "y": 3,
   "z": -7,
   "name": "Rock_Basalt"
  },
  {
   "x": -6,
   "y": 4,
   "z": -7,
   "name": "Rock_Basalt"
  },
  {
   "x": -6,
   "y": 5,
   "z": -7,
   "name": "Rock_Basalt"
  },
  {
   "x": -6,
   "y": 6,
   "z": -7,
   "name": "Rock_Basalt"
  },
  {
   "x": -6,
   "y": 7,
   "z": -7,
   "name": "Rock_Basalt"
  },
  {
   "x": -6,
   "y": 8,
   "z": -7,
   "name": "Rock_Basalt"
  },
  {
   "x": -6,
   "y": 9,
   "z": -7,
   "name": "Rock_Basalt"
  },
  {
   "x": -6,
   "y": 10,
   "z": -7,
   "name": "Rock_Basalt"
  },
  {
   "x": -6,
   "y": 11,
   "z": -7,
   "name": "Rock_Basalt"
  },
  {
   "x": -6,
   "y": 12,
   "z": -7,
   "name": "Rock_Basalt"
  },
  {
   "x": -6,
   "y": 13,
   "z": -7,
   "name": "Soil_Grass"
  },
  {
   "x": -6,
   "y": 2,
   "z": -6,
   "name": "Rock_Basalt"
  },
  {
   "x": -6,
   "y": 3,
   "z": -6,
   "name": "Rock_Basalt"
  },
  {
   "x": -6,
   "y": 4,
   "z": -6,
   "name": "Rock_Basalt"
  },
  {
   "x": -6,
   "y": 5,
   "z": -6,
   "name": "Rock_Basalt"
  },
  {
   "x": -6,
   "y": 6,
   "z": -6,
   "name": "Rock_Basalt"
  },
  {
   "x": -6,
   "y": 7,
   "z": -6,
   "name": "Rock_Basalt"
  },
  {
   "x": -6,
   "y": 8,
   "z": -6,
   "name": "Rock_Basalt"
  },
  {
   "x": -6,
   "y": 9,
   "z": -6,
   "name": "Rock_Basalt"
  },
  {
   "x": -6,
   "y": 10,
   "z": -6,
   "name": "Rock_Basalt"
  },
  {
   "x": -6,
   "y": 11,
   "z": -6,
   "name": "Rock_Basalt"
  },
  {
   "x": -6,
   "y": 12,
   "z": -6,
   "name": "Soil_Dirt"
  },
  {
   "x": -6,
   "y": 13,
   "z": -6,
   "name": "Soil_Grass"
  },
  {
   "x": -6,
   "y": 25,
   "z": -6,
   "name": "Plant_Leaves_Redwood"
  },
  {
   "x": -6,
   "y": 30,
   "z": -6,
   "name": "Plant_Leaves_Redwood"
  },
  {
   "x": -6,
   "y": 34,
   "z": -6,
   "name": "Plant_Leaves_Redwood"
  },
  {
   "x": -6,
   "y": 35,
   "z": -6,
   "name": "Plant_Leaves_Redwood"
  },
  {
   "x": -6,
   "y": 2,
   "z": -5,
   "name": "Rock_Basalt"
  },
  {
   "x": -6,
   "y": 3,
   "z": -5,
   "name": "Rock_Basalt"
  },
  {
   "x": -6,
   "y": 4,
   "z": -5,
   "name": "Rock_Basalt"
  },
  {
   "x": -6,
   "y": 5,
   "z": -5,
   "name": "Rock_Basalt"
  },
  {
   "x": -6,
   "y": 6,
   "z": -5,
   "name": "Rock_Basalt"
  },
  {
   "x": -6,
   "y": 7,
   "z": -5,
   "name": "Rock_Basalt"
  },
  {
   "x": -6,
   "y": 8,
   "z": -5,
   "name": "Rock_Basalt"
  },
  {
   "x": -6,
   "y": 9,
   "z": -5,
   "name": "Rock_Basalt"
  },
  {
   "x": -6,
   "y": 10,
   "z": -5,
   "name": "Rock_Basalt"
  },
  {
   "x": -6,
   "y": 11,
   "z": -5,
   "name": "Rock_Basalt"
  },
  {
   "x": -6,
   "y": 12,
   "z": -5,
   "name": "Soil_Dirt"
  },
  {
   "x": -6,
   "y": 13,
   "z": -5,
   "name": "Soil_Grass"
  },
  {
   "x": -6,
   "y": 25,
   "z": -5,
   "name": "Plant_Leaves_Redwood"
  },
  {
   "x": -6,
   "y": 30,
   "z": -5,
   "name": "Plant_Leaves_Redwood"
  },
  {
   "x": -6,
   "y": 3,
   "z": -4,
   "name": "Rock_Basalt"
  },
  {
   "x": -6,
   "y": 4,
   "z": -4,
   "name": "Rock_Basalt"
  },
  {
   "x": -6,
   "y": 5,
   "z": -4,
   "name": "Rock_Basalt"
  },
  {
   "x": -6,
   "y": 6,
   "z": -4,
   "name": "Rock_Basalt"
  },
  {
   "x": -6,
   "y": 7,
   "z": -4,
   "name": "Rock_Basalt"
  },
  {
   "x": -6,
   "y": 8,
   "z": -4,
   "name": "Rock_Basalt"
  },
  {
   "x": -6,
   "y": 9,
   "z": -4,
   "name": "Rock_Basalt"
  },
  {
   "x": -6,
   "y": 10,
   "z": -4,
   "name": "Rock_Basalt"
  },
  {
   "x": -6,
   "y": 11,
   "z": -4,
   "name": "Rock_Basalt"
  },
  {
   "x": -6,
   "y": 12,
   "z": -4,
   "name": "Soil_Dirt"
  },
  {
   "x": -6,
   "y": 13,
   "z": -4,
   "name": "Soil_Grass"
  },
  {
   "x": -6,
   "y": 14,
   "z": -4,
   "name": "Soil_Grass"
  },
  {
   "x": -6,
   "y": 3,
   "z": -3,
   "name": "Rock_Basalt"
  },
  {
   "x": -6,
   "y": 4,
   "z": -3,
   "name": "Rock_Basalt"
  },
  {
   "x": -6,
   "y": 5,
   "z": -3,
   "name": "Rock_Basalt"
  },
  {
   "x": -6,
   "y": 6,
   "z": -3,
   "name": "Rock_Basalt"
  },
  {
   "x": -6,
   "y": 7,
   "z": -3,
   "name": "Rock_Basalt"
  },
  {
   "x": -6,
   "y": 8,
   "z": -3,
   "name": "Rock_Basalt"
  },
  {
   "x": -6,
   "y": 9,
   "z": -3,
   "name": "Rock_Basalt"
  },
  {
   "x": -6,
   "y": 10,
   "z": -3,
   "name": "Rock_Basalt"
  },
  {
   "x": -6,
   "y": 11,
   "z": -3,
   "name": "Rock_Basalt"
  },
  {
   "x": -6,
   "y": 12,
   "z": -3,
   "name": "Soil_Dirt"
  },
  {
   "x": -6,
   "y": 13,
   "z": -3,
   "name": "Soil_Dirt"
  },
  {
   "x": -6,
   "y": 14,
   "z": -3,
   "name": "Soil_Grass"
  },
  {
   "x": -6,
   "y": 5,
   "z": -2,
   "name": "Rock_Basalt"
  },
  {
   "x": -6,
   "y": 6,
   "z": -2,
   "name": "Rock_Basalt"
  },
  {
   "x": -6,
   "y": 7,
   "z": -2,
   "name": "Rock_Basalt"
  },
  {
   "x": -6,
   "y": 8,
   "z": -2,
   "name": "Rock_Basalt"
  },
  {
   "x": -6,
   "y": 9,
   "z": -2,
   "name": "Rock_Basalt"
  },
  {
   "x": -6,
   "y": 10,
   "z": -2,
   "name": "Rock_Basalt"
  },
  {
   "x": -6,
   "y": 11,
   "z": -2,
   "name": "Rock_Basalt"
  },
  {
   "x": -6,
   "y": 12,
   "z": -2,
   "name": "Soil_Dirt"
  },
  {
   "x": -6,
   "y": 13,
   "z": -2,
   "name": "Soil_Dirt"
  },
  {
   "x": -6,
   "y": 14,
   "z": -2,
   "name": "Soil_Dirt"
  },
  {
   "x": -6,
   "y": 15,
   "z": -2,
   "name": "Soil_Grass"
  },
  {
   "x": -6,
   "y": 5,
   "z": -1,
   "name": "Rock_Basalt"
  },
  {
   "x": -6,
   "y": 6,
   "z": -1,
   "name": "Rock_Basalt"
  },
  {
   "x": -6,
   "y": 7,
   "z": -1,
   "name": "Rock_Basalt"
  },
  {
   "x": -6,
   "y": 8,
   "z": -1,
   "name": "Rock_Basalt"
  },
  {
   "x": -6,
   "y": 9,
   "z": -1,
   "name": "Rock_Basalt"
  },
  {
   "x": -6,
   "y": 10,
   "z": -1,
   "name": "Rock_Basalt"
  },
  {
   "x": -6,
   "y": 11,
   "z": -1,
   "name": "Rock_Basalt"
  },
  {
   "x": -6,
   "y": 12,
   "z": -1,
   "name": "Rock_Basalt"
  },
  {
   "x": -6,
   "y": 13,
   "z": -1,
   "name": "Soil_Dirt"
  },
  {
   "x": -6,
   "y": 14,
   "z": -1,
   "name": "Soil_Dirt"
  },
  {
   "x": -6,
   "y": 15,
   "z": -1,
   "name": "Soil_Grass"
  },
  {
   "x": -6,
   "y": 4,
   "z": 0,
   "name": "Rock_Basalt"
  },
  {
   "x": -6,
   "y": 5,
   "z": 0,
   "name": "Rock_Basalt"
  },
  {
   "x": -6,
   "y": 6,
   "z": 0,
   "name": "Rock_Basalt"
  },
  {
   "x": -6,
   "y": 7,
   "z": 0,
   "name": "Rock_Basalt"
  },
  {
   "x": -6,
   "y": 8,
   "z": 0,
   "name": "Rock_Basalt"
  },
  {
   "x": -6,
   "y": 9,
   "z": 0,
   "name": "Rock_Basalt"
  },
  {
   "x": -6,
   "y": 10,
   "z": 0,
   "name": "Rock_Basalt"
  },
  {
   "x": -6,
   "y": 11,
   "z": 0,
   "name": "Rock_Basalt"
  },
  {
   "x": -6,
   "y": 12,
   "z": 0,
   "name": "Rock_Basalt"
  },
  {
   "x": -6,
   "y": 13,
   "z": 0,
   "name": "Soil_Dirt"
  },
  {
   "x": -6,
   "y": 14,
   "z": 0,
   "name": "Soil_Dirt"
  },
  {
   "x": -6,
   "y": 15,
   "z": 0,
   "name": "Soil_Grass"
  },
  {
   "x": -6,
   "y": 3,
   "z": 1,
   "name": "Rock_Basalt"
  },
  {
   "x": -6,
   "y": 4,
   "z": 1,
   "name": "Rock_Basalt"
  },
  {
   "x": -6,
   "y": 5,
   "z": 1,
   "name": "Rock_Basalt"
  },
  {
   "x": -6,
   "y": 6,
   "z": 1,
   "name": "Rock_Basalt"
  },
  {
   "x": -6,
   "y": 7,
   "z": 1,
   "name": "Rock_Basalt"
  },
  {
   "x": -6,
   "y": 8,
   "z": 1,
   "name": "Rock_Basalt"
  },
  {
   "x": -6,
   "y": 9,
   "z": 1,
   "name": "Rock_Basalt"
  },
  {
   "x": -6,
   "y": 10,
   "z": 1,
   "name": "Rock_Basalt"
  },
  {
   "x": -6,
   "y": 11,
   "z": 1,
   "name": "Rock_Basalt"
  },
  {
   "x": -6,
   "y": 12,
   "z": 1,
   "name": "Rock_Basalt"
  },
  {
   "x": -6,
   "y": 13,
   "z": 1,
   "name": "Soil_Dirt"
  },
  {
   "x": -6,
   "y": 14,
   "z": 1,
   "name": "Soil_Dirt"
  },
  {
   "x": -6,
   "y": 15,
   "z": 1,
   "name": "Soil_Grass"
  },
  {
   "x": -6,
   "y": 16,
   "z": 1,
   "name": "Plant_Grass_Winter"
  },
  {
   "x": -6,
   "y": 2,
   "z": 2,
   "name": "Rock_Basalt"
  },
  {
   "x": -6,
   "y": 3,
   "z": 2,
   "name": "Rock_Basalt"
  },
  {
   "x": -6,
   "y": 4,
   "z": 2,
   "name": "Rock_Basalt"
  },
  {
   "x": -6,
   "y": 5,
   "z": 2,
   "name": "Rock_Basalt"
  },
  {
   "x": -6,
   "y": 6,
   "z": 2,
   "name": "Rock_Basalt"
  },
  {
   "x": -6,
   "y": 7,
   "z": 2,
   "name": "Rock_Basalt"
  },
  {
   "x": -6,
   "y": 8,
   "z": 2,
   "name": "Rock_Basalt"
  },
  {
   "x": -6,
   "y": 9,
   "z": 2,
   "name": "Rock_Basalt"
  },
  {
   "x": -6,
   "y": 10,
   "z": 2,
   "name": "Rock_Basalt"
  },
  {
   "x": -6,
   "y": 11,
   "z": 2,
   "name": "Rock_Basalt"
  },
  {
   "x": -6,
   "y": 12,
   "z": 2,
   "name": "Rock_Basalt"
  },
  {
   "x": -6,
   "y": 13,
   "z": 2,
   "name": "Rock_Basalt"
  },
  {
   "x": -6,
   "y": 14,
   "z": 2,
   "name": "Soil_Dirt"
  },
  {
   "x": -6,
   "y": 15,
   "z": 2,
   "name": "Soil_Grass"
  },
  {
   "x": -6,
   "y": 16,
   "z": 2,
   "name": "Plant_Grass_Winter"
  },
  {
   "x": -6,
   "y": 2,
   "z": 3,
   "name": "Rock_Basalt"
  },
  {
   "x": -6,
   "y": 3,
   "z": 3,
   "name": "Rock_Basalt"
  },
  {
   "x": -6,
   "y": 4,
   "z": 3,
   "name": "Rock_Basalt"
  },
  {
   "x": -6,
   "y": 5,
   "z": 3,
   "name": "Rock_Basalt"
  },
  {
   "x": -6,
   "y": 6,
   "z": 3,
   "name": "Rock_Basalt"
  },
  {
   "x": -6,
   "y": 7,
   "z": 3,
   "name": "Rock_Basalt"
  },
  {
   "x": -6,
   "y": 8,
   "z": 3,
   "name": "Rock_Basalt"
  },
  {
   "x": -6,
   "y": 9,
   "z": 3,
   "name": "Rock_Basalt"
  },
  {
   "x": -6,
   "y": 10,
   "z": 3,
   "name": "Rock_Basalt"
  },
  {
   "x": -6,
   "y": 11,
   "z": 3,
   "name": "Rock_Basalt"
  },
  {
   "x": -6,
   "y": 12,
   "z": 3,
   "name": "Rock_Basalt"
  },
  {
   "x": -6,
   "y": 13,
   "z": 3,
   "name": "Rock_Basalt"
  },
  {
   "x": -6,
   "y": 14,
   "z": 3,
   "name": "Rock_Basalt"
  },
  {
   "x": -6,
   "y": 15,
   "z": 3,
   "name": "Soil_Grass"
  },
  {
   "x": -6,
   "y": 16,
   "z": 3,
   "name": "Plant_Grass_Winter_Tall"
  },
  {
   "x": -6,
   "y": 17,
   "z": 3,
   "name": "Plant_Grass_Winter_Tall",
   "filler": 1024
  },
  {
   "x": -6,
   "y": 32,
   "z": 3,
   "name": "Plant_Leaves_Cedar"
  },
  {
   "x": -6,
   "y": 35,
   "z": 3,
   "name": "Plant_Leaves_Cedar"
  },
  {
   "x": -6,
   "y": 1,
   "z": 4,
   "name": "Rock_Basalt"
  },
  {
   "x": -6,
   "y": 2,
   "z": 4,
   "name": "Rock_Basalt"
  },
  {
   "x": -6,
   "y": 3,
   "z": 4,
   "name": "Rock_Basalt"
  },
  {
   "x": -6,
   "y": 4,
   "z": 4,
   "name": "Rock_Basalt"
  },
  {
   "x": -6,
   "y": 5,
   "z": 4,
   "name": "Rock_Basalt"
  },
  {
   "x": -6,
   "y": 6,
   "z": 4,
   "name": "Rock_Basalt"
  },
  {
   "x": -6,
   "y": 7,
   "z": 4,
   "name": "Rock_Basalt"
  },
  {
   "x": -6,
   "y": 8,
   "z": 4,
   "name": "Empty"
  },
  {
   "x": -6,
   "y": 9,
   "z": 4,
   "name": "Empty"
  },
  {
   "x": -6,
   "y": 10,
   "z": 4,
   "name": "Rock_Basalt"
  },
  {
   "x": -6,
   "y": 11,
   "z": 4,
   "name": "Rock_Basalt"
  },
  {
   "x": -6,
   "y": 12,
   "z": 4,
   "name": "Rock_Basalt"
  },
  {
   "x": -6,
   "y": 13,
   "z": 4,
   "name": "Rock_Basalt"
  },
  {
   "x": -6,
   "y": 14,
   "z": 4,
   "name": "Soil_Dirt"
  },
  {
   "x": -6,
   "y": 15,
   "z": 4,
   "name": "Soil_Dirt"
  },
  {
   "x": -6,
   "y": 16,
   "z": 4,
   "name": "Soil_Grass"
  },
  {
   "x": -6,
   "y": 17,
   "z": 4,
   "name": "Plant_Grass_Winter_Tall"
  },
  {
   "x": -6,
   "y": 18,
   "z": 4,
   "name": "Plant_Grass_Winter_Tall",
   "filler": 1024
  },
  {
   "x": -6,
   "y": 35,
   "z": 4,
   "name": "Plant_Leaves_Cedar"
  },
  {
   "x": -6,
   "y": 36,
   "z": 4,
   "name": "Plant_Leaves_Cedar"
  },
  {
   "x": -6,
   "y": 38,
   "z": 4,
   "name": "Plant_Leaves_Cedar"
  },
  {
   "x": -6,
   "y": 1,
   "z": 5,
   "name": "Rock_Basalt"
  },
  {
   "x": -6,
   "y": 2,
   "z": 5,
   "name": "Rock_Basalt"
  },
  {
   "x": -6,
   "y": 3,
   "z": 5,
   "name": "Rock_Basalt"
  },
  {
   "x": -6,
   "y": 4,
   "z": 5,
   "name": "Rock_Basalt"
  },
  {
   "x": -6,
   "y": 5,
   "z": 5,
   "name": "Rock_Basalt"
  },
  {
   "x": -6,
   "y": 6,
   "z": 5,
   "name": "Rock_Basalt"
  },
  {
   "x": -6,
   "y": 7,
   "z": 5,
   "name": "Rock_Basalt"
  },
  {
   "x": -6,
   "y": 8,
   "z": 5,
   "name": "Empty"
  },
  {
   "x": -6,
   "y": 9,
   "z": 5,
   "name": "Empty"
  },
  {
   "x": -6,
   "y": 10,
   "z": 5,
   "name": "Empty"
  },
  {
   "x": -6,
   "y": 11,
   "z": 5,
   "name": "Wood_Cedar_Trunk_Full"
  },
  {
   "x": -6,
   "y": 12,
   "z": 5,
   "name": "Wood_Cedar_Trunk",
   "support": 15
  },
  {
   "x": -6,
   "y": 13,
   "z": 5,
   "name": "Wood_Cedar_Trunk",
   "support": 15
  },
  {
   "x": -6,
   "y": 14,
   "z": 5,
   "name": "Soil_Dirt"
  },
  {
   "x": -6,
   "y": 15,
   "z": 5,
   "name": "Soil_Dirt"
  },
  {
   "x": -6,
   "y": 16,
   "z": 5,
   "name": "Soil_Grass"
  },
  {
   "x": -6,
   "y": 17,
   "z": 5,
   "name": "Plant_Grass_Winter_Tall"
  },
  {
   "x": -6,
   "y": 18,
   "z": 5,
   "name": "Plant_Grass_Winter_Tall",
   "filler": 1024
  },
  {
   "x": -6,
   "y": 32,
   "z": 5,
   "name": "Plant_Leaves_Cedar"
  },
  {
   "x": -6,
   "y": 36,
   "z": 5,
   "name": "Plant_Leaves_Cedar"
  },
  {
   "x": -6,
   "y": 38,
   "z": 5,
   "name": "Plant_Leaves_Cedar"
  },
  {
   "x": -6,
   "y": 43,
   "z": 5,
   "name": "Plant_Leaves_Cedar"
  },
  {
   "x": -6,
   "y": 1,
   "z": 6,
   "name": "Rock_Basalt"
  },
  {
   "x": -6,
   "y": 2,
   "z": 6,
   "name": "Rock_Basalt"
  },
  {
   "x": -6,
   "y": 3,
   "z": 6,
   "name": "Rock_Basalt"
  },
  {
   "x": -6,
   "y": 4,
   "z": 6,
   "name": "Rock_Basalt"
  },
  {
   "x": -6,
   "y": 5,
   "z": 6,
   "name": "Rock_Basalt"
  },
  {
   "x": -6,
   "y": 6,
   "z": 6,
   "name": "Rock_Basalt"
  },
  {
   "x": -6,
   "y": 7,
   "z": 6,
   "name": "Rock_Basalt"
  },
  {
   "x": -6,
   "y": 8,
   "z": 6,
   "name": "Empty"
  },
  {
   "x": -6,
   "y": 9,
   "z": 6,
   "name": "Empty"
  },
  {
   "x": -6,
   "y": 10,
   "z": 6,
   "name": "Empty"
  },
  {
   "x": -6,
   "y": 11,
   "z": 6,
   "name": "Empty"
  },
  {
   "x": -6,
   "y": 12,
   "z": 6,
   "name": "Rock_Basalt"
  },
  {
   "x": -6,
   "y": 13,
   "z": 6,
   "name": "Rock_Basalt"
  },
  {
   "x": -6,
   "y": 14,
   "z": 6,
   "name": "Soil_Dirt"
  },
  {
   "x": -6,
   "y": 15,
   "z": 6,
   "name": "Soil_Dirt"
  },
  {
   "x": -6,
   "y": 16,
   "z": 6,
   "name": "Soil_Grass"
  },
  {
   "x": -6,
   "y": 32,
   "z": 6,
   "name": "Plant_Leaves_Cedar"
  },
  {
   "x": -6,
   "y": 33,
   "z": 6,
   "name": "Plant_Leaves_Cedar"
  },
  {
   "x": -6,
   "y": 40,
   "z": 6,
   "name": "Plant_Leaves_Cedar"
  },
  {
   "x": -6,
   "y": 43,
   "z": 6,
   "name": "Plant_Leaves_Cedar"
  },
  {
   "x": -6,
   "y": 44,
   "z": 6,
   "name": "Plant_Leaves_Cedar"
  },
  {
   "x": -6,
   "y": 1,
   "z": 7,
   "name": "Rock_Basalt"
  },
  {
   "x": -6,
   "y": 2,
   "z": 7,
   "name": "Rock_Basalt"
  },
  {
   "x": -6,
   "y": 3,
   "z": 7,
   "name": "Rock_Basalt"
  },
  {
   "x": -6,
   "y": 4,
   "z": 7,
   "name": "Rock_Basalt"
  },
  {
   "x": -6,
   "y": 5,
   "z": 7,
   "name": "Rock_Basalt"
  },
  {
   "x": -6,
   "y": 6,
   "z": 7,
   "name": "Rock_Basalt"
  },
  {
   "x": -6,
   "y": 7,
   "z": 7,
   "name": "Rock_Basalt"
  },
  {
   "x": -6,
   "y": 8,
   "z": 7,
   "name": "Empty"
  },
  {
   "x": -6,
   "y": 9,
   "z": 7,
   "name": "Empty"
  },
  {
   "x": -6,
   "y": 10,
   "z": 7,
   "name": "Empty"
  },
  {
   "x": -6,
   "y": 11,
   "z": 7,
   "name": "Empty"
  },
  {
   "x": -6,
   "y": 12,
   "z": 7,
   "name": "Rock_Basalt"
  },
  {
   "x": -6,
   "y": 13,
   "z": 7,
   "name": "Rock_Basalt"
  },
  {
   "x": -6,
   "y": 14,
   "z": 7,
   "name": "Soil_Dirt"
  },
  {
   "x": -6,
   "y": 15,
   "z": 7,
   "name": "Soil_Dirt"
  },
  {
   "x": -6,
   "y": 16,
   "z": 7,
   "name": "Soil_Needles"
  },
  {
   "x": -6,
   "y": 17,
   "z": 7,
   "name": "Plant_Grass_Winter"
  },
  {
   "x": -6,
   "y": 32,
   "z": 7,
   "name": "Wood_Cedar_Branch_Long",
   "rotation": 5
  },
  {
   "x": -6,
   "y": 33,
   "z": 7,
   "name": "Plant_Leaves_Cedar"
  },
  {
   "x": -6,
   "y": 37,
   "z": 7,
   "name": "Plant_Leaves_Cedar"
  },
  {
   "x": -6,
   "y": 40,
   "z": 7,
   "name": "Plant_Leaves_Cedar"
  },
  {
   "x": -6,
   "y": 42,
   "z": 7,
   "name": "Plant_Leaves_Cedar"
  },
  {
   "x": -6,
   "y": 44,
   "z": 7,
   "name": "Plant_Leaves_Cedar"
  },
  {
   "x": -6,
   "y": 47,
   "z": 7,
   "name": "Plant_Leaves_Cedar"
  },
  {
   "x": -6,
   "y": 1,
   "z": 8,
   "name": "Rock_Basalt"
  },
  {
   "x": -6,
   "y": 2,
   "z": 8,
   "name": "Rock_Basalt"
  },
  {
   "x": -6,
   "y": 3,
   "z": 8,
   "name": "Rock_Basalt"
  },
  {
   "x": -6,
   "y": 4,
   "z": 8,
   "name": "Rock_Basalt"
  },
  {
   "x": -6,
   "y": 5,
   "z": 8,
   "name": "Rock_Basalt"
  },
  {
   "x": -6,
   "y": 6,
   "z": 8,
   "name": "Rock_Basalt"
  },
  {
   "x": -6,
   "y": 7,
   "z": 8,
   "name": "Rock_Basalt"
  },
  {
   "x": -6,
   "y": 8,
   "z": 8,
   "name": "Empty"
  },
  {
   "x": -6,
   "y": 9,
   "z": 8,
   "name": "Empty"
  },
  {
   "x": -6,
   "y": 10,
   "z": 8,
   "name": "Empty"
  },
  {
   "x": -6,
   "y": 11,
   "z": 8,
   "name": "Empty"
  },
  {
   "x": -6,
   "y": 12,
   "z": 8,
   "name": "Rock_Basalt"
  },
  {
   "x": -6,
   "y": 13,
   "z": 8,
   "name": "Rock_Basalt"
  },
  {
   "x": -6,
   "y": 14,
   "z": 8,
   "name": "Soil_Dirt"
  },
  {
   "x": -6,
   "y": 15,
   "z": 8,
   "name": "Soil_Dirt"
  },
  {
   "x": -6,
   "y": 16,
   "z": 8,
   "name": "Soil_Needles"
  },
  {
   "x": -6,
   "y": 31,
   "z": 8,
   "name": "Wood_Cedar_Branch_Long",
   "rotation": 5
  },
  {
   "x": -6,
   "y": 32,
   "z": 8,
   "name": "Plant_Leaves_Cedar"
  },
  {
   "x": -6,
   "y": 34,
   "z": 8,
   "name": "Wood_Cedar_Branch_Long",
   "rotation": 5
  },
  {
   "x": -6,
   "y": 37,
   "z": 8,
   "name": "Wood_Cedar_Branch_Long",
   "rotation": 5
  },
  {
   "x": -6,
   "y": 38,
   "z": 8,
   "name": "Plant_Leaves_Cedar"
  },
  {
   "x": -6,
   "y": 40,
   "z": 8,
   "name": "Wood_Cedar_Branch_Long",
   "rotation": 5
  },
  {
   "x": -6,
   "y": 42,
   "z": 8,
   "name": "Wood_Cedar_Branch_Long",
   "rotation": 5
  },
  {
   "x": -6,
   "y": 45,
   "z": 8,
   "name": "Plant_Leaves_Cedar"
  },
  {
   "x": -6,
   "y": 47,
   "z": 8,
   "name": "Plant_Leaves_Cedar"
  },
  {
   "x": -6,
   "y": 48,
   "z": 8,
   "name": "Plant_Leaves_Cedar"
  },
  {
   "x": -6,
   "y": 1,
   "z": 9,
   "name": "Rock_Basalt"
  },
  {
   "x": -6,
   "y": 2,
   "z": 9,
   "name": "Rock_Basalt"
  },
  {
   "x": -6,
   "y": 3,
   "z": 9,
   "name": "Rock_Basalt"
  },
  {
   "x": -6,
   "y": 4,
   "z": 9,
   "name": "Rock_Basalt"
  },
  {
   "x": -6,
   "y": 5,
   "z": 9,
   "name": "Rock_Basalt"
  },
  {
   "x": -6,
   "y": 6,
   "z": 9,
   "name": "Rock_Basalt"
  },
  {
   "x": -6,
   "y": 7,
   "z": 9,
   "name": "Rock_Basalt"
  },
  {
   "x": -6,
   "y": 8,
   "z": 9,
   "name": "Empty"
  },
  {
   "x": -6,
   "y": 9,
   "z": 9,
   "name": "Empty"
  },
  {
   "x": -6,
   "y": 10,
   "z": 9,
   "name": "Empty"
  },
  {
   "x": -6,
   "y": 11,
   "z": 9,
   "name": "Wood_Cedar_Roots"
  },
  {
   "x": -6,
   "y": 12,
   "z": 9,
   "name": "Wood_Cedar_Trunk_Full"
  },
  {
   "x": -6,
   "y": 13,
   "z": 9,
   "name": "Wood_Cedar_Trunk",
   "support": 15
  },
  {
   "x": -6,
   "y": 14,
   "z": 9,
   "name": "Wood_Cedar_Trunk",
   "support": 15
  },
  {
   "x": -6,
   "y": 15,
   "z": 9,
   "name": "Soil_Dirt"
  },
  {
   "x": -6,
   "y": 16,
   "z": 9,
   "name": "Soil_Needles"
  },
  {
   "x": -6,
   "y": 29,
   "z": 9,
   "name": "Wood_Cedar_Branch_Long",
   "rotation": 5
  },
  {
   "x": -6,
   "y": 34,
   "z": 9,
   "name": "Plant_Leaves_Cedar"
  },
  {
   "x": -6,
   "y": 37,
   "z": 9,
   "name": "Plant_Leaves_Cedar"
  },
  {
   "x": -6,
   "y": 40,
   "z": 9,
   "name": "Plant_Leaves_Cedar"
  },
  {
   "x": -6,
   "y": 42,
   "z": 9,
   "name": "Plant_Leaves_Cedar"
  },
  {
   "x": -6,
   "y": 45,
   "z": 9,
   "name": "Plant_Leaves_Cedar"
  },
  {
   "x": -6,
   "y": 47,
   "z": 9,
   "name": "Plant_Leaves_Cedar"
  },
  {
   "x": -6,
   "y": 3,
   "z": 10,
   "name": "Rock_Basalt"
  },
  {
   "x": -6,
   "y": 4,
   "z": 10,
   "name": "Rock_Basalt"
  },
  {
   "x": -6,
   "y": 5,
   "z": 10,
   "name": "Rock_Basalt"
  },
  {
   "x": -6,
   "y": 6,
   "z": 10,
   "name": "Rock_Basalt"
  },
  {
   "x": -6,
   "y": 7,
   "z": 10,
   "name": "Wood_Cedar_Trunk_Full",
   "rotation": 5
  },
  {
   "x": -6,
   "y": 8,
   "z": 10,
   "name": "Empty"
  },
  {
   "x": -6,
   "y": 9,
   "z": 10,
   "name": "Empty"
  },
  {
   "x": -6,
   "y": 10,
   "z": 10,
   "name": "Wood_Cedar_Trunk_Full"
  },
  {
   "x": -6,
   "y": 11,
   "z": 10,
   "name": "Wood_Cedar_Trunk",
   "support": 15
  },
  {
   "x": -6,
   "y": 12,
   "z": 10,
   "name": "Wood_Cedar_Trunk",
   "support": 15
  },
  {
   "x": -6,
   "y": 13,
   "z": 10,
   "name": "Rock_Basalt"
  },
  {
   "x": -6,
   "y": 14,
   "z": 10,
   "name": "Rock_Basalt"
  },
  {
   "x": -6,
   "y": 15,
   "z": 10,
   "name": "Soil_Dirt"
  },
  {
   "x": -6,
   "y": 16,
   "z": 10,
   "name": "Soil_Needles"
  },
  {
   "x": -6,
   "y": 38,
   "z": 10,
   "name": "Plant_Leaves_Cedar"
  },
  {
   "x": -6,
   "y": 41,
   "z": 10,
   "name": "Plant_Leaves_Cedar"
  },
  {
   "x": -6,
   "y": 5,
   "z": 11,
   "name": "Rock_Basalt"
  },
  {
   "x": -6,
   "y": 6,
   "z": 11,
   "name": "Rock_Basalt"
  },
  {
   "x": -6,
   "y": 7,
   "z": 11,
   "name": "Rock_Basalt"
  },
  {
   "x": -6,
   "y": 8,
   "z": 11,
   "name": "Rock_Basalt"
  },
  {
   "x": -6,
   "y": 9,
   "z": 11,
   "name": "Rock_Basalt"
  },
  {
   "x": -6,
   "y": 10,
   "z": 11,
   "name": "Rock_Basalt"
  },
  {
   "x": -6,
   "y": 11,
   "z": 11,
   "name": "Rock_Basalt"
  },
  {
   "x": -6,
   "y": 12,
   "z": 11,
   "name": "Rock_Basalt"
  },
  {
   "x": -6,
   "y": 13,
   "z": 11,
   "name": "Rock_Basalt"
  },
  {
   "x": -6,
   "y": 14,
   "z": 11,
   "name": "Rock_Basalt"
  },
  {
   "x": -6,
   "y": 15,
   "z": 11,
   "name": "Soil_Dirt"
  },
  {
   "x": -6,
   "y": 16,
   "z": 11,
   "name": "Soil_Needles"
  },
  {
   "x": -6,
   "y": 17,
   "z": 11,
   "name": "Plant_Grass_Winter_Short"
  },
  {
   "x": -6,
   "y": 32,
   "z": 11,
   "name": "Plant_Leaves_Cedar"
  },
  {
   "x": -6,
   "y": 33,
   "z": 11,
   "name": "Plant_Leaves_Cedar"
  },
  {
   "x": -6,
   "y": 37,
   "z": 11,
   "name": "Plant_Leaves_Cedar"
  },
  {
   "x": -6,
   "y": 38,
   "z": 11,
   "name": "Plant_Leaves_Cedar"
  },
  {
   "x": -6,
   "y": 8,
   "z": 12,
   "name": "Rock_Basalt"
  },
  {
   "x": -6,
   "y": 9,
   "z": 12,
   "name": "Rock_Basalt"
  },
  {
   "x": -6,
   "y": 10,
   "z": 12,
   "name": "Rock_Basalt"
  },
  {
   "x": -6,
   "y": 11,
   "z": 12,
   "name": "Rock_Basalt"
  },
  {
   "x": -6,
   "y": 12,
   "z": 12,
   "name": "Rock_Basalt"
  },
  {
   "x": -6,
   "y": 13,
   "z": 12,
   "name": "Rock_Basalt"
  },
  {
   "x": -6,
   "y": 14,
   "z": 12,
   "name": "Soil_Dirt"
  },
  {
   "x": -6,
   "y": 15,
   "z": 12,
   "name": "Soil_Dirt"
  },
  {
   "x": -6,
   "y": 16,
   "z": 12,
   "name": "Soil_Grass"
  },
  {
   "x": -6,
   "y": 17,
   "z": 12,
   "name": "Plant_Grass_Winter_Tall"
  },
  {
   "x": -6,
   "y": 18,
   "z": 12,
   "name": "Plant_Grass_Winter_Tall",
   "filler": 1024
  },
  {
   "x": -6,
   "y": 32,
   "z": 12,
   "name": "Plant_Leaves_Cedar"
  },
  {
   "x": -6,
   "y": 33,
   "z": 12,
   "name": "Plant_Leaves_Cedar"
  },
  {
   "x": -6,
   "y": 37,
   "z": 12,
   "name": "Plant_Leaves_Cedar"
  },
  {
   "x": -6,
   "y": 11,
   "z": 13,
   "name": "Rock_Basalt"
  },
  {
   "x": -6,
   "y": 12,
   "z": 13,
   "name": "Rock_Basalt"
  },
  {
   "x": -6,
   "y": 13,
   "z": 13,
   "name": "Rock_Basalt"
  },
  {
   "x": -6,
   "y": 14,
   "z": 13,
   "name": "Soil_Dirt"
  },
  {
   "x": -6,
   "y": 15,
   "z": 13,
   "name": "Soil_Dirt"
  },
  {
   "x": -6,
   "y": 16,
   "z": 13,
   "name": "Soil_Grass"
  },
  {
   "x": -6,
   "y": 17,
   "z": 13,
   "name": "KweebecNightmare_Moonbloom_Plant"
  },
  {
   "x": -6,
   "y": 15,
   "z": 14,
   "name": "Soil_Dirt"
  },
  {
   "x": -6,
   "y": 16,
   "z": 14,
   "name": "Soil_Grass"
  },
  {
   "x": -6,
   "y": 32,
   "z": 14,
   "name": "Plant_Leaves_Cedar"
  },
  {
   "x": -6,
   "y": 31,
   "z": 15,
   "name": "Plant_Leaves_Cedar"
  },
  {
   "x": -6,
   "y": 31,
   "z": 16,
   "name": "Plant_Leaves_Cedar"
  },
  {
   "x": -5,
   "y": 9,
   "z": -12,
   "name": "Rock_Basalt"
  },
  {
   "x": -5,
   "y": 10,
   "z": -12,
   "name": "Soil_Dirt"
  },
  {
   "x": -5,
   "y": 11,
   "z": -12,
   "name": "Soil_Dirt"
  },
  {
   "x": -5,
   "y": 12,
   "z": -12,
   "name": "Soil_Grass"
  },
  {
   "x": -5,
   "y": 28,
   "z": -12,
   "name": "Plant_Leaves_Redwood"
  },
  {
   "x": -5,
   "y": 4,
   "z": -11,
   "name": "Rock_Basalt"
  },
  {
   "x": -5,
   "y": 5,
   "z": -11,
   "name": "Rock_Basalt"
  },
  {
   "x": -5,
   "y": 6,
   "z": -11,
   "name": "Rock_Basalt"
  },
  {
   "x": -5,
   "y": 7,
   "z": -11,
   "name": "Rock_Basalt"
  },
  {
   "x": -5,
   "y": 8,
   "z": -11,
   "name": "Rock_Basalt"
  },
  {
   "x": -5,
   "y": 9,
   "z": -11,
   "name": "Rock_Basalt"
  },
  {
   "x": -5,
   "y": 10,
   "z": -11,
   "name": "Soil_Dirt"
  },
  {
   "x": -5,
   "y": 11,
   "z": -11,
   "name": "Soil_Dirt"
  },
  {
   "x": -5,
   "y": 12,
   "z": -11,
   "name": "Soil_Grass"
  },
  {
   "x": -5,
   "y": 28,
   "z": -11,
   "name": "Plant_Leaves_Redwood"
  },
  {
   "x": -5,
   "y": 3,
   "z": -10,
   "name": "Rock_Basalt"
  },
  {
   "x": -5,
   "y": 4,
   "z": -10,
   "name": "Rock_Basalt"
  },
  {
   "x": -5,
   "y": 5,
   "z": -10,
   "name": "Rock_Basalt"
  },
  {
   "x": -5,
   "y": 6,
   "z": -10,
   "name": "Rock_Basalt"
  },
  {
   "x": -5,
   "y": 7,
   "z": -10,
   "name": "Rock_Basalt"
  },
  {
   "x": -5,
   "y": 8,
   "z": -10,
   "name": "Rock_Basalt"
  },
  {
   "x": -5,
   "y": 9,
   "z": -10,
   "name": "Rock_Basalt"
  },
  {
   "x": -5,
   "y": 10,
   "z": -10,
   "name": "Soil_Dirt"
  },
  {
   "x": -5,
   "y": 11,
   "z": -10,
   "name": "Soil_Dirt"
  },
  {
   "x": -5,
   "y": 12,
   "z": -10,
