{
  "version": 8,
  "blockIdVersion": 11,
  "anchorX": -2,
  "anchorY": 10,
  "anchorZ": 1,
  "blocks": [
    {"x": -6, "y": 8, "z": -1, "name": "Soil_Dirt_Poisoned"},
    {"x": -6, "y": 9, "z": -1, "name": "Soil_Dirt_Burnt"},
    {"x": -6, "y": 10, "z": -1, "name": "Soil_Grass_Burnt"},
    {"x": -6, "y": 6, "z": 0, "name": "Soil_Dirt_Burnt"},
    {"x": -6, "y": 7, "z": 0, "name": "Soil_Dirt_Poisoned"},
    {"x": -6, "y": 8, "z": 0, "name": "Soil_Dirt_Burnt"},
    {"x": -6, "y": 9, "z": 0, "name": "Soil_Dirt_Poisoned"},
    {"x": -6, "y": 10, "z": 0, "name": "Soil_Grass_Dry"},
    {"x": -5, "y": 5, "z": -1, "name": "Soil_Dirt_Poisoned"},
    {"x": -5, "y": 6, "z": -1, "name": "Soil_Dirt_Burnt"},
    {"x": -5, "y": 7, "z": -1, "name": "Soil_Dirt_Poisoned"},
    {"x": -5, "y": 8, "z": -1, "name": "Soil_Dirt_Burnt"},
    {"x": -5, "y": 9, "z": -1, "name": "Soil_Dirt_Poisoned"},
    {"x": -5, "y": 10, "z": -1, "name": "Soil_Grass_Dry"},
    {"x": -5, "y": 11, "z": -1, "name": "Plant_Grass_Sharp"},
    {"x": -5, "y": 16, "z": -1, "name": "Wood_Hardwood_Planks_Half", "rotation": 8},
    {"x": -5, "y": 5, "z": 0, "name": "Soil_Dirt_Burnt"},
    {"x": -5, "y": 6, "z": 0, "name": "Soil_Dirt_Poisoned"},
    {"x": -5, "y": 7, "z": 0, "name": "Soil_Dirt_Burnt"},
    {"x": -5, "y": 8, "z": 0, "name": "Soil_Dirt_Poisoned"},
    {"x": -5, "y": 9, "z": 0, "name": "Soil_Dirt_Burnt"},
    {"x": -5, "y": 10, "z": 0, "name": "Soil_Grass_Burnt"},
    {"x": -5, "y": 16, "z": 0, "name": "Wood_Hardwood_Planks_Half", "rotation": 8},
    {"x": -5, "y": 5, "z": 1, "name": "Soil_Dirt_Poisoned"},
    {"x": -5, "y": 6, "z": 1, "name": "Soil_Dirt_Burnt"},
    {"x": -5, "y": 7, "z": 1, "name": "Soil_Dirt_Poisoned"},
    {"x": -5, "y": 8, "z": 1, "name": "Soil_Dirt_Burnt"},
    {"x": -5, "y": 9, "z": 1, "name": "Soil_Dirt_Poisoned"},
    {"x": -5, "y": 10, "z": 1, "name": "Soil_Grass_Dry"},
    {"x": -5, "y": 16, "z": 1, "name": "Wood_Hardwood_Planks_Half"},
    {"x": -5, "y": 19, "z": 1, "name": "Wood_Hardwood_Planks_Half", "rotation": 8},
    {"x": -5, "y": 5, "z": 2, "name": "Soil_Dirt_Burnt"},
    {"x": -5, "y": 6, "z": 2, "name": "Soil_Dirt_Poisoned"},
    {"x": -5, "y": 7, "z": 2, "name": "Soil_Dirt_Burnt"},
    {"x": -5, "y": 8, "z": 2, "name": "Soil_Dirt_Poisoned"},
    {"x": -5, "y": 9, "z": 2, "name": "Soil_Dirt_Burnt"},
    {"x": -5, "y": 10, "z": 2, "name": "Soil_Grass_Burnt"},
    {"x": -5, "y": 16, "z": 2, "name": "Wood_Hardwood_Planks_Half"},
    {"x": -5, "y": 19, "z": 2, "name": "Wood_Hardwood_Planks_Half", "rotation": 8},
    {"x": -5, "y": 15, "z": 3, "name": "Wood_Hardwood_Planks_Half", "rotation": 8},
    {"x": -5, "y": 19, "z": 3, "name": "Wood_Hardwood_Planks_Half", "rotation": 8},
    {"x": -5, "y": 19, "z": 4, "name": "Furniture_Kweebec_Platform"},
    {"x": -4, "y": 6, "z": -3, "name": "Soil_Dirt_Poisoned"},
    {"x": -4, "y": 7, "z": -3, "name": "Soil_Dirt_Burnt"},
    {"x": -4, "y": 8, "z": -3, "name": "Soil_Dirt_Poisoned"},
    {"x": -4, "y": 9, "z": -3, "name": "Soil_Dirt_Burnt"},
    {"x": -4, "y": 10, "z": -3, "name": "Soil_Grass_Burnt"},
    {"x": -4, "y": 11, "z": -3, "name": "Plant_Grass_Sharp"},
    {"x": -4, "y": 6, "z": -2, "name": "Soil_Dirt_Burnt"},
    {"x": -4, "y": 7, "z": -2, "name": "Soil_Dirt_Poisoned"},
    {"x": -4, "y": 8, "z": -2, "name": "Soil_Dirt_Burnt"},
    {"x": -4, "y": 9, "z": -2, "name": "Soil_Dirt_Poisoned"},
    {"x": -4, "y": 10, "z": -2, "name": "Soil_Grass_Dry"},
    {"x": -4, "y": 11, "z": -2, "name": "Wood_Hardwood_Planks_Half", "rotation": 8},
    {"x": -4, "y": 19, "z": -2, "name": "Furniture_Kweebec_Platform"},
    {"x": -4, "y": 5, "z": -1, "name": "Soil_Dirt_Burnt"},
    {"x": -4, "y": 6, "z": -1, "name": "Soil_Dirt_Poisoned"},
    {"x": -4, "y": 7, "z": -1, "name": "Soil_Dirt_Burnt"},
    {"x": -4, "y": 8, "z": -1, "name": "Soil_Dirt_Poisoned"},
    {"x": -4, "y": 9, "z": -1, "name": "Soil_Dirt_Burnt"},
    {"x": -4, "y": 10, "z": -1, "name": "Soil_Grass_Burnt"},
    {"x": -4, "y": 11, "z": -1, "name": "Wood_Hardwood_Planks_Half", "rotation": 8},
    {"x": -4, "y": 16, "z": -1, "name": "Wood_Hardwood_Planks_Half", "rotation": 8},
    {"x": -4, "y": 19, "z": -1, "name": "Furniture_Kweebec_Platform"},
    {"x": -4, "y": 5, "z": 0, "name": "Soil_Dirt_Poisoned"},
    {"x": -4, "y": 6, "z": 0, "name": "Soil_Dirt_Burnt"},
    {"x": -4, "y": 7, "z": 0, "name": "Soil_Dirt_Poisoned"},
    {"x": -4, "y": 8, "z": 0, "name": "Soil_Dirt_Burnt"},
    {"x": -4, "y": 9, "z": 0, "name": "Soil_Dirt_Poisoned"},
    {"x": -4, "y": 10, "z": 0, "name": "Soil_Dirt_Burnt"},
    {"x": -4, "y": 11, "z": 0, "name": "Wood_Hardwood_Planks_Half"},
    {"x": -4, "y": 16, "z": 0, "name": "Wood_Hardwood_Planks_Half", "rotation": 8},
    {"x": -4, "y": 19, "z": 0, "name": "Wood_Hardwood_Planks_Half", "rotation": 8},
    {"x": -4, "y": 5, "z": 1, "name": "Soil_Dirt_Burnt"},
    {"x": -4, "y": 6, "z": 1, "name": "Soil_Dirt_Poisoned"},
    {"x": -4, "y": 7, "z": 1, "name": "Soil_Dirt_Burnt"},
    {"x": -4, "y": 8, "z": 1, "name": "Soil_Dirt_Poisoned"},
    {"x": -4, "y": 9, "z": 1, "name": "Soil_Dirt_Burnt"},
    {"x": -4, "y": 10, "z": 1, "name": "Soil_Leaves"},
    {"x": -4, "y": 16, "z": 1, "name": "Wood_Hardwood_Planks_Half"},
    {"x": -4, "y": 19, "z": 1, "name": "Wood_Hardwood_Planks_Half", "rotation": 8},
    {"x": -4, "y": 5, "z": 2, "name": "Soil_Dirt_Poisoned"},
    {"x": -4, "y": 6, "z": 2, "name": "Soil_Dirt_Burnt"},
    {"x": -4, "y": 7, "z": 2, "name": "Soil_Dirt_Poisoned"},
    {"x": -4, "y": 8, "z": 2, "name": "Soil_Dirt_Burnt"},
    {"x": -4, "y": 9, "z": 2, "name": "Soil_Dirt_Poisoned"},
    {"x": -4, "y": 10, "z": 2, "name": "Soil_Grass_Dry"},
    {"x": -4, "y": 16, "z": 2, "name": "Wood_Hardwood_Planks_Half"},
    {"x": -4, "y": 19, "z": 2, "name": "Wood_Hardwood_Planks_Half", "rotation": 8},
    {"x": -4, "y": 5, "z": 3, "name": "Soil_Dirt_Burnt"},
    {"x": -4, "y": 6, "z": 3, "name": "Soil_Dirt_Poisoned"},
    {"x": -4, "y": 7, "z": 3, "name": "Soil_Dirt_Burnt"},
    {"x": -4, "y": 8, "z": 3, "name": "Soil_Dirt_Poisoned"},
    {"x": -4, "y": 9, "z": 3, "name": "Soil_Dirt_Burnt"},
    {"x": -4, "y": 10, "z": 3, "name": "Soil_Grass_Burnt"},
    {"x": -4, "y": 15, "z": 3, "name": "Wood_Hardwood_Planks_Half", "rotation": 8},
    {"x": -4, "y": 19, "z": 3, "name": "Wood_Hardwood_Planks_Half", "rotation": 8},
    {"x": -4, "y": 15, "z": 4, "name": "Wood_Hardwood_Planks_Half", "rotation": 8},
    {"x": -4, "y": 19, "z": 4, "name": "Wood_Hardwood_Planks_Half", "rotation": 8},
    {"x": -4, "y": 19, "z": 5, "name": "Wood_Hardwood_Planks_Half", "rotation": 8},
    {"x": -3, "y": 20, "z": -4, "name": "Wood_Ash_Branch_Corner", "rotation": 2},
    {"x": -3, "y": 21, "z": -4, "name": "Wood_Poisoned_Branch_Corner", "rotation": 8},
    {"x": -3, "y": 7, "z": -3, "name": "Soil_Dirt_Poisoned"},
    {"x": -3, "y": 8, "z": -3, "name": "Soil_Dirt_Burnt"},
    {"x": -3, "y": 9, "z": -3, "name": "Soil_Dirt_Poisoned"},
    {"x": -3, "y": 10, "z": -3, "name": "Soil_Grass_Dry"},
    {"x": -3, "y": 11, "z": -3, "name": "Wood_Hardwood_Planks_Half", "rotation": 8},
    {"x": -3, "y": 16, "z": -3, "name": "Wood_Petrified_Branch_Corner", "rotation": 3},
    {"x": -3, "y": 17, "z": -3, "name": "Wood_Poisoned_Branch_Long"},
    {"x": -3, "y": 18, "z": -3, "name": "Wood_Poisoned_Branch_Long"},
    {"x": -3, "y": 19, "z": -3, "name": "Wood_Petrified_Branch_Long"},
    {"x": -3, "y": 20, "z": -3, "name": "Wood_Petrified_Branch_Corner", "rotation": 10},
    {"x": -3, "y": 21, "z": -3, "name": "Wood_Petrified_Branch_Corner"},
    {"x": -3, "y": 5, "z": -2, "name": "Soil_Dirt_Burnt"},
    {"x": -3, "y": 6, "z": -2, "name": "Soil_Dirt_Poisoned"},
    {"x": -3, "y": 7, "z": -2, "name": "Soil_Dirt_Burnt"},
    {"x": -3, "y": 8, "z": -2, "name": "Soil_Dirt_Poisoned"},
    {"x": -3, "y": 9, "z": -2, "name": "Soil_Dirt_Burnt"},
    {"x": -3, "y": 10, "z": -2, "name": "Soil_Grass_Burnt"},
    {"x": -3, "y": 11, "z": -2, "name": "*Wood_Hardwood_Planks_Half_State_Definitions_Block"},
    {"x": -3, "y": 17, "z": -2, "name": "Wood_Hardwood_Planks_Half"},
    {"x": -3, "y": 19, "z": -2, "name": "Wood_Hardwood_Planks_Half", "rotation": 8},
    {"x": -3, "y": 5, "z": -1, "name": "Soil_Dirt_Poisoned"},
    {"x": -3, "y": 6, "z": -1, "name": "Soil_Dirt_Burnt"},
    {"x": -3, "y": 7, "z": -1, "name": "Soil_Dirt_Poisoned"},
    {"x": -3, "y": 8, "z": -1, "name": "Soil_Dirt_Burnt"},
    {"x": -3, "y": 9, "z": -1, "name": "Soil_Dirt_Poisoned"},
    {"x": -3, "y": 10, "z": -1, "name": "Soil_Grass_Dry"},
    {"x": -3, "y": 11, "z": -1, "name": "*Wood_Hardwood_Planks_Half_State_Definitions_Block"},
    {"x": -3, "y": 16, "z": -1, "name": "Wood_Ash_Roots"},
    {"x": -3, "y": 17, "z": -1, "name": "Wood_Hardwood_Planks_Half"},
    {"x": -3, "y": 19, "z": -1, "name": "Wood_Hardwood_Planks_Half", "rotation": 8},
    {"x": -3, "y": 5, "z": 0, "name": "Soil_Dirt_Burnt"},
    {"x": -3, "y": 6, "z": 0, "name": "Soil_Dirt_Poisoned"},
    {"x": -3, "y": 7, "z": 0, "name": "Soil_Dirt_Burnt"},
    {"x": -3, "y": 8, "z": 0, "name": "Soil_Dirt_Poisoned"},
    {"x": -3, "y": 9, "z": 0, "name": "Soil_Dirt_Burnt"},
    {"x": -3, "y": 10, "z": 0, "name": "Soil_Dirt_Poisoned"},
    {"x": -3, "y": 11, "z": 0, "name": "Wood_Hardwood_Planks_Half"},
    {"x": -3, "y": 16, "z": 0, "name": "Wood_Hardwood_Planks_Half", "rotation": 8},
    {"x": -3, "y": 19, "z": 0, "name": "Wood_Hardwood_Planks_Half", "rotation": 8},
    {"x": -3, "y": 5, "z": 1, "name": "Soil_Dirt_Poisoned"},
    {"x": -3, "y": 6, "z": 1, "name": "Soil_Dirt_Burnt"},
    {"x": -3, "y": 7, "z": 1, "name": "Soil_Dirt_Poisoned"},
    {"x": -3, "y": 8, "z": 1, "name": "Soil_Dirt_Burnt"},
    {"x": -3, "y": 9, "z": 1, "name": "Soil_Dirt_Poisoned"},
    {"x": -3, "y": 10, "z": 1, "name": "Soil_Leaves"},
    {"x": -3, "y": 15, "z": 1, "name": "Wood_Petrified_Roots"},
    {"x": -3, "y": 16, "z": 1, "name": "Wood_Hardwood_Planks_Half"},
    {"x": -3, "y": 19, "z": 1, "name": "Wood_Hardwood_Planks_Half", "rotation": 8},
    {"x": -3, "y": 22, "z": 1, "name": "Wood_Petrified_Branch_Corner", "rotation": 3},
    {"x": -3, "y": 23, "z": 1, "name": "Wood_Poisoned_Branch_Long"},
    {"x": -3, "y": 24, "z": 1, "name": "Wood_Poisoned_Branch_Corner", "rotation": 9},
    {"x": -3, "y": 5, "z": 2, "name": "Soil_Dirt_Burnt"},
    {"x": -3, "y": 6, "z": 2, "name": "Soil_Dirt_Poisoned"},
    {"x": -3, "y": 7, "z": 2, "name": "Soil_Dirt_Burnt"},
    {"x": -3, "y": 8, "z": 2, "name": "Soil_Dirt_Poisoned"},
    {"x": -3, "y": 9, "z": 2, "name": "Soil_Dirt_Burnt"},
    {"x": -3, "y": 10, "z": 2, "name": "Soil_Leaves"},
    {"x": -3, "y": 11, "z": 2, "name": "Plant_Grass_Sharp"},
    {"x": -3, "y": 15, "z": 2, "name": "Wood_Hardwood_Planks_Half", "rotation": 8},
    {"x": -3, "y": 19, "z": 2, "name": "*Wood_Hardwood_Planks_Half_State_Definitions_Block", "rotation": 8},
    {"x": -3, "y": 5, "z": 3, "name": "Soil_Dirt_Poisoned"},
    {"x": -3, "y": 6, "z": 3, "name": "Soil_Dirt_Burnt"},
    {"x": -3, "y": 7, "z": 3, "name": "Soil_Dirt_Poisoned"},
    {"x": -3, "y": 8, "z": 3, "name": "Soil_Dirt_Burnt"},
    {"x": -3, "y": 9, "z": 3, "name": "Soil_Dirt_Poisoned"},
    {"x": -3, "y": 10, "z": 3, "name": "Soil_Leaves"},
    {"x": -3, "y": 15, "z": 3, "name": "Wood_Hardwood_Planks_Half", "rotation": 8},
    {"x": -3, "y": 19, "z": 3, "name": "Wood_Hardwood_Planks_Half", "rotation": 8},
    {"x": -3, "y": 5, "z": 4, "name": "Soil_Dirt_Burnt"},
    {"x": -3, "y": 6, "z": 4, "name": "Soil_Dirt_Poisoned"},
    {"x": -3, "y": 7, "z": 4, "name": "Soil_Dirt_Burnt"},
    {"x": -3, "y": 8, "z": 4, "name": "Soil_Dirt_Poisoned"},
    {"x": -3, "y": 15, "z": 4, "name": "Wood_Hardwood_Planks_Half", "rotation": 8},
    {"x": -3, "y": 19, "z": 4, "name": "Wood_Hardwood_Planks_Half", "rotation": 8},
    {"x": -3, "y": 19, "z": 5, "name": "Wood_Hardwood_Planks_Half", "rotation": 8},
    {"x": -2, "y": 19, "z": -9, "name": "Furniture_Kweebec_Platform"},
    {"x": -2, "y": 19, "z": -8, "name": "Furniture_Kweebec_Platform"},
    {"x": -2, "y": 19, "z": -7, "name": "Furniture_Kweebec_Platform"},
    {"x": -2, "y": 19, "z": -6, "name": "Furniture_Kweebec_Platform"},
    {"x": -2, "y": 19, "z": -5, "name": "Furniture_Kweebec_Platform"},
    {"x": -2, "y": 19, "z": -4, "name": "Furniture_Kweebec_Platform"},
    {"x": -2, "y": 12, "z": -3, "name": "Wood_Hardwood_Planks_Half"},
    {"x": -2, "y": 16, "z": -3, "name": "Wood_Petrified_Branch_Long", "rotation": 5},
    {"x": -2, "y": 19, "z": -3, "name": "Wood_Hardwood_Planks_Half", "rotation": 8},
    {"x": -2, "y": 5, "z": -2, "name": "Soil_Dirt_Poisoned"},
    {"x": -2, "y": 6, "z": -2, "name": "Soil_Dirt_Burnt"},
    {"x": -2, "y": 7, "z": -2, "name": "Soil_Dirt_Poisoned"},
    {"x": -2, "y": 8, "z": -2, "name": "Soil_Dirt_Burnt"},
    {"x": -2, "y": 9, "z": -2, "name": "Soil_Dirt_Poisoned"},
    {"x": -2, "y": 10, "z": -2, "name": "Soil_Grass_Dry"},
    {"x": -2, "y": 11, "z": -2, "name": "Plant_Grass_Sharp"},
    {"x": -2, "y": 12, "z": -2, "name": "Wood_Hardwood_Planks_Half"},
    {"x": -2, "y": 17, "z": -2, "name": "Wood_Hardwood_Planks_Half"},
    {"x": -2, "y": 19, "z": -2, "name": "Wood_Hardwood_Planks_Half", "rotation": 8},
    {"x": -2, "y": 5, "z": -1, "name": "Soil_Dirt_Burnt"},
    {"x": -2, "y": 6, "z": -1, "name": "Soil_Dirt_Poisoned"},
    {"x": -2, "y": 7, "z": -1, "name": "Soil_Dirt_Burnt"},
    {"x": -2, "y": 8, "z": -1, "name": "Soil_Dirt_Poisoned"},
    {"x": -2, "y": 9, "z": -1, "name": "Soil_Dirt_Burnt"},
    {"x": -2, "y": 10, "z": -1, "name": "Wood_Ash_Trunk"},
    {"x": -2, "y": 11, "z": -1, "name": "Wood_Ash_Trunk"},
    {"x": -2, "y": 12, "z": -1, "name": "Wood_Ash_Trunk"},
    {"x": -2, "y": 13, "z": -1, "name": "Wood_Ash_Trunk"},
    {"x": -2, "y": 14, "z": -1, "name": "Wood_Ash_Branch_Corner", "rotation": 8},
    {"x": -2, "y": 17, "z": -1, "name": "Wood_Hardwood_Planks_Half"},
    {"x": -2, "y": 5, "z": 0, "name": "Soil_Dirt_Poisoned"},
    {"x": -2, "y": 6, "z": 0, "name": "Soil_Dirt_Burnt"},
    {"x": -2, "y": 7, "z": 0, "name": "Soil_Dirt_Poisoned"},
    {"x": -2, "y": 8, "z": 0, "name": "Soil_Dirt_Burnt"},
    {"x": -2, "y": 9, "z": 0, "name": "Soil_Dirt_Poisoned"},
    {"x": -2, "y": 10, "z": 0, "name": "Soil_Grass_Dry"},
    {"x": -2, "y": 13, "z": 0, "name": "Furniture_Kweebec_Lantern"},
    {"x": -2, "y": 14, "z": 0, "name": "Wood_Poisoned_Branch_Corner", "rotation": 10},
    {"x": -2, "y": 17, "z": 0, "name": "Wood_Hardwood_Planks_Half"},
    {"x": -2, "y": 20, "z": 0, "name": "Wood_Ash_Branch_Corner", "rotation": 2},
    {"x": -2, "y": 21, "z": 0, "name": "Furniture_Kweebec_Candle"},
    {"x": -2, "y": 5, "z": 1, "name": "Soil_Dirt_Burnt"},
    {"x": -2, "y": 6, "z": 1, "name": "Soil_Dirt_Poisoned"},
    {"x": -2, "y": 7, "z": 1, "name": "Soil_Dirt_Burnt"},
    {"x": -2, "y": 8, "z": 1, "name": "Soil_Dirt_Poisoned"},
    {"x": -2, "y": 9, "z": 1, "name": "Soil_Dirt_Burnt"},
    {"x": -2, "y": 10, "z": 1, "name": "Soil_Leaves"},
    {"x": -2, "y": 11, "z": 1, "name": "Wood_Ash_Trunk"},
    {"x": -2, "y": 12, "z": 1, "name": "Wood_Petrified_Trunk"},
    {"x": -2, "y": 13, "z": 1, "name": "Wood_Ash_Trunk"},
    {"x": -2, "y": 14, "z": 1, "name": "Wood_Petrified_Trunk"},
    {"x": -2, "y": 15, "z": 1, "name": "Wood_Ash_Trunk"},
    {"x": -2, "y": 16, "z": 1, "name": "Wood_Poisoned_Trunk"},
    {"x": -2, "y": 17, "z": 1, "name": "Wood_Ash_Trunk"},
    {"x": -2, "y": 18, "z": 1, "name": "Wood_Poisoned_Trunk"},
    {"x": -2, "y": 19, "z": 1, "name": "Wood_Petrified_Trunk"},
    {"x": -2, "y": 20, "z": 1, "name": "Wood_Poisoned_Trunk"},
    {"x": -2, "y": 21, "z": 1, "name": "Wood_Petrified_Trunk"},
    {"x": -2, "y": 22, "z": 1, "name": "Wood_Poisoned_Trunk"},
    {"x": -2, "y": 23, "z": 1, "name": "Wood_Petrified_Branch_Corner", "rotation": 3},
    {"x": -2, "y": 24, "z": 1, "name": "Wood_Ash_Branch_Long", "rotation": 5},
    {"x": -2, "y": 5, "z": 2, "name": "Soil_Dirt_Poisoned"},
    {"x": -2, "y": 6, "z": 2, "name": "Soil_Dirt_Burnt"},
    {"x": -2, "y": 7, "z": 2, "name": "Soil_Dirt_Poisoned"},
    {"x": -2, "y": 8, "z": 2, "name": "Soil_Dirt_Burnt"},
    {"x": -2, "y": 9, "z": 2, "name": "Soil_Dirt_Poisoned"},
    {"x": -2, "y": 10, "z": 2, "name": "Soil_Leaves"},
    {"x": -2, "y": 11, "z": 2, "name": "Plant_Bramble_Moss_Twisted"},
    {"x": -2, "y": 12, "z": 2, "name": "Wood_Ash_Branch_Short", "rotation": 3},
    {"x": -2, "y": 14, "z": 2, "name": "Furniture_Kweebec_Sign"},
    {"x": -2, "y": 15, "z": 2, "name": "Wood_Hardwood_Planks_Half"},
    {"x": -2, "y": 18, "z": 2, "name": "Wood_Poisoned_Trunk"},
    {"x": -2, "y": 19, "z": 2, "name": "Wood_Petrified_Trunk"},
    {"x": -2, "y": 5, "z": 3, "name": "Soil_Dirt_Burnt"},
    {"x": -2, "y": 6, "z": 3, "name": "Soil_Dirt_Poisoned"},
    {"x": -2, "y": 7, "z": 3, "name": "Soil_Dirt_Burnt"},
    {"x": -2, "y": 8, "z": 3, "name": "Soil_Dirt_Poisoned"},
    {"x": -2, "y": 9, "z": 3, "name": "Soil_Dirt_Burnt"},
    {"x": -2, "y": 10, "z": 3, "name": "Soil_Grass_Burnt"},
    {"x": -2, "y": 15, "z": 3, "name": "Wood_Hardwood_Planks_Half"},
    {"x": -2, "y": 18, "z": 3, "name": "Wood_Petrified_Branch_Long", "rotation": 4},
    {"x": -2, "y": 19, "z": 3, "name": "*Wood_Hardwood_Planks_Half_State_Definitions_Block", "rotation": 8},
    {"x": -2, "y": 5, "z": 4, "name": "Soil_Dirt_Poisoned"},
    {"x": -2, "y": 6, "z": 4, "name": "Soil_Dirt_Burnt"},
    {"x": -2, "y": 7, "z": 4, "name": "Soil_Dirt_Poisoned"},
    {"x": -2, "y": 8, "z": 4, "name": "Soil_Dirt_Burnt"},
    {"x": -2, "y": 9, "z": 4, "name": "Soil_Dirt_Poisoned"},
    {"x": -2, "y": 10, "z": 4, "name": "Soil_Grass_Dry"},
    {"x": -2, "y": 15, "z": 4, "name": "Wood_Hardwood_Planks_Half"},
    {"x": -2, "y": 18, "z": 4, "name": "Wood_Petrified_Branch_Long", "support": 1, "rotation": 4},
    {"x": -2, "y": 19, "z": 4, "name": "Wood_Hardwood_Planks_Half", "rotation": 8},
    {"x": -2, "y": 17, "z": 5, "name": "Wood_Petrified_Branch_Corner", "rotation": 2},
    {"x": -2, "y": 18, "z": 5, "name": "Wood_Ash_Branch_Corner", "rotation": 10},
    {"x": -2, "y": 19, "z": 5, "name": "Wood_Hardwood_Planks_Half", "rotation": 8},
    {"x": -2, "y": 17, "z": 6, "name": "Wood_Poisoned_Branch_Corner"},
    {"x": -2, "y": 18, "z": 6, "name": "Wood_Ash_Branch_Corner", "rotation": 8},
    {"x": -2, "y": 19, "z": 6, "name": "Wood_Hardwood_Planks_Half", "rotation": 8},
    {"x": -2, "y": 18, "z": 7, "name": "Wood_Poisoned_Branch_Corner"},
    {"x": -2, "y": 19, "z": 7, "name": "*Wood_Hardwood_Planks_Half_State_Definitions_Block"},
    {"x": -2, "y": 19, "z": 8, "name": "Furniture_Kweebec_Platform"},
    {"x": -2, "y": 19, "z": 9, "name": "Furniture_Kweebec_Platform"},
    {"x": -2, "y": 19, "z": 10, "name": "Furniture_Kweebec_Platform"},
    {"x": -2, "y": 19, "z": 11, "name": "Furniture_Kweebec_Platform"},
    {"x": -1, "y": 12, "z": -3, "name": "Wood_Hardwood_Planks_Half"},
    {"x": -1, "y": 15, "z": -3, "name": "Wood_Ash_Branch_Corner", "rotation": 2},
    {"x": -1, "y": 16, "z": -3, "name": "Wood_Poisoned_Branch_Corner", "rotation": 11},
    {"x": -1, "y": 5, "z": -2, "name": "Soil_Dirt_Burnt"},
    {"x": -1, "y": 6, "z": -2, "name": "Soil_Dirt_Poisoned"},
    {"x": -1, "y": 7, "z": -2, "name": "Soil_Dirt_Burnt"},
    {"x": -1, "y": 8, "z": -2, "name": "Soil_Dirt_Poisoned"},
    {"x": -1, "y": 9, "z": -2, "name": "Soil_Dirt_Burnt"},
    {"x": -1, "y": 10, "z": -2, "name": "Soil_Grass_Burnt"},
    {"x": -1, "y": 11, "z": -2, "name": "Plant_Grass_Sharp"},
    {"x": -1, "y": 12, "z": -2, "name": "Wood_Hardwood_Planks_Half"},
    {"x": -1, "y": 15, "z": -2, "name": "Wood_Poisoned_Branch_Corner"},
    {"x": -1, "y": 16, "z": -2, "name": "Wood_Poisoned_Branch_Corner", "rotation": 8},
    {"x": -1, "y": 17, "z": -2, "name": "Wood_Hardwood_Planks_Half", "rotation": 8},
    {"x": -1, "y": 5, "z": -1, "name": "Soil_Dirt_Poisoned"},
    {"x": -1, "y": 6, "z": -1, "name": "Soil_Dirt_Burnt"},
    {"x": -1, "y": 7, "z": -1, "name": "Soil_Dirt_Poisoned"},
    {"x": -1, "y": 8, "z": -1, "name": "Soil_Dirt_Burnt"},
    {"x": -1, "y": 9, "z": -1, "name": "Soil_Dirt_Poisoned"},
    {"x": -1, "y": 10, "z": -1, "name": "Soil_Grass_Dry"},
    {"x": -1, "y": 12, "z": -1, "name": "Wood_Hardwood_Planks_Half", "rotation": 8},
    {"x": -1, "y": 16, "z": -1, "name": "Wood_Ash_Branch_Long", "rotation": 4},
    {"x": -1, "y": 17, "z": -1, "name": "Wood_Hardwood_Planks_Half", "rotation": 8},
    {"x": -1, "y": 5, "z": 0, "name": "Soil_Dirt_Burnt"},
    {"x": -1, "y": 6, "z": 0, "name": "Soil_Dirt_Poisoned"},
    {"x": -1, "y": 7, "z": 0, "name": "Soil_Dirt_Burnt"},
    {"x": -1, "y": 8, "z": 0, "name": "Soil_Dirt_Poisoned"},
    {"x": -1, "y": 9, "z": 0, "name": "Soil_Dirt_Burnt"},
    {"x": -1, "y": 10, "z": 0, "name": "Soil_Grass_Burnt"},
    {"x": -1, "y": 11, "z": 0, "name": "Wood_Poisoned_Trunk"},
    {"x": -1, "y": 12, "z": 0, "name": "Wood_Petrified_Trunk"},
    {"x": -1, "y": 13, "z": 0, "name": "Wood_Petrified_Trunk"},
    {"x": -1, "y": 14, "z": 0, "name": "Wood_Petrified_Trunk"},
    {"x": -1, "y": 15, "z": 0, "name": "Wood_Petrified_Trunk"},
    {"x": -1, "y": 16, "z": 0, "name": "Wood_Poisoned_Branch_Corner", "rotation": 10},
    {"x": -1, "y": 17, "z": 0, "name": "Wood_Hardwood_Planks_Half", "rotation": 8},
    {"x": -1, "y": 5, "z": 1, "name": "Soil_Dirt_Poisoned"},
    {"x": -1, "y": 6, "z": 1, "name": "Soil_Dirt_Burnt"},
    {"x": -1, "y": 7, "z": 1, "name": "Soil_Dirt_Poisoned"},
    {"x": -1, "y": 8, "z": 1, "name": "Soil_Dirt_Burnt"},
    {"x": -1, "y": 9, "z": 1, "name": "Soil_Dirt_Poisoned"},
    {"x": -1, "y": 10, "z": 1, "name": "Soil_Grass_Dry"},
    {"x": -1, "y": 11, "z": 1, "name": "Wood_Petrified_Trunk"},
    {"x": -1, "y": 12, "z": 1, "name": "Wood_Poisoned_Trunk"},
    {"x": -1, "y": 13, "z": 1, "name": "Wood_Ash_Trunk"},
    {"x": -1, "y": 14, "z": 1, "name": "Wood_Poisoned_Trunk"},
    {"x": -1, "y": 15, "z": 1, "name": "Wood_Ash_Trunk"},
    {"x": -1, "y": 16, "z": 1, "name": "Wood_Ash_Trunk"},
    {"x": -1, "y": 17, "z": 1, "name": "Wood_Petrified_Trunk"},
    {"x": -1, "y": 18, "z": 1, "name": "Wood_Ash_Trunk"},
    {"x": -1, "y": 19, "z": 1, "name": "Wood_Petrified_Trunk"},
    {"x": -1, "y": 20, "z": 1, "name": "Wood_Ash_Trunk"},
    {"x": -1, "y": 21, "z": 1, "name": "Wood_Petrified_Trunk"},
    {"x": -1, "y": 23, "z": 1, "name": "Wood_Petrified_Branch_Corner", "rotation": 1},
    {"x": -1, "y": 24, "z": 1, "name": "Wood_Poisoned_Branch_Corner", "rotation": 11},
    {"x": -1, "y": 5, "z": 2, "name": "Soil_Dirt_Burnt"},
    {"x": -1, "y": 6, "z": 2, "name": "Soil_Dirt_Poisoned"},
    {"x": -1, "y": 7, "z": 2, "name": "Soil_Dirt_Burnt"},
    {"x": -1, "y": 8, "z": 2, "name": "Soil_Dirt_Poisoned"},
    {"x": -1, "y": 9, "z": 2, "name": "Wood_Petrified_Trunk"},
    {"x": -1, "y": 10, "z": 2, "name": "Wood_Ash_Trunk"},
    {"x": -1, "y": 11, "z": 2, "name": "Wood_Ash_Trunk"},
    {"x": -1, "y": 12, "z": 2, "name": "Wood_Poisoned_Trunk"},
    {"x": -1, "y": 13, "z": 2, "name": "Wood_Ash_Trunk"},
    {"x": -1, "y": 14, "z": 2, "name": "Wood_Ash_Trunk"},
    {"x": -1, "y": 15, "z": 2, "name": "Wood_Poisoned_Branch_Long"},
    {"x": -1, "y": 16, "z": 2, "name": "Furniture_Kweebec_Lantern"},
    {"x": -1, "y": 18, "z": 2, "name": "Wood_Hardwood_Planks_Half", "rotation": 8},
    {"x": -1, "y": 5, "z": 3, "name": "Soil_Dirt_Poisoned"},
    {"x": -1, "y": 6, "z": 3, "name": "Soil_Dirt_Burnt"},
    {"x": -1, "y": 7, "z": 3, "name": "Soil_Dirt_Poisoned"},
    {"x": -1, "y": 8, "z": 3, "name": "Soil_Dirt_Burnt"},
    {"x": -1, "y": 9, "z": 3, "name": "Soil_Dirt_Poisoned"},
    {"x": -1, "y": 10, "z": 3, "name": "Soil_Grass_Dry"},
    {"x": -1, "y": 11, "z": 3, "name": "Plant_Grass_Sharp"},
    {"x": -1, "y": 14, "z": 3, "name": "Wood_Hardwood_Planks_Half", "rotation": 8},
    {"x": -1, "y": 18, "z": 3, "name": "Wood_Poisoned_Roots"},
    {"x": -1, "y": 19, "z": 3, "name": "Wood_Hardwood_Planks_Half"},
    {"x": -1, "y": 5, "z": 4, "name": "Soil_Dirt_Burnt"},
    {"x": -1, "y": 6, "z": 4, "name": "Soil_Dirt_Poisoned"},
    {"x": -1, "y": 7, "z": 4, "name": "Soil_Dirt_Burnt"},
    {"x": -1, "y": 8, "z": 4, "name": "Soil_Dirt_Poisoned"},
    {"x": -1, "y": 9, "z": 4, "name": "Soil_Dirt_Burnt"},
    {"x": -1, "y": 10, "z": 4, "name": "Soil_Grass_Burnt"},
    {"x": -1, "y": 15, "z": 4, "name": "Wood_Hardwood_Planks_Half"},
    {"x": -1, "y": 19, "z": 4, "name": "*Wood_Hardwood_Planks_Half_State_Definitions_Block"},
    {"x": -1, "y": 19, "z": 5, "name": "Wood_Hardwood_Planks_Half", "rotation": 8},
    {"x": 0, "y": 8, "z": -2, "name": "Soil_Clay_Brick"},
    {"x": 0, "y": 9, "z": -2, "name": "Soil_Clay_Brick"},
    {"x": 0, "y": 10, "z": -2, "name": "Soil_Clay_Brick"},
    {"x": 0, "y": 12, "z": -2, "name": "Wood_Hardwood_Planks_Half", "rotation": 8},
    {"x": 0, "y": 17, "z": -2, "name": "Wood_Hardwood_Planks_Half", "rotation": 8},
    {"x": 0, "y": 5, "z": -1, "name": "Soil_Dirt_Burnt"},
    {"x": 0, "y": 6, "z": -1, "name": "Soil_Dirt_Poisoned"},
    {"x": 0, "y": 7, "z": -1, "name": "Soil_Dirt_Burnt"},
    {"x": 0, "y": 8, "z": -1, "name": "Soil_Dirt_Poisoned"},
    {"x": 0, "y": 9, "z": -1, "name": "Soil_Clay_Brick"},
    {"x": 0, "y": 10, "z": -1, "name": "Soil_Clay_Brick"},
    {"x": 0, "y": 11, "z": -1, "name": "Soil_Clay_Brick_Half"},
    {"x": 0, "y": 12, "z": -1, "name": "Wood_Hardwood_Planks_Half", "rotation": 8},
    {"x": 0, "y": 17, "z": -1, "name": "Wood_Hardwood_Planks_Half", "rotation": 8},
    {"x": 0, "y": 5, "z": 0, "name": "Soil_Dirt_Poisoned"},
    {"x": 0, "y": 6, "z": 0, "name": "Soil_Dirt_Burnt"},
    {"x": 0, "y": 7, "z": 0, "name": "Soil_Dirt_Poisoned"},
    {"x": 0, "y": 8, "z": 0, "name": "Soil_Dirt_Burnt"},
    {"x": 0, "y": 9, "z": 0, "name": "Soil_Dirt_Poisoned"},
    {"x": 0, "y": 10, "z": 0, "name": "Soil_Leaves"},
    {"x": 0, "y": 11, "z": 0, "name": "Plant_Bramble_Moss_Twisted"},
    {"x": 0, "y": 13, "z": 0, "name": "Wood_Hardwood_Planks_Half"},
    {"x": 0, "y": 18, "z": 0, "name": "Wood_Hardwood_Planks_Half"},
    {"x": 0, "y": 5, "z": 1, "name": "Soil_Dirt_Burnt"},
    {"x": 0, "y": 6, "z": 1, "name": "Soil_Dirt_Poisoned"},
    {"x": 0, "y": 7, "z": 1, "name": "Soil_Dirt_Burnt"},
    {"x": 0, "y": 8, "z": 1, "name": "Soil_Dirt_Poisoned"},
    {"x": 0, "y": 9, "z": 1, "name": "Soil_Dirt_Burnt"},
    {"x": 0, "y": 10, "z": 1, "name": "Soil_Leaves"},
    {"x": 0, "y": 11, "z": 1, "name": "Plant_Bramble_Moss_Twisted"},
    {"x": 0, "y": 13, "z": 1, "name": "Wood_Hardwood_Planks_Half", "rotation": 8},
    {"x": 0, "y": 17, "z": 1, "name": "Wood_Petrified_Branch_Long", "rotation": 5},
    {"x": 0, "y": 18, "z": 1, "name": "Wood_Hardwood_Planks_Half"},
    {"x": 0, "y": 5, "z": 2, "name": "Soil_Dirt_Poisoned"},
    {"x": 0, "y": 6, "z": 2, "name": "Soil_Dirt_Burnt"},
    {"x": 0, "y": 7, "z": 2, "name": "Soil_Dirt_Poisoned"},
    {"x": 0, "y": 8, "z": 2, "name": "Soil_Dirt_Burnt"},
    {"x": 0, "y": 9, "z": 2, "name": "Soil_Dirt_Poisoned"},
    {"x": 0, "y": 10, "z": 2, "name": "Soil_Grass_Dry"},
    {"x": 0, "y": 11, "z": 2, "name": "Wood_Ash_Branch_Corner", "rotation": 1},
    {"x": 0, "y": 12, "z": 2, "name": "Furniture_Kweebec_Lantern"},
    {"x": 0, "y": 14, "z": 2, "name": "Wood_Hardwood_Planks_Half"},
    {"x": 0, "y": 18, "z": 2, "name": "Wood_Hardwood_Planks_Half", "rotation": 8},
    {"x": 0, "y": 5, "z": 3, "name": "Soil_Dirt_Burnt"},
    {"x": 0, "y": 6, "z": 3, "name": "Soil_Dirt_Poisoned"},
    {"x": 0, "y": 7, "z": 3, "name": "Soil_Dirt_Burnt"},
    {"x": 0, "y": 8, "z": 3, "name": "Soil_Dirt_Poisoned"},
    {"x": 0, "y": 9, "z": 3, "name": "Soil_Dirt_Burnt"},
    {"x": 0, "y": 10, "z": 3, "name": "Soil_Grass_Burnt"},
    {"x": 0, "y": 11, "z": 3, "name": "Plant_Grass_Sharp"},
    {"x": 0, "y": 14, "z": 3, "name": "Wood_Hardwood_Planks_Half", "rotation": 8},
    {"x": 0, "y": 18, "z": 3, "name": "Wood_Hardwood_Planks_Half", "rotation": 8},
    {"x": 0, "y": 19, "z": 3, "name": "Wood_Hardwood_Planks_Half"},
    {"x": 0, "y": 6, "z": 4, "name": "Soil_Dirt_Burnt"},
    {"x": 0, "y": 7, "z": 4, "name": "Soil_Dirt_Poisoned"},
    {"x": 0, "y": 8, "z": 4, "name": "Soil_Dirt_Burnt"},
    {"x": 0, "y": 9, "z": 4, "name": "Soil_Dirt_Poisoned"},
    {"x": 0, "y": 10, "z": 4, "name": "Soil_Grass_Dry"},
    {"x": 0, "y": 11, "z": 4, "name": "Plant_Grass_Sharp"},
    {"x": 0, "y": 14, "z": 4, "name": "Wood_Hardwood_Planks_Half", "rotation": 8},
    {"x": 0, "y": 19, "z": 4, "name": "Wood_Hardwood_Planks_Half"},
    {"x": 1, "y": 6, "z": -1, "name": "Soil_Dirt_Burnt"},
    {"x": 1, "y": 7, "z": -1, "name": "Soil_Dirt_Poisoned"},
    {"x": 1, "y": 8, "z": -1, "name": "Soil_Dirt_Burnt"},
    {"x": 1, "y": 9, "z": -1, "name": "Soil_Dirt_Poisoned"},
    {"x": 1, "y": 10, "z": -1, "name": "Soil_Clay_Brick"},
    {"x": 1, "y": 11, "z": -1, "name": "Soil_Clay_Brick"},
    {"x": 1, "y": 13, "z": -1, "name": "Wood_Hardwood_Planks_Half"},
    {"x": 1, "y": 17, "z": -1, "name": "Wood_Ash_Roots"},
    {"x": 1, "y": 18, "z": -1, "name": "Wood_Hardwood_Planks_Half"},
    {"x": 1, "y": 5, "z": 0, "name": "Soil_Dirt_Burnt"},
    {"x": 1, "y": 6, "z": 0, "name": "Soil_Dirt_Poisoned"},
    {"x": 1, "y": 7, "z": 0, "name": "Soil_Dirt_Burnt"},
    {"x": 1, "y": 8, "z": 0, "name": "Soil_Dirt_Poisoned"},
    {"x": 1, "y": 9, "z": 0, "name": "Soil_Clay_Brick"},
    {"x": 1, "y": 10, "z": 0, "name": "Soil_Clay_Brick"},
    {"x": 1, "y": 11, "z": 0, "name": "Soil_Clay_Brick_Half"},
    {"x": 1, "y": 13, "z": 0, "name": "Wood_Hardwood_Planks_Half"},
    {"x": 1, "y": 17, "z": 0, "name": "Wood_Poisoned_Roots"},
    {"x": 1, "y": 18, "z": 0, "name": "Wood_Hardwood_Planks_Half"},
    {"x": 1, "y": 5, "z": 1, "name": "Soil_Dirt_Poisoned"},
    {"x": 1, "y": 6, "z": 1, "name": "Soil_Dirt_Burnt"},
    {"x": 1, "y": 7, "z": 1, "name": "Soil_Dirt_Poisoned"},
    {"x": 1, "y": 8, "z": 1, "name": "Soil_Dirt_Burnt"},
    {"x": 1, "y": 9, "z": 1, "name": "Soil_Clay_Brick"},
    {"x": 1, "y": 10, "z": 1, "name": "Soil_Clay_Brick"},
    {"x": 1, "y": 13, "z": 1, "name": "Wood_Hardwood_Planks_Half", "rotation": 8},
    {"x": 1, "y": 17, "z": 1, "name": "Wood_Petrified_Branch_Long", "rotation": 5},
    {"x": 1, "y": 18, "z": 1, "name": "Wood_Hardwood_Planks_Half"},
    {"x": 1, "y": 5, "z": 2, "name": "Soil_Dirt_Burnt"},
    {"x": 1, "y": 6, "z": 2, "name": "Soil_Dirt_Poisoned"},
    {"x": 1, "y": 7, "z": 2, "name": "Soil_Dirt_Burnt"},
    {"x": 1, "y": 8, "z": 2, "name": "Soil_Dirt_Poisoned"},
    {"x": 1, "y": 9, "z": 2, "name": "Soil_Dirt_Burnt"},
    {"x": 1, "y": 10, "z": 2, "name": "Soil_Grass_Burnt"},
    {"x": 1, "y": 14, "z": 2, "name": "Wood_Hardwood_Planks_Half"},
    {"x": 1, "y": 18, "z": 2, "name": "Wood_Hardwood_Planks_Half", "rotation": 8},
    {"x": 1, "y": 8, "z": 3, "name": "Soil_Dirt_Burnt"},
    {"x": 1, "y": 9, "z": 3, "name": "Soil_Dirt_Poisoned"},
    {"x": 1, "y": 10, "z": 3, "name": "Soil_Grass_Dry"},
    {"x": 1, "y": 14, "z": 3, "name": "Wood_Hardwood_Planks_Half"},
    {"x": 1, "y": 18, "z": 3, "name": "Wood_Hardwood_Planks_Half", "rotation": 8},
    {"x": 2, "y": 9, "z": -1, "name": "Soil_Clay_Brick"},
    {"x": 2, "y": 10, "z": -1, "name": "Soil_Clay_Brick"},
    {"x": 2, "y": 11, "z": -1, "name": "Soil_Clay_Brick_Half"},
    {"x": 2, "y": 7, "z": 0, "name": "Soil_Dirt_Poisoned"},
    {"x": 2, "y": 8, "z": 0, "name": "Soil_Dirt_Burnt"},
    {"x": 2, "y": 9, "z": 0, "name": "Soil_Clay_Brick"},
    {"x": 2, "y": 10, "z": 0, "name": "Soil_Clay_Brick"},
    {"x": 2, "y": 11, "z": 0, "name": "Soil_Clay_Brick_Half"},
    {"x": 2, "y": 6, "z": 1, "name": "Soil_Dirt_Poisoned"},
    {"x": 2, "y": 7, "z": 1, "name": "Soil_Dirt_Burnt"},
    {"x": 2, "y": 8, "z": 1, "name": "Soil_Dirt_Poisoned"},
    {"x": 2, "y": 9, "z": 1, "name": "Soil_Clay_Brick"},
    {"x": 2, "y": 10, "z": 1, "name": "Soil_Clay_Brick"},
    {"x": 2, "y": 17, "z": 1, "name": "Wood_Petrified_Branch_Long", "rotation": 5},
    {"x": 3, "y": 17, "z": 1, "name": "Wood_Ash_Branch_Corner", "rotation": 1},
    {"x": 3, "y": 18, "z": 1, "name": "Wood_Petrified_Branch_Long"},
    {"x": 3, "y": 19, "z": 1, "name": "Wood_Ash_Branch_Corner", "rotation": 9},
    {"x": 4, "y": 19, "z": 1, "name": "Wood_Ash_Branch_Corner", "rotation": 1},
    {"x": 4, "y": 20, "z": 1, "name": "Wood_Poisoned_Branch_Corner", "rotation": 9},
    {"x": 5, "y": 19, "z": 1, "name": "Wood_Ash_Branch_Corner", "rotation": 1},
    {"x": 5, "y": 20, "z": 1, "name": "Wood_Ash_Branch_Corner", "rotation": 11}
  ],
  "entities": []
}
