{
  "version": 8,
  "blockIdVersion": 11,
  "anchorX": 0,
  "anchorY": 6,
  "anchorZ": 0,
  "blocks": [
    {"x": -4, "y": 6, "z": -3, "name": "Wood_Petrified_Trunk_Full", "rotation": 4},
    {"x": -4, "y": 6, "z": 3, "name": "Wood_Ash_Trunk_Full"},
    {"x": -3, "y": 6, "z": -4, "name": "Wood_Ash_Trunk_Full", "rotation": 5},
    {"x": -3, "y": 6, "z": -3, "name": "Wood_Petrified_Trunk_Full"},
    {"x": -3, "y": 7, "z": -3, "name": "Wood_Poisoned_Trunk_Full"},
    {"x": -3, "y": 8, "z": -3, "name": "Plant_Moss_Rug_Green"},
    {"x": -3, "y": 5, "z": -2, "name": "Soil_Dirt_Burnt"},
    {"x": -3, "y": 6, "z": -2, "name": "Soil_Dirt_Poisoned"},
    {"x": -3, "y": 7, "z": -2, "name": "Wood_Poisoned_Trunk_Full"},
    {"x": -3, "y": 8, "z": -2, "name": "Plant_Moss_Rug_Green"},
    {"x": -3, "y": 4, "z": -1, "name": "Soil_Dirt_Burnt"},
    {"x": -3, "y": 5, "z": -1, "name": "Soil_Dirt_Poisoned"},
    {"x": -3, "y": 6, "z": -1, "name": "Soil_Grass_Dry"},
    {"x": -3, "y": 4, "z": 0, "name": "Soil_Dirt_Poisoned"},
    {"x": -3, "y": 5, "z": 0, "name": "Soil_Dirt_Burnt"},
    {"x": -3, "y": 6, "z": 0, "name": "Soil_Grass_Burnt"},
    {"x": -3, "y": 7, "z": 0, "name": "Wood_Petrified_Branch_Corner", "rotation": 2},
    {"x": -3, "y": 8, "z": 0, "name": "Plant_Flower_Bushy_Green", "components": {"Components": {"FarmingBlock": {}}}},
    {"x": -3, "y": 11, "z": 0, "name": "Wood_Poisoned_Branch_Long", "rotation": 5},
    {"x": -3, "y": 5, "z": 1, "name": "Soil_Dirt_Poisoned"},
    {"x": -3, "y": 6, "z": 1, "name": "Soil_Dirt_Burnt"},
    {"x": -3, "y": 7, "z": 1, "name": "Wood_Ash_Trunk_Full"},
    {"x": -3, "y": 8, "z": 1, "name": "Wood_Poisoned_Trunk_Full"},
    {"x": -3, "y": 6, "z": 2, "name": "Wood_Petrified_Trunk_Full"},
    {"x": -3, "y": 7, "z": 2, "name": "Wood_Ash_Trunk_Full"},
    {"x": -3, "y": 8, "z": 2, "name": "Plant_Moss_Rug_Green"},
    {"x": -3, "y": 6, "z": 3, "name": "Wood_Poisoned_Trunk_Full"},
    {"x": -3, "y": 7, "z": 3, "name": "Plant_Moss_Rug_Green"},
    {"x": -2, "y": 6, "z": -4, "name": "Wood_Ash_Trunk_Full", "rotation": 5},
    {"x": -2, "y": 5, "z": -3, "name": "Soil_Dirt_Burnt"},
    {"x": -2, "y": 6, "z": -3, "name": "Soil_Grass_Burnt"},
    {"x": -2, "y": 4, "z": -2, "name": "Soil_Dirt_Burnt"},
    {"x": -2, "y": 5, "z": -2, "name": "Soil_Dirt_Poisoned"},
    {"x": -2, "y": 6, "z": -2, "name": "Soil_Dirt_Burnt"},
    {"x": -2, "y": 7, "z": -2, "name": "Wood_Ash_Trunk_Full"},
    {"x": -2, "y": 8, "z": -2, "name": "Wood_Poisoned_Trunk_Full"},
    {"x": -2, "y": 3, "z": -1, "name": "Soil_Dirt_Burnt"},
    {"x": -2, "y": 4, "z": -1, "name": "Soil_Dirt_Poisoned"},
    {"x": -2, "y": 5, "z": -1, "name": "Soil_Dirt_Burnt"},
    {"x": -2, "y": 6, "z": -1, "name": "Soil_Dirt_Poisoned"},
    {"x": -2, "y": 7, "z": -1, "name": "Wood_Petrified_Trunk"},
    {"x": -2, "y": 8, "z": -1, "name": "Wood_Petrified_Trunk"},
    {"x": -2, "y": 9, "z": -1, "name": "Wood_Petrified_Trunk"},
    {"x": -2, "y": 10, "z": -1, "name": "Wood_Ash_Trunk"},
    {"x": -2, "y": 11, "z": -1, "name": "Wood_Ash_Trunk_Full"},
    {"x": -2, "y": 3, "z": 0, "name": "Soil_Dirt_Poisoned"},
    {"x": -2, "y": 4, "z": 0, "name": "Soil_Dirt_Burnt"},
    {"x": -2, "y": 5, "z": 0, "name": "Soil_Dirt_Poisoned"},
    {"x": -2, "y": 6, "z": 0, "name": "Soil_Dirt_Burnt"},
    {"x": -2, "y": 7, "z": 0, "name": "Wood_Petrified_Trunk"},
    {"x": -2, "y": 8, "z": 0, "name": "Wood_Petrified_Trunk"},
    {"x": -2, "y": 9, "z": 0, "name": "Wood_Petrified_Trunk"},
    {"x": -2, "y": 10, "z": 0, "name": "Wood_Poisoned_Trunk"},
    {"x": -2, "y": 11, "z": 0, "name": "Wood_Poisoned_Trunk_Full"},
    {"x": -2, "y": 4, "z": 1, "name": "Soil_Dirt_Poisoned"},
    {"x": -2, "y": 5, "z": 1, "name": "Soil_Dirt_Burnt"},
    {"x": -2, "y": 6, "z": 1, "name": "Soil_Dirt_Poisoned"},
    {"x": -2, "y": 7, "z": 1, "name": "Wood_Poisoned_Trunk"},
    {"x": -2, "y": 8, "z": 1, "name": "Wood_Ash_Trunk"},
    {"x": -2, "y": 9, "z": 1, "name": "Wood_Poisoned_Trunk"},
    {"x": -2, "y": 10, "z": 1, "name": "Wood_Petrified_Trunk_Full"},
    {"x": -2, "y": 11, "z": 1, "name": "Plant_Moss_Rug_Green"},
    {"x": -2, "y": 5, "z": 2, "name": "Soil_Dirt_Poisoned"},
    {"x": -2, "y": 6, "z": 2, "name": "Soil_Dirt_Burnt"},
    {"x": -2, "y": 7, "z": 2, "name": "Wood_Poisoned_Trunk_Full"},
    {"x": -2, "y": 8, "z": 2, "name": "Wood_Poisoned_Trunk_Full"},
    {"x": -1, "y": 4, "z": -3, "name": "Soil_Dirt_Burnt"},
    {"x": -1, "y": 5, "z": -3, "name": "Soil_Dirt_Poisoned"},
    {"x": -1, "y": 6, "z": -3, "name": "Soil_Grass_Dry"},
    {"x": -1, "y": 3, "z": -2, "name": "Soil_Dirt_Burnt"},
    {"x": -1, "y": 4, "z": -2, "name": "Soil_Dirt_Poisoned"},
    {"x": -1, "y": 5, "z": -2, "name": "Soil_Dirt_Burnt"},
    {"x": -1, "y": 6, "z": -2, "name": "Soil_Dirt_Poisoned"},
    {"x": -1, "y": 7, "z": -2, "name": "Wood_Petrified_Trunk"},
    {"x": -1, "y": 8, "z": -2, "name": "Wood_Poisoned_Trunk"},
    {"x": -1, "y": 9, "z": -2, "name": "Wood_Petrified_Trunk"},
    {"x": -1, "y": 10, "z": -2, "name": "Wood_Ash_Trunk"},
    {"x": -1, "y": 11, "z": -2, "name": "Wood_Petrified_Trunk_Full"},
    {"x": -1, "y": 3, "z": -1, "name": "Soil_Dirt_Poisoned"},
    {"x": -1, "y": 4, "z": -1, "name": "Soil_Dirt_Burnt"},
    {"x": -1, "y": 5, "z": -1, "name": "Soil_Dirt_Poisoned"},
    {"x": -1, "y": 6, "z": -1, "name": "Soil_Dirt_Burnt"},
    {"x": -1, "y": 7, "z": -1, "name": "Wood_Ash_Trunk"},
    {"x": -1, "y": 8, "z": -1, "name": "Wood_Ash_Trunk"},
    {"x": -1, "y": 9, "z": -1, "name": "Wood_Ash_Trunk"},
    {"x": -1, "y": 10, "z": -1, "name": "Soil_Needles"},
    {"x": -1, "y": 3, "z": 0, "name": "Soil_Dirt_Burnt"},
    {"x": -1, "y": 4, "z": 0, "name": "Soil_Dirt_Poisoned"},
    {"x": -1, "y": 5, "z": 0, "name": "Soil_Dirt_Burnt"},
    {"x": -1, "y": 6, "z": 0, "name": "Soil_Dirt_Poisoned"},
    {"x": -1, "y": 7, "z": 0, "name": "Wood_Poisoned_Trunk"},
    {"x": -1, "y": 8, "z": 0, "name": "Wood_Poisoned_Trunk"},
    {"x": -1, "y": 9, "z": 0, "name": "Wood_Poisoned_Trunk"},
    {"x": -1, "y": 10, "z": 0, "name": "Soil_Needles"},
    {"x": -1, "y": 3, "z": 1, "name": "Soil_Dirt_Poisoned"},
    {"x": -1, "y": 4, "z": 1, "name": "Soil_Dirt_Burnt"},
    {"x": -1, "y": 5, "z": 1, "name": "Soil_Dirt_Poisoned"},
    {"x": -1, "y": 6, "z": 1, "name": "Soil_Dirt_Burnt"},
    {"x": -1, "y": 7, "z": 1, "name": "Wood_Petrified_Trunk"},
    {"x": -1, "y": 8, "z": 1, "name": "Wood_Ash_Trunk"},
    {"x": -1, "y": 9, "z": 1, "name": "Wood_Petrified_Trunk"},
    {"x": -1, "y": 10, "z": 1, "name": "Soil_Needles"},
    {"x": -1, "y": 4, "z": 2, "name": "Soil_Dirt_Poisoned"},
    {"x": -1, "y": 5, "z": 2, "name": "Soil_Dirt_Burnt"},
    {"x": -1, "y": 6, "z": 2, "name": "Soil_Dirt_Poisoned"},
    {"x": -1, "y": 7, "z": 2, "name": "Wood_Ash_Trunk"},
    {"x": -1, "y": 8, "z": 2, "name": "Wood_Ash_Trunk"},
    {"x": -1, "y": 9, "z": 2, "name": "Wood_Petrified_Trunk"},
    {"x": -1, "y": 10, "z": 2, "name": "Wood_Ash_Trunk_Full"},
    {"x": -1, "y": 6, "z": 3, "name": "Soil_Dirt_Burnt"},
    {"x": -1, "y": 7, "z": 3, "name": "Wood_Poisoned_Trunk_Full"},
    {"x": -1, "y": 8, "z": 3, "name": "Wood_Petrified_Branch_Short"},
    {"x": 0, "y": 6, "z": -4, "name": "Soil_Dirt_Burnt"},
    {"x": 0, "y": 7, "z": -4, "name": "Soil_Clay_Brick_Half"},
    {"x": 0, "y": 4, "z": -3, "name": "Soil_Dirt_Poisoned"},
    {"x": 0, "y": 5, "z": -3, "name": "Soil_Dirt_Burnt"},
    {"x": 0, "y": 6, "z": -3, "name": "Soil_Dirt_Poisoned"},
    {"x": 0, "y": 7, "z": -3, "name": "Soil_Clay_Brick_Half"},
    {"x": 0, "y": 10, "z": -3, "name": "Wood_Ash_Branch_Long", "rotation": 4},
    {"x": 0, "y": 3, "z": -2, "name": "Soil_Dirt_Poisoned"},
    {"x": 0, "y": 4, "z": -2, "name": "Soil_Dirt_Burnt"},
    {"x": 0, "y": 5, "z": -2, "name": "Soil_Dirt_Poisoned"},
    {"x": 0, "y": 6, "z": -2, "name": "Soil_Dirt_Burnt"},
    {"x": 0, "y": 7, "z": -2, "name": "Wood_Poisoned_Trunk"},
    {"x": 0, "y": 8, "z": -2, "name": "Wood_Petrified_Trunk"},
    {"x": 0, "y": 9, "z": -2, "name": "Wood_Ash_Trunk"},
    {"x": 0, "y": 10, "z": -2, "name": "Wood_Poisoned_Trunk"},
    {"x": 0, "y": 11, "z": -2, "name": "Wood_Ash_Trunk_Full"},
    {"x": 0, "y": 3, "z": -1, "name": "Soil_Dirt_Burnt"},
    {"x": 0, "y": 4, "z": -1, "name": "Soil_Dirt_Poisoned"},
    {"x": 0, "y": 5, "z": -1, "name": "Soil_Dirt_Burnt"},
    {"x": 0, "y": 6, "z": -1, "name": "Soil_Dirt_Poisoned"},
    {"x": 0, "y": 7, "z": -1, "name": "Wood_Ash_Trunk"},
    {"x": 0, "y": 8, "z": -1, "name": "Wood_Ash_Trunk"},
    {"x": 0, "y": 9, "z": -1, "name": "Wood_Petrified_Trunk"},
    {"x": 0, "y": 10, "z": -1, "name": "Soil_Needles"},
    {"x": 0, "y": 11, "z": -1, "name": "Soil_Clay_Brick_Half"},
    {"x": 0, "y": 3, "z": 0, "name": "Soil_Dirt_Poisoned"},
    {"x": 0, "y": 4, "z": 0, "name": "Soil_Dirt_Burnt"},
    {"x": 0, "y": 5, "z": 0, "name": "Soil_Dirt_Poisoned"},
    {"x": 0, "y": 6, "z": 0, "name": "Soil_Dirt_Burnt"},
    {"x": 0, "y": 7, "z": 0, "name": "Wood_Poisoned_Trunk"},
    {"x": 0, "y": 8, "z": 0, "name": "Wood_Poisoned_Trunk"},
    {"x": 0, "y": 9, "z": 0, "name": "Wood_Petrified_Trunk"},
    {"x": 0, "y": 10, "z": 0, "name": "Soil_Needles"},
    {"x": 0, "y": 3, "z": 1, "name": "Soil_Dirt_Burnt"},
    {"x": 0, "y": 4, "z": 1, "name": "Soil_Dirt_Poisoned"},
    {"x": 0, "y": 5, "z": 1, "name": "Soil_Dirt_Burnt"},
    {"x": 0, "y": 6, "z": 1, "name": "Soil_Dirt_Poisoned"},
    {"x": 0, "y": 7, "z": 1, "name": "Wood_Ash_Trunk"},
    {"x": 0, "y": 8, "z": 1, "name": "Wood_Petrified_Trunk"},
    {"x": 0, "y": 9, "z": 1, "name": "Wood_Poisoned_Trunk"},
    {"x": 0, "y": 10, "z": 1, "name": "Soil_Needles"},
    {"x": 0, "y": 3, "z": 2, "name": "Soil_Dirt_Poisoned"},
    {"x": 0, "y": 4, "z": 2, "name": "Soil_Dirt_Burnt"},
    {"x": 0, "y": 5, "z": 2, "name": "Soil_Dirt_Poisoned"},
    {"x": 0, "y": 6, "z": 2, "name": "Soil_Dirt_Burnt"},
    {"x": 0, "y": 7, "z": 2, "name": "Wood_Petrified_Trunk"},
    {"x": 0, "y": 8, "z": 2, "name": "Wood_Petrified_Trunk"},
    {"x": 0, "y": 9, "z": 2, "name": "Wood_Poisoned_Trunk"},
    {"x": 0, "y": 10, "z": 2, "name": "Wood_Poisoned_Trunk"},
    {"x": 0, "y": 5, "z": 3, "name": "Soil_Dirt_Burnt"},
    {"x": 0, "y": 6, "z": 3, "name": "Soil_Dirt_Poisoned"},
    {"x": 0, "y": 7, "z": 3, "name": "Wood_Poisoned_Trunk_Full"},
    {"x": 0, "y": 8, "z": 3, "name": "Wood_Ash_Trunk_Full"},
    {"x": 1, "y": 5, "z": -4, "name": "Soil_Dirt_Burnt"},
    {"x": 1, "y": 6, "z": -4, "name": "Soil_Dirt_Poisoned"},
    {"x": 1, "y": 7, "z": -4, "name": "Soil_Clay_Brick_Half"},
    {"x": 1, "y": 4, "z": -3, "name": "Soil_Dirt_Burnt"},
    {"x": 1, "y": 5, "z": -3, "name": "Soil_Dirt_Poisoned"},
    {"x": 1, "y": 6, "z": -3, "name": "Soil_Dirt_Burnt"},
    {"x": 1, "y": 7, "z": -3, "name": "Soil_Clay_Brick"},
    {"x": 1, "y": 3, "z": -2, "name": "Soil_Dirt_Burnt"},
    {"x": 1, "y": 4, "z": -2, "name": "Soil_Dirt_Poisoned"},
    {"x": 1, "y": 5, "z": -2, "name": "Soil_Dirt_Burnt"},
    {"x": 1, "y": 6, "z": -2, "name": "Soil_Dirt_Poisoned"},
    {"x": 1, "y": 7, "z": -2, "name": "Wood_Petrified_Trunk"},
    {"x": 1, "y": 8, "z": -2, "name": "Wood_Ash_Trunk"},
    {"x": 1, "y": 9, "z": -2, "name": "Wood_Petrified_Trunk"},
    {"x": 1, "y": 10, "z": -2, "name": "Wood_Poisoned_Trunk_Full"},
    {"x": 1, "y": 11, "z": -2, "name": "Wood_Petrified_Branch_Corner", "rotation": 1},
    {"x": 1, "y": 12, "z": -2, "name": "Plant_Flower_Bushy_Green", "components": {"Components": {"FarmingBlock": {}}}},
    {"x": 1, "y": 3, "z": -1, "name": "Soil_Dirt_Poisoned"},
    {"x": 1, "y": 4, "z": -1, "name": "Soil_Dirt_Burnt"},
    {"x": 1, "y": 5, "z": -1, "name": "Soil_Dirt_Poisoned"},
    {"x": 1, "y": 6, "z": -1, "name": "Soil_Dirt_Burnt"},
    {"x": 1, "y": 7, "z": -1, "name": "Wood_Ash_Trunk"},
    {"x": 1, "y": 8, "z": -1, "name": "Wood_Petrified_Trunk"},
    {"x": 1, "y": 9, "z": -1, "name": "Wood_Ash_Trunk"},
    {"x": 1, "y": 10, "z": -1, "name": "Soil_Needles"},
    {"x": 1, "y": 11, "z": -1, "name": "Soil_Clay_Brick_Half"},
    {"x": 1, "y": 3, "z": 0, "name": "Soil_Dirt_Burnt"},
    {"x": 1, "y": 4, "z": 0, "name": "Soil_Dirt_Poisoned"},
    {"x": 1, "y": 5, "z": 0, "name": "Soil_Dirt_Burnt"},
    {"x": 1, "y": 6, "z": 0, "name": "Soil_Dirt_Poisoned"},
    {"x": 1, "y": 7, "z": 0, "name": "Wood_Poisoned_Trunk"},
    {"x": 1, "y": 8, "z": 0, "name": "Wood_Petrified_Trunk"},
    {"x": 1, "y": 9, "z": 0, "name": "Wood_Poisoned_Trunk"},
    {"x": 1, "y": 10, "z": 0, "name": "Soil_Needles"},
    {"x": 1, "y": 3, "z": 1, "name": "Soil_Dirt_Poisoned"},
    {"x": 1, "y": 4, "z": 1, "name": "Soil_Dirt_Burnt"},
    {"x": 1, "y": 5, "z": 1, "name": "Soil_Dirt_Poisoned"},
    {"x": 1, "y": 6, "z": 1, "name": "Soil_Dirt_Burnt"},
    {"x": 1, "y": 7, "z": 1, "name": "Wood_Petrified_Trunk"},
    {"x": 1, "y": 8, "z": 1, "name": "Wood_Poisoned_Trunk"},
    {"x": 1, "y": 9, "z": 1, "name": "Wood_Petrified_Trunk"},
    {"x": 1, "y": 10, "z": 1, "name": "Wood_Ash_Trunk"},
    {"x": 1, "y": 3, "z": 2, "name": "Soil_Dirt_Burnt"},
    {"x": 1, "y": 4, "z": 2, "name": "Soil_Dirt_Poisoned"},
    {"x": 1, "y": 5, "z": 2, "name": "Soil_Dirt_Burnt"},
    {"x": 1, "y": 6, "z": 2, "name": "Soil_Dirt_Poisoned"},
    {"x": 1, "y": 7, "z": 2, "name": "Wood_Petrified_Trunk"},
    {"x": 1, "y": 8, "z": 2, "name": "Wood_Ash_Trunk"},
    {"x": 1, "y": 9, "z": 2, "name": "Wood_Poisoned_Trunk"},
    {"x": 1, "y": 10, "z": 2, "name": "Soil_Clay_Brick"},
    {"x": 1, "y": 4, "z": 3, "name": "Soil_Dirt_Burnt"},
    {"x": 1, "y": 5, "z": 3, "name": "Soil_Dirt_Poisoned"},
    {"x": 1, "y": 6, "z": 3, "name": "Soil_Grass_Dry"},
    {"x": 1, "y": 9, "z": 3, "name": "Wood_Petrified_Branch_Corner"},
    {"x": 1, "y": 10, "z": 3, "name": "Wood_Petrified_Branch_Long"},
    {"x": 1, "y": 11, "z": 3, "name": "Plant_Flower_Bushy_Green", "components": {"Components": {"FarmingBlock": {}}}},
    {"x": 2, "y": 6, "z": -4, "name": "Soil_Dirt_Burnt"},
    {"x": 2, "y": 7, "z": -4, "name": "Soil_Clay_Brick"},
    {"x": 2, "y": 4, "z": -3, "name": "Soil_Dirt_Poisoned"},
    {"x": 2, "y": 5, "z": -3, "name": "Soil_Dirt_Burnt"},
    {"x": 2, "y": 6, "z": -3, "name": "Soil_Dirt_Poisoned"},
    {"x": 2, "y": 7, "z": -3, "name": "Soil_Clay_Brick"},
    {"x": 2, "y": 3, "z": -2, "name": "Soil_Dirt_Poisoned"},
    {"x": 2, "y": 4, "z": -2, "name": "Soil_Dirt_Burnt"},
    {"x": 2, "y": 5, "z": -2, "name": "Soil_Dirt_Poisoned"},
    {"x": 2, "y": 6, "z": -2, "name": "Soil_Dirt_Burnt"},
    {"x": 2, "y": 7, "z": -2, "name": "Soil_Clay_Brick"},
    {"x": 2, "y": 8, "z": -2, "name": "Soil_Clay_Brick_Half"},
    {"x": 2, "y": 3, "z": -1, "name": "Soil_Dirt_Burnt"},
    {"x": 2, "y": 4, "z": -1, "name": "Soil_Dirt_Poisoned"},
    {"x": 2, "y": 5, "z": -1, "name": "Soil_Dirt_Burnt"},
    {"x": 2, "y": 6, "z": -1, "name": "Soil_Dirt_Poisoned"},
    {"x": 2, "y": 7, "z": -1, "name": "Wood_Poisoned_Trunk"},
    {"x": 2, "y": 8, "z": -1, "name": "Wood_Petrified_Trunk"},
    {"x": 2, "y": 9, "z": -1, "name": "Wood_Petrified_Trunk"},
    {"x": 2, "y": 10, "z": -1, "name": "Wood_Ash_Trunk"},
    {"x": 2, "y": 11, "z": -1, "name": "Wood_Ash_Trunk_Full"},
    {"x": 2, "y": 3, "z": 0, "name": "Soil_Dirt_Poisoned"},
    {"x": 2, "y": 4, "z": 0, "name": "Soil_Dirt_Burnt"},
    {"x": 2, "y": 5, "z": 0, "name": "Soil_Dirt_Poisoned"},
    {"x": 2, "y": 6, "z": 0, "name": "Soil_Dirt_Burnt"},
    {"x": 2, "y": 7, "z": 0, "name": "Wood_Ash_Trunk"},
    {"x": 2, "y": 8, "z": 0, "name": "Wood_Petrified_Trunk"},
    {"x": 2, "y": 9, "z": 0, "name": "Wood_Petrified_Trunk"},
    {"x": 2, "y": 10, "z": 0, "name": "Wood_Poisoned_Trunk"},
    {"x": 2, "y": 3, "z": 1, "name": "Soil_Dirt_Burnt"},
    {"x": 2, "y": 4, "z": 1, "name": "Soil_Dirt_Poisoned"},
    {"x": 2, "y": 5, "z": 1, "name": "Soil_Dirt_Burnt"},
    {"x": 2, "y": 6, "z": 1, "name": "Soil_Dirt_Poisoned"},
    {"x": 2, "y": 7, "z": 1, "name": "Wood_Petrified_Trunk"},
    {"x": 2, "y": 8, "z": 1, "name": "Wood_Ash_Trunk"},
    {"x": 2, "y": 9, "z": 1, "name": "Wood_Poisoned_Trunk"},
    {"x": 2, "y": 10, "z": 1, "name": "Wood_Petrified_Trunk"},
    {"x": 2, "y": 4, "z": 2, "name": "Soil_Dirt_Burnt"},
    {"x": 2, "y": 5, "z": 2, "name": "Soil_Dirt_Poisoned"},
    {"x": 2, "y": 6, "z": 2, "name": "Soil_Dirt_Burnt"},
    {"x": 2, "y": 7, "z": 2, "name": "Wood_Petrified_Trunk_Full"},
    {"x": 2, "y": 9, "z": 2, "name": "Soil_Clay_Brick_Half", "rotation": 8},
    {"x": 2, "y": 10, "z": 2, "name": "Soil_Clay_Brick"},
    {"x": 2, "y": 4, "z": 3, "name": "Soil_Dirt_Poisoned"},
    {"x": 2, "y": 5, "z": 3, "name": "Soil_Dirt_Burnt"},
    {"x": 2, "y": 6, "z": 3, "name": "Wood_Petrified_Trunk_Full"},
    {"x": 2, "y": 7, "z": 3, "name": "Wood_Poisoned_Trunk_Full"},
    {"x": 2, "y": 9, "z": 3, "name": "Soil_Clay_Brick_Half", "rotation": 8},
    {"x": 2, "y": 10, "z": 3, "name": "Soil_Clay_Brick"},
    {"x": 3, "y": 5, "z": -3, "name": "Soil_Dirt_Poisoned"},
    {"x": 3, "y": 6, "z": -3, "name": "Soil_Dirt_Burnt"},
    {"x": 3, "y": 7, "z": -3, "name": "Soil_Clay_Brick"},
    {"x": 3, "y": 8, "z": -3, "name": "Soil_Clay_Brick_Half"},
    {"x": 3, "y": 4, "z": -2, "name": "Soil_Dirt_Poisoned"},
    {"x": 3, "y": 5, "z": -2, "name": "Soil_Dirt_Burnt"},
    {"x": 3, "y": 6, "z": -2, "name": "Soil_Dirt_Poisoned"},
    {"x": 3, "y": 7, "z": -2, "name": "Soil_Clay_Brick"},
    {"x": 3, "y": 8, "z": -2, "name": "Soil_Clay_Brick_Half"},
    {"x": 3, "y": 3, "z": -1, "name": "Soil_Dirt_Poisoned"},
    {"x": 3, "y": 4, "z": -1, "name": "Soil_Dirt_Burnt"},
    {"x": 3, "y": 5, "z": -1, "name": "Soil_Dirt_Poisoned"},
    {"x": 3, "y": 6, "z": -1, "name": "Soil_Grass_Dry"},
    {"x": 3, "y": 7, "z": -1, "name": "Soil_Clay_Brick_Half", "rotation": 8},
    {"x": 3, "y": 8, "z": -1, "name": "Soil_Clay_Brick"},
    {"x": 3, "y": 3, "z": 0, "name": "Soil_Dirt_Burnt"},
    {"x": 3, "y": 4, "z": 0, "name": "Soil_Dirt_Poisoned"},
    {"x": 3, "y": 5, "z": 0, "name": "Soil_Dirt_Burnt"},
    {"x": 3, "y": 6, "z": 0, "name": "Soil_Grass_Burnt"},
    {"x": 3, "y": 8, "z": 0, "name": "Soil_Clay_Brick"},
    {"x": 3, "y": 9, "z": 0, "name": "Soil_Clay_Brick_Half"},
    {"x": 3, "y": 3, "z": 1, "name": "Soil_Dirt_Poisoned"},
    {"x": 3, "y": 4, "z": 1, "name": "Soil_Dirt_Burnt"},
    {"x": 3, "y": 5, "z": 1, "name": "Soil_Dirt_Poisoned"},
    {"x": 3, "y": 6, "z": 1, "name": "Soil_Grass_Dry"},
    {"x": 3, "y": 8, "z": 1, "name": "Soil_Clay_Brick_Half", "rotation": 8},
    {"x": 3, "y": 9, "z": 1, "name": "Soil_Clay_Brick"},
    {"x": 3, "y": 4, "z": 2, "name": "Soil_Dirt_Poisoned"},
    {"x": 3, "y": 5, "z": 2, "name": "Soil_Dirt_Burnt"},
    {"x": 3, "y": 6, "z": 2, "name": "Soil_Dirt_Poisoned"},
    {"x": 3, "y": 7, "z": 2, "name": "Plant_Moss_Rug_Green"},
    {"x": 3, "y": 9, "z": 2, "name": "Soil_Clay_Brick"},
    {"x": 3, "y": 10, "z": 2, "name": "Soil_Clay_Brick_Half"},
    {"x": 3, "y": 5, "z": 3, "name": "Soil_Dirt_Poisoned"},
    {"x": 3, "y": 6, "z": 3, "name": "Wood_Ash_Trunk_Full"},
    {"x": 3, "y": 9, "z": 3, "name": "Soil_Clay_Brick_Half", "rotation": 8},
    {"x": 3, "y": 10, "z": 3, "name": "Soil_Clay_Brick"},
    {"x": 3, "y": 6, "z": 4, "name": "Wood_Poisoned_Trunk_Full"},
    {"x": 4, "y": 6, "z": -2, "name": "Soil_Grass_Dry"},
    {"x": 4, "y": 7, "z": -2, "name": "Soil_Clay_Brick_Half", "rotation": 8},
    {"x": 4, "y": 8, "z": -2, "name": "Soil_Clay_Brick"},
    {"x": 4, "y": 5, "z": -1, "name": "Soil_Dirt_Burnt"},
    {"x": 4, "y": 6, "z": -1, "name": "Soil_Grass_Burnt"},
    {"x": 4, "y": 7, "z": -1, "name": "Soil_Clay_Brick_Half", "rotation": 8},
    {"x": 4, "y": 8, "z": -1, "name": "Soil_Clay_Brick"},
    {"x": 4, "y": 4, "z": 0, "name": "Soil_Dirt_Burnt"},
    {"x": 4, "y": 5, "z": 0, "name": "Soil_Dirt_Poisoned"},
    {"x": 4, "y": 6, "z": 0, "name": "Soil_Grass_Dry"},
    {"x": 4, "y": 8, "z": 0, "name": "Soil_Clay_Brick"},
    {"x": 4, "y": 9, "z": 0, "name": "Soil_Clay_Brick_Half"},
    {"x": 4, "y": 4, "z": 1, "name": "Soil_Dirt_Poisoned"},
    {"x": 4, "y": 5, "z": 1, "name": "Soil_Dirt_Burnt"},
    {"x": 4, "y": 6, "z": 1, "name": "Soil_Grass_Burnt"},
    {"x": 4, "y": 8, "z": 1, "name": "Soil_Clay_Brick_Half", "rotation": 8},
    {"x": 4, "y": 9, "z": 1, "name": "Soil_Clay_Brick"},
    {"x": 4, "y": 5, "z": 2, "name": "Soil_Dirt_Poisoned"},
    {"x": 4, "y": 6, "z": 2, "name": "Soil_Grass_Dry"},
    {"x": 4, "y": 9, "z": 2, "name": "Soil_Clay_Brick"},
    {"x": 4, "y": 10, "z": 2, "name": "Soil_Clay_Brick_Half"},
    {"x": 4, "y": 6, "z": 3, "name": "Wood_Poisoned_Trunk_Full"}
  ],
  "entities": []
}
