{
  "version": 8,
  "blockIdVersion": 11,
  "anchorX": 0,
  "anchorY": 8,
  "anchorZ": 0,
  "blocks": [
    {"x": -3, "y": 8, "z": -4, "name": "Soil_Grass_Burnt"},
    {"x": -3, "y": 9, "z": -4, "name": "Plant_Grass_Sharp"},
    {"x": -3, "y": 10, "z": -4, "name": "Wood_Petrified_Branch_Corner", "rotation": 2},
    {"x": -3, "y": 11, "z": -4, "name": "Wood_Poisoned_Branch_Long"},
    {"x": -3, "y": 12, "z": -4, "name": "Plant_Flower_Bushy_Green", "components": {"Components": {"FarmingBlock": {}}}},
    {"x": -3, "y": 6, "z": -3, "name": "Soil_Dirt_Burnt"},
    {"x": -3, "y": 7, "z": -3, "name": "Soil_Dirt_Poisoned"},
    {"x": -3, "y": 8, "z": -3, "name": "Soil_Dirt_Burnt"},
    {"x": -3, "y": 9, "z": -3, "name": "Wood_Ash_Trunk"},
    {"x": -3, "y": 10, "z": -3, "name": "Wood_Poisoned_Trunk"},
    {"x": -3, "y": 11, "z": -3, "name": "Wood_Petrified_Trunk"},
    {"x": -3, "y": 12, "z": -3, "name": "Plant_Moss_Rug_Green", "support": 15},
    {"x": -3, "y": 6, "z": -2, "name": "Soil_Dirt_Poisoned"},
    {"x": -3, "y": 7, "z": -2, "name": "Soil_Dirt_Burnt"},
    {"x": -3, "y": 8, "z": -2, "name": "Soil_Grass_Burnt"},
    {"x": -3, "y": 9, "z": -2, "name": "Furniture_Kweebec_Shelf", "rotation": 3},
    {"x": -3, "y": 6, "z": -1, "name": "Soil_Dirt_Burnt"},
    {"x": -3, "y": 7, "z": -1, "name": "Soil_Dirt_Poisoned"},
    {"x": -3, "y": 8, "z": -1, "name": "Soil_Leaves"},
    {"x": -3, "y": 9, "z": -1, "name": "Furniture_Kweebec_Shelf", "rotation": 3},
    {"x": -3, "y": 6, "z": 0, "name": "Soil_Dirt_Poisoned"},
    {"x": -3, "y": 7, "z": 0, "name": "Soil_Dirt_Burnt"},
    {"x": -3, "y": 8, "z": 0, "name": "Soil_Leaves"},
    {"x": -3, "y": 9, "z": 0, "name": "Plant_Grass_Sharp"},
    {"x": -3, "y": 7, "z": 1, "name": "Soil_Dirt_Poisoned"},
    {"x": -3, "y": 8, "z": 1, "name": "Soil_Grass_Dry"},
    {"x": -3, "y": 9, "z": 1, "name": "Plant_Grass_Sharp_Tall"},
    {"x": -3, "y": 10, "z": 1, "name": "Plant_Grass_Sharp_Tall", "filler": 1024},
    {"x": -3, "y": 8, "z": 2, "name": "Soil_Grass_Burnt"},
    {"x": -3, "y": 9, "z": 2, "name": "Wood_Poisoned_Branch_Corner", "rotation": 3},
    {"x": -3, "y": 10, "z": 2, "name": "Plant_Flower_Bushy_Green", "components": {"Components": {"FarmingBlock": {}}}},
    {"x": -2, "y": 7, "z": -4, "name": "Soil_Dirt_Poisoned"},
    {"x": -2, "y": 8, "z": -4, "name": "Soil_Grass_Dry"},
    {"x": -2, "y": 9, "z": -4, "name": "Wood_Petrified_Branch_Short", "rotation": 2},
    {"x": -2, "y": 5, "z": -3, "name": "Soil_Dirt_Burnt"},
    {"x": -2, "y": 6, "z": -3, "name": "Soil_Dirt_Poisoned"},
    {"x": -2, "y": 7, "z": -3, "name": "Soil_Dirt_Burnt"},
    {"x": -2, "y": 8, "z": -3, "name": "Soil_Dirt_Poisoned"},
    {"x": -2, "y": 9, "z": -3, "name": "Wood_Poisoned_Trunk", "rotation": 5},
    {"x": -2, "y": 5, "z": -2, "name": "Soil_Dirt_Poisoned"},
    {"x": -2, "y": 6, "z": -2, "name": "Soil_Dirt_Burnt"},
    {"x": -2, "y": 7, "z": -2, "name": "Soil_Dirt_Poisoned"},
    {"x": -2, "y": 8, "z": -2, "name": "Soil_Dirt_Burnt"},
    {"x": -2, "y": 9, "z": -2, "name": "Wood_Ash_Trunk", "rotation": 4},
    {"x": -2, "y": 10, "z": -2, "name": "Deco_Nest"},
    {"x": -2, "y": 5, "z": -1, "name": "Soil_Dirt_Burnt"},
    {"x": -2, "y": 6, "z": -1, "name": "Soil_Dirt_Poisoned"},
    {"x": -2, "y": 7, "z": -1, "name": "Soil_Dirt_Burnt"},
    {"x": -2, "y": 8, "z": -1, "name": "Soil_Dirt_Poisoned"},
    {"x": -2, "y": 9, "z": -1, "name": "Wood_Petrified_Trunk", "rotation": 4},
    {"x": -2, "y": 10, "z": -1, "name": "Deco_Nest"},
    {"x": -2, "y": 6, "z": 0, "name": "Soil_Dirt_Burnt"},
    {"x": -2, "y": 7, "z": 0, "name": "Soil_Dirt_Poisoned"},
    {"x": -2, "y": 8, "z": 0, "name": "Soil_Dirt_Burnt"},
    {"x": -2, "y": 9, "z": 0, "name": "Wood_Petrified_Trunk", "rotation": 4},
    {"x": -2, "y": 6, "z": 1, "name": "Soil_Dirt_Poisoned"},
    {"x": -2, "y": 7, "z": 1, "name": "Soil_Dirt_Burnt"},
    {"x": -2, "y": 8, "z": 1, "name": "Soil_Dirt_Poisoned"},
    {"x": -2, "y": 9, "z": 1, "name": "Wood_Poisoned_Trunk", "rotation": 4},
    {"x": -2, "y": 7, "z": 2, "name": "Soil_Dirt_Poisoned"},
    {"x": -2, "y": 8, "z": 2, "name": "Soil_Dirt_Burnt"},
    {"x": -2, "y": 9, "z": 2, "name": "Wood_Ash_Trunk", "rotation": 4},
    {"x": -2, "y": 10, "z": 2, "name": "Deco_Nest"},
    {"x": -1, "y": 6, "z": -4, "name": "Soil_Dirt_Poisoned"},
    {"x": -1, "y": 7, "z": -4, "name": "Soil_Dirt_Burnt"},
    {"x": -1, "y": 8, "z": -4, "name": "Soil_Leaves"},
    {"x": -1, "y": 9, "z": -4, "name": "Furniture_Kweebec_Shelf", "rotation": 2},
    {"x": -1, "y": 5, "z": -3, "name": "Soil_Dirt_Poisoned"},
    {"x": -1, "y": 6, "z": -3, "name": "Soil_Dirt_Burnt"},
    {"x": -1, "y": 7, "z": -3, "name": "Soil_Dirt_Poisoned"},
    {"x": -1, "y": 8, "z": -3, "name": "Soil_Dirt_Burnt"},
    {"x": -1, "y": 9, "z": -3, "name": "Wood_Petrified_Trunk", "rotation": 5},
    {"x": -1, "y": 5, "z": -2, "name": "Soil_Dirt_Burnt"},
    {"x": -1, "y": 6, "z": -2, "name": "Soil_Dirt_Poisoned"},
    {"x": -1, "y": 7, "z": -2, "name": "Soil_Dirt_Burnt"},
    {"x": -1, "y": 8, "z": -2, "name": "Soil_Dirt_Poisoned"},
    {"x": -1, "y": 9, "z": -2, "name": "Soil_Clay_Brick_Half"},
    {"x": -1, "y": 5, "z": -1, "name": "Soil_Dirt_Poisoned"},
    {"x": -1, "y": 6, "z": -1, "name": "Soil_Dirt_Burnt"},
    {"x": -1, "y": 7, "z": -1, "name": "Soil_Dirt_Poisoned"},
    {"x": -1, "y": 8, "z": -1, "name": "Soil_Dirt_Burnt"},
    {"x": -1, "y": 9, "z": -1, "name": "Soil_Clay_Brick_Half"},
    {"x": -1, "y": 5, "z": 0, "name": "Soil_Dirt_Burnt"},
    {"x": -1, "y": 6, "z": 0, "name": "Soil_Dirt_Poisoned"},
    {"x": -1, "y": 7, "z": 0, "name": "Soil_Dirt_Burnt"},
    {"x": -1, "y": 8, "z": 0, "name": "Soil_Dirt_Poisoned"},
    {"x": -1, "y": 9, "z": 0, "name": "Soil_Clay_Brick_Half"},
    {"x": -1, "y": 5, "z": 1, "name": "Soil_Dirt_Poisoned"},
    {"x": -1, "y": 6, "z": 1, "name": "Soil_Dirt_Burnt"},
    {"x": -1, "y": 7, "z": 1, "name": "Soil_Dirt_Poisoned"},
    {"x": -1, "y": 8, "z": 1, "name": "Soil_Dirt_Burnt"},
    {"x": -1, "y": 9, "z": 1, "name": "Soil_Clay_Brick_Half"},
    {"x": -1, "y": 7, "z": 2, "name": "Soil_Dirt_Burnt"},
    {"x": -1, "y": 8, "z": 2, "name": "Soil_Dirt_Poisoned"},
    {"x": -1, "y": 9, "z": 2, "name": "Soil_Clay_Brick_Half"},
    {"x": 0, "y": 6, "z": -4, "name": "Soil_Dirt_Burnt"},
    {"x": 0, "y": 7, "z": -4, "name": "Soil_Dirt_Poisoned"},
    {"x": 0, "y": 8, "z": -4, "name": "Soil_Leaves"},
    {"x": 0, "y": 9, "z": -4, "name": "Furniture_Kweebec_Shelf", "rotation": 2},
    {"x": 0, "y": 6, "z": -3, "name": "Soil_Dirt_Poisoned"},
    {"x": 0, "y": 7, "z": -3, "name": "Soil_Dirt_Burnt"},
    {"x": 0, "y": 8, "z": -3, "name": "Soil_Dirt_Poisoned"},
    {"x": 0, "y": 9, "z": -3, "name": "Wood_Ash_Trunk", "rotation": 5},
    {"x": 0, "y": 10, "z": -3, "name": "Deco_Nest"},
    {"x": 0, "y": 5, "z": -2, "name": "Soil_Dirt_Poisoned"},
    {"x": 0, "y": 6, "z": -2, "name": "Soil_Dirt_Burnt"},
    {"x": 0, "y": 7, "z": -2, "name": "Soil_Dirt_Poisoned"},
    {"x": 0, "y": 8, "z": -2, "name": "Soil_Dirt_Burnt"},
    {"x": 0, "y": 9, "z": -2, "name": "Soil_Clay_Brick_Half"},
    {"x": 0, "y": 5, "z": -1, "name": "Soil_Dirt_Burnt"},
    {"x": 0, "y": 6, "z": -1, "name": "Soil_Dirt_Poisoned"},
    {"x": 0, "y": 7, "z": -1, "name": "Soil_Dirt_Burnt"},
    {"x": 0, "y": 8, "z": -1, "name": "Soil_Dirt_Poisoned"},
    {"x": 0, "y": 9, "z": -1, "name": "Soil_Clay_Brick_Half"},
    {"x": 0, "y": 5, "z": 0, "name": "Soil_Dirt_Poisoned"},
    {"x": 0, "y": 6, "z": 0, "name": "Soil_Dirt_Burnt"},
    {"x": 0, "y": 7, "z": 0, "name": "Soil_Dirt_Poisoned"},
    {"x": 0, "y": 8, "z": 0, "name": "Soil_Dirt_Burnt"},
    {"x": 0, "y": 9, "z": 0, "name": "Soil_Clay_Brick_Half"},
    {"x": 0, "y": 13, "z": 0, "name": "Furniture_Kweebec_Platform", "rotation": 1},
    {"x": 0, "y": 5, "z": 1, "name": "Soil_Dirt_Burnt"},
    {"x": 0, "y": 6, "z": 1, "name": "Soil_Dirt_Poisoned"},
    {"x": 0, "y": 7, "z": 1, "name": "Soil_Dirt_Burnt"},
    {"x": 0, "y": 8, "z": 1, "name": "Soil_Dirt_Poisoned"},
    {"x": 0, "y": 9, "z": 1, "name": "Soil_Clay_Brick_Half"},
    {"x": 0, "y": 11, "z": 1, "name": "Furniture_Kweebec_Lantern"},
    {"x": 0, "y": 12, "z": 1, "name": "Wood_Ash_Branch_Corner", "rotation": 9},
    {"x": 0, "y": 13, "z": 1, "name": "Furniture_Kweebec_Platform", "rotation": 1},
    {"x": 0, "y": 14, "z": 1, "name": "Plant_Moss_Rug_Green"},
    {"x": 0, "y": 6, "z": 2, "name": "Soil_Dirt_Burnt"},
    {"x": 0, "y": 7, "z": 2, "name": "Soil_Dirt_Poisoned"},
    {"x": 0, "y": 8, "z": 2, "name": "Soil_Dirt_Burnt"},
    {"x": 0, "y": 9, "z": 2, "name": "Soil_Clay_Brick_Half"},
    {"x": 1, "y": 7, "z": -4, "name": "Soil_Dirt_Burnt"},
    {"x": 1, "y": 8, "z": -4, "name": "Soil_Leaves"},
    {"x": 1, "y": 9, "z": -4, "name": "Furniture_Kweebec_Shelf", "rotation": 2},
    {"x": 1, "y": 6, "z": -3, "name": "Soil_Dirt_Burnt"},
    {"x": 1, "y": 7, "z": -3, "name": "Soil_Dirt_Poisoned"},
    {"x": 1, "y": 8, "z": -3, "name": "Soil_Dirt_Burnt"},
    {"x": 1, "y": 9, "z": -3, "name": "Wood_Poisoned_Trunk", "rotation": 5},
    {"x": 1, "y": 10, "z": -3, "name": "Deco_Nest"},
    {"x": 1, "y": 13, "z": -3, "name": "Furniture_Kweebec_Platform", "rotation": 1},
    {"x": 1, "y": 14, "z": -3, "name": "Plant_Moss_Rug_Green"},
    {"x": 1, "y": 5, "z": -2, "name": "Soil_Dirt_Burnt"},
    {"x": 1, "y": 6, "z": -2, "name": "Soil_Dirt_Poisoned"},
    {"x": 1, "y": 7, "z": -2, "name": "Soil_Dirt_Burnt"},
    {"x": 1, "y": 8, "z": -2, "name": "Soil_Dirt_Poisoned"},
    {"x": 1, "y": 9, "z": -2, "name": "Soil_Clay_Brick_Half"},
    {"x": 1, "y": 13, "z": -2, "name": "Furniture_Kweebec_Platform", "rotation": 1},
    {"x": 1, "y": 14, "z": -2, "name": "Plant_Moss_Rug_Green"},
    {"x": 1, "y": 5, "z": -1, "name": "Soil_Dirt_Poisoned"},
    {"x": 1, "y": 6, "z": -1, "name": "Soil_Dirt_Burnt"},
    {"x": 1, "y": 7, "z": -1, "name": "Soil_Dirt_Poisoned"},
    {"x": 1, "y": 8, "z": -1, "name": "Soil_Dirt_Burnt"},
    {"x": 1, "y": 9, "z": -1, "name": "Soil_Clay_Brick_Half"},
    {"x": 1, "y": 13, "z": -1, "name": "Furniture_Kweebec_Platform", "rotation": 1},
    {"x": 1, "y": 5, "z": 0, "name": "Soil_Dirt_Burnt"},
    {"x": 1, "y": 6, "z": 0, "name": "Soil_Dirt_Poisoned"},
    {"x": 1, "y": 7, "z": 0, "name": "Soil_Dirt_Burnt"},
    {"x": 1, "y": 8, "z": 0, "name": "Soil_Dirt_Poisoned"},
    {"x": 1, "y": 9, "z": 0, "name": "Soil_Clay_Brick_Half"},
    {"x": 1, "y": 13, "z": 0, "name": "Furniture_Kweebec_Platform", "rotation": 1},
    {"x": 1, "y": 6, "z": 1, "name": "Soil_Dirt_Burnt"},
    {"x": 1, "y": 7, "z": 1, "name": "Soil_Dirt_Poisoned"},
    {"x": 1, "y": 8, "z": 1, "name": "Soil_Dirt_Burnt"},
    {"x": 1, "y": 9, "z": 1, "name": "Wood_Petrified_Trunk"},
    {"x": 1, "y": 10, "z": 1, "name": "Wood_Ash_Trunk"},
    {"x": 1, "y": 11, "z": 1, "name": "Wood_Petrified_Trunk"},
    {"x": 1, "y": 12, "z": 1, "name": "Wood_Poisoned_Trunk"},
    {"x": 1, "y": 13, "z": 1, "name": "Wood_Ash_Trunk"},
    {"x": 1, "y": 14, "z": 1, "name": "Wood_Poisoned_Trunk_Full"},
    {"x": 1, "y": 6, "z": 2, "name": "Soil_Dirt_Poisoned"},
    {"x": 1, "y": 7, "z": 2, "name": "Soil_Dirt_Burnt"},
    {"x": 1, "y": 8, "z": 2, "name": "Soil_Leaves"},
    {"x": 1, "y": 9, "z": 2, "name": "Plant_Grass_Sharp"},
    {"x": 2, "y": 7, "z": -4, "name": "Soil_Dirt_Poisoned"},
    {"x": 2, "y": 8, "z": -4, "name": "Soil_Dirt_Burnt"},
    {"x": 2, "y": 9, "z": -4, "name": "Wood_Petrified_Trunk", "rotation": 4},
    {"x": 2, "y": 12, "z": -4, "name": "Furniture_Kweebec_Lantern"},
    {"x": 2, "y": 13, "z": -4, "name": "Wood_Petrified_Branch_Corner", "rotation": 8},
    {"x": 2, "y": 7, "z": -3, "name": "Soil_Dirt_Burnt"},
    {"x": 2, "y": 8, "z": -3, "name": "Soil_Dirt_Poisoned"},
    {"x": 2, "y": 9, "z": -3, "name": "Wood_Poisoned_Trunk"},
    {"x": 2, "y": 10, "z": -3, "name": "Wood_Petrified_Trunk"},
    {"x": 2, "y": 11, "z": -3, "name": "Wood_Poisoned_Trunk"},
    {"x": 2, "y": 12, "z": -3, "name": "Wood_Ash_Trunk"},
    {"x": 2, "y": 13, "z": -3, "name": "Wood_Poisoned_Trunk"},
    {"x": 2, "y": 14, "z": -3, "name": "Wood_Poisoned_Trunk_Full"},
    {"x": 2, "y": 6, "z": -2, "name": "Soil_Dirt_Burnt"},
    {"x": 2, "y": 7, "z": -2, "name": "Soil_Dirt_Poisoned"},
    {"x": 2, "y": 8, "z": -2, "name": "Soil_Dirt_Burnt"},
    {"x": 2, "y": 9, "z": -2, "name": "Soil_Clay_Brick_Half"},
    {"x": 2, "y": 13, "z": -2, "name": "Furniture_Kweebec_Platform", "rotation": 1},
    {"x": 2, "y": 14, "z": -2, "name": "Plant_Moss_Rug_Green"},
    {"x": 2, "y": 6, "z": -1, "name": "Soil_Dirt_Poisoned"},
    {"x": 2, "y": 7, "z": -1, "name": "Soil_Dirt_Burnt"},
    {"x": 2, "y": 8, "z": -1, "name": "Soil_Dirt_Poisoned"},
    {"x": 2, "y": 9, "z": -1, "name": "Wood_Petrified_Trunk", "rotation": 4},
    {"x": 2, "y": 13, "z": -1, "name": "Furniture_Kweebec_Platform", "rotation": 1},
    {"x": 2, "y": 14, "z": -1, "name": "Plant_Moss_Rug_Green"},
    {"x": 2, "y": 5, "z": 0, "name": "Soil_Dirt_Poisoned"},
    {"x": 2, "y": 6, "z": 0, "name": "Soil_Dirt_Burnt"},
    {"x": 2, "y": 7, "z": 0, "name": "Soil_Dirt_Poisoned"},
    {"x": 2, "y": 8, "z": 0, "name": "Soil_Dirt_Burnt"},
    {"x": 2, "y": 9, "z": 0, "name": "Wood_Petrified_Trunk", "rotation": 4},
    {"x": 2, "y": 13, "z": 0, "name": "Furniture_Kweebec_Platform", "rotation": 1},
    {"x": 2, "y": 6, "z": 1, "name": "Soil_Dirt_Poisoned"},
    {"x": 2, "y": 7, "z": 1, "name": "Soil_Dirt_Burnt"},
    {"x": 2, "y": 8, "z": 1, "name": "Soil_Dirt_Poisoned"},
    {"x": 2, "y": 9, "z": 1, "name": "Wood_Poisoned_Trunk", "rotation": 5},
    {"x": 2, "y": 13, "z": 1, "name": "Furniture_Kweebec_Platform", "rotation": 1},
    {"x": 2, "y": 6, "z": 2, "name": "Soil_Dirt_Burnt"},
    {"x": 2, "y": 7, "z": 2, "name": "Soil_Dirt_Poisoned"},
    {"x": 2, "y": 8, "z": 2, "name": "Soil_Leaves"},
    {"x": 2, "y": 9, "z": 2, "name": "Plant_Moss_Rug_Green"},
    {"x": 3, "y": 8, "z": -4, "name": "Soil_Grass_Burnt"},
    {"x": 3, "y": 7, "z": -3, "name": "Soil_Dirt_Poisoned"},
    {"x": 3, "y": 8, "z": -3, "name": "Soil_Dirt_Burnt"},
    {"x": 3, "y": 9, "z": -3, "name": "Wood_Poisoned_Trunk_Full", "rotation": 5},
    {"x": 3, "y": 13, "z": -3, "name": "Furniture_Kweebec_Platform", "rotation": 1},
    {"x": 3, "y": 14, "z": -3, "name": "Plant_Moss_Rug_Green"},
    {"x": 3, "y": 6, "z": -2, "name": "Soil_Dirt_Poisoned"},
    {"x": 3, "y": 7, "z": -2, "name": "Soil_Dirt_Burnt"},
    {"x": 3, "y": 8, "z": -2, "name": "Soil_Grass_Burnt"},
    {"x": 3, "y": 9, "z": -2, "name": "Plant_Grass_Sharp"},
    {"x": 3, "y": 13, "z": -2, "name": "Furniture_Kweebec_Platform", "rotation": 1},
    {"x": 3, "y": 14, "z": -2, "name": "Plant_Moss_Rug_Green"},
    {"x": 3, "y": 6, "z": -1, "name": "Soil_Dirt_Burnt"},
    {"x": 3, "y": 7, "z": -1, "name": "Soil_Dirt_Poisoned"},
    {"x": 3, "y": 8, "z": -1, "name": "Soil_Grass_Dry"},
    {"x": 3, "y": 9, "z": -1, "name": "Wood_Petrified_Branch_Short", "rotation": 1},
    {"x": 3, "y": 13, "z": -1, "name": "Furniture_Kweebec_Platform", "rotation": 1},
    {"x": 3, "y": 14, "z": -1, "name": "Plant_Moss_Rug_Green"},
    {"x": 3, "y": 6, "z": 0, "name": "Soil_Dirt_Poisoned"},
    {"x": 3, "y": 7, "z": 0, "name": "Soil_Dirt_Burnt"},
    {"x": 3, "y": 8, "z": 0, "name": "Soil_Leaves"},
    {"x": 3, "y": 9, "z": 0, "name": "Block_Spawner_Block", "components": {"Components": {"BlockSpawner": {"BlockSpawnerId": "Zone1_Kweebec_Tier1"}}}, "rotation": 1},
    {"x": 3, "y": 7, "z": 1, "name": "Soil_Dirt_Poisoned"},
    {"x": 3, "y": 8, "z": 1, "name": "Soil_Dirt_Burnt"},
    {"x": 3, "y": 9, "z": 1, "name": "Wood_Ash_Trunk", "rotation": 5},
    {"x": 3, "y": 7, "z": 2, "name": "Soil_Dirt_Burnt"},
    {"x": 3, "y": 8, "z": 2, "name": "Soil_Grass_Burnt"},
    {"x": 3, "y": 9, "z": 2, "name": "Wood_Ash_Branch_Corner", "rotation": 10}
  ],
  "entities": []
}
