{
  "version": 8,
  "blockIdVersion": 11,
  "anchorX": 1,
  "anchorY": 12,
  "anchorZ": 1,
  "blocks": [
    {"x": -2, "y": 8, "z": -1, "name": "Soil_Dirt_Poisoned"},
    {"x": -2, "y": 9, "z": -1, "name": "Soil_Dirt_Burnt"},
    {"x": -2, "y": 10, "z": -1, "name": "Soil_Dirt_Poisoned"},
    {"x": -2, "y": 11, "z": -1, "name": "Soil_Dirt_Burnt"},
    {"x": -2, "y": 12, "z": -1, "name": "Soil_Leaves"},
    {"x": -2, "y": 6, "z": 0, "name": "Soil_Dirt_Burnt"},
    {"x": -2, "y": 7, "z": 0, "name": "Soil_Dirt_Poisoned"},
    {"x": -2, "y": 8, "z": 0, "name": "Soil_Dirt_Burnt"},
    {"x": -2, "y": 9, "z": 0, "name": "Soil_Dirt_Poisoned"},
    {"x": -2, "y": 10, "z": 0, "name": "Soil_Dirt_Burnt"},
    {"x": -2, "y": 11, "z": 0, "name": "Soil_Dirt_Poisoned"},
    {"x": -2, "y": 12, "z": 0, "name": "Soil_Leaves"},
    {"x": -2, "y": 8, "z": 1, "name": "Soil_Dirt_Poisoned"},
    {"x": -2, "y": 9, "z": 1, "name": "Soil_Dirt_Burnt"},
    {"x": -2, "y": 10, "z": 1, "name": "Soil_Dirt_Poisoned"},
    {"x": -2, "y": 11, "z": 1, "name": "Soil_Dirt_Burnt"},
    {"x": -2, "y": 12, "z": 1, "name": "Soil_Grass_Burnt"},
    {"x": -2, "y": 9, "z": 2, "name": "Soil_Dirt_Poisoned"},
    {"x": -2, "y": 10, "z": 2, "name": "Soil_Dirt_Burnt"},
    {"x": -2, "y": 11, "z": 2, "name": "Soil_Dirt_Poisoned"},
    {"x": -2, "y": 12, "z": 2, "name": "Soil_Grass_Dry"},
    {"x": -1, "y": 6, "z": -2, "name": "Soil_Dirt_Poisoned"},
    {"x": -1, "y": 7, "z": -2, "name": "Soil_Dirt_Burnt"},
    {"x": -1, "y": 8, "z": -2, "name": "Soil_Dirt_Poisoned"},
    {"x": -1, "y": 9, "z": -2, "name": "Soil_Dirt_Burnt"},
    {"x": -1, "y": 10, "z": -2, "name": "Soil_Dirt_Poisoned"},
    {"x": -1, "y": 11, "z": -2, "name": "Soil_Dirt_Burnt"},
    {"x": -1, "y": 12, "z": -2, "name": "Soil_Leaves"},
    {"x": -1, "y": 13, "z": -2, "name": "Plant_Grass_Sharp"},
    {"x": -1, "y": 6, "z": -1, "name": "Soil_Dirt_Burnt"},
    {"x": -1, "y": 7, "z": -1, "name": "Soil_Dirt_Poisoned"},
    {"x": -1, "y": 8, "z": -1, "name": "Soil_Dirt_Burnt"},
    {"x": -1, "y": 9, "z": -1, "name": "Soil_Dirt_Poisoned"},
    {"x": -1, "y": 10, "z": -1, "name": "Soil_Dirt_Burnt"},
    {"x": -1, "y": 11, "z": -1, "name": "Soil_Dirt_Poisoned"},
    {"x": -1, "y": 12, "z": -1, "name": "Soil_Leaves"},
    {"x": -1, "y": 13, "z": -1, "name": "Plant_Grass_Sharp"},
    {"x": -1, "y": 5, "z": 0, "name": "Soil_Dirt_Burnt"},
    {"x": -1, "y": 6, "z": 0, "name": "Soil_Dirt_Poisoned"},
    {"x": -1, "y": 7, "z": 0, "name": "Soil_Dirt_Burnt"},
    {"x": -1, "y": 8, "z": 0, "name": "Soil_Dirt_Poisoned"},
    {"x": -1, "y": 9, "z": 0, "name": "Soil_Dirt_Burnt"},
    {"x": -1, "y": 10, "z": 0, "name": "Soil_Dirt_Poisoned"},
    {"x": -1, "y": 11, "z": 0, "name": "Soil_Dirt_Burnt"},
    {"x": -1, "y": 12, "z": 0, "name": "Soil_Grass_Burnt"},
    {"x": -1, "y": 4, "z": 1, "name": "Soil_Dirt_Burnt"},
    {"x": -1, "y": 5, "z": 1, "name": "Soil_Dirt_Poisoned"},
    {"x": -1, "y": 6, "z": 1, "name": "Soil_Dirt_Burnt"},
    {"x": -1, "y": 7, "z": 1, "name": "Soil_Dirt_Poisoned"},
    {"x": -1, "y": 8, "z": 1, "name": "Soil_Dirt_Burnt"},
    {"x": -1, "y": 9, "z": 1, "name": "Soil_Dirt_Poisoned"},
    {"x": -1, "y": 10, "z": 1, "name": "Soil_Dirt_Burnt"},
    {"x": -1, "y": 11, "z": 1, "name": "Soil_Dirt_Poisoned"},
    {"x": -1, "y": 12, "z": 1, "name": "Soil_Grass_Dry"},
    {"x": -1, "y": 4, "z": 2, "name": "Soil_Dirt_Poisoned"},
    {"x": -1, "y": 5, "z": 2, "name": "Soil_Dirt_Burnt"},
    {"x": -1, "y": 6, "z": 2, "name": "Soil_Dirt_Poisoned"},
    {"x": -1, "y": 7, "z": 2, "name": "Soil_Dirt_Burnt"},
    {"x": -1, "y": 8, "z": 2, "name": "Soil_Dirt_Poisoned"},
    {"x": -1, "y": 9, "z": 2, "name": "Soil_Dirt_Burnt"},
    {"x": -1, "y": 10, "z": 2, "name": "Soil_Dirt_Poisoned"},
    {"x": -1, "y": 11, "z": 2, "name": "Soil_Dirt_Burnt"},
    {"x": -1, "y": 12, "z": 2, "name": "Soil_Grass_Burnt"},
    {"x": -1, "y": 13, "z": 2, "name": "Plant_Grass_Sharp"},
    {"x": -1, "y": 7, "z": 3, "name": "Soil_Dirt_Poisoned"},
    {"x": -1, "y": 8, "z": 3, "name": "Soil_Dirt_Burnt"},
    {"x": -1, "y": 9, "z": 3, "name": "Soil_Dirt_Poisoned"},
    {"x": -1, "y": 10, "z": 3, "name": "Soil_Dirt_Burnt"},
    {"x": -1, "y": 11, "z": 3, "name": "Soil_Dirt_Poisoned"},
    {"x": -1, "y": 12, "z": 3, "name": "Soil_Grass_Dry"},
    {"x": -1, "y": 13, "z": 3, "name": "Plant_Grass_Sharp"},
    {"x": 0, "y": 8, "z": -2, "name": "Soil_Dirt_Burnt"},
    {"x": 0, "y": 9, "z": -2, "name": "Soil_Dirt_Poisoned"},
    {"x": 0, "y": 10, "z": -2, "name": "Soil_Dirt_Burnt"},
    {"x": 0, "y": 11, "z": -2, "name": "Soil_Dirt_Poisoned"},
    {"x": 0, "y": 12, "z": -2, "name": "Soil_Leaves"},
    {"x": 0, "y": 13, "z": -2, "name": "Plant_Grass_Sharp"},
    {"x": 0, "y": 6, "z": -1, "name": "Soil_Dirt_Poisoned"},
    {"x": 0, "y": 7, "z": -1, "name": "Soil_Dirt_Burnt"},
    {"x": 0, "y": 8, "z": -1, "name": "Soil_Dirt_Poisoned"},
    {"x": 0, "y": 9, "z": -1, "name": "Soil_Dirt_Burnt"},
    {"x": 0, "y": 10, "z": -1, "name": "Soil_Dirt_Poisoned"},
    {"x": 0, "y": 11, "z": -1, "name": "Soil_Dirt_Burnt"},
    {"x": 0, "y": 12, "z": -1, "name": "Soil_Pathway"},
    {"x": 0, "y": 13, "z": -1, "name": "Container_Bucket"},
    {"x": 0, "y": 4, "z": 0, "name": "Soil_Clay_Brick"},
    {"x": 0, "y": 5, "z": 0, "name": "Soil_Clay_Brick"},
    {"x": 0, "y": 6, "z": 0, "name": "Soil_Clay_Brick"},
    {"x": 0, "y": 7, "z": 0, "name": "Soil_Clay_Brick"},
    {"x": 0, "y": 8, "z": 0, "name": "Soil_Clay_Brick"},
    {"x": 0, "y": 9, "z": 0, "name": "Soil_Clay_Brick"},
    {"x": 0, "y": 10, "z": 0, "name": "Soil_Clay_Brick"},
    {"x": 0, "y": 11, "z": 0, "name": "Soil_Clay_Brick"},
    {"x": 0, "y": 12, "z": 0, "name": "Soil_Clay_Brick"},
    {"x": 0, "y": 4, "z": 1, "name": "Soil_Clay_Brick"},
    {"x": 0, "y": 5, "z": 1, "name": "Soil_Clay_Brick"},
    {"x": 0, "y": 6, "z": 1, "name": "Soil_Clay_Brick"},
    {"x": 0, "y": 7, "z": 1, "name": "Soil_Clay_Brick"},
    {"x": 0, "y": 8, "z": 1, "name": "Soil_Clay_Brick"},
    {"x": 0, "y": 9, "z": 1, "name": "Soil_Clay_Brick"},
    {"x": 0, "y": 10, "z": 1, "name": "Soil_Clay_Brick"},
    {"x": 0, "y": 11, "z": 1, "name": "Soil_Clay_Brick"},
    {"x": 0, "y": 12, "z": 1, "name": "Soil_Clay_Brick"},
    {"x": 0, "y": 4, "z": 2, "name": "Soil_Dirt_Burnt"},
    {"x": 0, "y": 5, "z": 2, "name": "Soil_Dirt_Poisoned"},
    {"x": 0, "y": 6, "z": 2, "name": "Soil_Dirt_Burnt"},
    {"x": 0, "y": 7, "z": 2, "name": "Soil_Dirt_Poisoned"},
    {"x": 0, "y": 8, "z": 2, "name": "Soil_Dirt_Burnt"},
    {"x": 0, "y": 9, "z": 2, "name": "Soil_Dirt_Poisoned"},
    {"x": 0, "y": 10, "z": 2, "name": "Soil_Dirt_Burnt"},
    {"x": 0, "y": 11, "z": 2, "name": "Soil_Dirt_Poisoned"},
    {"x": 0, "y": 12, "z": 2, "name": "Wood_Ash_Trunk_Full"},
    {"x": 0, "y": 13, "z": 2, "name": "Wood_Poisoned_Trunk_Full"},
    {"x": 0, "y": 5, "z": 3, "name": "Soil_Dirt_Burnt"},
    {"x": 0, "y": 6, "z": 3, "name": "Soil_Dirt_Poisoned"},
    {"x": 0, "y": 7, "z": 3, "name": "Soil_Dirt_Burnt"},
    {"x": 0, "y": 8, "z": 3, "name": "Soil_Dirt_Poisoned"},
    {"x": 0, "y": 9, "z": 3, "name": "Soil_Dirt_Burnt"},
    {"x": 0, "y": 10, "z": 3, "name": "Soil_Dirt_Poisoned"},
    {"x": 0, "y": 11, "z": 3, "name": "Soil_Dirt_Burnt"},
    {"x": 0, "y": 12, "z": 3, "name": "Soil_Grass_Burnt"},
    {"x": 0, "y": 13, "z": 3, "name": "Plant_Grass_Sharp"},
    {"x": 1, "y": 10, "z": -2, "name": "Wood_Poisoned_Roots"},
    {"x": 1, "y": 11, "z": -2, "name": "Wood_Petrified_Trunk_Full"},
    {"x": 1, "y": 12, "z": -2, "name": "Wood_Ash_Trunk"},
    {"x": 1, "y": 13, "z": -2, "name": "Wood_Poisoned_Trunk_Full"},
    {"x": 1, "y": 4, "z": -1, "name": "Soil_Clay_Brick"},
    {"x": 1, "y": 5, "z": -1, "name": "Soil_Clay_Brick"},
    {"x": 1, "y": 6, "z": -1, "name": "Soil_Clay_Brick"},
    {"x": 1, "y": 7, "z": -1, "name": "Soil_Clay_Brick"},
    {"x": 1, "y": 8, "z": -1, "name": "Soil_Clay_Brick"},
    {"x": 1, "y": 9, "z": -1, "name": "Soil_Clay_Brick"},
    {"x": 1, "y": 10, "z": -1, "name": "Soil_Clay_Brick"},
    {"x": 1, "y": 11, "z": -1, "name": "Soil_Clay_Brick"},
    {"x": 1, "y": 12, "z": -1, "name": "Soil_Clay_Brick"},
    {"x": 1, "y": 15, "z": -1, "name": "Furniture_Kweebec_Platform", "rotation": 1},
    {"x": 1, "y": 16, "z": -1, "name": "Wood_Ash_Branch_Corner", "rotation": 3},
    {"x": 1, "y": 4, "z": 0, "name": "Soil_Clay_Brick"},
    {"x": 1, "y": 7, "z": 0, "name": "Empty"},
    {"x": 1, "y": 8, "z": 0, "name": "Empty"},
    {"x": 1, "y": 9, "z": 0, "name": "Empty"},
    {"x": 1, "y": 10, "z": 0, "name": "Empty"},
    {"x": 1, "y": 11, "z": 0, "name": "Empty"},
    {"x": 1, "y": 12, "z": 0, "name": "Empty"},
    {"x": 1, "y": 13, "z": 0, "name": "Empty"},
    {"x": 1, "y": 14, "z": 0, "name": "Empty"},
    {"x": 1, "y": 15, "z": 0, "name": "Furniture_Kweebec_Platform"},
    {"x": 1, "y": 4, "z": 1, "name": "Soil_Clay_Brick"},
    {"x": 1, "y": 7, "z": 1, "name": "Empty"},
    {"x": 1, "y": 8, "z": 1, "name": "Empty"},
    {"x": 1, "y": 9, "z": 1, "name": "Empty"},
    {"x": 1, "y": 10, "z": 1, "name": "Empty"},
    {"x": 1, "y": 11, "z": 1, "name": "Empty"},
    {"x": 1, "y": 12, "z": 1, "name": "Soil_Clay_Brick"},
    {"x": 1, "y": 14, "z": 1, "name": "Empty"},
    {"x": 1, "y": 15, "z": 1, "name": "Furniture_Kweebec_Platform"},
    {"x": 1, "y": 4, "z": 2, "name": "Soil_Clay_Brick"},
    {"x": 1, "y": 5, "z": 2, "name": "Soil_Clay_Brick"},
    {"x": 1, "y": 6, "z": 2, "name": "Soil_Clay_Brick"},
    {"x": 1, "y": 7, "z": 2, "name": "Soil_Clay_Brick"},
    {"x": 1, "y": 8, "z": 2, "name": "Soil_Clay_Brick"},
    {"x": 1, "y": 9, "z": 2, "name": "Soil_Clay_Brick"},
    {"x": 1, "y": 10, "z": 2, "name": "Soil_Clay_Brick"},
    {"x": 1, "y": 11, "z": 2, "name": "Soil_Clay_Brick"},
    {"x": 1, "y": 12, "z": 2, "name": "Soil_Clay_Brick"},
    {"x": 1, "y": 13, "z": 2, "name": "Wood_Poisoned_Trunk_Full"},
    {"x": 1, "y": 14, "z": 2, "name": "Wood_Poisoned_Trunk"},
    {"x": 1, "y": 15, "z": 2, "name": "Wood_Ash_Trunk_Full"},
    {"x": 1, "y": 4, "z": 3, "name": "Soil_Dirt_Burnt"},
    {"x": 1, "y": 5, "z": 3, "name": "Soil_Dirt_Poisoned"},
    {"x": 1, "y": 6, "z": 3, "name": "Soil_Dirt_Burnt"},
    {"x": 1, "y": 7, "z": 3, "name": "Soil_Dirt_Poisoned"},
    {"x": 1, "y": 8, "z": 3, "name": "Soil_Dirt_Burnt"},
    {"x": 1, "y": 9, "z": 3, "name": "Soil_Dirt_Poisoned"},
    {"x": 1, "y": 10, "z": 3, "name": "Soil_Dirt_Burnt"},
    {"x": 1, "y": 11, "z": 3, "name": "Wood_Ash_Trunk_Full"},
    {"x": 1, "y": 12, "z": 3, "name": "Wood_Petrified_Trunk"},
    {"x": 1, "y": 13, "z": 3, "name": "Wood_Petrified_Trunk"},
    {"x": 1, "y": 14, "z": 3, "name": "Wood_Ash_Trunk_Full"},
    {"x": 1, "y": 9, "z": 4, "name": "Soil_Dirt_Burnt"},
    {"x": 1, "y": 10, "z": 4, "name": "Soil_Dirt_Poisoned"},
    {"x": 1, "y": 11, "z": 4, "name": "Soil_Dirt_Burnt"},
    {"x": 1, "y": 12, "z": 4, "name": "Soil_Leaves"},
    {"x": 2, "y": 15, "z": -3, "name": "Wood_Ash_Branch_Corner", "rotation": 2},
    {"x": 2, "y": 14, "z": -2, "name": "Wood_Poisoned_Trunk_Full"},
    {"x": 2, "y": 15, "z": -2, "name": "Wood_Ash_Trunk_Full"},
    {"x": 2, "y": 4, "z": -1, "name": "Soil_Clay_Brick"},
    {"x": 2, "y": 5, "z": -1, "name": "Soil_Clay_Brick"},
    {"x": 2, "y": 6, "z": -1, "name": "Soil_Clay_Brick"},
    {"x": 2, "y": 7, "z": -1, "name": "Soil_Clay_Brick"},
    {"x": 2, "y": 8, "z": -1, "name": "Soil_Clay_Brick"},
    {"x": 2, "y": 9, "z": -1, "name": "Soil_Clay_Brick"},
    {"x": 2, "y": 10, "z": -1, "name": "Soil_Clay_Brick"},
    {"x": 2, "y": 11, "z": -1, "name": "Soil_Clay_Brick"},
    {"x": 2, "y": 12, "z": -1, "name": "Soil_Clay_Brick"},
    {"x": 2, "y": 15, "z": -1, "name": "Wood_Petrified_Trunk", "rotation": 4},
    {"x": 2, "y": 16, "z": -1, "name": "Wood_Poisoned_Branch_Corner", "rotation": 11},
    {"x": 2, "y": 4, "z": 0, "name": "Soil_Clay_Brick"},
    {"x": 2, "y": 7, "z": 0, "name": "Empty"},
    {"x": 2, "y": 8, "z": 0, "name": "Deco_Rope"},
    {"x": 2, "y": 9, "z": 0, "name": "Deco_Rope"},
    {"x": 2, "y": 10, "z": 0, "name": "Deco_Rope"},
    {"x": 2, "y": 11, "z": 0, "name": "Deco_Rope"},
    {"x": 2, "y": 12, "z": 0, "name": "Deco_Rope"},
    {"x": 2, "y": 13, "z": 0, "name": "Deco_Rope"},
    {"x": 2, "y": 14, "z": 0, "name": "Deco_Rope"},
    {"x": 2, "y": 15, "z": 0, "name": "Wood_Petrified_Trunk", "rotation": 4},
    {"x": 2, "y": 4, "z": 1, "name": "Soil_Clay_Brick"},
    {"x": 2, "y": 7, "z": 1, "name": "Empty"},
    {"x": 2, "y": 8, "z": 1, "name": "Empty"},
    {"x": 2, "y": 9, "z": 1, "name": "Empty"},
    {"x": 2, "y": 10, "z": 1, "name": "Empty"},
    {"x": 2, "y": 11, "z": 1, "name": "Empty"},
    {"x": 2, "y": 12, "z": 1, "name": "Empty"},
    {"x": 2, "y": 13, "z": 1, "name": "Empty"},
    {"x": 2, "y": 14, "z": 1, "name": "Empty"},
    {"x": 2, "y": 15, "z": 1, "name": "Wood_Poisoned_Trunk", "rotation": 4},
    {"x": 2, "y": 4, "z": 2, "name": "Soil_Clay_Brick"},
    {"x": 2, "y": 5, "z": 2, "name": "Soil_Clay_Brick"},
    {"x": 2, "y": 6, "z": 2, "name": "Soil_Clay_Brick"},
    {"x": 2, "y": 7, "z": 2, "name": "Soil_Clay_Brick"},
    {"x": 2, "y": 8, "z": 2, "name": "Soil_Clay_Brick"},
    {"x": 2, "y": 9, "z": 2, "name": "Soil_Clay_Brick"},
    {"x": 2, "y": 10, "z": 2, "name": "Soil_Clay_Brick"},
    {"x": 2, "y": 11, "z": 2, "name": "Soil_Clay_Brick"},
    {"x": 2, "y": 12, "z": 2, "name": "Soil_Clay_Brick"},
    {"x": 2, "y": 15, "z": 2, "name": "Wood_Poisoned_Trunk_Full"},
    {"x": 2, "y": 16, "z": 2, "name": "Wood_Petrified_Trunk_Full"},
    {"x": 2, "y": 17, "z": 2, "name": "Furniture_Kweebec_Lantern"},
    {"x": 2, "y": 6, "z": 3, "name": "Soil_Dirt_Poisoned"},
    {"x": 2, "y": 7, "z": 3, "name": "Soil_Dirt_Burnt"},
    {"x": 2, "y": 8, "z": 3, "name": "Soil_Dirt_Poisoned"},
    {"x": 2, "y": 9, "z": 3, "name": "Soil_Dirt_Burnt"},
    {"x": 2, "y": 10, "z": 3, "name": "Soil_Dirt_Poisoned"},
    {"x": 2, "y": 11, "z": 3, "name": "Soil_Dirt_Burnt"},
    {"x": 2, "y": 12, "z": 3, "name": "Soil_Grass_Burnt"},
    {"x": 2, "y": 15, "z": 3, "name": "Wood_Ash_Branch_Short"},
    {"x": 2, "y": 8, "z": 4, "name": "Soil_Dirt_Burnt"},
    {"x": 2, "y": 9, "z": 4, "name": "Soil_Dirt_Poisoned"},
    {"x": 2, "y": 10, "z": 4, "name": "Soil_Dirt_Burnt"},
    {"x": 2, "y": 11, "z": 4, "name": "Soil_Dirt_Poisoned"},
    {"x": 2, "y": 12, "z": 4, "name": "Soil_Leaves"},
    {"x": 3, "y": 6, "z": -2, "name": "Soil_Dirt_Poisoned"},
    {"x": 3, "y": 7, "z": -2, "name": "Soil_Dirt_Burnt"},
    {"x": 3, "y": 8, "z": -2, "name": "Soil_Dirt_Poisoned"},
    {"x": 3, "y": 9, "z": -2, "name": "Soil_Dirt_Burnt"},
    {"x": 3, "y": 10, "z": -2, "name": "Soil_Dirt_Poisoned"},
    {"x": 3, "y": 11, "z": -2, "name": "Soil_Dirt_Burnt"},
    {"x": 3, "y": 12, "z": -2, "name": "Wood_Poisoned_Trunk_Full"},
    {"x": 3, "y": 13, "z": -2, "name": "Wood_Petrified_Trunk"},
    {"x": 3, "y": 14, "z": -2, "name": "Wood_Poisoned_Trunk_Full"},
    {"x": 3, "y": 5, "z": -1, "name": "Soil_Dirt_Poisoned"},
    {"x": 3, "y": 6, "z": -1, "name": "Soil_Dirt_Burnt"},
    {"x": 3, "y": 7, "z": -1, "name": "Soil_Dirt_Poisoned"},
    {"x": 3, "y": 8, "z": -1, "name": "Soil_Dirt_Burnt"},
    {"x": 3, "y": 9, "z": -1, "name": "Soil_Dirt_Poisoned"},
    {"x": 3, "y": 10, "z": -1, "name": "Wood_Petrified_Trunk_Full"},
    {"x": 3, "y": 11, "z": -1, "name": "Wood_Petrified_Trunk"},
    {"x": 3, "y": 12, "z": -1, "name": "Wood_Ash_Trunk_Full"},
    {"x": 3, "y": 4, "z": 0, "name": "Soil_Clay_Brick"},
    {"x": 3, "y": 5, "z": 0, "name": "Soil_Clay_Brick"},
    {"x": 3, "y": 6, "z": 0, "name": "Soil_Clay_Brick"},
    {"x": 3, "y": 7, "z": 0, "name": "Soil_Clay_Brick"},
    {"x": 3, "y": 8, "z": 0, "name": "Soil_Clay_Brick"},
    {"x": 3, "y": 9, "z": 0, "name": "Soil_Clay_Brick"},
    {"x": 3, "y": 10, "z": 0, "name": "Soil_Clay_Brick"},
    {"x": 3, "y": 11, "z": 0, "name": "Soil_Pathway"},
    {"x": 3, "y": 12, "z": 0, "name": "Soil_Grass_Burnt"},
    {"x": 3, "y": 15, "z": 0, "name": "Furniture_Kweebec_Platform"},
    {"x": 3, "y": 4, "z": 1, "name": "Soil_Clay_Brick"},
    {"x": 3, "y": 5, "z": 1, "name": "Soil_Clay_Brick"},
    {"x": 3, "y": 6, "z": 1, "name": "Soil_Clay_Brick"},
    {"x": 3, "y": 7, "z": 1, "name": "Soil_Clay_Brick"},
    {"x": 3, "y": 8, "z": 1, "name": "Soil_Clay_Brick"},
    {"x": 3, "y": 9, "z": 1, "name": "Soil_Clay_Brick"},
    {"x": 3, "y": 10, "z": 1, "name": "Soil_Clay_Brick"},
    {"x": 3, "y": 11, "z": 1, "name": "Soil_Clay_Brick"},
    {"x": 3, "y": 12, "z": 1, "name": "Soil_Grass_Dry"},
    {"x": 3, "y": 15, "z": 1, "name": "Furniture_Kweebec_Platform"},
    {"x": 3, "y": 6, "z": 2, "name": "Soil_Dirt_Poisoned"},
    {"x": 3, "y": 7, "z": 2, "name": "Soil_Dirt_Burnt"},
    {"x": 3, "y": 8, "z": 2, "name": "Soil_Dirt_Poisoned"},
    {"x": 3, "y": 9, "z": 2, "name": "Soil_Dirt_Burnt"},
    {"x": 3, "y": 10, "z": 2, "name": "Soil_Dirt_Poisoned"},
    {"x": 3, "y": 11, "z": 2, "name": "Soil_Dirt_Burnt"},
    {"x": 3, "y": 12, "z": 2, "name": "Soil_Leaves"},
    {"x": 3, "y": 13, "z": 2, "name": "Plant_Grass_Sharp"},
    {"x": 3, "y": 14, "z": 2, "name": "Wood_Petrified_Trunk_Full"},
    {"x": 3, "y": 15, "z": 2, "name": "Wood_Ash_Trunk"},
    {"x": 3, "y": 16, "z": 2, "name": "Wood_Poisoned_Trunk_Full"},
    {"x": 3, "y": 9, "z": 3, "name": "Wood_Poisoned_Roots"},
    {"x": 3, "y": 10, "z": 3, "name": "Wood_Petrified_Trunk_Full"},
    {"x": 3, "y": 11, "z": 3, "name": "Wood_Petrified_Trunk_Full"},
    {"x": 3, "y": 12, "z": 3, "name": "Soil_Leaves"},
    {"x": 3, "y": 13, "z": 3, "name": "Plant_Grass_Sharp"},
    {"x": 3, "y": 10, "z": 4, "name": "Soil_Dirt_Poisoned"},
    {"x": 3, "y": 11, "z": 4, "name": "Soil_Dirt_Burnt"},
    {"x": 3, "y": 12, "z": 4, "name": "Soil_Leaves"},
    {"x": 4, "y": 9, "z": -2, "name": "Soil_Dirt_Poisoned"},
    {"x": 4, "y": 10, "z": -2, "name": "Soil_Dirt_Burnt"},
    {"x": 4, "y": 11, "z": -2, "name": "Soil_Dirt_Poisoned"},
    {"x": 4, "y": 12, "z": -2, "name": "Soil_Grass_Dry"},
    {"x": 4, "y": 13, "z": -2, "name": "Plant_Grass_Sharp"},
    {"x": 4, "y": 5, "z": -1, "name": "Soil_Dirt_Burnt"},
    {"x": 4, "y": 6, "z": -1, "name": "Soil_Dirt_Poisoned"},
    {"x": 4, "y": 7, "z": -1, "name": "Soil_Dirt_Burnt"},
    {"x": 4, "y": 8, "z": -1, "name": "Soil_Dirt_Poisoned"},
    {"x": 4, "y": 9, "z": -1, "name": "Soil_Dirt_Burnt"},
    {"x": 4, "y": 10, "z": -1, "name": "Soil_Dirt_Poisoned"},
    {"x": 4, "y": 11, "z": -1, "name": "Soil_Dirt_Burnt"},
    {"x": 4, "y": 12, "z": -1, "name": "Soil_Grass_Burnt"},
    {"x": 4, "y": 13, "z": -1, "name": "Plant_Grass_Sharp"},
    {"x": 4, "y": 4, "z": 0, "name": "Soil_Dirt_Burnt"},
    {"x": 4, "y": 5, "z": 0, "name": "Soil_Dirt_Poisoned"},
    {"x": 4, "y": 6, "z": 0, "name": "Soil_Dirt_Burnt"},
    {"x": 4, "y": 7, "z": 0, "name": "Soil_Dirt_Poisoned"},
    {"x": 4, "y": 8, "z": 0, "name": "Soil_Dirt_Burnt"},
    {"x": 4, "y": 9, "z": 0, "name": "Soil_Dirt_Poisoned"},
    {"x": 4, "y": 10, "z": 0, "name": "Soil_Dirt_Burnt"},
    {"x": 4, "y": 11, "z": 0, "name": "Soil_Dirt_Poisoned"},
    {"x": 4, "y": 12, "z": 0, "name": "Soil_Grass_Dry"},
    {"x": 4, "y": 6, "z": 1, "name": "Soil_Dirt_Poisoned"},
    {"x": 4, "y": 7, "z": 1, "name": "Soil_Dirt_Burnt"},
    {"x": 4, "y": 8, "z": 1, "name": "Soil_Dirt_Poisoned"},
    {"x": 4, "y": 9, "z": 1, "name": "Soil_Dirt_Burnt"},
    {"x": 4, "y": 10, "z": 1, "name": "Soil_Dirt_Poisoned"},
    {"x": 4, "y": 11, "z": 1, "name": "Soil_Dirt_Burnt"},
    {"x": 4, "y": 12, "z": 1, "name": "Soil_Grass_Burnt"},
    {"x": 4, "y": 10, "z": 2, "name": "Wood_Petrified_Roots"},
    {"x": 4, "y": 11, "z": 2, "name": "Wood_Poisoned_Trunk_Full"},
    {"x": 4, "y": 12, "z": 2, "name": "Wood_Ash_Trunk"},
    {"x": 4, "y": 13, "z": 2, "name": "Wood_Petrified_Trunk"},
    {"x": 4, "y": 14, "z": 2, "name": "Wood_Petrified_Trunk_Full"},
    {"x": 4, "y": 11, "z": 3, "name": "Wood_Ash_Trunk_Full"},
    {"x": 4, "y": 12, "z": 3, "name": "Soil_Leaves"},
    {"x": 4, "y": 13, "z": 3, "name": "Plant_Grass_Sharp"},
    {"x": 5, "y": 14, "z": 2, "name": "Wood_Poisoned_Branch_Corner", "rotation": 1}
  ],
  "fluids": [
    {"x": 1, "y": 5, "z": 0, "name": "Water_Source", "level": 1},
    {"x": 1, "y": 6, "z": 0, "name": "Water_Source", "level": 1},
    {"x": 1, "y": 5, "z": 1, "name": "Water_Source", "level": 1},
    {"x": 1, "y": 6, "z": 1, "name": "Water_Source", "level": 1},
    {"x": 2, "y": 5, "z": 0, "name": "Water_Source", "level": 1},
    {"x": 2, "y": 6, "z": 0, "name": "Water_Source", "level": 1},
    {"x": 2, "y": 5, "z": 1, "name": "Water_Source", "level": 1},
    {"x": 2, "y": 6, "z": 1, "name": "Water_Source", "level": 1}
  ],
  "entities": []
}
