{
  "version": 8,
  "blockIdVersion": 11,
  "anchorX": 0,
  "anchorY": 6,
  "anchorZ": 0,
  "blocks": [
    {"x": -7, "y": 17, "z": -4, "name": "Plant_Leaves_Petrified"},
    {"x": -7, "y": 17, "z": -3, "name": "Plant_Leaves_Dead"},
    {"x": -7, "y": 18, "z": -3, "name": "Plant_Leaves_Dead"},
    {"x": -7, "y": 16, "z": -2, "name": "Plant_Leaves_Dead"},
    {"x": -7, "y": 17, "z": -2, "name": "Plant_Leaves_Poisoned"},
    {"x": -7, "y": 18, "z": -2, "name": "Plant_Leaves_Dead"},
    {"x": -7, "y": 17, "z": -1, "name": "Plant_Leaves_Petrified"},
    {"x": -7, "y": 19, "z": 1, "name": "Plant_Leaves_Petrified"},
    {"x": -7, "y": 18, "z": 2, "name": "Plant_Leaves_Poisoned"},
    {"x": -7, "y": 19, "z": 2, "name": "Plant_Leaves_Petrified"},
    {"x": -7, "y": 17, "z": 3, "name": "Plant_Leaves_Petrified"},
    {"x": -7, "y": 18, "z": 3, "name": "Plant_Leaves_Dead"},
    {"x": -7, "y": 17, "z": 4, "name": "Plant_Leaves_Dead"},
    {"x": -7, "y": 18, "z": 4, "name": "Plant_Leaves_Poisoned"},
    {"x": -6, "y": 17, "z": -5, "name": "Plant_Leaves_Dead"},
    {"x": -6, "y": 18, "z": -4, "name": "Plant_Leaves_Dead"},
    {"x": -6, "y": 17, "z": -3, "name": "Plant_Leaves_Dead"},
    {"x": -6, "y": 18, "z": -3, "name": "Plant_Leaves_Poisoned"},
    {"x": -6, "y": 18, "z": -2, "name": "Plant_Leaves_Poisoned"},
    {"x": -6, "y": 19, "z": -2, "name": "Plant_Leaves_Dead"},
    {"x": -6, "y": 16, "z": -1, "name": "Plant_Leaves_Petrified"},
    {"x": -6, "y": 17, "z": -1, "name": "Plant_Leaves_Poisoned"},
    {"x": -6, "y": 18, "z": -1, "name": "Plant_Leaves_Petrified"},
    {"x": -6, "y": 19, "z": -1, "name": "Plant_Leaves_Petrified"},
    {"x": -6, "y": 18, "z": 0, "name": "Plant_Leaves_Petrified"},
    {"x": -6, "y": 19, "z": 0, "name": "Plant_Leaves_Petrified"},
    {"x": -6, "y": 19, "z": 1, "name": "Plant_Leaves_Poisoned"},
    {"x": -6, "y": 20, "z": 1, "name": "Plant_Leaves_Poisoned"},
    {"x": -6, "y": 18, "z": 2, "name": "Plant_Leaves_Dead"},
    {"x": -6, "y": 19, "z": 2, "name": "Plant_Leaves_Poisoned"},
    {"x": -6, "y": 20, "z": 2, "name": "Plant_Leaves_Petrified"},
    {"x": -6, "y": 18, "z": 3, "name": "Plant_Leaves_Poisoned"},
    {"x": -6, "y": 19, "z": 3, "name": "Plant_Leaves_Dead"},
    {"x": -6, "y": 20, "z": 3, "name": "Plant_Leaves_Dead"},
    {"x": -6, "y": 17, "z": 4, "name": "Plant_Leaves_Poisoned"},
    {"x": -6, "y": 18, "z": 4, "name": "Plant_Leaves_Dead"},
    {"x": -6, "y": 19, "z": 4, "name": "Plant_Leaves_Poisoned"},
    {"x": -6, "y": 17, "z": 5, "name": "Plant_Leaves_Dead"},
    {"x": -6, "y": 18, "z": 5, "name": "Plant_Leaves_Poisoned"},
    {"x": -5, "y": 17, "z": -5, "name": "Plant_Leaves_Poisoned"},
    {"x": -5, "y": 18, "z": -5, "name": "Plant_Leaves_Dead"},
    {"x": -5, "y": 17, "z": -4, "name": "Plant_Leaves_Poisoned"},
    {"x": -5, "y": 18, "z": -4, "name": "Plant_Leaves_Petrified"},
    {"x": -5, "y": 19, "z": -4, "name": "Plant_Leaves_Petrified"},
    {"x": -5, "y": 17, "z": -3, "name": "Wood_Petrified_Trunk_Full"},
    {"x": -5, "y": 18, "z": -3, "name": "Plant_Leaves_Poisoned"},
    {"x": -5, "y": 19, "z": -3, "name": "Plant_Leaves_Dead"},
    {"x": -5, "y": 20, "z": -3, "name": "Plant_Leaves_Poisoned"},
    {"x": -5, "y": 1, "z": -2, "name": "Soil_Dirt_Burnt"},
    {"x": -5, "y": 2, "z": -2, "name": "Soil_Dirt_Poisoned"},
    {"x": -5, "y": 3, "z": -2, "name": "Soil_Dirt_Burnt"},
    {"x": -5, "y": 4, "z": -2, "name": "Soil_Dirt_Poisoned"},
    {"x": -5, "y": 5, "z": -2, "name": "Soil_Dirt_Burnt"},
    {"x": -5, "y": 6, "z": -2, "name": "Soil_Leaves"},
    {"x": -5, "y": 18, "z": -2, "name": "Plant_Leaves_Dead"},
    {"x": -5, "y": 19, "z": -2, "name": "Plant_Leaves_Poisoned"},
    {"x": -5, "y": 20, "z": -2, "name": "Plant_Leaves_Poisoned"},
    {"x": -5, "y": 1, "z": -1, "name": "Soil_Dirt_Poisoned"},
    {"x": -5, "y": 2, "z": -1, "name": "Soil_Dirt_Burnt"},
    {"x": -5, "y": 3, "z": -1, "name": "Soil_Dirt_Poisoned"},
    {"x": -5, "y": 4, "z": -1, "name": "Soil_Dirt_Burnt"},
    {"x": -5, "y": 5, "z": -1, "name": "Soil_Dirt_Poisoned"},
    {"x": -5, "y": 6, "z": -1, "name": "Soil_Leaves"},
    {"x": -5, "y": 17, "z": -1, "name": "Plant_Leaves_Dead"},
    {"x": -5, "y": 18, "z": -1, "name": "Plant_Leaves_Petrified"},
    {"x": -5, "y": 19, "z": -1, "name": "Plant_Leaves_Petrified"},
    {"x": -5, "y": 1, "z": 0, "name": "Soil_Dirt_Burnt"},
    {"x": -5, "y": 2, "z": 0, "name": "Soil_Dirt_Poisoned"},
    {"x": -5, "y": 3, "z": 0, "name": "Soil_Dirt_Burnt"},
    {"x": -5, "y": 4, "z": 0, "name": "Soil_Dirt_Poisoned"},
    {"x": -5, "y": 5, "z": 0, "name": "Soil_Dirt_Burnt"},
    {"x": -5, "y": 6, "z": 0, "name": "Soil_Leaves"},
    {"x": -5, "y": 18, "z": 0, "name": "Plant_Leaves_Petrified"},
    {"x": -5, "y": 19, "z": 0, "name": "Plant_Leaves_Petrified"},
    {"x": -5, "y": 20, "z": 0, "name": "Plant_Leaves_Poisoned"},
    {"x": -5, "y": 1, "z": 1, "name": "Soil_Dirt_Poisoned"},
    {"x": -5, "y": 2, "z": 1, "name": "Soil_Dirt_Burnt"},
    {"x": -5, "y": 3, "z": 1, "name": "Soil_Dirt_Poisoned"},
    {"x": -5, "y": 4, "z": 1, "name": "Soil_Dirt_Burnt"},
    {"x": -5, "y": 5, "z": 1, "name": "Soil_Dirt_Poisoned"},
    {"x": -5, "y": 6, "z": 1, "name": "Soil_Leaves"},
    {"x": -5, "y": 18, "z": 1, "name": "Plant_Leaves_Poisoned"},
    {"x": -5, "y": 19, "z": 1, "name": "Plant_Leaves_Dead"},
    {"x": -5, "y": 20, "z": 1, "name": "Plant_Leaves_Dead"},
    {"x": -5, "y": 21, "z": 1, "name": "Plant_Leaves_Petrified"},
    {"x": -5, "y": 1, "z": 2, "name": "Soil_Dirt_Burnt"},
    {"x": -5, "y": 2, "z": 2, "name": "Soil_Dirt_Poisoned"},
    {"x": -5, "y": 3, "z": 2, "name": "Soil_Dirt_Burnt"},
    {"x": -5, "y": 4, "z": 2, "name": "Soil_Dirt_Poisoned"},
    {"x": -5, "y": 5, "z": 2, "name": "Soil_Dirt_Burnt"},
    {"x": -5, "y": 6, "z": 2, "name": "Soil_Leaves"},
    {"x": -5, "y": 19, "z": 2, "name": "Wood_Poisoned_Trunk_Full"},
    {"x": -5, "y": 20, "z": 2, "name": "Plant_Leaves_Dead"},
    {"x": -5, "y": 21, "z": 2, "name": "Plant_Leaves_Petrified"},
    {"x": -5, "y": 1, "z": 3, "name": "Soil_Dirt_Poisoned"},
    {"x": -5, "y": 2, "z": 3, "name": "Soil_Dirt_Burnt"},
    {"x": -5, "y": 3, "z": 3, "name": "Soil_Dirt_Poisoned"},
    {"x": -5, "y": 4, "z": 3, "name": "Soil_Dirt_Burnt"},
    {"x": -5, "y": 5, "z": 3, "name": "Soil_Dirt_Poisoned"},
    {"x": -5, "y": 6, "z": 3, "name": "Soil_Grass_Dry"},
    {"x": -5, "y": 19, "z": 3, "name": "Plant_Leaves_Petrified"},
    {"x": -5, "y": 20, "z": 3, "name": "Plant_Leaves_Petrified"},
    {"x": -5, "y": 21, "z": 3, "name": "Plant_Leaves_Dead"},
    {"x": -5, "y": 18, "z": 4, "name": "Plant_Leaves_Poisoned"},
    {"x": -5, "y": 19, "z": 4, "name": "Plant_Leaves_Poisoned"},
    {"x": -5, "y": 20, "z": 4, "name": "Plant_Leaves_Dead"},
    {"x": -5, "y": 17, "z": 5, "name": "Plant_Leaves_Poisoned"},
    {"x": -5, "y": 18, "z": 5, "name": "Plant_Leaves_Dead"},
    {"x": -5, "y": 19, "z": 5, "name": "Plant_Leaves_Petrified"},
    {"x": -5, "y": 17, "z": 6, "name": "Plant_Leaves_Poisoned"},
    {"x": -5, "y": 18, "z": 6, "name": "Plant_Leaves_Petrified"},
    {"x": -4, "y": 17, "z": -7, "name": "Plant_Leaves_Poisoned"},
    {"x": -4, "y": 18, "z": -7, "name": "Plant_Leaves_Dead"},
    {"x": -4, "y": 18, "z": -6, "name": "Plant_Leaves_Poisoned"},
    {"x": -4, "y": 19, "z": -6, "name": "Plant_Leaves_Dead"},
    {"x": -4, "y": 17, "z": -5, "name": "Plant_Leaves_Dead"},
    {"x": -4, "y": 19, "z": -5, "name": "Plant_Leaves_Petrified"},
    {"x": -4, "y": 17, "z": -4, "name": "Plant_Leaves_Dead"},
    {"x": -4, "y": 18, "z": -4, "name": "Plant_Leaves_Poisoned"},
    {"x": -4, "y": 19, "z": -4, "name": "Plant_Leaves_Poisoned"},
    {"x": -4, "y": 1, "z": -3, "name": "Soil_Dirt_Burnt"},
    {"x": -4, "y": 2, "z": -3, "name": "Soil_Dirt_Poisoned"},
    {"x": -4, "y": 3, "z": -3, "name": "Soil_Dirt_Burnt"},
    {"x": -4, "y": 4, "z": -3, "name": "Soil_Dirt_Poisoned"},
    {"x": -4, "y": 5, "z": -3, "name": "Soil_Dirt_Burnt"},
    {"x": -4, "y": 6, "z": -3, "name": "Soil_Grass_Burnt"},
    {"x": -4, "y": 17, "z": -3, "name": "Wood_Petrified_Trunk_Full"},
    {"x": -4, "y": 18, "z": -3, "name": "Plant_Leaves_Petrified"},
    {"x": -4, "y": 19, "z": -3, "name": "Plant_Leaves_Dead"},
    {"x": -4, "y": 20, "z": -3, "name": "Plant_Leaves_Poisoned"},
    {"x": -4, "y": 1, "z": -2, "name": "Soil_Dirt_Poisoned"},
    {"x": -4, "y": 2, "z": -2, "name": "Soil_Dirt_Burnt"},
    {"x": -4, "y": 3, "z": -2, "name": "Soil_Dirt_Poisoned"},
    {"x": -4, "y": 4, "z": -2, "name": "Soil_Dirt_Burnt"},
    {"x": -4, "y": 5, "z": -2, "name": "Soil_Dirt_Poisoned"},
    {"x": -4, "y": 6, "z": -2, "name": "Soil_Leaves"},
    {"x": -4, "y": 17, "z": -2, "name": "Wood_Petrified_Trunk_Full"},
    {"x": -4, "y": 18, "z": -2, "name": "Plant_Leaves_Dead"},
    {"x": -4, "y": 19, "z": -2, "name": "Plant_Leaves_Petrified"},
    {"x": -4, "y": 20, "z": -2, "name": "Plant_Leaves_Poisoned"},
    {"x": -4, "y": 1, "z": -1, "name": "Soil_Dirt_Burnt"},
    {"x": -4, "y": 2, "z": -1, "name": "Soil_Dirt_Poisoned"},
    {"x": -4, "y": 3, "z": -1, "name": "Soil_Dirt_Burnt"},
    {"x": -4, "y": 4, "z": -1, "name": "Soil_Dirt_Poisoned"},
    {"x": -4, "y": 5, "z": -1, "name": "Soil_Dirt_Burnt"},
    {"x": -4, "y": 6, "z": -1, "name": "Soil_Leaves"},
    {"x": -4, "y": 8, "z": -1, "name": "Furniture_Kweebec_Sign", "rotation": 3},
    {"x": -4, "y": 1, "z": 0, "name": "Soil_Dirt_Poisoned"},
    {"x": -4, "y": 2, "z": 0, "name": "Soil_Dirt_Burnt"},
    {"x": -4, "y": 3, "z": 0, "name": "Soil_Dirt_Poisoned"},
    {"x": -4, "y": 4, "z": 0, "name": "Soil_Dirt_Burnt"},
    {"x": -4, "y": 5, "z": 0, "name": "Soil_Dirt_Poisoned"},
    {"x": -4, "y": 6, "z": 0, "name": "Soil_Grass_Dry"},
    {"x": -4, "y": 19, "z": 0, "name": "Plant_Leaves_Dead"},
    {"x": -4, "y": 20, "z": 0, "name": "Plant_Leaves_Petrified"},
    {"x": -4, "y": 1, "z": 1, "name": "Soil_Dirt_Burnt"},
    {"x": -4, "y": 2, "z": 1, "name": "Soil_Dirt_Poisoned"},
    {"x": -4, "y": 3, "z": 1, "name": "Soil_Dirt_Burnt"},
    {"x": -4, "y": 4, "z": 1, "name": "Soil_Dirt_Poisoned"},
    {"x": -4, "y": 5, "z": 1, "name": "Soil_Dirt_Burnt"},
    {"x": -4, "y": 6, "z": 1, "name": "Soil_Grass_Burnt"},
    {"x": -4, "y": 18, "z": 1, "name": "Plant_Leaves_Poisoned"},
    {"x": -4, "y": 19, "z": 1, "name": "Plant_Leaves_Petrified"},
    {"x": -4, "y": 20, "z": 1, "name": "Plant_Leaves_Dead"},
    {"x": -4, "y": 1, "z": 2, "name": "Soil_Dirt_Poisoned"},
    {"x": -4, "y": 2, "z": 2, "name": "Soil_Dirt_Burnt"},
    {"x": -4, "y": 3, "z": 2, "name": "Soil_Dirt_Poisoned"},
    {"x": -4, "y": 4, "z": 2, "name": "Soil_Dirt_Burnt"},
    {"x": -4, "y": 5, "z": 2, "name": "Soil_Dirt_Poisoned"},
    {"x": -4, "y": 6, "z": 2, "name": "Wood_Petrified_Trunk_Full"},
    {"x": -4, "y": 7, "z": 2, "name": "Wood_Poisoned_Trunk_Full"},
    {"x": -4, "y": 19, "z": 2, "name": "Wood_Poisoned_Trunk_Full"},
    {"x": -4, "y": 20, "z": 2, "name": "Plant_Leaves_Dead"},
    {"x": -4, "y": 21, "z": 2, "name": "Plant_Leaves_Poisoned"},
    {"x": -4, "y": 1, "z": 3, "name": "Soil_Dirt_Burnt"},
    {"x": -4, "y": 2, "z": 3, "name": "Soil_Dirt_Poisoned"},
    {"x": -4, "y": 3, "z": 3, "name": "Soil_Dirt_Burnt"},
    {"x": -4, "y": 4, "z": 3, "name": "Soil_Dirt_Poisoned"},
    {"x": -4, "y": 5, "z": 3, "name": "Soil_Dirt_Burnt"},
    {"x": -4, "y": 6, "z": 3, "name": "Soil_Leaves"},
    {"x": -4, "y": 18, "z": 3, "name": "Plant_Leaves_Dead"},
    {"x": -4, "y": 20, "z": 3, "name": "Plant_Leaves_Poisoned"},
    {"x": -4, "y": 1, "z": 4, "name": "Soil_Dirt_Poisoned"},
    {"x": -4, "y": 2, "z": 4, "name": "Soil_Dirt_Burnt"},
    {"x": -4, "y": 3, "z": 4, "name": "Soil_Dirt_Poisoned"},
    {"x": -4, "y": 4, "z": 4, "name": "Soil_Dirt_Burnt"},
    {"x": -4, "y": 5, "z": 4, "name": "Soil_Dirt_Poisoned"},
    {"x": -4, "y": 6, "z": 4, "name": "Soil_Grass_Dry"},
    {"x": -4, "y": 18, "z": 4, "name": "Plant_Leaves_Petrified"},
    {"x": -4, "y": 19, "z": 4, "name": "Plant_Leaves_Petrified"},
    {"x": -4, "y": 20, "z": 4, "name": "Plant_Leaves_Dead"},
    {"x": -4, "y": 21, "z": 4, "name": "Plant_Leaves_Poisoned"},
    {"x": -4, "y": 18, "z": 5, "name": "Plant_Leaves_Dead"},
    {"x": -4, "y": 19, "z": 5, "name": "Plant_Leaves_Poisoned"},
    {"x": -4, "y": 20, "z": 5, "name": "Plant_Leaves_Poisoned"},
    {"x": -4, "y": 17, "z": 6, "name": "Plant_Leaves_Dead"},
    {"x": -4, "y": 18, "z": 6, "name": "Plant_Leaves_Poisoned"},
    {"x": -3, "y": 17, "z": -8, "name": "Plant_Leaves_Poisoned"},
    {"x": -3, "y": 17, "z": -7, "name": "Plant_Leaves_Petrified"},
    {"x": -3, "y": 18, "z": -7, "name": "Plant_Leaves_Dead"},
    {"x": -3, "y": 18, "z": -6, "name": "Plant_Leaves_Dead"},
    {"x": -3, "y": 19, "z": -6, "name": "Plant_Leaves_Dead"},
    {"x": -3, "y": 18, "z": -5, "name": "Plant_Leaves_Petrified"},
    {"x": -3, "y": 19, "z": -5, "name": "Plant_Leaves_Poisoned"},
    {"x": -3, "y": 20, "z": -5, "name": "Plant_Leaves_Petrified"},
    {"x": -3, "y": 1, "z": -4, "name": "Soil_Dirt_Burnt"},
    {"x": -3, "y": 2, "z": -4, "name": "Soil_Dirt_Poisoned"},
    {"x": -3, "y": 3, "z": -4, "name": "Soil_Dirt_Burnt"},
    {"x": -3, "y": 4, "z": -4, "name": "Soil_Dirt_Poisoned"},
    {"x": -3, "y": 5, "z": -4, "name": "Soil_Dirt_Burnt"},
    {"x": -3, "y": 6, "z": -4, "name": "Soil_Grass_Burnt"},
    {"x": -3, "y": 20, "z": -4, "name": "Plant_Leaves_Dead"},
    {"x": -3, "y": 21, "z": -4, "name": "Plant_Leaves_Poisoned"},
    {"x": -3, "y": 1, "z": -3, "name": "Soil_Dirt_Poisoned"},
    {"x": -3, "y": 2, "z": -3, "name": "Soil_Dirt_Burnt"},
    {"x": -3, "y": 3, "z": -3, "name": "Soil_Dirt_Poisoned"},
    {"x": -3, "y": 4, "z": -3, "name": "Soil_Dirt_Burnt"},
    {"x": -3, "y": 5, "z": -3, "name": "Soil_Dirt_Poisoned"},
    {"x": -3, "y": 6, "z": -3, "name": "Soil_Grass_Dry"},
    {"x": -3, "y": 18, "z": -3, "name": "Plant_Leaves_Poisoned"},
    {"x": -3, "y": 20, "z": -3, "name": "Plant_Leaves_Petrified"},
    {"x": -3, "y": 21, "z": -3, "name": "Plant_Leaves_Petrified"},
    {"x": -3, "y": 1, "z": -2, "name": "Soil_Dirt_Burnt"},
    {"x": -3, "y": 2, "z": -2, "name": "Soil_Dirt_Poisoned"},
    {"x": -3, "y": 3, "z": -2, "name": "Soil_Dirt_Burnt"},
    {"x": -3, "y": 4, "z": -2, "name": "Soil_Dirt_Poisoned"},
    {"x": -3, "y": 5, "z": -2, "name": "Wood_Ash_Trunk_Full"},
    {"x": -3, "y": 6, "z": -2, "name": "Wood_Petrified_Trunk_Full"},
    {"x": -3, "y": 7, "z": -2, "name": "Wood_Poisoned_Trunk_Full"},
    {"x": -3, "y": 16, "z": -2, "name": "Wood_Poisoned_Trunk_Full"},
    {"x": -3, "y": 17, "z": -2, "name": "Wood_Petrified_Trunk_Full"},
    {"x": -3, "y": 21, "z": -2, "name": "Plant_Leaves_Dead"},
    {"x": -3, "y": 1, "z": -1, "name": "Soil_Dirt_Poisoned"},
    {"x": -3, "y": 2, "z": -1, "name": "Soil_Dirt_Burnt"},
    {"x": -3, "y": 3, "z": -1, "name": "Soil_Dirt_Poisoned"},
    {"x": -3, "y": 4, "z": -1, "name": "Soil_Dirt_Burnt"},
    {"x": -3, "y": 5, "z": -1, "name": "Soil_Dirt_Poisoned"},
    {"x": -3, "y": 6, "z": -1, "name": "Soil_Grass_Dry"},
    {"x": -3, "y": 7, "z": -1, "name": "Wood_Petrified_Trunk_Full"},
    {"x": -3, "y": 8, "z": -1, "name": "Wood_Petrified_Trunk_Full"},
    {"x": -3, "y": 9, "z": -1, "name": "Wood_Petrified_Trunk_Full"},
    {"x": -3, "y": 10, "z": -1, "name": "Wood_Ash_Trunk_Full"},
    {"x": -3, "y": 11, "z": -1, "name": "Wood_Ash_Trunk_Full"},
    {"x": -3, "y": 21, "z": -1, "name": "Plant_Leaves_Poisoned"},
    {"x": -3, "y": 22, "z": -1, "name": "Plant_Leaves_Poisoned"},
    {"x": -3, "y": 1, "z": 0, "name": "Soil_Dirt_Burnt"},
    {"x": -3, "y": 2, "z": 0, "name": "Soil_Dirt_Poisoned"},
    {"x": -3, "y": 3, "z": 0, "name": "Soil_Dirt_Burnt"},
    {"x": -3, "y": 4, "z": 0, "name": "Soil_Dirt_Poisoned"},
    {"x": -3, "y": 5, "z": 0, "name": "Soil_Dirt_Burnt"},
    {"x": -3, "y": 6, "z": 0, "name": "Soil_Grass_Burnt"},
    {"x": -3, "y": 7, "z": 0, "name": "Soil_Clay_Brick_Half", "rotation": 4},
    {"x": -3, "y": 8, "z": 0, "name": "Soil_Clay_Brick_Half", "rotation": 4},
    {"x": -3, "y": 9, "z": 0, "name": "Wood_Petrified_Trunk_Full"},
    {"x": -3, "y": 10, "z": 0, "name": "Wood_Poisoned_Trunk_Full"},
    {"x": -3, "y": 11, "z": 0, "name": "Wood_Poisoned_Trunk_Full"},
    {"x": -3, "y": 12, "z": 0, "name": "Wood_Poisoned_Trunk_Full"},
    {"x": -3, "y": 13, "z": 0, "name": "Wood_Poisoned_Trunk_Full"},
    {"x": -3, "y": 19, "z": 0, "name": "Plant_Leaves_Poisoned"},
    {"x": -3, "y": 20, "z": 0, "name": "Plant_Leaves_Poisoned"},
    {"x": -3, "y": 1, "z": 1, "name": "Soil_Dirt_Poisoned"},
    {"x": -3, "y": 2, "z": 1, "name": "Soil_Dirt_Burnt"},
    {"x": -3, "y": 3, "z": 1, "name": "Soil_Dirt_Poisoned"},
    {"x": -3, "y": 4, "z": 1, "name": "Soil_Dirt_Burnt"},
    {"x": -3, "y": 5, "z": 1, "name": "Soil_Dirt_Poisoned"},
    {"x": -3, "y": 6, "z": 1, "name": "Soil_Grass_Dry"},
    {"x": -3, "y": 7, "z": 1, "name": "Soil_Clay_Brick_Half", "rotation": 6},
    {"x": -3, "y": 8, "z": 1, "name": "Soil_Clay_Brick_Half", "rotation": 6},
    {"x": -3, "y": 9, "z": 1, "name": "Wood_Ash_Trunk_Full"},
    {"x": -3, "y": 10, "z": 1, "name": "Wood_Ash_Trunk_Full"},
    {"x": -3, "y": 19, "z": 1, "name": "Plant_Leaves_Petrified"},
    {"x": -3, "y": 20, "z": 1, "name": "Plant_Leaves_Dead"},
    {"x": -3, "y": 21, "z": 1, "name": "Plant_Leaves_Poisoned"},
    {"x": -3, "y": 1, "z": 2, "name": "Soil_Dirt_Burnt"},
    {"x": -3, "y": 2, "z": 2, "name": "Soil_Dirt_Poisoned"},
    {"x": -3, "y": 3, "z": 2, "name": "Soil_Dirt_Burnt"},
    {"x": -3, "y": 4, "z": 2, "name": "Wood_Poisoned_Trunk_Full"},
    {"x": -3, "y": 5, "z": 2, "name": "Wood_Petrified_Trunk_Full"},
    {"x": -3, "y": 6, "z": 2, "name": "Wood_Petrified_Trunk_Full"},
    {"x": -3, "y": 7, "z": 2, "name": "Wood_Ash_Trunk_Full"},
    {"x": -3, "y": 8, "z": 2, "name": "Wood_Ash_Trunk_Full"},
    {"x": -3, "y": 9, "z": 2, "name": "Wood_Poisoned_Trunk_Full"},
    {"x": -3, "y": 15, "z": 2, "name": "Furniture_Kweebec_Lantern"},
    {"x": -3, "y": 16, "z": 2, "name": "Deco_Rope"},
    {"x": -3, "y": 17, "z": 2, "name": "Deco_Rope"},
    {"x": -3, "y": 18, "z": 2, "name": "Wood_Ash_Trunk_Full"},
    {"x": -3, "y": 19, "z": 2, "name": "Wood_Petrified_Trunk_Full"},
    {"x": -3, "y": 20, "z": 2, "name": "Plant_Leaves_Petrified"},
    {"x": -3, "y": 21, "z": 2, "name": "Plant_Leaves_Petrified"},
    {"x": -3, "y": 22, "z": 2, "name": "Plant_Leaves_Petrified"},
    {"x": -3, "y": 1, "z": 3, "name": "Soil_Dirt_Poisoned"},
    {"x": -3, "y": 2, "z": 3, "name": "Soil_Dirt_Burnt"},
    {"x": -3, "y": 3, "z": 3, "name": "Soil_Dirt_Poisoned"},
    {"x": -3, "y": 4, "z": 3, "name": "Soil_Dirt_Burnt"},
    {"x": -3, "y": 5, "z": 3, "name": "Soil_Dirt_Poisoned"},
    {"x": -3, "y": 6, "z": 3, "name": "Soil_Leaves"},
    {"x": -3, "y": 20, "z": 3, "name": "Plant_Leaves_Poisoned"},
    {"x": -3, "y": 21, "z": 3, "name": "Plant_Leaves_Dead"},
    {"x": -3, "y": 1, "z": 4, "name": "Soil_Dirt_Burnt"},
    {"x": -3, "y": 2, "z": 4, "name": "Soil_Dirt_Poisoned"},
    {"x": -3, "y": 3, "z": 4, "name": "Soil_Dirt_Burnt"},
    {"x": -3, "y": 4, "z": 4, "name": "Soil_Dirt_Poisoned"},
    {"x": -3, "y": 5, "z": 4, "name": "Soil_Dirt_Burnt"},
    {"x": -3, "y": 6, "z": 4, "name": "Soil_Leaves"},
    {"x": -3, "y": 18, "z": 4, "name": "Plant_Leaves_Petrified"},
    {"x": -3, "y": 19, "z": 4, "name": "Plant_Leaves_Dead"},
    {"x": -3, "y": 21, "z": 4, "name": "Plant_Leaves_Poisoned"},
    {"x": -3, "y": 19, "z": 5, "name": "Plant_Leaves_Poisoned"},
    {"x": -3, "y": 18, "z": 6, "name": "Plant_Leaves_Poisoned"},
    {"x": -3, "y": 19, "z": 6, "name": "Plant_Leaves_Poisoned"},
    {"x": -3, "y": 18, "z": 7, "name": "Plant_Leaves_Dead"},
    {"x": -2, "y": 17, "z": -8, "name": "Plant_Leaves_Poisoned"},
    {"x": -2, "y": 18, "z": -8, "name": "Plant_Leaves_Dead"},
    {"x": -2, "y": 17, "z": -7, "name": "Plant_Leaves_Dead"},
    {"x": -2, "y": 18, "z": -7, "name": "Plant_Leaves_Poisoned"},
    {"x": -2, "y": 19, "z": -7, "name": "Plant_Leaves_Poisoned"},
    {"x": -2, "y": 18, "z": -6, "name": "Plant_Leaves_Poisoned"},
    {"x": -2, "y": 19, "z": -6, "name": "Plant_Leaves_Poisoned"},
    {"x": -2, "y": 20, "z": -6, "name": "Plant_Leaves_Petrified"},
    {"x": -2, "y": 18, "z": -5, "name": "Plant_Leaves_Petrified"},
    {"x": -2, "y": 19, "z": -5, "name": "Wood_Ash_Trunk_Full"},
    {"x": -2, "y": 20, "z": -5, "name": "Plant_Leaves_Dead"},
    {"x": -2, "y": 21, "z": -5, "name": "Plant_Leaves_Dead"},
    {"x": -2, "y": 1, "z": -4, "name": "Soil_Dirt_Poisoned"},
    {"x": -2, "y": 2, "z": -4, "name": "Soil_Dirt_Burnt"},
    {"x": -2, "y": 3, "z": -4, "name": "Soil_Dirt_Poisoned"},
    {"x": -2, "y": 4, "z": -4, "name": "Soil_Dirt_Burnt"},
    {"x": -2, "y": 5, "z": -4, "name": "Soil_Dirt_Poisoned"},
    {"x": -2, "y": 6, "z": -4, "name": "Soil_Grass_Dry"},
    {"x": -2, "y": 16, "z": -4, "name": "Wood_Poisoned_Trunk_Full"},
    {"x": -2, "y": 18, "z": -4, "name": "Plant_Leaves_Petrified"},
    {"x": -2, "y": 20, "z": -4, "name": "Plant_Leaves_Poisoned"},
    {"x": -2, "y": 21, "z": -4, "name": "Plant_Leaves_Poisoned"},
    {"x": -2, "y": 1, "z": -3, "name": "Soil_Dirt_Burnt"},
    {"x": -2, "y": 2, "z": -3, "name": "Soil_Dirt_Poisoned"},
    {"x": -2, "y": 3, "z": -3, "name": "Soil_Dirt_Burnt"},
    {"x": -2, "y": 4, "z": -3, "name": "Soil_Dirt_Poisoned"},
    {"x": -2, "y": 5, "z": -3, "name": "Soil_Dirt_Burnt"},
    {"x": -2, "y": 6, "z": -3, "name": "Soil_Grass_Burnt"},
    {"x": -2, "y": 15, "z": -3, "name": "Wood_Poisoned_Trunk_Full"},
    {"x": -2, "y": 16, "z": -3, "name": "Wood_Petrified_Trunk_Full"},
    {"x": -2, "y": 19, "z": -3, "name": "Plant_Leaves_Petrified"},
    {"x": -2, "y": 20, "z": -3, "name": "Plant_Leaves_Petrified"},
    {"x": -2, "y": 21, "z": -3, "name": "Plant_Leaves_Dead"},
    {"x": -2, "y": 1, "z": -2, "name": "Soil_Dirt_Poisoned"},
    {"x": -2, "y": 2, "z": -2, "name": "Soil_Dirt_Burnt"},
    {"x": -2, "y": 3, "z": -2, "name": "Soil_Dirt_Poisoned"},
    {"x": -2, "y": 4, "z": -2, "name": "Soil_Dirt_Burnt"},
    {"x": -2, "y": 5, "z": -2, "name": "Wood_Ash_Trunk_Full"},
    {"x": -2, "y": 6, "z": -2, "name": "Wood_Poisoned_Trunk_Full"},
    {"x": -2, "y": 7, "z": -2, "name": "Wood_Ash_Trunk_Full"},
    {"x": -2, "y": 8, "z": -2, "name": "Wood_Poisoned_Trunk_Full"},
    {"x": -2, "y": 9, "z": -2, "name": "Wood_Ash_Trunk_Full"},
    {"x": -2, "y": 15, "z": -2, "name": "Wood_Poisoned_Trunk_Full"},
    {"x": -2, "y": 16, "z": -2, "name": "Wood_Ash_Trunk_Full"},
    {"x": -2, "y": 19, "z": -2, "name": "Plant_Leaves_Petrified"},
    {"x": -2, "y": 20, "z": -2, "name": "Plant_Leaves_Dead"},
    {"x": -2, "y": 21, "z": -2, "name": "Plant_Leaves_Petrified"},
    {"x": -2, "y": 22, "z": -2, "name": "Plant_Leaves_Dead"},
    {"x": -2, "y": 1, "z": -1, "name": "Soil_Dirt_Burnt"},
    {"x": -2, "y": 2, "z": -1, "name": "Soil_Dirt_Poisoned"},
    {"x": -2, "y": 3, "z": -1, "name": "Soil_Dirt_Burnt"},
    {"x": -2, "y": 4, "z": -1, "name": "Soil_Dirt_Poisoned"},
    {"x": -2, "y": 5, "z": -1, "name": "Soil_Dirt_Burnt"},
    {"x": -2, "y": 6, "z": -1, "name": "Soil_Grass_Burnt"},
    {"x": -2, "y": 7, "z": -1, "name": "Plant_Crop_Mushroom_Common_Brown", "components": {"Components": {"FarmingBlock": {}}}},
    {"x": -2, "y": 8, "z": -1, "name": "Furniture_Kweebec_Painting"},
    {"x": -2, "y": 9, "z": -1, "name": "Plant_Vine"},
    {"x": -2, "y": 10, "z": -1, "name": "Wood_Ash_Trunk_Full"},
    {"x": -2, "y": 11, "z": -1, "name": "Wood_Ash_Trunk_Full"},
    {"x": -2, "y": 12, "z": -1, "name": "Wood_Ash_Trunk_Full"},
    {"x": -2, "y": 13, "z": -1, "name": "Wood_Ash_Trunk_Full"},
    {"x": -2, "y": 14, "z": -1, "name": "Wood_Ash_Trunk_Full"},
    {"x": -2, "y": 15, "z": -1, "name": "Wood_Ash_Trunk_Full"},
    {"x": -2, "y": 16, "z": -1, "name": "Wood_Poisoned_Trunk_Full"},
    {"x": -2, "y": 21, "z": -1, "name": "Plant_Leaves_Poisoned"},
    {"x": -2, "y": 22, "z": -1, "name": "Plant_Leaves_Poisoned"},
    {"x": -2, "y": 1, "z": 0, "name": "Soil_Dirt_Poisoned"},
    {"x": -2, "y": 2, "z": 0, "name": "Soil_Dirt_Burnt"},
    {"x": -2, "y": 3, "z": 0, "name": "Soil_Dirt_Poisoned"},
    {"x": -2, "y": 4, "z": 0, "name": "Soil_Dirt_Burnt"},
    {"x": -2, "y": 5, "z": 0, "name": "Soil_Dirt_Poisoned"},
    {"x": -2, "y": 6, "z": 0, "name": "Soil_Grass_Dry"},
    {"x": -2, "y": 9, "z": 0, "name": "Plant_Vine_Wall", "rotation": 1},
    {"x": -2, "y": 10, "z": 0, "name": "Wood_Poisoned_Trunk_Full"},
    {"x": -2, "y": 11, "z": 0, "name": "Wood_Poisoned_Trunk_Full"},
    {"x": -2, "y": 12, "z": 0, "name": "Wood_Poisoned_Trunk_Full"},
    {"x": -2, "y": 13, "z": 0, "name": "Wood_Poisoned_Trunk_Full"},
    {"x": -2, "y": 14, "z": 0, "name": "Wood_Poisoned_Trunk_Full"},
    {"x": -2, "y": 15, "z": 0, "name": "Wood_Poisoned_Trunk_Full"},
    {"x": -2, "y": 22, "z": 0, "name": "Plant_Leaves_Dead"},
    {"x": -2, "y": 1, "z": 1, "name": "Soil_Dirt_Burnt"},
    {"x": -2, "y": 2, "z": 1, "name": "Soil_Dirt_Poisoned"},
    {"x": -2, "y": 3, "z": 1, "name": "Soil_Dirt_Burnt"},
    {"x": -2, "y": 4, "z": 1, "name": "Soil_Dirt_Poisoned"},
    {"x": -2, "y": 5, "z": 1, "name": "Soil_Dirt_Burnt"},
    {"x": -2, "y": 6, "z": 1, "name": "Soil_Pathway"},
    {"x": -2, "y": 8, "z": 1, "name": "Plant_Vine_Wall", "rotation": 1},
    {"x": -2, "y": 9, "z": 1, "name": "Plant_Vine", "rotation": 1},
    {"x": -2, "y": 10, "z": 1, "name": "Wood_Petrified_Trunk_Full"},
    {"x": -2, "y": 11, "z": 1, "name": "Wood_Ash_Trunk_Full"},
    {"x": -2, "y": 12, "z": 1, "name": "Wood_Petrified_Trunk_Full"},
    {"x": -2, "y": 18, "z": 1, "name": "Wood_Poisoned_Trunk_Full"},
    {"x": -2, "y": 21, "z": 1, "name": "Plant_Leaves_Petrified"},
    {"x": -2, "y": 22, "z": 1, "name": "Plant_Leaves_Poisoned"},
    {"x": -2, "y": 1, "z": 2, "name": "Soil_Dirt_Poisoned"},
    {"x": -2, "y": 2, "z": 2, "name": "Soil_Dirt_Burnt"},
    {"x": -2, "y": 3, "z": 2, "name": "Soil_Dirt_Poisoned"},
    {"x": -2, "y": 4, "z": 2, "name": "Wood_Poisoned_Trunk_Full"},
    {"x": -2, "y": 5, "z": 2, "name": "Wood_Ash_Trunk_Full"},
    {"x": -2, "y": 6, "z": 2, "name": "Soil_Pathway"},
    {"x": -2, "y": 7, "z": 2, "name": "Furniture_Kweebec_Bed", "components": {"Components": {"RespawnBlock": {}}}, "rotation": 1},
    {"x": -2, "y": 8, "z": 2, "name": "Furniture_Kweebec_Bed", "filler": 1024, "rotation": 1},
    {"x": -2, "y": 9, "z": 2, "name": "Plant_Seeds_Pine"},
    {"x": -2, "y": 10, "z": 2, "name": "Wood_Petrified_Trunk_Full"},
    {"x": -2, "y": 11, "z": 2, "name": "Wood_Ash_Trunk_Full"},
    {"x": -2, "y": 18, "z": 2, "name": "Wood_Poisoned_Trunk_Full"},
    {"x": -2, "y": 20, "z": 2, "name": "Plant_Leaves_Petrified"},
    {"x": -2, "y": 21, "z": 2, "name": "Plant_Leaves_Poisoned"},
    {"x": -2, "y": 22, "z": 2, "name": "Plant_Leaves_Poisoned"},
    {"x": -2, "y": 1, "z": 3, "name": "Wood_Ash_Trunk_Full"},
    {"x": -2, "y": 2, "z": 3, "name": "Wood_Poisoned_Trunk_Full"},
    {"x": -2, "y": 3, "z": 3, "name": "Soil_Dirt_Burnt"},
    {"x": -2, "y": 4, "z": 3, "name": "Soil_Dirt_Poisoned"},
    {"x": -2, "y": 5, "z": 3, "name": "Soil_Dirt_Burnt"},
    {"x": -2, "y": 6, "z": 3, "name": "Wood_Poisoned_Trunk_Full"},
    {"x": -2, "y": 7, "z": 3, "name": "Wood_Ash_Trunk_Full"},
    {"x": -2, "y": 8, "z": 3, "name": "Wood_Petrified_Trunk_Full"},
    {"x": -2, "y": 9, "z": 3, "name": "Wood_Petrified_Trunk_Full"},
    {"x": -2, "y": 18, "z": 3, "name": "Wood_Petrified_Trunk_Full"},
    {"x": -2, "y": 20, "z": 3, "name": "Plant_Leaves_Dead"},
    {"x": -2, "y": 21, "z": 3, "name": "Plant_Leaves_Dead"},
    {"x": -2, "y": 1, "z": 4, "name": "Soil_Dirt_Poisoned"},
    {"x": -2, "y": 2, "z": 4, "name": "Soil_Dirt_Burnt"},
    {"x": -2, "y": 3, "z": 4, "name": "Soil_Dirt_Poisoned"},
    {"x": -2, "y": 4, "z": 4, "name": "Soil_Dirt_Burnt"},
    {"x": -2, "y": 5, "z": 4, "name": "Soil_Dirt_Poisoned"},
    {"x": -2, "y": 6, "z": 4, "name": "Soil_Grass_Dry"},
    {"x": -2, "y": 19, "z": 5, "name": "Plant_Leaves_Dead"},
    {"x": -2, "y": 20, "z": 5, "name": "Plant_Leaves_Petrified"},
    {"x": -2, "y": 18, "z": 6, "name": "Plant_Leaves_Dead"},
    {"x": -2, "y": 19, "z": 6, "name": "Plant_Leaves_Dead"},
    {"x": -2, "y": 17, "z": 7, "name": "Plant_Leaves_Dead"},
    {"x": -2, "y": 18, "z": 7, "name": "Plant_Leaves_Poisoned"},
    {"x": -2, "y": 19, "z": 7, "name": "Plant_Leaves_Petrified"},
    {"x": -2, "y": 17, "z": 8, "name": "Plant_Leaves_Petrified"},
    {"x": -2, "y": 18, "z": 8, "name": "Plant_Leaves_Petrified"},
    {"x": -1, "y": 17, "z": -8, "name": "Plant_Leaves_Dead"},
    {"x": -1, "y": 18, "z": -8, "name": "Plant_Leaves_Petrified"},
    {"x": -1, "y": 17, "z": -7, "name": "Plant_Leaves_Poisoned"},
    {"x": -1, "y": 18, "z": -7, "name": "Plant_Leaves_Poisoned"},
    {"x": -1, "y": 19, "z": -7, "name": "Plant_Leaves_Dead"},
    {"x": -1, "y": 17, "z": -6, "name": "Wood_Poisoned_Trunk_Full"},
    {"x": -1, "y": 18, "z": -6, "name": "Plant_Leaves_Dead"},
    {"x": -1, "y": 19, "z": -6, "name": "Plant_Leaves_Poisoned"},
    {"x": -1, "y": 20, "z": -6, "name": "Plant_Leaves_Dead"},
    {"x": -1, "y": 16, "z": -5, "name": "Wood_Poisoned_Trunk_Full"},
    {"x": -1, "y": 17, "z": -5, "name": "Wood_Petrified_Trunk_Full"},
    {"x": -1, "y": 18, "z": -5, "name": "Plant_Leaves_Petrified"},
    {"x": -1, "y": 19, "z": -5, "name": "Wood_Petrified_Trunk_Full"},
    {"x": -1, "y": 20, "z": -5, "name": "Plant_Leaves_Petrified"},
    {"x": -1, "y": 21, "z": -5, "name": "Plant_Leaves_Poisoned"},
    {"x": -1, "y": 1, "z": -4, "name": "Soil_Dirt_Burnt"},
    {"x": -1, "y": 2, "z": -4, "name": "Soil_Dirt_Poisoned"},
    {"x": -1, "y": 3, "z": -4, "name": "Soil_Dirt_Burnt"},
    {"x": -1, "y": 4, "z": -4, "name": "Soil_Dirt_Poisoned"},
    {"x": -1, "y": 5, "z": -4, "name": "Soil_Dirt_Burnt"},
    {"x": -1, "y": 6, "z": -4, "name": "Soil_Grass_Burnt"},
    {"x": -1, "y": 16, "z": -4, "name": "Wood_Petrified_Trunk_Full"},
    {"x": -1, "y": 17, "z": -4, "name": "Plant_Leaves_Poisoned"},
    {"x": -1, "y": 18, "z": -4, "name": "Plant_Leaves_Dead"},
    {"x": -1, "y": 19, "z": -4, "name": "Wood_Ash_Trunk_Full"},
    {"x": -1, "y": 20, "z": -4, "name": "Plant_Leaves_Petrified"},
    {"x": -1, "y": 21, "z": -4, "name": "Plant_Leaves_Poisoned"},
    {"x": -1, "y": 22, "z": -4, "name": "Plant_Leaves_Petrified"},
    {"x": -1, "y": 1, "z": -3, "name": "Soil_Dirt_Poisoned"},
    {"x": -1, "y": 2, "z": -3, "name": "Soil_Dirt_Burnt"},
    {"x": -1, "y": 3, "z": -3, "name": "Soil_Dirt_Poisoned"},
    {"x": -1, "y": 4, "z": -3, "name": "Soil_Dirt_Burnt"},
    {"x": -1, "y": 5, "z": -3, "name": "Soil_Dirt_Poisoned"},
    {"x": -1, "y": 6, "z": -3, "name": "Wood_Petrified_Trunk_Full"},
    {"x": -1, "y": 7, "z": -3, "name": "Wood_Poisoned_Trunk_Full"},
    {"x": -1, "y": 8, "z": -3, "name": "Furniture_Kweebec_Window"},
    {"x": -1, "y": 19, "z": -3, "name": "Wood_Poisoned_Trunk_Full"},
    {"x": -1, "y": 20, "z": -3, "name": "Plant_Leaves_Poisoned"},
    {"x": -1, "y": 21, "z": -3, "name": "Plant_Leaves_Petrified"},
    {"x": -1, "y": 22, "z": -3, "name": "Plant_Leaves_Poisoned"},
    {"x": -1, "y": 1, "z": -2, "name": "Soil_Dirt_Burnt"},
    {"x": -1, "y": 2, "z": -2, "name": "Soil_Dirt_Poisoned"},
    {"x": -1, "y": 3, "z": -2, "name": "Soil_Dirt_Burnt"},
    {"x": -1, "y": 4, "z": -2, "name": "Wood_Poisoned_Trunk_Full"},
    {"x": -1, "y": 5, "z": -2, "name": "Wood_Ash_Trunk_Full"},
    {"x": -1, "y": 6, "z": -2, "name": "Soil_Pathway"},
    {"x": -1, "y": 7, "z": -2, "name": "Furniture_Kweebec_Wardrobe", "filler": 31},
    {"x": -1, "y": 8, "z": -2, "name": "Furniture_Kweebec_Wardrobe", "filler": 1055},
    {"x": -1, "y": 9, "z": -2, "name": "Wood_Petrified_Trunk_Full"},
    {"x": -1, "y": 10, "z": -2, "name": "Wood_Ash_Trunk_Full"},
    {"x": -1, "y": 14, "z": -2, "name": "Wood_Ash_Trunk_Full"},
    {"x": -1, "y": 15, "z": -2, "name": "Wood_Poisoned_Trunk_Full"},
    {"x": -1, "y": 20, "z": -2, "name": "Plant_Leaves_Poisoned"},
    {"x": -1, "y": 22, "z": -2, "name": "Plant_Leaves_Dead"},
    {"x": -1, "y": 1, "z": -1, "name": "Soil_Dirt_Poisoned"},
    {"x": -1, "y": 2, "z": -1, "name": "Soil_Dirt_Burnt"},
    {"x": -1, "y": 3, "z": -1, "name": "Soil_Dirt_Poisoned"},
    {"x": -1, "y": 4, "z": -1, "name": "Wood_Ash_Trunk_Full"},
    {"x": -1, "y": 6, "z": -1, "name": "Soil_Pathway"},
    {"x": -1, "y": 10, "z": -1, "name": "Wood_Petrified_Trunk_Full"},
    {"x": -1, "y": 11, "z": -1, "name": "Wood_Ash_Trunk_Full"},
    {"x": -1, "y": 12, "z": -1, "name": "Wood_Petrified_Trunk_Full"},
    {"x": -1, "y": 13, "z": -1, "name": "Wood_Petrified_Trunk_Full"},
    {"x": -1, "y": 14, "z": -1, "name": "Wood_Petrified_Trunk_Full"},
    {"x": -1, "y": 15, "z": -1, "name": "Wood_Petrified_Trunk_Full"},
    {"x": -1, "y": 20, "z": -1, "name": "Plant_Leaves_Dead"},
    {"x": -1, "y": 21, "z": -1, "name": "Plant_Leaves_Dead"},
    {"x": -1, "y": 22, "z": -1, "name": "Plant_Leaves_Petrified"},
    {"x": -1, "y": 23, "z": -1, "name": "Plant_Leaves_Dead"},
    {"x": -1, "y": 1, "z": 0, "name": "Soil_Dirt_Burnt"},
    {"x": -1, "y": 2, "z": 0, "name": "Soil_Dirt_Poisoned"},
    {"x": -1, "y": 3, "z": 0, "name": "Soil_Dirt_Burnt"},
    {"x": -1, "y": 4, "z": 0, "name": "Soil_Dirt_Poisoned"},
    {"x": -1, "y": 5, "z": 0, "name": "Soil_Dirt_Burnt"},
    {"x": -1, "y": 6, "z": 0, "name": "Soil_Grass_Burnt"},
    {"x": -1, "y": 10, "z": 0, "name": "Wood_Petrified_Trunk_Full"},
    {"x": -1, "y": 11, "z": 0, "name": "Wood_Poisoned_Trunk_Full"},
    {"x": -1, "y": 12, "z": 0, "name": "Wood_Petrified_Trunk_Full"},
    {"x": -1, "y": 13, "z": 0, "name": "Wood_Petrified_Trunk_Full"},
    {"x": -1, "y": 14, "z": 0, "name": "Wood_Petrified_Trunk_Full"},
    {"x": -1, "y": 15, "z": 0, "name": "Wood_Petrified_Trunk_Full"},
    {"x": -1, "y": 16, "z": 0, "name": "Wood_Poisoned_Trunk_Full"},
    {"x": -1, "y": 17, "z": 0, "name": "Wood_Poisoned_Trunk_Full"},
    {"x": -1, "y": 18, "z": 0, "name": "Wood_Poisoned_Trunk_Full"},
    {"x": -1, "y": 19, "z": 0, "name": "Wood_Poisoned_Trunk_Full"},
    {"x": -1, "y": 21, "z": 0, "name": "Plant_Leaves_Poisoned"},
    {"x": -1, "y": 22, "z": 0, "name": "Plant_Leaves_Petrified"},
    {"x": -1, "y": 23, "z": 0, "name": "Plant_Leaves_Poisoned"},
    {"x": -1, "y": 1, "z": 1, "name": "Soil_Dirt_Poisoned"},
    {"x": -1, "y": 2, "z": 1, "name": "Soil_Dirt_Burnt"},
    {"x": -1, "y": 3, "z": 1, "name": "Soil_Dirt_Poisoned"},
    {"x": -1, "y": 4, "z": 1, "name": "Soil_Dirt_Burnt"},
    {"x": -1, "y": 5, "z": 1, "name": "Soil_Dirt_Poisoned"},
    {"x": -1, "y": 6, "z": 1, "name": "Soil_Leaves"},
    {"x": -1, "y": 10, "z": 1, "name": "Wood_Poisoned_Trunk_Full"},
    {"x": -1, "y": 11, "z": 1, "name": "Wood_Petrified_Trunk_Full"},
    {"x": -1, "y": 12, "z": 1, "name": "Wood_Poisoned_Trunk_Full"},
    {"x": -1, "y": 13, "z": 1, "name": "Wood_Ash_Trunk_Full"},
    {"x": -1, "y": 16, "z": 1, "name": "Wood_Ash_Trunk_Full"},
    {"x": -1, "y": 17, "z": 1, "name": "Wood_Petrified_Trunk_Full"},
    {"x": -1, "y": 18, "z": 1, "name": "Wood_Ash_Trunk_Full"},
    {"x": -1, "y": 21, "z": 1, "name": "Plant_Leaves_Petrified"},
    {"x": -1, "y": 22, "z": 1, "name": "Plant_Leaves_Poisoned"},
    {"x": -1, "y": 1, "z": 2, "name": "Soil_Dirt_Burnt"},
    {"x": -1, "y": 2, "z": 2, "name": "Soil_Dirt_Poisoned"},
    {"x": -1, "y": 3, "z": 2, "name": "Soil_Dirt_Burnt"},
    {"x": -1, "y": 4, "z": 2, "name": "Wood_Ash_Trunk_Full"},
    {"x": -1, "y": 5, "z": 2, "name": "Wood_Poisoned_Trunk_Full"},
    {"x": -1, "y": 6, "z": 2, "name": "Soil_Pathway"},
    {"x": -1, "y": 7, "z": 2, "name": "Furniture_Kweebec_Bed", "filler": 1, "rotation": 1},
    {"x": -1, "y": 8, "z": 2, "name": "Furniture_Kweebec_Bed", "filler": 1025, "rotation": 1},
    {"x": -1, "y": 10, "z": 2, "name": "Wood_Ash_Trunk_Full"},
    {"x": -1, "y": 11, "z": 2, "name": "Wood_Ash_Trunk_Full"},
    {"x": -1, "y": 12, "z": 2, "name": "Wood_Poisoned_Trunk_Full"},
    {"x": -1, "y": 20, "z": 2, "name": "Plant_Leaves_Dead"},
    {"x": -1, "y": 21, "z": 2, "name": "Plant_Leaves_Petrified"},
    {"x": -1, "y": 22, "z": 2, "name": "Plant_Leaves_Dead"},
    {"x": -1, "y": 23, "z": 2, "name": "Plant_Leaves_Dead"},
    {"x": -1, "y": 1, "z": 3, "name": "Soil_Dirt_Poisoned"},
    {"x": -1, "y": 2, "z": 3, "name": "Wood_Ash_Trunk_Full"},
    {"x": -1, "y": 3, "z": 3, "name": "Wood_Ash_Trunk_Full"},
    {"x": -1, "y": 4, "z": 3, "name": "Wood_Petrified_Trunk_Full"},
    {"x": -1, "y": 5, "z": 3, "name": "Soil_Dirt_Poisoned"},
    {"x": -1, "y": 6, "z": 3, "name": "Wood_Poisoned_Trunk_Full"},
    {"x": -1, "y": 7, "z": 3, "name": "Wood_Poisoned_Trunk_Full"},
    {"x": -1, "y": 8, "z": 3, "name": "Furniture_Kweebec_Window"},
    {"x": -1, "y": 9, "z": 3, "name": "Wood_Ash_Trunk_Full"},
    {"x": -1, "y": 10, "z": 3, "name": "Wood_Petrified_Trunk_Full"},
    {"x": -1, "y": 18, "z": 3, "name": "Wood_Poisoned_Trunk_Full"},
    {"x": -1, "y": 19, "z": 3, "name": "Plant_Leaves_Poisoned"},
    {"x": -1, "y": 20, "z": 3, "name": "Plant_Leaves_Petrified"},
    {"x": -1, "y": 21, "z": 3, "name": "Plant_Leaves_Dead"},
    {"x": -1, "y": 22, "z": 3, "name": "Plant_Leaves_Petrified"},
    {"x": -1, "y": 23, "z": 3, "name": "Plant_Leaves_Poisoned"},
    {"x": -1, "y": 1, "z": 4, "name": "Soil_Dirt_Burnt"},
    {"x": -1, "y": 2, "z": 4, "name": "Soil_Dirt_Poisoned"},
    {"x": -1, "y": 3, "z": 4, "name": "Soil_Dirt_Burnt"},
    {"x": -1, "y": 4, "z": 4, "name": "Soil_Dirt_Poisoned"},
    {"x": -1, "y": 5, "z": 4, "name": "Soil_Dirt_Burnt"},
    {"x": -1, "y": 6, "z": 4, "name": "Soil_Grass_Burnt"},
    {"x": -1, "y": 18, "z": 4, "name": "Wood_Petrified_Trunk_Full"},
    {"x": -1, "y": 20, "z": 4, "name": "Plant_Leaves_Petrified"},
    {"x": -1, "y": 22, "z": 4, "name": "Plant_Leaves_Poisoned"},
    {"x": -1, "y": 19, "z": 5, "name": "Plant_Leaves_Dead"},
    {"x": -1, "y": 20, "z": 5, "name": "Plant_Leaves_Poisoned"},
    {"x": -1, "y": 19, "z": 6, "name": "Plant_Leaves_Poisoned"},
    {"x": -1, "y": 20, "z": 6, "name": "Plant_Leaves_Poisoned"},
    {"x": -1, "y": 18, "z": 7, "name": "Plant_Leaves_Petrified"},
    {"x": -1, "y": 19, "z": 7, "name": "Plant_Leaves_Petrified"},
    {"x": -1, "y": 20, "z": 7, "name": "Plant_Leaves_Dead"},
    {"x": -1, "y": 17, "z": 8, "name": "Plant_Leaves_Dead"},
    {"x": -1, "y": 18, "z": 8, "name": "Plant_Leaves_Petrified"},
    {"x": -1, "y": 19, "z": 8, "name": "Plant_Leaves_Petrified"},
    {"x": -1, "y": 17, "z": 9, "name": "Plant_Leaves_Poisoned"},
    {"x": -1, "y": 18, "z": 9, "name": "Plant_Leaves_Poisoned"},
    {"x": 0, "y": 18, "z": -8, "name": "Plant_Leaves_Dead"},
    {"x": 0, "y": 19, "z": -8, "name": "Plant_Leaves_Dead"},
    {"x": 0, "y": 16, "z": -7, "name": "Plant_Leaves_Petrified"},
    {"x": 0, "y": 17, "z": -7, "name": "Plant_Leaves_Dead"},
    {"x": 0, "y": 18, "z": -7, "name": "Plant_Leaves_Poisoned"},
    {"x": 0, "y": 19, "z": -7, "name": "Plant_Leaves_Petrified"},
    {"x": 0, "y": 16, "z": -6, "name": "Plant_Leaves_Petrified"},
    {"x": 0, "y": 17, "z": -6, "name": "Plant_Leaves_Dead"},
    {"x": 0, "y": 18, "z": -6, "name": "Plant_Leaves_Petrified"},
    {"x": 0, "y": 19, "z": -6, "name": "Plant_Leaves_Poisoned"},
    {"x": 0, "y": 20, "z": -6, "name": "Plant_Leaves_Poisoned"},
    {"x": 0, "y": 4, "z": -5, "name": "Wood_Poisoned_Trunk_Full"},
    {"x": 0, "y": 5, "z": -5, "name": "Wood_Petrified_Trunk_Full"},
    {"x": 0, "y": 17, "z": -5, "name": "Plant_Leaves_Petrified"},
    {"x": 0, "y": 18, "z": -5, "name": "Plant_Leaves_Dead"},
    {"x": 0, "y": 19, "z": -5, "name": "Plant_Leaves_Dead"},
    {"x": 0, "y": 20, "z": -5, "name": "Plant_Leaves_Petrified"},
    {"x": 0, "y": 22, "z": -5, "name": "Plant_Leaves_Petrified"},
    {"x": 0, "y": 1, "z": -4, "name": "Soil_Dirt_Poisoned"},
    {"x": 0, "y": 2, "z": -4, "name": "Soil_Dirt_Burnt"},
    {"x": 0, "y": 3, "z": -4, "name": "Soil_Dirt_Poisoned"},
    {"x": 0, "y": 4, "z": -4, "name": "Soil_Dirt_Burnt"},
    {"x": 0, "y": 5, "z": -4, "name": "Wood_Petrified_Trunk_Full"},
    {"x": 0, "y": 6, "z": -4, "name": "Wood_Ash_Trunk_Full"},
    {"x": 0, "y": 7, "z": -4, "name": "Wood_Ash_Trunk_Full"},
    {"x": 0, "y": 8, "z": -4, "name": "Wood_Poisoned_Trunk_Full"},
    {"x": 0, "y": 17, "z": -4, "name": "Plant_Leaves_Dead"},
    {"x": 0, "y": 20, "z": -4, "name": "Plant_Leaves_Petrified"},
    {"x": 0, "y": 21, "z": -4, "name": "Plant_Leaves_Dead"},
    {"x": 0, "y": 22, "z": -4, "name": "Plant_Leaves_Poisoned"},
    {"x": 0, "y": 1, "z": -3, "name": "Soil_Dirt_Burnt"},
    {"x": 0, "y": 2, "z": -3, "name": "Soil_Dirt_Poisoned"},
    {"x": 0, "y": 3, "z": -3, "name": "Soil_Dirt_Burnt"},
    {"x": 0, "y": 4, "z": -3, "name": "Soil_Dirt_Poisoned"},
    {"x": 0, "y": 5, "z": -3, "name": "Wood_Poisoned_Trunk_Full"},
    {"x": 0, "y": 6, "z": -3, "name": "Wood_Poisoned_Trunk_Full"},
    {"x": 0, "y": 7, "z": -3, "name": "Wood_Petrified_Trunk_Full"},
    {"x": 0, "y": 8, "z": -3, "name": "Wood_Petrified_Trunk_Full"},
    {"x": 0, "y": 9, "z": -3, "name": "Wood_Ash_Trunk_Full"},
    {"x": 0, "y": 19, "z": -3, "name": "Wood_Ash_Trunk_Full"},
    {"x": 0, "y": 22, "z": -3, "name": "Plant_Leaves_Petrified"},
    {"x": 0, "y": 23, "z": -3, "name": "Plant_Leaves_Petrified"},
    {"x": 0, "y": 1, "z": -2, "name": "Soil_Dirt_Poisoned"},
    {"x": 0, "y": 2, "z": -2, "name": "Soil_Dirt_Burnt"},
    {"x": 0, "y": 3, "z": -2, "name": "Soil_Dirt_Poisoned"},
    {"x": 0, "y": 4, "z": -2, "name": "Wood_Petrified_Trunk_Full"},
    {"x": 0, "y": 5, "z": -2, "name": "Wood_Poisoned_Trunk_Full"},
    {"x": 0, "y": 6, "z": -2, "name": "Soil_Pathway"},
    {"x": 0, "y": 7, "z": -2, "name": "Furniture_Kweebec_Wardrobe"},
    {"x": 0, "y": 8, "z": -2, "name": "Furniture_Kweebec_Wardrobe", "filler": 1024},
    {"x": 0, "y": 10, "z": -2, "name": "Wood_Poisoned_Trunk_Full"},
    {"x": 0, "y": 11, "z": -2, "name": "Wood_Ash_Trunk_Full"},
    {"x": 0, "y": 12, "z": -2, "name": "Wood_Poisoned_Trunk_Full"},
    {"x": 0, "y": 17, "z": -2, "name": "Wood_Petrified_Trunk_Full"},
    {"x": 0, "y": 22, "z": -2, "name": "Plant_Leaves_Dead"},
    {"x": 0, "y": 23, "z": -2, "name": "Plant_Leaves_Poisoned"},
    {"x": 0, "y": 1, "z": -1, "name": "Soil_Dirt_Burnt"},
    {"x": 0, "y": 2, "z": -1, "name": "Soil_Dirt_Poisoned"},
    {"x": 0, "y": 3, "z": -1, "name": "Wood_Ash_Trunk_Full"},
    {"x": 0, "y": 4, "z": -1, "name": "Wood_Ash_Trunk_Full"},
    {"x": 0, "y": 5, "z": -1, "name": "Wood_Ash_Trunk_Full"},
    {"x": 0, "y": 6, "z": -1, "name": "Soil_Pathway"},
    {"x": 0, "y": 10, "z": -1, "name": "Wood_Petrified_Trunk_Full"},
    {"x": 0, "y": 11, "z": -1, "name": "Wood_Petrified_Trunk_Full"},
    {"x": 0, "y": 12, "z": -1, "name": "Wood_Petrified_Trunk_Full"},
    {"x": 0, "y": 13, "z": -1, "name": "Wood_Petrified_Trunk_Full"},
    {"x": 0, "y": 14, "z": -1, "name": "Wood_Petrified_Trunk_Full"},
    {"x": 0, "y": 17, "z": -1, "name": "Wood_Poisoned_Trunk_Full"},
    {"x": 0, "y": 21, "z": -1, "name": "Plant_Leaves_Poisoned"},
    {"x": 0, "y": 22, "z": -1, "name": "Plant_Leaves_Poisoned"},
    {"x": 0, "y": 23, "z": -1, "name": "Plant_Leaves_Dead"},
    {"x": 0, "y": 1, "z": 0, "name": "Wood_Ash_Trunk_Full"},
    {"x": 0, "y": 2, "z": 0, "name": "Wood_Poisoned_Trunk_Full"},
    {"x": 0, "y": 3, "z": 0, "name": "Wood_Poisoned_Trunk_Full"},
    {"x": 0, "y": 6, "z": 0, "name": "Soil_Leaves"},
    {"x": 0, "y": 10, "z": 0, "name": "Wood_Petrified_Trunk_Full"},
    {"x": 0, "y": 11, "z": 0, "name": "Wood_Petrified_Trunk_Full"},
    {"x": 0, "y": 12, "z": 0, "name": "Wood_Petrified_Trunk_Full"},
    {"x": 0, "y": 13, "z": 0, "name": "Wood_Petrified_Trunk_Full"},
    {"x": 0, "y": 14, "z": 0, "name": "Wood_Petrified_Trunk_Full"},
    {"x": 0, "y": 15, "z": 0, "name": "Wood_Petrified_Trunk_Full"},
    {"x": 0, "y": 16, "z": 0, "name": "Wood_Ash_Trunk_Full"},
    {"x": 0, "y": 17, "z": 0, "name": "Wood_Ash_Trunk_Full"},
    {"x": 0, "y": 18, "z": 0, "name": "Wood_Ash_Trunk_Full"},
    {"x": 0, "y": 19, "z": 0, "name": "Wood_Ash_Trunk_Full"},
    {"x": 0, "y": 20, "z": 0, "name": "Wood_Ash_Trunk_Full"},
    {"x": 0, "y": 21, "z": 0, "name": "Plant_Leaves_Dead"},
    {"x": 0, "y": 22, "z": 0, "name": "Plant_Leaves_Dead"},
    {"x": 0, "y": 23, "z": 0, "name": "Plant_Leaves_Poisoned"},
    {"x": 0, "y": 24, "z": 0, "name": "Plant_Leaves_Poisoned"},
    {"x": 0, "y": 1, "z": 1, "name": "Soil_Dirt_Burnt"},
    {"x": 0, "y": 2, "z": 1, "name": "Soil_Dirt_Poisoned"},
    {"x": 0, "y": 3, "z": 1, "name": "Soil_Dirt_Burnt"},
    {"x": 0, "y": 4, "z": 1, "name": "Soil_Dirt_Poisoned"},
    {"x": 0, "y": 5, "z": 1, "name": "Soil_Dirt_Burnt"},
    {"x": 0, "y": 6, "z": 1, "name": "Soil_Leaves"},
    {"x": 0, "y": 7, "z": 1, "name": "Furniture_Kweebec_Stool"},
    {"x": 0, "y": 10, "z": 1, "name": "Wood_Ash_Trunk_Full"},
    {"x": 0, "y": 11, "z": 1, "name": "Wood_Poisoned_Trunk_Full"},
    {"x": 0, "y": 12, "z": 1, "name": "Wood_Ash_Trunk_Full"},
    {"x": 0, "y": 21, "z": 1, "name": "Plant_Leaves_Petrified"},
    {"x": 0, "y": 22, "z": 1, "name": "Plant_Leaves_Poisoned"},
    {"x": 0, "y": 23, "z": 1, "name": "Plant_Leaves_Dead"},
    {"x": 0, "y": 1, "z": 2, "name": "Soil_Dirt_Poisoned"},
    {"x": 0, "y": 2, "z": 2, "name": "Soil_Dirt_Burnt"},
    {"x": 0, "y": 3, "z": 2, "name": "Soil_Dirt_Poisoned"},
    {"x": 0, "y": 4, "z": 2, "name": "Soil_Dirt_Burnt"},
    {"x": 0, "y": 5, "z": 2, "name": "Soil_Dirt_Poisoned"},
    {"x": 0, "y": 6, "z": 2, "name": "Soil_Leaves"},
    {"x": 0, "y": 7, "z": 2, "name": "Furniture_Kweebec_Platform"},
    {"x": 0, "y": 8, "z": 2, "name": "Deco_Nest"},
    {"x": 0, "y": 10, "z": 2, "name": "Wood_Poisoned_Trunk_Full"},
    {"x": 0, "y": 11, "z": 2, "name": "Wood_Ash_Trunk_Full"},
    {"x": 0, "y": 12, "z": 2, "name": "Wood_Ash_Trunk_Full"},
    {"x": 0, "y": 22, "z": 2, "name": "Plant_Leaves_Petrified"},
    {"x": 0, "y": 23, "z": 2, "name": "Plant_Leaves_Petrified"},
    {"x": 0, "y": 1, "z": 3, "name": "Soil_Dirt_Burnt"},
    {"x": 0, "y": 2, "z": 3, "name": "Soil_Dirt_Poisoned"},
    {"x": 0, "y": 3, "z": 3, "name": "Soil_Dirt_Burnt"},
    {"x": 0, "y": 4, "z": 3, "name": "Soil_Dirt_Poisoned"},
    {"x": 0, "y": 5, "z": 3, "name": "Wood_Petrified_Trunk_Full"},
    {"x": 0, "y": 6, "z": 3, "name": "Wood_Poisoned_Trunk_Full"},
    {"x": 0, "y": 7, "z": 3, "name": "Wood_Poisoned_Trunk_Full"},
    {"x": 0, "y": 8, "z": 3, "name": "Wood_Ash_Trunk_Full"},
    {"x": 0, "y": 9, "z": 3, "name": "Wood_Ash_Trunk_Full"},
    {"x": 0, "y": 10, "z": 3, "name": "Wood_Petrified_Trunk_Full"},
    {"x": 0, "y": 19, "z": 3, "name": "Plant_Leaves_Dead"},
    {"x": 0, "y": 20, "z": 3, "name": "Plant_Leaves_Petrified"},
    {"x": 0, "y": 21, "z": 3, "name": "Plant_Leaves_Poisoned"},
    {"x": 0, "y": 22, "z": 3, "name": "Plant_Leaves_Dead"},
    {"x": 0, "y": 23, "z": 3, "name": "Plant_Leaves_Poisoned"},
    {"x": 0, "y": 1, "z": 4, "name": "Soil_Dirt_Poisoned"},
    {"x": 0, "y": 2, "z": 4, "name": "Soil_Dirt_Burnt"},
    {"x": 0, "y": 3, "z": 4, "name": "Soil_Dirt_Poisoned"},
    {"x": 0, "y": 4, "z": 4, "name": "Soil_Dirt_Burnt"},
    {"x": 0, "y": 5, "z": 4, "name": "Soil_Dirt_Poisoned"},
    {"x": 0, "y": 6, "z": 4, "name": "Soil_Grass_Dry"},
    {"x": 0, "y": 18, "z": 4, "name": "Wood_Poisoned_Trunk_Full"},
    {"x": 0, "y": 19, "z": 4, "name": "Wood_Poisoned_Trunk_Full"},
    {"x": 0, "y": 20, "z": 4, "name": "Plant_Leaves_Petrified"},
    {"x": 0, "y": 21, "z": 4, "name": "Plant_Leaves_Poisoned"},
    {"x": 0, "y": 22, "z": 4, "name": "Plant_Leaves_Petrified"},
    {"x": 0, "y": 19, "z": 5, "name": "Plant_Leaves_Dead"},
    {"x": 0, "y": 20, "z": 5, "name": "Plant_Leaves_Dead"},
    {"x": 0, "y": 21, "z": 5, "name": "Plant_Leaves_Dead"},
    {"x": 0, "y": 19, "z": 6, "name": "Plant_Leaves_Petrified"},
    {"x": 0, "y": 20, "z": 6, "name": "Plant_Leaves_Dead"},
    {"x": 0, "y": 19, "z": 7, "name": "Plant_Leaves_Poisoned"},
    {"x": 0, "y": 20, "z": 7, "name": "Plant_Leaves_Poisoned"},
    {"x": 0, "y": 17, "z": 8, "name": "Plant_Leaves_Petrified"},
    {"x": 0, "y": 18, "z": 8, "name": "Plant_Leaves_Poisoned"},
    {"x": 0, "y": 19, "z": 8, "name": "Plant_Leaves_Poisoned"},
    {"x": 0, "y": 20, "z": 8, "name": "Plant_Leaves_Poisoned"},
    {"x": 0, "y": 17, "z": 9, "name": "Plant_Leaves_Poisoned"},
    {"x": 0, "y": 18, "z": 9, "name": "Plant_Leaves_Petrified"},
    {"x": 1, "y": 18, "z": -8, "name": "Plant_Leaves_Dead"},
    {"x": 1, "y": 16, "z": -7, "name": "Plant_Leaves_Poisoned"},
    {"x": 1, "y": 18, "z": -7, "name": "Plant_Leaves_Petrified"},
    {"x": 1, "y": 19, "z": -7, "name": "Plant_Leaves_Poisoned"},
    {"x": 1, "y": 16, "z": -6, "name": "Plant_Leaves_Dead"},
    {"x": 1, "y": 17, "z": -6, "name": "Plant_Leaves_Poisoned"},
    {"x": 1, "y": 20, "z": -6, "name": "Plant_Leaves_Poisoned"},
    {"x": 1, "y": 21, "z": -6, "name": "Plant_Leaves_Petrified"},
    {"x": 1, "y": 2, "z": -5, "name": "Wood_Petrified_Trunk_Full"},
    {"x": 1, "y": 3, "z": -5, "name": "Wood_Ash_Trunk_Full"},
    {"x": 1, "y": 4, "z": -5, "name": "Wood_Poisoned_Trunk_Full"},
    {"x": 1, "y": 17, "z": -5, "name": "Plant_Leaves_Petrified"},
    {"x": 1, "y": 20, "z": -5, "name": "Plant_Leaves_Dead"},
    {"x": 1, "y": 21, "z": -5, "name": "Plant_Leaves_Dead"},
    {"x": 1, "y": 1, "z": -4, "name": "Soil_Dirt_Burnt"},
    {"x": 1, "y": 2, "z": -4, "name": "Soil_Dirt_Poisoned"},
    {"x": 1, "y": 3, "z": -4, "name": "Soil_Dirt_Burnt"},
    {"x": 1, "y": 4, "z": -4, "name": "Soil_Dirt_Poisoned"},
    {"x": 1, "y": 5, "z": -4, "name": "Soil_Dirt_Burnt"},
    {"x": 1, "y": 6, "z": -4, "name": "Soil_Leaves"},
    {"x": 1, "y": 7, "z": -4, "name": "Plant_Grass_Lush_Short"},
    {"x": 1, "y": 20, "z": -4, "name": "Plant_Leaves_Petrified"},
    {"x": 1, "y": 1, "z": -3, "name": "Soil_Dirt_Poisoned"},
    {"x": 1, "y": 2, "z": -3, "name": "Soil_Dirt_Burnt"},
    {"x": 1, "y": 3, "z": -3, "name": "Soil_Dirt_Poisoned"},
    {"x": 1, "y": 4, "z": -3, "name": "Soil_Dirt_Burnt"},
    {"x": 1, "y": 5, "z": -3, "name": "Soil_Dirt_Poisoned"},
    {"x": 1, "y": 6, "z": -3, "name": "Wood_Poisoned_Trunk_Full"},
    {"x": 1, "y": 7, "z": -3, "name": "Wood_Petrified_Trunk_Full"},
    {"x": 1, "y": 8, "z": -3, "name": "Wood_Poisoned_Trunk_Full"},
    {"x": 1, "y": 9, "z": -3, "name": "Wood_Poisoned_Trunk_Full"},
    {"x": 1, "y": 18, "z": -3, "name": "Wood_Poisoned_Trunk_Full"},
    {"x": 1, "y": 19, "z": -3, "name": "Wood_Petrified_Trunk_Full"},
    {"x": 1, "y": 22, "z": -3, "name": "Plant_Leaves_Poisoned"},
    {"x": 1, "y": 23, "z": -3, "name": "Plant_Leaves_Petrified"},
    {"x": 1, "y": 1, "z": -2, "name": "Soil_Dirt_Burnt"},
    {"x": 1, "y": 2, "z": -2, "name": "Soil_Dirt_Poisoned"},
    {"x": 1, "y": 3, "z": -2, "name": "Soil_Dirt_Burnt"},
    {"x": 1, "y": 4, "z": -2, "name": "Soil_Dirt_Poisoned"},
    {"x": 1, "y": 5, "z": -2, "name": "Soil_Dirt_Burnt"},
    {"x": 1, "y": 6, "z": -2, "name": "Wood_Poisoned_Trunk_Full"},
    {"x": 1, "y": 7, "z": -2, "name": "Block_Spawner_Block", "components": {"Components": {"BlockSpawner": {"BlockSpawnerId": "Zone1_Kweebec_Tier3"}}}},
    {"x": 1, "y": 8, "z": -2, "name": "Furniture_Kweebec_Lantern"},
    {"x": 1, "y": 9, "z": -2, "name": "Deco_Rope"},
    {"x": 1, "y": 10, "z": -2, "name": "Wood_Poisoned_Trunk_Full"},
    {"x": 1, "y": 17, "z": -2, "name": "Wood_Petrified_Trunk_Full"},
    {"x": 1, "y": 18, "z": -2, "name": "Wood_Poisoned_Trunk_Full"},
    {"x": 1, "y": 21, "z": -2, "name": "Plant_Leaves_Poisoned"},
    {"x": 1, "y": 22, "z": -2, "name": "Plant_Leaves_Poisoned"},
    {"x": 1, "y": 23, "z": -2, "name": "Plant_Leaves_Petrified"},
    {"x": 1, "y": 24, "z": -2, "name": "Plant_Leaves_Dead"},
    {"x": 1, "y": 1, "z": -1, "name": "Soil_Dirt_Poisoned"},
    {"x": 1, "y": 2, "z": -1, "name": "Soil_Dirt_Burnt"},
    {"x": 1, "y": 3, "z": -1, "name": "Soil_Dirt_Poisoned"},
    {"x": 1, "y": 4, "z": -1, "name": "Soil_Dirt_Burnt"},
    {"x": 1, "y": 5, "z": -1, "name": "Soil_Dirt_Poisoned"},
    {"x": 1, "y": 6, "z": -1, "name": "Soil_Pathway"},
    {"x": 1, "y": 10, "z": -1, "name": "Wood_Ash_Trunk_Full"},
    {"x": 1, "y": 11, "z": -1, "name": "Wood_Ash_Trunk_Full"},
    {"x": 1, "y": 21, "z": -1, "name": "Plant_Leaves_Petrified"},
    {"x": 1, "y": 22, "z": -1, "name": "Plant_Leaves_Dead"},
    {"x": 1, "y": 23, "z": -1, "name": "Plant_Leaves_Dead"},
    {"x": 1, "y": 24, "z": -1, "name": "Plant_Leaves_Petrified"},
    {"x": 1, "y": 1, "z": 0, "name": "Soil_Dirt_Burnt"},
    {"x": 1, "y": 2, "z": 0, "name": "Soil_Dirt_Poisoned"},
    {"x": 1, "y": 3, "z": 0, "name": "Soil_Dirt_Burnt"},
    {"x": 1, "y": 4, "z": 0, "name": "Soil_Dirt_Poisoned"},
    {"x": 1, "y": 5, "z": 0, "name": "Soil_Dirt_Burnt"},
    {"x": 1, "y": 6, "z": 0, "name": "Soil_Grass_Burnt"},
    {"x": 1, "y": 9, "z": 0, "name": "Plant_Vine", "rotation": 3},
    {"x": 1, "y": 10, "z": 0, "name": "Wood_Poisoned_Trunk_Full"},
    {"x": 1, "y": 11, "z": 0, "name": "Wood_Poisoned_Trunk_Full"},
    {"x": 1, "y": 12, "z": 0, "name": "Wood_Petrified_Trunk_Full"},
    {"x": 1, "y": 15, "z": 0, "name": "Wood_Petrified_Trunk_Full"},
    {"x": 1, "y": 16, "z": 0, "name": "Wood_Poisoned_Trunk_Full"},
    {"x": 1, "y": 20, "z": 0, "name": "Wood_Petrified_Trunk_Full"},
    {"x": 1, "y": 21, "z": 0, "name": "Plant_Leaves_Petrified"},
    {"x": 1, "y": 22, "z": 0, "name": "Plant_Leaves_Poisoned"},
    {"x": 1, "y": 23, "z": 0, "name": "Plant_Leaves_Poisoned"},
    {"x": 1, "y": 24, "z": 0, "name": "Plant_Leaves_Petrified"},
    {"x": 1, "y": 1, "z": 1, "name": "Soil_Dirt_Poisoned"},
    {"x": 1, "y": 2, "z": 1, "name": "Soil_Dirt_Burnt"},
    {"x": 1, "y": 3, "z": 1, "name": "Soil_Dirt_Poisoned"},
    {"x": 1, "y": 4, "z": 1, "name": "Soil_Dirt_Burnt"},
    {"x": 1, "y": 5, "z": 1, "name": "Soil_Dirt_Poisoned"},
    {"x": 1, "y": 6, "z": 1, "name": "Soil_Grass_Dry"},
    {"x": 1, "y": 7, "z": 1, "name": "Plant_Crop_Mushroom_Common_Brown", "components": {"Components": {"FarmingBlock": {}}}},
    {"x": 1, "y": 9, "z": 1, "name": "Plant_Vine_Wall", "rotation": 3},
    {"x": 1, "y": 10, "z": 1, "name": "Wood_Ash_Trunk_Full"},
    {"x": 1, "y": 11, "z": 1, "name": "Wood_Petrified_Trunk_Full"},
    {"x": 1, "y": 16, "z": 1, "name": "Wood_Ash_Trunk_Full"},
    {"x": 1, "y": 20, "z": 1, "name": "Plant_Leaves_Poisoned"},
    {"x": 1, "y": 21, "z": 1, "name": "Plant_Leaves_Dead"},
    {"x": 1, "y": 22, "z": 1, "name": "Plant_Leaves_Dead"},
    {"x": 1, "y": 23, "z": 1, "name": "Plant_Leaves_Petrified"},
    {"x": 1, "y": 24, "z": 1, "name": "Plant_Leaves_Poisoned"},
    {"x": 1, "y": 1, "z": 2, "name": "Soil_Dirt_Burnt"},
    {"x": 1, "y": 2, "z": 2, "name": "Soil_Dirt_Poisoned"},
    {"x": 1, "y": 3, "z": 2, "name": "Soil_Dirt_Burnt"},
    {"x": 1, "y": 4, "z": 2, "name": "Soil_Dirt_Poisoned"},
    {"x": 1, "y": 5, "z": 2, "name": "Soil_Dirt_Burnt"},
    {"x": 1, "y": 6, "z": 2, "name": "Soil_Pathway"},
    {"x": 1, "y": 7, "z": 2, "name": "Wood_Petrified_Trunk_Full"},
    {"x": 1, "y": 8, "z": 2, "name": "Wood_Ash_Trunk_Full"},
    {"x": 1, "y": 9, "z": 2, "name": "Wood_Poisoned_Trunk_Full"},
    {"x": 1, "y": 10, "z": 2, "name": "Wood_Ash_Trunk_Full"},
    {"x": 1, "y": 11, "z": 2, "name": "Wood_Petrified_Trunk_Full"},
    {"x": 1, "y": 21, "z": 2, "name": "Plant_Leaves_Poisoned"},
    {"x": 1, "y": 22, "z": 2, "name": "Plant_Leaves_Dead"},
    {"x": 1, "y": 23, "z": 2, "name": "Plant_Leaves_Petrified"},
    {"x": 1, "y": 1, "z": 3, "name": "Soil_Dirt_Poisoned"},
    {"x": 1, "y": 2, "z": 3, "name": "Soil_Dirt_Burnt"},
    {"x": 1, "y": 3, "z": 3, "name": "Soil_Dirt_Poisoned"},
    {"x": 1, "y": 4, "z": 3, "name": "Soil_Dirt_Burnt"},
    {"x": 1, "y": 5, "z": 3, "name": "Soil_Dirt_Poisoned"},
    {"x": 1, "y": 6, "z": 3, "name": "Wood_Petrified_Trunk_Full"},
    {"x": 1, "y": 7, "z": 3, "name": "Wood_Ash_Trunk_Full"},
    {"x": 1, "y": 8, "z": 3, "name": "Wood_Petrified_Trunk_Full"},
    {"x": 1, "y": 9, "z": 3, "name": "Wood_Petrified_Trunk_Full"},
    {"x": 1, "y": 19, "z": 3, "name": "Plant_Leaves_Dead"},
    {"x": 1, "y": 20, "z": 3, "name": "Plant_Leaves_Petrified"},
    {"x": 1, "y": 21, "z": 3, "name": "Plant_Leaves_Petrified"},
    {"x": 1, "y": 22, "z": 3, "name": "Plant_Leaves_Petrified"},
    {"x": 1, "y": 23, "z": 3, "name": "Plant_Leaves_Dead"},
    {"x": 1, "y": 1, "z": 4, "name": "Soil_Dirt_Burnt"},
    {"x": 1, "y": 2, "z": 4, "name": "Soil_Dirt_Poisoned"},
    {"x": 1, "y": 3, "z": 4, "name": "Wood_Poisoned_Trunk_Full"},
    {"x": 1, "y": 4, "z": 4, "name": "Wood_Ash_Trunk_Full"},
    {"x": 1, "y": 5, "z": 4, "name": "Wood_Ash_Trunk_Full"},
    {"x": 1, "y": 6, "z": 4, "name": "Wood_Petrified_Trunk_Full"},
    {"x": 1, "y": 7, "z": 4, "name": "Wood_Ash_Trunk_Full"},
    {"x": 1, "y": 8, "z": 4, "name": "Wood_Ash_Trunk_Full"},
    {"x": 1, "y": 19, "z": 4, "name": "Wood_Petrified_Trunk_Full"},
    {"x": 1, "y": 21, "z": 4, "name": "Plant_Leaves_Poisoned"},
    {"x": 1, "y": 19, "z": 5, "name": "Wood_Ash_Trunk_Full"},
    {"x": 1, "y": 20, "z": 5, "name": "Plant_Leaves_Dead"},
    {"x": 1, "y": 21, "z": 5, "name": "Plant_Leaves_Petrified"},
    {"x": 1, "y": 19, "z": 6, "name": "Wood_Ash_Trunk_Full"},
    {"x": 1, "y": 20, "z": 6, "name": "Plant_Leaves_Petrified"},
    {"x": 1, "y": 21, "z": 6, "name": "Plant_Leaves_Dead"},
    {"x": 1, "y": 19, "z": 7, "name": "Wood_Poisoned_Trunk_Full"},
    {"x": 1, "y": 20, "z": 7, "name": "Plant_Leaves_Poisoned"},
    {"x": 1, "y": 18, "z": 8, "name": "Plant_Leaves_Dead"},
    {"x": 1, "y": 19, "z": 8, "name": "Plant_Leaves_Dead"},
    {"x": 1, "y": 18, "z": 9, "name": "Plant_Leaves_Petrified"},
    {"x": 1, "y": 19, "z": 9, "name": "Plant_Leaves_Poisoned"},
    {"x": 2, "y": 18, "z": -8, "name": "Plant_Leaves_Poisoned"},
    {"x": 2, "y": 19, "z": -8, "name": "Plant_Leaves_Poisoned"},
    {"x": 2, "y": 19, "z": -7, "name": "Plant_Leaves_Dead"},
    {"x": 2, "y": 20, "z": -7, "name": "Plant_Leaves_Petrified"},
    {"x": 2, "y": 18, "z": -6, "name": "Plant_Leaves_Petrified"},
    {"x": 2, "y": 19, "z": -6, "name": "Plant_Leaves_Dead"},
    {"x": 2, "y": 20, "z": -6, "name": "Plant_Leaves_Dead"},
    {"x": 2, "y": 21, "z": -6, "name": "Plant_Leaves_Petrified"},
    {"x": 2, "y": 18, "z": -5, "name": "Plant_Leaves_Dead"},
    {"x": 2, "y": 19, "z": -5, "name": "Plant_Leaves_Petrified"},
    {"x": 2, "y": 20, "z": -5, "name": "Plant_Leaves_Poisoned"},
    {"x": 2, "y": 21, "z": -5, "name": "Plant_Leaves_Poisoned"},
    {"x": 2, "y": 1, "z": -4, "name": "Soil_Dirt_Poisoned"},
    {"x": 2, "y": 2, "z": -4, "name": "Soil_Dirt_Burnt"},
    {"x": 2, "y": 3, "z": -4, "name": "Soil_Dirt_Poisoned"},
    {"x": 2, "y": 4, "z": -4, "name": "Soil_Dirt_Burnt"},
    {"x": 2, "y": 5, "z": -4, "name": "Soil_Dirt_Poisoned"},
    {"x": 2, "y": 6, "z": -4, "name": "Soil_Grass_Dry"},
    {"x": 2, "y": 19, "z": -4, "name": "Wood_Ash_Trunk_Full"},
    {"x": 2, "y": 20, "z": -4, "name": "Plant_Leaves_Dead"},
    {"x": 2, "y": 21, "z": -4, "name": "Plant_Leaves_Dead"},
    {"x": 2, "y": 22, "z": -4, "name": "Plant_Leaves_Poisoned"},
    {"x": 2, "y": 1, "z": -3, "name": "Soil_Dirt_Burnt"},
    {"x": 2, "y": 2, "z": -3, "name": "Soil_Dirt_Poisoned"},
    {"x": 2, "y": 3, "z": -3, "name": "Soil_Dirt_Burnt"},
    {"x": 2, "y": 4, "z": -3, "name": "Soil_Dirt_Poisoned"},
    {"x": 2, "y": 5, "z": -3, "name": "Soil_Dirt_Burnt"},
    {"x": 2, "y": 6, "z": -3, "name": "Wood_Ash_Trunk_Full"},
    {"x": 2, "y": 7, "z": -3, "name": "Wood_Petrified_Trunk_Full"},
    {"x": 2, "y": 8, "z": -3, "name": "Wood_Ash_Trunk_Full"},
    {"x": 2, "y": 19, "z": -3, "name": "Wood_Petrified_Trunk_Full"},
    {"x": 2, "y": 20, "z": -3, "name": "Plant_Leaves_Poisoned"},
    {"x": 2, "y": 22, "z": -3, "name": "Plant_Leaves_Petrified"},
    {"x": 2, "y": 1, "z": -2, "name": "Soil_Dirt_Poisoned"},
    {"x": 2, "y": 2, "z": -2, "name": "Soil_Dirt_Burnt"},
    {"x": 2, "y": 3, "z": -2, "name": "Soil_Dirt_Poisoned"},
    {"x": 2, "y": 4, "z": -2, "name": "Soil_Dirt_Burnt"},
    {"x": 2, "y": 5, "z": -2, "name": "Wood_Petrified_Trunk_Full"},
    {"x": 2, "y": 6, "z": -2, "name": "Wood_Ash_Trunk_Full"},
    {"x": 2, "y": 7, "z": -2, "name": "Wood_Petrified_Trunk_Full"},
    {"x": 2, "y": 8, "z": -2, "name": "Wood_Poisoned_Trunk_Full"},
    {"x": 2, "y": 9, "z": -2, "name": "Wood_Ash_Trunk_Full"},
    {"x": 2, "y": 10, "z": -2, "name": "Wood_Petrified_Trunk_Full"},
    {"x": 2, "y": 21, "z": -2, "name": "Plant_Leaves_Poisoned"},
    {"x": 2, "y": 22, "z": -2, "name": "Plant_Leaves_Petrified"},
    {"x": 2, "y": 23, "z": -2, "name": "Plant_Leaves_Poisoned"},
    {"x": 2, "y": 1, "z": -1, "name": "Soil_Dirt_Burnt"},
    {"x": 2, "y": 2, "z": -1, "name": "Soil_Dirt_Poisoned"},
    {"x": 2, "y": 3, "z": -1, "name": "Soil_Dirt_Burnt"},
    {"x": 2, "y": 4, "z": -1, "name": "Soil_Dirt_Poisoned"},
    {"x": 2, "y": 5, "z": -1, "name": "Soil_Dirt_Burnt"},
    {"x": 2, "y": 6, "z": -1, "name": "Soil_Leaves"},
    {"x": 2, "y": 7, "z": -1, "name": "Soil_Clay_Brick_Half", "rotation": 4},
    {"x": 2, "y": 8, "z": -1, "name": "Soil_Clay_Brick_Half", "rotation": 4},
    {"x": 2, "y": 9, "z": -1, "name": "Wood_Petrified_Trunk_Full"},
    {"x": 2, "y": 10, "z": -1, "name": "Wood_Ash_Trunk_Full"},
    {"x": 2, "y": 11, "z": -1, "name": "Wood_Ash_Trunk_Full"},
    {"x": 2, "y": 19, "z": -1, "name": "Plant_Leaves_Poisoned"},
    {"x": 2, "y": 20, "z": -1, "name": "Plant_Leaves_Dead"},
    {"x": 2, "y": 21, "z": -1, "name": "Plant_Leaves_Dead"},
    {"x": 2, "y": 22, "z": -1, "name": "Plant_Leaves_Dead"},
    {"x": 2, "y": 23, "z": -1, "name": "Plant_Leaves_Dead"},
    {"x": 2, "y": 24, "z": -1, "name": "Plant_Leaves_Petrified"},
    {"x": 2, "y": 1, "z": 0, "name": "Soil_Dirt_Poisoned"},
    {"x": 2, "y": 2, "z": 0, "name": "Soil_Dirt_Burnt"},
    {"x": 2, "y": 3, "z": 0, "name": "Soil_Dirt_Poisoned"},
    {"x": 2, "y": 4, "z": 0, "name": "Soil_Dirt_Burnt"},
    {"x": 2, "y": 5, "z": 0, "name": "Soil_Dirt_Poisoned"},
    {"x": 2, "y": 6, "z": 0, "name": "Soil_Leaves"},
    {"x": 2, "y": 9, "z": 0, "name": "Wood_Petrified_Trunk_Full"},
    {"x": 2, "y": 10, "z": 0, "name": "Wood_Poisoned_Trunk_Full"},
    {"x": 2, "y": 11, "z": 0, "name": "Wood_Poisoned_Trunk_Full"},
    {"x": 2, "y": 19, "z": 0, "name": "Plant_Leaves_Dead"},
    {"x": 2, "y": 20, "z": 0, "name": "Wood_Poisoned_Trunk_Full"},
    {"x": 2, "y": 21, "z": 0, "name": "Plant_Leaves_Poisoned"},
    {"x": 2, "y": 22, "z": 0, "name": "Plant_Leaves_Poisoned"},
    {"x": 2, "y": 23, "z": 0, "name": "Plant_Leaves_Poisoned"},
    {"x": 2, "y": 24, "z": 0, "name": "Plant_Leaves_Petrified"},
    {"x": 2, "y": 1, "z": 1, "name": "Soil_Dirt_Burnt"},
    {"x": 2, "y": 2, "z": 1, "name": "Soil_Dirt_Poisoned"},
    {"x": 2, "y": 3, "z": 1, "name": "Soil_Dirt_Burnt"},
    {"x": 2, "y": 4, "z": 1, "name": "Soil_Dirt_Poisoned"},
    {"x": 2, "y": 5, "z": 1, "name": "Soil_Dirt_Burnt"},
    {"x": 2, "y": 6, "z": 1, "name": "Soil_Leaves"},
    {"x": 2, "y": 7, "z": 1, "name": "Soil_Clay_Brick_Half", "rotation": 6},
    {"x": 2, "y": 8, "z": 1, "name": "Soil_Clay_Brick_Half", "rotation": 6},
    {"x": 2, "y": 9, "z": 1, "name": "Wood_Poisoned_Trunk_Full"},
    {"x": 2, "y": 10, "z": 1, "name": "Wood_Petrified_Trunk_Full"},
    {"x": 2, "y": 16, "z": 1, "name": "Wood_Poisoned_Trunk_Full"},
    {"x": 2, "y": 20, "z": 1, "name": "Wood_Petrified_Trunk_Full"},
    {"x": 2, "y": 21, "z": 1, "name": "Plant_Leaves_Dead"},
    {"x": 2, "y": 22, "z": 1, "name": "Plant_Leaves_Petrified"},
    {"x": 2, "y": 23, "z": 1, "name": "Plant_Leaves_Dead"},
    {"x": 2, "y": 1, "z": 2, "name": "Soil_Dirt_Poisoned"},
    {"x": 2, "y": 2, "z": 2, "name": "Soil_Dirt_Burnt"},
    {"x": 2, "y": 3, "z": 2, "name": "Soil_Dirt_Poisoned"},
    {"x": 2, "y": 4, "z": 2, "name": "Soil_Dirt_Burnt"},
    {"x": 2, "y": 5, "z": 2, "name": "Soil_Dirt_Poisoned"},
    {"x": 2, "y": 6, "z": 2, "name": "Soil_Pathway"},
    {"x": 2, "y": 7, "z": 2, "name": "Wood_Petrified_Trunk_Full"},
    {"x": 2, "y": 8, "z": 2, "name": "Wood_Poisoned_Trunk_Full"},
    {"x": 2, "y": 9, "z": 2, "name": "Wood_Ash_Trunk_Full"},
    {"x": 2, "y": 10, "z": 2, "name": "Wood_Petrified_Trunk_Full"},
    {"x": 2, "y": 16, "z": 2, "name": "Plant_Leaves_Petrified"},
    {"x": 2, "y": 17, "z": 2, "name": "Plant_Leaves_Poisoned"},
    {"x": 2, "y": 21, "z": 2, "name": "Plant_Leaves_Petrified"},
    {"x": 2, "y": 22, "z": 2, "name": "Plant_Leaves_Petrified"},
    {"x": 2, "y": 23, "z": 2, "name": "Plant_Leaves_Dead"},
    {"x": 2, "y": 1, "z": 3, "name": "Wood_Ash_Trunk_Full"},
    {"x": 2, "y": 2, "z": 3, "name": "Wood_Poisoned_Trunk_Full"},
    {"x": 2, "y": 3, "z": 3, "name": "Wood_Poisoned_Trunk_Full"},
    {"x": 2, "y": 4, "z": 3, "name": "Soil_Dirt_Poisoned"},
    {"x": 2, "y": 5, "z": 3, "name": "Wood_Ash_Trunk_Full"},
    {"x": 2, "y": 6, "z": 3, "name": "Wood_Petrified_Trunk_Full"},
    {"x": 2, "y": 7, "z": 3, "name": "Wood_Poisoned_Trunk_Full"},
    {"x": 2, "y": 8, "z": 3, "name": "Wood_Petrified_Trunk_Full"},
    {"x": 2, "y": 9, "z": 3, "name": "Wood_Petrified_Trunk_Full"},
    {"x": 2, "y": 16, "z": 3, "name": "Plant_Leaves_Dead"},
    {"x": 2, "y": 17, "z": 3, "name": "Plant_Leaves_Dead"},
    {"x": 2, "y": 19, "z": 3, "name": "Plant_Leaves_Poisoned"},
    {"x": 2, "y": 20, "z": 3, "name": "Plant_Leaves_Poisoned"},
    {"x": 2, "y": 22, "z": 3, "name": "Plant_Leaves_Dead"},
    {"x": 2, "y": 1, "z": 4, "name": "Soil_Dirt_Poisoned"},
    {"x": 2, "y": 2, "z": 4, "name": "Soil_Dirt_Burnt"},
    {"x": 2, "y": 3, "z": 4, "name": "Wood_Petrified_Trunk_Full"},
    {"x": 2, "y": 4, "z": 4, "name": "Wood_Petrified_Trunk_Full"},
    {"x": 2, "y": 5, "z": 4, "name": "Wood_Petrified_Trunk_Full"},
    {"x": 2, "y": 6, "z": 4, "name": "Wood_Petrified_Trunk_Full"},
    {"x": 2, "y": 7, "z": 4, "name": "Wood_Poisoned_Trunk_Full"},
    {"x": 2, "y": 8, "z": 4, "name": "Wood_Ash_Trunk_Full"},
    {"x": 2, "y": 15, "z": 4, "name": "Plant_Leaves_Dead"},
    {"x": 2, "y": 16, "z": 4, "name": "Plant_Leaves_Poisoned"},
    {"x": 2, "y": 20, "z": 4, "name": "Plant_Leaves_Dead"},
    {"x": 2, "y": 21, "z": 4, "name": "Plant_Leaves_Dead"},
    {"x": 2, "y": 22, "z": 4, "name": "Plant_Leaves_Dead"},
    {"x": 2, "y": 1, "z": 5, "name": "Wood_Ash_Trunk_Full"},
    {"x": 2, "y": 2, "z": 5, "name": "Wood_Poisoned_Trunk_Full"},
    {"x": 2, "y": 3, "z": 5, "name": "Wood_Poisoned_Trunk_Full"},
    {"x": 2, "y": 4, "z": 5, "name": "Wood_Ash_Trunk_Full"},
    {"x": 2, "y": 5, "z": 5, "name": "Wood_Poisoned_Trunk_Full"},
    {"x": 2, "y": 6, "z": 5, "name": "Wood_Ash_Trunk_Full"},
    {"x": 2, "y": 18, "z": 5, "name": "Plant_Leaves_Petrified"},
    {"x": 2, "y": 19, "z": 5, "name": "Wood_Poisoned_Trunk_Full"},
    {"x": 2, "y": 20, "z": 5, "name": "Wood_Poisoned_Trunk_Full"},
    {"x": 2, "y": 21, "z": 5, "name": "Plant_Leaves_Petrified"},
    {"x": 2, "y": 18, "z": 6, "name": "Plant_Leaves_Petrified"},
    {"x": 2, "y": 19, "z": 6, "name": "Plant_Leaves_Poisoned"},
    {"x": 2, "y": 20, "z": 6, "name": "Plant_Leaves_Petrified"},
    {"x": 2, "y": 21, "z": 6, "name": "Plant_Leaves_Poisoned"},
    {"x": 2, "y": 17, "z": 7, "name": "Plant_Leaves_Poisoned"},
    {"x": 2, "y": 18, "z": 7, "name": "Plant_Leaves_Dead"},
    {"x": 2, "y": 20, "z": 7, "name": "Plant_Leaves_Dead"},
    {"x": 2, "y": 18, "z": 8, "name": "Plant_Leaves_Poisoned"},
    {"x": 2, "y": 19, "z": 8, "name": "Plant_Leaves_Poisoned"},
    {"x": 2, "y": 20, "z": 8, "name": "Plant_Leaves_Petrified"},
    {"x": 2, "y": 18, "z": 9, "name": "Plant_Leaves_Petrified"},
    {"x": 2, "y": 19, "z": 9, "name": "Plant_Leaves_Dead"},
    {"x": 3, "y": 18, "z": -8, "name": "Plant_Leaves_Petrified"},
    {"x": 3, "y": 19, "z": -8, "name": "Plant_Leaves_Dead"},
    {"x": 3, "y": 19, "z": -7, "name": "Plant_Leaves_Poisoned"},
    {"x": 3, "y": 20, "z": -7, "name": "Plant_Leaves_Poisoned"},
    {"x": 3, "y": 18, "z": -6, "name": "Plant_Leaves_Dead"},
    {"x": 3, "y": 19, "z": -6, "name": "Plant_Leaves_Petrified"},
    {"x": 3, "y": 20, "z": -6, "name": "Plant_Leaves_Poisoned"},
    {"x": 3, "y": 21, "z": -6, "name": "Plant_Leaves_Dead"},
    {"x": 3, "y": 18, "z": -5, "name": "Plant_Leaves_Petrified"},
    {"x": 3, "y": 19, "z": -5, "name": "Plant_Leaves_Dead"},
    {"x": 3, "y": 20, "z": -5, "name": "Wood_Ash_Trunk_Full"},
    {"x": 3, "y": 21, "z": -5, "name": "Plant_Leaves_Poisoned"},
    {"x": 3, "y": 1, "z": -4, "name": "Soil_Dirt_Burnt"},
    {"x": 3, "y": 2, "z": -4, "name": "Soil_Dirt_Poisoned"},
    {"x": 3, "y": 3, "z": -4, "name": "Soil_Dirt_Burnt"},
    {"x": 3, "y": 4, "z": -4, "name": "Soil_Dirt_Poisoned"},
    {"x": 3, "y": 5, "z": -4, "name": "Soil_Dirt_Burnt"},
    {"x": 3, "y": 6, "z": -4, "name": "Soil_Grass_Burnt"},
    {"x": 3, "y": 19, "z": -4, "name": "Wood_Petrified_Trunk_Full"},
    {"x": 3, "y": 20, "z": -4, "name": "Wood_Poisoned_Trunk_Full"},
    {"x": 3, "y": 21, "z": -4, "name": "Plant_Leaves_Dead"},
    {"x": 3, "y": 22, "z": -4, "name": "Plant_Leaves_Petrified"},
    {"x": 3, "y": 1, "z": -3, "name": "Soil_Dirt_Poisoned"},
    {"x": 3, "y": 2, "z": -3, "name": "Soil_Dirt_Burnt"},
    {"x": 3, "y": 3, "z": -3, "name": "Soil_Dirt_Poisoned"},
    {"x": 3, "y": 4, "z": -3, "name": "Soil_Dirt_Burnt"},
    {"x": 3, "y": 5, "z": -3, "name": "Soil_Dirt_Poisoned"},
    {"x": 3, "y": 6, "z": -3, "name": "Soil_Grass_Dry"},
    {"x": 3, "y": 20, "z": -3, "name": "Plant_Leaves_Dead"},
    {"x": 3, "y": 21, "z": -3, "name": "Plant_Leaves_Poisoned"},
    {"x": 3, "y": 22, "z": -3, "name": "Plant_Leaves_Poisoned"},
    {"x": 3, "y": 1, "z": -2, "name": "Soil_Dirt_Burnt"},
    {"x": 3, "y": 2, "z": -2, "name": "Soil_Dirt_Poisoned"},
    {"x": 3, "y": 3, "z": -2, "name": "Soil_Dirt_Burnt"},
    {"x": 3, "y": 4, "z": -2, "name": "Soil_Dirt_Poisoned"},
    {"x": 3, "y": 5, "z": -2, "name": "Soil_Dirt_Burnt"},
    {"x": 3, "y": 6, "z": -2, "name": "Soil_Grass_Burnt"},
    {"x": 3, "y": 18, "z": -2, "name": "Plant_Leaves_Petrified"},
    {"x": 3, "y": 19, "z": -2, "name": "Plant_Leaves_Poisoned"},
    {"x": 3, "y": 20, "z": -2, "name": "Plant_Leaves_Dead"},
    {"x": 3, "y": 21, "z": -2, "name": "Plant_Leaves_Poisoned"},
    {"x": 3, "y": 22, "z": -2, "name": "Plant_Leaves_Dead"},
    {"x": 3, "y": 1, "z": -1, "name": "Soil_Dirt_Poisoned"},
    {"x": 3, "y": 2, "z": -1, "name": "Soil_Dirt_Burnt"},
    {"x": 3, "y": 3, "z": -1, "name": "Soil_Dirt_Poisoned"},
    {"x": 3, "y": 4, "z": -1, "name": "Soil_Dirt_Burnt"},
    {"x": 3, "y": 5, "z": -1, "name": "Soil_Dirt_Poisoned"},
    {"x": 3, "y": 6, "z": -1, "name": "Soil_Leaves"},
    {"x": 3, "y": 7, "z": -1, "name": "Plant_Grass_Lush"},
    {"x": 3, "y": 20, "z": -1, "name": "Plant_Leaves_Petrified"},
    {"x": 3, "y": 21, "z": -1, "name": "Plant_Leaves_Petrified"},
    {"x": 3, "y": 22, "z": -1, "name": "Plant_Leaves_Petrified"},
    {"x": 3, "y": 23, "z": -1, "name": "Plant_Leaves_Petrified"},
    {"x": 3, "y": 1, "z": 0, "name": "Soil_Dirt_Burnt"},
    {"x": 3, "y": 2, "z": 0, "name": "Soil_Dirt_Poisoned"},
    {"x": 3, "y": 3, "z": 0, "name": "Soil_Dirt_Burnt"},
    {"x": 3, "y": 4, "z": 0, "name": "Soil_Dirt_Poisoned"},
    {"x": 3, "y": 5, "z": 0, "name": "Soil_Dirt_Burnt"},
    {"x": 3, "y": 6, "z": 0, "name": "Soil_Leaves"},
    {"x": 3, "y": 16, "z": 0, "name": "Plant_Leaves_Petrified"},
    {"x": 3, "y": 17, "z": 0, "name": "Plant_Leaves_Petrified"},
    {"x": 3, "y": 19, "z": 0, "name": "Plant_Leaves_Petrified"},
    {"x": 3, "y": 20, "z": 0, "name": "Plant_Leaves_Petrified"},
    {"x": 3, "y": 21, "z": 0, "name": "Plant_Leaves_Petrified"},
    {"x": 3, "y": 22, "z": 0, "name": "Plant_Leaves_Petrified"},
    {"x": 3, "y": 1, "z": 1, "name": "Soil_Dirt_Poisoned"},
    {"x": 3, "y": 2, "z": 1, "name": "Soil_Dirt_Burnt"},
    {"x": 3, "y": 3, "z": 1, "name": "Soil_Dirt_Poisoned"},
    {"x": 3, "y": 4, "z": 1, "name": "Soil_Dirt_Burnt"},
    {"x": 3, "y": 5, "z": 1, "name": "Soil_Dirt_Poisoned"},
    {"x": 3, "y": 6, "z": 1, "name": "Soil_Leaves"},
    {"x": 3, "y": 16, "z": 1, "name": "Wood_Poisoned_Trunk_Full"},
    {"x": 3, "y": 17, "z": 1, "name": "Plant_Leaves_Dead"},
    {"x": 3, "y": 19, "z": 1, "name": "Plant_Leaves_Dead"},
    {"x": 3, "y": 20, "z": 1, "name": "Wood_Poisoned_Trunk_Full"},
    {"x": 3, "y": 21, "z": 1, "name": "Plant_Leaves_Dead"},
    {"x": 3, "y": 22, "z": 1, "name": "Plant_Leaves_Poisoned"},
    {"x": 3, "y": 1, "z": 2, "name": "Wood_Poisoned_Trunk_Full"},
    {"x": 3, "y": 2, "z": 2, "name": "Soil_Dirt_Poisoned"},
    {"x": 3, "y": 3, "z": 2, "name": "Soil_Dirt_Burnt"},
    {"x": 3, "y": 4, "z": 2, "name": "Soil_Dirt_Poisoned"},
    {"x": 3, "y": 5, "z": 2, "name": "Soil_Dirt_Burnt"},
    {"x": 3, "y": 6, "z": 2, "name": "Soil_Pathway"},
    {"x": 3, "y": 7, "z": 2, "name": "Wood_Petrified_Trunk_Full"},
    {"x": 3, "y": 8, "z": 2, "name": "Wood_Poisoned_Trunk_Full"},
    {"x": 3, "y": 16, "z": 2, "name": "Wood_Poisoned_Trunk_Full"},
    {"x": 3, "y": 17, "z": 2, "name": "Plant_Leaves_Dead"},
    {"x": 3, "y": 18, "z": 2, "name": "Plant_Leaves_Poisoned"},
    {"x": 3, "y": 20, "z": 2, "name": "Plant_Leaves_Poisoned"},
    {"x": 3, "y": 21, "z": 2, "name": "Plant_Leaves_Dead"},
    {"x": 3, "y": 22, "z": 2, "name": "Plant_Leaves_Dead"},
    {"x": 3, "y": 23, "z": 2, "name": "Plant_Leaves_Poisoned"},
    {"x": 3, "y": 1, "z": 3, "name": "Wood_Petrified_Trunk_Full"},
    {"x": 3, "y": 2, "z": 3, "name": "Soil_Dirt_Burnt"},
    {"x": 3, "y": 3, "z": 3, "name": "Soil_Dirt_Poisoned"},
    {"x": 3, "y": 4, "z": 3, "name": "Soil_Dirt_Burnt"},
    {"x": 3, "y": 5, "z": 3, "name": "Soil_Dirt_Poisoned"},
    {"x": 3, "y": 6, "z": 3, "name": "Wood_Ash_Trunk_Full"},
    {"x": 3, "y": 7, "z": 3, "name": "Wood_Ash_Trunk_Full"},
    {"x": 3, "y": 8, "z": 3, "name": "Wood_Ash_Trunk_Full"},
    {"x": 3, "y": 16, "z": 3, "name": "Plant_Leaves_Dead"},
    {"x": 3, "y": 17, "z": 3, "name": "Plant_Leaves_Poisoned"},
    {"x": 3, "y": 20, "z": 3, "name": "Plant_Leaves_Dead"},
    {"x": 3, "y": 22, "z": 3, "name": "Plant_Leaves_Petrified"},
    {"x": 3, "y": 3, "z": 4, "name": "Wood_Petrified_Trunk_Full"},
    {"x": 3, "y": 4, "z": 4, "name": "Wood_Poisoned_Trunk_Full"},
    {"x": 3, "y": 5, "z": 4, "name": "Wood_Ash_Trunk_Full"},
    {"x": 3, "y": 6, "z": 4, "name": "Wood_Poisoned_Trunk_Full"},
    {"x": 3, "y": 7, "z": 4, "name": "Wood_Poisoned_Trunk_Full"},
    {"x": 3, "y": 15, "z": 4, "name": "Plant_Leaves_Petrified"},
    {"x": 3, "y": 16, "z": 4, "name": "Plant_Leaves_Dead"},
    {"x": 3, "y": 17, "z": 4, "name": "Plant_Leaves_Poisoned"},
    {"x": 3, "y": 19, "z": 4, "name": "Plant_Leaves_Poisoned"},
    {"x": 3, "y": 20, "z": 4, "name": "Plant_Leaves_Poisoned"},
    {"x": 3, "y": 21, "z": 4, "name": "Plant_Leaves_Dead"},
    {"x": 3, "y": 22, "z": 4, "name": "Plant_Leaves_Dead"},
    {"x": 3, "y": 2, "z": 5, "name": "Wood_Poisoned_Trunk_Full"},
    {"x": 3, "y": 3, "z": 5, "name": "Wood_Ash_Trunk_Full"},
    {"x": 3, "y": 16, "z": 5, "name": "Plant_Leaves_Petrified"},
    {"x": 3, "y": 18, "z": 5, "name": "Plant_Leaves_Poisoned"},
    {"x": 3, "y": 19, "z": 5, "name": "Plant_Leaves_Petrified"},
    {"x": 3, "y": 20, "z": 5, "name": "Wood_Ash_Trunk_Full"},
    {"x": 3, "y": 21, "z": 5, "name": "Plant_Leaves_Poisoned"},
    {"x": 3, "y": 22, "z": 5, "name": "Plant_Leaves_Petrified"},
    {"x": 3, "y": 17, "z": 6, "name": "Plant_Leaves_Petrified"},
    {"x": 3, "y": 18, "z": 6, "name": "Plant_Leaves_Dead"},
    {"x": 3, "y": 19, "z": 6, "name": "Plant_Leaves_Dead"},
    {"x": 3, "y": 20, "z": 6, "name": "Plant_Leaves_Dead"},
    {"x": 3, "y": 21, "z": 6, "name": "Plant_Leaves_Poisoned"},
    {"x": 3, "y": 17, "z": 7, "name": "Plant_Leaves_Dead"},
    {"x": 3, "y": 18, "z": 7, "name": "Plant_Leaves_Petrified"},
    {"x": 3, "y": 19, "z": 7, "name": "Plant_Leaves_Poisoned"},
    {"x": 3, "y": 20, "z": 7, "name": "Plant_Leaves_Petrified"},
    {"x": 3, "y": 18, "z": 8, "name": "Plant_Leaves_Poisoned"},
    {"x": 3, "y": 19, "z": 8, "name": "Plant_Leaves_Dead"},
    {"x": 3, "y": 18, "z": 9, "name": "Plant_Leaves_Dead"},
    {"x": 4, "y": 19, "z": -7, "name": "Plant_Leaves_Dead"},
    {"x": 4, "y": 18, "z": -6, "name": "Plant_Leaves_Dead"},
    {"x": 4, "y": 20, "z": -6, "name": "Plant_Leaves_Petrified"},
    {"x": 4, "y": 19, "z": -5, "name": "Plant_Leaves_Poisoned"},
    {"x": 4, "y": 20, "z": -5, "name": "Plant_Leaves_Dead"},
    {"x": 4, "y": 21, "z": -5, "name": "Plant_Leaves_Petrified"},
    {"x": 4, "y": 19, "z": -4, "name": "Plant_Leaves_Dead"},
    {"x": 4, "y": 20, "z": -4, "name": "Plant_Leaves_Petrified"},
    {"x": 4, "y": 21, "z": -4, "name": "Plant_Leaves_Dead"},
    {"x": 4, "y": 1, "z": -3, "name": "Soil_Dirt_Burnt"},
    {"x": 4, "y": 2, "z": -3, "name": "Soil_Dirt_Poisoned"},
    {"x": 4, "y": 3, "z": -3, "name": "Soil_Dirt_Burnt"},
    {"x": 4, "y": 4, "z": -3, "name": "Soil_Dirt_Poisoned"},
    {"x": 4, "y": 5, "z": -3, "name": "Soil_Dirt_Burnt"},
    {"x": 4, "y": 6, "z": -3, "name": "Soil_Grass_Burnt"},
    {"x": 4, "y": 19, "z": -3, "name": "Plant_Leaves_Petrified"},
    {"x": 4, "y": 20, "z": -3, "name": "Plant_Leaves_Dead"},
    {"x": 4, "y": 21, "z": -3, "name": "Plant_Leaves_Petrified"},
    {"x": 4, "y": 22, "z": -3, "name": "Plant_Leaves_Petrified"},
    {"x": 4, "y": 1, "z": -2, "name": "Soil_Dirt_Poisoned"},
    {"x": 4, "y": 2, "z": -2, "name": "Soil_Dirt_Burnt"},
    {"x": 4, "y": 3, "z": -2, "name": "Soil_Dirt_Poisoned"},
    {"x": 4, "y": 4, "z": -2, "name": "Soil_Dirt_Burnt"},
    {"x": 4, "y": 5, "z": -2, "name": "Soil_Dirt_Poisoned"},
    {"x": 4, "y": 6, "z": -2, "name": "Soil_Grass_Dry"},
    {"x": 4, "y": 18, "z": -2, "name": "Plant_Leaves_Petrified"},
    {"x": 4, "y": 19, "z": -2, "name": "Plant_Leaves_Poisoned"},
    {"x": 4, "y": 20, "z": -2, "name": "Plant_Leaves_Dead"},
    {"x": 4, "y": 1, "z": -1, "name": "Soil_Dirt_Burnt"},
    {"x": 4, "y": 2, "z": -1, "name": "Soil_Dirt_Poisoned"},
    {"x": 4, "y": 3, "z": -1, "name": "Soil_Dirt_Burnt"},
    {"x": 4, "y": 4, "z": -1, "name": "Soil_Dirt_Poisoned"},
    {"x": 4, "y": 5, "z": -1, "name": "Soil_Dirt_Burnt"},
    {"x": 4, "y": 6, "z": -1, "name": "Soil_Grass_Burnt"},
    {"x": 4, "y": 20, "z": -1, "name": "Plant_Leaves_Poisoned"},
    {"x": 4, "y": 1, "z": 0, "name": "Soil_Dirt_Poisoned"},
    {"x": 4, "y": 2, "z": 0, "name": "Soil_Dirt_Burnt"},
    {"x": 4, "y": 3, "z": 0, "name": "Soil_Dirt_Poisoned"},
    {"x": 4, "y": 4, "z": 0, "name": "Soil_Dirt_Burnt"},
    {"x": 4, "y": 5, "z": 0, "name": "Soil_Dirt_Poisoned"},
    {"x": 4, "y": 6, "z": 0, "name": "Soil_Grass_Dry"},
    {"x": 4, "y": 16, "z": 0, "name": "Plant_Leaves_Poisoned"},
    {"x": 4, "y": 17, "z": 0, "name": "Plant_Leaves_Poisoned"},
    {"x": 4, "y": 20, "z": 0, "name": "Plant_Leaves_Dead"},
    {"x": 4, "y": 21, "z": 0, "name": "Plant_Leaves_Dead"},
    {"x": 4, "y": 22, "z": 0, "name": "Plant_Leaves_Dead"},
    {"x": 4, "y": 1, "z": 1, "name": "Soil_Dirt_Burnt"},
    {"x": 4, "y": 2, "z": 1, "name": "Soil_Dirt_Poisoned"},
    {"x": 4, "y": 3, "z": 1, "name": "Soil_Dirt_Burnt"},
    {"x": 4, "y": 4, "z": 1, "name": "Soil_Dirt_Poisoned"},
    {"x": 4, "y": 5, "z": 1, "name": "Soil_Dirt_Burnt"},
    {"x": 4, "y": 6, "z": 1, "name": "Soil_Leaves"},
    {"x": 4, "y": 17, "z": 1, "name": "Plant_Leaves_Dead"},
    {"x": 4, "y": 18, "z": 1, "name": "Plant_Leaves_Petrified"},
    {"x": 4, "y": 19, "z": 1, "name": "Plant_Leaves_Dead"},
    {"x": 4, "y": 20, "z": 1, "name": "Plant_Leaves_Poisoned"},
    {"x": 4, "y": 21, "z": 1, "name": "Plant_Leaves_Petrified"},
    {"x": 4, "y": 22, "z": 1, "name": "Plant_Leaves_Poisoned"},
    {"x": 4, "y": 1, "z": 2, "name": "Soil_Dirt_Poisoned"},
    {"x": 4, "y": 2, "z": 2, "name": "Soil_Dirt_Burnt"},
    {"x": 4, "y": 3, "z": 2, "name": "Soil_Dirt_Poisoned"},
    {"x": 4, "y": 4, "z": 2, "name": "Soil_Dirt_Burnt"},
    {"x": 4, "y": 5, "z": 2, "name": "Soil_Dirt_Poisoned"},
    {"x": 4, "y": 6, "z": 2, "name": "Soil_Leaves"},
    {"x": 4, "y": 16, "z": 2, "name": "Wood_Petrified_Trunk_Full"},
    {"x": 4, "y": 17, "z": 2, "name": "Plant_Leaves_Dead"},
    {"x": 4, "y": 18, "z": 2, "name": "Plant_Leaves_Dead"},
    {"x": 4, "y": 20, "z": 2, "name": "Plant_Leaves_Poisoned"},
    {"x": 4, "y": 21, "z": 2, "name": "Plant_Leaves_Petrified"},
    {"x": 4, "y": 2, "z": 3, "name": "Soil_Dirt_Poisoned"},
    {"x": 4, "y": 3, "z": 3, "name": "Soil_Dirt_Burnt"},
    {"x": 4, "y": 4, "z": 3, "name": "Soil_Dirt_Poisoned"},
    {"x": 4, "y": 5, "z": 3, "name": "Soil_Dirt_Burnt"},
    {"x": 4, "y": 15, "z": 3, "name": "Plant_Leaves_Dead"},
    {"x": 4, "y": 16, "z": 3, "name": "Plant_Leaves_Dead"},
    {"x": 4, "y": 17, "z": 3, "name": "Plant_Leaves_Petrified"},
    {"x": 4, "y": 18, "z": 3, "name": "Plant_Leaves_Poisoned"},
    {"x": 4, "y": 20, "z": 3, "name": "Plant_Leaves_Petrified"},
    {"x": 4, "y": 16, "z": 4, "name": "Plant_Leaves_Dead"},
    {"x": 4, "y": 17, "z": 4, "name": "Plant_Leaves_Petrified"},
    {"x": 4, "y": 19, "z": 4, "name": "Plant_Leaves_Dead"},
    {"x": 4, "y": 20, "z": 4, "name": "Plant_Leaves_Poisoned"},
    {"x": 4, "y": 21, "z": 4, "name": "Plant_Leaves_Petrified"},
    {"x": 4, "y": 16, "z": 5, "name": "Plant_Leaves_Poisoned"},
    {"x": 4, "y": 20, "z": 5, "name": "Plant_Leaves_Petrified"},
    {"x": 4, "y": 21, "z": 5, "name": "Plant_Leaves_Poisoned"},
    {"x": 4, "y": 17, "z": 6, "name": "Plant_Leaves_Poisoned"},
    {"x": 4, "y": 19, "z": 6, "name": "Plant_Leaves_Poisoned"},
    {"x": 4, "y": 20, "z": 6, "name": "Plant_Leaves_Petrified"},
    {"x": 4, "y": 21, "z": 6, "name": "Plant_Leaves_Poisoned"},
    {"x": 5, "y": 18, "z": -6, "name": "Plant_Leaves_Petrified"},
    {"x": 5, "y": 19, "z": -6, "name": "Plant_Leaves_Petrified"},
    {"x": 5, "y": 20, "z": -6, "name": "Plant_Leaves_Dead"},
    {"x": 5, "y": 18, "z": -5, "name": "Plant_Leaves_Poisoned"},
    {"x": 5, "y": 19, "z": -5, "name": "Plant_Leaves_Dead"},
    {"x": 5, "y": 20, "z": -5, "name": "Plant_Leaves_Petrified"},
    {"x": 5, "y": 19, "z": -4, "name": "Plant_Leaves_Dead"},
    {"x": 5, "y": 20, "z": -4, "name": "Plant_Leaves_Dead"},
    {"x": 5, "y": 21, "z": -4, "name": "Plant_Leaves_Dead"},
    {"x": 5, "y": 1, "z": -3, "name": "Soil_Dirt_Poisoned"},
    {"x": 5, "y": 2, "z": -3, "name": "Soil_Dirt_Burnt"},
    {"x": 5, "y": 3, "z": -3, "name": "Soil_Dirt_Poisoned"},
    {"x": 5, "y": 4, "z": -3, "name": "Soil_Dirt_Burnt"},
    {"x": 5, "y": 5, "z": -3, "name": "Soil_Dirt_Poisoned"},
    {"x": 5, "y": 6, "z": -3, "name": "Soil_Grass_Dry"},
    {"x": 5, "y": 19, "z": -3, "name": "Plant_Leaves_Poisoned"},
    {"x": 5, "y": 20, "z": -3, "name": "Plant_Leaves_Petrified"},
    {"x": 5, "y": 21, "z": -3, "name": "Plant_Leaves_Poisoned"},
    {"x": 5, "y": 1, "z": -2, "name": "Soil_Dirt_Burnt"},
    {"x": 5, "y": 2, "z": -2, "name": "Soil_Dirt_Poisoned"},
    {"x": 5, "y": 3, "z": -2, "name": "Soil_Dirt_Burnt"},
    {"x": 5, "y": 4, "z": -2, "name": "Soil_Dirt_Poisoned"},
    {"x": 5, "y": 5, "z": -2, "name": "Soil_Dirt_Burnt"},
    {"x": 5, "y": 6, "z": -2, "name": "Soil_Grass_Burnt"},
    {"x": 5, "y": 19, "z": -2, "name": "Plant_Leaves_Poisoned"},
    {"x": 5, "y": 20, "z": -2, "name": "Plant_Leaves_Poisoned"},
    {"x": 5, "y": 1, "z": -1, "name": "Soil_Dirt_Poisoned"},
    {"x": 5, "y": 2, "z": -1, "name": "Soil_Dirt_Burnt"},
    {"x": 5, "y": 3, "z": -1, "name": "Soil_Dirt_Poisoned"},
    {"x": 5, "y": 4, "z": -1, "name": "Soil_Dirt_Burnt"},
    {"x": 5, "y": 5, "z": -1, "name": "Soil_Dirt_Poisoned"},
    {"x": 5, "y": 6, "z": -1, "name": "Soil_Grass_Dry"},
    {"x": 5, "y": 1, "z": 0, "name": "Soil_Dirt_Burnt"},
    {"x": 5, "y": 2, "z": 0, "name": "Soil_Dirt_Poisoned"},
    {"x": 5, "y": 3, "z": 0, "name": "Soil_Dirt_Burnt"},
    {"x": 5, "y": 4, "z": 0, "name": "Soil_Dirt_Poisoned"},
    {"x": 5, "y": 5, "z": 0, "name": "Soil_Dirt_Burnt"},
    {"x": 5, "y": 6, "z": 0, "name": "Soil_Grass_Burnt"},
    {"x": 5, "y": 16, "z": 0, "name": "Plant_Leaves_Petrified"},
    {"x": 5, "y": 17, "z": 0, "name": "Plant_Leaves_Petrified"},
    {"x": 5, "y": 20, "z": 0, "name": "Plant_Leaves_Poisoned"},
    {"x": 5, "y": 21, "z": 0, "name": "Plant_Leaves_Poisoned"},
    {"x": 5, "y": 1, "z": 1, "name": "Soil_Dirt_Poisoned"},
    {"x": 5, "y": 2, "z": 1, "name": "Soil_Dirt_Burnt"},
    {"x": 5, "y": 3, "z": 1, "name": "Soil_Dirt_Poisoned"},
    {"x": 5, "y": 4, "z": 1, "name": "Soil_Dirt_Burnt"},
    {"x": 5, "y": 5, "z": 1, "name": "Soil_Dirt_Poisoned"},
    {"x": 5, "y": 6, "z": 1, "name": "Soil_Leaves"},
    {"x": 5, "y": 16, "z": 1, "name": "Plant_Leaves_Poisoned"},
    {"x": 5, "y": 17, "z": 1, "name": "Plant_Leaves_Dead"},
    {"x": 5, "y": 20, "z": 1, "name": "Plant_Leaves_Dead"},
    {"x": 5, "y": 21, "z": 1, "name": "Plant_Leaves_Petrified"},
    {"x": 5, "y": 15, "z": 2, "name": "Plant_Leaves_Dead"},
    {"x": 5, "y": 16, "z": 2, "name": "Plant_Leaves_Dead"},
    {"x": 5, "y": 17, "z": 2, "name": "Plant_Leaves_Poisoned"},
    {"x": 5, "y": 18, "z": 2, "name": "Plant_Leaves_Poisoned"},
    {"x": 5, "y": 20, "z": 2, "name": "Plant_Leaves_Petrified"},
    {"x": 5, "y": 21, "z": 2, "name": "Plant_Leaves_Dead"},
    {"x": 5, "y": 15, "z": 3, "name": "Plant_Leaves_Poisoned"},
    {"x": 5, "y": 16, "z": 3, "name": "Plant_Leaves_Petrified"},
    {"x": 5, "y": 17, "z": 3, "name": "Plant_Leaves_Petrified"},
    {"x": 5, "y": 20, "z": 3, "name": "Plant_Leaves_Poisoned"},
    {"x": 5, "y": 15, "z": 4, "name": "Plant_Leaves_Dead"},
    {"x": 5, "y": 16, "z": 4, "name": "Plant_Leaves_Poisoned"},
    {"x": 5, "y": 17, "z": 4, "name": "Plant_Leaves_Poisoned"},
    {"x": 5, "y": 19, "z": 4, "name": "Plant_Leaves_Poisoned"},
    {"x": 5, "y": 20, "z": 4, "name": "Plant_Leaves_Petrified"},
    {"x": 5, "y": 21, "z": 4, "name": "Plant_Leaves_Petrified"},
    {"x": 5, "y": 16, "z": 5, "name": "Plant_Leaves_Dead"},
    {"x": 5, "y": 19, "z": 5, "name": "Plant_Leaves_Petrified"},
    {"x": 5, "y": 20, "z": 5, "name": "Plant_Leaves_Poisoned"},
    {"x": 5, "y": 21, "z": 5, "name": "Plant_Leaves_Dead"},
    {"x": 5, "y": 20, "z": 6, "name": "Plant_Leaves_Dead"},
    {"x": 6, "y": 18, "z": -6, "name": "Plant_Leaves_Poisoned"},
    {"x": 6, "y": 18, "z": -5, "name": "Plant_Leaves_Petrified"},
    {"x": 6, "y": 19, "z": -5, "name": "Plant_Leaves_Dead"},
    {"x": 6, "y": 18, "z": -4, "name": "Plant_Leaves_Petrified"},
    {"x": 6, "y": 19, "z": -4, "name": "Plant_Leaves_Dead"},
    {"x": 6, "y": 20, "z": -4, "name": "Plant_Leaves_Petrified"},
    {"x": 6, "y": 19, "z": -3, "name": "Plant_Leaves_Petrified"},
    {"x": 6, "y": 20, "z": -3, "name": "Plant_Leaves_Dead"},
    {"x": 6, "y": 16, "z": 1, "name": "Plant_Leaves_Poisoned"},
    {"x": 6, "y": 15, "z": 2, "name": "Plant_Leaves_Dead"},
    {"x": 6, "y": 16, "z": 2, "name": "Plant_Leaves_Petrified"},
    {"x": 6, "y": 17, "z": 2, "name": "Plant_Leaves_Poisoned"},
    {"x": 6, "y": 15, "z": 3, "name": "Plant_Leaves_Petrified"},
    {"x": 6, "y": 16, "z": 3, "name": "Plant_Leaves_Dead"},
    {"x": 6, "y": 17, "z": 3, "name": "Plant_Leaves_Dead"},
    {"x": 6, "y": 15, "z": 4, "name": "Plant_Leaves_Dead"},
    {"x": 6, "y": 16, "z": 4, "name": "Plant_Leaves_Petrified"},
    {"x": 6, "y": 20, "z": 4, "name": "Plant_Leaves_Dead"},
    {"x": 6, "y": 20, "z": 5, "name": "Plant_Leaves_Petrified"},
    {"x": 7, "y": 16, "z": 2, "name": "Plant_Leaves_Poisoned"},
    {"x": 7, "y": 15, "z": 3, "name": "Plant_Leaves_Poisoned"},
    {"x": 7, "y": 16, "z": 3, "name": "Plant_Leaves_Dead"},
    {"x": 7, "y": 16, "z": 4, "name": "Plant_Leaves_Poisoned"}
  ],
  "entities": []
}
