{
 "version": 8,
 "blockIdVersion": 11,
 "anchorX": 0,
 "anchorY": 36,
 "anchorZ": 0,
 "entities": [
  {
   "Components": {
    "Transform": { "Position": { "X": 0.5, "Y": 36.0, "Z": 0.5 }, "Rotation": { "Pitch": 0.0, "Yaw": 0.0, "Roll": 0.0 } },
    "HiddenFromAdventurePlayer": {},
    "Model": { "Model": { "Id": "NPC_Path_Marker", "Scale": 1.0, "Static": false } },
    "PersistentDisplayName": { "DisplayName": { "RawText": "kn_shrine_marker" } },
    "Nameplate": { "Text": "kn_shrine_marker" }
   }
  }
 ],
 "blocks": [
  {
   "x": -7,
   "y": 33,
   "z": 0,
   "name": "Rock_Stone_Brick_Smooth"
  },
  {
   "x": -7,
   "y": 34,
   "z": 0,
   "name": "Rock_Stone_Brick_Smooth"
  },
  {
   "x": -7,
   "y": 35,
   "z": 0,
   "name": "Rock_Stone_Brick_Smooth"
  },
  {
   "x": -7,
   "y": 33,
   "z": 1,
   "name": "Rock_Stone_Brick_Smooth"
  },
  {
   "x": -7,
   "y": 34,
   "z": 1,
   "name": "Rock_Stone_Brick_Smooth"
  },
  {
   "x": -7,
   "y": 35,
   "z": 1,
   "name": "Rock_Stone_Brick_Smooth"
  },
  {
   "x": -7,
   "y": 31,
   "z": 2,
   "name": "Rock_Stone"
  },
  {
   "x": -7,
   "y": 32,
   "z": 2,
   "name": "Rock_Stone"
  },
  {
   "x": -7,
   "y": 33,
   "z": 2,
   "name": "Rock_Stone_Brick_Smooth"
  },
  {
   "x": -7,
   "y": 34,
   "z": 2,
   "name": "Rock_Stone_Brick_Smooth"
  },
  {
   "x": -7,
   "y": 35,
   "z": 2,
   "name": "Rock_Stone_Brick_Smooth"
  },
  {
   "x": -7,
   "y": 31,
   "z": 3,
   "name": "Rock_Stone"
  },
  {
   "x": -7,
   "y": 32,
   "z": 3,
   "name": "Rock_Stone"
  },
  {
   "x": -7,
   "y": 33,
   "z": 3,
   "name": "Rock_Stone_Brick_Smooth"
  },
  {
   "x": -7,
   "y": 34,
   "z": 3,
   "name": "Rock_Stone_Brick_Smooth"
  },
  {
   "x": -7,
   "y": 35,
   "z": 3,
   "name": "Rock_Stone_Brick_Smooth"
  },
  {
   "x": -7,
   "y": 31,
   "z": 4,
   "name": "Rock_Stone"
  },
  {
   "x": -7,
   "y": 32,
   "z": 4,
   "name": "Rock_Stone"
  },
  {
   "x": -7,
   "y": 33,
   "z": 4,
   "name": "Rock_Stone"
  },
  {
   "x": -7,
   "y": 34,
   "z": 4,
   "name": "Rock_Stone"
  },
  {
   "x": -7,
   "y": 32,
   "z": 5,
   "name": "Rock_Stone"
  },
  {
   "x": -7,
   "y": 33,
   "z": 5,
   "name": "Rock_Stone"
  },
  {
   "x": -6,
   "y": 0,
   "z": -9,
   "name": "Rock_Stone"
  },
  {
   "x": -6,
   "y": 1,
   "z": -9,
   "name": "Rock_Stone"
  },
  {
   "x": -6,
   "y": 2,
   "z": -9,
   "name": "Rock_Stone"
  },
  {
   "x": -6,
   "y": 3,
   "z": -9,
   "name": "Rock_Stone"
  },
  {
   "x": -6,
   "y": 4,
   "z": -9,
   "name": "Rock_Stone"
  },
  {
   "x": -6,
   "y": 5,
   "z": -9,
   "name": "Rock_Stone"
  },
  {
   "x": -6,
   "y": 6,
   "z": -9,
   "name": "Rock_Stone"
  },
  {
   "x": -6,
   "y": 7,
   "z": -9,
   "name": "Rock_Stone"
  },
  {
   "x": -6,
   "y": 8,
   "z": -9,
   "name": "Rock_Stone"
  },
  {
   "x": -6,
   "y": 9,
   "z": -9,
   "name": "Rock_Stone"
  },
  {
   "x": -6,
   "y": 10,
   "z": -9,
   "name": "Rock_Stone"
  },
  {
   "x": -6,
   "y": 11,
   "z": -9,
   "name": "Rock_Stone"
  },
  {
   "x": -6,
   "y": 12,
   "z": -9,
   "name": "Rock_Stone"
  },
  {
   "x": -6,
   "y": 13,
   "z": -9,
   "name": "Rock_Stone"
  },
  {
   "x": -6,
   "y": 0,
   "z": -8,
   "name": "Rock_Stone"
  },
  {
   "x": -6,
   "y": 1,
   "z": -8,
   "name": "Rock_Stone"
  },
  {
   "x": -6,
   "y": 2,
   "z": -8,
   "name": "Rock_Stone"
  },
  {
   "x": -6,
   "y": 3,
   "z": -8,
   "name": "Rock_Stone"
  },
  {
   "x": -6,
   "y": 4,
   "z": -8,
   "name": "Rock_Stone"
  },
  {
   "x": -6,
   "y": 5,
   "z": -8,
   "name": "Rock_Stone"
  },
  {
   "x": -6,
   "y": 6,
   "z": -8,
   "name": "Rock_Stone"
  },
  {
   "x": -6,
   "y": 7,
   "z": -8,
   "name": "Rock_Stone"
  },
  {
   "x": -6,
   "y": 8,
   "z": -8,
   "name": "Rock_Stone"
  },
  {
   "x": -6,
   "y": 9,
   "z": -8,
   "name": "Rock_Stone"
  },
  {
   "x": -6,
   "y": 10,
   "z": -8,
   "name": "Rock_Stone"
  },
  {
   "x": -6,
   "y": 11,
   "z": -8,
   "name": "Rock_Stone"
  },
  {
   "x": -6,
   "y": 12,
   "z": -8,
   "name": "Rock_Stone"
  },
  {
   "x": -6,
   "y": 13,
   "z": -8,
   "name": "Rock_Stone"
  },
  {
   "x": -6,
   "y": 0,
   "z": -7,
   "name": "Rock_Stone"
  },
  {
   "x": -6,
   "y": 1,
   "z": -7,
   "name": "Rock_Stone"
  },
  {
   "x": -6,
   "y": 2,
   "z": -7,
   "name": "Rock_Stone"
  },
  {
   "x": -6,
   "y": 3,
   "z": -7,
   "name": "Rock_Stone"
  },
  {
   "x": -6,
   "y": 4,
   "z": -7,
   "name": "Rock_Stone"
  },
  {
   "x": -6,
   "y": 5,
   "z": -7,
   "name": "Rock_Stone"
  },
  {
   "x": -6,
   "y": 6,
   "z": -7,
   "name": "Rock_Stone"
  },
  {
   "x": -6,
   "y": 7,
   "z": -7,
   "name": "Rock_Stone"
  },
  {
   "x": -6,
   "y": 8,
   "z": -7,
   "name": "Rock_Stone"
  },
  {
   "x": -6,
   "y": 9,
   "z": -7,
   "name": "Rock_Stone"
  },
  {
   "x": -6,
   "y": 10,
   "z": -7,
   "name": "Rock_Stone"
  },
  {
   "x": -6,
   "y": 11,
   "z": -7,
   "name": "Rock_Stone"
  },
  {
   "x": -6,
   "y": 12,
   "z": -7,
   "name": "Rock_Stone"
  },
  {
   "x": -6,
   "y": 13,
   "z": -7,
   "name": "Rock_Stone"
  },
  {
   "x": -6,
   "y": 21,
   "z": -7,
   "name": "Rock_Stone"
  },
  {
   "x": -6,
   "y": 22,
   "z": -7,
   "name": "Rock_Stone"
  },
  {
   "x": -6,
   "y": 23,
   "z": -7,
   "name": "Rock_Stone"
  },
  {
   "x": -6,
   "y": 24,
   "z": -7,
   "name": "Rock_Stone"
  },
  {
   "x": -6,
   "y": 25,
   "z": -7,
   "name": "Rock_Stone"
  },
  {
   "x": -6,
   "y": 26,
   "z": -7,
   "name": "Rock_Stone"
  },
  {
   "x": -6,
   "y": 27,
   "z": -7,
   "name": "Rock_Stone"
  },
  {
   "x": -6,
   "y": 28,
   "z": -7,
   "name": "Rock_Stone"
  },
  {
   "x": -6,
   "y": 29,
   "z": -7,
   "name": "Rock_Stone"
  },
  {
   "x": -6,
   "y": 30,
   "z": -7,
   "name": "Rock_Stone"
  },
  {
   "x": -6,
   "y": 31,
   "z": -7,
   "name": "Rock_Stone"
  },
  {
   "x": -6,
   "y": 32,
   "z": -7,
   "name": "Rock_Stone"
  },
  {
   "x": -6,
   "y": 33,
   "z": -7,
   "name": "Rock_Stone"
  },
  {
   "x": -6,
   "y": 34,
   "z": -7,
   "name": "Rock_Stone"
  },
  {
   "x": -6,
   "y": 35,
   "z": -7,
   "name": "Rock_Stone"
  },
  {
   "x": -6,
   "y": 36,
   "z": -7,
   "name": "Rock_Stone"
  },
  {
   "x": -6,
   "y": 0,
   "z": -6,
   "name": "Rock_Stone"
  },
  {
   "x": -6,
   "y": 1,
   "z": -6,
   "name": "Rock_Stone"
  },
  {
   "x": -6,
   "y": 2,
   "z": -6,
   "name": "Rock_Stone"
  },
  {
   "x": -6,
   "y": 3,
   "z": -6,
   "name": "Rock_Stone"
  },
  {
   "x": -6,
   "y": 4,
   "z": -6,
   "name": "Rock_Stone"
  },
  {
   "x": -6,
   "y": 5,
   "z": -6,
   "name": "Rock_Stone"
  },
  {
   "x": -6,
   "y": 6,
   "z": -6,
   "name": "Rock_Stone"
  },
  {
   "x": -6,
   "y": 7,
   "z": -6,
   "name": "Rock_Stone"
  },
  {
   "x": -6,
   "y": 8,
   "z": -6,
   "name": "Rock_Stone"
  },
  {
   "x": -6,
   "y": 9,
   "z": -6,
   "name": "Rock_Stone"
  },
  {
   "x": -6,
   "y": 10,
   "z": -6,
   "name": "Rock_Stone"
  },
  {
   "x": -6,
   "y": 11,
   "z": -6,
   "name": "Rock_Stone"
  },
  {
   "x": -6,
   "y": 12,
   "z": -6,
   "name": "Rock_Stone"
  },
  {
   "x": -6,
   "y": 13,
   "z": -6,
   "name": "Rock_Stone"
  },
  {
   "x": -6,
   "y": 21,
   "z": -6,
   "name": "Rock_Stone"
  },
  {
   "x": -6,
   "y": 22,
   "z": -6,
   "name": "Rock_Stone"
  },
  {
   "x": -6,
   "y": 23,
   "z": -6,
   "name": "Rock_Stone"
  },
  {
   "x": -6,
   "y": 24,
   "z": -6,
   "name": "Rock_Stone"
  },
  {
   "x": -6,
   "y": 25,
   "z": -6,
   "name": "Rock_Stone"
  },
  {
   "x": -6,
   "y": 26,
   "z": -6,
   "name": "Rock_Stone"
  },
  {
   "x": -6,
   "y": 27,
   "z": -6,
   "name": "Rock_Stone"
  },
  {
   "x": -6,
   "y": 28,
   "z": -6,
   "name": "Rock_Stone"
  },
  {
   "x": -6,
   "y": 29,
   "z": -6,
   "name": "Rock_Stone"
  },
  {
   "x": -6,
   "y": 30,
   "z": -6,
   "name": "Rock_Stone"
  },
  {
   "x": -6,
   "y": 31,
   "z": -6,
   "name": "Rock_Stone"
  },
  {
   "x": -6,
   "y": 32,
   "z": -6,
   "name": "Rock_Stone"
  },
  {
   "x": -6,
   "y": 33,
   "z": -6,
   "name": "Rock_Stone"
  },
  {
   "x": -6,
   "y": 34,
   "z": -6,
   "name": "Rock_Stone"
  },
  {
   "x": -6,
   "y": 35,
   "z": -6,
   "name": "Rock_Stone"
  },
  {
   "x": -6,
   "y": 36,
   "z": -6,
   "name": "Rock_Stone"
  },
  {
   "x": -6,
   "y": 0,
   "z": -5,
   "name": "Rock_Stone"
  },
  {
   "x": -6,
   "y": 1,
   "z": -5,
   "name": "Rock_Stone"
  },
  {
   "x": -6,
   "y": 2,
   "z": -5,
   "name": "Rock_Stone"
  },
  {
   "x": -6,
   "y": 3,
   "z": -5,
   "name": "Rock_Stone"
  },
  {
   "x": -6,
   "y": 4,
   "z": -5,
   "name": "Rock_Stone"
  },
  {
   "x": -6,
   "y": 5,
   "z": -5,
   "name": "Rock_Stone"
  },
  {
   "x": -6,
   "y": 6,
   "z": -5,
   "name": "Rock_Stone"
  },
  {
   "x": -6,
   "y": 7,
   "z": -5,
   "name": "Rock_Stone"
  },
  {
   "x": -6,
   "y": 8,
   "z": -5,
   "name": "Rock_Stone"
  },
  {
   "x": -6,
   "y": 9,
   "z": -5,
   "name": "Rock_Stone"
  },
  {
   "x": -6,
   "y": 10,
   "z": -5,
   "name": "Rock_Stone"
  },
  {
   "x": -6,
   "y": 11,
   "z": -5,
   "name": "Rock_Stone"
  },
  {
   "x": -6,
   "y": 12,
   "z": -5,
   "name": "Rock_Stone"
  },
  {
   "x": -6,
   "y": 13,
   "z": -5,
   "name": "Rock_Stone"
  },
  {
   "x": -6,
   "y": 21,
   "z": -5,
   "name": "Rock_Stone"
  },
  {
   "x": -6,
   "y": 22,
   "z": -5,
   "name": "Rock_Stone"
  },
  {
   "x": -6,
   "y": 23,
   "z": -5,
   "name": "Rock_Stone"
  },
  {
   "x": -6,
   "y": 24,
   "z": -5,
   "name": "Rock_Stone"
  },
  {
   "x": -6,
   "y": 25,
   "z": -5,
   "name": "Rock_Stone"
  },
  {
   "x": -6,
   "y": 26,
   "z": -5,
   "name": "Rock_Stone"
  },
  {
   "x": -6,
   "y": 27,
   "z": -5,
   "name": "Rock_Stone"
  },
  {
   "x": -6,
   "y": 28,
   "z": -5,
   "name": "Rock_Stone"
  },
  {
   "x": -6,
   "y": 29,
   "z": -5,
   "name": "Rock_Stone"
  },
  {
   "x": -6,
   "y": 30,
   "z": -5,
   "name": "Rock_Stone"
  },
  {
   "x": -6,
   "y": 31,
   "z": -5,
   "name": "Rock_Stone"
  },
  {
   "x": -6,
   "y": 32,
   "z": -5,
   "name": "Rock_Stone"
  },
  {
   "x": -6,
   "y": 33,
   "z": -5,
   "name": "Rock_Stone"
  },
  {
   "x": -6,
   "y": 34,
   "z": -5,
   "name": "Rock_Stone"
  },
  {
   "x": -6,
   "y": 35,
   "z": -5,
   "name": "Rock_Stone"
  },
  {
   "x": -6,
   "y": 36,
   "z": -5,
   "name": "Rock_Stone"
  },
  {
   "x": -6,
   "y": 0,
   "z": -4,
   "name": "Rock_Stone"
  },
  {
   "x": -6,
   "y": 1,
   "z": -4,
   "name": "Rock_Stone"
  },
  {
   "x": -6,
   "y": 2,
   "z": -4,
   "name": "Rock_Stone"
  },
  {
   "x": -6,
   "y": 3,
   "z": -4,
   "name": "Rock_Stone"
  },
  {
   "x": -6,
   "y": 4,
   "z": -4,
   "name": "Rock_Stone"
  },
  {
   "x": -6,
   "y": 5,
   "z": -4,
   "name": "Rock_Stone"
  },
  {
   "x": -6,
   "y": 6,
   "z": -4,
   "name": "Rock_Stone"
  },
  {
   "x": -6,
   "y": 7,
   "z": -4,
   "name": "Rock_Stone"
  },
  {
   "x": -6,
   "y": 8,
   "z": -4,
   "name": "Rock_Stone"
  },
  {
   "x": -6,
   "y": 9,
   "z": -4,
   "name": "Rock_Stone"
  },
  {
   "x": -6,
   "y": 10,
   "z": -4,
   "name": "Rock_Stone"
  },
  {
   "x": -6,
   "y": 11,
   "z": -4,
   "name": "Rock_Stone"
  },
  {
   "x": -6,
   "y": 12,
   "z": -4,
   "name": "Rock_Stone"
  },
  {
   "x": -6,
   "y": 13,
   "z": -4,
   "name": "Rock_Stone"
  },
  {
   "x": -6,
   "y": 14,
   "z": -4,
   "name": "Rock_Stone"
  },
  {
   "x": -6,
   "y": 15,
   "z": -4,
   "name": "Rock_Stone"
  },
  {
   "x": -6,
   "y": 16,
   "z": -4,
   "name": "Rock_Stone"
  },
  {
   "x": -6,
   "y": 17,
   "z": -4,
   "name": "Rock_Stone"
  },
  {
   "x": -6,
   "y": 18,
   "z": -4,
   "name": "Rock_Stone"
  },
  {
   "x": -6,
   "y": 19,
   "z": -4,
   "name": "Rock_Stone"
  },
  {
   "x": -6,
   "y": 20,
   "z": -4,
   "name": "Rock_Stone"
  },
  {
   "x": -6,
   "y": 21,
   "z": -4,
   "name": "Rock_Stone"
  },
  {
   "x": -6,
   "y": 22,
   "z": -4,
   "name": "Rock_Stone"
  },
  {
   "x": -6,
   "y": 23,
   "z": -4,
   "name": "Rock_Stone"
  },
  {
   "x": -6,
   "y": 24,
   "z": -4,
   "name": "Rock_Stone"
  },
  {
   "x": -6,
   "y": 25,
   "z": -4,
   "name": "Rock_Stone_Brick_Smooth"
  },
  {
   "x": -6,
   "y": 26,
   "z": -4,
   "name": "Rock_Stone_Brick_Smooth"
  },
  {
   "x": -6,
   "y": 27,
   "z": -4,
   "name": "Rock_Stone"
  },
  {
   "x": -6,
   "y": 28,
   "z": -4,
   "name": "Rock_Stone"
  },
  {
   "x": -6,
   "y": 29,
   "z": -4,
   "name": "Rock_Stone"
  },
  {
   "x": -6,
   "y": 30,
   "z": -4,
   "name": "Rock_Stone"
  },
  {
   "x": -6,
   "y": 31,
   "z": -4,
   "name": "Rock_Stone"
  },
  {
   "x": -6,
   "y": 32,
   "z": -4,
   "name": "Rock_Stone"
  },
  {
   "x": -6,
   "y": 33,
   "z": -4,
   "name": "Rock_Stone"
  },
  {
   "x": -6,
   "y": 34,
   "z": -4,
   "name": "Rock_Stone"
  },
  {
   "x": -6,
   "y": 35,
   "z": -4,
   "name": "Rock_Stone"
  },
  {
   "x": -6,
   "y": 36,
   "z": -4,
   "name": "Rock_Stone_Brick_Smooth"
  },
  {
   "x": -6,
   "y": 0,
   "z": -3,
   "name": "Rock_Stone"
  },
  {
   "x": -6,
   "y": 1,
   "z": -3,
   "name": "Rock_Stone"
  },
  {
   "x": -6,
   "y": 2,
   "z": -3,
   "name": "Rock_Stone"
  },
  {
   "x": -6,
   "y": 3,
   "z": -3,
   "name": "Rock_Stone"
  },
  {
   "x": -6,
   "y": 4,
   "z": -3,
   "name": "Rock_Stone"
  },
  {
   "x": -6,
   "y": 5,
   "z": -3,
   "name": "Rock_Stone"
  },
  {
   "x": -6,
   "y": 6,
   "z": -3,
   "name": "Rock_Stone"
  },
  {
   "x": -6,
   "y": 7,
   "z": -3,
   "name": "Rock_Stone"
  },
  {
   "x": -6,
   "y": 8,
   "z": -3,
   "name": "Rock_Stone"
  },
  {
   "x": -6,
   "y": 9,
   "z": -3,
   "name": "Rock_Stone"
  },
  {
   "x": -6,
   "y": 10,
   "z": -3,
   "name": "Rock_Stone"
  },
  {
   "x": -6,
   "y": 11,
   "z": -3,
   "name": "Rock_Stone"
  },
  {
   "x": -6,
   "y": 12,
   "z": -3,
   "name": "Rock_Stone"
  },
  {
   "x": -6,
   "y": 13,
   "z": -3,
   "name": "Rock_Stone"
  },
  {
   "x": -6,
   "y": 14,
   "z": -3,
   "name": "Rock_Stone"
  },
  {
   "x": -6,
   "y": 15,
   "z": -3,
   "name": "Rock_Stone"
  },
  {
   "x": -6,
   "y": 16,
   "z": -3,
   "name": "Rock_Stone"
  },
  {
   "x": -6,
   "y": 17,
   "z": -3,
   "name": "Rock_Stone"
  },
  {
   "x": -6,
   "y": 18,
   "z": -3,
   "name": "Rock_Stone"
  },
  {
   "x": -6,
   "y": 19,
   "z": -3,
   "name": "Rock_Stone"
  },
  {
   "x": -6,
   "y": 20,
   "z": -3,
   "name": "Rock_Stone"
  },
  {
   "x": -6,
   "y": 21,
   "z": -3,
   "name": "Rock_Stone"
  },
  {
   "x": -6,
   "y": 22,
   "z": -3,
   "name": "Rock_Stone"
  },
  {
   "x": -6,
   "y": 23,
   "z": -3,
   "name": "Rock_Stone"
  },
  {
   "x": -6,
   "y": 24,
   "z": -3,
   "name": "Rock_Stone_Brick_Smooth"
  },
  {
   "x": -6,
   "y": 25,
   "z": -3,
   "name": "Rock_Stone_Brick_Smooth"
  },
  {
   "x": -6,
   "y": 26,
   "z": -3,
   "name": "Rock_Stone_Brick_Smooth"
  },
  {
   "x": -6,
   "y": 27,
   "z": -3,
   "name": "Rock_Stone"
  },
  {
   "x": -6,
   "y": 28,
   "z": -3,
   "name": "Rock_Stone"
  },
  {
   "x": -6,
   "y": 29,
   "z": -3,
   "name": "Rock_Stone"
  },
  {
   "x": -6,
   "y": 30,
   "z": -3,
   "name": "Rock_Stone"
  },
  {
   "x": -6,
   "y": 31,
   "z": -3,
   "name": "Rock_Stone"
  },
  {
   "x": -6,
   "y": 32,
   "z": -3,
   "name": "Rock_Stone"
  },
  {
   "x": -6,
   "y": 33,
   "z": -3,
   "name": "Rock_Stone"
  },
  {
   "x": -6,
   "y": 34,
   "z": -3,
   "name": "Rock_Stone"
  },
  {
   "x": -6,
   "y": 35,
   "z": -3,
   "name": "Rock_Stone"
  },
  {
   "x": -6,
   "y": 36,
   "z": -3,
   "name": "Rock_Stone_Brick_Smooth"
  },
  {
   "x": -6,
   "y": 0,
   "z": -2,
   "name": "Rock_Stone"
  },
  {
   "x": -6,
   "y": 1,
   "z": -2,
   "name": "Rock_Stone"
  },
  {
   "x": -6,
   "y": 2,
   "z": -2,
   "name": "Rock_Stone"
  },
  {
   "x": -6,
   "y": 3,
   "z": -2,
   "name": "Rock_Stone"
  },
  {
   "x": -6,
   "y": 4,
   "z": -2,
   "name": "Rock_Stone"
  },
  {
   "x": -6,
   "y": 5,
   "z": -2,
   "name": "Rock_Stone"
  },
  {
   "x": -6,
   "y": 6,
   "z": -2,
   "name": "Rock_Stone"
  },
  {
   "x": -6,
   "y": 7,
   "z": -2,
   "name": "Rock_Stone"
  },
  {
   "x": -6,
   "y": 8,
   "z": -2,
   "name": "Rock_Stone"
  },
  {
   "x": -6,
   "y": 9,
   "z": -2,
   "name": "Rock_Stone"
  },
  {
   "x": -6,
   "y": 10,
   "z": -2,
   "name": "Rock_Stone"
  },
  {
   "x": -6,
   "y": 11,
   "z": -2,
   "name": "Rock_Stone"
  },
  {
   "x": -6,
   "y": 12,
   "z": -2,
   "name": "Rock_Stone"
  },
  {
   "x": -6,
   "y": 13,
   "z": -2,
   "name": "Rock_Stone"
  },
  {
   "x": -6,
   "y": 14,
   "z": -2,
   "name": "Rock_Stone"
  },
  {
   "x": -6,
   "y": 15,
   "z": -2,
   "name": "Rock_Stone"
  },
  {
   "x": -6,
   "y": 16,
   "z": -2,
   "name": "Rock_Stone"
  },
  {
   "x": -6,
   "y": 17,
   "z": -2,
   "name": "Rock_Stone"
  },
  {
   "x": -6,
   "y": 18,
   "z": -2,
   "name": "Rock_Stone"
  },
  {
   "x": -6,
   "y": 19,
   "z": -2,
   "name": "Rock_Stone"
  },
  {
   "x": -6,
   "y": 20,
   "z": -2,
   "name": "Rock_Stone"
  },
  {
   "x": -6,
   "y": 21,
   "z": -2,
   "name": "Rock_Stone"
  },
  {
   "x": -6,
   "y": 22,
   "z": -2,
   "name": "Rock_Stone"
  },
  {
   "x": -6,
   "y": 23,
   "z": -2,
   "name": "Rock_Stone_Brick_Smooth"
  },
  {
   "x": -6,
   "y": 24,
   "z": -2,
   "name": "Rock_Stone_Brick_Smooth"
  },
  {
   "x": -6,
   "y": 25,
   "z": -2,
   "name": "Rock_Stone_Brick_Smooth"
  },
  {
   "x": -6,
   "y": 26,
   "z": -2,
   "name": "Rock_Stone_Brick_Smooth"
  },
  {
   "x": -6,
   "y": 27,
   "z": -2,
   "name": "Rock_Stone"
  },
  {
   "x": -6,
   "y": 28,
   "z": -2,
   "name": "Rock_Stone"
  },
  {
   "x": -6,
   "y": 29,
   "z": -2,
   "name": "Rock_Stone"
  },
  {
   "x": -6,
   "y": 30,
   "z": -2,
   "name": "Rock_Stone"
  },
  {
   "x": -6,
   "y": 31,
   "z": -2,
   "name": "Rock_Stone"
  },
  {
   "x": -6,
   "y": 32,
   "z": -2,
   "name": "Rock_Stone"
  },
  {
   "x": -6,
   "y": 33,
   "z": -2,
   "name": "Rock_Stone"
  },
  {
   "x": -6,
   "y": 34,
   "z": -2,
   "name": "Rock_Stone"
  },
  {
   "x": -6,
   "y": 35,
   "z": -2,
   "name": "Rock_Stone"
  },
  {
   "x": -6,
   "y": 36,
   "z": -2,
   "name": "Rock_Stone_Brick_Smooth"
  },
  {
   "x": -6,
   "y": 0,
   "z": -1,
   "name": "Rock_Stone"
  },
  {
   "x": -6,
   "y": 1,
   "z": -1,
   "name": "Rock_Stone"
  },
  {
   "x": -6,
   "y": 2,
   "z": -1,
   "name": "Rock_Stone"
  },
  {
   "x": -6,
   "y": 3,
   "z": -1,
   "name": "Rock_Stone"
  },
  {
   "x": -6,
   "y": 4,
   "z": -1,
   "name": "Rock_Stone"
  },
  {
   "x": -6,
   "y": 5,
   "z": -1,
   "name": "Rock_Stone"
  },
  {
   "x": -6,
   "y": 6,
   "z": -1,
   "name": "Rock_Stone"
  },
  {
   "x": -6,
   "y": 7,
   "z": -1,
   "name": "Rock_Stone"
  },
  {
   "x": -6,
   "y": 8,
   "z": -1,
   "name": "Rock_Stone"
  },
  {
   "x": -6,
   "y": 9,
   "z": -1,
   "name": "Rock_Stone"
  },
  {
   "x": -6,
   "y": 10,
   "z": -1,
   "name": "Rock_Stone"
  },
  {
   "x": -6,
   "y": 11,
   "z": -1,
   "name": "Rock_Stone"
  },
  {
   "x": -6,
   "y": 12,
   "z": -1,
   "name": "Rock_Stone"
  },
  {
   "x": -6,
   "y": 13,
   "z": -1,
   "name": "Rock_Stone"
  },
  {
   "x": -6,
   "y": 14,
   "z": -1,
   "name": "Rock_Stone"
  },
  {
   "x": -6,
   "y": 15,
   "z": -1,
   "name": "Rock_Stone"
  },
  {
   "x": -6,
   "y": 16,
   "z": -1,
   "name": "Rock_Stone"
  },
  {
   "x": -6,
   "y": 17,
   "z": -1,
   "name": "Rock_Stone"
  },
  {
   "x": -6,
   "y": 18,
   "z": -1,
   "name": "Rock_Stone"
  },
  {
   "x": -6,
   "y": 19,
   "z": -1,
   "name": "Rock_Stone"
  },
  {
   "x": -6,
   "y": 20,
   "z": -1,
   "name": "Rock_Stone"
  },
  {
   "x": -6,
   "y": 21,
   "z": -1,
   "name": "Rock_Stone"
  },
  {
   "x": -6,
   "y": 22,
   "z": -1,
   "name": "Rock_Stone_Brick_Smooth"
  },
  {
   "x": -6,
   "y": 23,
   "z": -1,
   "name": "Rock_Stone_Brick_Smooth"
  },
  {
   "x": -6,
   "y": 24,
   "z": -1,
   "name": "Rock_Stone_Brick_Smooth"
  },
  {
   "x": -6,
   "y": 25,
   "z": -1,
   "name": "Rock_Stone_Brick_Smooth"
  },
  {
   "x": -6,
   "y": 26,
   "z": -1,
   "name": "Rock_Stone"
  },
  {
   "x": -6,
   "y": 27,
   "z": -1,
   "name": "Rock_Stone"
  },
  {
   "x": -6,
   "y": 28,
   "z": -1,
   "name": "Rock_Stone"
  },
  {
   "x": -6,
   "y": 29,
   "z": -1,
   "name": "Rock_Stone"
  },
  {
   "x": -6,
   "y": 30,
   "z": -1,
   "name": "Rock_Stone"
  },
  {
   "x": -6,
   "y": 31,
   "z": -1,
   "name": "Rock_Stone"
  },
  {
   "x": -6,
   "y": 32,
   "z": -1,
   "name": "Rock_Stone"
  },
  {
   "x": -6,
   "y": 33,
   "z": -1,
   "name": "Rock_Stone"
  },
  {
   "x": -6,
   "y": 34,
   "z": -1,
   "name": "Rock_Stone_Brick_Smooth"
  },
  {
   "x": -6,
   "y": 35,
   "z": -1,
   "name": "Rock_Stone_Brick_Smooth"
  },
  {
   "x": -6,
   "y": 36,
   "z": -1,
   "name": "Rock_Stone_Brick_Smooth"
  },
  {
   "x": -6,
   "y": 0,
   "z": 0,
   "name": "Rock_Stone"
  },
  {
   "x": -6,
   "y": 1,
   "z": 0,
   "name": "Rock_Stone"
  },
  {
   "x": -6,
   "y": 2,
   "z": 0,
   "name": "Rock_Stone"
  },
  {
   "x": -6,
   "y": 3,
   "z": 0,
   "name": "Rock_Stone"
  },
  {
   "x": -6,
   "y": 4,
   "z": 0,
   "name": "Rock_Stone"
  },
  {
   "x": -6,
   "y": 5,
   "z": 0,
   "name": "Rock_Stone"
  },
  {
   "x": -6,
   "y": 6,
   "z": 0,
   "name": "Rock_Stone"
  },
  {
   "x": -6,
   "y": 7,
   "z": 0,
   "name": "Rock_Stone"
  },
  {
   "x": -6,
   "y": 8,
   "z": 0,
   "name": "Rock_Stone"
  },
  {
   "x": -6,
   "y": 9,
   "z": 0,
   "name": "Rock_Stone"
  },
  {
   "x": -6,
   "y": 10,
   "z": 0,
   "name": "Rock_Stone"
  },
  {
   "x": -6,
   "y": 11,
   "z": 0,
   "name": "Rock_Stone"
  },
  {
   "x": -6,
   "y": 12,
   "z": 0,
   "name": "Rock_Stone"
  },
  {
   "x": -6,
   "y": 13,
   "z": 0,
   "name": "Rock_Stone"
  },
  {
   "x": -6,
   "y": 14,
   "z": 0,
   "name": "Rock_Stone"
  },
  {
   "x": -6,
   "y": 15,
   "z": 0,
   "name": "Rock_Stone"
  },
  {
   "x": -6,
   "y": 16,
   "z": 0,
   "name": "Rock_Stone"
  },
  {
   "x": -6,
   "y": 17,
   "z": 0,
   "name": "Rock_Stone"
  },
  {
   "x": -6,
   "y": 18,
   "z": 0,
   "name": "Rock_Stone"
  },
  {
   "x": -6,
   "y": 19,
   "z": 0,
   "name": "Rock_Stone"
  },
  {
   "x": -6,
   "y": 20,
   "z": 0,
   "name": "Rock_Stone"
  },
  {
   "x": -6,
   "y": 21,
   "z": 0,
   "name": "Rock_Stone_Brick_Smooth"
  },
  {
   "x": -6,
   "y": 22,
   "z": 0,
   "name": "Rock_Stone_Brick_Smooth"
  },
  {
   "x": -6,
   "y": 23,
   "z": 0,
   "name": "Rock_Stone_Brick_Smooth"
  },
  {
   "x": -6,
   "y": 24,
   "z": 0,
   "name": "Rock_Stone_Brick_Smooth"
  },
  {
   "x": -6,
   "y": 25,
   "z": 0,
   "name": "Rock_Stone"
  },
  {
   "x": -6,
   "y": 26,
   "z": 0,
   "name": "Rock_Stone"
  },
  {
   "x": -6,
   "y": 27,
   "z": 0,
   "name": "Rock_Stone"
  },
  {
   "x": -6,
   "y": 28,
   "z": 0,
   "name": "Rock_Stone"
  },
  {
   "x": -6,
   "y": 29,
   "z": 0,
   "name": "Rock_Stone"
  },
  {
   "x": -6,
   "y": 30,
   "z": 0,
   "name": "Rock_Stone"
  },
  {
   "x": -6,
   "y": 31,
   "z": 0,
   "name": "Rock_Stone"
  },
  {
   "x": -6,
   "y": 32,
   "z": 0,
   "name": "Rock_Stone"
  },
  {
   "x": -6,
   "y": 33,
   "z": 0,
   "name": "Rock_Stone"
  },
  {
   "x": -6,
   "y": 34,
   "z": 0,
   "name": "Rock_Stone_Brick_Smooth"
  },
  {
   "x": -6,
   "y": 35,
   "z": 0,
   "name": "Rock_Stone_Brick_Smooth"
  },
  {
   "x": -6,
   "y": 36,
   "z": 0,
   "name": "Rock_Stone_Brick_Smooth"
  },
  {
   "x": -6,
   "y": 0,
   "z": 1,
   "name": "Rock_Stone"
  },
  {
   "x": -6,
   "y": 1,
   "z": 1,
   "name": "Rock_Stone"
  },
  {
   "x": -6,
   "y": 2,
   "z": 1,
   "name": "Rock_Stone"
  },
  {
   "x": -6,
   "y": 3,
   "z": 1,
   "name": "Rock_Stone"
  },
  {
   "x": -6,
   "y": 4,
   "z": 1,
   "name": "Rock_Stone"
  },
  {
   "x": -6,
   "y": 5,
   "z": 1,
   "name": "Rock_Stone"
  },
  {
   "x": -6,
   "y": 6,
   "z": 1,
   "name": "Rock_Stone"
  },
  {
   "x": -6,
   "y": 7,
   "z": 1,
   "name": "Rock_Stone"
  },
  {
   "x": -6,
   "y": 8,
   "z": 1,
   "name": "Rock_Stone"
  },
  {
   "x": -6,
   "y": 9,
   "z": 1,
   "name": "Rock_Stone"
  },
  {
   "x": -6,
   "y": 10,
   "z": 1,
   "name": "Rock_Stone"
  },
  {
   "x": -6,
   "y": 11,
   "z": 1,
   "name": "Rock_Stone"
  },
  {
   "x": -6,
   "y": 12,
   "z": 1,
   "name": "Rock_Stone"
  },
  {
   "x": -6,
   "y": 13,
   "z": 1,
   "name": "Rock_Stone"
  },
  {
   "x": -6,
   "y": 14,
   "z": 1,
   "name": "Rock_Stone"
  },
  {
   "x": -6,
   "y": 15,
   "z": 1,
   "name": "Rock_Stone"
  },
  {
   "x": -6,
   "y": 16,
   "z": 1,
   "name": "Rock_Stone"
  },
  {
   "x": -6,
   "y": 17,
   "z": 1,
   "name": "Rock_Stone"
  },
  {
   "x": -6,
   "y": 18,
   "z": 1,
   "name": "Rock_Stone"
  },
  {
   "x": -6,
   "y": 19,
   "z": 1,
   "name": "Rock_Stone"
  },
  {
   "x": -6,
   "y": 20,
   "z": 1,
   "name": "Rock_Stone_Brick_Smooth"
  },
  {
   "x": -6,
   "y": 21,
   "z": 1,
   "name": "Rock_Stone_Brick_Smooth"
  },
  {
   "x": -6,
   "y": 22,
   "z": 1,
   "name": "Rock_Stone_Brick_Smooth"
  },
  {
   "x": -6,
   "y": 23,
   "z": 1,
   "name": "Rock_Stone_Brick_Smooth"
  },
  {
   "x": -6,
   "y": 24,
   "z": 1,
   "name": "Rock_Stone_Brick_Smooth"
  },
  {
   "x": -6,
   "y": 25,
   "z": 1,
   "name": "Rock_Stone"
  },
  {
   "x": -6,
   "y": 26,
   "z": 1,
   "name": "Rock_Stone"
  },
  {
   "x": -6,
   "y": 27,
   "z": 1,
   "name": "Rock_Stone"
  },
  {
   "x": -6,
   "y": 28,
   "z": 1,
   "name": "Rock_Stone"
  },
  {
   "x": -6,
   "y": 29,
   "z": 1,
   "name": "Rock_Stone"
  },
  {
   "x": -6,
   "y": 30,
   "z": 1,
   "name": "Rock_Stone"
  },
  {
   "x": -6,
   "y": 31,
   "z": 1,
   "name": "Rock_Stone"
  },
  {
   "x": -6,
   "y": 32,
   "z": 1,
   "name": "Rock_Stone"
  },
  {
   "x": -6,
   "y": 33,
   "z": 1,
   "name": "Rock_Stone"
  },
  {
   "x": -6,
   "y": 34,
   "z": 1,
   "name": "Rock_Stone_Brick_Smooth_Half",
   "rotation": 5
  },
  {
   "x": -6,
   "y": 35,
   "z": 1,
   "name": "Rock_Stone_Brick_Smooth"
  },
  {
   "x": -6,
   "y": 36,
   "z": 1,
   "name": "Rock_Stone_Brick_Smooth"
  },
  {
   "x": -6,
   "y": 0,
   "z": 2,
   "name": "Rock_Stone"
  },
  {
   "x": -6,
   "y": 1,
   "z": 2,
   "name": "Rock_Stone"
  },
  {
   "x": -6,
   "y": 2,
   "z": 2,
   "name": "Rock_Stone"
  },
  {
   "x": -6,
   "y": 3,
   "z": 2,
   "name": "Rock_Stone"
  },
  {
   "x": -6,
   "y": 4,
   "z": 2,
   "name": "Rock_Stone"
  },
  {
   "x": -6,
   "y": 5,
   "z": 2,
   "name": "Rock_Stone"
  },
  {
   "x": -6,
   "y": 6,
   "z": 2,
   "name": "Rock_Stone"
  },
  {
   "x": -6,
   "y": 7,
   "z": 2,
   "name": "Rock_Stone"
  },
  {
   "x": -6,
   "y": 8,
   "z": 2,
   "name": "Rock_Stone"
  },
  {
   "x": -6,
   "y": 9,
   "z": 2,
   "name": "Rock_Stone"
  },
  {
   "x": -6,
   "y": 10,
   "z": 2,
   "name": "Rock_Stone"
  },
  {
   "x": -6,
   "y": 11,
   "z": 2,
   "name": "Rock_Stone"
  },
  {
   "x": -6,
   "y": 12,
   "z": 2,
   "name": "Rock_Stone"
  },
  {
   "x": -6,
   "y": 13,
   "z": 2,
   "name": "Rock_Stone"
  },
  {
   "x": -6,
   "y": 14,
   "z": 2,
   "name": "Rock_Stone"
  },
  {
   "x": -6,
   "y": 15,
   "z": 2,
   "name": "Rock_Stone"
  },
  {
   "x": -6,
   "y": 16,
   "z": 2,
   "name": "Rock_Stone"
  },
  {
   "x": -6,
   "y": 17,
   "z": 2,
   "name": "Rock_Stone"
  },
  {
   "x": -6,
   "y": 18,
   "z": 2,
   "name": "Rock_Stone"
  },
  {
   "x": -6,
   "y": 19,
   "z": 2,
   "name": "Rock_Stone"
  },
  {
   "x": -6,
   "y": 20,
   "z": 2,
   "name": "Rock_Stone_Brick_Smooth"
  },
  {
   "x": -6,
   "y": 21,
   "z": 2,
   "name": "Rock_Stone_Brick_Smooth"
  },
  {
   "x": -6,
   "y": 22,
   "z": 2,
   "name": "Rock_Stone_Brick_Smooth"
  },
  {
   "x": -6,
   "y": 23,
   "z": 2,
   "name": "Rock_Stone_Brick_Smooth"
  },
  {
   "x": -6,
   "y": 24,
   "z": 2,
   "name": "Rock_Stone_Brick_Smooth"
  },
  {
   "x": -6,
   "y": 25,
   "z": 2,
   "name": "Rock_Stone"
  },
  {
   "x": -6,
   "y": 26,
   "z": 2,
   "name": "Rock_Stone"
  },
  {
   "x": -6,
   "y": 27,
   "z": 2,
   "name": "Rock_Stone"
  },
  {
   "x": -6,
   "y": 28,
   "z": 2,
   "name": "Rock_Stone"
  },
  {
   "x": -6,
   "y": 29,
   "z": 2,
   "name": "Rock_Stone"
  },
  {
   "x": -6,
   "y": 30,
   "z": 2,
   "name": "Rock_Stone"
  },
  {
   "x": -6,
   "y": 31,
   "z": 2,
   "name": "Rock_Stone"
  },
  {
   "x": -6,
   "y": 32,
   "z": 2,
   "name": "Rock_Stone"
  },
  {
   "x": -6,
   "y": 33,
   "z": 2,
   "name": "Rock_Stone_Brick_Smooth_Half",
   "rotation": 5
  },
  {
   "x": -6,
   "y": 34,
   "z": 2,
   "name": "Rock_Stone_Brick_Smooth_Half",
   "rotation": 5
  },
  {
   "x": -6,
   "y": 35,
   "z": 2,
   "name": "Rock_Stone_Brick_Smooth_Half",
   "rotation": 5
  },
  {
   "x": -6,
   "y": 36,
   "z": 2,
   "name": "Rock_Stone_Brick_Smooth"
  },
  {
   "x": -6,
   "y": 0,
   "z": 3,
   "name": "Rock_Stone"
  },
  {
   "x": -6,
   "y": 1,
   "z": 3,
   "name": "Rock_Stone"
  },
  {
   "x": -6,
   "y": 2,
   "z": 3,
   "name": "Rock_Stone"
  },
  {
   "x": -6,
   "y": 3,
   "z": 3,
   "name": "Rock_Stone"
  },
  {
   "x": -6,
   "y": 4,
   "z": 3,
   "name": "Rock_Stone"
  },
  {
   "x": -6,
   "y": 5,
   "z": 3,
   "name": "Rock_Stone"
  },
  {
   "x": -6,
   "y": 6,
   "z": 3,
   "name": "Rock_Stone"
  },
  {
   "x": -6,
   "y": 7,
   "z": 3,
   "name": "Rock_Stone"
  },
  {
   "x": -6,
   "y": 8,
   "z": 3,
   "name": "Rock_Stone"
  },
  {
   "x": -6,
   "y": 9,
   "z": 3,
   "name": "Rock_Stone"
  },
  {
   "x": -6,
   "y": 10,
   "z": 3,
   "name": "Rock_Stone"
  },
  {
   "x": -6,
   "y": 11,
   "z": 3,
   "name": "Rock_Stone"
  },
  {
   "x": -6,
   "y": 12,
   "z": 3,
   "name": "Rock_Stone"
  },
  {
   "x": -6,
   "y": 13,
   "z": 3,
   "name": "Rock_Stone"
  },
  {
   "x": -6,
   "y": 14,
   "z": 3,
   "name": "Rock_Stone"
  },
  {
   "x": -6,
   "y": 15,
   "z": 3,
   "name": "Rock_Stone"
  },
  {
   "x": -6,
   "y": 16,
   "z": 3,
   "name": "Rock_Stone"
  },
  {
   "x": -6,
   "y": 17,
   "z": 3,
   "name": "Rock_Stone"
  },
  {
   "x": -6,
   "y": 18,
   "z": 3,
   "name": "Rock_Stone"
  },
  {
   "x": -6,
   "y": 19,
   "z": 3,
   "name": "Rock_Stone"
  },
  {
   "x": -6,
   "y": 20,
   "z": 3,
   "name": "Rock_Stone_Brick_Smooth"
  },
  {
   "x": -6,
   "y": 21,
   "z": 3,
   "name": "Rock_Stone_Brick_Smooth"
  },
  {
   "x": -6,
   "y": 22,
   "z": 3,
   "name": "Rock_Stone_Brick_Smooth"
  },
  {
   "x": -6,
   "y": 23,
   "z": 3,
   "name": "Rock_Stone_Brick_Smooth"
  },
  {
   "x": -6,
   "y": 24,
   "z": 3,
   "name": "Rock_Stone"
  },
  {
   "x": -6,
   "y": 25,
   "z": 3,
   "name": "Rock_Stone"
  },
  {
   "x": -6,
   "y": 26,
   "z": 3,
   "name": "Rock_Stone"
  },
  {
   "x": -6,
   "y": 27,
   "z": 3,
   "name": "Rock_Stone"
  },
  {
   "x": -6,
   "y": 28,
   "z": 3,
   "name": "Rock_Stone"
  },
  {
   "x": -6,
   "y": 29,
   "z": 3,
   "name": "Rock_Stone"
  },
  {
   "x": -6,
   "y": 30,
   "z": 3,
   "name": "Rock_Stone"
  },
  {
   "x": -6,
   "y": 31,
   "z": 3,
   "name": "Empty"
  },
  {
   "x": -6,
   "y": 32,
   "z": 3,
   "name": "Empty"
  },
  {
   "x": -6,
   "y": 33,
   "z": 3,
   "name": "Empty"
  },
  {
   "x": -6,
   "y": 34,
   "z": 3,
   "name": "Rock_Stone_Brick_Smooth_Half",
   "rotation": 5
  },
  {
   "x": -6,
   "y": 35,
   "z": 3,
   "name": "Rock_Stone_Brick_Smooth_Half",
   "rotation": 5
  },
  {
   "x": -6,
   "y": 36,
   "z": 3,
   "name": "Rock_Stone_Brick_Smooth"
  },
  {
   "x": -6,
   "y": 0,
   "z": 4,
   "name": "Rock_Stone"
  },
  {
   "x": -6,
   "y": 1,
   "z": 4,
   "name": "Rock_Stone"
  },
  {
   "x": -6,
   "y": 2,
   "z": 4,
   "name": "Rock_Stone"
  },
  {
   "x": -6,
   "y": 3,
   "z": 4,
   "name": "Rock_Stone"
  },
  {
   "x": -6,
   "y": 4,
   "z": 4,
   "name": "Rock_Stone"
  },
  {
   "x": -6,
   "y": 5,
   "z": 4,
   "name": "Rock_Stone"
  },
  {
   "x": -6,
   "y": 6,
   "z": 4,
   "name": "Rock_Stone"
  },
  {
   "x": -6,
   "y": 7,
   "z": 4,
   "name": "Rock_Stone"
  },
  {
   "x": -6,
   "y": 8,
   "z": 4,
   "name": "Rock_Stone"
  },
  {
   "x": -6,
   "y": 9,
   "z": 4,
   "name": "Rock_Stone"
  },
  {
   "x": -6,
   "y": 10,
   "z": 4,
   "name": "Rock_Stone"
  },
  {
   "x": -6,
   "y": 11,
   "z": 4,
   "name": "Rock_Stone"
  },
  {
   "x": -6,
   "y": 12,
   "z": 4,
   "name": "Rock_Stone"
  },
  {
   "x": -6,
   "y": 13,
   "z": 4,
   "name": "Rock_Stone"
  },
  {
   "x": -6,
   "y": 14,
   "z": 4,
   "name": "Rock_Stone"
  },
  {
   "x": -6,
   "y": 15,
   "z": 4,
   "name": "Rock_Stone"
  },
  {
   "x": -6,
   "y": 16,
   "z": 4,
   "name": "Rock_Stone"
  },
  {
   "x": -6,
   "y": 17,
   "z": 4,
   "name": "Rock_Stone"
  },
  {
   "x": -6,
   "y": 18,
   "z": 4,
   "name": "Rock_Stone"
  },
  {
   "x": -6,
   "y": 19,
   "z": 4,
   "name": "Rock_Stone"
  },
  {
   "x": -6,
   "y": 20,
   "z": 4,
   "name": "Rock_Stone_Brick_Smooth"
  },
  {
   "x": -6,
   "y": 21,
   "z": 4,
   "name": "Rock_Stone_Brick_Smooth"
  },
  {
   "x": -6,
   "y": 22,
   "z": 4,
   "name": "Rock_Stone_Brick_Smooth"
  },
  {
   "x": -6,
   "y": 23,
   "z": 4,
   "name": "Rock_Stone_Brick_Smooth"
  },
  {
   "x": -6,
   "y": 24,
   "z": 4,
   "name": "Rock_Stone"
  },
  {
   "x": -6,
   "y": 25,
   "z": 4,
   "name": "Rock_Stone"
  },
  {
   "x": -6,
   "y": 26,
   "z": 4,
   "name": "Rock_Stone"
  },
  {
   "x": -6,
   "y": 27,
   "z": 4,
   "name": "Rock_Stone"
  },
  {
   "x": -6,
   "y": 28,
   "z": 4,
   "name": "Rock_Stone"
  },
  {
   "x": -6,
   "y": 29,
   "z": 4,
   "name": "Rock_Stone"
  },
  {
   "x": -6,
   "y": 30,
   "z": 4,
   "name": "Rock_Stone"
  },
  {
   "x": -6,
   "y": 31,
   "z": 4,
   "name": "Empty"
  },
  {
   "x": -6,
   "y": 32,
   "z": 4,
   "name": "Empty"
  },
  {
   "x": -6,
   "y": 33,
   "z": 4,
   "name": "Empty"
  },
  {
   "x": -6,
   "y": 34,
   "z": 4,
   "name": "Empty"
  },
  {
   "x": -6,
   "y": 35,
   "z": 4,
   "name": "Rock_Stone"
  },
  {
   "x": -6,
   "y": 36,
   "z": 4,
   "name": "Rock_Stone"
  },
  {
   "x": -6,
   "y": 0,
   "z": 5,
   "name": "Rock_Stone"
  },
  {
   "x": -6,
   "y": 1,
   "z": 5,
   "name": "Rock_Stone"
  },
  {
   "x": -6,
   "y": 2,
   "z": 5,
   "name": "Rock_Stone"
  },
  {
   "x": -6,
   "y": 3,
   "z": 5,
   "name": "Rock_Stone"
  },
  {
   "x": -6,
   "y": 4,
   "z": 5,
   "name": "Rock_Stone"
  },
  {
   "x": -6,
   "y": 5,
   "z": 5,
   "name": "Rock_Stone"
  },
  {
   "x": -6,
   "y": 6,
   "z": 5,
   "name": "Rock_Stone"
  },
  {
   "x": -6,
   "y": 7,
   "z": 5,
   "name": "Rock_Stone"
  },
  {
   "x": -6,
   "y": 8,
   "z": 5,
   "name": "Rock_Stone"
  },
  {
   "x": -6,
   "y": 9,
   "z": 5,
   "name": "Rock_Stone"
  },
  {
   "x": -6,
   "y": 10,
   "z": 5,
   "name": "Rock_Stone"
  },
  {
   "x": -6,
   "y": 11,
   "z": 5,
   "name": "Rock_Stone"
  },
  {
   "x": -6,
   "y": 12,
   "z": 5,
   "name": "Rock_Stone"
  },
  {
   "x": -6,
   "y": 13,
   "z": 5,
   "name": "Rock_Stone"
  },
  {
   "x": -6,
   "y": 14,
   "z": 5,
   "name": "Rock_Stone"
  },
  {
   "x": -6,
   "y": 15,
   "z": 5,
   "name": "Rock_Stone"
  },
  {
   "x": -6,
   "y": 16,
   "z": 5,
   "name": "Rock_Stone"
  },
  {
   "x": -6,
   "y": 17,
   "z": 5,
   "name": "Rock_Stone"
  },
  {
   "x": -6,
   "y": 18,
   "z": 5,
   "name": "Rock_Stone"
  },
  {
   "x": -6,
   "y": 19,
   "z": 5,
   "name": "Rock_Stone"
  },
  {
   "x": -6,
   "y": 20,
   "z": 5,
   "name": "Rock_Stone_Brick_Smooth"
  },
  {
   "x": -6,
   "y": 21,
   "z": 5,
   "name": "Rock_Stone_Brick_Smooth"
  },
  {
   "x": -6,
   "y": 22,
   "z": 5,
   "name": "Rock_Stone_Brick_Smooth"
  },
  {
   "x": -6,
   "y": 23,
   "z": 5,
   "name": "Rock_Stone"
  },
  {
   "x": -6,
   "y": 24,
   "z": 5,
   "name": "Rock_Stone"
  },
  {
   "x": -6,
   "y": 25,
   "z": 5,
   "name": "Rock_Stone"
  },
  {
   "x": -6,
   "y": 26,
   "z": 5,
   "name": "Rock_Stone"
  },
  {
   "x": -6,
   "y": 27,
   "z": 5,
   "name": "Rock_Stone"
  },
  {
   "x": -6,
   "y": 28,
   "z": 5,
   "name": "Rock_Stone"
  },
  {
   "x": -6,
   "y": 29,
   "z": 5,
   "name": "Rock_Stone"
  },
  {
   "x": -6,
   "y": 30,
   "z": 5,
   "name": "Rock_Stone"
  },
  {
   "x": -6,
   "y": 31,
   "z": 5,
   "name": "Rock_Stone"
  },
  {
   "x": -6,
   "y": 32,
   "z": 5,
   "name": "Empty"
  },
  {
   "x": -6,
   "y": 33,
   "z": 5,
   "name": "Empty"
  },
  {
   "x": -6,
   "y": 34,
   "z": 5,
   "name": "Rock_Stone"
  },
  {
   "x": -6,
   "y": 35,
   "z": 5,
   "name": "Rock_Stone"
  },
  {
   "x": -6,
   "y": 36,
   "z": 5,
   "name": "Rock_Stone"
  },
  {
   "x": -6,
   "y": 0,
   "z": 6,
   "name": "Rock_Stone"
  },
  {
   "x": -6,
   "y": 1,
   "z": 6,
   "name": "Rock_Stone"
  },
  {
   "x": -6,
   "y": 2,
   "z": 6,
   "name": "Rock_Stone"
  },
  {
   "x": -6,
   "y": 3,
   "z": 6,
   "name": "Rock_Stone"
  },
  {
   "x": -6,
   "y": 4,
   "z": 6,
   "name": "Rock_Stone"
  },
  {
   "x": -6,
   "y": 5,
   "z": 6,
   "name": "Rock_Stone"
  },
  {
   "x": -6,
   "y": 6,
   "z": 6,
   "name": "Rock_Stone"
  },
  {
   "x": -6,
   "y": 7,
   "z": 6,
   "name": "Rock_Stone"
  },
  {
   "x": -6,
   "y": 8,
   "z": 6,
   "name": "Rock_Stone"
  },
  {
   "x": -6,
   "y": 9,
   "z": 6,
   "name": "Rock_Stone"
  },
  {
   "x": -6,
   "y": 10,
   "z": 6,
   "name": "Rock_Stone"
  },
  {
   "x": -6,
   "y": 11,
   "z": 6,
   "name": "Rock_Stone"
  },
  {
   "x": -6,
   "y": 12,
   "z": 6,
   "name": "Rock_Stone"
  },
  {
   "x": -6,
   "y": 13,
   "z": 6,
   "name": "Rock_Stone"
  },
  {
   "x": -6,
   "y": 14,
   "z": 6,
   "name": "Rock_Stone"
  },
  {
   "x": -6,
   "y": 15,
   "z": 6,
   "name": "Rock_Stone"
  },
  {
   "x": -6,
   "y": 16,
   "z": 6,
   "name": "Rock_Stone"
  },
  {
   "x": -6,
   "y": 17,
   "z": 6,
   "name": "Rock_Stone"
  },
  {
   "x": -6,
   "y": 18,
   "z": 6,
   "name": "Rock_Stone"
  },
  {
   "x": -6,
   "y": 19,
   "z": 6,
   "name": "Rock_Stone"
  },
  {
   "x": -6,
   "y": 20,
   "z": 6,
   "name": "Rock_Stone_Brick_Smooth"
  },
  {
   "x": -6,
   "y": 21,
   "z": 6,
   "name": "Rock_Stone_Brick_Smooth"
  },
  {
   "x": -6,
   "y": 22,
   "z": 6,
   "name": "Rock_Stone_Brick_Smooth"
  },
  {
   "x": -6,
   "y": 23,
   "z": 6,
   "name": "Rock_Stone"
  },
  {
   "x": -6,
   "y": 24,
   "z": 6,
   "name": "Rock_Stone"
  },
  {
   "x": -6,
   "y": 25,
   "z": 6,
   "name": "Rock_Stone"
  },
  {
   "x": -6,
   "y": 26,
   "z": 6,
   "name": "Rock_Stone"
  },
  {
   "x": -6,
   "y": 27,
   "z": 6,
   "name": "Rock_Stone"
  },
  {
   "x": -6,
   "y": 28,
   "z": 6,
   "name": "Rock_Stone"
  },
  {
   "x": -6,
   "y": 29,
   "z": 6,
   "name": "Rock_Stone"
  },
  {
   "x": -6,
   "y": 30,
   "z": 6,
   "name": "Rock_Stone"
  },
  {
   "x": -6,
   "y": 31,
   "z": 6,
   "name": "Rock_Stone"
  },
  {
   "x": -6,
   "y": 32,
   "z": 6,
   "name": "Rock_Stone"
  },
  {
   "x": -6,
   "y": 33,
   "z": 6,
   "name": "Rock_Stone"
  },
  {
   "x": -6,
   "y": 34,
   "z": 6,
   "name": "Rock_Stone"
  },
  {
   "x": -6,
   "y": 35,
   "z": 6,
   "name": "Rock_Stone"
  },
  {
   "x": -6,
   "y": 36,
   "z": 6,
   "name": "Rock_Stone"
  },
  {
   "x": -6,
   "y": 0,
   "z": 7,
   "name": "Rock_Stone"
  },
  {
   "x": -6,
   "y": 1,
   "z": 7,
   "name": "Rock_Stone"
  },
  {
   "x": -6,
   "y": 2,
   "z": 7,
   "name": "Rock_Stone"
  },
  {
   "x": -6,
   "y": 3,
   "z": 7,
   "name": "Rock_Stone"
  },
  {
   "x": -6,
   "y": 4,
   "z": 7,
   "name": "Rock_Stone"
  },
  {
   "x": -6,
   "y": 5,
   "z": 7,
   "name": "Rock_Stone"
  },
  {
   "x": -6,
   "y": 6,
   "z": 7,
   "name": "Rock_Stone"
  },
  {
   "x": -6,
   "y": 7,
   "z": 7,
   "name": "Rock_Stone"
  },
  {
   "x": -6,
   "y": 8,
   "z": 7,
   "name": "Rock_Stone"
  },
  {
   "x": -6,
   "y": 9,
   "z": 7,
   "name": "Rock_Stone"
  },
  {
   "x": -6,
   "y": 10,
   "z": 7,
   "name": "Rock_Stone"
  },
  {
   "x": -6,
   "y": 11,
   "z": 7,
   "name": "Rock_Stone"
  },
  {
   "x": -6,
   "y": 12,
   "z": 7,
   "name": "Rock_Stone"
  },
  {
   "x": -6,
   "y": 13,
   "z": 7,
   "name": "Rock_Stone"
  },
  {
   "x": -6,
   "y": 14,
   "z": 7,
   "name": "Rock_Stone"
  },
  {
   "x": -6,
   "y": 15,
   "z": 7,
   "name": "Rock_Stone"
  },
  {
   "x": -6,
   "y": 16,
   "z": 7,
   "name": "Rock_Stone"
  },
  {
   "x": -6,
   "y": 17,
   "z": 7,
   "name": "Rock_Stone"
  },
  {
   "x": -6,
   "y": 18,
   "z": 7,
   "name": "Rock_Stone"
  },
  {
   "x": -6,
   "y": 19,
   "z": 7,
   "name": "Rock_Stone"
  },
  {
   "x": -6,
   "y": 20,
   "z": 7,
   "name": "Rock_Stone"
  },
  {
   "x": -6,
   "y": 21,
   "z": 7,
   "name": "Rock_Stone"
  },
  {
   "x": -6,
   "y": 22,
   "z": 7,
   "name": "Rock_Stone"
  },
  {
   "x": -6,
   "y": 23,
   "z": 7,
   "name": "Rock_Stone"
  },
  {
   "x": -6,
   "y": 24,
   "z": 7,
   "name": "Rock_Stone"
  },
  {
   "x": -6,
   "y": 25,
   "z": 7,
   "name": "Rock_Stone"
  },
  {
   "x": -6,
   "y": 26,
   "z": 7,
   "name": "Rock_Stone"
  },
  {
   "x": -6,
   "y": 27,
   "z": 7,
   "name": "Rock_Stone"
  },
  {
   "x": -6,
   "y": 28,
   "z": 7,
   "name": "Rock_Stone"
  },
  {
   "x": -6,
   "y": 29,
   "z": 7,
   "name": "Rock_Stone"
  },
  {
   "x": -6,
   "y": 30,
   "z": 7,
   "name": "Rock_Stone"
  },
  {
   "x": -6,
   "y": 31,
   "z": 7,
   "name": "Rock_Stone"
  },
  {
   "x": -6,
   "y": 32,
   "z": 7,
   "name": "Rock_Stone"
  },
  {
   "x": -6,
   "y": 33,
   "z": 7,
   "name": "Rock_Stone"
  },
  {
   "x": -6,
   "y": 34,
   "z": 7,
   "name": "Rock_Stone"
  },
  {
   "x": -6,
   "y": 35,
   "z": 7,
   "name": "Rock_Stone"
  },
  {
   "x": -6,
   "y": 36,
   "z": 7,
   "name": "Rock_Stone"
  },
  {
   "x": -6,
   "y": 0,
   "z": 8,
   "name": "Rock_Stone"
  },
  {
   "x": -6,
   "y": 1,
   "z": 8,
   "name": "Rock_Stone"
  },
  {
   "x": -6,
   "y": 2,
   "z": 8,
   "name": "Rock_Stone"
  },
  {
   "x": -6,
   "y": 3,
   "z": 8,
   "name": "Rock_Stone"
  },
  {
   "x": -6,
   "y": 4,
   "z": 8,
   "name": "Rock_Stone"
  },
  {
   "x": -6,
   "y": 5,
   "z": 8,
   "name": "Rock_Stone"
  },
  {
   "x": -6,
   "y": 6,
   "z": 8,
   "name": "Rock_Stone"
  },
  {
   "x": -6,
   "y": 7,
   "z": 8,
   "name": "Rock_Stone"
  },
  {
   "x": -6,
   "y": 8,
   "z": 8,
   "name": "Rock_Stone"
  },
  {
   "x": -6,
   "y": 9,
   "z": 8,
   "name": "Rock_Stone"
  },
  {
   "x": -6,
   "y": 10,
   "z": 8,
   "name": "Rock_Stone"
  },
  {
   "x": -6,
   "y": 11,
   "z": 8,
   "name": "Rock_Stone"
  },
  {
   "x": -6,
   "y": 12,
   "z": 8,
   "name": "Rock_Stone"
  },
  {
   "x": -6,
   "y": 13,
   "z": 8,
   "name": "Rock_Stone"
  },
  {
   "x": -6,
   "y": 14,
   "z": 8,
   "name": "Rock_Stone"
  },
  {
   "x": -6,
   "y": 15,
   "z": 8,
   "name": "Rock_Stone"
  },
  {
   "x": -6,
   "y": 16,
   "z": 8,
   "name": "Rock_Stone"
  },
  {
   "x": -6,
   "y": 17,
   "z": 8,
   "name": "Rock_Stone"
  },
  {
   "x": -6,
   "y": 18,
   "z": 8,
   "name": "Rock_Stone"
  },
  {
   "x": -6,
   "y": 19,
   "z": 8,
   "name": "Rock_Stone"
  },
  {
   "x": -6,
   "y": 20,
   "z": 8,
   "name": "Rock_Stone"
  },
  {
   "x": -6,
   "y": 21,
   "z": 8,
   "name": "Rock_Stone"
  },
  {
   "x": -6,
   "y": 22,
   "z": 8,
   "name": "Rock_Stone"
  },
  {
   "x": -6,
   "y": 23,
   "z": 8,
   "name": "Rock_Stone"
  },
  {
   "x": -6,
   "y": 24,
   "z": 8,
   "name": "Rock_Stone"
  },
  {
   "x": -6,
   "y": 25,
   "z": 8,
   "name": "Rock_Stone"
  },
  {
   "x": -6,
   "y": 26,
   "z": 8,
   "name": "Rock_Stone"
  },
  {
   "x": -6,
   "y": 27,
   "z": 8,
   "name": "Rock_Stone"
  },
  {
   "x": -6,
   "y": 28,
   "z": 8,
   "name": "Rock_Stone"
  },
  {
   "x": -6,
   "y": 29,
   "z": 8,
   "name": "Rock_Stone"
  },
  {
   "x": -6,
   "y": 30,
   "z": 8,
   "name": "Rock_Stone"
  },
  {
   "x": -6,
   "y": 31,
   "z": 8,
   "name": "Rock_Stone"
  },
  {
   "x": -6,
   "y": 32,
   "z": 8,
   "name": "Rock_Stone"
  },
  {
   "x": -6,
   "y": 33,
   "z": 8,
   "name": "Rock_Stone"
  },
  {
   "x": -6,
   "y": 34,
   "z": 8,
   "name": "Rock_Stone"
  },
  {
   "x": -6,
   "y": 35,
   "z": 8,
   "name": "Rock_Stone"
  },
  {
   "x": -6,
   "y": 36,
   "z": 8,
   "name": "Rock_Stone"
  },
  {
   "x": -5,
   "y": 0,
   "z": -9,
   "name": "Rock_Stone"
  },
  {
   "x": -5,
   "y": 1,
   "z": -9,
   "name": "Rock_Stone"
  },
  {
   "x": -5,
   "y": 2,
   "z": -9,
   "name": "Rock_Stone"
  },
  {
   "x": -5,
   "y": 3,
   "z": -9,
   "name": "Rock_Stone"
  },
  {
   "x": -5,
   "y": 4,
   "z": -9,
   "name": "Rock_Stone"
  },
  {
   "x": -5,
   "y": 5,
   "z": -9,
   "name": "Rock_Stone"
  },
  {
   "x": -5,
   "y": 6,
   "z": -9,
   "name": "Rock_Stone"
  },
  {
   "x": -5,
   "y": 7,
   "z": -9,
   "name": "Rock_Stone"
  },
  {
   "x": -5,
   "y": 8,
   "z": -9,
   "name": "Rock_Stone"
  },
  {
   "x": -5,
   "y": 9,
   "z": -9,
   "name": "Rock_Stone"
  },
  {
   "x": -5,
   "y": 10,
   "z": -9,
   "name": "Rock_Stone"
  },
  {
   "x": -5,
   "y": 11,
   "z": -9,
   "name": "Rock_Stone"
  },
  {
   "x": -5,
   "y": 12,
   "z": -9,
   "name": "Rock_Stone"
  },
  {
   "x": -5,
   "y": 13,
   "z": -9,
   "name": "Rock_Stone"
  },
  {
   "x": -5,
   "y": 0,
   "z": -8,
   "name": "Rock_Stone"
  },
  {
   "x": -5,
   "y": 1,
   "z": -8,
   "name": "Rock_Stone"
  },
  {
   "x": -5,
   "y": 2,
   "z": -8,
   "name": "Rock_Stone"
  },
  {
   "x": -5,
   "y": 3,
   "z": -8,
   "name": "Rock_Stone"
  },
  {
   "x": -5,
   "y": 4,
   "z": -8,
   "name": "Rock_Stone"
  },
  {
   "x": -5,
   "y": 5,
   "z": -8,
   "name": "Rock_Stone"
  },
  {
   "x": -5,
   "y": 6,
   "z": -8,
   "name": "Rock_Stone"
  },
  {
   "x": -5,
   "y": 7,
   "z": -8,
   "name": "Rock_Stone"
  },
  {
   "x": -5,
   "y": 8,
   "z": -8,
   "name": "Rock_Stone"
  },
  {
   "x": -5,
   "y": 9,
   "z": -8,
   "name": "Rock_Stone"
  },
  {
   "x": -5,
   "y": 10,
   "z": -8,
   "name": "Rock_Stone"
  },
  {
   "x": -5,
   "y": 11,
   "z": -8,
   "name": "Rock_Stone"
  },
  {
   "x": -5,
   "y": 12,
   "z": -8,
   "name": "Rock_Stone"
  },
  {
   "x": -5,
   "y": 13,
   "z": -8,
   "name": "Rock_Stone"
  },
  {
   "x": -5,
   "y": 0,
   "z": -7,
   "name": "Rock_Stone"
  },
  {
   "x": -5,
   "y": 1,
   "z": -7,
   "name": "Rock_Stone"
  },
  {
   "x": -5,
   "y": 2,
   "z": -7,
   "name": "Rock_Stone"
  },
  {
   "x": -5,
   "y": 3,
   "z": -7,
   "name": "Rock_Stone"
  },
  {
   "x": -5,
   "y": 4,
   "z": -7,
   "name": "Rock_Stone"
  },
  {
   "x": -5,
   "y": 5,
   "z": -7,
   "name": "Rock_Stone"
  },
  {
   "x": -5,
   "y": 6,
   "z": -7,
   "name": "Rock_Stone"
  },
  {
   "x": -5,
   "y": 7,
   "z": -7,
   "name": "Rock_Stone"
  },
  {
   "x": -5,
   "y": 8,
   "z": -7,
   "name": "Rock_Stone"
  },
  {
   "x": -5,
   "y": 9,
   "z": -7,
   "name": "Rock_Stone"
  },
  {
   "x": -5,
   "y": 10,
   "z": -7,
   "name": "Rock_Stone"
  },
  {
   "x": -5,
   "y": 11,
   "z": -7,
   "name": "Rock_Stone"
  },
  {
   "x": -5,
   "y": 12,
   "z": -7,
   "name": "Rock_Stone"
  },
  {
   "x": -5,
   "y": 13,
   "z": -7,
   "name": "Rock_Stone"
  },
  {
   "x": -5,
   "y": 21,
   "z": -7,
   "name": "Rock_Stone"
  },
  {
   "x": -5,
   "y": 22,
   "z": -7,
   "name": "Rock_Stone"
  },
  {
   "x": -5,
   "y": 23,
   "z": -7,
   "name": "Rock_Stone"
  },
  {
   "x": -5,
   "y": 24,
   "z": -7,
   "name": "Rock_Stone"
  },
  {
   "x": -5,
   "y": 25,
   "z": -7,
   "name": "Rock_Stone"
  },
  {
   "x": -5,
   "y": 26,
   "z": -7,
   "name": "Rock_Stone"
  },
  {
   "x": -5,
   "y": 27,
   "z": -7,
   "name": "Rock_Stone"
  },
  {
   "x": -5,
   "y": 28,
   "z": -7,
   "name": "Rock_Stone"
  },
  {
   "x": -5,
   "y": 29,
   "z": -7,
   "name": "Rock_Stone"
  },
  {
   "x": -5,
   "y": 30,
   "z": -7,
   "name": "Rock_Stone"
  },
  {
   "x": -5,
   "y": 31,
   "z": -7,
   "name": "Rock_Stone"
  },
  {
   "x": -5,
   "y": 32,
   "z": -7,
   "name": "Rock_Stone"
  },
  {
   "x": -5,
   "y": 33,
   "z": -7,
   "name": "Rock_Stone"
  },
  {
   "x": -5,
   "y": 34,
   "z": -7,
   "name": "Rock_Stone"
  },
  {
   "x": -5,
   "y": 35,
   "z": -7,
   "name": "Rock_Stone"
  },
  {
   "x": -5,
   "y": 36,
   "z": -7,
   "name": "Rock_Stone"
  },
  {
   "x": -5,
   "y": 0,
   "z": -6,
   "name": "Rock_Stone"
  },
  {
   "x": -5,
   "y": 1,
   "z": -6,
   "name": "Rock_Stone"
  },
  {
   "x": -5,
   "y": 2,
   "z": -6,
   "name": "Rock_Stone"
  },
  {
   "x": -5,
   "y": 3,
   "z": -6,
   "name": "Rock_Stone"
  },
  {
   "x": -5,
   "y": 4,
   "z": -6,
   "name": "Rock_Stone"
  },
  {
   "x": -5,
   "y": 5,
   "z": -6,
   "name": "Rock_Stone"
  },
  {
   "x": -5,
   "y": 6,
   "z": -6,
   "name": "Rock_Stone"
  },
  {
   "x": -5,
   "y": 7,
   "z": -6,
   "name": "Rock_Stone"
  },
  {
   "x": -5,
   "y": 8,
   "z": -6,
   "name": "Rock_Stone"
  },
  {
   "x": -5,
   "y": 9,
   "z": -6,
   "name": "Rock_Stone"
  },
  {
   "x": -5,
   "y": 10,
   "z": -6,
   "name": "Rock_Stone"
  },
  {
   "x": -5,
   "y": 11,
   "z": -6,
   "name": "Rock_Stone"
  },
  {
   "x": -5,
   "y": 12,
   "z": -6,
   "name": "Rock_Stone"
  },
  {
   "x": -5,
   "y": 13,
   "z": -6,
   "name": "Rock_Stone"
  },
  {
   "x": -5,
   "y": 21,
   "z": -6,
   "name": "Rock_Stone"
  },
  {
   "x": -5,
   "y": 22,
   "z": -6,
   "name": "Rock_Stone"
  },
  {
   "x": -5,
   "y": 23,
   "z": -6,
   "name": "Rock_Stone"
  },
  {
   "x": -5,
   "y": 24,
   "z": -6,
   "name": "Rock_Stone"
  },
  {
   "x": -5,
   "y": 25,
   "z": -6,
   "name": "Rock_Stone"
  },
  {
   "x": -5,
   "y": 26,
   "z": -6,
   "name": "Rock_Stone"
  },
  {
   "x": -5,
   "y": 27,
   "z": -6,
   "name": "Rock_Stone"
  },
  {
   "x": -5,
   "y": 28,
   "z": -6,
   "name": "Rock_Stone"
  },
  {
   "x": -5,
   "y": 29,
   "z": -6,
   "name": "Rock_Stone"
  },
  {
   "x": -5,
   "y": 30,
   "z": -6,
   "name": "Rock_Stone"
  },
  {
   "x": -5,
   "y": 31,
   "z": -6,
   "name": "Rock_Stone"
  },
  {
   "x": -5,
   "y": 32,
   "z": -6,
   "name": "Rock_Stone"
  },
  {
   "x": -5,
   "y": 33,
   "z": -6,
   "name": "Rock_Stone"
  },
  {
   "x": -5,
   "y": 34,
   "z": -6,
   "name": "Rock_Stone"
  },
  {
   "x": -5,
   "y": 35,
   "z": -6,
   "name": "Rock_Stone"
  },
  {
   "x": -5,
   "y": 36,
   "z": -6,
   "name": "Rock_Stone"
  },
  {
   "x": -5,
   "y": 0,
   "z": -5,
   "name": "Rock_Stone"
  },
  {
   "x": -5,
   "y": 1,
   "z": -5,
   "name": "Rock_Stone"
  },
  {
   "x": -5,
   "y": 2,
   "z": -5,
   "name": "Rock_Stone"
  },
  {
   "x": -5,
   "y": 3,
   "z": -5,
   "name": "Rock_Stone"
  },
  {
   "x": -5,
   "y": 4,
   "z": -5,
   "name": "Rock_Stone"
  },
  {
   "x": -5,
   "y": 5,
   "z": -5,
   "name": "Rock_Stone"
  },
  {
   "x": -5,
   "y": 6,
   "z": -5,
   "name": "Rock_Stone"
  },
  {
   "x": -5,
   "y": 7,
   "z": -5,
   "name": "Rock_Stone"
  },
  {
   "x": -5,
   "y": 8,
   "z": -5,
   "name": "Rock_Stone"
  },
  {
   "x": -5,
   "y": 9,
   "z": -5,
   "name": "Rock_Stone"
  },
  {
   "x": -5,
   "y": 10,
   "z": -5,
   "name": "Rock_Stone"
  },
  {
   "x": -5,
   "y": 11,
   "z": -5,
   "name": "Rock_Stone"
  },
  {
   "x": -5,
   "y": 12,
   "z": -5,
   "name": "Rock_Stone"
  },
  {
   "x": -5,
   "y": 13,
   "z": -5,
   "name": "Rock_Stone"
  },
  {
   "x": -5,
   "y": 21,
   "z": -5,
   "name": "Rock_Stone"
  },
  {
   "x": -5,
   "y": 22,
   "z": -5,
   "name": "Rock_Stone"
  },
  {
   "x": -5,
   "y": 23,
   "z": -5,
   "name": "Rock_Stone"
  },
  {
   "x": -5,
   "y": 24,
   "z": -5,
   "name": "Rock_Stone"
  },
  {
   "x": -5,
   "y": 25,
   "z": -5,
   "name": "Rock_Stone"
  },
  {
   "x": -5,
   "y": 26,
   "z": -5,
   "name": "Empty"
  },
  {
   "x": -5,
   "y": 27,
   "z": -5,
   "name": "Rock_Stone"
  },
  {
   "x": -5,
   "y": 28,
   "z": -5,
   "name": "Rock_Stone"
  },
  {
   "x": -5,
   "y": 29,
   "z": -5,
   "name": "Rock_Stone"
  },
  {
   "x": -5,
   "y": 30,
   "z": -5,
   "name": "Rock_Stone"
  },
  {
   "x": -5,
   "y": 31,
   "z": -5,
   "name": "Rock_Stone"
  },
  {
   "x": -5,
   "y": 32,
   "z": -5,
   "name": "Rock_Stone"
  },
  {
   "x": -5,
   "y": 33,
   "z": -5,
   "name": "Rock_Stone"
  },
  {
   "x": -5,
   "y": 34,
   "z": -5,
   "name": "Rock_Stone"
  },
  {
   "x": -5,
   "y": 35,
   "z": -5,
   "name": "Rock_Stone"
  },
  {
   "x": -5,
   "y": 36,
   "z": -5,
   "name": "Rock_Stone"
  },
  {
   "x": -5,
   "y": 0,
   "z": -4,
   "name": "Rock_Stone"
  },
  {
   "x": -5,
   "y": 1,
   "z": -4,
   "name": "Rock_Stone"
  },
  {
   "x": -5,
   "y": 2,
   "z": -4,
   "name": "Rock_Stone"
  },
  {
   "x": -5,
   "y": 3,
   "z": -4,
   "name": "Rock_Stone"
  },
  {
   "x": -5,
   "y": 4,
   "z": -4,
   "name": "Rock_Stone"
  },
  {
   "x": -5,
   "y": 5,
   "z": -4,
   "name": "Rock_Stone"
  },
  {
   "x": -5,
   "y": 6,
   "z": -4,
   "name": "Rock_Stone"
  },
  {
   "x": -5,
   "y": 7,
   "z": -4,
   "name": "Rock_Stone"
  },
  {
   "x": -5,
   "y": 8,
   "z": -4,
   "name": "Rock_Stone"
  },
  {
   "x": -5,
   "y": 9,
   "z": -4,
   "name": "Rock_Stone"
  },
  {
   "x": -5,
   "y": 10,
   "z": -4,
   "name": "Rock_Stone"
  },
  {
   "x": -5,
   "y": 11,
   "z": -4,
   "name": "Rock_Stone"
  },
  {
   "x": -5,
   "y": 12,
   "z": -4,
   "name": "Rock_Stone"
  },
  {
   "x": -5,
   "y": 13,
   "z": -4,
   "name": "Rock_Stone"
  },
  {
   "x": -5,
   "y": 14,
   "z": -4,
   "name": "Rock_Stone"
  },
  {
   "x": -5,
   "y": 15,
   "z": -4,
   "name": "Rock_Stone"
  },
  {
   "x": -5,
   "y": 16,
   "z": -4,
   "name": "Rock_Stone"
  },
  {
   "x": -5,
   "y": 17,
   "z": -4,
   "name": "Rock_Stone"
  },
  {
   "x": -5,
   "y": 18,
   "z": -4,
   "name": "Rock_Stone"
  },
  {
   "x": -5,
   "y": 19,
   "z": -4,
   "name": "Rock_Stone"
  },
  {
   "x": -5,
   "y": 20,
   "z": -4,
   "name": "Rock_Stone"
  },
  {
   "x": -5,
   "y": 21,
   "z": -4,
   "name": "Rock_Stone"
  },
  {
   "x": -5,
   "y": 22,
   "z": -4,
   "name": "Rock_Stone"
  },
  {
   "x": -5,
   "y": 23,
   "z": -4,
   "name": "Rock_Stone"
  },
  {
   "x": -5,
   "y": 24,
   "z": -4,
   "name": "Rock_Stone"
  },
  {
   "x": -5,
   "y": 25,
   "z": -4,
   "name": "Empty"
  },
  {
   "x": -5,
   "y": 26,
   "z": -4,
   "name": "Empty"
  },
  {
   "x": -5,
   "y": 27,
   "z": -4,
   "name": "Empty"
  },
  {
   "x": -5,
   "y": 28,
   "z": -4,
   "name": "Rock_Stone"
  },
  {
   "x": -5,
   "y": 29,
   "z": -4,
   "name": "Rock_Stone"
  },
  {
   "x": -5,
   "y": 30,
   "z": -4,
   "name": "Rock_Stone"
  },
  {
   "x": -5,
   "y": 31,
   "z": -4,
   "name": "Rock_Stone"
  },
  {
   "x": -5,
   "y": 32,
   "z": -4,
   "name": "Rock_Stone"
  },
  {
   "x": -5,
   "y": 33,
   "z": -4,
   "name": "Rock_Stone"
  },
  {
   "x": -5,
   "y": 34,
   "z": -4,
   "name": "Rock_Stone"
  },
  {
   "x": -5,
   "y": 35,
   "z": -4,
   "name": "Rock_Stone"
  },
  {
   "x": -5,
   "y": 36,
   "z": -4,
   "name": "Rock_Basalt_Brick"
  },
  {
   "x": -5,
   "y": 0,
   "z": -3,
   "name": "Rock_Stone"
  },
  {
   "x": -5,
   "y": 1,
   "z": -3,
   "name": "Rock_Stone"
  },
  {
   "x": -5,
   "y": 2,
   "z": -3,
   "name": "Rock_Stone"
  },
  {
   "x": -5,
   "y": 3,
   "z": -3,
   "name": "Rock_Stone"
  },
  {
   "x": -5,
   "y": 4,
   "z": -3,
   "name": "Rock_Stone"
  },
  {
   "x": -5,
   "y": 5,
   "z": -3,
   "name": "Rock_Stone"
  },
  {
   "x": -5,
   "y": 6,
   "z": -3,
   "name": "Rock_Stone"
  },
  {
   "x": -5,
   "y": 7,
   "z": -3,
   "name": "Rock_Stone"
  },
  {
   "x": -5,
   "y": 8,
   "z": -3,
   "name": "Rock_Stone"
  },
  {
   "x": -5,
   "y": 9,
   "z": -3,
   "name": "Rock_Stone"
  },
  {
   "x": -5,
   "y": 10,
   "z": -3,
   "name": "Rock_Stone"
  },
  {
   "x": -5,
   "y": 11,
   "z": -3,
   "name": "Rock_Stone"
  },
  {
   "x": -5,
   "y": 12,
   "z": -3,
   "name": "Rock_Stone"
  },
  {
   "x": -5,
   "y": 13,
   "z": -3,
   "name": "Rock_Stone"
  },
  {
   "x": -5,
   "y": 14,
   "z": -3,
   "name": "Rock_Stone"
  },
  {
   "x": -5,
   "y": 15,
   "z": -3,
   "name": "Rock_Stone"
  },
  {
   "x": -5,
   "y": 16,
   "z": -3,
   "name": "Rock_Stone"
  },
  {
   "x": -5,
   "y": 17,
   "z": -3,
   "name": "Rock_Stone"
  },
  {
   "x": -5,
   "y": 18,
   "z": -3,
   "name": "Rock_Stone"
  },
  {
   "x": -5,
   "y": 19,
   "z": -3,
   "name": "Rock_Stone"
  },
  {
   "x": -5,
   "y": 20,
   "z": -3,
   "name": "Rock_Stone"
  },
  {
   "x": -5,
   "y": 21,
   "z": -3,
   "name": "Rock_Stone"
  },
  {
   "x": -5,
   "y": 22,
   "z": -3,
   "name": "Rock_Stone"
  },
  {
   "x": -5,
   "y": 23,
   "z": -3,
   "name": "Rock_Stone_Brick"
  },
  {
   "x": -5,
   "y": 24,
   "z": -3,
   "name": "Rock_Stone_Brick_Stairs"
  },
  {
   "x": -5,
   "y": 25,
   "z": -3,
   "name": "Empty"
  },
  {
   "x": -5,
   "y": 26,
   "z": -3,
   "name": "Empty"
  },
  {
   "x": -5,
   "y": 27,
   "z": -3,
   "name": "Empty"
  },
  {
   "x": -5,
   "y": 28,
   "z": -3,
   "name": "Empty"
  },
  {
   "x": -5,
   "y": 29,
   "z": -3,
   "name": "Rock_Stone"
  },
  {
   "x": -5,
   "y": 30,
   "z": -3,
   "name": "Rock_Stone"
  },
  {
   "x": -5,
   "y": 31,
   "z": -3,
   "name": "Rock_Stone"
  },
  {
   "x": -5,
   "y": 32,
   "z": -3,
   "name": "Rock_Stone"
  },
  {
   "x": -5,
   "y": 33,
   "z": -3,
   "name": "Rock_Stone"
  },
  {
   "x": -5,
   "y": 34,
   "z": -3,
   "name": "Rock_Stone"
  },
  {
   "x": -5,
   "y": 35,
   "z": -3,
   "name": "Rock_Basalt_Brick"
  },
  {
   "x": -5,
   "y": 36,
   "z": -3,
   "name": "KweebecNightmare_Moonbloom_Plant"
  },
  {
   "x": -5,
   "y": 0,
   "z": -2,
   "name": "Rock_Stone"
  },
  {
   "x": -5,
   "y": 1,
   "z": -2,
   "name": "Rock_Stone"
  },
  {
   "x": -5,
   "y": 2,
   "z": -2,
   "name": "Rock_Stone"
  },
  {
   "x": -5,
   "y": 3,
   "z": -2,
   "name": "Rock_Stone"
  },
  {
   "x": -5,
   "y": 4,
   "z": -2,
   "name": "Rock_Stone"
  },
  {
   "x": -5,
   "y": 5,
   "z": -2,
   "name": "Rock_Stone"
  },
  {
   "x": -5,
   "y": 6,
   "z": -2,
   "name": "Rock_Stone"
  },
  {
   "x": -5,
   "y": 7,
   "z": -2,
   "name": "Rock_Stone"
  },
  {
   "x": -5,
   "y": 8,
   "z": -2,
   "name": "Rock_Stone"
  },
  {
   "x": -5,
   "y": 9,
   "z": -2,
   "name": "Rock_Stone"
  },
  {
   "x": -5,
   "y": 10,
   "z": -2,
   "name": "Rock_Stone"
  },
  {
   "x": -5,
   "y": 11,
   "z": -2,
   "name": "Rock_Stone"
  },
  {
   "x": -5,
   "y": 12,
   "z": -2,
   "name": "Rock_Stone"
  },
  {
   "x": -5,
   "y": 13,
   "z": -2,
   "name": "Rock_Stone"
  },
  {
   "x": -5,
   "y": 14,
   "z": -2,
   "name": "Rock_Stone"
  },
  {
   "x": -5,
   "y": 15,
   "z": -2,
   "name": "Rock_Stone"
  },
  {
   "x": -5,
   "y": 16,
   "z": -2,
   "name": "Rock_Stone"
  },
  {
   "x": -5,
   "y": 17,
   "z": -2,
   "name": "Rock_Stone"
  },
  {
   "x": -5,
   "y": 18,
   "z": -2,
   "name": "Rock_Stone"
  },
  {
   "x": -5,
   "y": 19,
   "z": -2,
   "name": "Rock_Stone"
  },
  {
   "x": -5,
   "y": 20,
   "z": -2,
   "name": "Rock_Stone"
  },
  {
   "x": -5,
   "y": 21,
   "z": -2,
   "name": "Rock_Stone"
  },
  {
   "x": -5,
   "y": 22,
   "z": -2,
   "name": "Rock_Stone_Brick"
  },
  {
   "x": -5,
   "y": 23,
   "z": -2,
   "name": "Rock_Stone_Brick_Stairs"
  },
  {
   "x": -5,
   "y": 24,
   "z": -2,
   "name": "Empty"
  },
  {
   "x": -5,
   "y": 25,
   "z": -2,
   "name": "Empty"
  },
  {
   "x": -5,
   "y": 26,
   "z": -2,
   "name": "Empty"
  },
  {
   "x": -5,
   "y": 27,
   "z": -2,
   "name": "Empty"
  },
  {
   "x": -5,
   "y": 28,
   "z": -2,
   "name": "Empty"
  },
  {
   "x": -5,
   "y": 29,
   "z": -2,
   "name": "Rock_Stone"
  },
  {
   "x": -5,
   "y": 30,
   "z": -2,
   "name": "Rock_Stone"
  },
  {
   "x": -5,
   "y": 31,
   "z": -2,
   "name": "Rock_Stone"
  },
  {
   "x": -5,
   "y": 32,
   "z": -2,
   "name": "Rock_Stone"
  },
  {
   "x": -5,
   "y": 33,
   "z": -2,
   "name": "Rock_Stone"
  },
  {
   "x": -5,
   "y": 34,
   "z": -2,
   "name": "Rock_Basalt_Brick"
  },
  {
   "x": -5,
   "y": 35,
   "z": -2,
   "name": "Rock_Basalt_Brick_Half",
   "rotation": 4
  },
  {
   "x": -5,
   "y": 36,
   "z": -2,
   "name": "Empty"
  },
  {
   "x": -5,
   "y": 0,
   "z": -1,
   "name": "Rock_Stone"
  },
  {
   "x": -5,
   "y": 1,
   "z": -1,
   "name": "Rock_Stone"
  },
  {
   "x": -5,
   "y": 2,
   "z": -1,
   "name": "Rock_Stone"
  },
  {
   "x": -5,
   "y": 3,
   "z": -1,
   "name": "Rock_Stone"
  },
  {
   "x": -5,
   "y": 4,
   "z": -1,
   "name": "Rock_Stone"
  },
  {
   "x": -5,
   "y": 5,
   "z": -1,
   "name": "Rock_Stone"
  },
  {
   "x": -5,
   "y": 6,
   "z": -1,
   "name": "Rock_Stone"
  },
  {
   "x": -5,
   "y": 7,
   "z": -1,
   "name": "Rock_Stone"
  },
  {
   "x": -5,
   "y": 8,
   "z": -1,
   "name": "Rock_Stone"
  },
  {
   "x": -5,
   "y": 9,
   "z": -1,
   "name": "Rock_Stone"
  },
  {
   "x": -5,
   "y": 10,
   "z": -1,
   "name": "Rock_Stone"
  },
  {
   "x": -5,
   "y": 11,
   "z": -1,
   "name": "Rock_Stone"
  },
  {
   "x": -5,
   "y": 12,
   "z": -1,
   "name": "Rock_Stone_Brick_Smooth"
  },
  {
   "x": -5,
   "y": 13,
   "z": -1,
   "name": "Empty"
  },
  {
   "x": -5,
   "y": 14,
   "z": -1,
   "name": "Empty"
  },
  {
   "x": -5,
   "y": 15,
   "z": -1,
   "name": "Rock_Stone"
  },
  {
   "x": -5,
   "y": 16,
   "z": -1,
   "name": "Rock_Stone"
  },
  {
   "x": -5,
   "y": 17,
   "z": -1,
   "name": "Rock_Stone"
  },
  {
   "x": -5,
   "y": 18,
   "z": -1,
   "name": "Rock_Stone"
  },
  {
   "x": -5,
   "y": 19,
   "z": -1,
   "name": "Rock_Stone"
  },
  {
   "x": -5,
   "y": 20,
   "z": -1,
   "name": "Rock_Stone"
  },
  {
   "x": -5,
   "y": 21,
   "z": -1,
   "name": "Rock_Stone"
  },
  {
   "x": -5,
   "y": 22,
   "z": -1,
   "name": "Rock_Stone_Brick_Stairs"
  },
  {
   "x": -5,
   "y": 23,
   "z": -1,
   "name": "Empty"
  },
  {
   "x": -5,
   "y": 24,
   "z": -1,
   "name": "Empty"
  },
  {
   "x": -5,
   "y": 25,
   "z": -1,
   "name": "Empty"
  },
  {
   "x": -5,
   "y": 26,
   "z": -1,
   "name": "Empty"
  },
  {
   "x": -5,
   "y": 27,
   "z": -1,
   "name": "Empty"
  },
  {
   "x": -5,
   "y": 28,
   "z": -1,
   "name": "Empty"
  },
  {
   "x": -5,
   "y": 29,
   "z": -1,
   "name": "Rock_Stone"
  },
  {
   "x": -5,
   "y": 30,
   "z": -1,
   "name": "Rock_Stone"
  },
  {
   "x": -5,
   "y": 31,
   "z": -1,
   "name": "Rock_Stone"
  },
  {
   "x": -5,
   "y": 32,
   "z": -1,
   "name": "Rock_Stone"
  },
  {
   "x": -5,
   "y": 33,
   "z": -1,
   "name": "Rock_Stone"
  },
  {
   "x": -5,
   "y": 34,
   "z": -1,
   "name": "Rock_Basalt_Brick_Stairs"
  },
  {
   "x": -5,
   "y": 35,
   "z": -1,
   "name": "Empty"
  },
  {
   "x": -5,
   "y": 36,
   "z": -1,
   "name": "Empty"
  },
  {
   "x": -5,
   "y": 0,
   "z": 0,
   "name": "Rock_Stone"
  },
  {
   "x": -5,
   "y": 1,
   "z": 0,
   "name": "Rock_Stone"
  },
  {
   "x": -5,
   "y": 2,
   "z": 0,
   "name": "Rock_Stone"
  },
  {
   "x": -5,
   "y": 3,
   "z": 0,
   "name": "Rock_Stone"
  },
  {
   "x": -5,
   "y": 4,
   "z": 0,
   "name": "Rock_Stone"
  },
  {
   "x": -5,
   "y": 5,
   "z": 0,
   "name": "Rock_Stone"
  },
  {
   "x": -5,
   "y": 6,
   "z": 0,
   "name": "Rock_Stone"
  },
  {
   "x": -5,
   "y": 7,
   "z": 0,
   "name": "Rock_Stone"
  },
  {
   "x": -5,
   "y": 8,
   "z": 0,
   "name": "Rock_Stone"
  },
  {
   "x": -5,
   "y": 9,
   "z": 0,
   "name": "Rock_Stone"
  },
  {
   "x": -5,
   "y": 10,
   "z": 0,
   "name": "Rock_Stone"
  },
  {
   "x": -5,
   "y": 11,
   "z": 0,
   "name": "Rock_Stone"
  },
  {
   "x": -5,
   "y": 12,
   "z": 0,
   "name": "Rock_Stone_Brick_Smooth"
  },
  {
   "x": -5,
   "y": 13,
   "z": 0,
   "name": "Block_Spawner_Block",
   "components": {
    "Components": {
     "BlockSpawner": {
      "BlockSpawnerId": "Zone1_Encounters_Tier3"
     }
    }
   },
   "rotation": 1
  },
  {
   "x": -5,
   "y": 14,
   "z": 0,
   "name": "Empty"
  },
  {
   "x": -5,
   "y": 15,
   "z": 0,
   "name": "Rock_Stone"
  },
  {
   "x": -5,
   "y": 16,
   "z": 0,
   "name": "Rock_Stone"
  },
  {
   "x": -5,
   "y": 17,
   "z": 0,
   "name": "Rock_Stone"
  },
  {
   "x": -5,
   "y": 18,
   "z": 0,
   "name": "Rock_Stone"
  },
  {
   "x": -5,
   "y": 19,
   "z": 0,
   "name": "Rock_Stone"
  },
  {
   "x": -5,
   "y": 20,
   "z": 0,
   "name": "Rock_Stone"
  },
  {
   "x": -5,
   "y": 21,
   "z": 0,
   "name": "Rock_Stone_Brick_Stairs"
  },
  {
   "x": -5,
   "y": 22,
   "z": 0,
   "name": "Empty"
  },
  {
   "x": -5,
   "y": 23,
   "z": 0,
   "name": "Empty"
  },
  {
   "x": -5,
   "y": 24,
   "z": 0,
   "name": "Empty"
  },
  {
   "x": -5,
   "y": 25,
   "z": 0,
   "name": "Empty"
  },
  {
   "x": -5,
   "y": 26,
   "z": 0,
   "name": "Empty"
  },
  {
   "x": -5,
   "y": 27,
   "z": 0,
   "name": "Plant_Roots_Cave",
   "rotation": 8
  },
  {
   "x": -5,
   "y": 28,
   "z": 0,
   "name": "Rock_Stone"
  },
  {
   "x": -5,
   "y": 29,
   "z": 0,
   "name": "Rock_Stone"
  },
  {
   "x": -5,
   "y": 30,
   "z": 0,
   "name": "Rock_Stone"
  },
  {
   "x": -5,
   "y": 31,
   "z": 0,
   "name": "Rock_Stone"
  },
  {
   "x": -5,
   "y": 32,
   "z": 0,
   "name": "Rock_Basalt_Brick"
  },
  {
   "x": -5,
   "y": 33,
   "z": 0,
   "name": "Rock_Basalt_Brick_Stairs"
  },
  {
   "x": -5,
   "y": 34,
   "z": 0,
   "name": "Empty"
  },
  {
   "x": -5,
   "y": 35,
   "z": 0,
   "name": "Empty"
  },
  {
   "x": -5,
   "y": 36,
   "z": 0,
   "name": "Empty"
  },
  {
   "x": -5,
   "y": 0,
   "z": 1,
   "name": "Rock_Stone"
  },
  {
   "x": -5,
   "y": 1,
   "z": 1,
   "name": "Rock_Stone"
  },
  {
   "x": -5,
   "y": 2,
   "z": 1,
   "name": "Rock_Stone"
  },
  {
   "x": -5,
   "y": 3,
   "z": 1,
   "name": "Rock_Stone"
  },
  {
   "x": -5,
   "y": 4,
   "z": 1,
   "name": "Rock_Stone"
  },
  {
   "x": -5,
   "y": 5,
   "z": 1,
   "name": "Rock_Stone"
  },
  {
   "x": -5,
   "y": 6,
   "z": 1,
   "name": "Rock_Stone"
  },
  {
   "x": -5,
   "y": 7,
   "z": 1,
   "name": "Rock_Stone"
  },
  {
   "x": -5,
   "y": 8,
   "z": 1,
   "name": "Rock_Stone"
  },
  {
   "x": -5,
   "y": 9,
   "z": 1,
   "name": "Rock_Stone"
  },
  {
   "x": -5,
   "y": 10,
   "z": 1,
   "name": "Rock_Stone"
  },
  {
   "x": -5,
   "y": 11,
   "z": 1,
   "name": "Rock_Stone"
  },
  {
   "x": -5,
   "y": 12,
   "z": 1,
   "name": "Rock_Stone_Brick_Smooth"
  },
  {
   "x": -5,
   "y": 13,
   "z": 1,
   "name": "Plant_Flower_Orchid_Blue"
  },
  {
   "x": -5,
   "y": 14,
   "z": 1,
   "name": "Empty"
  },
  {
   "x": -5,
   "y": 15,
   "z": 1,
   "name": "Rock_Stone"
  },
  {
   "x": -5,
   "y": 16,
   "z": 1,
   "name": "Rock_Stone"
  },
  {
   "x": -5,
   "y": 17,
   "z": 1,
   "name": "Rock_Stone"
  },
  {
   "x": -5,
   "y": 18,
   "z": 1,
   "name": "Rock_Stone"
  },
  {
   "x": -5,
   "y": 19,
   "z": 1,
   "name": "Rock_Stone"
  },
  {
   "x": -5,
   "y": 20,
   "z": 1,
   "name": "Rock_Stone_Brick_Stairs"
  },
  {
   "x": -5,
   "y": 21,
   "z": 1,
   "name": "Empty"
  },
  {
   "x": -5,
   "y": 22,
   "z": 1,
   "name": "Empty"
  },
  {
   "x": -5,
   "y": 23,
   "z": 1,
   "name": "Empty"
  },
  {
   "x": -5,
   "y": 24,
   "z": 1,
   "name": "Empty"
  },
  {
   "x": -5,
   "y": 25,
   "z": 1,
   "name": "Empty"
  },
  {
   "x": -5,
   "y": 26,
   "z": 1,
   "name": "Empty"
  },
  {
   "x": -5,
   "y": 27,
   "z": 1,
   "name": "Rock_Stone"
  },
  {
   "x": -5,
   "y": 28,
   "z": 1,
   "name": "Rock_Stone"
  },
  {
   "x": -5,
   "y": 29,
   "z": 1,
   "name": "Rock_Stone"
  },
  {
   "x": -5,
   "y": 30,
   "z": 1,
   "name": "Rock_Stone"
  },
  {
   "x": -5,
   "y": 31,
   "z": 1,
   "name": "Rock_Stone"
  },
  {
   "x": -5,
   "y": 32,
   "z": 1,
   "name": "Rock_Basalt_Brick_Stairs"
  },
  {
   "x": -5,
   "y": 33,
   "z": 1,
   "name": "Empty"
  },
  {
   "x": -5,
   "y": 34,
   "z": 1,
   "name": "Empty"
  },
  {
   "x": -5,
   "y": 35,
   "z": 1,
   "name": "Empty"
  },
  {
   "x": -5,
   "y": 36,
   "z": 1,
   "name": "Empty"
  },
  {
   "x": -5,
   "y": 0,
   "z": 2,
   "name": "Rock_Stone"
  },
  {
   "x": -5,
   "y": 1,
   "z": 2,
   "name": "Rock_Stone"
  },
  {
   "x": -5,
   "y": 2,
   "z": 2,
   "name": "Rock_Stone"
  },
  {
   "x": -5,
   "y": 3,
   "z": 2,
   "name": "Rock_Stone"
  },
  {
   "x": -5,
   "y": 4,
   "z": 2,
   "name": "Rock_Stone"
  },
  {
   "x": -5,
   "y": 5,
   "z": 2,
   "name": "Rock_Stone"
  },
  {
   "x": -5,
   "y": 6,
   "z": 2,
   "name": "Rock_Stone"
  },
  {
   "x": -5,
   "y": 7,
   "z": 2,
   "name": "Rock_Stone"
  },
  {
   "x": -5,
   "y": 8,
   "z": 2,
   "name": "Rock_Stone"
  },
  {
   "x": -5,
   "y": 9,
   "z": 2,
   "name": "Rock_Stone"
  },
  {
   "x": -5,
   "y": 10,
   "z": 2,
   "name": "Rock_Stone"
  },
  {
   "x": -5,
   "y": 11,
   "z": 2,
   "name": "Rock_Stone"
  },
  {
   "x": -5,
   "y": 12,
   "z": 2,
   "name": "Rock_Stone"
  },
  {
   "x": -5,
   "y": 13,
   "z": 2,
   "name": "Rock_Stone"
  },
  {
   "x": -5,
   "y": 14,
   "z": 2,
   "name": "Rock_Stone"
  },
  {
   "x": -5,
   "y": 15,
   "z": 2,
   "name": "Rock_Stone"
  },
  {
   "x": -5,
   "y": 16,
   "z": 2,
   "name": "Rock_Stone"
  },
  {
   "x": -5,
   "y": 17,
   "z": 2,
   "name": "Rock_Stone"
  },
  {
   "x": -5,
   "y": 18,
   "z": 2,
   "name": "Rock_Stone"
  },
  {
   "x": -5,
   "y": 19,
   "z": 2,
   "name": "Rock_Stone_Brick"
  },
  {
   "x": -5,
   "y": 20,
   "z": 2,
   "name": "Empty"
  },
  {
   "x": -5,
   "y": 21,
   "z": 2,
   "name": "Empty"
  },
  {
   "x": -5,
   "y": 22,
   "z": 2,
   "name": "Empty"
  },
  {
   "x": -5,
   "y": 23,
   "z": 2,
   "name": "Empty"
  },
  {
   "x": -5,
   "y": 24,
   "z": 2,
   "name": "Empty"
  },
  {
   "x": -5,
   "y": 25,
   "z": 2,
   "name": "Empty"
  },
  {
   "x": -5,
   "y": 26,
   "z": 2,
   "name": "Empty"
  },
  {
   "x": -5,
   "y": 27,
   "z": 2,
   "name": "Rock_Stone"
  },
  {
   "x": -5,
   "y": 28,
   "z": 2,
   "name": "Rock_Stone"
  },
  {
   "x": -5,
   "y": 29,
   "z": 2,
   "name": "Rock_Stone"
  },
  {
   "x": -5,
   "y": 30,
   "z": 2,
   "name": "Rock_Stone"
  },
  {
   "x": -5,
   "y": 31,
   "z": 2,
   "name": "Rock_Basalt_Brick_Stairs"
  },
  {
   "x": -5,
   "y": 32,
   "z": 2,
   "name": "Empty"
  },
  {
   "x": -5,
   "y": 33,
   "z": 2,
   "name": "Empty"
  },
  {
   "x": -5,
   "y": 34,
   "z": 2,
   "name": "Empty"
  },
  {
   "x": -5,
   "y": 35,
   "z": 2,
   "name": "Empty"
  },
  {
   "x": -5,
   "y": 36,
   "z": 2,
   "name": "Empty"
  },
  {
   "x": -5,
   "y": 0,
   "z": 3,
   "name": "Rock_Stone"
  },
  {
   "x": -5,
   "y": 1,
   "z": 3,
   "name": "Rock_Stone"
  },
  {
   "x": -5,
   "y": 2,
   "z": 3,
   "name": "Rock_Stone"
  },
  {
   "x": -5,
   "y": 3,
   "z": 3,
   "name": "Rock_Stone"
  },
  {
   "x": -5,
   "y": 4,
   "z": 3,
   "name": "Rock_Stone"
  },
  {
   "x": -5,
   "y": 5,
   "z": 3,
   "name": "Rock_Stone"
  },
  {
   "x": -5,
   "y": 6,
   "z": 3,
   "name": "Rock_Stone"
  },
  {
   "x": -5,
   "y": 7,
   "z": 3,
   "name": "Rock_Stone"
  },
  {
   "x": -5,
   "y": 8,
   "z": 3,
   "name": "Rock_Stone"
  },
  {
   "x": -5,
   "y": 9,
   "z": 3,
   "name": "Rock_Stone"
  },
  {
   "x": -5,
   "y": 10,
   "z": 3,
   "name": "Rock_Stone"
  },
  {
   "x": -5,
   "y": 11,
   "z": 3,
   "name": "Rock_Stone"
  },
  {
   "x": -5,
   "y": 12,
   "z": 3,
   "name": "Rock_Stone"
  },
  {
   "x": -5,
   "y": 13,
   "z": 3,
   "name": "Rock_Stone"
  },
  {
   "x": -5,
   "y": 14,
   "z": 3,
   "name": "Rock_Stone"
  },
  {
   "x": -5,
   "y": 15,
   "z": 3,
   "name": "Rock_Stone"
  },
  {
   "x": -5,
   "y": 16,
   "z": 3,
   "name": "Rock_Stone"
  },
  {
   "x": -5,
   "y": 17,
   "z": 3,
   "name": "Rock_Stone"
  },
  {
   "x": -5,
   "y": 18,
   "z": 3,
   "name": "Rock_Stone"
  },
  {
   "x": -5,
   "y": 19,
   "z": 3,
   "name": "Rock_Stone_Brick"
  },
  {
   "x": -5,
   "y": 20,
   "z": 3,
   "name": "Empty"
  },
  {
   "x": -5,
   "y": 21,
   "z": 3,
   "name": "Empty"
  },
  {
   "x": -5,
   "y": 22,
   "z": 3,
   "name": "Empty"
  },
  {
   "x": -5,
   "y": 23,
   "z": 3,
   "name": "Empty"
  },
  {
   "x": -5,
   "y": 24,
   "z": 3,
   "name": "Empty"
  },
  {
   "x": -5,
   "y": 25,
   "z": 3,
   "name": "Empty"
  },
  {
   "x": -5,
   "y": 26,
   "z": 3,
   "name": "Empty"
  },
  {
   "x": -5,
   "y": 27,
   "z": 3,
   "name": "Rock_Stone"
  },
  {
   "x": -5,
   "y": 28,
   "z": 3,
   "name": "Rock_Stone"
  },
  {
   "x": -5,
   "y": 29,
   "z": 3,
   "name": "Rock_Stone"
  },
  {
   "x": -5,
   "y": 30,
   "z": 3,
   "name": "Rock_Basalt_Cobble"
  },
  {
   "x": -5,
   "y": 31,
   "z": 3,
   "name": "Empty"
  },
  {
   "x": -5,
   "y": 32,
   "z": 3,
   "name": "Empty"
  },
  {
   "x": -5,
   "y": 33,
   "z": 3,
   "name": "Empty"
  },
  {
   "x": -5,
   "y": 34,
   "z": 3,
   "name": "Empty"
  },
  {
   "x": -5,
   "y": 35,
   "z": 3,
   "name": "Empty"
  },
  {
   "x": -5,
   "y": 36,
   "z": 3,
   "name": "Empty"
  },
  {
   "x": -5,
   "y": 0,
   "z": 4,
   "name": "Rock_Stone"
  },
  {
   "x": -5,
   "y": 1,
   "z": 4,
   "name": "Rock_Stone"
  },
  {
   "x": -5,
   "y": 2,
   "z": 4,
   "name": "Rock_Stone"
  },
  {
   "x": -5,
   "y": 3,
   "z": 4,
   "name": "Rock_Stone"
  },
  {
   "x": -5,
   "y": 4,
   "z": 4,
   "name": "Rock_Stone"
  },
  {
   "x": -5,
   "y": 5,
   "z": 4,
   "name": "Rock_Stone"
  },
  {
   "x": -5,
   "y": 6,
   "z": 4,
   "name": "Rock_Stone"
  },
  {
   "x": -5,
   "y": 7,
   "z": 4,
   "name": "Rock_Stone"
  },
  {
   "x": -5,
   "y": 8,
   "z": 4,
   "name": "Rock_Stone"
  },
  {
   "x": -5,
   "y": 9,
   "z": 4,
   "name": "Rock_Stone"
  },
  {
   "x": -5,
   "y": 10,
   "z": 4,
   "name": "Rock_Stone"
  },
  {
   "x": -5,
   "y": 11,
   "z": 4,
   "name": "Rock_Stone"
  },
  {
   "x": -5,
   "y": 12,
   "z": 4,
   "name": "Rock_Stone"
  },
  {
   "x": -5,
   "y": 13,
   "z": 4,
   "name": "Rock_Stone"
  },
  {
   "x": -5,
   "y": 14,
   "z": 4,
   "name": "Rock_Stone"
  },
  {
   "x": -5,
   "y": 15,
   "z": 4,
   "name": "Rock_Stone"
  },
  {
   "x": -5,
   "y": 16,
   "z": 4,
   "name": "Rock_Stone"
  },
  {
   "x": -5,
   "y": 17,
   "z": 4,
   "name": "Rock_Stone"
  },
  {
   "x": -5,
   "y": 18,
   "z": 4,
   "name": "Rock_Stone"
  },
  {
   "x": -5,
   "y": 19,
   "z": 4,
   "name": "Rock_Stone_Brick"
  },
  {
   "x": -5,
   "y": 20,
   "z": 4,
   "name": "Furniture_Human_Ruins_Coffin",
   "filler": 992,
   "rotation": 1
  },
  {
   "x": -5,
   "y": 21,
   "z": 4,
   "name": "Empty"
  },
  {
   "x": -5,
   "y": 22,
   "z": 4,
   "name": "Empty"
  },
  {
   "x": -5,
   "y": 23,
   "z": 4,
   "name": "Empty"
  },
  {
   "x": -5,
   "y": 24,
   "z": 4,
   "name": "Empty"
  },
  {
   "x": -5,
   "y": 25,
   "z": 4,
   "name": "Empty"
  },
  {
   "x": -5,
   "y": 26,
   "z": 4,
   "name": "Empty"
  },
  {
   "x": -5,
   "y": 27,
   "z": 4,
   "name": "Rock_Stone"
  },
  {
   "x": -5,
   "y": 28,
   "z": 4,
   "name": "Rock_Stone"
  },
  {
   "x": -5,
   "y": 29,
   "z": 4,
   "name": "Rock_Stone"
  },
  {
   "x": -5,
   "y": 30,
   "z": 4,
   "name": "Rock_Stone"
  },
  {
   "x": -5,
   "y": 31,
   "z": 4,
   "name": "Empty"
  },
  {
   "x": -5,
   "y": 32,
   "z": 4,
   "name": "Empty"
  },
  {
   "x": -5,
   "y": 33,
   "z": 4,
   "name": "Empty"
  },
  {
   "x": -5,
   "y": 34,
   "z": 4,
   "name": "Empty"
  },
  {
   "x": -5,
   "y": 35,
   "z": 4,
   "name": "Empty"
  },
  {
   "x": -5,
   "y": 36,
   "z": 4,
   "name": "Empty"
  },
  {
   "x": -5,
   "y": 0,
   "z": 5,
   "name": "Rock_Stone"
  },
  {
   "x": -5,
   "y": 1,
   "z": 5,
   "name": "Rock_Stone"
  },
  {
   "x": -5,
   "y": 2,
   "z": 5,
   "name": "Rock_Stone"
  },
  {
   "x": -5,
   "y": 3,
   "z": 5,
   "name": "Rock_Stone"
  },
  {
   "x": -5,
   "y": 4,
   "z": 5,
   "name": "Rock_Stone"
  },
  {
   "x": -5,
   "y": 5,
   "z": 5,
   "name": "Rock_Stone"
  },
  {
   "x": -5,
   "y": 6,
   "z": 5,
   "name": "Rock_Stone"
  },
  {
   "x": -5,
   "y": 7,
   "z": 5,
   "name": "Rock_Stone"
  },
  {
   "x": -5,
   "y": 8,
   "z": 5,
   "name": "Rock_Stone"
  },
  {
   "x": -5,
   "y": 9,
   "z": 5,
   "name": "Rock_Stone"
  },
  {
   "x": -5,
   "y": 10,
   "z": 5,
   "name": "Rock_Stone"
  },
  {
   "x": -5,
   "y": 11,
   "z": 5,
   "name": "Rock_Stone"
  },
  {
   "x": -5,
   "y": 12,
   "z": 5,
   "name": "Rock_Stone"
  },
  {
   "x": -5,
   "y": 13,
   "z": 5,
   "name": "Rock_Stone"
  },
  {
   "x": -5,
   "y": 14,
   "z": 5,
   "name": "Rock_Stone"
  },
  {
   "x": -5,
   "y": 15,
   "z": 5,
   "name": "Rock_Stone"
  },
  {
   "x": -5,
   "y": 16,
   "z": 5,
   "name": "Rock_Stone"
  },
  {
   "x": -5,
   "y": 17,
   "z": 5,
   "name": "Rock_Stone"
  },
  {
   "x": -5,
   "y": 18,
   "z": 5,
   "name": "Rock_Stone"
  },
  {
   "x": -5,
   "y": 19,
   "z": 5,
   "name": "Rock_Stone_Brick"
  },
  {
   "x": -5,
   "y": 20,
   "z": 5,
   "name": "Furniture_Human_Ruins_Coffin",
   "rotation": 1
  },
  {
   "x": -5,
   "y": 21,
   "z": 5,
   "name": "Empty"
  },
  {
   "x": -5,
   "y": 22,
   "z": 5,
   "name": "Empty"
  },
  {
   "x": -5,
   "y": 23,
   "z": 5,
   "name": "Empty"
  },
  {
   "x": -5,
   "y": 24,
   "z": 5,
   "name": "Empty"
  },
  {
   "x": -5,
   "y": 25,
   "z": 5,
   "name": "Empty"
  },
  {
   "x": -5,
   "y": 26,
   "z": 5,
   "name": "Rock_Stone_Brick"
  },
  {
   "x": -5,
   "y": 27,
   "z": 5,
   "name": "Rock_Stone"
  },
  {
   "x": -5,
   "y": 28,
   "z": 5,
   "name": "Rock_Stone"
  },
  {
   "x": -5,
   "y": 29,
   "z": 5,
   "name": "Rock_Stone"
  },
  {
   "x": -5,
   "y": 30,
   "z": 5,
   "name": "Rock_Stone"
  },
  {
   "x": -5,
   "y": 31,
   "z": 5,
   "name": "Empty"
  },
  {
   "x": -5,
   "y": 32,
   "z": 5,
   "name": "Empty"
  },
  {
   "x": -5,
   "y": 33,
   "z": 5,
   "name": "Empty"
  },
  {
   "x": -5,
   "y": 34,
   "z": 5,
   "name": "Empty"
  },
  {
   "x": -5,
   "y": 35,
   "z": 5,
   "name": "Empty"
  },
  {
   "x": -5,
   "y": 36,
   "z": 5,
   "name": "Rock_Stone"
  },
  {
   "x": -5,
   "y": 0,
   "z": 6,
   "name": "Rock_Stone"
  },
  {
   "x": -5,
   "y": 1,
   "z": 6,
   "name": "Rock_Stone"
  },
  {
   "x": -5,
   "y": 2,
   "z": 6,
   "name": "Rock_Stone"
  },
  {
   "x": -5,
   "y": 3,
   "z": 6,
   "name": "Rock_Stone"
  },
  {
   "x": -5,
   "y": 4,
   "z": 6,
   "name": "Rock_Stone"
  },
  {
   "x": -5,
   "y": 5,
   "z": 6,
   "name": "Rock_Stone"
  },
  {
   "x": -5,
   "y": 6,
   "z": 6,
   "name": "Rock_Stone"
  },
  {
   "x": -5,
   "y": 7,
   "z": 6,
   "name": "Rock_Stone"
  },
  {
   "x": -5,
   "y": 8,
   "z": 6,
   "name": "Rock_Stone"
  },
  {
   "x": -5,
   "y": 9,
   "z": 6,
   "name": "Rock_Stone"
  },
  {
   "x": -5,
   "y": 10,
   "z": 6,
   "name": "Rock_Stone"
  },
  {
   "x": -5,
   "y": 11,
   "z": 6,
   "name": "Rock_Stone"
  },
  {
   "x": -5,
   "y": 12,
   "z": 6,
   "name": "Rock_Stone"
  },
  {
   "x": -5,
   "y": 13,
   "z": 6,
   "name": "Rock_Stone"
  },
  {
   "x": -5,
   "y": 14,
   "z": 6,
   "name": "Rock_Stone"
  },
  {
   "x": -5,
   "y": 15,
   "z": 6,
   "name": "Rock_Stone"
  },
  {
   "x": -5,
   "y": 16,
   "z": 6,
   "name": "Rock_Stone"
  },
  {
   "x": -5,
   "y": 17,
   "z": 6,
   "name": "Rock_Stone"
  },
  {
   "x": -5,
   "y": 18,
   "z": 6,
   "name": "Rock_Stone"
  },
  {
   "x": -5,
   "y": 19,
   "z": 6,
   "name": "Rock_Stone_Brick"
  },
  {
   "x": -5,
   "y": 20,
   "z": 6,
   "name": "Furniture_Human_Ruins_Planter"
  },
  {
   "x": -5,
   "y": 21,
   "z": 6,
   "name": "KweebecNightmare_Moonbloom_Plant"
  },
  {
   "x": -5,
   "y": 22,
   "z": 6,
   "name": "Empty"
  },
  {
   "x": -5,
   "y": 23,
   "z": 6,
   "name": "Empty"
  },
  {
   "x": -5,
   "y": 24,
   "z": 6,
   "name": "Empty"
  },
  {
   "x": -5,
   "y": 25,
   "z": 6,
   "name": "Empty"
  },
  {
   "x": -5,
   "y": 26,
   "z": 6,
   "name": "Rock_Stone_Brick"
  },
  {
   "x": -5,
   "y": 27,
   "z": 6,
   "name": "Rock_Stone"
  },
  {
   "x": -5,
   "y": 28,
   "z": 6,
   "name": "Rock_Stone"
  },
  {
   "x": -5,
   "y": 29,
   "z": 6,
   "name": "Rock_Stone"
  },
  {
   "x": -5,
   "y": 30,
   "z": 6,
   "name": "Rock_Stone"
  },
  {
   "x": -5,
   "y": 31,
   "z": 6,
   "name": "Empty"
  },
  {
   "x": -5,
   "y": 32,
   "z": 6,
   "name": "Empty"
  },
  {
   "x": -5,
   "y": 33,
   "z": 6,
   "name": "Empty"
  },
  {
   "x": -5,
   "y": 34,
   "z": 6,
   "name": "Rock_Stone"
  },
  {
   "x": -5,
   "y": 35,
   "z": 6,
   "name": "Rock_Stone"
  },
  {
   "x": -5,
   "y": 36,
   "z": 6,
   "name": "Rock_Stone"
  },
  {
   "x": -5,
   "y": 0,
   "z": 7,
   "name": "Rock_Stone"
  },
  {
   "x": -5,
   "y": 1,
   "z": 7,
   "name": "Rock_Stone"
  },
  {
   "x": -5,
   "y": 2,
   "z": 7,
   "name": "Rock_Stone"
  },
  {
   "x": -5,
   "y": 3,
   "z": 7,
   "name": "Rock_Stone"
  },
  {
   "x": -5,
   "y": 4,
   "z": 7,
   "name": "Rock_Stone"
  },
  {
   "x": -5,
   "y": 5,
   "z": 7,
   "name": "Rock_Stone"
  },
  {
   "x": -5,
   "y": 6,
   "z": 7,
   "name": "Rock_Stone"
  },
  {
   "x": -5,
   "y": 7,
   "z": 7,
   "name": "Rock_Stone"
  },
  {
   "x": -5,
   "y": 8,
   "z": 7,
   "name": "Rock_Stone"
  },
  {
   "x": -5,
   "y": 9,
   "z": 7,
   "name": "Rock_Stone"
  },
  {
   "x": -5,
   "y": 10,
   "z": 7,
   "name": "Rock_Stone"
  },
  {
   "x": -5,
   "y": 11,
   "z": 7,
   "name": "Rock_Stone"
  },
  {
   "x": -5,
   "y": 12,
   "z": 7,
   "name": "Rock_Stone"
  },
  {
   "x": -5,
   "y": 13,
   "z": 7,
   "name": "Rock_Stone"
  },
  {
   "x": -5,
   "y": 14,
   "z": 7,
   "name": "Rock_Stone"
  },
  {
   "x": -5,
   "y": 15,
   "z": 7,
   "name": "Rock_Stone"
  },
  {
   "x": -5,
   "y": 16,
   "z": 7,
   "name": "Rock_Stone"
  },
  {
   "x": -5,
   "y": 17,
   "z": 7,
   "name": "Rock_Stone"
  },
  {
   "x": -5,
   "y": 18,
   "z": 7,
   "name": "Rock_Stone"
  },
  {
   "x": -5,
   "y": 19,
   "z": 7,
   "name": "Rock_Stone_Brick"
  },
  {
   "x": -5,
   "y": 20,
   "z": 7,
   "name": "Rock_Stone_Brick_Pillar_Base"
  },
  {
   "x": -5,
   "y": 21,
   "z": 7,
   "name": "Rock_Stone_Brick_Pillar_Middle"
  },
  {
   "x": -5,
   "y": 22,
   "z": 7,
   "name": "Rock_Stone_Brick_Pillar_Middle"
  },
  {
   "x": -5,
   "y": 23,
   "z": 7,
   "name": "Rock_Stone_Brick_Pillar_Middle"
  },
  {
   "x": -5,
   "y": 24,
   "z": 7,
   "name": "Rock_Stone_Brick_Pillar_Middle"
  },
  {
   "x": -5,
   "y": 25,
   "z": 7,
   "name": "Rock_Stone_Brick_Pillar_Base",
   "rotation": 8
  },
  {
   "x": -5,
   "y": 26,
   "z": 7,
   "name": "Rock_Stone_Brick"
  },
  {
   "x": -5,
   "y": 27,
   "z": 7,
   "name": "Rock_Stone"
  },
  {
   "x": -5,
   "y": 28,
   "z": 7,
   "name": "Rock_Stone"
  },
  {
   "x": -5,
   "y": 29,
   "z": 7,
   "name": "Rock_Stone"
  },
  {
   "x": -5,
   "y": 30,
   "z": 7,
   "name": "Soil_Gravel"
  },
  {
   "x": -5,
   "y": 31,
   "z": 7,
   "name": "Rock_Stone"
  },
  {
   "x": -5,
   "y": 32,
   "z": 7,
   "name": "Rock_Stone"
  },
  {
   "x": -5,
   "y": 33,
   "z": 7,
   "name": "Rock_Stone"
  },
  {
   "x": -5,
   "y": 34,
   "z": 7,
   "name": "Rock_Stone"
  },
  {
   "x": -5,
   "y": 35,
   "z": 7,
   "name": "Rock_Stone"
  },
  {
   "x": -5,
   "y": 36,
   "z": 7,
   "name": "Rock_Stone"
  },
  {
   "x": -5,
   "y": 0,
   "z": 8,
   "name": "Rock_Stone"
  },
  {
   "x": -5,
   "y": 1,
   "z": 8,
   "name": "Rock_Stone"
  },
  {
   "x": -5,
   "y": 2,
   "z": 8,
   "name": "Rock_Stone"
  },
  {
   "x": -5,
   "y": 3,
   "z": 8,
   "name": "Rock_Stone"
  },
  {
   "x": -5,
   "y": 4,
   "z": 8,
   "name": "Rock_Stone"
  },
  {
   "x": -5,
   "y": 5,
   "z": 8,
   "name": "Rock_Stone"
  },
  {
   "x": -5,
   "y": 6,
   "z": 8,
   "name": "Rock_Stone"
  },
  {
   "x": -5,
   "y": 7,
   "z": 8,
   "name": "Rock_Stone"
  },
  {
   "x": -5,
   "y": 8,
   "z": 8,
   "name": "Rock_Stone"
  },
  {
   "x": -5,
   "y": 9,
   "z": 8,
   "name": "Rock_Stone"
  },
  {
   "x": -5,
   "y": 10,
   "z": 8,
   "name": "Rock_Stone"
  },
  {
   "x": -5,
   "y": 11,
   "z": 8,
   "name": "Rock_Stone"
  },
  {
   "x": -5,
   "y": 12,
   "z": 8,
   "name": "Rock_Stone"
  },
  {
   "x": -5,
   "y": 13,
   "z": 8,
   "name": "Rock_Stone"
  },
  {
   "x": -5,
   "y": 14,
   "z": 8,
   "name": "Rock_Stone"
  },
  {
   "x": -5,
   "y": 15,
   "z": 8,
   "name": "Rock_Stone"
  },
  {
   "x": -5,
   "y": 16,
   "z": 8,
   "name": "Rock_Stone"
  },
  {
   "x": -5,
   "y": 17,
   "z": 8,
   "name": "Rock_Stone"
  },
  {
   "x": -5,
   "y": 18,
   "z": 8,
   "name": "Rock_Stone"
  },
  {
   "x": -5,
   "y": 19,
   "z": 8,
   "name": "Rock_Stone"
  },
  {
   "x": -5,
   "y": 20,
   "z": 8,
   "name": "Rock_Stone_Brick_Smooth"
  },
  {
   "x": -5,
   "y": 21,
   "z": 8,
   "name": "Rock_Stone_Brick_Smooth"
  },
  {
   "x": -5,
   "y": 22,
   "z": 8,
   "name": "Rock_Stone_Brick_Smooth"
  },
  {
   "x": -5,
   "y": 23,
   "z": 8,
   "name": "Rock_Stone"
  },
  {
   "x": -5,
   "y": 24,
   "z": 8,
   "name": "Rock_Stone"
  },
  {
   "x": -5,
   "y": 25,
   "z": 8,
   "name": "Rock_Stone"
  },
  {
   "x": -5,
   "y": 26,
   "z": 8,
   "name": "Rock_Stone"
  },
  {
   "x": -5,
   "y": 27,
   "z": 8,
   "name": "Rock_Stone"
  },
  {
   "x": -5,
   "y": 28,
   "z": 8,
   "name": "Rock_Stone"
  },
  {
   "x": -5,
   "y": 29,
   "z": 8,
   "name": "Rock_Stone"
  },
  {
   "x": -5,
   "y": 30,
   "z": 8,
   "name": "Rock_Stone"
  },
  {
   "x": -5,
   "y": 31,
   "z": 8,
   "name": "Rock_Stone"
  },
  {
   "x": -5,
   "y": 32,
   "z": 8,
   "name": "Rock_Stone"
  },
  {
   "x": -5,
   "y": 33,
   "z": 8,
   "name": "Rock_Stone"
  },
  {
   "x": -5,
   "y": 34,
   "z": 8,
   "name": "Rock_Stone"
  },
  {
   "x": -5,
   "y": 35,
   "z": 8,
   "name": "Rock_Stone"
  },
  {
   "x": -5,
   "y": 36,
   "z": 8,
   "name": "Rock_Stone"
  },
  {
   "x": -4,
   "y": 0,
   "z": -9,
   "name": "Rock_Stone"
  },
  {
   "x": -4,
   "y": 1,
   "z": -9,
   "name": "Rock_Stone"
  },
  {
   "x": -4,
   "y": 2,
   "z": -9,
   "name": "Rock_Stone"
  },
  {
   "x": -4,
   "y": 3,
   "z": -9,
   "name": "Rock_Stone"
  },
  {
   "x": -4,
   "y": 4,
   "z": -9,
   "name": "Rock_Stone"
  },
  {
   "x": -4,
   "y": 5,
   "z": -9,
   "name": "Rock_Stone"
  },
  {
   "x": -4,
   "y": 6,
   "z": -9,
   "name": "Rock_Stone"
  },
  {
   "x": -4,
   "y": 7,
   "z": -9,
   "name": "Rock_Stone"
  },
  {
   "x": -4,
   "y": 8,
   "z": -9,
   "name": "Rock_Stone"
  },
  {
   "x": -4,
   "y": 9,
   "z": -9,
   "name": "Rock_Stone"
  },
  {
   "x": -4,
   "y": 10,
   "z": -9,
   "name": "Rock_Stone"
  },
  {
   "x": -4,
   "y": 11,
   "z": -9,
   "name": "Rock_Stone"
  },
  {
   "x": -4,
   "y": 12,
   "z": -9,
   "name": "Rock_Stone"
  },
  {
   "x": -4,
   "y": 13,
   "z": -9,
   "name": "Rock_Stone"
  },
  {
   "x": -4,
   "y": 0,
   "z": -8,
   "name": "Rock_Stone"
  },
  {
   "x": -4,
   "y": 1,
   "z": -8,
   "name": "Rock_Stone"
  },
  {
   "x": -4,
   "y": 2,
   "z": -8,
   "name": "Rock_Stone"
  },
  {
   "x": -4,
   "y": 3,
   "z": -8,
   "name": "Rock_Stone"
  },
  {
   "x": -4,
   "y": 4,
   "z": -8,
   "name": "Rock_Stone"
  },
  {
   "x": -4,
   "y": 5,
   "z": -8,
   "name": "Rock_Stone"
  },
  {
   "x": -4,
   "y": 6,
   "z": -8,
   "name": "Rock_Stone"
  },
  {
   "x": -4,
   "y": 7,
   "z": -8,
   "name": "Rock_Stone"
  },
  {
   "x": -4,
   "y": 8,
   "z": -8,
   "name": "Rock_Stone"
  },
  {
   "x": -4,
   "y": 9,
   "z": -8,
   "name": "Rock_Stone"
  },
  {
   "x": -4,
   "y": 10,
   "z": -8,
   "name": "Rock_Stone"
  },
  {
   "x": -4,
   "y": 11,
   "z": -8,
   "name": "Rock_Stone"
  },
  {
   "x": -4,
   "y": 12,
   "z": -8,
   "name": "Rock_Stone"
  },
  {
   "x": -4,
   "y": 13,
   "z": -8,
   "name": "Rock_Stone"
  },
  {
   "x": -4,
   "y": 0,
   "z": -7,
   "name": "Rock_Stone"
  },
  {
   "x": -4,
   "y": 1,
   "z": -7,
   "name": "Rock_Stone"
  },
  {
   "x": -4,
   "y": 2,
   "z": -7,
   "name": "Rock_Stone"
  },
  {
   "x": -4,
   "y": 3,
   "z": -7,
   "name": "Rock_Stone"
  },
  {
   "x": -4,
   "y": 4,
   "z": -7,
   "name": "Rock_Stone"
  },
  {
   "x": -4,
   "y": 5,
   "z": -7,
   "name": "Rock_Stone"
  },
  {
   "x": -4,
   "y": 6,
   "z": -7,
   "name": "Rock_Stone"
  },
  {
   "x": -4,
   "y": 7,
   "z": -7,
   "name": "Rock_Stone"
  },
  {
   "x": -4,
   "y": 8,
   "z": -7,
   "name": "Rock_Stone"
  },
  {
   "x": -4,
   "y": 9,
   "z": -7,
   "name": "Rock_Stone"
  },
  {
   "x": -4,
   "y": 10,
   "z": -7,
   "name": "Rock_Stone"
  },
  {
   "x": -4,
   "y": 11,
   "z": -7,
   "name": "Rock_Stone"
  },
  {
   "x": -4,
   "y": 12,
   "z": -7,
   "name": "Rock_Stone"
  },
  {
   "x": -4,
   "y": 13,
   "z": -7,
   "name": "Rock_Stone"
  },
  {
   "x": -4,
   "y": 21,
   "z": -7,
   "name": "Rock_Stone"
  },
  {
   "x": -4,
   "y": 22,
   "z": -7,
   "name": "Rock_Stone"
  },
  {
   "x": -4,
   "y": 23,
   "z": -7,
   "name": "Rock_Stone"
  },
  {
   "x": -4,
   "y": 24,
   "z": -7,
   "name": "Rock_Stone"
  },
  {
   "x": -4,
   "y": 25,
   "z": -7,
   "name": "Rock_Stone"
  },
  {
   "x": -4,
   "y": 26,
   "z": -7,
   "name": "Rock_Stone"
  },
  {
   "x": -4,
   "y": 27,
   "z": -7,
   "name": "Rock_Stone"
  },
  {
   "x": -4,
   "y": 28,
   "z": -7,
   "name": "Rock_Stone"
  },
  {
   "x": -4,
   "y": 29,
   "z": -7,
   "name": "Rock_Stone"
  },
  {
   "x": -4,
   "y": 30,
   "z": -7,
   "name": "Rock_Stone"
  },
  {
   "x": -4,
   "y": 31,
   "z": -7,
   "name": "Rock_Stone"
  },
  {
   "x": -4,
   "y": 32,
   "z": -7,
   "name": "Rock_Stone"
  },
  {
   "x": -4,
   "y": 33,
   "z": -7,
   "name": "Rock_Stone"
  },
  {
   "x": -4,
   "y": 34,
   "z": -7,
   "name": "Rock_Stone"
  },
  {
   "x": -4,
   "y": 35,
   "z": -7,
   "name": "Rock_Stone"
  },
  {
   "x": -4,
   "y": 36,
   "z": -7,
   "name": "Rock_Stone"
  },
  {
   "x": -4,
   "y": 0,
   "z": -6,
   "name": "Rock_Stone"
  },
  {
   "x": -4,
   "y": 1,
   "z": -6,
   "name": "Rock_Stone"
  },
  {
   "x": -4,
   "y": 2,
   "z": -6,
   "name": "Rock_Stone"
  },
  {
   "x": -4,
   "y": 3,
   "z": -6,
   "name": "Rock_Stone"
  },
  {
   "x": -4,
   "y": 4,
   "z": -6,
   "name": "Rock_Stone"
  },
  {
   "x": -4,
   "y": 5,
   "z": -6,
   "name": "Rock_Stone"
  },
  {
   "x": -4,
   "y": 6,
   "z": -6,
   "name": "Rock_Stone"
  },
  {
   "x": -4,
   "y": 7,
   "z": -6,
   "name": "Rock_Stone"
  },
  {
   "x": -4,
   "y": 8,
   "z": -6,
   "name": "Rock_Stone"
  },
  {
   "x": -4,
   "y": 9,
   "z": -6,
   "name": "Rock_Stone"
  },
  {
   "x": -4,
   "y": 10,
   "z": -6,
   "name": "Rock_Stone"
  },
  {
   "x": -4,
   "y": 11,
   "z": -6,
   "name": "Rock_Stone"
  },
  {
   "x": -4,
   "y": 12,
   "z": -6,
   "name": "Rock_Stone"
  },
  {
   "x": -4,
   "y": 13,
   "z": -6,
   "name": "Rock_Stone"
  },
  {
   "x": -4,
   "y": 21,
   "z": -6,
   "name": "Rock_Stone"
  },
  {
   "x": -4,
   "y": 22,
   "z": -6,
   "name": "Rock_Stone"
  },
  {
   "x": -4,
   "y": 23,
   "z": -6,
   "name": "Rock_Stone"
  },
  {
   "x": -4,
   "y": 24,
   "z": -6,
   "name": "Rock_Stone"
  },
  {
   "x": -4,
   "y": 25,
   "z": -6,
   "name": "Empty"
  },
  {
   "x": -4,
   "y": 26,
   "z": -6,
   "name": "Rock_Stone"
  },
  {
   "x": -4,
   "y": 27,
   "z": -6,
   "name": "Rock_Stone"
  },
  {
   "x": -4,
   "y": 28,
   "z": -6,
   "name": "Rock_Stone"
  },
  {
   "x": -4,
   "y": 29,
   "z": -6,
   "name": "Rock_Stone"
  },
  {
   "x": -4,
   "y": 30,
   "z": -6,
   "name": "Rock_Stone"
  },
  {
   "x": -4,
   "y": 31,
   "z": -6,
   "name": "Rock_Stone"
  },
  {
   "x": -4,
   "y": 32,
   "z": -6,
   "name": "Rock_Stone"
  },
  {
   "x": -4,
   "y": 33,
   "z": -6,
   "name": "Rock_Stone"
  },
  {
   "x": -4,
   "y": 34,
   "z": -6,
   "name": "Rock_Stone"
  },
  {
   "x": -4,
   "y": 35,
   "z": -6,
   "name": "Rock_Stone"
  },
  {
   "x": -4,
   "y": 36,
   "z": -6,
   "name": "Rock_Stone"
  },
  {
   "x": -4,
   "y": 0,
   "z": -5,
   "name": "Rock_Stone"
  },
  {
   "x": -4,
   "y": 1,
   "z": -5,
   "name": "Rock_Stone"
  },
  {
   "x": -4,
   "y": 2,
   "z": -5,
   "name": "Rock_Stone"
  },
  {
   "x": -4,
   "y": 3,
   "z": -5,
   "name": "Rock_Stone"
  },
  {
   "x": -4,
   "y": 4,
   "z": -5,
   "name": "Rock_Stone"
  },
  {
   "x": -4,
   "y": 5,
   "z": -5,
   "name": "Rock_Stone"
  },
  {
   "x": -4,
   "y": 6,
   "z": -5,
   "name": "Rock_Stone"
  },
  {
   "x": -4,
   "y": 7,
   "z": -5,
   "name": "Rock_Stone"
  },
  {
   "x": -4,
   "y": 8,
   "z": -5,
   "name": "Rock_Stone"
  },
  {
   "x": -4,
   "y": 9,
   "z": -5,
   "name": "Rock_Stone"
  },
  {
   "x": -4,
   "y": 10,
   "z": -5,
   "name": "Rock_Stone"
  },
  {
   "x": -4,
   "y": 11,
   "z": -5,
   "name": "Rock_Stone"
  },
  {
   "x": -4,
   "y": 12,
   "z": -5,
   "name": "Rock_Stone"
  },
  {
   "x": -4,
   "y": 13,
   "z": -5,
   "name": "Rock_Stone"
  },
  {
   "x": -4,
   "y": 21,
   "z": -5,
   "name": "Rock_Stone"
  },
  {
   "x": -4,
   "y": 22,
   "z": -5,
   "name": "Rock_Stone"
  },
  {
   "x": -4,
   "y": 23,
   "z": -5,
   "name": "Rock_Stone"
  },
  {
   "x": -4,
   "y": 24,
   "z": -5,
   "name": "Rock_Stone"
  },
  {
   "x": -4,
   "y": 25,
   "z": -5,
   "name": "Rock_Stone"
  },
  {
   "x": -4,
   "y": 26,
   "z": -5,
   "name": "Rock_Stone"
  },
  {
   "x": -4,
   "y": 27,
   "z": -5,
   "name": "Rock_Stone"
  },
  {
   "x": -4,
   "y": 28,
   "z": -5,
   "name": "Rock_Stone"
  },
  {
   "x": -4,
   "y": 29,
   "z": -5,
   "name": "Rock_Stone"
  },
  {
   "x": -4,
   "y": 30,
   "z": -5,
   "name": "Rock_Stone"
  },
  {
   "x": -4,
   "y": 31,
   "z": -5,
   "name": "Rock_Stone"
  },
  {
   "x": -4,
   "y": 32,
   "z": -5,
   "name": "Rock_Stone"
  },
  {
   "x": -4,
   "y": 33,
   "z": -5,
   "name": "Rock_Stone"
  },
  {
   "x": -4,
   "y": 34,
   "z": -5,
   "name": "Rock_Stone"
  },
  {
   "x": -4,
   "y": 35,
   "z": -5,
   "name": "Rock_Stone"
  },
  {
   "x": -4,
   "y": 36,
   "z": -5,
   "name": "Rock_Stone"
  },
  {
   "x": -4,
   "y": 0,
   "z": -4,
   "name": "Rock_Stone"
  },
  {
   "x": -4,
   "y": 1,
   "z": -4,
   "name": "Rock_Stone"
  },
  {
   "x": -4,
   "y": 2,
   "z": -4,
   "name": "Rock_Stone"
  },
  {
   "x": -4,
   "y": 3,
   "z": -4,
   "name": "Rock_Stone"
  },
  {
   "x": -4,
   "y": 4,
   "z": -4,
   "name": "Rock_Stone"
  },
  {
   "x": -4,
   "y": 5,
   "z": -4,
   "name": "Rock_Stone"
  },
  {
   "x": -4,
   "y": 6,
   "z": -4,
   "name": "Rock_Stone"
  },
  {
   "x": -4,
   "y": 7,
   "z": -4,
   "name": "Rock_Stone"
  },
  {
   "x": -4,
   "y": 8,
   "z": -4,
   "name": "Rock_Stone"
  },
  {
   "x": -4,
   "y": 9,
   "z": -4,
   "name": "Rock_Stone"
  },
  {
   "x": -4,
   "y": 10,
   "z": -4,
   "name": "Rock_Stone"
  },
  {
   "x": -4,
   "y": 11,
   "z": -4,
   "name": "Rock_Stone"
  },
  {
   "x": -4,
   "y": 12,
   "z": -4,
   "name": "Rock_Stone"
  },
  {
   "x": -4,
   "y": 13,
   "z": -4,
   "name": "Rock_Stone"
  },
  {
   "x": -4,
   "y": 14,
   "z": -4,
   "name": "Rock_Stone"
  },
  {
   "x": -4,
   "y": 15,
   "z": -4,
   "name": "Rock_Stone"
  },
  {
   "x": -4,
   "y": 16,
   "z": -4,
   "name": "Rock_Stone"
  },
  {
   "x": -4,
   "y": 17,
   "z": -4,
   "name": "Rock_Stone"
  },
  {
   "x": -4,
   "y": 18,
   "z": -4,
   "name": "Rock_Stone"
  },
  {
   "x": -4,
   "y": 19,
   "z": -4,
   "name": "Rock_Stone"
  },
  {
   "x": -4,
   "y": 20,
   "z": -4,
   "name": "Rock_Stone"
  },
  {
   "x": -4,
   "y": 21,
   "z": -4,
   "name": "Rock_Stone"
  },
  {
   "x": -4,
   "y": 22,
   "z": -4,
   "name": "Rock_Stone"
  },
  {
   "x": -4,
   "y": 23,
   "z": -4,
   "name": "Rock_Stone"
  },
  {
   "x": -4,
   "y": 24,
   "z": -4,
   "name": "Rock_Stone"
  },
  {
   "x": -4,
   "y": 25,
   "z": -4,
   "name": "Rock_Stone_Stalactite_Small"
  },
  {
   "x": -4,
   "y": 26,
   "z": -4,
   "name": "Empty"
  },
  {
   "x": -4,
   "y": 27,
   "z": -4,
   "name": "Empty"
  },
  {
   "x": -4,
   "y": 28,
   "z": -4,
   "name": "Rock_Stone"
  },
  {
   "x": -4,
   "y": 29,
   "z": -4,
   "name": "Rock_Stone"
  },
  {
   "x": -4,
   "y": 30,
   "z": -4,
   "name": "Rock_Stone"
  },
  {
   "x": -4,
   "y": 31,
   "z": -4,
   "name": "Rock_Stone"
  },
  {
   "x": -4,
   "y": 32,
   "z": -4,
   "name": "Rock_Stone"
  },
  {
   "x": -4,
   "y": 33,
   "z": -4,
   "name": "Rock_Stone"
  },
  {
   "x": -4,
   "y": 34,
   "z": -4,
   "name": "Rock_Stone"
  },
  {
   "x": -4,
   "y": 35,
   "z": -4,
   "name": "Rock_Stone"
  },
  {
   "x": -4,
   "y": 36,
   "z": -4,
   "name": "Rock_Basalt_Brick"
  },
  {
   "x": -4,
   "y": 0,
   "z": -3,
   "name": "Rock_Stone"
  },
  {
   "x": -4,
   "y": 1,
   "z": -3,
   "name": "Rock_Stone"
  },
  {
   "x": -4,
   "y": 2,
   "z": -3,
   "name": "Rock_Stone"
  },
  {
   "x": -4,
   "y": 3,
   "z": -3,
   "name": "Rock_Stone"
  },
  {
   "x": -4,
   "y": 4,
   "z": -3,
   "name": "Rock_Stone"
  },
  {
   "x": -4,
   "y": 5,
   "z": -3,
   "name": "Rock_Stone"
  },
  {
   "x": -4,
   "y": 6,
   "z": -3,
   "name": "Rock_Stone"
  },
  {
   "x": -4,
   "y": 7,
   "z": -3,
   "name": "Rock_Stone"
  },
  {
   "x": -4,
   "y": 8,
   "z": -3,
   "name": "Rock_Stone"
  },
  {
   "x": -4,
   "y": 9,
   "z": -3,
   "name": "Rock_Stone"
  },
  {
   "x": -4,
   "y": 10,
   "z": -3,
   "name": "Rock_Stone"
  },
  {
   "x": -4,
   "y": 11,
   "z": -3,
   "name": "Rock_Stone"
  },
  {
   "x": -4,
   "y": 12,
   "z": -3,
   "name": "Rock_Stone"
  },
  {
   "x": -4,
   "y": 13,
   "z": -3,
   "name": "Empty"
  },
  {
   "x": -4,
   "y": 14,
   "z": -3,
   "name": "Empty"
  },
  {
   "x": -4,
   "y": 15,
   "z": -3,
   "name": "Empty"
  },
  {
   "x": -4,
   "y": 16,
   "z": -3,
   "name": "Empty"
  },
  {
   "x": -4,
   "y": 17,
   "z": -3,
   "name": "Rock_Stone"
  },
  {
   "x": -4,
   "y": 18,
   "z": -3,
   "name": "Rock_Stone"
  },
  {
   "x": -4,
   "y": 19,
   "z": -3,
   "name": "Rock_Stone"
  },
  {
   "x": -4,
   "y": 20,
   "z": -3,
   "name": "Rock_Stone"
  },
  {
   "x": -4,
   "y": 21,
   "z": -3,
   "name": "Rock_Stone"
  },
  {
   "x": -4,
   "y": 22,
   "z": -3,
   "name": "Rock_Stone"
  },
  {
   "x": -4,
   "y": 23,
   "z": -3,
   "name": "Rock_Stone_Brick"
  },
  {
   "x": -4,
   "y": 24,
   "z": -3,
   "name": "Empty"
  },
  {
   "x": -4,
   "y": 25,
   "z": -3,
   "name": "Empty"
  },
  {
   "x": -4,
   "y": 26,
   "z": -3,
   "name": "Empty"
  },
  {
   "x": -4,
   "y": 27,
   "z": -3,
   "name": "Empty"
  },
  {
   "x": -4,
   "y": 28,
   "z": -3,
   "name": "Empty"
  },
  {
   "x": -4,
   "y": 29,
   "z": -3,
   "name": "Empty"
  },
  {
   "x": -4,
   "y": 30,
   "z": -3,
   "name": "Rock_Stone"
  },
  {
   "x": -4,
   "y": 31,
   "z": -3,
   "name": "Rock_Stone"
  },
  {
   "x": -4,
   "y": 32,
   "z": -3,
   "name": "Rock_Stone"
  },
  {
   "x": -4,
   "y": 33,
   "z": -3,
   "name": "Rock_Stone"
  },
  {
   "x": -4,
   "y": 34,
   "z": -3,
   "name": "Rock_Stone"
  },
  {
   "x": -4,
   "y": 35,
   "z": -3,
   "name": "Rock_Basalt_Brick"
  },
  {
   "x": -4,
   "y": 36,
   "z": -3,
   "name": "KweebecNightmare_Moonbloom_Plant"
  },
  {
   "x": -4,
   "y": 0,
   "z": -2,
   "name": "Rock_Stone"
  },
  {
   "x": -4,
   "y": 1,
   "z": -2,
   "name": "Rock_Stone"
  },
  {
   "x": -4,
   "y": 2,
   "z": -2,
   "name": "Rock_Stone"
  },
  {
   "x": -4,
   "y": 3,
   "z": -2,
   "name": "Rock_Stone"
  },
  {
   "x": -4,
   "y": 4,
   "z": -2,
   "name": "Rock_Stone"
  },
  {
   "x": -4,
   "y": 5,
   "z": -2,
   "name": "Rock_Stone"
  },
  {
   "x": -4,
   "y": 6,
   "z": -2,
   "name": "Rock_Stone"
  },
  {
   "x": -4,
   "y": 7,
   "z": -2,
   "name": "Rock_Stone"
  },
  {
   "x": -4,
   "y": 8,
   "z": -2,
   "name": "Rock_Stone"
  },
  {
   "x": -4,
   "y": 9,
   "z": -2,
   "name": "Rock_Stone"
  },
  {
   "x": -4,
   "y": 10,
   "z": -2,
   "name": "Rock_Stone"
  },
  {
   "x": -4,
   "y": 11,
   "z": -2,
   "name": "Rock_Stone"
  },
  {
   "x": -4,
   "y": 12,
   "z": -2,
   "name": "Rock_Stone"
  },
  {
   "x": -4,
   "y": 13,
   "z": -2,
   "name": "Deco_Bone_Skulls_Wall",
   "rotation": 2
  },
  {
   "x": -4,
   "y": 14,
   "z": -2,
   "name": "Deco_Bone_Skulls_Wall",
   "rotation": 2
  },
  {
   "x": -4,
   "y": 15,
   "z": -2,
   "name": "Rock_Stone"
  },
  {
   "x": -4,
   "y": 16,
   "z": -2,
   "name": "Rock_Stone"
  },
  {
   "x": -4,
   "y": 17,
   "z": -2,
   "name": "Rock_Stone"
  },
  {
   "x": -4,
   "y": 18,
   "z": -2,
   "name": "Rock_Stone"
  },
  {
   "x": -4,
   "y": 19,
   "z": -2,
   "name": "Rock_Stone"
  },
  {
   "x": -4,
   "y": 20,
   "z": -2,
   "name": "Rock_Stone"
  },
  {
   "x": -4,
   "y": 21,
   "z": -2,
   "name": "Rock_Stone"
  },
  {
   "x": -4,
   "y": 22,
   "z": -2,
   "name": "Rock_Stone_Brick"
  },
  {
   "x": -4,
   "y": 23,
   "z": -2,
   "name": "Rock_Stone_Brick_Stairs"
  },
  {
   "x": -4,
   "y": 24,
   "z": -2,
   "name": "Empty"
  },
  {
   "x": -4,
   "y": 25,
